Workbook

Sheet Como usar
A1: Agenda de prazos e audiências
A2: Kit de Gestão para Advogados · Seu Sócio Gestor · versão 1.0 (setembro de 2026)
A4: O que esta planilha faz | B4: Reúne todos os prazos, audiências e compromissos do escritório em uma lista só e mostra, no Painel, o que está atrasado, o que vence hoje, o que vence nos próximos dias, quem responde por cada um e quantos caem em cada dia da semana.
A5: Passo 1 | B5: Em Config, confira a data de referência (fica em =HOJE()), cadastre as pessoas do escritório e ajuste a lista de tipos de prazo. Preencha de cima para baixo, sem pular linha.
A6: Passo 2 | B6: Em Prazos, apague os exemplos e registre uma linha por prazo: processo, cliente, tipo (lista), data, responsável (lista) e observação. Quando cumprir, marque Sim em Feito: a linha fica cinza e sai do painel.
A7: Passo 3 | B7: Em Painel, leia de cima para baixo: quadros de contagem, lista "O que vence primeiro", carga por responsável e os próximos 7 dias.
A8: Rotina de segunda | B8: 10 minutos: abra o Painel, resolva ou reagende os atrasados, confirme com cada responsável os prazos da semana e registre os prazos novos que chegaram.
A9: Limite | B9: A planilha organiza e avisa. A contagem do prazo, a conferência da data na fonte oficial e o cumprimento continuam sendo responsabilidade de quem responde pelo caso.
A10: Com a IA | B10: Copie a tabela "O que vence primeiro" e use o prompt "Prazos 04 · Distribuir a semana entre as pessoas" da biblioteca do kit.
A11: Legenda | B11: Células amarelas: você preenche. Brancas: calculadas. Não é preciso mexer em nada fora do amarelo.
A12: Proteção | B12: Fórmulas protegidas sem senha. Para editar: Revisar > Desproteger planilha (Excel) ou Dados > Proteger intervalos (Google Sheets).
A13: Requisitos | B13: Excel 2019 ou mais novo, Microsoft 365 ou Google Sheets. No celular abre nos aplicativos; para preencher, use o computador.
A14: Google Sheets | B14: Faça upload no Google Drive e abra com o Google Sheets. Fórmulas, listas, cores e gráficos funcionam.
A15: Exemplos | B15: Ferraz & Lima Advocacia é um escritório fictício. Clientes, processos, nomes e valores são inventados. Apague-os antes de começar. Datas de prazo do exemplo são relativas a hoje.
A16: Suporte | B16: suporte@seusociogestor.com.br · resposta em até 5 dias úteis · reembolso em até 7 dias pelo mesmo canal.

Sheet Painel
A1: =Config!$B$4&" · Painel de prazos · "&TEXT(Config!$B$5,"dd/mm/yyyy")
A2: Nada para digitar aqui: tudo vem de Config e Prazos. A planilha avisa; a conferência do prazo é de quem responde por ele.
A4: Atrasados | C4: Hoje | E4: ="Próximos "&Config!$B$6&" dias" | G4: ="De "&(Config!$B$6+1)&" a "&Config!$B$7&" dias" | I4: Abertos no total | K4: Feitos
A5: =COUNTIFS(Prazos!$I$5:$I$404,"Atrasado") | C5: =COUNTIFS(Prazos!$I$5:$I$404,"Hoje") | E5: =COUNTIFS(Prazos!$I$5:$I$404,"Até "&Config!$B$6&" dias") | G5: =COUNTIFS(Prazos!$I$5:$I$404,"Até "&Config!$B$7&" dias") | I5: =COUNTIF(Prazos!$J$5:$J$404,">0")+COUNTIFS(Prazos!$I$5:$I$404,"Sem data") | K5: =COUNTIFS(Prazos!$I$5:$I$404,"Feito")
A7: O que vence primeiro
A8: Ordem: atrasados (mais tempo de atraso primeiro), hoje, depois os mais próximos. Mostra os 15 primeiros; os demais ficam na aba Prazos, que pode ser filtrada por situação.
A9: # | B9: Processo | C9: Cliente | D9: Tipo de prazo | E9: Data | F9: Dias | G9: Situação | H9: Responsável
A10: 1 | B10: =IFERROR(IF(LARGE(Prazos!$J$5:$J$404,1)>0,IF(INDEX(Prazos!$A$5:$A$404,MATCH(LARGE(Prazos!$J$5:$J$404,1),Prazos!$J$5:$J$404,0))="","",INDEX(Prazos!$A$5:$A$404,MATCH(LARGE(Prazos!$J$5:$J$404,1),Prazos!$J$5:$J$404,0))),""),"") | C10: =IFERROR(IF(LARGE(Prazos!$J$5:$J$404,1)>0,IF(INDEX(Prazos!$B$5:$B$404,MATCH(LARGE(Prazos!$J$5:$J$404,1),Prazos!$J$5:$J$404,0))="","",INDEX(Prazos!$B$5:$B$404,MATCH(LARGE(Prazos!$J$5:$J$404,1),Prazos!$J$5:$J$404,0))),""),"") | D10: =IFERROR(IF(LARGE(Prazos!$J$5:$J$404,1)>0,IF(INDEX(Prazos!$C$5:$C$404,MATCH(LARGE(Prazos!$J$5:$J$404,1),Prazos!$J$5:$J$404,0))="","",INDEX(Prazos!$C$5:$C$404,MATCH(LARGE(Prazos!$J$5:$J$404,1),Prazos!$J$5:$J$404,0))),""),"") | E10: =IFERROR(IF(LARGE(Prazos!$J$5:$J$404,1)>0,IF(INDEX(Prazos!$D$5:$D$404,MATCH(LARGE(Prazos!$J$5:$J$404,1),Prazos!$J$5:$J$404,0))="","",INDEX(Prazos!$D$5:$D$404,MATCH(LARGE(Prazos!$J$5:$J$404,1),Prazos!$J$5:$J$404,0))),""),"") | F10: =IFERROR(IF(LARGE(Prazos!$J$5:$J$404,1)>0,IF(INDEX(Prazos!$H$5:$H$404,MATCH(LARGE(Prazos!$J$5:$J$404,1),Prazos!$J$5:$J$404,0))="","",INDEX(Prazos!$H$5:$H$404,MATCH(LARGE(Prazos!$J$5:$J$404,1),Prazos!$J$5:$J$404,0))),""),"") | G10: =IFERROR(IF(LARGE(Prazos!$J$5:$J$404,1)>0,IF(INDEX(Prazos!$I$5:$I$404,MATCH(LARGE(Prazos!$J$5:$J$404,1),Prazos!$J$5:$J$404,0))="","",INDEX(Prazos!$I$5:$I$404,MATCH(LARGE(Prazos!$J$5:$J$404,1),Prazos!$J$5:$J$404,0))),""),"") | H10: =IFERROR(IF(LARGE(Prazos!$J$5:$J$404,1)>0,IF(INDEX(Prazos!$E$5:$E$404,MATCH(LARGE(Prazos!$J$5:$J$404,1),Prazos!$J$5:$J$404,0))="","",INDEX(Prazos!$E$5:$E$404,MATCH(LARGE(Prazos!$J$5:$J$404,1),Prazos!$J$5:$J$404,0))),""),"")
A11: 2 | B11: =IFERROR(IF(LARGE(Prazos!$J$5:$J$404,2)>0,IF(INDEX(Prazos!$A$5:$A$404,MATCH(LARGE(Prazos!$J$5:$J$404,2),Prazos!$J$5:$J$404,0))="","",INDEX(Prazos!$A$5:$A$404,MATCH(LARGE(Prazos!$J$5:$J$404,2),Prazos!$J$5:$J$404,0))),""),"") | C11: =IFERROR(IF(LARGE(Prazos!$J$5:$J$404,2)>0,IF(INDEX(Prazos!$B$5:$B$404,MATCH(LARGE(Prazos!$J$5:$J$404,2),Prazos!$J$5:$J$404,0))="","",INDEX(Prazos!$B$5:$B$404,MATCH(LARGE(Prazos!$J$5:$J$404,2),Prazos!$J$5:$J$404,0))),""),"") | D11: =IFERROR(IF(LARGE(Prazos!$J$5:$J$404,2)>0,IF(INDEX(Prazos!$C$5:$C$404,MATCH(LARGE(Prazos!$J$5:$J$404,2),Prazos!$J$5:$J$404,0))="","",INDEX(Prazos!$C$5:$C$404,MATCH(LARGE(Prazos!$J$5:$J$404,2),Prazos!$J$5:$J$404,0))),""),"") | E11: =IFERROR(IF(LARGE(Prazos!$J$5:$J$404,2)>0,IF(INDEX(Prazos!$D$5:$D$404,MATCH(LARGE(Prazos!$J$5:$J$404,2),Prazos!$J$5:$J$404,0))="","",INDEX(Prazos!$D$5:$D$404,MATCH(LARGE(Prazos!$J$5:$J$404,2),Prazos!$J$5:$J$404,0))),""),"") | F11: =IFERROR(IF(LARGE(Prazos!$J$5:$J$404,2)>0,IF(INDEX(Prazos!$H$5:$H$404,MATCH(LARGE(Prazos!$J$5:$J$404,2),Prazos!$J$5:$J$404,0))="","",INDEX(Prazos!$H$5:$H$404,MATCH(LARGE(Prazos!$J$5:$J$404,2),Prazos!$J$5:$J$404,0))),""),"") | G11: =IFERROR(IF(LARGE(Prazos!$J$5:$J$404,2)>0,IF(INDEX(Prazos!$I$5:$I$404,MATCH(LARGE(Prazos!$J$5:$J$404,2),Prazos!$J$5:$J$404,0))="","",INDEX(Prazos!$I$5:$I$404,MATCH(LARGE(Prazos!$J$5:$J$404,2),Prazos!$J$5:$J$404,0))),""),"") | H11: =IFERROR(IF(LARGE(Prazos!$J$5:$J$404,2)>0,IF(INDEX(Prazos!$E$5:$E$404,MATCH(LARGE(Prazos!$J$5:$J$404,2),Prazos!$J$5:$J$404,0))="","",INDEX(Prazos!$E$5:$E$404,MATCH(LARGE(Prazos!$J$5:$J$404,2),Prazos!$J$5:$J$404,0))),""),"")
A12: 3 | B12: =IFERROR(IF(LARGE(Prazos!$J$5:$J$404,3)>0,IF(INDEX(Prazos!$A$5:$A$404,MATCH(LARGE(Prazos!$J$5:$J$404,3),Prazos!$J$5:$J$404,0))="","",INDEX(Prazos!$A$5:$A$404,MATCH(LARGE(Prazos!$J$5:$J$404,3),Prazos!$J$5:$J$404,0))),""),"") | C12: =IFERROR(IF(LARGE(Prazos!$J$5:$J$404,3)>0,IF(INDEX(Prazos!$B$5:$B$404,MATCH(LARGE(Prazos!$J$5:$J$404,3),Prazos!$J$5:$J$404,0))="","",INDEX(Prazos!$B$5:$B$404,MATCH(LARGE(Prazos!$J$5:$J$404,3),Prazos!$J$5:$J$404,0))),""),"") | D12: =IFERROR(IF(LARGE(Prazos!$J$5:$J$404,3)>0,IF(INDEX(Prazos!$C$5:$C$404,MATCH(LARGE(Prazos!$J$5:$J$404,3),Prazos!$J$5:$J$404,0))="","",INDEX(Prazos!$C$5:$C$404,MATCH(LARGE(Prazos!$J$5:$J$404,3),Prazos!$J$5:$J$404,0))),""),"") | E12: =IFERROR(IF(LARGE(Prazos!$J$5:$J$404,3)>0,IF(INDEX(Prazos!$D$5:$D$404,MATCH(LARGE(Prazos!$J$5:$J$404,3),Prazos!$J$5:$J$404,0))="","",INDEX(Prazos!$D$5:$D$404,MATCH(LARGE(Prazos!$J$5:$J$404,3),Prazos!$J$5:$J$404,0))),""),"") | F12: =IFERROR(IF(LARGE(Prazos!$J$5:$J$404,3)>0,IF(INDEX(Prazos!$H$5:$H$404,MATCH(LARGE(Prazos!$J$5:$J$404,3),Prazos!$J$5:$J$404,0))="","",INDEX(Prazos!$H$5:$H$404,MATCH(LARGE(Prazos!$J$5:$J$404,3),Prazos!$J$5:$J$404,0))),""),"") | G12: =IFERROR(IF(LARGE(Prazos!$J$5:$J$404,3)>0,IF(INDEX(Prazos!$I$5:$I$404,MATCH(LARGE(Prazos!$J$5:$J$404,3),Prazos!$J$5:$J$404,0))="","",INDEX(Prazos!$I$5:$I$404,MATCH(LARGE(Prazos!$J$5:$J$404,3),Prazos!$J$5:$J$404,0))),""),"") | H12: =IFERROR(IF(LARGE(Prazos!$J$5:$J$404,3)>0,IF(INDEX(Prazos!$E$5:$E$404,MATCH(LARGE(Prazos!$J$5:$J$404,3),Prazos!$J$5:$J$404,0))="","",INDEX(Prazos!$E$5:$E$404,MATCH(LARGE(Prazos!$J$5:$J$404,3),Prazos!$J$5:$J$404,0))),""),"")
A13: 4 | B13: =IFERROR(IF(LARGE(Prazos!$J$5:$J$404,4)>0,IF(INDEX(Prazos!$A$5:$A$404,MATCH(LARGE(Prazos!$J$5:$J$404,4),Prazos!$J$5:$J$404,0))="","",INDEX(Prazos!$A$5:$A$404,MATCH(LARGE(Prazos!$J$5:$J$404,4),Prazos!$J$5:$J$404,0))),""),"") | C13: =IFERROR(IF(LARGE(Prazos!$J$5:$J$404,4)>0,IF(INDEX(Prazos!$B$5:$B$404,MATCH(LARGE(Prazos!$J$5:$J$404,4),Prazos!$J$5:$J$404,0))="","",INDEX(Prazos!$B$5:$B$404,MATCH(LARGE(Prazos!$J$5:$J$404,4),Prazos!$J$5:$J$404,0))),""),"") | D13: =IFERROR(IF(LARGE(Prazos!$J$5:$J$404,4)>0,IF(INDEX(Prazos!$C$5:$C$404,MATCH(LARGE(Prazos!$J$5:$J$404,4),Prazos!$J$5:$J$404,0))="","",INDEX(Prazos!$C$5:$C$404,MATCH(LARGE(Prazos!$J$5:$J$404,4),Prazos!$J$5:$J$404,0))),""),"") | E13: =IFERROR(IF(LARGE(Prazos!$J$5:$J$404,4)>0,IF(INDEX(Prazos!$D$5:$D$404,MATCH(LARGE(Prazos!$J$5:$J$404,4),Prazos!$J$5:$J$404,0))="","",INDEX(Prazos!$D$5:$D$404,MATCH(LARGE(Prazos!$J$5:$J$404,4),Prazos!$J$5:$J$404,0))),""),"") | F13: =IFERROR(IF(LARGE(Prazos!$J$5:$J$404,4)>0,IF(INDEX(Prazos!$H$5:$H$404,MATCH(LARGE(Prazos!$J$5:$J$404,4),Prazos!$J$5:$J$404,0))="","",INDEX(Prazos!$H$5:$H$404,MATCH(LARGE(Prazos!$J$5:$J$404,4),Prazos!$J$5:$J$404,0))),""),"") | G13: =IFERROR(IF(LARGE(Prazos!$J$5:$J$404,4)>0,IF(INDEX(Prazos!$I$5:$I$404,MATCH(LARGE(Prazos!$J$5:$J$404,4),Prazos!$J$5:$J$404,0))="","",INDEX(Prazos!$I$5:$I$404,MATCH(LARGE(Prazos!$J$5:$J$404,4),Prazos!$J$5:$J$404,0))),""),"") | H13: =IFERROR(IF(LARGE(Prazos!$J$5:$J$404,4)>0,IF(INDEX(Prazos!$E$5:$E$404,MATCH(LARGE(Prazos!$J$5:$J$404,4),Prazos!$J$5:$J$404,0))="","",INDEX(Prazos!$E$5:$E$404,MATCH(LARGE(Prazos!$J$5:$J$404,4),Prazos!$J$5:$J$404,0))),""),"")
A14: 5 | B14: =IFERROR(IF(LARGE(Prazos!$J$5:$J$404,5)>0,IF(INDEX(Prazos!$A$5:$A$404,MATCH(LARGE(Prazos!$J$5:$J$404,5),Prazos!$J$5:$J$404,0))="","",INDEX(Prazos!$A$5:$A$404,MATCH(LARGE(Prazos!$J$5:$J$404,5),Prazos!$J$5:$J$404,0))),""),"") | C14: =IFERROR(IF(LARGE(Prazos!$J$5:$J$404,5)>0,IF(INDEX(Prazos!$B$5:$B$404,MATCH(LARGE(Prazos!$J$5:$J$404,5),Prazos!$J$5:$J$404,0))="","",INDEX(Prazos!$B$5:$B$404,MATCH(LARGE(Prazos!$J$5:$J$404,5),Prazos!$J$5:$J$404,0))),""),"") | D14: =IFERROR(IF(LARGE(Prazos!$J$5:$J$404,5)>0,IF(INDEX(Prazos!$C$5:$C$404,MATCH(LARGE(Prazos!$J$5:$J$404,5),Prazos!$J$5:$J$404,0))="","",INDEX(Prazos!$C$5:$C$404,MATCH(LARGE(Prazos!$J$5:$J$404,5),Prazos!$J$5:$J$404,0))),""),"") | E14: =IFERROR(IF(LARGE(Prazos!$J$5:$J$404,5)>0,IF(INDEX(Prazos!$D$5:$D$404,MATCH(LARGE(Prazos!$J$5:$J$404,5),Prazos!$J$5:$J$404,0))="","",INDEX(Prazos!$D$5:$D$404,MATCH(LARGE(Prazos!$J$5:$J$404,5),Prazos!$J$5:$J$404,0))),""),"") | F14: =IFERROR(IF(LARGE(Prazos!$J$5:$J$404,5)>0,IF(INDEX(Prazos!$H$5:$H$404,MATCH(LARGE(Prazos!$J$5:$J$404,5),Prazos!$J$5:$J$404,0))="","",INDEX(Prazos!$H$5:$H$404,MATCH(LARGE(Prazos!$J$5:$J$404,5),Prazos!$J$5:$J$404,0))),""),"") | G14: =IFERROR(IF(LARGE(Prazos!$J$5:$J$404,5)>0,IF(INDEX(Prazos!$I$5:$I$404,MATCH(LARGE(Prazos!$J$5:$J$404,5),Prazos!$J$5:$J$404,0))="","",INDEX(Prazos!$I$5:$I$404,MATCH(LARGE(Prazos!$J$5:$J$404,5),Prazos!$J$5:$J$404,0))),""),"") | H14: =IFERROR(IF(LARGE(Prazos!$J$5:$J$404,5)>0,IF(INDEX(Prazos!$E$5:$E$404,MATCH(LARGE(Prazos!$J$5:$J$404,5),Prazos!$J$5:$J$404,0))="","",INDEX(Prazos!$E$5:$E$404,MATCH(LARGE(Prazos!$J$5:$J$404,5),Prazos!$J$5:$J$404,0))),""),"")
A15: 6 | B15: =IFERROR(IF(LARGE(Prazos!$J$5:$J$404,6)>0,IF(INDEX(Prazos!$A$5:$A$404,MATCH(LARGE(Prazos!$J$5:$J$404,6),Prazos!$J$5:$J$404,0))="","",INDEX(Prazos!$A$5:$A$404,MATCH(LARGE(Prazos!$J$5:$J$404,6),Prazos!$J$5:$J$404,0))),""),"") | C15: =IFERROR(IF(LARGE(Prazos!$J$5:$J$404,6)>0,IF(INDEX(Prazos!$B$5:$B$404,MATCH(LARGE(Prazos!$J$5:$J$404,6),Prazos!$J$5:$J$404,0))="","",INDEX(Prazos!$B$5:$B$404,MATCH(LARGE(Prazos!$J$5:$J$404,6),Prazos!$J$5:$J$404,0))),""),"") | D15: =IFERROR(IF(LARGE(Prazos!$J$5:$J$404,6)>0,IF(INDEX(Prazos!$C$5:$C$404,MATCH(LARGE(Prazos!$J$5:$J$404,6),Prazos!$J$5:$J$404,0))="","",INDEX(Prazos!$C$5:$C$404,MATCH(LARGE(Prazos!$J$5:$J$404,6),Prazos!$J$5:$J$404,0))),""),"") | E15: =IFERROR(IF(LARGE(Prazos!$J$5:$J$404,6)>0,IF(INDEX(Prazos!$D$5:$D$404,MATCH(LARGE(Prazos!$J$5:$J$404,6),Prazos!$J$5:$J$404,0))="","",INDEX(Prazos!$D$5:$D$404,MATCH(LARGE(Prazos!$J$5:$J$404,6),Prazos!$J$5:$J$404,0))),""),"") | F15: =IFERROR(IF(LARGE(Prazos!$J$5:$J$404,6)>0,IF(INDEX(Prazos!$H$5:$H$404,MATCH(LARGE(Prazos!$J$5:$J$404,6),Prazos!$J$5:$J$404,0))="","",INDEX(Prazos!$H$5:$H$404,MATCH(LARGE(Prazos!$J$5:$J$404,6),Prazos!$J$5:$J$404,0))),""),"") | G15: =IFERROR(IF(LARGE(Prazos!$J$5:$J$404,6)>0,IF(INDEX(Prazos!$I$5:$I$404,MATCH(LARGE(Prazos!$J$5:$J$404,6),Prazos!$J$5:$J$404,0))="","",INDEX(Prazos!$I$5:$I$404,MATCH(LARGE(Prazos!$J$5:$J$404,6),Prazos!$J$5:$J$404,0))),""),"") | H15: =IFERROR(IF(LARGE(Prazos!$J$5:$J$404,6)>0,IF(INDEX(Prazos!$E$5:$E$404,MATCH(LARGE(Prazos!$J$5:$J$404,6),Prazos!$J$5:$J$404,0))="","",INDEX(Prazos!$E$5:$E$404,MATCH(LARGE(Prazos!$J$5:$J$404,6),Prazos!$J$5:$J$404,0))),""),"")
A16: 7 | B16: =IFERROR(IF(LARGE(Prazos!$J$5:$J$404,7)>0,IF(INDEX(Prazos!$A$5:$A$404,MATCH(LARGE(Prazos!$J$5:$J$404,7),Prazos!$J$5:$J$404,0))="","",INDEX(Prazos!$A$5:$A$404,MATCH(LARGE(Prazos!$J$5:$J$404,7),Prazos!$J$5:$J$404,0))),""),"") | C16: =IFERROR(IF(LARGE(Prazos!$J$5:$J$404,7)>0,IF(INDEX(Prazos!$B$5:$B$404,MATCH(LARGE(Prazos!$J$5:$J$404,7),Prazos!$J$5:$J$404,0))="","",INDEX(Prazos!$B$5:$B$404,MATCH(LARGE(Prazos!$J$5:$J$404,7),Prazos!$J$5:$J$404,0))),""),"") | D16: =IFERROR(IF(LARGE(Prazos!$J$5:$J$404,7)>0,IF(INDEX(Prazos!$C$5:$C$404,MATCH(LARGE(Prazos!$J$5:$J$404,7),Prazos!$J$5:$J$404,0))="","",INDEX(Prazos!$C$5:$C$404,MATCH(LARGE(Prazos!$J$5:$J$404,7),Prazos!$J$5:$J$404,0))),""),"") | E16: =IFERROR(IF(LARGE(Prazos!$J$5:$J$404,7)>0,IF(INDEX(Prazos!$D$5:$D$404,MATCH(LARGE(Prazos!$J$5:$J$404,7),Prazos!$J$5:$J$404,0))="","",INDEX(Prazos!$D$5:$D$404,MATCH(LARGE(Prazos!$J$5:$J$404,7),Prazos!$J$5:$J$404,0))),""),"") | F16: =IFERROR(IF(LARGE(Prazos!$J$5:$J$404,7)>0,IF(INDEX(Prazos!$H$5:$H$404,MATCH(LARGE(Prazos!$J$5:$J$404,7),Prazos!$J$5:$J$404,0))="","",INDEX(Prazos!$H$5:$H$404,MATCH(LARGE(Prazos!$J$5:$J$404,7),Prazos!$J$5:$J$404,0))),""),"") | G16: =IFERROR(IF(LARGE(Prazos!$J$5:$J$404,7)>0,IF(INDEX(Prazos!$I$5:$I$404,MATCH(LARGE(Prazos!$J$5:$J$404,7),Prazos!$J$5:$J$404,0))="","",INDEX(Prazos!$I$5:$I$404,MATCH(LARGE(Prazos!$J$5:$J$404,7),Prazos!$J$5:$J$404,0))),""),"") | H16: =IFERROR(IF(LARGE(Prazos!$J$5:$J$404,7)>0,IF(INDEX(Prazos!$E$5:$E$404,MATCH(LARGE(Prazos!$J$5:$J$404,7),Prazos!$J$5:$J$404,0))="","",INDEX(Prazos!$E$5:$E$404,MATCH(LARGE(Prazos!$J$5:$J$404,7),Prazos!$J$5:$J$404,0))),""),"")
A17: 8 | B17: =IFERROR(IF(LARGE(Prazos!$J$5:$J$404,8)>0,IF(INDEX(Prazos!$A$5:$A$404,MATCH(LARGE(Prazos!$J$5:$J$404,8),Prazos!$J$5:$J$404,0))="","",INDEX(Prazos!$A$5:$A$404,MATCH(LARGE(Prazos!$J$5:$J$404,8),Prazos!$J$5:$J$404,0))),""),"") | C17: =IFERROR(IF(LARGE(Prazos!$J$5:$J$404,8)>0,IF(INDEX(Prazos!$B$5:$B$404,MATCH(LARGE(Prazos!$J$5:$J$404,8),Prazos!$J$5:$J$404,0))="","",INDEX(Prazos!$B$5:$B$404,MATCH(LARGE(Prazos!$J$5:$J$404,8),Prazos!$J$5:$J$404,0))),""),"") | D17: =IFERROR(IF(LARGE(Prazos!$J$5:$J$404,8)>0,IF(INDEX(Prazos!$C$5:$C$404,MATCH(LARGE(Prazos!$J$5:$J$404,8),Prazos!$J$5:$J$404,0))="","",INDEX(Prazos!$C$5:$C$404,MATCH(LARGE(Prazos!$J$5:$J$404,8),Prazos!$J$5:$J$404,0))),""),"") | E17: =IFERROR(IF(LARGE(Prazos!$J$5:$J$404,8)>0,IF(INDEX(Prazos!$D$5:$D$404,MATCH(LARGE(Prazos!$J$5:$J$404,8),Prazos!$J$5:$J$404,0))="","",INDEX(Prazos!$D$5:$D$404,MATCH(LARGE(Prazos!$J$5:$J$404,8),Prazos!$J$5:$J$404,0))),""),"") | F17: =IFERROR(IF(LARGE(Prazos!$J$5:$J$404,8)>0,IF(INDEX(Prazos!$H$5:$H$404,MATCH(LARGE(Prazos!$J$5:$J$404,8),Prazos!$J$5:$J$404,0))="","",INDEX(Prazos!$H$5:$H$404,MATCH(LARGE(Prazos!$J$5:$J$404,8),Prazos!$J$5:$J$404,0))),""),"") | G17: =IFERROR(IF(LARGE(Prazos!$J$5:$J$404,8)>0,IF(INDEX(Prazos!$I$5:$I$404,MATCH(LARGE(Prazos!$J$5:$J$404,8),Prazos!$J$5:$J$404,0))="","",INDEX(Prazos!$I$5:$I$404,MATCH(LARGE(Prazos!$J$5:$J$404,8),Prazos!$J$5:$J$404,0))),""),"") | H17: =IFERROR(IF(LARGE(Prazos!$J$5:$J$404,8)>0,IF(INDEX(Prazos!$E$5:$E$404,MATCH(LARGE(Prazos!$J$5:$J$404,8),Prazos!$J$5:$J$404,0))="","",INDEX(Prazos!$E$5:$E$404,MATCH(LARGE(Prazos!$J$5:$J$404,8),Prazos!$J$5:$J$404,0))),""),"")
A18: 9 | B18: =IFERROR(IF(LARGE(Prazos!$J$5:$J$404,9)>0,IF(INDEX(Prazos!$A$5:$A$404,MATCH(LARGE(Prazos!$J$5:$J$404,9),Prazos!$J$5:$J$404,0))="","",INDEX(Prazos!$A$5:$A$404,MATCH(LARGE(Prazos!$J$5:$J$404,9),Prazos!$J$5:$J$404,0))),""),"") | C18: =IFERROR(IF(LARGE(Prazos!$J$5:$J$404,9)>0,IF(INDEX(Prazos!$B$5:$B$404,MATCH(LARGE(Prazos!$J$5:$J$404,9),Prazos!$J$5:$J$404,0))="","",INDEX(Prazos!$B$5:$B$404,MATCH(LARGE(Prazos!$J$5:$J$404,9),Prazos!$J$5:$J$404,0))),""),"") | D18: =IFERROR(IF(LARGE(Prazos!$J$5:$J$404,9)>0,IF(INDEX(Prazos!$C$5:$C$404,MATCH(LARGE(Prazos!$J$5:$J$404,9),Prazos!$J$5:$J$404,0))="","",INDEX(Prazos!$C$5:$C$404,MATCH(LARGE(Prazos!$J$5:$J$404,9),Prazos!$J$5:$J$404,0))),""),"") | E18: =IFERROR(IF(LARGE(Prazos!$J$5:$J$404,9)>0,IF(INDEX(Prazos!$D$5:$D$404,MATCH(LARGE(Prazos!$J$5:$J$404,9),Prazos!$J$5:$J$404,0))="","",INDEX(Prazos!$D$5:$D$404,MATCH(LARGE(Prazos!$J$5:$J$404,9),Prazos!$J$5:$J$404,0))),""),"") | F18: =IFERROR(IF(LARGE(Prazos!$J$5:$J$404,9)>0,IF(INDEX(Prazos!$H$5:$H$404,MATCH(LARGE(Prazos!$J$5:$J$404,9),Prazos!$J$5:$J$404,0))="","",INDEX(Prazos!$H$5:$H$404,MATCH(LARGE(Prazos!$J$5:$J$404,9),Prazos!$J$5:$J$404,0))),""),"") | G18: =IFERROR(IF(LARGE(Prazos!$J$5:$J$404,9)>0,IF(INDEX(Prazos!$I$5:$I$404,MATCH(LARGE(Prazos!$J$5:$J$404,9),Prazos!$J$5:$J$404,0))="","",INDEX(Prazos!$I$5:$I$404,MATCH(LARGE(Prazos!$J$5:$J$404,9),Prazos!$J$5:$J$404,0))),""),"") | H18: =IFERROR(IF(LARGE(Prazos!$J$5:$J$404,9)>0,IF(INDEX(Prazos!$E$5:$E$404,MATCH(LARGE(Prazos!$J$5:$J$404,9),Prazos!$J$5:$J$404,0))="","",INDEX(Prazos!$E$5:$E$404,MATCH(LARGE(Prazos!$J$5:$J$404,9),Prazos!$J$5:$J$404,0))),""),"")
A19: 10 | B19: =IFERROR(IF(LARGE(Prazos!$J$5:$J$404,10)>0,IF(INDEX(Prazos!$A$5:$A$404,MATCH(LARGE(Prazos!$J$5:$J$404,10),Prazos!$J$5:$J$404,0))="","",INDEX(Prazos!$A$5:$A$404,MATCH(LARGE(Prazos!$J$5:$J$404,10),Prazos!$J$5:$J$404,0))),""),"") | C19: =IFERROR(IF(LARGE(Prazos!$J$5:$J$404,10)>0,IF(INDEX(Prazos!$B$5:$B$404,MATCH(LARGE(Prazos!$J$5:$J$404,10),Prazos!$J$5:$J$404,0))="","",INDEX(Prazos!$B$5:$B$404,MATCH(LARGE(Prazos!$J$5:$J$404,10),Prazos!$J$5:$J$404,0))),""),"") | D19: =IFERROR(IF(LARGE(Prazos!$J$5:$J$404,10)>0,IF(INDEX(Prazos!$C$5:$C$404,MATCH(LARGE(Prazos!$J$5:$J$404,10),Prazos!$J$5:$J$404,0))="","",INDEX(Prazos!$C$5:$C$404,MATCH(LARGE(Prazos!$J$5:$J$404,10),Prazos!$J$5:$J$404,0))),""),"") | E19: =IFERROR(IF(LARGE(Prazos!$J$5:$J$404,10)>0,IF(INDEX(Prazos!$D$5:$D$404,MATCH(LARGE(Prazos!$J$5:$J$404,10),Prazos!$J$5:$J$404,0))="","",INDEX(Prazos!$D$5:$D$404,MATCH(LARGE(Prazos!$J$5:$J$404,10),Prazos!$J$5:$J$404,0))),""),"") | F19: =IFERROR(IF(LARGE(Prazos!$J$5:$J$404,10)>0,IF(INDEX(Prazos!$H$5:$H$404,MATCH(LARGE(Prazos!$J$5:$J$404,10),Prazos!$J$5:$J$404,0))="","",INDEX(Prazos!$H$5:$H$404,MATCH(LARGE(Prazos!$J$5:$J$404,10),Prazos!$J$5:$J$404,0))),""),"") | G19: =IFERROR(IF(LARGE(Prazos!$J$5:$J$404,10)>0,IF(INDEX(Prazos!$I$5:$I$404,MATCH(LARGE(Prazos!$J$5:$J$404,10),Prazos!$J$5:$J$404,0))="","",INDEX(Prazos!$I$5:$I$404,MATCH(LARGE(Prazos!$J$5:$J$404,10),Prazos!$J$5:$J$404,0))),""),"") | H19: =IFERROR(IF(LARGE(Prazos!$J$5:$J$404,10)>0,IF(INDEX(Prazos!$E$5:$E$404,MATCH(LARGE(Prazos!$J$5:$J$404,10),Prazos!$J$5:$J$404,0))="","",INDEX(Prazos!$E$5:$E$404,MATCH(LARGE(Prazos!$J$5:$J$404,10),Prazos!$J$5:$J$404,0))),""),"")
A20: 11 | B20: =IFERROR(IF(LARGE(Prazos!$J$5:$J$404,11)>0,IF(INDEX(Prazos!$A$5:$A$404,MATCH(LARGE(Prazos!$J$5:$J$404,11),Prazos!$J$5:$J$404,0))="","",INDEX(Prazos!$A$5:$A$404,MATCH(LARGE(Prazos!$J$5:$J$404,11),Prazos!$J$5:$J$404,0))),""),"") | C20: =IFERROR(IF(LARGE(Prazos!$J$5:$J$404,11)>0,IF(INDEX(Prazos!$B$5:$B$404,MATCH(LARGE(Prazos!$J$5:$J$404,11),Prazos!$J$5:$J$404,0))="","",INDEX(Prazos!$B$5:$B$404,MATCH(LARGE(Prazos!$J$5:$J$404,11),Prazos!$J$5:$J$404,0))),""),"") | D20: =IFERROR(IF(LARGE(Prazos!$J$5:$J$404,11)>0,IF(INDEX(Prazos!$C$5:$C$404,MATCH(LARGE(Prazos!$J$5:$J$404,11),Prazos!$J$5:$J$404,0))="","",INDEX(Prazos!$C$5:$C$404,MATCH(LARGE(Prazos!$J$5:$J$404,11),Prazos!$J$5:$J$404,0))),""),"") | E20: =IFERROR(IF(LARGE(Prazos!$J$5:$J$404,11)>0,IF(INDEX(Prazos!$D$5:$D$404,MATCH(LARGE(Prazos!$J$5:$J$404,11),Prazos!$J$5:$J$404,0))="","",INDEX(Prazos!$D$5:$D$404,MATCH(LARGE(Prazos!$J$5:$J$404,11),Prazos!$J$5:$J$404,0))),""),"") | F20: =IFERROR(IF(LARGE(Prazos!$J$5:$J$404,11)>0,IF(INDEX(Prazos!$H$5:$H$404,MATCH(LARGE(Prazos!$J$5:$J$404,11),Prazos!$J$5:$J$404,0))="","",INDEX(Prazos!$H$5:$H$404,MATCH(LARGE(Prazos!$J$5:$J$404,11),Prazos!$J$5:$J$404,0))),""),"") | G20: =IFERROR(IF(LARGE(Prazos!$J$5:$J$404,11)>0,IF(INDEX(Prazos!$I$5:$I$404,MATCH(LARGE(Prazos!$J$5:$J$404,11),Prazos!$J$5:$J$404,0))="","",INDEX(Prazos!$I$5:$I$404,MATCH(LARGE(Prazos!$J$5:$J$404,11),Prazos!$J$5:$J$404,0))),""),"") | H20: =IFERROR(IF(LARGE(Prazos!$J$5:$J$404,11)>0,IF(INDEX(Prazos!$E$5:$E$404,MATCH(LARGE(Prazos!$J$5:$J$404,11),Prazos!$J$5:$J$404,0))="","",INDEX(Prazos!$E$5:$E$404,MATCH(LARGE(Prazos!$J$5:$J$404,11),Prazos!$J$5:$J$404,0))),""),"")
A21: 12 | B21: =IFERROR(IF(LARGE(Prazos!$J$5:$J$404,12)>0,IF(INDEX(Prazos!$A$5:$A$404,MATCH(LARGE(Prazos!$J$5:$J$404,12),Prazos!$J$5:$J$404,0))="","",INDEX(Prazos!$A$5:$A$404,MATCH(LARGE(Prazos!$J$5:$J$404,12),Prazos!$J$5:$J$404,0))),""),"") | C21: =IFERROR(IF(LARGE(Prazos!$J$5:$J$404,12)>0,IF(INDEX(Prazos!$B$5:$B$404,MATCH(LARGE(Prazos!$J$5:$J$404,12),Prazos!$J$5:$J$404,0))="","",INDEX(Prazos!$B$5:$B$404,MATCH(LARGE(Prazos!$J$5:$J$404,12),Prazos!$J$5:$J$404,0))),""),"") | D21: =IFERROR(IF(LARGE(Prazos!$J$5:$J$404,12)>0,IF(INDEX(Prazos!$C$5:$C$404,MATCH(LARGE(Prazos!$J$5:$J$404,12),Prazos!$J$5:$J$404,0))="","",INDEX(Prazos!$C$5:$C$404,MATCH(LARGE(Prazos!$J$5:$J$404,12),Prazos!$J$5:$J$404,0))),""),"") | E21: =IFERROR(IF(LARGE(Prazos!$J$5:$J$404,12)>0,IF(INDEX(Prazos!$D$5:$D$404,MATCH(LARGE(Prazos!$J$5:$J$404,12),Prazos!$J$5:$J$404,0))="","",INDEX(Prazos!$D$5:$D$404,MATCH(LARGE(Prazos!$J$5:$J$404,12),Prazos!$J$5:$J$404,0))),""),"") | F21: =IFERROR(IF(LARGE(Prazos!$J$5:$J$404,12)>0,IF(INDEX(Prazos!$H$5:$H$404,MATCH(LARGE(Prazos!$J$5:$J$404,12),Prazos!$J$5:$J$404,0))="","",INDEX(Prazos!$H$5:$H$404,MATCH(LARGE(Prazos!$J$5:$J$404,12),Prazos!$J$5:$J$404,0))),""),"") | G21: =IFERROR(IF(LARGE(Prazos!$J$5:$J$404,12)>0,IF(INDEX(Prazos!$I$5:$I$404,MATCH(LARGE(Prazos!$J$5:$J$404,12),Prazos!$J$5:$J$404,0))="","",INDEX(Prazos!$I$5:$I$404,MATCH(LARGE(Prazos!$J$5:$J$404,12),Prazos!$J$5:$J$404,0))),""),"") | H21: =IFERROR(IF(LARGE(Prazos!$J$5:$J$404,12)>0,IF(INDEX(Prazos!$E$5:$E$404,MATCH(LARGE(Prazos!$J$5:$J$404,12),Prazos!$J$5:$J$404,0))="","",INDEX(Prazos!$E$5:$E$404,MATCH(LARGE(Prazos!$J$5:$J$404,12),Prazos!$J$5:$J$404,0))),""),"")
A22: 13 | B22: =IFERROR(IF(LARGE(Prazos!$J$5:$J$404,13)>0,IF(INDEX(Prazos!$A$5:$A$404,MATCH(LARGE(Prazos!$J$5:$J$404,13),Prazos!$J$5:$J$404,0))="","",INDEX(Prazos!$A$5:$A$404,MATCH(LARGE(Prazos!$J$5:$J$404,13),Prazos!$J$5:$J$404,0))),""),"") | C22: =IFERROR(IF(LARGE(Prazos!$J$5:$J$404,13)>0,IF(INDEX(Prazos!$B$5:$B$404,MATCH(LARGE(Prazos!$J$5:$J$404,13),Prazos!$J$5:$J$404,0))="","",INDEX(Prazos!$B$5:$B$404,MATCH(LARGE(Prazos!$J$5:$J$404,13),Prazos!$J$5:$J$404,0))),""),"") | D22: =IFERROR(IF(LARGE(Prazos!$J$5:$J$404,13)>0,IF(INDEX(Prazos!$C$5:$C$404,MATCH(LARGE(Prazos!$J$5:$J$404,13),Prazos!$J$5:$J$404,0))="","",INDEX(Prazos!$C$5:$C$404,MATCH(LARGE(Prazos!$J$5:$J$404,13),Prazos!$J$5:$J$404,0))),""),"") | E22: =IFERROR(IF(LARGE(Prazos!$J$5:$J$404,13)>0,IF(INDEX(Prazos!$D$5:$D$404,MATCH(LARGE(Prazos!$J$5:$J$404,13),Prazos!$J$5:$J$404,0))="","",INDEX(Prazos!$D$5:$D$404,MATCH(LARGE(Prazos!$J$5:$J$404,13),Prazos!$J$5:$J$404,0))),""),"") | F22: =IFERROR(IF(LARGE(Prazos!$J$5:$J$404,13)>0,IF(INDEX(Prazos!$H$5:$H$404,MATCH(LARGE(Prazos!$J$5:$J$404,13),Prazos!$J$5:$J$404,0))="","",INDEX(Prazos!$H$5:$H$404,MATCH(LARGE(Prazos!$J$5:$J$404,13),Prazos!$J$5:$J$404,0))),""),"") | G22: =IFERROR(IF(LARGE(Prazos!$J$5:$J$404,13)>0,IF(INDEX(Prazos!$I$5:$I$404,MATCH(LARGE(Prazos!$J$5:$J$404,13),Prazos!$J$5:$J$404,0))="","",INDEX(Prazos!$I$5:$I$404,MATCH(LARGE(Prazos!$J$5:$J$404,13),Prazos!$J$5:$J$404,0))),""),"") | H22: =IFERROR(IF(LARGE(Prazos!$J$5:$J$404,13)>0,IF(INDEX(Prazos!$E$5:$E$404,MATCH(LARGE(Prazos!$J$5:$J$404,13),Prazos!$J$5:$J$404,0))="","",INDEX(Prazos!$E$5:$E$404,MATCH(LARGE(Prazos!$J$5:$J$404,13),Prazos!$J$5:$J$404,0))),""),"")
A23: 14 | B23: =IFERROR(IF(LARGE(Prazos!$J$5:$J$404,14)>0,IF(INDEX(Prazos!$A$5:$A$404,MATCH(LARGE(Prazos!$J$5:$J$404,14),Prazos!$J$5:$J$404,0))="","",INDEX(Prazos!$A$5:$A$404,MATCH(LARGE(Prazos!$J$5:$J$404,14),Prazos!$J$5:$J$404,0))),""),"") | C23: =IFERROR(IF(LARGE(Prazos!$J$5:$J$404,14)>0,IF(INDEX(Prazos!$B$5:$B$404,MATCH(LARGE(Prazos!$J$5:$J$404,14),Prazos!$J$5:$J$404,0))="","",INDEX(Prazos!$B$5:$B$404,MATCH(LARGE(Prazos!$J$5:$J$404,14),Prazos!$J$5:$J$404,0))),""),"") | D23: =IFERROR(IF(LARGE(Prazos!$J$5:$J$404,14)>0,IF(INDEX(Prazos!$C$5:$C$404,MATCH(LARGE(Prazos!$J$5:$J$404,14),Prazos!$J$5:$J$404,0))="","",INDEX(Prazos!$C$5:$C$404,MATCH(LARGE(Prazos!$J$5:$J$404,14),Prazos!$J$5:$J$404,0))),""),"") | E23: =IFERROR(IF(LARGE(Prazos!$J$5:$J$404,14)>0,IF(INDEX(Prazos!$D$5:$D$404,MATCH(LARGE(Prazos!$J$5:$J$404,14),Prazos!$J$5:$J$404,0))="","",INDEX(Prazos!$D$5:$D$404,MATCH(LARGE(Prazos!$J$5:$J$404,14),Prazos!$J$5:$J$404,0))),""),"") | F23: =IFERROR(IF(LARGE(Prazos!$J$5:$J$404,14)>0,IF(INDEX(Prazos!$H$5:$H$404,MATCH(LARGE(Prazos!$J$5:$J$404,14),Prazos!$J$5:$J$404,0))="","",INDEX(Prazos!$H$5:$H$404,MATCH(LARGE(Prazos!$J$5:$J$404,14),Prazos!$J$5:$J$404,0))),""),"") | G23: =IFERROR(IF(LARGE(Prazos!$J$5:$J$404,14)>0,IF(INDEX(Prazos!$I$5:$I$404,MATCH(LARGE(Prazos!$J$5:$J$404,14),Prazos!$J$5:$J$404,0))="","",INDEX(Prazos!$I$5:$I$404,MATCH(LARGE(Prazos!$J$5:$J$404,14),Prazos!$J$5:$J$404,0))),""),"") | H23: =IFERROR(IF(LARGE(Prazos!$J$5:$J$404,14)>0,IF(INDEX(Prazos!$E$5:$E$404,MATCH(LARGE(Prazos!$J$5:$J$404,14),Prazos!$J$5:$J$404,0))="","",INDEX(Prazos!$E$5:$E$404,MATCH(LARGE(Prazos!$J$5:$J$404,14),Prazos!$J$5:$J$404,0))),""),"")
A24: 15 | B24: =IFERROR(IF(LARGE(Prazos!$J$5:$J$404,15)>0,IF(INDEX(Prazos!$A$5:$A$404,MATCH(LARGE(Prazos!$J$5:$J$404,15),Prazos!$J$5:$J$404,0))="","",INDEX(Prazos!$A$5:$A$404,MATCH(LARGE(Prazos!$J$5:$J$404,15),Prazos!$J$5:$J$404,0))),""),"") | C24: =IFERROR(IF(LARGE(Prazos!$J$5:$J$404,15)>0,IF(INDEX(Prazos!$B$5:$B$404,MATCH(LARGE(Prazos!$J$5:$J$404,15),Prazos!$J$5:$J$404,0))="","",INDEX(Prazos!$B$5:$B$404,MATCH(LARGE(Prazos!$J$5:$J$404,15),Prazos!$J$5:$J$404,0))),""),"") | D24: =IFERROR(IF(LARGE(Prazos!$J$5:$J$404,15)>0,IF(INDEX(Prazos!$C$5:$C$404,MATCH(LARGE(Prazos!$J$5:$J$404,15),Prazos!$J$5:$J$404,0))="","",INDEX(Prazos!$C$5:$C$404,MATCH(LARGE(Prazos!$J$5:$J$404,15),Prazos!$J$5:$J$404,0))),""),"") | E24: =IFERROR(IF(LARGE(Prazos!$J$5:$J$404,15)>0,IF(INDEX(Prazos!$D$5:$D$404,MATCH(LARGE(Prazos!$J$5:$J$404,15),Prazos!$J$5:$J$404,0))="","",INDEX(Prazos!$D$5:$D$404,MATCH(LARGE(Prazos!$J$5:$J$404,15),Prazos!$J$5:$J$404,0))),""),"") | F24: =IFERROR(IF(LARGE(Prazos!$J$5:$J$404,15)>0,IF(INDEX(Prazos!$H$5:$H$404,MATCH(LARGE(Prazos!$J$5:$J$404,15),Prazos!$J$5:$J$404,0))="","",INDEX(Prazos!$H$5:$H$404,MATCH(LARGE(Prazos!$J$5:$J$404,15),Prazos!$J$5:$J$404,0))),""),"") | G24: =IFERROR(IF(LARGE(Prazos!$J$5:$J$404,15)>0,IF(INDEX(Prazos!$I$5:$I$404,MATCH(LARGE(Prazos!$J$5:$J$404,15),Prazos!$J$5:$J$404,0))="","",INDEX(Prazos!$I$5:$I$404,MATCH(LARGE(Prazos!$J$5:$J$404,15),Prazos!$J$5:$J$404,0))),""),"") | H24: =IFERROR(IF(LARGE(Prazos!$J$5:$J$404,15)>0,IF(INDEX(Prazos!$E$5:$E$404,MATCH(LARGE(Prazos!$J$5:$J$404,15),Prazos!$J$5:$J$404,0))="","",INDEX(Prazos!$E$5:$E$404,MATCH(LARGE(Prazos!$J$5:$J$404,15),Prazos!$J$5:$J$404,0))),""),"")
A26: Carga por responsável
A27: Responsável | C27: Abertos | D27: Atrasados | E27: Hoje | F27: Em alerta | G27: Mais antigo em aberto | H27: Feitos
A28: =IF(Config!$B$10="","",Config!$B$10) | C28: =IF(Config!$B$10="","",COUNTIFS(Prazos!$E$5:$E$404,Config!$B$10,Prazos!$J$5:$J$404,">0")+COUNTIFS(Prazos!$E$5:$E$404,Config!$B$10,Prazos!$I$5:$I$404,"Sem data")) | D28: =IF(Config!$B$10="","",COUNTIFS(Prazos!$E$5:$E$404,Config!$B$10,Prazos!$I$5:$I$404,"Atrasado")) | E28: =IF(Config!$B$10="","",COUNTIFS(Prazos!$E$5:$E$404,Config!$B$10,Prazos!$I$5:$I$404,"Hoje")) | F28: =IF(Config!$B$10="","",COUNTIFS(Prazos!$E$5:$E$404,Config!$B$10,Prazos!$I$5:$I$404,"Até "&Config!$B$6&" dias")) | G28: =IF(Config!$B$10="","",IFERROR(IF(_xlfn.MINIFS(Prazos!$D$5:$D$404,Prazos!$E$5:$E$404,Config!$B$10,Prazos!$J$5:$J$404,">0")=0,"",_xlfn.MINIFS(Prazos!$D$5:$D$404,Prazos!$E$5:$E$404,Config!$B$10,Prazos!$J$5:$J$404,">0")),"")) | H28: =IF(Config!$B$10="","",COUNTIFS(Prazos!$E$5:$E$404,Config!$B$10,Prazos!$I$5:$I$404,"Feito"))
A29: =IF(Config!$B$11="","",Config!$B$11) | C29: =IF(Config!$B$11="","",COUNTIFS(Prazos!$E$5:$E$404,Config!$B$11,Prazos!$J$5:$J$404,">0")+COUNTIFS(Prazos!$E$5:$E$404,Config!$B$11,Prazos!$I$5:$I$404,"Sem data")) | D29: =IF(Config!$B$11="","",COUNTIFS(Prazos!$E$5:$E$404,Config!$B$11,Prazos!$I$5:$I$404,"Atrasado")) | E29: =IF(Config!$B$11="","",COUNTIFS(Prazos!$E$5:$E$404,Config!$B$11,Prazos!$I$5:$I$404,"Hoje")) | F29: =IF(Config!$B$11="","",COUNTIFS(Prazos!$E$5:$E$404,Config!$B$11,Prazos!$I$5:$I$404,"Até "&Config!$B$6&" dias")) | G29: =IF(Config!$B$11="","",IFERROR(IF(_xlfn.MINIFS(Prazos!$D$5:$D$404,Prazos!$E$5:$E$404,Config!$B$11,Prazos!$J$5:$J$404,">0")=0,"",_xlfn.MINIFS(Prazos!$D$5:$D$404,Prazos!$E$5:$E$404,Config!$B$11,Prazos!$J$5:$J$404,">0")),"")) | H29: =IF(Config!$B$11="","",COUNTIFS(Prazos!$E$5:$E$404,Config!$B$11,Prazos!$I$5:$I$404,"Feito"))
A30: =IF(Config!$B$12="","",Config!$B$12) | C30: =IF(Config!$B$12="","",COUNTIFS(Prazos!$E$5:$E$404,Config!$B$12,Prazos!$J$5:$J$404,">0")+COUNTIFS(Prazos!$E$5:$E$404,Config!$B$12,Prazos!$I$5:$I$404,"Sem data")) | D30: =IF(Config!$B$12="","",COUNTIFS(Prazos!$E$5:$E$404,Config!$B$12,Prazos!$I$5:$I$404,"Atrasado")) | E30: =IF(Config!$B$12="","",COUNTIFS(Prazos!$E$5:$E$404,Config!$B$12,Prazos!$I$5:$I$404,"Hoje")) | F30: =IF(Config!$B$12="","",COUNTIFS(Prazos!$E$5:$E$404,Config!$B$12,Prazos!$I$5:$I$404,"Até "&Config!$B$6&" dias")) | G30: =IF(Config!$B$12="","",IFERROR(IF(_xlfn.MINIFS(Prazos!$D$5:$D$404,Prazos!$E$5:$E$404,Config!$B$12,Prazos!$J$5:$J$404,">0")=0,"",_xlfn.MINIFS(Prazos!$D$5:$D$404,Prazos!$E$5:$E$404,Config!$B$12,Prazos!$J$5:$J$404,">0")),"")) | H30: =IF(Config!$B$12="","",COUNTIFS(Prazos!$E$5:$E$404,Config!$B$12,Prazos!$I$5:$I$404,"Feito"))
A31: =IF(Config!$B$13="","",Config!$B$13) | C31: =IF(Config!$B$13="","",COUNTIFS(Prazos!$E$5:$E$404,Config!$B$13,Prazos!$J$5:$J$404,">0")+COUNTIFS(Prazos!$E$5:$E$404,Config!$B$13,Prazos!$I$5:$I$404,"Sem data")) | D31: =IF(Config!$B$13="","",COUNTIFS(Prazos!$E$5:$E$404,Config!$B$13,Prazos!$I$5:$I$404,"Atrasado")) | E31: =IF(Config!$B$13="","",COUNTIFS(Prazos!$E$5:$E$404,Config!$B$13,Prazos!$I$5:$I$404,"Hoje")) | F31: =IF(Config!$B$13="","",COUNTIFS(Prazos!$E$5:$E$404,Config!$B$13,Prazos!$I$5:$I$404,"Até "&Config!$B$6&" dias")) | G31: =IF(Config!$B$13="","",IFERROR(IF(_xlfn.MINIFS(Prazos!$D$5:$D$404,Prazos!$E$5:$E$404,Config!$B$13,Prazos!$J$5:$J$404,">0")=0,"",_xlfn.MINIFS(Prazos!$D$5:$D$404,Prazos!$E$5:$E$404,Config!$B$13,Prazos!$J$5:$J$404,">0")),"")) | H31: =IF(Config!$B$13="","",COUNTIFS(Prazos!$E$5:$E$404,Config!$B$13,Prazos!$I$5:$I$404,"Feito"))
A32: =IF(Config!$B$14="","",Config!$B$14) | C32: =IF(Config!$B$14="","",COUNTIFS(Prazos!$E$5:$E$404,Config!$B$14,Prazos!$J$5:$J$404,">0")+COUNTIFS(Prazos!$E$5:$E$404,Config!$B$14,Prazos!$I$5:$I$404,"Sem data")) | D32: =IF(Config!$B$14="","",COUNTIFS(Prazos!$E$5:$E$404,Config!$B$14,Prazos!$I$5:$I$404,"Atrasado")) | E32: =IF(Config!$B$14="","",COUNTIFS(Prazos!$E$5:$E$404,Config!$B$14,Prazos!$I$5:$I$404,"Hoje")) | F32: =IF(Config!$B$14="","",COUNTIFS(Prazos!$E$5:$E$404,Config!$B$14,Prazos!$I$5:$I$404,"Até "&Config!$B$6&" dias")) | G32: =IF(Config!$B$14="","",IFERROR(IF(_xlfn.MINIFS(Prazos!$D$5:$D$404,Prazos!$E$5:$E$404,Config!$B$14,Prazos!$J$5:$J$404,">0")=0,"",_xlfn.MINIFS(Prazos!$D$5:$D$404,Prazos!$E$5:$E$404,Config!$B$14,Prazos!$J$5:$J$404,">0")),"")) | H32: =IF(Config!$B$14="","",COUNTIFS(Prazos!$E$5:$E$404,Config!$B$14,Prazos!$I$5:$I$404,"Feito"))
A33: =IF(Config!$B$15="","",Config!$B$15) | C33: =IF(Config!$B$15="","",COUNTIFS(Prazos!$E$5:$E$404,Config!$B$15,Prazos!$J$5:$J$404,">0")+COUNTIFS(Prazos!$E$5:$E$404,Config!$B$15,Prazos!$I$5:$I$404,"Sem data")) | D33: =IF(Config!$B$15="","",COUNTIFS(Prazos!$E$5:$E$404,Config!$B$15,Prazos!$I$5:$I$404,"Atrasado")) | E33: =IF(Config!$B$15="","",COUNTIFS(Prazos!$E$5:$E$404,Config!$B$15,Prazos!$I$5:$I$404,"Hoje")) | F33: =IF(Config!$B$15="","",COUNTIFS(Prazos!$E$5:$E$404,Config!$B$15,Prazos!$I$5:$I$404,"Até "&Config!$B$6&" dias")) | G33: =IF(Config!$B$15="","",IFERROR(IF(_xlfn.MINIFS(Prazos!$D$5:$D$404,Prazos!$E$5:$E$404,Config!$B$15,Prazos!$J$5:$J$404,">0")=0,"",_xlfn.MINIFS(Prazos!$D$5:$D$404,Prazos!$E$5:$E$404,Config!$B$15,Prazos!$J$5:$J$404,">0")),"")) | H33: =IF(Config!$B$15="","",COUNTIFS(Prazos!$E$5:$E$404,Config!$B$15,Prazos!$I$5:$I$404,"Feito"))
A34: =IF(Config!$B$16="","",Config!$B$16) | C34: =IF(Config!$B$16="","",COUNTIFS(Prazos!$E$5:$E$404,Config!$B$16,Prazos!$J$5:$J$404,">0")+COUNTIFS(Prazos!$E$5:$E$404,Config!$B$16,Prazos!$I$5:$I$404,"Sem data")) | D34: =IF(Config!$B$16="","",COUNTIFS(Prazos!$E$5:$E$404,Config!$B$16,Prazos!$I$5:$I$404,"Atrasado")) | E34: =IF(Config!$B$16="","",COUNTIFS(Prazos!$E$5:$E$404,Config!$B$16,Prazos!$I$5:$I$404,"Hoje")) | F34: =IF(Config!$B$16="","",COUNTIFS(Prazos!$E$5:$E$404,Config!$B$16,Prazos!$I$5:$I$404,"Até "&Config!$B$6&" dias")) | G34: =IF(Config!$B$16="","",IFERROR(IF(_xlfn.MINIFS(Prazos!$D$5:$D$404,Prazos!$E$5:$E$404,Config!$B$16,Prazos!$J$5:$J$404,">0")=0,"",_xlfn.MINIFS(Prazos!$D$5:$D$404,Prazos!$E$5:$E$404,Config!$B$16,Prazos!$J$5:$J$404,">0")),"")) | H34: =IF(Config!$B$16="","",COUNTIFS(Prazos!$E$5:$E$404,Config!$B$16,Prazos!$I$5:$I$404,"Feito"))
A35: =IF(Config!$B$17="","",Config!$B$17) | C35: =IF(Config!$B$17="","",COUNTIFS(Prazos!$E$5:$E$404,Config!$B$17,Prazos!$J$5:$J$404,">0")+COUNTIFS(Prazos!$E$5:$E$404,Config!$B$17,Prazos!$I$5:$I$404,"Sem data")) | D35: =IF(Config!$B$17="","",COUNTIFS(Prazos!$E$5:$E$404,Config!$B$17,Prazos!$I$5:$I$404,"Atrasado")) | E35: =IF(Config!$B$17="","",COUNTIFS(Prazos!$E$5:$E$404,Config!$B$17,Prazos!$I$5:$I$404,"Hoje")) | F35: =IF(Config!$B$17="","",COUNTIFS(Prazos!$E$5:$E$404,Config!$B$17,Prazos!$I$5:$I$404,"Até "&Config!$B$6&" dias")) | G35: =IF(Config!$B$17="","",IFERROR(IF(_xlfn.MINIFS(Prazos!$D$5:$D$404,Prazos!$E$5:$E$404,Config!$B$17,Prazos!$J$5:$J$404,">0")=0,"",_xlfn.MINIFS(Prazos!$D$5:$D$404,Prazos!$E$5:$E$404,Config!$B$17,Prazos!$J$5:$J$404,">0")),"")) | H35: =IF(Config!$B$17="","",COUNTIFS(Prazos!$E$5:$E$404,Config!$B$17,Prazos!$I$5:$I$404,"Feito"))
A36: =IF(Config!$B$18="","",Config!$B$18) | C36: =IF(Config!$B$18="","",COUNTIFS(Prazos!$E$5:$E$404,Config!$B$18,Prazos!$J$5:$J$404,">0")+COUNTIFS(Prazos!$E$5:$E$404,Config!$B$18,Prazos!$I$5:$I$404,"Sem data")) | D36: =IF(Config!$B$18="","",COUNTIFS(Prazos!$E$5:$E$404,Config!$B$18,Prazos!$I$5:$I$404,"Atrasado")) | E36: =IF(Config!$B$18="","",COUNTIFS(Prazos!$E$5:$E$404,Config!$B$18,Prazos!$I$5:$I$404,"Hoje")) | F36: =IF(Config!$B$18="","",COUNTIFS(Prazos!$E$5:$E$404,Config!$B$18,Prazos!$I$5:$I$404,"Até "&Config!$B$6&" dias")) | G36: =IF(Config!$B$18="","",IFERROR(IF(_xlfn.MINIFS(Prazos!$D$5:$D$404,Prazos!$E$5:$E$404,Config!$B$18,Prazos!$J$5:$J$404,">0")=0,"",_xlfn.MINIFS(Prazos!$D$5:$D$404,Prazos!$E$5:$E$404,Config!$B$18,Prazos!$J$5:$J$404,">0")),"")) | H36: =IF(Config!$B$18="","",COUNTIFS(Prazos!$E$5:$E$404,Config!$B$18,Prazos!$I$5:$I$404,"Feito"))
A37: =IF(Config!$B$19="","",Config!$B$19) | C37: =IF(Config!$B$19="","",COUNTIFS(Prazos!$E$5:$E$404,Config!$B$19,Prazos!$J$5:$J$404,">0")+COUNTIFS(Prazos!$E$5:$E$404,Config!$B$19,Prazos!$I$5:$I$404,"Sem data")) | D37: =IF(Config!$B$19="","",COUNTIFS(Prazos!$E$5:$E$404,Config!$B$19,Prazos!$I$5:$I$404,"Atrasado")) | E37: =IF(Config!$B$19="","",COUNTIFS(Prazos!$E$5:$E$404,Config!$B$19,Prazos!$I$5:$I$404,"Hoje")) | F37: =IF(Config!$B$19="","",COUNTIFS(Prazos!$E$5:$E$404,Config!$B$19,Prazos!$I$5:$I$404,"Até "&Config!$B$6&" dias")) | G37: =IF(Config!$B$19="","",IFERROR(IF(_xlfn.MINIFS(Prazos!$D$5:$D$404,Prazos!$E$5:$E$404,Config!$B$19,Prazos!$J$5:$J$404,">0")=0,"",_xlfn.MINIFS(Prazos!$D$5:$D$404,Prazos!$E$5:$E$404,Config!$B$19,Prazos!$J$5:$J$404,">0")),"")) | H37: =IF(Config!$B$19="","",COUNTIFS(Prazos!$E$5:$E$404,Config!$B$19,Prazos!$I$5:$I$404,"Feito"))
A38: Prazos sem responsável não entram nesta tabela: confira na aba Prazos, filtrando a coluna Responsável por vazio.
A41: Próximos 7 dias, dia a dia
A42: Dia | C42: Data | D42: Prazos abertos | E42: =IF(Config!$B$10="","",Config!$B$10) | F42: =IF(Config!$B$11="","",Config!$B$11) | G42: =IF(Config!$B$12="","",Config!$B$12)
A43: =CHOOSE(WEEKDAY(C43),"domingo","segunda","terça","quarta","quinta","sexta","sábado") | C43: =Config!$B$5+0 | D43: =COUNTIFS(Prazos!$D$5:$D$404,C43,Prazos!$F$5:$F$404,"<>Sim") | E43: =IF(Config!$B$10="","",COUNTIFS(Prazos!$D$5:$D$404,C43,Prazos!$F$5:$F$404,"<>Sim",Prazos!$E$5:$E$404,Config!$B$10)) | F43: =IF(Config!$B$11="","",COUNTIFS(Prazos!$D$5:$D$404,C43,Prazos!$F$5:$F$404,"<>Sim",Prazos!$E$5:$E$404,Config!$B$11)) | G43: =IF(Config!$B$12="","",COUNTIFS(Prazos!$D$5:$D$404,C43,Prazos!$F$5:$F$404,"<>Sim",Prazos!$E$5:$E$404,Config!$B$12))
A44: =CHOOSE(WEEKDAY(C44),"domingo","segunda","terça","quarta","quinta","sexta","sábado") | C44: =Config!$B$5+1 | D44: =COUNTIFS(Prazos!$D$5:$D$404,C44,Prazos!$F$5:$F$404,"<>Sim") | E44: =IF(Config!$B$10="","",COUNTIFS(Prazos!$D$5:$D$404,C44,Prazos!$F$5:$F$404,"<>Sim",Prazos!$E$5:$E$404,Config!$B$10)) | F44: =IF(Config!$B$11="","",COUNTIFS(Prazos!$D$5:$D$404,C44,Prazos!$F$5:$F$404,"<>Sim",Prazos!$E$5:$E$404,Config!$B$11)) | G44: =IF(Config!$B$12="","",COUNTIFS(Prazos!$D$5:$D$404,C44,Prazos!$F$5:$F$404,"<>Sim",Prazos!$E$5:$E$404,Config!$B$12))
A45: =CHOOSE(WEEKDAY(C45),"domingo","segunda","terça","quarta","quinta","sexta","sábado") | C45: =Config!$B$5+2 | D45: =COUNTIFS(Prazos!$D$5:$D$404,C45,Prazos!$F$5:$F$404,"<>Sim") | E45: =IF(Config!$B$10="","",COUNTIFS(Prazos!$D$5:$D$404,C45,Prazos!$F$5:$F$404,"<>Sim",Prazos!$E$5:$E$404,Config!$B$10)) | F45: =IF(Config!$B$11="","",COUNTIFS(Prazos!$D$5:$D$404,C45,Prazos!$F$5:$F$404,"<>Sim",Prazos!$E$5:$E$404,Config!$B$11)) | G45: =IF(Config!$B$12="","",COUNTIFS(Prazos!$D$5:$D$404,C45,Prazos!$F$5:$F$404,"<>Sim",Prazos!$E$5:$E$404,Config!$B$12))
...

Sheet Config
A1: Configurações
A2: Células amarelas: você preenche. Responsáveis e tipos de prazo aparecem nas listas da aba Prazos.
A4: Escritório | B4: Ferraz & Lima Advocacia (exemplo fictício)
A5: Data de referência (hoje) | B5: =TODAY() | C5: Deixe =HOJE() para acompanhar o dia; troque por uma data para simular outro dia.
A6: Alerta: avisar prazos nos próximos (dias) | B6: 7 | C6: Prazos dentro desse número de dias ficam em alerta amarelo no painel.
A7: Janela do painel: prazos nos próximos (dias) | B7: 30 | C7: Prazos entre o alerta e essa janela contam no quarto quadro do painel; o resto fica como "Depois".
A9: Responsáveis (até 10) | D9: Tipos de prazo (até 20)
B10: Marina Ferraz | D10: Contestação
B11: Rafael Lima | D11: Réplica
B12: Júlia Prado | D12: Audiência de conciliação
D13: Audiência de instrução
D14: Manifestação sobre laudo
D15: Alegações finais
D16: Recurso ordinário
D17: Contrarrazões
D18: Embargos
D19: Cumprimento de sentença
D20: Juntada de documentos
D21: Reunião com cliente
D22: Prazo interno
A31: Preencha responsáveis e tipos de cima para baixo, sem pular linha: as listas suspensas param na última linha preenchida.
A32: O tipo de prazo é só um rótulo para organizar a agenda. Conte os dias e confira a data na fonte oficial: a planilha avisa, não calcula prazo.

Sheet Prazos
A1: Prazos
A2: Uma linha por prazo, audiência ou compromisso. Preencha as colunas amarelas; dias e situação são calculados. Quando cumprir, marque Sim em Feito.
A4: Processo | B4: Cliente | C4: Tipo de prazo | D4: Data | E4: Responsável | F4: Feito? | G4: Observação | H4: Dias | I4: Situação | J4: Chave
A5: 9236009-85.2026.8.26.0452 | B5: Padaria do Sol Ltda | C5: Cumprimento de sentença | D5: =TODAY()+60 | E5: Marina Ferraz | H5: =IF(OR(I5="",I5="Feito",I5="Sem data"),"",D5-Config!$B$5) | I5: =IF(AND(A5="",C5="",D5=""),"",IF(F5="Sim","Feito",IF(D5="","Sem data",IF(D5<Config!$B$5,"Atrasado",IF(D5=Config!$B$5,"Hoje",IF(D5-Config!$B$5<=Config!$B$6,"Até "&Config!$B$6&" dias",IF(D5-Config!$B$5<=Config!$B$7,"Até "&Config!$B$7&" dias","Depois"))))))) | J5: =IF(OR(I5="",I5="Feito",I5="Sem data"),0,IF(I5="Atrasado",3000+MIN(Config!$B$5-D5,60),IF(I5="Hoje",2500,IF(D5-Config!$B$5<=Config!$B$6,2000-(D5-Config!$B$5),IF(D5-Config!$B$5<=Config!$B$7,1000-(D5-Config!$B$5),500-MIN(D5-Config!$B$5,400)))))-ROW()/100000)
A6: 9225646-96.2026.8.26.0322 | B6: Ana Beatriz Moreira | C6: Contrarrazões | D6: =TODAY()-3 | E6: Rafael Lima | G6: Confirmar com o cliente ainda hoje | H6: =IF(OR(I6="",I6="Feito",I6="Sem data"),"",D6-Config!$B$5) | I6: =IF(AND(A6="",C6="",D6=""),"",IF(F6="Sim","Feito",IF(D6="","Sem data",IF(D6<Config!$B$5,"Atrasado",IF(D6=Config!$B$5,"Hoje",IF(D6-Config!$B$5<=Config!$B$6,"Até "&Config!$B$6&" dias",IF(D6-Config!$B$5<=Config!$B$7,"Até "&Config!$B$7&" dias","Depois"))))))) | J6: =IF(OR(I6="",I6="Feito",I6="Sem data"),0,IF(I6="Atrasado",3000+MIN(Config!$B$5-D6,60),IF(I6="Hoje",2500,IF(D6-Config!$B$5<=Config!$B$6,2000-(D6-Config!$B$5),IF(D6-Config!$B$5<=Config!$B$7,1000-(D6-Config!$B$5),500-MIN(D6-Config!$B$5,400)))))-ROW()/100000)
A7: 6710873-21.2025.8.26.0571 | B7: Construtora Horizonte | C7: Reunião com cliente | D7: =TODAY() | E7: Marina Ferraz | G7: Pasta separada na mesa | H7: =IF(OR(I7="",I7="Feito",I7="Sem data"),"",D7-Config!$B$5) | I7: =IF(AND(A7="",C7="",D7=""),"",IF(F7="Sim","Feito",IF(D7="","Sem data",IF(D7<Config!$B$5,"Atrasado",IF(D7=Config!$B$5,"Hoje",IF(D7-Config!$B$5<=Config!$B$6,"Até "&Config!$B$6&" dias",IF(D7-Config!$B$5<=Config!$B$7,"Até "&Config!$B$7&" dias","Depois"))))))) | J7: =IF(OR(I7="",I7="Feito",I7="Sem data"),0,IF(I7="Atrasado",3000+MIN(Config!$B$5-D7,60),IF(I7="Hoje",2500,IF(D7-Config!$B$5<=Config!$B$6,2000-(D7-Config!$B$5),IF(D7-Config!$B$5<=Config!$B$7,1000-(D7-Config!$B$5),500-MIN(D7-Config!$B$5,400)))))-ROW()/100000)
A8: 8735513-64.2025.8.26.0093 | B8: Carlos Eduardo Nunes | C8: Alegações finais | D8: =TODAY()+15 | E8: Rafael Lima | G8: Rascunho começado | H8: =IF(OR(I8="",I8="Feito",I8="Sem data"),"",D8-Config!$B$5) | I8: =IF(AND(A8="",C8="",D8=""),"",IF(F8="Sim","Feito",IF(D8="","Sem data",IF(D8<Config!$B$5,"Atrasado",IF(D8=Config!$B$5,"Hoje",IF(D8-Config!$B$5<=Config!$B$6,"Até "&Config!$B$6&" dias",IF(D8-Config!$B$5<=Config!$B$7,"Até "&Config!$B$7&" dias","Depois"))))))) | J8: =IF(OR(I8="",I8="Feito",I8="Sem data"),0,IF(I8="Atrasado",3000+MIN(Config!$B$5-D8,60),IF(I8="Hoje",2500,IF(D8-Config!$B$5<=Config!$B$6,2000-(D8-Config!$B$5),IF(D8-Config!$B$5<=Config!$B$7,1000-(D8-Config!$B$5),500-MIN(D8-Config!$B$5,400)))))-ROW()/100000)
A9: 9802211-43.2025.8.26.0431 | B9: Loja Verde Comércio | C9: Cumprimento de sentença | D9: =TODAY()+35 | E9: Marina Ferraz | H9: =IF(OR(I9="",I9="Feito",I9="Sem data"),"",D9-Config!$B$5) | I9: =IF(AND(A9="",C9="",D9=""),"",IF(F9="Sim","Feito",IF(D9="","Sem data",IF(D9<Config!$B$5,"Atrasado",IF(D9=Config!$B$5,"Hoje",IF(D9-Config!$B$5<=Config!$B$6,"Até "&Config!$B$6&" dias",IF(D9-Config!$B$5<=Config!$B$7,"Até "&Config!$B$7&" dias","Depois"))))))) | J9: =IF(OR(I9="",I9="Feito",I9="Sem data"),0,IF(I9="Atrasado",3000+MIN(Config!$B$5-D9,60),IF(I9="Hoje",2500,IF(D9-Config!$B$5<=Config!$B$6,2000-(D9-Config!$B$5),IF(D9-Config!$B$5<=Config!$B$7,1000-(D9-Config!$B$5),500-MIN(D9-Config!$B$5,400)))))-ROW()/100000)
A10: 8875326-79.2026.8.26.0258 | B10: Bistrô 42 | C10: Contrarrazões | D10: =TODAY()+27 | E10: Rafael Lima | H10: =IF(OR(I10="",I10="Feito",I10="Sem data"),"",D10-Config!$B$5) | I10: =IF(AND(A10="",C10="",D10=""),"",IF(F10="Sim","Feito",IF(D10="","Sem data",IF(D10<Config!$B$5,"Atrasado",IF(D10=Config!$B$5,"Hoje",IF(D10-Config!$B$5<=Config!$B$6,"Até "&Config!$B$6&" dias",IF(D10-Config!$B$5<=Config!$B$7,"Até "&Config!$B$7&" dias","Depois"))))))) | J10: =IF(OR(I10="",I10="Feito",I10="Sem data"),0,IF(I10="Atrasado",3000+MIN(Config!$B$5-D10,60),IF(I10="Hoje",2500,IF(D10-Config!$B$5<=Config!$B$6,2000-(D10-Config!$B$5),IF(D10-Config!$B$5<=Config!$B$7,1000-(D10-Config!$B$5),500-MIN(D10-Config!$B$5,400)))))-ROW()/100000)
A11: 4397912-47.2025.8.26.0276 | B11: Roberto Almeida | C11: Cumprimento de sentença | D11: =TODAY()+18 | E11: Marina Ferraz | H11: =IF(OR(I11="",I11="Feito",I11="Sem data"),"",D11-Config!$B$5) | I11: =IF(AND(A11="",C11="",D11=""),"",IF(F11="Sim","Feito",IF(D11="","Sem data",IF(D11<Config!$B$5,"Atrasado",IF(D11=Config!$B$5,"Hoje",IF(D11-Config!$B$5<=Config!$B$6,"Até "&Config!$B$6&" dias",IF(D11-Config!$B$5<=Config!$B$7,"Até "&Config!$B$7&" dias","Depois"))))))) | J11: =IF(OR(I11="",I11="Feito",I11="Sem data"),0,IF(I11="Atrasado",3000+MIN(Config!$B$5-D11,60),IF(I11="Hoje",2500,IF(D11-Config!$B$5<=Config!$B$6,2000-(D11-Config!$B$5),IF(D11-Config!$B$5<=Config!$B$7,1000-(D11-Config!$B$5),500-MIN(D11-Config!$B$5,400)))))-ROW()/100000)
A12: 5470559-73.2026.8.26.0380 | B12: Transportadora Rota Sul | C12: Contrarrazões | D12: =TODAY() | E12: Rafael Lima | G12: Pasta separada na mesa | H12: =IF(OR(I12="",I12="Feito",I12="Sem data"),"",D12-Config!$B$5) | I12: =IF(AND(A12="",C12="",D12=""),"",IF(F12="Sim","Feito",IF(D12="","Sem data",IF(D12<Config!$B$5,"Atrasado",IF(D12=Config!$B$5,"Hoje",IF(D12-Config!$B$5<=Config!$B$6,"Até "&Config!$B$6&" dias",IF(D12-Config!$B$5<=Config!$B$7,"Até "&Config!$B$7&" dias","Depois"))))))) | J12: =IF(OR(I12="",I12="Feito",I12="Sem data"),0,IF(I12="Atrasado",3000+MIN(Config!$B$5-D12,60),IF(I12="Hoje",2500,IF(D12-Config!$B$5<=Config!$B$6,2000-(D12-Config!$B$5),IF(D12-Config!$B$5<=Config!$B$7,1000-(D12-Config!$B$5),500-MIN(D12-Config!$B$5,400)))))-ROW()/100000)
A13: 8570388-84.2025.8.26.0560 | B13: Patrícia Gomes | C13: Contestação | D13: =TODAY() | E13: Marina Ferraz | G13: Pasta separada na mesa | H13: =IF(OR(I13="",I13="Feito",I13="Sem data"),"",D13-Config!$B$5) | I13: =IF(AND(A13="",C13="",D13=""),"",IF(F13="Sim","Feito",IF(D13="","Sem data",IF(D13<Config!$B$5,"Atrasado",IF(D13=Config!$B$5,"Hoje",IF(D13-Config!$B$5<=Config!$B$6,"Até "&Config!$B$6&" dias",IF(D13-Config!$B$5<=Config!$B$7,"Até "&Config!$B$7&" dias","Depois"))))))) | J13: =IF(OR(I13="",I13="Feito",I13="Sem data"),0,IF(I13="Atrasado",3000+MIN(Config!$B$5-D13,60),IF(I13="Hoje",2500,IF(D13-Config!$B$5<=Config!$B$6,2000-(D13-Config!$B$5),IF(D13-Config!$B$5<=Config!$B$7,1000-(D13-Config!$B$5),500-MIN(D13-Config!$B$5,400)))))-ROW()/100000)
A14: 6258696-95.2026.8.26.0598 | B14: Escola Aurora | C14: Contestação | D14: =TODAY()+2 | E14: Marina Ferraz | G14: Cliente confirmou presença | H14: =IF(OR(I14="",I14="Feito",I14="Sem data"),"",D14-Config!$B$5) | I14: =IF(AND(A14="",C14="",D14=""),"",IF(F14="Sim","Feito",IF(D14="","Sem data",IF(D14<Config!$B$5,"Atrasado",IF(D14=Config!$B$5,"Hoje",IF(D14-Config!$B$5<=Config!$B$6,"Até "&Config!$B$6&" dias",IF(D14-Config!$B$5<=Config!$B$7,"Até "&Config!$B$7&" dias","Depois"))))))) | J14: =IF(OR(I14="",I14="Feito",I14="Sem data"),0,IF(I14="Atrasado",3000+MIN(Config!$B$5-D14,60),IF(I14="Hoje",2500,IF(D14-Config!$B$5<=Config!$B$6,2000-(D14-Config!$B$5),IF(D14-Config!$B$5<=Config!$B$7,1000-(D14-Config!$B$5),500-MIN(D14-Config!$B$5,400)))))-ROW()/100000)
A15: 4300029-58.2025.8.26.0015 | B15: Oficina Mecânica Central | C15: Audiência de conciliação | D15: =TODAY()+2 | E15: Rafael Lima | G15: Cliente confirmou presença | H15: =IF(OR(I15="",I15="Feito",I15="Sem data"),"",D15-Config!$B$5) | I15: =IF(AND(A15="",C15="",D15=""),"",IF(F15="Sim","Feito",IF(D15="","Sem data",IF(D15<Config!$B$5,"Atrasado",IF(D15=Config!$B$5,"Hoje",IF(D15-Config!$B$5<=Config!$B$6,"Até "&Config!$B$6&" dias",IF(D15-Config!$B$5<=Config!$B$7,"Até "&Config!$B$7&" dias","Depois"))))))) | J15: =IF(OR(I15="",I15="Feito",I15="Sem data"),0,IF(I15="Atrasado",3000+MIN(Config!$B$5-D15,60),IF(I15="Hoje",2500,IF(D15-Config!$B$5<=Config!$B$6,2000-(D15-Config!$B$5),IF(D15-Config!$B$5<=Config!$B$7,1000-(D15-Config!$B$5),500-MIN(D15-Config!$B$5,400)))))-ROW()/100000)
A16: 8986364-51.2026.8.26.0700 | B16: Luciana Farias | C16: Audiência de conciliação | D16: =TODAY()-3 | E16: Marina Ferraz | G16: Confirmar com o cliente ainda hoje | H16: =IF(OR(I16="",I16="Feito",I16="Sem data"),"",D16-Config!$B$5) | I16: =IF(AND(A16="",C16="",D16=""),"",IF(F16="Sim","Feito",IF(D16="","Sem data",IF(D16<Config!$B$5,"Atrasado",IF(D16=Config!$B$5,"Hoje",IF(D16-Config!$B$5<=Config!$B$6,"Até "&Config!$B$6&" dias",IF(D16-Config!$B$5<=Config!$B$7,"Até "&Config!$B$7&" dias","Depois"))))))) | J16: =IF(OR(I16="",I16="Feito",I16="Sem data"),0,IF(I16="Atrasado",3000+MIN(Config!$B$5-D16,60),IF(I16="Hoje",2500,IF(D16-Config!$B$5<=Config!$B$6,2000-(D16-Config!$B$5),IF(D16-Config!$B$5<=Config!$B$7,1000-(D16-Config!$B$5),500-MIN(D16-Config!$B$5,400)))))-ROW()/100000)
A17: 9717671-36.2026.8.26.0445 | B17: Agência Prisma | C17: Audiência de instrução | D17: =TODAY()+3 | E17: Marina Ferraz | H17: =IF(OR(I17="",I17="Feito",I17="Sem data"),"",D17-Config!$B$5) | I17: =IF(AND(A17="",C17="",D17=""),"",IF(F17="Sim","Feito",IF(D17="","Sem data",IF(D17<Config!$B$5,"Atrasado",IF(D17=Config!$B$5,"Hoje",IF(D17-Config!$B$5<=Config!$B$6,"Até "&Config!$B$6&" dias",IF(D17-Config!$B$5<=Config!$B$7,"Até "&Config!$B$7&" dias","Depois"))))))) | J17: =IF(OR(I17="",I17="Feito",I17="Sem data"),0,IF(I17="Atrasado",3000+MIN(Config!$B$5-D17,60),IF(I17="Hoje",2500,IF(D17-Config!$B$5<=Config!$B$6,2000-(D17-Config!$B$5),IF(D17-Config!$B$5<=Config!$B$7,1000-(D17-Config!$B$5),500-MIN(D17-Config!$B$5,400)))))-ROW()/100000)
A18: 1808451-67.2026.8.26.0657 | B18: Helena Duarte | C18: Contestação | D18: =TODAY()+3 | E18: Rafael Lima | H18: =IF(OR(I18="",I18="Feito",I18="Sem data"),"",D18-Config!$B$5) | I18: =IF(AND(A18="",C18="",D18=""),"",IF(F18="Sim","Feito",IF(D18="","Sem data",IF(D18<Config!$B$5,"Atrasado",IF(D18=Config!$B$5,"Hoje",IF(D18-Config!$B$5<=Config!$B$6,"Até "&Config!$B$6&" dias",IF(D18-Config!$B$5<=Config!$B$7,"Até "&Config!$B$7&" dias","Depois"))))))) | J18: =IF(OR(I18="",I18="Feito",I18="Sem data"),0,IF(I18="Atrasado",3000+MIN(Config!$B$5-D18,60),IF(I18="Hoje",2500,IF(D18-Config!$B$5<=Config!$B$6,2000-(D18-Config!$B$5),IF(D18-Config!$B$5<=Config!$B$7,1000-(D18-Config!$B$5),500-MIN(D18-Config!$B$5,400)))))-ROW()/100000)
A19: 3930894-43.2025.8.26.0476 | B19: Ana Beatriz Moreira | C19: Alegações finais | D19: =TODAY()+3 | E19: Rafael Lima | H19: =IF(OR(I19="",I19="Feito",I19="Sem data"),"",D19-Config!$B$5) | I19: =IF(AND(A19="",C19="",D19=""),"",IF(F19="Sim","Feito",IF(D19="","Sem data",IF(D19<Config!$B$5,"Atrasado",IF(D19=Config!$B$5,"Hoje",IF(D19-Config!$B$5<=Config!$B$6,"Até "&Config!$B$6&" dias",IF(D19-Config!$B$5<=Config!$B$7,"Até "&Config!$B$7&" dias","Depois"))))))) | J19: =IF(OR(I19="",I19="Feito",I19="Sem data"),0,IF(I19="Atrasado",3000+MIN(Config!$B$5-D19,60),IF(I19="Hoje",2500,IF(D19-Config!$B$5<=Config!$B$6,2000-(D19-Config!$B$5),IF(D19-Config!$B$5<=Config!$B$7,1000-(D19-Config!$B$5),500-MIN(D19-Config!$B$5,400)))))-ROW()/100000)
A20: 9802987-45.2025.8.26.0097 | B20: Construtora Horizonte | C20: Audiência de conciliação | D20: =TODAY()+1 | E20: Marina Ferraz | H20: =IF(OR(I20="",I20="Feito",I20="Sem data"),"",D20-Config!$B$5) | I20: =IF(AND(A20="",C20="",D20=""),"",IF(F20="Sim","Feito",IF(D20="","Sem data",IF(D20<Config!$B$5,"Atrasado",IF(D20=Config!$B$5,"Hoje",IF(D20-Config!$B$5<=Config!$B$6,"Até "&Config!$B$6&" dias",IF(D20-Config!$B$5<=Config!$B$7,"Até "&Config!$B$7&" dias","Depois"))))))) | J20: =IF(OR(I20="",I20="Feito",I20="Sem data"),0,IF(I20="Atrasado",3000+MIN(Config!$B$5-D20,60),IF(I20="Hoje",2500,IF(D20-Config!$B$5<=Config!$B$6,2000-(D20-Config!$B$5),IF(D20-Config!$B$5<=Config!$B$7,1000-(D20-Config!$B$5),500-MIN(D20-Config!$B$5,400)))))-ROW()/100000)
A21: 6904743-30.2025.8.26.0361 | B21: Carlos Eduardo Nunes | C21: Contestação | D21: =TODAY()+3 | E21: Rafael Lima | H21: =IF(OR(I21="",I21="Feito",I21="Sem data"),"",D21-Config!$B$5) | I21: =IF(AND(A21="",C21="",D21=""),"",IF(F21="Sim","Feito",IF(D21="","Sem data",IF(D21<Config!$B$5,"Atrasado",IF(D21=Config!$B$5,"Hoje",IF(D21-Config!$B$5<=Config!$B$6,"Até "&Config!$B$6&" dias",IF(D21-Config!$B$5<=Config!$B$7,"Até "&Config!$B$7&" dias","Depois"))))))) | J21: =IF(OR(I21="",I21="Feito",I21="Sem data"),0,IF(I21="Atrasado",3000+MIN(Config!$B$5-D21,60),IF(I21="Hoje",2500,IF(D21-Config!$B$5<=Config!$B$6,2000-(D21-Config!$B$5),IF(D21-Config!$B$5<=Config!$B$7,1000-(D21-Config!$B$5),500-MIN(D21-Config!$B$5,400)))))-ROW()/100000)
A22: 5497983-95.2025.8.26.0570 | B22: Loja Verde Comércio | C22: Embargos | D22: =TODAY()+10 | E22: Marina Ferraz | H22: =IF(OR(I22="",I22="Feito",I22="Sem data"),"",D22-Config!$B$5) | I22: =IF(AND(A22="",C22="",D22=""),"",IF(F22="Sim","Feito",IF(D22="","Sem data",IF(D22<Config!$B$5,"Atrasado",IF(D22=Config!$B$5,"Hoje",IF(D22-Config!$B$5<=Config!$B$6,"Até "&Config!$B$6&" dias",IF(D22-Config!$B$5<=Config!$B$7,"Até "&Config!$B$7&" dias","Depois"))))))) | J22: =IF(OR(I22="",I22="Feito",I22="Sem data"),0,IF(I22="Atrasado",3000+MIN(Config!$B$5-D22,60),IF(I22="Hoje",2500,IF(D22-Config!$B$5<=Config!$B$6,2000-(D22-Config!$B$5),IF(D22-Config!$B$5<=Config!$B$7,1000-(D22-Config!$B$5),500-MIN(D22-Config!$B$5,400)))))-ROW()/100000)
A23: 4112092-92.2025.8.26.0646 | B23: Fernanda Castro | C23: Alegações finais | D23: =TODAY()-1 | E23: Rafael Lima | G23: Aguardando documentos do cliente | H23: =IF(OR(I23="",I23="Feito",I23="Sem data"),"",D23-Config!$B$5) | I23: =IF(AND(A23="",C23="",D23=""),"",IF(F23="Sim","Feito",IF(D23="","Sem data",IF(D23<Config!$B$5,"Atrasado",IF(D23=Config!$B$5,"Hoje",IF(D23-Config!$B$5<=Config!$B$6,"Até "&Config!$B$6&" dias",IF(D23-Config!$B$5<=Config!$B$7,"Até "&Config!$B$7&" dias","Depois"))))))) | J23: =IF(OR(I23="",I23="Feito",I23="Sem data"),0,IF(I23="Atrasado",3000+MIN(Config!$B$5-D23,60),IF(I23="Hoje",2500,IF(D23-Config!$B$5<=Config!$B$6,2000-(D23-Config!$B$5),IF(D23-Config!$B$5<=Config!$B$7,1000-(D23-Config!$B$5),500-MIN(D23-Config!$B$5,400)))))-ROW()/100000)
A24: 5297049-18.2026.8.26.0015 | B24: Bistrô 42 | C24: Manifestação sobre laudo | D24: =TODAY()+3 | E24: Marina Ferraz | H24: =IF(OR(I24="",I24="Feito",I24="Sem data"),"",D24-Config!$B$5) | I24: =IF(AND(A24="",C24="",D24=""),"",IF(F24="Sim","Feito",IF(D24="","Sem data",IF(D24<Config!$B$5,"Atrasado",IF(D24=Config!$B$5,"Hoje",IF(D24-Config!$B$5<=Config!$B$6,"Até "&Config!$B$6&" dias",IF(D24-Config!$B$5<=Config!$B$7,"Até "&Config!$B$7&" dias","Depois"))))))) | J24: =IF(OR(I24="",I24="Feito",I24="Sem data"),0,IF(I24="Atrasado",3000+MIN(Config!$B$5-D24,60),IF(I24="Hoje",2500,IF(D24-Config!$B$5<=Config!$B$6,2000-(D24-Config!$B$5),IF(D24-Config!$B$5<=Config!$B$7,1000-(D24-Config!$B$5),500-MIN(D24-Config!$B$5,400)))))-ROW()/100000)
A25: 6877173-50.2026.8.26.0467 | B25: Roberto Almeida | C25: Réplica | D25: =TODAY()+1 | E25: Marina Ferraz | H25: =IF(OR(I25="",I25="Feito",I25="Sem data"),"",D25-Config!$B$5) | I25: =IF(AND(A25="",C25="",D25=""),"",IF(F25="Sim","Feito",IF(D25="","Sem data",IF(D25<Config!$B$5,"Atrasado",IF(D25=Config!$B$5,"Hoje",IF(D25-Config!$B$5<=Config!$B$6,"Até "&Config!$B$6&" dias",IF(D25-Config!$B$5<=Config!$B$7,"Até "&Config!$B$7&" dias","Depois"))))))) | J25: =IF(OR(I25="",I25="Feito",I25="Sem data"),0,IF(I25="Atrasado",3000+MIN(Config!$B$5-D25,60),IF(I25="Hoje",2500,IF(D25-Config!$B$5<=Config!$B$6,2000-(D25-Config!$B$5),IF(D25-Config!$B$5<=Config!$B$7,1000-(D25-Config!$B$5),500-MIN(D25-Config!$B$5,400)))))-ROW()/100000)
A26: 6545676-47.2025.8.26.0126 | B26: Marcos Vinícius Teles | C26: Manifestação sobre laudo | D26: =TODAY()-3 | E26: Marina Ferraz | G26: Confirmar com o cliente ainda hoje | H26: =IF(OR(I26="",I26="Feito",I26="Sem data"),"",D26-Config!$B$5) | I26: =IF(AND(A26="",C26="",D26=""),"",IF(F26="Sim","Feito",IF(D26="","Sem data",IF(D26<Config!$B$5,"Atrasado",IF(D26=Config!$B$5,"Hoje",IF(D26-Config!$B$5<=Config!$B$6,"Até "&Config!$B$6&" dias",IF(D26-Config!$B$5<=Config!$B$7,"Até "&Config!$B$7&" dias","Depois"))))))) | J26: =IF(OR(I26="",I26="Feito",I26="Sem data"),0,IF(I26="Atrasado",3000+MIN(Config!$B$5-D26,60),IF(I26="Hoje",2500,IF(D26-Config!$B$5<=Config!$B$6,2000-(D26-Config!$B$5),IF(D26-Config!$B$5<=Config!$B$7,1000-(D26-Config!$B$5),500-MIN(D26-Config!$B$5,400)))))-ROW()/100000)
A27: 1941959-24.2026.8.26.0167 | B27: Transportadora Rota Sul | C27: Audiência de conciliação | D27: =TODAY()+4 | E27: Rafael Lima | G27: Levar via impressa | H27: =IF(OR(I27="",I27="Feito",I27="Sem data"),"",D27-Config!$B$5) | I27: =IF(AND(A27="",C27="",D27=""),"",IF(F27="Sim","Feito",IF(D27="","Sem data",IF(D27<Config!$B$5,"Atrasado",IF(D27=Config!$B$5,"Hoje",IF(D27-Config!$B$5<=Config!$B$6,"Até "&Config!$B$6&" dias",IF(D27-Config!$B$5<=Config!$B$7,"Até "&Config!$B$7&" dias","Depois"))))))) | J27: =IF(OR(I27="",I27="Feito",I27="Sem data"),0,IF(I27="Atrasado",3000+MIN(Config!$B$5-D27,60),IF(I27="Hoje",2500,IF(D27-Config!$B$5<=Config!$B$6,2000-(D27-Config!$B$5),IF(D27-Config!$B$5<=Config!$B$7,1000-(D27-Config!$B$5),500-MIN(D27-Config!$B$5,400)))))-ROW()/100000)
A28: 3118925-55.2025.8.26.0426 | B28: Patrícia Gomes | C28: Cumprimento de sentença | D28: =TODAY()-3 | E28: Marina Ferraz | G28: Confirmar com o cliente ainda hoje | H28: =IF(OR(I28="",I28="Feito",I28="Sem data"),"",D28-Config!$B$5) | I28: =IF(AND(A28="",C28="",D28=""),"",IF(F28="Sim","Feito",IF(D28="","Sem data",IF(D28<Config!$B$5,"Atrasado",IF(D28=Config!$B$5,"Hoje",IF(D28-Config!$B$5<=Config!$B$6,"Até "&Config!$B$6&" dias",IF(D28-Config!$B$5<=Config!$B$7,"Até "&Config!$B$7&" dias","Depois"))))))) | J28: =IF(OR(I28="",I28="Feito",I28="Sem data"),0,IF(I28="Atrasado",3000+MIN(Config!$B$5-D28,60),IF(I28="Hoje",2500,IF(D28-Config!$B$5<=Config!$B$6,2000-(D28-Config!$B$5),IF(D28-Config!$B$5<=Config!$B$7,1000-(D28-Config!$B$5),500-MIN(D28-Config!$B$5,400)))))-ROW()/100000)
A29: 7658179-42.2026.8.26.0152 | B29: Escola Aurora | C29: Contrarrazões | D29: =TODAY()-3 | E29: Marina Ferraz | G29: Confirmar com o cliente ainda hoje | H29: =IF(OR(I29="",I29="Feito",I29="Sem data"),"",D29-Config!$B$5) | I29: =IF(AND(A29="",C29="",D29=""),"",IF(F29="Sim","Feito",IF(D29="","Sem data",IF(D29<Config!$B$5,"Atrasado",IF(D29=Config!$B$5,"Hoje",IF(D29-Config!$B$5<=Config!$B$6,"Até "&Config!$B$6&" dias",IF(D29-Config!$B$5<=Config!$B$7,"Até "&Config!$B$7&" dias","Depois"))))))) | J29: =IF(OR(I29="",I29="Feito",I29="Sem data"),0,IF(I29="Atrasado",3000+MIN(Config!$B$5-D29,60),IF(I29="Hoje",2500,IF(D29-Config!$B$5<=Config!$B$6,2000-(D29-Config!$B$5),IF(D29-Config!$B$5<=Config!$B$7,1000-(D29-Config!$B$5),500-MIN(D29-Config!$B$5,400)))))-ROW()/100000)
A30: 1191416-90.2025.8.26.0249 | B30: Oficina Mecânica Central | C30: Contrarrazões | D30: =TODAY()-1 | E30: Marina Ferraz | G30: Aguardando documentos do cliente | H30: =IF(OR(I30="",I30="Feito",I30="Sem data"),"",D30-Config!$B$5) | I30: =IF(AND(A30="",C30="",D30=""),"",IF(F30="Sim","Feito",IF(D30="","Sem data",IF(D30<Config!$B$5,"Atrasado",IF(D30=Config!$B$5,"Hoje",IF(D30-Config!$B$5<=Config!$B$6,"Até "&Config!$B$6&" dias",IF(D30-Config!$B$5<=Config!$B$7,"Até "&Config!$B$7&" dias","Depois"))))))) | J30: =IF(OR(I30="",I30="Feito",I30="Sem data"),0,IF(I30="Atrasado",3000+MIN(Config!$B$5-D30,60),IF(I30="Hoje",2500,IF(D30-Config!$B$5<=Config!$B$6,2000-(D30-Config!$B$5),IF(D30-Config!$B$5<=Config!$B$7,1000-(D30-Config!$B$5),500-MIN(D30-Config!$B$5,400)))))-ROW()/100000)
