Workbook

Sheet Como usar
A1: Andamento por processo
A2: Kit de Gestão para Advogados · Seu Sócio Gestor · versão 1.0 (setembro de 2026)
A4: O que esta planilha faz | B4: Uma linha por caso com fase, responsável, próxima ação e data. O Painel mostra quantos casos há em cada fase e área, a carga de cada pessoa e quais casos estão parados há mais tempo sem atualização.
A5: Passo 1 | B5: Em Config, troque a data de referência por =HOJE() (no exemplo ela está congelada em 14/09/2026), o número de dias para considerar um caso parado, e as listas de fases, áreas e responsáveis. Preencha de cima para baixo, sem pular linha.
A6: Passo 2 | B6: Em Processos, apague os exemplos e cadastre os seus casos: número, cliente, área, fase, responsável, próxima ação com data, e a data da última atualização. O cadastro (número, cliente, área, fase, responsável) é o mesmo da planilha 13 · Carteira: copie de lá e mantenha a 13 como fonte.
A7: Passo 3 | B7: A cada movimentação, atualize a fase, a próxima ação e a data da última atualização. Ao encerrar, mude a fase para Encerrado: o caso sai das contagens de ativos.
A8: Passo 4 | B8: Em Painel, confira os casos com ação atrasada, os sem próxima ação (ninguém sabe o próximo passo) e os parados há mais de N dias.
A9: Rotina de segunda | B9: 5 minutos depois da Agenda de prazos: casos parados e sem próxima ação. Decida a ação e a data; se o caso só aguarda o andamento, registre isso na observação e atualize a data.
A10: Exemplo | B10: Caso consultivo não tem número de processo (referência CONS-ano-nº) e a próxima ação é entrega de parecer ou reunião. A próxima ação de cada caso é coerente com a fase (inicial: contestação, réplica, juntada, conciliação; instrução: audiência, laudo, alegações finais; sentença: embargos, recurso; recurso: contrarrazões; execução: cumprimento, penhora; acordo: minuta, homologação).
A11: Com a IA | B11: Copie a tabela "Parados" ou "Por responsável" e use o prompt "Prazos 05 · Resumo de andamento para o sócio" da biblioteca do kit.
A12: Legenda | B12: Células amarelas: você preenche. Brancas: calculadas. Não é preciso mexer em nada fora do amarelo.
A13: Proteção | B13: Fórmulas protegidas sem senha. Para editar: Revisar > Desproteger planilha (Excel) ou Dados > Proteger intervalos (Google Sheets).
A14: Requisitos | B14: Excel 2016 ou mais novo, Microsoft 365 ou Google Sheets (só funções do Excel 2007+; nada de MÍNIMOSES, MÁXIMOSES ou UNIRTEXTO). No celular abre nos aplicativos; para preencher, use o computador.
A15: Google Sheets | B15: Faça upload no Google Drive e abra com o Google Sheets. Fórmulas, listas, cores, semáforos e gráficos funcionam: as regras de cor que dependem do mês escolhido em Config usam INDIRECT, que é a forma que o Sheets aceita para regra condicional apontar para outra aba.
... A18: Suporte | B18: suporte@seusociogestor.com.br · resposta em até 5 dias úteis · reembolso em até 7 dias pelo mesmo canal.

Sheet Painel
A1: =Config!$B$4&" · Andamento dos processos · "&TEXT(DAY(Config!$B$5),"00")&"/"&TEXT(MONTH(Config!$B$5),"00")&"/"&YEAR(Config!$B$5) -> Ferraz & Lima Advocacia (exemplo fictício) · Andamento dos processos · 14/09/2026
A2: Nada para digitar aqui: tudo vem de Config e Processos.
A4: Casos ativos | C4: Ação atrasada | E4: Ação hoje ou esta semana | G4: Sem próxima ação | I4: ="Parados há mais de "&Config!$B$6&" dias" -> Parados há mais de 30 dias | K4: Encerrados
A5: =COUNTIFS(Processos!$A$5:$A$304,"<>",Processos!$D$5:$D$304,"<>Encerrado") -> 30 | C5: =COUNTIFS(Processos!$K$5:$K$304,"Atrasado") -> 7 | E5: =COUNTIFS(Processos!$K$5:$K$304,"Hoje")+COUNTIFS(Processos!$K$5:$K$304,"Esta semana") -> 12 | G5: =COUNTIFS(Processos!$K$5:$K$304,"Sem próxima ação") -> 0 | I5: =COUNTIFS(Processos!$M$5:$M$304,"Sim") -> 4 | K5: =COUNTIFS(Processos!$A$5:$A$304,"<>",Processos!$D$5:$D$304,"Encerrado") -> 8
A7: Por fase | H7: Por área
A8: Fase | B8: Casos | C8: Ação atrasada | D8: Esta semana | E8: Sem próxima ação | F8: Parados | H8: Área | I8: Ativos | J8: Encerrados | K8: Ação atrasada | L8: Parados
A9: =IF(Config!$B$10="","",Config!$B$10) -> Consultivo | B9: =IF(Config!$B$10="","",COUNTIFS(Processos!$A$5:$A$304,"<>",Processos!$D$5:$D$304,Config!$B$10)) -> 7 | C9: =IF(Config!$B$10="","",COUNTIFS(Processos!$D$5:$D$304,Config!$B$10,Processos!$K$5:$K$304,"Atrasado")) -> 1 | D9: =IF(Config!$B$10="","",COUNTIFS(Processos!$D$5:$D$304,Config!$B$10,Processos!$K$5:$K$304,"Hoje")+COUNTIFS(Processos!$D$5:$D$304,Config!$B$10,Processos!$K$5:$K$304,"Esta semana")) -> 4 | E9: =IF(Config!$B$10="","",COUNTIFS(Processos!$D$5:$D$304,Config!$B$10,Processos!$K$5:$K$304,"Sem próxima ação")) -> 0 | F9: =IF(Config!$B$10="","",COUNTIFS(Processos!$D$5:$D$304,Config!$B$10,Processos!$M$5:$M$304,"Sim")) -> 0 | H9: =IF(Config!$D$10="","",Config!$D$10) -> Cível | I9: =IF(Config!$D$10="","",COUNTIFS(Processos!$A$5:$A$304,"<>",Processos!$C$5:$C$304,Config!$D$10,Processos!$D$5:$D$304,"<>Encerrado")) -> 7 | J9: =IF(Config!$D$10="","",COUNTIFS(Processos!$C$5:$C$304,Config!$D$10,Processos!$D$5:$D$304,"Encerrado")) -> 1 | K9: =IF(Config!$D$10="","",COUNTIFS(Processos!$C$5:$C$304,Config!$D$10,Processos!$K$5:$K$304,"Atrasado")) -> 3 | L9: =IF(Config!$D$10="","",COUNTIFS(Processos!$C$5:$C$304,Config!$D$10,Processos!$M$5:$M$304,"Sim")) -> 1
A10: =IF(Config!$B$11="","",Config!$B$11) -> Inicial | B10: =IF(Config!$B$11="","",COUNTIFS(Processos!$A$5:$A$304,"<>",Processos!$D$5:$D$304,Config!$B$11)) -> 8 | C10: =IF(Config!$B$11="","",COUNTIFS(Processos!$D$5:$D$304,Config!$B$11,Processos!$K$5:$K$304,"Atrasado")) -> 2 | D10: =IF(Config!$B$11="","",COUNTIFS(Processos!$D$5:$D$304,Config!$B$11,Processos!$K$5:$K$304,"Hoje")+COUNTIFS(Processos!$D$5:$D$304,Config!$B$11,Processos!$K$5:$K$304,"Esta semana")) -> 4 | E10: =IF(Config!$B$11="","",COUNTIFS(Processos!$D$5:$D$304,Config!$B$11,Processos!$K$5:$K$304,"Sem próxima ação")) -> 0 | F10: =IF(Config!$B$11="","",COUNTIFS(Processos!$D$5:$D$304,Config!$B$11,Processos!$M$5:$M$304,"Sim")) -> 1 | H10: =IF(Config!$D$11="","",Config!$D$11) -> Trabalhista | I10: =IF(Config!$D$11="","",COUNTIFS(Processos!$A$5:$A$304,"<>",Processos!$C$5:$C$304,Config!$D$11,Processos!$D$5:$D$304,"<>Encerrado")) -> 10 | J10: =IF(Config!$D$11="","",COUNTIFS(Processos!$C$5:$C$304,Config!$D$11,Processos!$D$5:$D$304,"Encerrado")) -> 2 | K10: =IF(Config!$D$11="","",COUNTIFS(Processos!$C$5:$C$304,Config!$D$11,Processos!$K$5:$K$304,"Atrasado")) -> 1 | L10: =IF(Config!$D$11="","",COUNTIFS(Processos!$C$5:$C$304,Config!$D$11,Processos!$M$5:$M$304,"Sim")) -> 3
A11: =IF(Config!$B$12="","",Config!$B$12) -> Instrução | B11: =IF(Config!$B$12="","",COUNTIFS(Processos!$A$5:$A$304,"<>",Processos!$D$5:$D$304,Config!$B$12)) -> 4 | C11: =IF(Config!$B$12="","",COUNTIFS(Processos!$D$5:$D$304,Config!$B$12,Processos!$K$5:$K$304,"Atrasado")) -> 1 | D11: =IF(Config!$B$12="","",COUNTIFS(Processos!$D$5:$D$304,Config!$B$12,Processos!$K$5:$K$304,"Hoje")+COUNTIFS(Processos!$D$5:$D$304,Config!$B$12,Processos!$K$5:$K$304,"Esta semana")) -> 1 | E11: =IF(Config!$B$12="","",COUNTIFS(Processos!$D$5:$D$304,Config!$B$12,Processos!$K$5:$K$304,"Sem próxima ação")) -> 0 | F11: =IF(Config!$B$12="","",COUNTIFS(Processos!$D$5:$D$304,Config!$B$12,Processos!$M$5:$M$304,"Sim")) -> 0 | H11: =IF(Config!$D$12="","",Config!$D$12) -> Previdenciário | I11: =IF(Config!$D$12="","",COUNTIFS(Processos!$A$5:$A$304,"<>",Processos!$C$5:$C$304,Config!$D$12,Processos!$D$5:$D$304,"<>Encerrado")) -> 5 | J11: =IF(Config!$D$12="","",COUNTIFS(Processos!$C$5:$C$304,Config!$D$12,Processos!$D$5:$D$304,"Encerrado")) -> 2 | K11: =IF(Config!$D$12="","",COUNTIFS(Processos!$C$5:$C$304,Config!$D$12,Processos!$K$5:$K$304,"Atrasado")) -> 2 | L11: =IF(Config!$D$12="","",COUNTIFS(Processos!$C$5:$C$304,Config!$D$12,Processos!$M$5:$M$304,"Sim")) -> 0
A12: =IF(Config!$B$13="","",Config!$B$13) -> Sentença | B12: =IF(Config!$B$13="","",COUNTIFS(Processos!$A$5:$A$304,"<>",Processos!$D$5:$D$304,Config!$B$13)) -> 3 | C12: =IF(Config!$B$13="","",COUNTIFS(Processos!$D$5:$D$304,Config!$B$13,Processos!$K$5:$K$304,"Atrasado")) -> 1 | D12: =IF(Config!$B$13="","",COUNTIFS(Processos!$D$5:$D$304,Config!$B$13,Processos!$K$5:$K$304,"Hoje")+COUNTIFS(Processos!$D$5:$D$304,Config!$B$13,Processos!$K$5:$K$304,"Esta semana")) -> 2 | E12: =IF(Config!$B$13="","",COUNTIFS(Processos!$D$5:$D$304,Config!$B$13,Processos!$K$5:$K$304,"Sem próxima ação")) -> 0 | F12: =IF(Config!$B$13="","",COUNTIFS(Processos!$D$5:$D$304,Config!$B$13,Processos!$M$5:$M$304,"Sim")) -> 0 | H12: =IF(Config!$D$13="","",Config!$D$13) -> Empresarial | I12: =IF(Config!$D$13="","",COUNTIFS(Processos!$A$5:$A$304,"<>",Processos!$C$5:$C$304,Config!$D$13,Processos!$D$5:$D$304,"<>Encerrado")) -> 6 | J12: =IF(Config!$D$13="","",COUNTIFS(Processos!$C$5:$C$304,Config!$D$13,Processos!$D$5:$D$304,"Encerrado")) -> 2 | K12: =IF(Config!$D$13="","",COUNTIFS(Processos!$C$5:$C$304,Config!$D$13,Processos!$K$5:$K$304,"Atrasado")) -> 0 | L12: =IF(Config!$D$13="","",COUNTIFS(Processos!$C$5:$C$304,Config!$D$13,Processos!$M$5:$M$304,"Sim")) -> 0
A13: =IF(Config!$B$14="","",Config!$B$14) -> Recurso | B13: =IF(Config!$B$14="","",COUNTIFS(Processos!$A$5:$A$304,"<>",Processos!$D$5:$D$304,Config!$B$14)) -> 3 | C13: =IF(Config!$B$14="","",COUNTIFS(Processos!$D$5:$D$304,Config!$B$14,Processos!$K$5:$K$304,"Atrasado")) -> 1 | D13: =IF(Config!$B$14="","",COUNTIFS(Processos!$D$5:$D$304,Config!$B$14,Processos!$K$5:$K$304,"Hoje")+COUNTIFS(Processos!$D$5:$D$304,Config!$B$14,Processos!$K$5:$K$304,"Esta semana")) -> 0 | E13: =IF(Config!$B$14="","",COUNTIFS(Processos!$D$5:$D$304,Config!$B$14,Processos!$K$5:$K$304,"Sem próxima ação")) -> 0 | F13: =IF(Config!$B$14="","",COUNTIFS(Processos!$D$5:$D$304,Config!$B$14,Processos!$M$5:$M$304,"Sim")) -> 0 | H13: =IF(Config!$D$14="","",Config!$D$14) -> Família | I13: =IF(Config!$D$14="","",COUNTIFS(Processos!$A$5:$A$304,"<>",Processos!$C$5:$C$304,Config!$D$14,Processos!$D$5:$D$304,"<>Encerrado")) -> 2 | J13: =IF(Config!$D$14="","",COUNTIFS(Processos!$C$5:$C$304,Config!$D$14,Processos!$D$5:$D$304,"Encerrado")) -> 1 | K13: =IF(Config!$D$14="","",COUNTIFS(Processos!$C$5:$C$304,Config!$D$14,Processos!$K$5:$K$304,"Atrasado")) -> 1 | L13: =IF(Config!$D$14="","",COUNTIFS(Processos!$C$5:$C$304,Config!$D$14,Processos!$M$5:$M$304,"Sim")) -> 0
A14: =IF(Config!$B$15="","",Config!$B$15) -> Execução | B14: =IF(Config!$B$15="","",COUNTIFS(Processos!$A$5:$A$304,"<>",Processos!$D$5:$D$304,Config!$B$15)) -> 3 | C14: =IF(Config!$B$15="","",COUNTIFS(Processos!$D$5:$D$304,Config!$B$15,Processos!$K$5:$K$304,"Atrasado")) -> 1 | D14: =IF(Config!$B$15="","",COUNTIFS(Processos!$D$5:$D$304,Config!$B$15,Processos!$K$5:$K$304,"Hoje")+COUNTIFS(Processos!$D$5:$D$304,Config!$B$15,Processos!$K$5:$K$304,"Esta semana")) -> 0 | E14: =IF(Config!$B$15="","",COUNTIFS(Processos!$D$5:$D$304,Config!$B$15,Processos!$K$5:$K$304,"Sem próxima ação")) -> 0 | F14: =IF(Config!$B$15="","",COUNTIFS(Processos!$D$5:$D$304,Config!$B$15,Processos!$M$5:$M$304,"Sim")) -> 2 | H14: =IF(Config!$D$15="","",Config!$D$15) | I14: =IF(Config!$D$15="","",COUNTIFS(Processos!$A$5:$A$304,"<>",Processos!$C$5:$C$304,Config!$D$15,Processos!$D$5:$D$304,"<>Encerrado")) | J14: =IF(Config!$D$15="","",COUNTIFS(Processos!$C$5:$C$304,Config!$D$15,Processos!$D$5:$D$304,"Encerrado")) | K14: =IF(Config!$D$15="","",COUNTIFS(Processos!$C$5:$C$304,Config!$D$15,Processos!$K$5:$K$304,"Atrasado")) | L14: =IF(Config!$D$15="","",COUNTIFS(Processos!$C$5:$C$304,Config!$D$15,Processos!$M$5:$M$304,"Sim"))
A15: =IF(Config!$B$16="","",Config!$B$16) -> Acordo | B15: =IF(Config!$B$16="","",COUNTIFS(Processos!$A$5:$A$304,"<>",Processos!$D$5:$D$304,Config!$B$16)) -> 2 | C15: =IF(Config!$B$16="","",COUNTIFS(Processos!$D$5:$D$304,Config!$B$16,Processos!$K$5:$K$304,"Atrasado")) -> 0 | D15: =IF(Config!$B$16="","",COUNTIFS(Processos!$D$5:$D$304,Config!$B$16,Processos!$K$5:$K$304,"Hoje")+COUNTIFS(Processos!$D$5:$D$304,Config!$B$16,Processos!$K$5:$K$304,"Esta semana")) -> 1 | E15: =IF(Config!$B$16="","",COUNTIFS(Processos!$D$5:$D$304,Config!$B$16,Processos!$K$5:$K$304,"Sem próxima ação")) -> 0 | F15: =IF(Config!$B$16="","",COUNTIFS(Processos!$D$5:$D$304,Config!$B$16,Processos!$M$5:$M$304,"Sim")) -> 1 | H15: =IF(Config!$D$16="","",Config!$D$16) | I15: =IF(Config!$D$16="","",COUNTIFS(Processos!$A$5:$A$304,"<>",Processos!$C$5:$C$304,Config!$D$16,Processos!$D$5:$D$304,"<>Encerrado")) | J15: =IF(Config!$D$16="","",COUNTIFS(Processos!$C$5:$C$304,Config!$D$16,Processos!$D$5:$D$304,"Encerrado")) | K15: =IF(Config!$D$16="","",COUNTIFS(Processos!$C$5:$C$304,Config!$D$16,Processos!$K$5:$K$304,"Atrasado")) | L15: =IF(Config!$D$16="","",COUNTIFS(Processos!$C$5:$C$304,Config!$D$16,Processos!$M$5:$M$304,"Sim"))
A16: =IF(Config!$B$17="","",Config!$B$17) -> Encerrado | B16: =IF(Config!$B$17="","",COUNTIFS(Processos!$A$5:$A$304,"<>",Processos!$D$5:$D$304,Config!$B$17)) -> 8 | C16: =IF(Config!$B$17="","",COUNTIFS(Processos!$D$5:$D$304,Config!$B$17,Processos!$K$5:$K$304,"Atrasado")) -> 0 | D16: =IF(Config!$B$17="","",COUNTIFS(Processos!$D$5:$D$304,Config!$B$17,Processos!$K$5:$K$304,"Hoje")+COUNTIFS(Processos!$D$5:$D$304,Config!$B$17,Processos!$K$5:$K$304,"Esta semana")) -> 0 | E16: =IF(Config!$B$17="","",COUNTIFS(Processos!$D$5:$D$304,Config!$B$17,Processos!$K$5:$K$304,"Sem próxima ação")) -> 0 | F16: =IF(Config!$B$17="","",COUNTIFS(Processos!$D$5:$D$304,Config!$B$17,Processos!$M$5:$M$304,"Sim")) -> 0 | H16: =IF(Config!$D$17="","",Config!$D$17) | I16: =IF(Config!$D$17="","",COUNTIFS(Processos!$A$5:$A$304,"<>",Processos!$C$5:$C$304,Config!$D$17,Processos!$D$5:$D$304,"<>Encerrado")) | J16: =IF(Config!$D$17="","",COUNTIFS(Processos!$C$5:$C$304,Config!$D$17,Processos!$D$5:$D$304,"Encerrado")) | K16: =IF(Config!$D$17="","",COUNTIFS(Processos!$C$5:$C$304,Config!$D$17,Processos!$K$5:$K$304,"Atrasado")) | L16: =IF(Config!$D$17="","",COUNTIFS(Processos!$C$5:$C$304,Config!$D$17,Processos!$M$5:$M$304,"Sim"))
A17: =IF(Config!$B$18="","",Config!$B$18) | B17: =IF(Config!$B$18="","",COUNTIFS(Processos!$A$5:$A$304,"<>",Processos!$D$5:$D$304,Config!$B$18)) | C17: =IF(Config!$B$18="","",COUNTIFS(Processos!$D$5:$D$304,Config!$B$18,Processos!$K$5:$K$304,"Atrasado")) | D17: =IF(Config!$B$18="","",COUNTIFS(Processos!$D$5:$D$304,Config!$B$18,Processos!$K$5:$K$304,"Hoje")+COUNTIFS(Processos!$D$5:$D$304,Config!$B$18,Processos!$K$5:$K$304,"Esta semana")) | E17: =IF(Config!$B$18="","",COUNTIFS(Processos!$D$5:$D$304,Config!$B$18,Processos!$K$5:$K$304,"Sem próxima ação")) | F17: =IF(Config!$B$18="","",COUNTIFS(Processos!$D$5:$D$304,Config!$B$18,Processos!$M$5:$M$304,"Sim")) | H17: =IF(Config!$D$18="","",Config!$D$18) | I17: =IF(Config!$D$18="","",COUNTIFS(Processos!$A$5:$A$304,"<>",Processos!$C$5:$C$304,Config!$D$18,Processos!$D$5:$D$304,"<>Encerrado")) | J17: =IF(Config!$D$18="","",COUNTIFS(Processos!$C$5:$C$304,Config!$D$18,Processos!$D$5:$D$304,"Encerrado")) | K17: =IF(Config!$D$18="","",COUNTIFS(Processos!$C$5:$C$304,Config!$D$18,Processos!$K$5:$K$304,"Atrasado")) | L17: =IF(Config!$D$18="","",COUNTIFS(Processos!$C$5:$C$304,Config!$D$18,Processos!$M$5:$M$304,"Sim"))
A18: =IF(Config!$B$19="","",Config!$B$19) | B18: =IF(Config!$B$19="","",COUNTIFS(Processos!$A$5:$A$304,"<>",Processos!$D$5:$D$304,Config!$B$19)) | C18: =IF(Config!$B$19="","",COUNTIFS(Processos!$D$5:$D$304,Config!$B$19,Processos!$K$5:$K$304,"Atrasado")) | D18: =IF(Config!$B$19="","",COUNTIFS(Processos!$D$5:$D$304,Config!$B$19,Processos!$K$5:$K$304,"Hoje")+COUNTIFS(Processos!$D$5:$D$304,Config!$B$19,Processos!$K$5:$K$304,"Esta semana")) | E18: =IF(Config!$B$19="","",COUNTIFS(Processos!$D$5:$D$304,Config!$B$19,Processos!$K$5:$K$304,"Sem próxima ação")) | F18: =IF(Config!$B$19="","",COUNTIFS(Processos!$D$5:$D$304,Config!$B$19,Processos!$M$5:$M$304,"Sim")) | H18: =IF(Config!$D$19="","",Config!$D$19) | I18: =IF(Config!$D$19="","",COUNTIFS(Processos!$A$5:$A$304,"<>",Processos!$C$5:$C$304,Config!$D$19,Processos!$D$5:$D$304,"<>Encerrado")) | J18: =IF(Config!$D$19="","",COUNTIFS(Processos!$C$5:$C$304,Config!$D$19,Processos!$D$5:$D$304,"Encerrado")) | K18: =IF(Config!$D$19="","",COUNTIFS(Processos!$C$5:$C$304,Config!$D$19,Processos!$K$5:$K$304,"Atrasado")) | L18: =IF(Config!$D$19="","",COUNTIFS(Processos!$C$5:$C$304,Config!$D$19,Processos!$M$5:$M$304,"Sim"))
A21: Por responsável
A22: Responsável | B22: Casos ativos | C22: Ação atrasada | D22: Esta semana | E22: Sem próxima ação | F22: Parados | G22: Próxima ação a partir de hoje
A23: =IF(Config!$F$10="","",Config!$F$10) -> Marina Ferraz | B23: =IF(Config!$F$10="","",COUNTIFS(Processos!$A$5:$A$304,"<>",Processos!$E$5:$E$304,Config!$F$10,Processos!$D$5:$D$304,"<>Encerrado")) -> 15 | C23: =IF(Config!$F$10="","",COUNTIFS(Processos!$E$5:$E$304,Config!$F$10,Processos!$K$5:$K$304,"Atrasado")) -> 4 | D23: =IF(Config!$F$10="","",COUNTIFS(Processos!$E$5:$E$304,Config!$F$10,Processos!$K$5:$K$304,"Hoje")+COUNTIFS(Processos!$E$5:$E$304,Config!$F$10,Processos!$K$5:$K$304,"Esta semana")) -> 6 | E23: =IF(Config!$F$10="","",COUNTIFS(Processos!$E$5:$E$304,Config!$F$10,Processos!$K$5:$K$304,"Sem próxima ação")) -> 0 | F23: =IF(Config!$F$10="","",COUNTIFS(Processos!$E$5:$E$304,Config!$F$10,Processos!$M$5:$M$304,"Sim")) -> 1 | G23: =IF(Config!$F$10="","",IFERROR(IF(SUMPRODUCT(MIN(((Processos!$E$5:$E$304=Config!$F$10)*(Processos!$D$5:$D$304<>"Encerrado")*(Processos!$G$5:$G$304>=Config!$B$5))*Processos!$G$5:$G$304+(1-((Processos!$E$5:$E$304=Config!$F$10)*(Processos!$D$5:$D$304<>"Encerrado")*(Processos!$G$5:$G$304>=Config!$B$5)))*1E+10))>=1E+10,"",SUMPRODUCT(MIN(((Processos!$E$5:$E$304=Config!$F$10)*(Processos!$D$5:$D$304<>"Encerrado")*(Processos!$G$5:$G$304>=Config!$B$5))*Processos!$G$5:$G$304+(1-((Processos!$E$5:$E$304=Config!$F$10)*(Processos!$D$5:$D$304<>"Encerrado")*(Processos!$G$5:$G$304>=Config!$B$5)))*1E+10))),"")) -> 46279
A24: =IF(Config!$F$11="","",Config!$F$11) -> Rafael Lima | B24: =IF(Config!$F$11="","",COUNTIFS(Processos!$A$5:$A$304,"<>",Processos!$E$5:$E$304,Config!$F$11,Processos!$D$5:$D$304,"<>Encerrado")) -> 15 | C24: =IF(Config!$F$11="","",COUNTIFS(Processos!$E$5:$E$304,Config!$F$11,Processos!$K$5:$K$304,"Atrasado")) -> 3 | D24: =IF(Config!$F$11="","",COUNTIFS(Processos!$E$5:$E$304,Config!$F$11,Processos!$K$5:$K$304,"Hoje")+COUNTIFS(Processos!$E$5:$E$304,Config!$F$11,Processos!$K$5:$K$304,"Esta semana")) -> 6 | E24: =IF(Config!$F$11="","",COUNTIFS(Processos!$E$5:$E$304,Config!$F$11,Processos!$K$5:$K$304,"Sem próxima ação")) -> 0 | F24: =IF(Config!$F$11="","",COUNTIFS(Processos!$E$5:$E$304,Config!$F$11,Processos!$M$5:$M$304,"Sim")) -> 3 | G24: =IF(Config!$F$11="","",IFERROR(IF(SUMPRODUCT(MIN(((Processos!$E$5:$E$304=Config!$F$11)*(Processos!$D$5:$D$304<>"Encerrado")*(Processos!$G$5:$G$304>=Config!$B$5))*Processos!$G$5:$G$304+(1-((Processos!$E$5:$E$304=Config!$F$11)*(Processos!$D$5:$D$304<>"Encerrado")*(Processos!$G$5:$G$304>=Config!$B$5)))*1E+10))>=1E+10,"",SUMPRODUCT(MIN(((Processos!$E$5:$E$304=Config!$F$11)*(Processos!$D$5:$D$304<>"Encerrado")*(Processos!$G$5:$G$304>=Config!$B$5))*Processos!$G$5:$G$304+(1-((Processos!$E$5:$E$304=Config!$F$11)*(Processos!$D$5:$D$304<>"Encerrado")*(Processos!$G$5:$G$304>=Config!$B$5)))*1E+10))),"")) -> 46279
A25: =IF(Config!$F$12="","",Config!$F$12) -> Júlia Prado | B25: =IF(Config!$F$12="","",COUNTIFS(Processos!$A$5:$A$304,"<>",Processos!$E$5:$E$304,Config!$F$12,Processos!$D$5:$D$304,"<>Encerrado")) -> 0 | C25: =IF(Config!$F$12="","",COUNTIFS(Processos!$E$5:$E$304,Config!$F$12,Processos!$K$5:$K$304,"Atrasado")) -> 0 | D25: =IF(Config!$F$12="","",COUNTIFS(Processos!$E$5:$E$304,Config!$F$12,Processos!$K$5:$K$304,"Hoje")+COUNTIFS(Processos!$E$5:$E$304,Config!$F$12,Processos!$K$5:$K$304,"Esta semana")) -> 0 | E25: =IF(Config!$F$12="","",COUNTIFS(Processos!$E$5:$E$304,Config!$F$12,Processos!$K$5:$K$304,"Sem próxima ação")) -> 0 | F25: =IF(Config!$F$12="","",COUNTIFS(Processos!$E$5:$E$304,Config!$F$12,Processos!$M$5:$M$304,"Sim")) -> 0 | G25: =IF(Config!$F$12="","",IFERROR(IF(SUMPRODUCT(MIN(((Processos!$E$5:$E$304=Config!$F$12)*(Processos!$D$5:$D$304<>"Encerrado")*(Processos!$G$5:$G$304>=Config!$B$5))*Processos!$G$5:$G$304+(1-((Processos!$E$5:$E$304=Config!$F$12)*(Processos!$D$5:$D$304<>"Encerrado")*(Processos!$G$5:$G$304>=Config!$B$5)))*1E+10))>=1E+10,"",SUMPRODUCT(MIN(((Processos!$E$5:$E$304=Config!$F$12)*(Processos!$D$5:$D$304<>"Encerrado")*(Processos!$G$5:$G$304>=Config!$B$5))*Processos!$G$5:$G$304+(1-((Processos!$E$5:$E$304=Config!$F$12)*(Processos!$D$5:$D$304<>"Encerrado")*(Processos!$G$5:$G$304>=Config!$B$5)))*1E+10))),""))
A26: =IF(Config!$F$13="","",Config!$F$13) | B26: =IF(Config!$F$13="","",COUNTIFS(Processos!$A$5:$A$304,"<>",Processos!$E$5:$E$304,Config!$F$13,Processos!$D$5:$D$304,"<>Encerrado")) | C26: =IF(Config!$F$13="","",COUNTIFS(Processos!$E$5:$E$304,Config!$F$13,Processos!$K$5:$K$304,"Atrasado")) | D26: =IF(Config!$F$13="","",COUNTIFS(Processos!$E$5:$E$304,Config!$F$13,Processos!$K$5:$K$304,"Hoje")+COUNTIFS(Processos!$E$5:$E$304,Config!$F$13,Processos!$K$5:$K$304,"Esta semana")) | E26: =IF(Config!$F$13="","",COUNTIFS(Processos!$E$5:$E$304,Config!$F$13,Processos!$K$5:$K$304,"Sem próxima ação")) | F26: =IF(Config!$F$13="","",COUNTIFS(Processos!$E$5:$E$304,Config!$F$13,Processos!$M$5:$M$304,"Sim")) | G26: =IF(Config!$F$13="","",IFERROR(IF(SUMPRODUCT(MIN(((Processos!$E$5:$E$304=Config!$F$13)*(Processos!$D$5:$D$304<>"Encerrado")*(Processos!$G$5:$G$304>=Config!$B$5))*Processos!$G$5:$G$304+(1-((Processos!$E$5:$E$304=Config!$F$13)*(Processos!$D$5:$D$304<>"Encerrado")*(Processos!$G$5:$G$304>=Config!$B$5)))*1E+10))>=1E+10,"",SUMPRODUCT(MIN(((Processos!$E$5:$E$304=Config!$F$13)*(Processos!$D$5:$D$304<>"Encerrado")*(Processos!$G$5:$G$304>=Config!$B$5))*Processos!$G$5:$G$304+(1-((Processos!$E$5:$E$304=Config!$F$13)*(Processos!$D$5:$D$304<>"Encerrado")*(Processos!$G$5:$G$304>=Config!$B$5)))*1E+10))),""))
A27: =IF(Config!$F$14="","",Config!$F$14) | B27: =IF(Config!$F$14="","",COUNTIFS(Processos!$A$5:$A$304,"<>",Processos!$E$5:$E$304,Config!$F$14,Processos!$D$5:$D$304,"<>Encerrado")) | C27: =IF(Config!$F$14="","",COUNTIFS(Processos!$E$5:$E$304,Config!$F$14,Processos!$K$5:$K$304,"Atrasado")) | D27: =IF(Config!$F$14="","",COUNTIFS(Processos!$E$5:$E$304,Config!$F$14,Processos!$K$5:$K$304,"Hoje")+COUNTIFS(Processos!$E$5:$E$304,Config!$F$14,Processos!$K$5:$K$304,"Esta semana")) | E27: =IF(Config!$F$14="","",COUNTIFS(Processos!$E$5:$E$304,Config!$F$14,Processos!$K$5:$K$304,"Sem próxima ação")) | F27: =IF(Config!$F$14="","",COUNTIFS(Processos!$E$5:$E$304,Config!$F$14,Processos!$M$5:$M$304,"Sim")) | G27: =IF(Config!$F$14="","",IFERROR(IF(SUMPRODUCT(MIN(((Processos!$E$5:$E$304=Config!$F$14)*(Processos!$D$5:$D$304<>"Encerrado")*(Processos!$G$5:$G$304>=Config!$B$5))*Processos!$G$5:$G$304+(1-((Processos!$E$5:$E$304=Config!$F$14)*(Processos!$D$5:$D$304<>"Encerrado")*(Processos!$G$5:$G$304>=Config!$B$5)))*1E+10))>=1E+10,"",SUMPRODUCT(MIN(((Processos!$E$5:$E$304=Config!$F$14)*(Processos!$D$5:$D$304<>"Encerrado")*(Processos!$G$5:$G$304>=Config!$B$5))*Processos!$G$5:$G$304+(1-((Processos!$E$5:$E$304=Config!$F$14)*(Processos!$D$5:$D$304<>"Encerrado")*(Processos!$G$5:$G$304>=Config!$B$5)))*1E+10))),""))
A28: =IF(Config!$F$15="","",Config!$F$15) | B28: =IF(Config!$F$15="","",COUNTIFS(Processos!$A$5:$A$304,"<>",Processos!$E$5:$E$304,Config!$F$15,Processos!$D$5:$D$304,"<>Encerrado")) | C28: =IF(Config!$F$15="","",COUNTIFS(Processos!$E$5:$E$304,Config!$F$15,Processos!$K$5:$K$304,"Atrasado")) | D28: =IF(Config!$F$15="","",COUNTIFS(Processos!$E$5:$E$304,Config!$F$15,Processos!$K$5:$K$304,"Hoje")+COUNTIFS(Processos!$E$5:$E$304,Config!$F$15,Processos!$K$5:$K$304,"Esta semana")) | E28: =IF(Config!$F$15="","",COUNTIFS(Processos!$E$5:$E$304,Config!$F$15,Processos!$K$5:$K$304,"Sem próxima ação")) | F28: =IF(Config!$F$15="","",COUNTIFS(Processos!$E$5:$E$304,Config!$F$15,Processos!$M$5:$M$304,"Sim")) | G28: =IF(Config!$F$15="","",IFERROR(IF(SUMPRODUCT(MIN(((Processos!$E$5:$E$304=Config!$F$15)*(Processos!$D$5:$D$304<>"Encerrado")*(Processos!$G$5:$G$304>=Config!$B$5))*Processos!$G$5:$G$304+(1-((Processos!$E$5:$E$304=Config!$F$15)*(Processos!$D$5:$D$304<>"Encerrado")*(Processos!$G$5:$G$304>=Config!$B$5)))*1E+10))>=1E+10,"",SUMPRODUCT(MIN(((Processos!$E$5:$E$304=Config!$F$15)*(Processos!$D$5:$D$304<>"Encerrado")*(Processos!$G$5:$G$304>=Config!$B$5))*Processos!$G$5:$G$304+(1-((Processos!$E$5:$E$304=Config!$F$15)*(Processos!$D$5:$D$304<>"Encerrado")*(Processos!$G$5:$G$304>=Config!$B$5)))*1E+10))),""))
A29: =IF(Config!$F$16="","",Config!$F$16) | B29: =IF(Config!$F$16="","",COUNTIFS(Processos!$A$5:$A$304,"<>",Processos!$E$5:$E$304,Config!$F$16,Processos!$D$5:$D$304,"<>Encerrado")) | C29: =IF(Config!$F$16="","",COUNTIFS(Processos!$E$5:$E$304,Config!$F$16,Processos!$K$5:$K$304,"Atrasado")) | D29: =IF(Config!$F$16="","",COUNTIFS(Processos!$E$5:$E$304,Config!$F$16,Processos!$K$5:$K$304,"Hoje")+COUNTIFS(Processos!$E$5:$E$304,Config!$F$16,Processos!$K$5:$K$304,"Esta semana")) | E29: =IF(Config!$F$16="","",COUNTIFS(Processos!$E$5:$E$304,Config!$F$16,Processos!$K$5:$K$304,"Sem próxima ação")) | F29: =IF(Config!$F$16="","",COUNTIFS(Processos!$E$5:$E$304,Config!$F$16,Processos!$M$5:$M$304,"Sim")) | G29: =IF(Config!$F$16="","",IFERROR(IF(SUMPRODUCT(MIN(((Processos!$E$5:$E$304=Config!$F$16)*(Processos!$D$5:$D$304<>"Encerrado")*(Processos!$G$5:$G$304>=Config!$B$5))*Processos!$G$5:$G$304+(1-((Processos!$E$5:$E$304=Config!$F$16)*(Processos!$D$5:$D$304<>"Encerrado")*(Processos!$G$5:$G$304>=Config!$B$5)))*1E+10))>=1E+10,"",SUMPRODUCT(MIN(((Processos!$E$5:$E$304=Config!$F$16)*(Processos!$D$5:$D$304<>"Encerrado")*(Processos!$G$5:$G$304>=Config!$B$5))*Processos!$G$5:$G$304+(1-((Processos!$E$5:$E$304=Config!$F$16)*(Processos!$D$5:$D$304<>"Encerrado")*(Processos!$G$5:$G$304>=Config!$B$5)))*1E+10))),""))
A30: =IF(Config!$F$17="","",Config!$F$17) | B30: =IF(Config!$F$17="","",COUNTIFS(Processos!$A$5:$A$304,"<>",Processos!$E$5:$E$304,Config!$F$17,Processos!$D$5:$D$304,"<>Encerrado")) | C30: =IF(Config!$F$17="","",COUNTIFS(Processos!$E$5:$E$304,Config!$F$17,Processos!$K$5:$K$304,"Atrasado")) | D30: =IF(Config!$F$17="","",COUNTIFS(Processos!$E$5:$E$304,Config!$F$17,Processos!$K$5:$K$304,"Hoje")+COUNTIFS(Processos!$E$5:$E$304,Config!$F$17,Processos!$K$5:$K$304,"Esta semana")) | E30: =IF(Config!$F$17="","",COUNTIFS(Processos!$E$5:$E$304,Config!$F$17,Processos!$K$5:$K$304,"Sem próxima ação")) | F30: =IF(Config!$F$17="","",COUNTIFS(Processos!$E$5:$E$304,Config!$F$17,Processos!$M$5:$M$304,"Sim")) | G30: =IF(Config!$F$17="","",IFERROR(IF(SUMPRODUCT(MIN(((Processos!$E$5:$E$304=Config!$F$17)*(Processos!$D$5:$D$304<>"Encerrado")*(Processos!$G$5:$G$304>=Config!$B$5))*Processos!$G$5:$G$304+(1-((Processos!$E$5:$E$304=Config!$F$17)*(Processos!$D$5:$D$304<>"Encerrado")*(Processos!$G$5:$G$304>=Config!$B$5)))*1E+10))>=1E+10,"",SUMPRODUCT(MIN(((Processos!$E$5:$E$304=Config!$F$17)*(Processos!$D$5:$D$304<>"Encerrado")*(Processos!$G$5:$G$304>=Config!$B$5))*Processos!$G$5:$G$304+(1-((Processos!$E$5:$E$304=Config!$F$17)*(Processos!$D$5:$D$304<>"Encerrado")*(Processos!$G$5:$G$304>=Config!$B$5)))*1E+10))),""))
A31: =IF(Config!$F$18="","",Config!$F$18) | B31: =IF(Config!$F$18="","",COUNTIFS(Processos!$A$5:$A$304,"<>",Processos!$E$5:$E$304,Config!$F$18,Processos!$D$5:$D$304,"<>Encerrado")) | C31: =IF(Config!$F$18="","",COUNTIFS(Processos!$E$5:$E$304,Config!$F$18,Processos!$K$5:$K$304,"Atrasado")) | D31: =IF(Config!$F$18="","",COUNTIFS(Processos!$E$5:$E$304,Config!$F$18,Processos!$K$5:$K$304,"Hoje")+COUNTIFS(Processos!$E$5:$E$304,Config!$F$18,Processos!$K$5:$K$304,"Esta semana")) | E31: =IF(Config!$F$18="","",COUNTIFS(Processos!$E$5:$E$304,Config!$F$18,Processos!$K$5:$K$304,"Sem próxima ação")) | F31: =IF(Config!$F$18="","",COUNTIFS(Processos!$E$5:$E$304,Config!$F$18,Processos!$M$5:$M$304,"Sim")) | G31: =IF(Config!$F$18="","",IFERROR(IF(SUMPRODUCT(MIN(((Processos!$E$5:$E$304=Config!$F$18)*(Processos!$D$5:$D$304<>"Encerrado")*(Processos!$G$5:$G$304>=Config!$B$5))*Processos!$G$5:$G$304+(1-((Processos!$E$5:$E$304=Config!$F$18)*(Processos!$D$5:$D$304<>"Encerrado")*(Processos!$G$5:$G$304>=Config!$B$5)))*1E+10))>=1E+10,"",SUMPRODUCT(MIN(((Processos!$E$5:$E$304=Config!$F$18)*(Processos!$D$5:$D$304<>"Encerrado")*(Processos!$G$5:$G$304>=Config!$B$5))*Processos!$G$5:$G$304+(1-((Processos!$E$5:$E$304=Config!$F$18)*(Processos!$D$5:$D$304<>"Encerrado")*(Processos!$G$5:$G$304>=Config!$B$5)))*1E+10))),""))
A32: =IF(Config!$F$19="","",Config!$F$19) | B32: =IF(Config!$F$19="","",COUNTIFS(Processos!$A$5:$A$304,"<>",Processos!$E$5:$E$304,Config!$F$19,Processos!$D$5:$D$304,"<>Encerrado")) | C32: =IF(Config!$F$19="","",COUNTIFS(Processos!$E$5:$E$304,Config!$F$19,Processos!$K$5:$K$304,"Atrasado")) | D32: =IF(Config!$F$19="","",COUNTIFS(Processos!$E$5:$E$304,Config!$F$19,Processos!$K$5:$K$304,"Hoje")+COUNTIFS(Processos!$E$5:$E$304,Config!$F$19,Processos!$K$5:$K$304,"Esta semana")) | E32: =IF(Config!$F$19="","",COUNTIFS(Processos!$E$5:$E$304,Config!$F$19,Processos!$K$5:$K$304,"Sem próxima ação")) | F32: =IF(Config!$F$19="","",COUNTIFS(Processos!$E$5:$E$304,Config!$F$19,Processos!$M$5:$M$304,"Sim")) | G32: =IF(Config!$F$19="","",IFERROR(IF(SUMPRODUCT(MIN(((Processos!$E$5:$E$304=Config!$F$19)*(Processos!$D$5:$D$304<>"Encerrado")*(Processos!$G$5:$G$304>=Config!$B$5))*Processos!$G$5:$G$304+(1-((Processos!$E$5:$E$304=Config!$F$19)*(Processos!$D$5:$D$304<>"Encerrado")*(Processos!$G$5:$G$304>=Config!$B$5)))*1E+10))>=1E+10,"",SUMPRODUCT(MIN(((Processos!$E$5:$E$304=Config!$F$19)*(Processos!$D$5:$D$304<>"Encerrado")*(Processos!$G$5:$G$304>=Config!$B$5))*Processos!$G$5:$G$304+(1-((Processos!$E$5:$E$304=Config!$F$19)*(Processos!$D$5:$D$304<>"Encerrado")*(Processos!$G$5:$G$304>=Config!$B$5)))*1E+10))),""))
A33: Próxima ação a partir de hoje: a data mais próxima entre as ações de hoje em diante; as atrasadas estão na coluna "Ação atrasada".
A35: ="Parados há mais de "&Config!$B$6&" dias (os mais antigos primeiro)" -> Parados há mais de 30 dias (os mais antigos primeiro)
A36: Mostra os 12 casos ativos há mais tempo sem atualização. Um caso parado pode estar apenas aguardando o andamento; o painel avisa para que alguém confira.
A37: # | B37: Número | C37: Cliente | D37: Fase | E37: Responsável | F37: Última atualização | G37: Dias parado | H37: Próxima ação
A38: 1 | B38: =IFERROR(IF(LARGE(Processos!$N$5:$N$304,1)>0,IF(INDEX(Processos!$A$5:$A$304,MATCH(LARGE(Processos!$N$5:$N$304,1),Processos!$N$5:$N$304,0))="","",INDEX(Processos!$A$5:$A$304,MATCH(LARGE(Processos!$N$5:$N$304,1),Processos!$N$5:$N$304,0))),""),"") -> 9495290-86.2025.8.26.0503 | C38: =IFERROR(IF(LARGE(Processos!$N$5:$N$304,1)>0,IF(INDEX(Processos!$B$5:$B$304,MATCH(LARGE(Processos!$N$5:$N$304,1),Processos!$N$5:$N$304,0))="","",INDEX(Processos!$B$5:$B$304,MATCH(LARGE(Processos!$N$5:$N$304,1),Processos!$N$5:$N$304,0))),""),"") -> Helena Duarte | D38: =IFERROR(IF(LARGE(Processos!$N$5:$N$304,1)>0,IF(INDEX(Processos!$D$5:$D$304,MATCH(LARGE(Processos!$N$5:$N$304,1),Processos!$N$5:$N$304,0))="","",INDEX(Processos!$D$5:$D$304,MATCH(LARGE(Processos!$N$5:$N$304,1),Processos!$N$5:$N$304,0))),""),"") -> Execução | E38: =IFERROR(IF(LARGE(Processos!$N$5:$N$304,1)>0,IF(INDEX(Processos!$E$5:$E$304,MATCH(LARGE(Processos!$N$5:$N$304,1),Processos!$N$5:$N$304,0))="","",INDEX(Processos!$E$5:$E$304,MATCH(LARGE(Processos!$N$5:$N$304,1),Processos!$N$5:$N$304,0))),""),"") -> Rafael Lima | F38: =IFERROR(IF(LARGE(Processos!$N$5:$N$304,1)>0,IF(INDEX(Processos!$H$5:$H$304,MATCH(LARGE(Processos!$N$5:$N$304,1),Processos!$N$5:$N$304,0))="","",INDEX(Processos!$H$5:$H$304,MATCH(LARGE(Processos!$N$5:$N$304,1),Processos!$N$5:$N$304,0))),""),"") -> 46232 | G38: =IFERROR(IF(LARGE(Processos!$N$5:$N$304,1)>0,IF(INDEX(Processos!$L$5:$L$304,MATCH(LARGE(Processos!$N$5:$N$304,1),Processos!$N$5:$N$304,0))="","",INDEX(Processos!$L$5:$L$304,MATCH(LARGE(Processos!$N$5:$N$304,1),Processos!$N$5:$N$304,0))),""),"") -> 47 | H38: =IFERROR(IF(LARGE(Processos!$N$5:$N$304,1)>0,IF(INDEX(Processos!$F$5:$F$304,MATCH(LARGE(Processos!$N$5:$N$304,1),Processos!$N$5:$N$304,0))="","",INDEX(Processos!$F$5:$F$304,MATCH(LARGE(Processos!$N$5:$N$304,1),Processos!$N$5:$N$304,0))),""),"") -> Iniciar o cumprimento de sentença
A39: 2 | B39: =IFERROR(IF(LARGE(Processos!$N$5:$N$304,2)>0,IF(INDEX(Processos!$A$5:$A$304,MATCH(LARGE(Processos!$N$5:$N$304,2),Processos!$N$5:$N$304,0))="","",INDEX(Processos!$A$5:$A$304,MATCH(LARGE(Processos!$N$5:$N$304,2),Processos!$N$5:$N$304,0))),""),"") -> 9236009-85.2025.8.26.0452 | C39: =IFERROR(IF(LARGE(Processos!$N$5:$N$304,2)>0,IF(INDEX(Processos!$B$5:$B$304,MATCH(LARGE(Processos!$N$5:$N$304,2),Processos!$N$5:$N$304,0))="","",INDEX(Processos!$B$5:$B$304,MATCH(LARGE(Processos!$N$5:$N$304,2),Processos!$N$5:$N$304,0))),""),"") -> Bistrô 42 | D39: =IFERROR(IF(LARGE(Processos!$N$5:$N$304,2)>0,IF(INDEX(Processos!$D$5:$D$304,MATCH(LARGE(Processos!$N$5:$N$304,2),Processos!$N$5:$N$304,0))="","",INDEX(Processos!$D$5:$D$304,MATCH(LARGE(Processos!$N$5:$N$304,2),Processos!$N$5:$N$304,0))),""),"") -> Execução | E39: =IFERROR(IF(LARGE(Processos!$N$5:$N$304,2)>0,IF(INDEX(Processos!$E$5:$E$304,MATCH(LARGE(Processos!$N$5:$N$304,2),Processos!$N$5:$N$304,0))="","",INDEX(Processos!$E$5:$E$304,MATCH(LARGE(Processos!$N$5:$N$304,2),Processos!$N$5:$N$304,0))),""),"") -> Rafael Lima | F39: =IFERROR(IF(LARGE(Processos!$N$5:$N$304,2)>0,IF(INDEX(Processos!$H$5:$H$304,MATCH(LARGE(Processos!$N$5:$N$304,2),Processos!$N$5:$N$304,0))="","",INDEX(Processos!$H$5:$H$304,MATCH(LARGE(Processos!$N$5:$N$304,2),Processos!$N$5:$N$304,0))),""),"") -> 46238 | G39: =IFERROR(IF(LARGE(Processos!$N$5:$N$304,2)>0,IF(INDEX(Processos!$L$5:$L$304,MATCH(LARGE(Processos!$N$5:$N$304,2),Processos!$N$5:$N$304,0))="","",INDEX(Processos!$L$5:$L$304,MATCH(LARGE(Processos!$N$5:$N$304,2),Processos!$N$5:$N$304,0))),""),"") -> 41 | H39: =IFERROR(IF(LARGE(Processos!$N$5:$N$304,2)>0,IF(INDEX(Processos!$F$5:$F$304,MATCH(LARGE(Processos!$N$5:$N$304,2),Processos!$N$5:$N$304,0))="","",INDEX(Processos!$F$5:$F$304,MATCH(LARGE(Processos!$N$5:$N$304,2),Processos!$N$5:$N$304,0))),""),"") -> Iniciar o cumprimento de sentença
A40: 3 | B40: =IFERROR(IF(LARGE(Processos!$N$5:$N$304,3)>0,IF(INDEX(Processos!$A$5:$A$304,MATCH(LARGE(Processos!$N$5:$N$304,3),Processos!$N$5:$N$304,0))="","",INDEX(Processos!$A$5:$A$304,MATCH(LARGE(Processos!$N$5:$N$304,3),Processos!$N$5:$N$304,0))),""),"") -> 6184138-13.2026.8.26.0378 | C40: =IFERROR(IF(LARGE(Processos!$N$5:$N$304,3)>0,IF(INDEX(Processos!$B$5:$B$304,MATCH(LARGE(Processos!$N$5:$N$304,3),Processos!$N$5:$N$304,0))="","",INDEX(Processos!$B$5:$B$304,MATCH(LARGE(Processos!$N$5:$N$304,3),Processos!$N$5:$N$304,0))),""),"") -> Oficina Mecânica Central | D40: =IFERROR(IF(LARGE(Processos!$N$5:$N$304,3)>0,IF(INDEX(Processos!$D$5:$D$304,MATCH(LARGE(Processos!$N$5:$N$304,3),Processos!$N$5:$N$304,0))="","",INDEX(Processos!$D$5:$D$304,MATCH(LARGE(Processos!$N$5:$N$304,3),Processos!$N$5:$N$304,0))),""),"") -> Inicial | E40: =IFERROR(IF(LARGE(Processos!$N$5:$N$304,3)>0,IF(INDEX(Processos!$E$5:$E$304,MATCH(LARGE(Processos!$N$5:$N$304,3),Processos!$N$5:$N$304,0))="","",INDEX(Processos!$E$5:$E$304,MATCH(LARGE(Processos!$N$5:$N$304,3),Processos!$N$5:$N$304,0))),""),"") -> Rafael Lima | F40: =IFERROR(IF(LARGE(Processos!$N$5:$N$304,3)>0,IF(INDEX(Processos!$H$5:$H$304,MATCH(LARGE(Processos!$N$5:$N$304,3),Processos!$N$5:$N$304,0))="","",INDEX(Processos!$H$5:$H$304,MATCH(LARGE(Processos!$N$5:$N$304,3),Processos!$N$5:$N$304,0))),""),"") -> 46243 | G40: =IFERROR(IF(LARGE(Processos!$N$5:$N$304,3)>0,IF(INDEX(Processos!$L$5:$L$304,MATCH(LARGE(Processos!$N$5:$N$304,3),Processos!$N$5:$N$304,0))="","",INDEX(Processos!$L$5:$L$304,MATCH(LARGE(Processos!$N$5:$N$304,3),Processos!$N$5:$N$304,0))),""),"") -> 36 | H40: =IFERROR(IF(LARGE(Processos!$N$5:$N$304,3)>0,IF(INDEX(Processos!$F$5:$F$304,MATCH(LARGE(Processos!$N$5:$N$304,3),Processos!$N$5:$N$304,0))="","",INDEX(Processos!$F$5:$F$304,MATCH(LARGE(Processos!$N$5:$N$304,3),Processos!$N$5:$N$304,0))),""),"") -> Audiência de conciliação (confirmar presença do cliente)
A41: 4 | B41: =IFERROR(IF(LARGE(Processos!$N$5:$N$304,4)>0,IF(INDEX(Processos!$A$5:$A$304,MATCH(LARGE(Processos!$N$5:$N$304,4),Processos!$N$5:$N$304,0))="","",INDEX(Processos!$A$5:$A$304,MATCH(LARGE(Processos!$N$5:$N$304,4),Processos!$N$5:$N$304,0))),""),"") -> 2521428-61.2026.8.26.0600 | C41: =IFERROR(IF(LARGE(Processos!$N$5:$N$304,4)>0,IF(INDEX(Processos!$B$5:$B$304,MATCH(LARGE(Processos!$N$5:$N$304,4),Processos!$N$5:$N$304,0))="","",INDEX(Processos!$B$5:$B$304,MATCH(LARGE(Processos!$N$5:$N$304,4),Processos!$N$5:$N$304,0))),""),"") -> Luciana Farias | D41: =IFERROR(IF(LARGE(Processos!$N$5:$N$304,4)>0,IF(INDEX(Processos!$D$5:$D$304,MATCH(LARGE(Processos!$N$5:$N$304,4),Processos!$N$5:$N$304,0))="","",INDEX(Processos!$D$5:$D$304,MATCH(LARGE(Processos!$N$5:$N$304,4),Processos!$N$5:$N$304,0))),""),"") -> Acordo | E41: =IFERROR(IF(LARGE(Processos!$N$5:$N$304,4)>0,IF(INDEX(Processos!$E$5:$E$304,MATCH(LARGE(Processos!$N$5:$N$304,4),Processos!$N$5:$N$304,0))="","",INDEX(Processos!$E$5:$E$304,MATCH(LARGE(Processos!$N$5:$N$304,4),Processos!$N$5:$N$304,0))),""),"") -> Marina Ferraz | F41: =IFERROR(IF(LARGE(Processos!$N$5:$N$304,4)>0,IF(INDEX(Processos!$H$5:$H$304,MATCH(LARGE(Processos!$N$5:$N$304,4),Processos!$N$5:$N$304,0))="","",INDEX(Processos!$H$5:$H$304,MATCH(LARGE(Processos!$N$5:$N$304,4),Processos!$N$5:$N$304,0))),""),"") -> 46246 | G41: =IFERROR(IF(LARGE(Processos!$N$5:$N$304,4)>0,IF(INDEX(Processos!$L$5:$L$304,MATCH(LARGE(Processos!$N$5:$N$304,4),Processos!$N$5:$N$304,0))="","",INDEX(Processos!$L$5:$L$304,MATCH(LARGE(Processos!$N$5:$N$304,4),Processos!$N$5:$N$304,0))),""),"") -> 33 | H41: =IFERROR(IF(LARGE(Processos!$N$5:$N$304,4)>0,IF(INDEX(Processos!$F$5:$F$304,MATCH(LARGE(Processos!$N$5:$N$304,4),Processos!$N$5:$N$304,0))="","",INDEX(Processos!$F$5:$F$304,MATCH(LARGE(Processos!$N$5:$N$304,4),Processos!$N$5:$N$304,0))),""),"") -> Acompanhar a homologação do acordo
A42: 5 | B42: =IFERROR(IF(LARGE(Processos!$N$5:$N$304,5)>0,IF(INDEX(Processos!$A$5:$A$304,MATCH(LARGE(Processos!$N$5:$N$304,5),Processos!$N$5:$N$304,0))="","",INDEX(Processos!$A$5:$A$304,MATCH(LARGE(Processos!$N$5:$N$304,5),Processos!$N$5:$N$304,0))),""),"") | C42: =IFERROR(IF(LARGE(Processos!$N$5:$N$304,5)>0,IF(INDEX(Processos!$B$5:$B$304,MATCH(LARGE(Processos!$N$5:$N$304,5),Processos!$N$5:$N$304,0))="","",INDEX(Processos!$B$5:$B$304,MATCH(LARGE(Processos!$N$5:$N$304,5),Processos!$N$5:$N$304,0))),""),"") | D42: =IFERROR(IF(LARGE(Processos!$N$5:$N$304,5)>0,IF(INDEX(Processos!$D$5:$D$304,MATCH(LARGE(Processos!$N$5:$N$304,5),Processos!$N$5:$N$304,0))="","",INDEX(Processos!$D$5:$D$304,MATCH(LARGE(Processos!$N$5:$N$304,5),Processos!$N$5:$N$304,0))),""),"") | E42: =IFERROR(IF(LARGE(Processos!$N$5:$N$304,5)>0,IF(INDEX(Processos!$E$5:$E$304,MATCH(LARGE(Processos!$N$5:$N$304,5),Processos!$N$5:$N$304,0))="","",INDEX(Processos!$E$5:$E$304,MATCH(LARGE(Processos!$N$5:$N$304,5),Processos!$N$5:$N$304,0))),""),"") | F42: =IFERROR(IF(LARGE(Processos!$N$5:$N$304,5)>0,IF(INDEX(Processos!$H$5:$H$304,MATCH(LARGE(Processos!$N$5:$N$304,5),Processos!$N$5:$N$304,0))="","",INDEX(Processos!$H$5:$H$304,MATCH(LARGE(Processos!$N$5:$N$304,5),Processos!$N$5:$N$304,0))),""),"") | G42: =IFERROR(IF(LARGE(Processos!$N$5:$N$304,5)>0,IF(INDEX(Processos!$L$5:$L$304,MATCH(LARGE(Processos!$N$5:$N$304,5),Processos!$N$5:$N$304,0))="","",INDEX(Processos!$L$5:$L$304,MATCH(LARGE(Processos!$N$5:$N$304,5),Processos!$N$5:$N$304,0))),""),"") | H42: =IFERROR(IF(LARGE(Processos!$N$5:$N$304,5)>0,IF(INDEX(Processos!$F$5:$F$304,MATCH(LARGE(Processos!$N$5:$N$304,5),Processos!$N$5:$N$304,0))="","",INDEX(Processos!$F$5:$F$304,MATCH(LARGE(Processos!$N$5:$N$304,5),Processos!$N$5:$N$304,0))),""),"")
A43: 6 | B43: =IFERROR(IF(LARGE(Processos!$N$5:$N$304,6)>0,IF(INDEX(Processos!$A$5:$A$304,MATCH(LARGE(Processos!$N$5:$N$304,6),Processos!$N$5:$N$304,0))="","",INDEX(Processos!$A$5:$A$304,MATCH(LARGE(Processos!$N$5:$N$304,6),Processos!$N$5:$N$304,0))),""),"") | C43: =IFERROR(IF(LARGE(Processos!$N$5:$N$304,6)>0,IF(INDEX(Processos!$B$5:$B$304,MATCH(LARGE(Processos!$N$5:$N$304,6),Processos!$N$5:$N$304,0))="","",INDEX(Processos!$B$5:$B$304,MATCH(LARGE(Processos!$N$5:$N$304,6),Processos!$N$5:$N$304,0))),""),"") | D43: =IFERROR(IF(LARGE(Processos!$N$5:$N$304,6)>0,IF(INDEX(Processos!$D$5:$D$304,MATCH(LARGE(Processos!$N$5:$N$304,6),Processos!$N$5:$N$304,0))="","",INDEX(Processos!$D$5:$D$304,MATCH(LARGE(Processos!$N$5:$N$304,6),Processos!$N$5:$N$304,0))),""),"") | E43: =IFERROR(IF(LARGE(Processos!$N$5:$N$304,6)>0,IF(INDEX(Processos!$E$5:$E$304,MATCH(LARGE(Processos!$N$5:$N$304,6),Processos!$N$5:$N$304,0))="","",INDEX(Processos!$E$5:$E$304,MATCH(LARGE(Processos!$N$5:$N$304,6),Processos!$N$5:$N$304,0))),""),"") | F43: =IFERROR(IF(LARGE(Processos!$N$5:$N$304,6)>0,IF(INDEX(Processos!$H$5:$H$304,MATCH(LARGE(Processos!$N$5:$N$304,6),Processos!$N$5:$N$304,0))="","",INDEX(Processos!$H$5:$H$304,MATCH(LARGE(Processos!$N$5:$N$304,6),Processos!$N$5:$N$304,0))),""),"") | G43: =IFERROR(IF(LARGE(Processos!$N$5:$N$304,6)>0,IF(INDEX(Processos!$L$5:$L$304,MATCH(LARGE(Processos!$N$5:$N$304,6),Processos!$N$5:$N$304,0))="","",INDEX(Processos!$L$5:$L$304,MATCH(LARGE(Processos!$N$5:$N$304,6),Processos!$N$5:$N$304,0))),""),"") | H43: =IFERROR(IF(LARGE(Processos!$N$5:$N$304,6)>0,IF(INDEX(Processos!$F$5:$F$304,MATCH(LARGE(Processos!$N$5:$N$304,6),Processos!$N$5:$N$304,0))="","",INDEX(Processos!$F$5:$F$304,MATCH(LARGE(Processos!$N$5:$N$304,6),Processos!$N$5:$N$304,0))),""),"")
A44: 7 | B44: =IFERROR(IF(LARGE(Processos!$N$5:$N$304,7)>0,IF(INDEX(Processos!$A$5:$A$304,MATCH(LARGE(Processos!$N$5:$N$304,7),Processos!$N$5:$N$304,0))="","",INDEX(Processos!$A$5:$A$304,MATCH(LARGE(Processos!$N$5:$N$304,7),Processos!$N$5:$N$304,0))),""),"") | C44: =IFERROR(IF(LARGE(Processos!$N$5:$N$304,7)>0,IF(INDEX(Processos!$B$5:$B$304,MATCH(LARGE(Processos!$N$5:$N$304,7),Processos!$N$5:$N$304,0))="","",INDEX(Processos!$B$5:$B$304,MATCH(LARGE(Processos!$N$5:$N$304,7),Processos!$N$5:$N$304,0))),""),"") | D44: =IFERROR(IF(LARGE(Processos!$N$5:$N$304,7)>0,IF(INDEX(Processos!$D$5:$D$304,MATCH(LARGE(Processos!$N$5:$N$304,7),Processos!$N$5:$N$304,0))="","",INDEX(Processos!$D$5:$D$304,MATCH(LARGE(Processos!$N$5:$N$304,7),Processos!$N$5:$N$304,0))),""),"") | E44: =IFERROR(IF(LARGE(Processos!$N$5:$N$304,7)>0,IF(INDEX(Processos!$E$5:$E$304,MATCH(LARGE(Processos!$N$5:$N$304,7),Processos!$N$5:$N$304,0))="","",INDEX(Processos!$E$5:$E$304,MATCH(LARGE(Processos!$N$5:$N$304,7),Processos!$N$5:$N$304,0))),""),"") | F44: =IFERROR(IF(LARGE(Processos!$N$5:$N$304,7)>0,IF(INDEX(Processos!$H$5:$H$304,MATCH(LARGE(Processos!$N$5:$N$304,7),Processos!$N$5:$N$304,0))="","",INDEX(Processos!$H$5:$H$304,MATCH(LARGE(Processos!$N$5:$N$304,7),Processos!$N$5:$N$304,0))),""),"") | G44: =IFERROR(IF(LARGE(Processos!$N$5:$N$304,7)>0,IF(INDEX(Processos!$L$5:$L$304,MATCH(LARGE(Processos!$N$5:$N$304,7),Processos!$N$5:$N$304,0))="","",INDEX(Processos!$L$5:$L$304,MATCH(LARGE(Processos!$N$5:$N$304,7),Processos!$N$5:$N$304,0))),""),"") | H44: =IFERROR(IF(LARGE(Processos!$N$5:$N$304,7)>0,IF(INDEX(Processos!$F$5:$F$304,MATCH(LARGE(Processos!$N$5:$N$304,7),Processos!$N$5:$N$304,0))="","",INDEX(Processos!$F$5:$F$304,MATCH(LARGE(Processos!$N$5:$N$304,7),Processos!$N$5:$N$304,0))),""),"")
A45: 8 | B45: =IFERROR(IF(LARGE(Processos!$N$5:$N$304,8)>0,IF(INDEX(Processos!$A$5:$A$304,MATCH(LARGE(Processos!$N$5:$N$304,8),Processos!$N$5:$N$304,0))="","",INDEX(Processos!$A$5:$A$304,MATCH(LARGE(Processos!$N$5:$N$304,8),Processos!$N$5:$N$304,0))),""),"") | C45: =IFERROR(IF(LARGE(Processos!$N$5:$N$304,8)>0,IF(INDEX(Processos!$B$5:$B$304,MATCH(LARGE(Processos!$N$5:$N$304,8),Processos!$N$5:$N$304,0))="","",INDEX(Processos!$B$5:$B$304,MATCH(LARGE(Processos!$N$5:$N$304,8),Processos!$N$5:$N$304,0))),""),"") | D45: =IFERROR(IF(LARGE(Processos!$N$5:$N$304,8)>0,IF(INDEX(Processos!$D$5:$D$304,MATCH(LARGE(Processos!$N$5:$N$304,8),Processos!$N$5:$N$304,0))="","",INDEX(Processos!$D$5:$D$304,MATCH(LARGE(Processos!$N$5:$N$304,8),Processos!$N$5:$N$304,0))),""),"") | E45: =IFERROR(IF(LARGE(Processos!$N$5:$N$304,8)>0,IF(INDEX(Processos!$E$5:$E$304,MATCH(LARGE(Processos!$N$5:$N$304,8),Processos!$N$5:$N$304,0))="","",INDEX(Processos!$E$5:$E$304,MATCH(LARGE(Processos!$N$5:$N$304,8),Processos!$N$5:$N$304,0))),""),"") | F45: =IFERROR(IF(LARGE(Processos!$N$5:$N$304,8)>0,IF(INDEX(Processos!$H$5:$H$304,MATCH(LARGE(Processos!$N$5:$N$304,8),Processos!$N$5:$N$304,0))="","",INDEX(Processos!$H$5:$H$304,MATCH(LARGE(Processos!$N$5:$N$304,8),Processos!$N$5:$N$304,0))),""),"") | G45: =IFERROR(IF(LARGE(Processos!$N$5:$N$304,8)>0,IF(INDEX(Processos!$L$5:$L$304,MATCH(LARGE(Processos!$N$5:$N$304,8),Processos!$N$5:$N$304,0))="","",INDEX(Processos!$L$5:$L$304,MATCH(LARGE(Processos!$N$5:$N$304,8),Processos!$N$5:$N$304,0))),""),"") | H45: =IFERROR(IF(LARGE(Processos!$N$5:$N$304,8)>0,IF(INDEX(Processos!$F$5:$F$304,MATCH(LARGE(Processos!$N$5:$N$304,8),Processos!$N$5:$N$304,0))="","",INDEX(Processos!$F$5:$F$304,MATCH(LARGE(Processos!$N$5:$N$304,8),Processos!$N$5:$N$304,0))),""),"")
...

Sheet Config
A1: Configurações
A2: Células amarelas: você preenche. Fases, áreas e responsáveis aparecem nas listas da aba Processos.
A4: Escritório | B4: Ferraz & Lima Advocacia (exemplo fictício)
A5: Data de referência (hoje) | B5: 46279 | C5: O exemplo está congelado em 14/09/2026, para os arquivos do kit mostrarem a mesma foto. Ao usar com os seus dados, troque por =HOJE().
A6: Considerar parado após (dias sem atualização) | B6: 30 | C6: Caso sem atualização há mais dias do que isso aparece como parado no Painel.
A9: Fases (até 10) | D9: Áreas (até 10) | F9: Responsáveis (até 10)
B10: Consultivo | D10: Cível | F10: Marina Ferraz
B11: Inicial | D11: Trabalhista | F11: Rafael Lima
B12: Instrução | D12: Previdenciário | F12: Júlia Prado
B13: Sentença | D13: Empresarial
B14: Recurso | D14: Família
B15: Execução
B16: Acordo
B17: Encerrado
A21: Preencha de cima para baixo, sem pular linha: as listas suspensas param na última linha preenchida.
A22: Mantenha a fase "Encerrado" com esse nome: é ela que tira o caso das contagens de ativos.

Sheet Processos
A1: Processos
A2: Uma linha por caso (copie o cadastro da planilha 13 · Carteira, aba Casos: a 13 é a fonte). Preencha as colunas amarelas; dias, situação e parado são calculados. A cada movimentação, atualize a fase, a próxima ação e a data da última atualização.
A4: Número | B4: Cliente | C4: Área | D4: Fase | E4: Responsável | F4: Próxima ação | G4: Data da próxima ação | H4: Última atualização | I4: Observação | J4: Dias para a ação | K4: Situação | L4: Dias sem atualizar | M4: Parado? | N4: Chave
A5: CONS-2026-01 | B5: Padaria do Sol Ltda | C5: Empresarial | D5: Consultivo | E5: Marina Ferraz | F5: Reunião com o cliente | G5: 46288 | H5: 46273 | J5: =IF(OR(K5="",K5="Encerrado",K5="Sem próxima ação"),"",G5-Config!$B$5) -> 9 | K5: =IF(A5="","",IF(D5="Encerrado","Encerrado",IF(G5="","Sem próxima ação",IF(G5<Config!$B$5,"Atrasado",IF(G5=Config!$B$5,"Hoje",IF(G5-Config!$B$5<=7,"Esta semana","Em dia")))))) -> Em dia | L5: =IF(OR(A5="",D5="Encerrado",H5=""),"",Config!$B$5-H5) -> 6 | M5: =IF(L5="","",IF(L5>Config!$B$6,"Sim","")) | N5: =IF(M5="Sim",L5-ROW()/100000,0) -> 0
A6: 2998500-50.2026.8.26.0515 | B6: Ana Beatriz Moreira | C6: Trabalhista | D6: Inicial | E6: Rafael Lima | F6: Audiência de conciliação (confirmar presença do cliente) | G6: 46281 | H6: 46275 | J6: =IF(OR(K6="",K6="Encerrado",K6="Sem próxima ação"),"",G6-Config!$B$5) -> 2 | K6: =IF(A6="","",IF(D6="Encerrado","Encerrado",IF(G6="","Sem próxima ação",IF(G6<Config!$B$5,"Atrasado",IF(G6=Config!$B$5,"Hoje",IF(G6-Config!$B$5<=7,"Esta semana","Em dia")))))) -> Esta semana | L6: =IF(OR(A6="",D6="Encerrado",H6=""),"",Config!$B$5-H6) -> 4 | M6: =IF(L6="","",IF(L6>Config!$B$6,"Sim","")) | N6: =IF(M6="Sim",L6-ROW()/100000,0) -> 0
A7: 9586960-92.2026.8.26.0106 | B7: Construtora Horizonte | C7: Cível | D7: Inicial | E7: Marina Ferraz | F7: Protocolar: réplica | G7: 46276 | H7: 46276 | J7: =IF(OR(K7="",K7="Encerrado",K7="Sem próxima ação"),"",G7-Config!$B$5) -> -3 | K7: =IF(A7="","",IF(D7="Encerrado","Encerrado",IF(G7="","Sem próxima ação",IF(G7<Config!$B$5,"Atrasado",IF(G7=Config!$B$5,"Hoje",IF(G7-Config!$B$5<=7,"Esta semana","Em dia")))))) -> Atrasado | L7: =IF(OR(A7="",D7="Encerrado",H7=""),"",Config!$B$5-H7) -> 3 | M7: =IF(L7="","",IF(L7>Config!$B$6,"Sim","")) | N7: =IF(M7="Sim",L7-ROW()/100000,0) -> 0
A8: 4746093-86.2026.8.26.0637 | B8: Carlos Eduardo Nunes | C8: Previdenciário | D8: Inicial | E8: Rafael Lima | F8: Juntar documentos enviados pelo cliente | G8: 46285 | H8: 46274 | J8: =IF(OR(K8="",K8="Encerrado",K8="Sem próxima ação"),"",G8-Config!$B$5) -> 6 | K8: =IF(A8="","",IF(D8="Encerrado","Encerrado",IF(G8="","Sem próxima ação",IF(G8<Config!$B$5,"Atrasado",IF(G8=Config!$B$5,"Hoje",IF(G8-Config!$B$5<=7,"Esta semana","Em dia")))))) -> Esta semana | L8: =IF(OR(A8="",D8="Encerrado",H8=""),"",Config!$B$5-H8) -> 5 | M8: =IF(L8="","",IF(L8>Config!$B$6,"Sim","")) | N8: =IF(M8="Sim",L8-ROW()/100000,0) -> 0
A9: CONS-2026-02 | B9: Loja Verde Comércio | C9: Empresarial | D9: Consultivo | E9: Marina Ferraz | F9: Entregar o parecer ao cliente | G9: 46283 | H9: 46277 | J9: =IF(OR(K9="",K9="Encerrado",K9="Sem próxima ação"),"",G9-Config!$B$5) -> 4 | K9: =IF(A9="","",IF(D9="Encerrado","Encerrado",IF(G9="","Sem próxima ação",IF(G9<Config!$B$5,"Atrasado",IF(G9=Config!$B$5,"Hoje",IF(G9-Config!$B$5<=7,"Esta semana","Em dia")))))) -> Esta semana | L9: =IF(OR(A9="",D9="Encerrado",H9=""),"",Config!$B$5-H9) -> 2 | M9: =IF(L9="","",IF(L9>Config!$B$6,"Sim","")) | N9: =IF(M9="Sim",L9-ROW()/100000,0) -> 0
A10: CONS-2026-03 | B10: Marcos Vinícius Teles | C10: Previdenciário | D10: Consultivo | E10: Rafael Lima | F10: Entregar o parecer ao cliente | G10: 46279 | H10: 46278 | J10: =IF(OR(K10="",K10="Encerrado",K10="Sem próxima ação"),"",G10-Config!$B$5) -> 0 | K10: =IF(A10="","",IF(D10="Encerrado","Encerrado",IF(G10="","Sem próxima ação",IF(G10<Config!$B$5,"Atrasado",IF(G10=Config!$B$5,"Hoje",IF(G10-Config!$B$5<=7,"Esta semana","Em dia")))))) -> Hoje | L10: =IF(OR(A10="",D10="Encerrado",H10=""),"",Config!$B$5-H10) -> 1 | M10: =IF(L10="","",IF(L10>Config!$B$6,"Sim","")) | N10: =IF(M10="Sim",L10-ROW()/100000,0) -> 0
A11: CONS-2026-04 | B11: Escola Aurora | C11: Cível | D11: Consultivo | E11: Marina Ferraz | F11: Reunião com o cliente | G11: 46282 | H11: 46270 | J11: =IF(OR(K11="",K11="Encerrado",K11="Sem próxima ação"),"",G11-Config!$B$5) -> 3 | K11: =IF(A11="","",IF(D11="Encerrado","Encerrado",IF(G11="","Sem próxima ação",IF(G11<Config!$B$5,"Atrasado",IF(G11=Config!$B$5,"Hoje",IF(G11-Config!$B$5<=7,"Esta semana","Em dia")))))) -> Esta semana | L11: =IF(OR(A11="",D11="Encerrado",H11=""),"",Config!$B$5-H11) -> 9 | M11: =IF(L11="","",IF(L11>Config!$B$6,"Sim","")) | N11: =IF(M11="Sim",L11-ROW()/100000,0) -> 0
A12: 8056747-83.2026.8.26.0561 | B12: Bistrô 42 | C12: Trabalhista | D12: Instrução | E12: Rafael Lima | F12: Audiência de instrução (avisar testemunhas) | G12: 46288 | H12: 46267 | J12: =IF(OR(K12="",K12="Encerrado",K12="Sem próxima ação"),"",G12-Config!$B$5) -> 9 | K12: =IF(A12="","",IF(D12="Encerrado","Encerrado",IF(G12="","Sem próxima ação",IF(G12<Config!$B$5,"Atrasado",IF(G12=Config!$B$5,"Hoje",IF(G12-Config!$B$5<=7,"Esta semana","Em dia")))))) -> Em dia | L12: =IF(OR(A12="",D12="Encerrado",H12=""),"",Config!$B$5-H12) -> 12 | M12: =IF(L12="","",IF(L12>Config!$B$6,"Sim","")) | N12: =IF(M12="Sim",L12-ROW()/100000,0) -> 0
A13: 9236009-85.2025.8.26.0452 | B13: Bistrô 42 | C13: Trabalhista | D13: Execução | E13: Rafael Lima | F13: Iniciar o cumprimento de sentença | G13: 46294 | H13: 46238 | I13: Aguardando andamento da execução (penhora) | J13: =IF(OR(K13="",K13="Encerrado",K13="Sem próxima ação"),"",G13-Config!$B$5) -> 15 | K13: =IF(A13="","",IF(D13="Encerrado","Encerrado",IF(G13="","Sem próxima ação",IF(G13<Config!$B$5,"Atrasado",IF(G13=Config!$B$5,"Hoje",IF(G13-Config!$B$5<=7,"Esta semana","Em dia")))))) -> Em dia | L13: =IF(OR(A13="",D13="Encerrado",H13=""),"",Config!$B$5-H13) -> 41 | M13: =IF(L13="","",IF(L13>Config!$B$6,"Sim","")) -> Sim | N13: =IF(M13="Sim",L13-ROW()/100000,0) -> 40.99987
A14: 5025425-10.2025.8.26.0629 | B14: Roberto Almeida | C14: Cível | D14: Sentença | E14: Marina Ferraz | F14: Protocolar: embargos de declaração | G14: 46278 | H14: 46277 | J14: =IF(OR(K14="",K14="Encerrado",K14="Sem próxima ação"),"",G14-Config!$B$5) -> -1 | K14: =IF(A14="","",IF(D14="Encerrado","Encerrado",IF(G14="","Sem próxima ação",IF(G14<Config!$B$5,"Atrasado",IF(G14=Config!$B$5,"Hoje",IF(G14-Config!$B$5<=7,"Esta semana","Em dia")))))) -> Atrasado | L14: =IF(OR(A14="",D14="Encerrado",H14=""),"",Config!$B$5-H14) -> 2 | M14: =IF(L14="","",IF(L14>Config!$B$6,"Sim","")) | N14: =IF(M14="Sim",L14-ROW()/100000,0) -> 0
A15: 2354318-24.2026.8.26.0295 | B15: Roberto Almeida | C15: Cível | D15: Recurso | E15: Marina Ferraz | F15: Protocolar: contrarrazões | G15: 46287 | H15: 46272 | J15: =IF(OR(K15="",K15="Encerrado",K15="Sem próxima ação"),"",G15-Config!$B$5) -> 8 | K15: =IF(A15="","",IF(D15="Encerrado","Encerrado",IF(G15="","Sem próxima ação",IF(G15<Config!$B$5,"Atrasado",IF(G15=Config!$B$5,"Hoje",IF(G15-Config!$B$5<=7,"Esta semana","Em dia")))))) -> Em dia | L15: =IF(OR(A15="",D15="Encerrado",H15=""),"",Config!$B$5-H15) -> 7 | M15: =IF(L15="","",IF(L15>Config!$B$6,"Sim","")) | N15: =IF(M15="Sim",L15-ROW()/100000,0) -> 0
A16: CONS-2025-05 | B16: Clínica Bem-Estar | C16: Empresarial | D16: Consultivo | E16: Marina Ferraz | F16: Reunião com o cliente | G16: 46284 | H16: 46271 | J16: =IF(OR(K16="",K16="Encerrado",K16="Sem próxima ação"),"",G16-Config!$B$5) -> 5 | K16: =IF(A16="","",IF(D16="Encerrado","Encerrado",IF(G16="","Sem próxima ação",IF(G16<Config!$B$5,"Atrasado",IF(G16=Config!$B$5,"Hoje",IF(G16-Config!$B$5<=7,"Esta semana","Em dia")))))) -> Esta semana | L16: =IF(OR(A16="",D16="Encerrado",H16=""),"",Config!$B$5-H16) -> 8 | M16: =IF(L16="","",IF(L16>Config!$B$6,"Sim","")) | N16: =IF(M16="Sim",L16-ROW()/100000,0) -> 0
A17: 2645033-67.2026.8.26.0012 | B17: Clínica Bem-Estar | C17: Empresarial | D17: Inicial | E17: Marina Ferraz | F17: Protocolar: contestação | G17: 46279 | H17: 46278 | J17: =IF(OR(K17="",K17="Encerrado",K17="Sem próxima ação"),"",G17-Config!$B$5) -> 0 | K17: =IF(A17="","",IF(D17="Encerrado","Encerrado",IF(G17="","Sem próxima ação",IF(G17<Config!$B$5,"Atrasado",IF(G17=Config!$B$5,"Hoje",IF(G17-Config!$B$5<=7,"Esta semana","Em dia")))))) -> Hoje | L17: =IF(OR(A17="",D17="Encerrado",H17=""),"",Config!$B$5-H17) -> 1 | M17: =IF(L17="","",IF(L17>Config!$B$6,"Sim","")) | N17: =IF(M17="Sim",L17-ROW()/100000,0) -> 0
A18: 9225646-96.2025.8.26.0322 | B18: Transportadora Rota Sul | C18: Trabalhista | D18: Instrução | E18: Rafael Lima | F18: Protocolar: manifestação sobre laudo | G18: 46283 | H18: 46273 | J18: =IF(OR(K18="",K18="Encerrado",K18="Sem próxima ação"),"",G18-Config!$B$5) -> 4 | K18: =IF(A18="","",IF(D18="Encerrado","Encerrado",IF(G18="","Sem próxima ação",IF(G18<Config!$B$5,"Atrasado",IF(G18=Config!$B$5,"Hoje",IF(G18-Config!$B$5<=7,"Esta semana","Em dia")))))) -> Esta semana | L18: =IF(OR(A18="",D18="Encerrado",H18=""),"",Config!$B$5-H18) -> 6 | M18: =IF(L18="","",IF(L18>Config!$B$6,"Sim","")) | N18: =IF(M18="Sim",L18-ROW()/100000,0) -> 0
A19: 4526984-60.2026.8.26.0258 | B19: Transportadora Rota Sul | C19: Trabalhista | D19: Inicial | E19: Rafael Lima | F19: Audiência de conciliação (confirmar presença do cliente) | G19: 46299 | H19: 46266 | J19: =IF(OR(K19="",K19="Encerrado",K19="Sem próxima ação"),"",G19-Config!$B$5) -> 20 | K19: =IF(A19="","",IF(D19="Encerrado","Encerrado",IF(G19="","Sem próxima ação",IF(G19<Config!$B$5,"Atrasado",IF(G19=Config!$B$5,"Hoje",IF(G19-Config!$B$5<=7,"Esta semana","Em dia")))))) -> Em dia | L19: =IF(OR(A19="",D19="Encerrado",H19=""),"",Config!$B$5-H19) -> 13 | M19: =IF(L19="","",IF(L19>Config!$B$6,"Sim","")) | N19: =IF(M19="Sim",L19-ROW()/100000,0) -> 0
A20: CONS-2026-06 | B20: Transportadora Rota Sul | C20: Trabalhista | D20: Consultivo | E20: Rafael Lima | F20: Reunião com o cliente | G20: 46274 | H20: 46261 | I20: Cliente pediu para remarcar a reunião | J20: =IF(OR(K20="",K20="Encerrado",K20="Sem próxima ação"),"",G20-Config!$B$5) -> -5 | K20: =IF(A20="","",IF(D20="Encerrado","Encerrado",IF(G20="","Sem próxima ação",IF(G20<Config!$B$5,"Atrasado",IF(G20=Config!$B$5,"Hoje",IF(G20-Config!$B$5<=7,"Esta semana","Em dia")))))) -> Atrasado | L20: =IF(OR(A20="",D20="Encerrado",H20=""),"",Config!$B$5-H20) -> 18 | M20: =IF(L20="","",IF(L20>Config!$B$6,"Sim","")) | N20: =IF(M20="Sim",L20-ROW()/100000,0) -> 0
A21: 6832730-55.2026.8.26.0386 | B21: Patrícia Gomes | C21: Família | D21: Acordo | E21: Marina Ferraz | F21: Enviar a minuta de acordo | G21: 46279 | H21: 46278 | J21: =IF(OR(K21="",K21="Encerrado",K21="Sem próxima ação"),"",G21-Config!$B$5) -> 0 | K21: =IF(A21="","",IF(D21="Encerrado","Encerrado",IF(G21="","Sem próxima ação",IF(G21<Config!$B$5,"Atrasado",IF(G21=Config!$B$5,"Hoje",IF(G21-Config!$B$5<=7,"Esta semana","Em dia")))))) -> Hoje | L21: =IF(OR(A21="",D21="Encerrado",H21=""),"",Config!$B$5-H21) -> 1 | M21: =IF(L21="","",IF(L21>Config!$B$6,"Sim","")) | N21: =IF(M21="Sim",L21-ROW()/100000,0) -> 0
A22: 9616569-91.2026.8.26.0079 | B22: Patrícia Gomes | C22: Família | D22: Execução | E22: Marina Ferraz | F22: Protocolar: impugnação | G22: 46277 | H22: 46275 | I22: Aguardando documentos do cliente | J22: =IF(OR(K22="",K22="Encerrado",K22="Sem próxima ação"),"",G22-Config!$B$5) -> -2 | K22: =IF(A22="","",IF(D22="Encerrado","Encerrado",IF(G22="","Sem próxima ação",IF(G22<Config!$B$5,"Atrasado",IF(G22=Config!$B$5,"Hoje",IF(G22-Config!$B$5<=7,"Esta semana","Em dia")))))) -> Atrasado | L22: =IF(OR(A22="",D22="Encerrado",H22=""),"",Config!$B$5-H22) -> 4 | M22: =IF(L22="","",IF(L22>Config!$B$6,"Sim","")) | N22: =IF(M22="Sim",L22-ROW()/100000,0) -> 0
A23: 6710873-21.2025.8.26.0571 | B23: Escola Aurora | C23: Cível | D23: Sentença | E23: Marina Ferraz | F23: Protocolar: recurso de apelação | G23: 46281 | H23: 46276 | J23: =IF(OR(K23="",K23="Encerrado",K23="Sem próxima ação"),"",G23-Config!$B$5) -> 2 | K23: =IF(A23="","",IF(D23="Encerrado","Encerrado",IF(G23="","Sem próxima ação",IF(G23<Config!$B$5,"Atrasado",IF(G23=Config!$B$5,"Hoje",IF(G23-Config!$B$5<=7,"Esta semana","Em dia")))))) -> Esta semana | L23: =IF(OR(A23="",D23="Encerrado",H23=""),"",Config!$B$5-H23) -> 3 | M23: =IF(L23="","",IF(L23>Config!$B$6,"Sim","")) | N23: =IF(M23="Sim",L23-ROW()/100000,0) -> 0
A24: 5900991-46.2026.8.26.0469 | B24: José Antônio Ribeiro | C24: Previdenciário | D24: Instrução | E24: Rafael Lima | F24: Protocolar: manifestação sobre laudo | G24: 46275 | H24: 46274 | J24: =IF(OR(K24="",K24="Encerrado",K24="Sem próxima ação"),"",G24-Config!$B$5) -> -4 | K24: =IF(A24="","",IF(D24="Encerrado","Encerrado",IF(G24="","Sem próxima ação",IF(G24<Config!$B$5,"Atrasado",IF(G24=Config!$B$5,"Hoje",IF(G24-Config!$B$5<=7,"Esta semana","Em dia")))))) -> Atrasado | L24: =IF(OR(A24="",D24="Encerrado",H24=""),"",Config!$B$5-H24) -> 5 | M24: =IF(L24="","",IF(L24>Config!$B$6,"Sim","")) | N24: =IF(M24="Sim",L24-ROW()/100000,0) -> 0
A25: 3363714-92.2025.8.26.0592 | B25: Oficina Mecânica Central | C25: Trabalhista | D25: Instrução | E25: Rafael Lima | F25: Protocolar: alegações finais | G25: 46289 | H25: 46270 | J25: =IF(OR(K25="",K25="Encerrado",K25="Sem próxima ação"),"",G25-Config!$B$5) -> 10 | K25: =IF(A25="","",IF(D25="Encerrado","Encerrado",IF(G25="","Sem próxima ação",IF(G25<Config!$B$5,"Atrasado",IF(G25=Config!$B$5,"Hoje",IF(G25-Config!$B$5<=7,"Esta semana","Em dia")))))) -> Em dia | L25: =IF(OR(A25="",D25="Encerrado",H25=""),"",Config!$B$5-H25) -> 9 | M25: =IF(L25="","",IF(L25>Config!$B$6,"Sim","")) | N25: =IF(M25="Sim",L25-ROW()/100000,0) -> 0
