Workbook

Sheet Como usar
A1: Checklist de abertura e encerramento de caso
A2: Kit de Gestão para Advogados · Seu Sócio Gestor · versão 1.0 (setembro de 2026)
A4: O que esta planilha faz | B4: Para cada caso, marca os itens administrativos que precisam estar em ordem na abertura (contrato, procuração, documentos, honorário, cadastro no caixa) e no encerramento (última parcela, arquivo, devolução, avaliação). Calcula o % concluído por caso e mostra no Painel quem está com pendência.
A5: Passo 1 | B5: Em Config, ajuste os itens de abertura e de encerramento ao jeito do escritório e cadastre os responsáveis. Preencha de cima para baixo, sem pular linha.
A6: Passo 2 | B6: Em Checklist, apague os exemplos e cadastre uma linha por caso (número, cliente e responsável copiados da planilha 13 · Carteira, que é a fonte do cadastro). Em cada item, marque Sim, Não ou N/A (não se aplica). Vazio conta como pendente, de propósito: caso novo começa com tudo pendente.
A7: Passo 3 | B7: Ao encerrar um caso, mude a situação para Encerrado: os itens de encerramento passam a contar. Enquanto o caso está em andamento, essa parte fica cinza.
A8: Passo 4 | B8: Em Painel, resolva primeiro os casos com mais pendências e olhe "Item mais esquecido": se o mesmo item pende em vários casos, o problema é a rotina, não o caso.
A9: Rotina | B9: Na abertura de cada caso, 3 minutos para criar a linha. Na sexta, junto com o caixa, confira os encerrados do mês: caso encerrado sem a última parcela cobrada é dinheiro parado.
A10: Com a IA | B10: Copie a coluna "O que falta" de um caso e use o prompt "Prazos 07 · Pendências de abertura e encerramento viram tarefas" da biblioteca do kit.
A11: Legenda | B11: Células amarelas: você preenche. Brancas: calculadas. Não é preciso mexer em nada fora do amarelo.
A12: Proteção | B12: Fórmulas protegidas sem senha. Para editar: Revisar > Desproteger planilha (Excel) ou Dados > Proteger intervalos (Google Sheets).
A13: Requisitos | B13: Excel 2016 ou mais novo, Microsoft 365 ou Google Sheets (só funções do Excel 2007+; nada de MÍNIMOSES, MÁXIMOSES ou UNIRTEXTO). No celular abre nos aplicativos; para preencher, use o computador.
A14: Google Sheets | B14: Faça upload no Google Drive e abra com o Google Sheets. Fórmulas, listas, cores e semáforos funcionam: as regras de cor que dependem do mês escolhido em Config usam INDIRECT, que é a forma que o Sheets aceita para regra condicional apontar para outra aba.
A15: Exemplos | B15: Ferraz & Lima Advocacia é um escritório fictício. Clientes, processos, nomes e valores são inventados. Apague-os antes de começar.
... A17: Suporte | B17: suporte@seusociogestor.com.br · resposta em até 5 dias úteis · reembolso em até 7 dias pelo mesmo canal.

Sheet Painel
A1: =Config!$B$4&" · Abertura e encerramento · "&TEXT(DAY(Config!$B$5),"00")&"/"&TEXT(MONTH(Config!$B$5),"00")&"/"&YEAR(Config!$B$5) -> Ferraz & Lima Advocacia (exemplo fictício) · Abertura e encerramento · 14/09/2026
A2: Nada para digitar aqui: tudo vem de Config e Checklist. Pendência = item de abertura (ou de encerramento, em caso encerrado) que não está marcado como Sim ou N/A.
A4: Casos cadastrados | C4: Abertos com pendência de abertura | E4: Encerrados com pendência | G4: Itens pendentes no total | I4: Casos sem pendência
A5: =COUNTIFS(Checklist!$A$5:$A$304,"<>") -> 38 | C5: =COUNTIFS(Checklist!$D$5:$D$304,"Em andamento",Checklist!$AA$5:$AA$304,">0") -> 7 | E5: =COUNTIFS(Checklist!$D$5:$D$304,"Encerrado",Checklist!$AB$5:$AB$304,">0") -> 3 | G5: =SUM(Checklist!$AC$5:$AC$304) -> 12 | I5: =COUNTIFS(Checklist!$A$5:$A$304,"<>",Checklist!$AC$5:$AC$304,0) -> 28
A7: Casos com pendência (mais itens pendentes primeiro)
A8: Mostra os 15 primeiros; os demais ficam na aba Checklist, que pode ser filtrada pela coluna Pendências.
A9: # | B9: Número | C9: Cliente | D9: Situação | E9: Responsável | F9: % abertura | G9: % encerramento | H9: Pendências | I9: O que falta
A10: 1 | B10: =IFERROR(IF(LARGE(Checklist!$AE$5:$AE$304,1)>0,IF(INDEX(Checklist!$A$5:$A$304,MATCH(LARGE(Checklist!$AE$5:$AE$304,1),Checklist!$AE$5:$AE$304,0))="","",INDEX(Checklist!$A$5:$A$304,MATCH(LARGE(Checklist!$AE$5:$AE$304,1),Checklist!$AE$5:$AE$304,0))),""),"") -> 6184138-13.2026.8.26.0378 | C10: =IFERROR(IF(LARGE(Checklist!$AE$5:$AE$304,1)>0,IF(INDEX(Checklist!$B$5:$B$304,MATCH(LARGE(Checklist!$AE$5:$AE$304,1),Checklist!$AE$5:$AE$304,0))="","",INDEX(Checklist!$B$5:$B$304,MATCH(LARGE(Checklist!$AE$5:$AE$304,1),Checklist!$AE$5:$AE$304,0))),""),"") -> Oficina Mecânica Central | D10: =IFERROR(IF(LARGE(Checklist!$AE$5:$AE$304,1)>0,IF(INDEX(Checklist!$D$5:$D$304,MATCH(LARGE(Checklist!$AE$5:$AE$304,1),Checklist!$AE$5:$AE$304,0))="","",INDEX(Checklist!$D$5:$D$304,MATCH(LARGE(Checklist!$AE$5:$AE$304,1),Checklist!$AE$5:$AE$304,0))),""),"") -> Em andamento | E10: =IFERROR(IF(LARGE(Checklist!$AE$5:$AE$304,1)>0,IF(INDEX(Checklist!$C$5:$C$304,MATCH(LARGE(Checklist!$AE$5:$AE$304,1),Checklist!$AE$5:$AE$304,0))="","",INDEX(Checklist!$C$5:$C$304,MATCH(LARGE(Checklist!$AE$5:$AE$304,1),Checklist!$AE$5:$AE$304,0))),""),"") -> Rafael Lima | F10: =IFERROR(IF(LARGE(Checklist!$AE$5:$AE$304,1)>0,IF(INDEX(Checklist!$Y$5:$Y$304,MATCH(LARGE(Checklist!$AE$5:$AE$304,1),Checklist!$AE$5:$AE$304,0))="","",INDEX(Checklist!$Y$5:$Y$304,MATCH(LARGE(Checklist!$AE$5:$AE$304,1),Checklist!$AE$5:$AE$304,0))),""),"") -> 0.77777778 | G10: =IFERROR(IF(LARGE(Checklist!$AE$5:$AE$304,1)>0,IF(INDEX(Checklist!$Z$5:$Z$304,MATCH(LARGE(Checklist!$AE$5:$AE$304,1),Checklist!$AE$5:$AE$304,0))="","",INDEX(Checklist!$Z$5:$Z$304,MATCH(LARGE(Checklist!$AE$5:$AE$304,1),Checklist!$AE$5:$AE$304,0))),""),"") | H10: =IFERROR(IF(LARGE(Checklist!$AE$5:$AE$304,1)>0,IF(INDEX(Checklist!$AC$5:$AC$304,MATCH(LARGE(Checklist!$AE$5:$AE$304,1),Checklist!$AE$5:$AE$304,0))="","",INDEX(Checklist!$AC$5:$AC$304,MATCH(LARGE(Checklist!$AE$5:$AE$304,1),Checklist!$AE$5:$AE$304,0))),""),"") -> 2 | I10: =IFERROR(IF(LARGE(Checklist!$AE$5:$AE$304,1)>0,IF(INDEX(Checklist!$AD$5:$AD$304,MATCH(LARGE(Checklist!$AE$5:$AE$304,1),Checklist!$AE$5:$AE$304,0))="","",INDEX(Checklist!$AD$5:$AD$304,MATCH(LARGE(Checklist!$AE$5:$AE$304,1),Checklist!$AE$5:$AE$304,0))),""),"") -> Canal de contato combinado com o cliente; Pasta do caso criada (física ou digital)
A11: 2 | B11: =IFERROR(IF(LARGE(Checklist!$AE$5:$AE$304,2)>0,IF(INDEX(Checklist!$A$5:$A$304,MATCH(LARGE(Checklist!$AE$5:$AE$304,2),Checklist!$AE$5:$AE$304,0))="","",INDEX(Checklist!$A$5:$A$304,MATCH(LARGE(Checklist!$AE$5:$AE$304,2),Checklist!$AE$5:$AE$304,0))),""),"") -> 8663770-96.2025.8.26.0481 | C11: =IFERROR(IF(LARGE(Checklist!$AE$5:$AE$304,2)>0,IF(INDEX(Checklist!$B$5:$B$304,MATCH(LARGE(Checklist!$AE$5:$AE$304,2),Checklist!$AE$5:$AE$304,0))="","",INDEX(Checklist!$B$5:$B$304,MATCH(LARGE(Checklist!$AE$5:$AE$304,2),Checklist!$AE$5:$AE$304,0))),""),"") -> Oficina Mecânica Central | D11: =IFERROR(IF(LARGE(Checklist!$AE$5:$AE$304,2)>0,IF(INDEX(Checklist!$D$5:$D$304,MATCH(LARGE(Checklist!$AE$5:$AE$304,2),Checklist!$AE$5:$AE$304,0))="","",INDEX(Checklist!$D$5:$D$304,MATCH(LARGE(Checklist!$AE$5:$AE$304,2),Checklist!$AE$5:$AE$304,0))),""),"") -> Encerrado | E11: =IFERROR(IF(LARGE(Checklist!$AE$5:$AE$304,2)>0,IF(INDEX(Checklist!$C$5:$C$304,MATCH(LARGE(Checklist!$AE$5:$AE$304,2),Checklist!$AE$5:$AE$304,0))="","",INDEX(Checklist!$C$5:$C$304,MATCH(LARGE(Checklist!$AE$5:$AE$304,2),Checklist!$AE$5:$AE$304,0))),""),"") -> Rafael Lima | F11: =IFERROR(IF(LARGE(Checklist!$AE$5:$AE$304,2)>0,IF(INDEX(Checklist!$Y$5:$Y$304,MATCH(LARGE(Checklist!$AE$5:$AE$304,2),Checklist!$AE$5:$AE$304,0))="","",INDEX(Checklist!$Y$5:$Y$304,MATCH(LARGE(Checklist!$AE$5:$AE$304,2),Checklist!$AE$5:$AE$304,0))),""),"") -> 1 | G11: =IFERROR(IF(LARGE(Checklist!$AE$5:$AE$304,2)>0,IF(INDEX(Checklist!$Z$5:$Z$304,MATCH(LARGE(Checklist!$AE$5:$AE$304,2),Checklist!$AE$5:$AE$304,0))="","",INDEX(Checklist!$Z$5:$Z$304,MATCH(LARGE(Checklist!$AE$5:$AE$304,2),Checklist!$AE$5:$AE$304,0))),""),"") -> 0.75 | H11: =IFERROR(IF(LARGE(Checklist!$AE$5:$AE$304,2)>0,IF(INDEX(Checklist!$AC$5:$AC$304,MATCH(LARGE(Checklist!$AE$5:$AE$304,2),Checklist!$AE$5:$AE$304,0))="","",INDEX(Checklist!$AC$5:$AC$304,MATCH(LARGE(Checklist!$AE$5:$AE$304,2),Checklist!$AE$5:$AE$304,0))),""),"") -> 2 | I11: =IFERROR(IF(LARGE(Checklist!$AE$5:$AE$304,2)>0,IF(INDEX(Checklist!$AD$5:$AD$304,MATCH(LARGE(Checklist!$AE$5:$AE$304,2),Checklist!$AE$5:$AE$304,0))="","",INDEX(Checklist!$AD$5:$AD$304,MATCH(LARGE(Checklist!$AE$5:$AE$304,2),Checklist!$AE$5:$AE$304,0))),""),"") -> Documentos devolvidos ao cliente; Avaliação do cliente pedida
A12: 3 | B12: =IFERROR(IF(LARGE(Checklist!$AE$5:$AE$304,3)>0,IF(INDEX(Checklist!$A$5:$A$304,MATCH(LARGE(Checklist!$AE$5:$AE$304,3),Checklist!$AE$5:$AE$304,0))="","",INDEX(Checklist!$A$5:$A$304,MATCH(LARGE(Checklist!$AE$5:$AE$304,3),Checklist!$AE$5:$AE$304,0))),""),"") -> 2998500-50.2026.8.26.0515 | C12: =IFERROR(IF(LARGE(Checklist!$AE$5:$AE$304,3)>0,IF(INDEX(Checklist!$B$5:$B$304,MATCH(LARGE(Checklist!$AE$5:$AE$304,3),Checklist!$AE$5:$AE$304,0))="","",INDEX(Checklist!$B$5:$B$304,MATCH(LARGE(Checklist!$AE$5:$AE$304,3),Checklist!$AE$5:$AE$304,0))),""),"") -> Ana Beatriz Moreira | D12: =IFERROR(IF(LARGE(Checklist!$AE$5:$AE$304,3)>0,IF(INDEX(Checklist!$D$5:$D$304,MATCH(LARGE(Checklist!$AE$5:$AE$304,3),Checklist!$AE$5:$AE$304,0))="","",INDEX(Checklist!$D$5:$D$304,MATCH(LARGE(Checklist!$AE$5:$AE$304,3),Checklist!$AE$5:$AE$304,0))),""),"") -> Em andamento | E12: =IFERROR(IF(LARGE(Checklist!$AE$5:$AE$304,3)>0,IF(INDEX(Checklist!$C$5:$C$304,MATCH(LARGE(Checklist!$AE$5:$AE$304,3),Checklist!$AE$5:$AE$304,0))="","",INDEX(Checklist!$C$5:$C$304,MATCH(LARGE(Checklist!$AE$5:$AE$304,3),Checklist!$AE$5:$AE$304,0))),""),"") -> Rafael Lima | F12: =IFERROR(IF(LARGE(Checklist!$AE$5:$AE$304,3)>0,IF(INDEX(Checklist!$Y$5:$Y$304,MATCH(LARGE(Checklist!$AE$5:$AE$304,3),Checklist!$AE$5:$AE$304,0))="","",INDEX(Checklist!$Y$5:$Y$304,MATCH(LARGE(Checklist!$AE$5:$AE$304,3),Checklist!$AE$5:$AE$304,0))),""),"") -> 0.88888889 | G12: =IFERROR(IF(LARGE(Checklist!$AE$5:$AE$304,3)>0,IF(INDEX(Checklist!$Z$5:$Z$304,MATCH(LARGE(Checklist!$AE$5:$AE$304,3),Checklist!$AE$5:$AE$304,0))="","",INDEX(Checklist!$Z$5:$Z$304,MATCH(LARGE(Checklist!$AE$5:$AE$304,3),Checklist!$AE$5:$AE$304,0))),""),"") | H12: =IFERROR(IF(LARGE(Checklist!$AE$5:$AE$304,3)>0,IF(INDEX(Checklist!$AC$5:$AC$304,MATCH(LARGE(Checklist!$AE$5:$AE$304,3),Checklist!$AE$5:$AE$304,0))="","",INDEX(Checklist!$AC$5:$AC$304,MATCH(LARGE(Checklist!$AE$5:$AE$304,3),Checklist!$AE$5:$AE$304,0))),""),"") -> 1 | I12: =IFERROR(IF(LARGE(Checklist!$AE$5:$AE$304,3)>0,IF(INDEX(Checklist!$AD$5:$AD$304,MATCH(LARGE(Checklist!$AE$5:$AE$304,3),Checklist!$AE$5:$AE$304,0))="","",INDEX(Checklist!$AD$5:$AD$304,MATCH(LARGE(Checklist!$AE$5:$AE$304,3),Checklist!$AE$5:$AE$304,0))),""),"") -> Contrato de honorários assinado
A13: 4 | B13: =IFERROR(IF(LARGE(Checklist!$AE$5:$AE$304,4)>0,IF(INDEX(Checklist!$A$5:$A$304,MATCH(LARGE(Checklist!$AE$5:$AE$304,4),Checklist!$AE$5:$AE$304,0))="","",INDEX(Checklist!$A$5:$A$304,MATCH(LARGE(Checklist!$AE$5:$AE$304,4),Checklist!$AE$5:$AE$304,0))),""),"") -> CONS-2026-02 | C13: =IFERROR(IF(LARGE(Checklist!$AE$5:$AE$304,4)>0,IF(INDEX(Checklist!$B$5:$B$304,MATCH(LARGE(Checklist!$AE$5:$AE$304,4),Checklist!$AE$5:$AE$304,0))="","",INDEX(Checklist!$B$5:$B$304,MATCH(LARGE(Checklist!$AE$5:$AE$304,4),Checklist!$AE$5:$AE$304,0))),""),"") -> Loja Verde Comércio | D13: =IFERROR(IF(LARGE(Checklist!$AE$5:$AE$304,4)>0,IF(INDEX(Checklist!$D$5:$D$304,MATCH(LARGE(Checklist!$AE$5:$AE$304,4),Checklist!$AE$5:$AE$304,0))="","",INDEX(Checklist!$D$5:$D$304,MATCH(LARGE(Checklist!$AE$5:$AE$304,4),Checklist!$AE$5:$AE$304,0))),""),"") -> Em andamento | E13: =IFERROR(IF(LARGE(Checklist!$AE$5:$AE$304,4)>0,IF(INDEX(Checklist!$C$5:$C$304,MATCH(LARGE(Checklist!$AE$5:$AE$304,4),Checklist!$AE$5:$AE$304,0))="","",INDEX(Checklist!$C$5:$C$304,MATCH(LARGE(Checklist!$AE$5:$AE$304,4),Checklist!$AE$5:$AE$304,0))),""),"") -> Marina Ferraz | F13: =IFERROR(IF(LARGE(Checklist!$AE$5:$AE$304,4)>0,IF(INDEX(Checklist!$Y$5:$Y$304,MATCH(LARGE(Checklist!$AE$5:$AE$304,4),Checklist!$AE$5:$AE$304,0))="","",INDEX(Checklist!$Y$5:$Y$304,MATCH(LARGE(Checklist!$AE$5:$AE$304,4),Checklist!$AE$5:$AE$304,0))),""),"") -> 0.85714286 | G13: =IFERROR(IF(LARGE(Checklist!$AE$5:$AE$304,4)>0,IF(INDEX(Checklist!$Z$5:$Z$304,MATCH(LARGE(Checklist!$AE$5:$AE$304,4),Checklist!$AE$5:$AE$304,0))="","",INDEX(Checklist!$Z$5:$Z$304,MATCH(LARGE(Checklist!$AE$5:$AE$304,4),Checklist!$AE$5:$AE$304,0))),""),"") | H13: =IFERROR(IF(LARGE(Checklist!$AE$5:$AE$304,4)>0,IF(INDEX(Checklist!$AC$5:$AC$304,MATCH(LARGE(Checklist!$AE$5:$AE$304,4),Checklist!$AE$5:$AE$304,0))="","",INDEX(Checklist!$AC$5:$AC$304,MATCH(LARGE(Checklist!$AE$5:$AE$304,4),Checklist!$AE$5:$AE$304,0))),""),"") -> 1 | I13: =IFERROR(IF(LARGE(Checklist!$AE$5:$AE$304,4)>0,IF(INDEX(Checklist!$AD$5:$AD$304,MATCH(LARGE(Checklist!$AE$5:$AE$304,4),Checklist!$AE$5:$AE$304,0))="","",INDEX(Checklist!$AD$5:$AD$304,MATCH(LARGE(Checklist!$AE$5:$AE$304,4),Checklist!$AE$5:$AE$304,0))),""),"") -> Caso cadastrado no caixa e na carteira
A14: 5 | B14: =IFERROR(IF(LARGE(Checklist!$AE$5:$AE$304,5)>0,IF(INDEX(Checklist!$A$5:$A$304,MATCH(LARGE(Checklist!$AE$5:$AE$304,5),Checklist!$AE$5:$AE$304,0))="","",INDEX(Checklist!$A$5:$A$304,MATCH(LARGE(Checklist!$AE$5:$AE$304,5),Checklist!$AE$5:$AE$304,0))),""),"") -> 4526984-60.2026.8.26.0258 | C14: =IFERROR(IF(LARGE(Checklist!$AE$5:$AE$304,5)>0,IF(INDEX(Checklist!$B$5:$B$304,MATCH(LARGE(Checklist!$AE$5:$AE$304,5),Checklist!$AE$5:$AE$304,0))="","",INDEX(Checklist!$B$5:$B$304,MATCH(LARGE(Checklist!$AE$5:$AE$304,5),Checklist!$AE$5:$AE$304,0))),""),"") -> Transportadora Rota Sul | D14: =IFERROR(IF(LARGE(Checklist!$AE$5:$AE$304,5)>0,IF(INDEX(Checklist!$D$5:$D$304,MATCH(LARGE(Checklist!$AE$5:$AE$304,5),Checklist!$AE$5:$AE$304,0))="","",INDEX(Checklist!$D$5:$D$304,MATCH(LARGE(Checklist!$AE$5:$AE$304,5),Checklist!$AE$5:$AE$304,0))),""),"") -> Em andamento | E14: =IFERROR(IF(LARGE(Checklist!$AE$5:$AE$304,5)>0,IF(INDEX(Checklist!$C$5:$C$304,MATCH(LARGE(Checklist!$AE$5:$AE$304,5),Checklist!$AE$5:$AE$304,0))="","",INDEX(Checklist!$C$5:$C$304,MATCH(LARGE(Checklist!$AE$5:$AE$304,5),Checklist!$AE$5:$AE$304,0))),""),"") -> Rafael Lima | F14: =IFERROR(IF(LARGE(Checklist!$AE$5:$AE$304,5)>0,IF(INDEX(Checklist!$Y$5:$Y$304,MATCH(LARGE(Checklist!$AE$5:$AE$304,5),Checklist!$AE$5:$AE$304,0))="","",INDEX(Checklist!$Y$5:$Y$304,MATCH(LARGE(Checklist!$AE$5:$AE$304,5),Checklist!$AE$5:$AE$304,0))),""),"") -> 0.88888889 | G14: =IFERROR(IF(LARGE(Checklist!$AE$5:$AE$304,5)>0,IF(INDEX(Checklist!$Z$5:$Z$304,MATCH(LARGE(Checklist!$AE$5:$AE$304,5),Checklist!$AE$5:$AE$304,0))="","",INDEX(Checklist!$Z$5:$Z$304,MATCH(LARGE(Checklist!$AE$5:$AE$304,5),Checklist!$AE$5:$AE$304,0))),""),"") | H14: =IFERROR(IF(LARGE(Checklist!$AE$5:$AE$304,5)>0,IF(INDEX(Checklist!$AC$5:$AC$304,MATCH(LARGE(Checklist!$AE$5:$AE$304,5),Checklist!$AE$5:$AE$304,0))="","",INDEX(Checklist!$AC$5:$AC$304,MATCH(LARGE(Checklist!$AE$5:$AE$304,5),Checklist!$AE$5:$AE$304,0))),""),"") -> 1 | I14: =IFERROR(IF(LARGE(Checklist!$AE$5:$AE$304,5)>0,IF(INDEX(Checklist!$AD$5:$AD$304,MATCH(LARGE(Checklist!$AE$5:$AE$304,5),Checklist!$AE$5:$AE$304,0))="","",INDEX(Checklist!$AD$5:$AD$304,MATCH(LARGE(Checklist!$AE$5:$AE$304,5),Checklist!$AE$5:$AE$304,0))),""),"") -> Caso cadastrado no caixa e na carteira
A15: 6 | B15: =IFERROR(IF(LARGE(Checklist!$AE$5:$AE$304,6)>0,IF(INDEX(Checklist!$A$5:$A$304,MATCH(LARGE(Checklist!$AE$5:$AE$304,6),Checklist!$AE$5:$AE$304,0))="","",INDEX(Checklist!$A$5:$A$304,MATCH(LARGE(Checklist!$AE$5:$AE$304,6),Checklist!$AE$5:$AE$304,0))),""),"") -> 5900991-46.2026.8.26.0469 | C15: =IFERROR(IF(LARGE(Checklist!$AE$5:$AE$304,6)>0,IF(INDEX(Checklist!$B$5:$B$304,MATCH(LARGE(Checklist!$AE$5:$AE$304,6),Checklist!$AE$5:$AE$304,0))="","",INDEX(Checklist!$B$5:$B$304,MATCH(LARGE(Checklist!$AE$5:$AE$304,6),Checklist!$AE$5:$AE$304,0))),""),"") -> José Antônio Ribeiro | D15: =IFERROR(IF(LARGE(Checklist!$AE$5:$AE$304,6)>0,IF(INDEX(Checklist!$D$5:$D$304,MATCH(LARGE(Checklist!$AE$5:$AE$304,6),Checklist!$AE$5:$AE$304,0))="","",INDEX(Checklist!$D$5:$D$304,MATCH(LARGE(Checklist!$AE$5:$AE$304,6),Checklist!$AE$5:$AE$304,0))),""),"") -> Em andamento | E15: =IFERROR(IF(LARGE(Checklist!$AE$5:$AE$304,6)>0,IF(INDEX(Checklist!$C$5:$C$304,MATCH(LARGE(Checklist!$AE$5:$AE$304,6),Checklist!$AE$5:$AE$304,0))="","",INDEX(Checklist!$C$5:$C$304,MATCH(LARGE(Checklist!$AE$5:$AE$304,6),Checklist!$AE$5:$AE$304,0))),""),"") -> Rafael Lima | F15: =IFERROR(IF(LARGE(Checklist!$AE$5:$AE$304,6)>0,IF(INDEX(Checklist!$Y$5:$Y$304,MATCH(LARGE(Checklist!$AE$5:$AE$304,6),Checklist!$AE$5:$AE$304,0))="","",INDEX(Checklist!$Y$5:$Y$304,MATCH(LARGE(Checklist!$AE$5:$AE$304,6),Checklist!$AE$5:$AE$304,0))),""),"") -> 0.88888889 | G15: =IFERROR(IF(LARGE(Checklist!$AE$5:$AE$304,6)>0,IF(INDEX(Checklist!$Z$5:$Z$304,MATCH(LARGE(Checklist!$AE$5:$AE$304,6),Checklist!$AE$5:$AE$304,0))="","",INDEX(Checklist!$Z$5:$Z$304,MATCH(LARGE(Checklist!$AE$5:$AE$304,6),Checklist!$AE$5:$AE$304,0))),""),"") | H15: =IFERROR(IF(LARGE(Checklist!$AE$5:$AE$304,6)>0,IF(INDEX(Checklist!$AC$5:$AC$304,MATCH(LARGE(Checklist!$AE$5:$AE$304,6),Checklist!$AE$5:$AE$304,0))="","",INDEX(Checklist!$AC$5:$AC$304,MATCH(LARGE(Checklist!$AE$5:$AE$304,6),Checklist!$AE$5:$AE$304,0))),""),"") -> 1 | I15: =IFERROR(IF(LARGE(Checklist!$AE$5:$AE$304,6)>0,IF(INDEX(Checklist!$AD$5:$AD$304,MATCH(LARGE(Checklist!$AE$5:$AE$304,6),Checklist!$AE$5:$AE$304,0))="","",INDEX(Checklist!$AD$5:$AD$304,MATCH(LARGE(Checklist!$AE$5:$AE$304,6),Checklist!$AE$5:$AE$304,0))),""),"") -> Documentos do cliente recebidos
A16: 7 | B16: =IFERROR(IF(LARGE(Checklist!$AE$5:$AE$304,7)>0,IF(INDEX(Checklist!$A$5:$A$304,MATCH(LARGE(Checklist!$AE$5:$AE$304,7),Checklist!$AE$5:$AE$304,0))="","",INDEX(Checklist!$A$5:$A$304,MATCH(LARGE(Checklist!$AE$5:$AE$304,7),Checklist!$AE$5:$AE$304,0))),""),"") -> 2521428-61.2026.8.26.0600 | C16: =IFERROR(IF(LARGE(Checklist!$AE$5:$AE$304,7)>0,IF(INDEX(Checklist!$B$5:$B$304,MATCH(LARGE(Checklist!$AE$5:$AE$304,7),Checklist!$AE$5:$AE$304,0))="","",INDEX(Checklist!$B$5:$B$304,MATCH(LARGE(Checklist!$AE$5:$AE$304,7),Checklist!$AE$5:$AE$304,0))),""),"") -> Luciana Farias | D16: =IFERROR(IF(LARGE(Checklist!$AE$5:$AE$304,7)>0,IF(INDEX(Checklist!$D$5:$D$304,MATCH(LARGE(Checklist!$AE$5:$AE$304,7),Checklist!$AE$5:$AE$304,0))="","",INDEX(Checklist!$D$5:$D$304,MATCH(LARGE(Checklist!$AE$5:$AE$304,7),Checklist!$AE$5:$AE$304,0))),""),"") -> Em andamento | E16: =IFERROR(IF(LARGE(Checklist!$AE$5:$AE$304,7)>0,IF(INDEX(Checklist!$C$5:$C$304,MATCH(LARGE(Checklist!$AE$5:$AE$304,7),Checklist!$AE$5:$AE$304,0))="","",INDEX(Checklist!$C$5:$C$304,MATCH(LARGE(Checklist!$AE$5:$AE$304,7),Checklist!$AE$5:$AE$304,0))),""),"") -> Marina Ferraz | F16: =IFERROR(IF(LARGE(Checklist!$AE$5:$AE$304,7)>0,IF(INDEX(Checklist!$Y$5:$Y$304,MATCH(LARGE(Checklist!$AE$5:$AE$304,7),Checklist!$AE$5:$AE$304,0))="","",INDEX(Checklist!$Y$5:$Y$304,MATCH(LARGE(Checklist!$AE$5:$AE$304,7),Checklist!$AE$5:$AE$304,0))),""),"") -> 0.88888889 | G16: =IFERROR(IF(LARGE(Checklist!$AE$5:$AE$304,7)>0,IF(INDEX(Checklist!$Z$5:$Z$304,MATCH(LARGE(Checklist!$AE$5:$AE$304,7),Checklist!$AE$5:$AE$304,0))="","",INDEX(Checklist!$Z$5:$Z$304,MATCH(LARGE(Checklist!$AE$5:$AE$304,7),Checklist!$AE$5:$AE$304,0))),""),"") | H16: =IFERROR(IF(LARGE(Checklist!$AE$5:$AE$304,7)>0,IF(INDEX(Checklist!$AC$5:$AC$304,MATCH(LARGE(Checklist!$AE$5:$AE$304,7),Checklist!$AE$5:$AE$304,0))="","",INDEX(Checklist!$AC$5:$AC$304,MATCH(LARGE(Checklist!$AE$5:$AE$304,7),Checklist!$AE$5:$AE$304,0))),""),"") -> 1 | I16: =IFERROR(IF(LARGE(Checklist!$AE$5:$AE$304,7)>0,IF(INDEX(Checklist!$AD$5:$AD$304,MATCH(LARGE(Checklist!$AE$5:$AE$304,7),Checklist!$AE$5:$AE$304,0))="","",INDEX(Checklist!$AD$5:$AD$304,MATCH(LARGE(Checklist!$AE$5:$AE$304,7),Checklist!$AE$5:$AE$304,0))),""),"") -> Procuração recebida
A17: 8 | B17: =IFERROR(IF(LARGE(Checklist!$AE$5:$AE$304,8)>0,IF(INDEX(Checklist!$A$5:$A$304,MATCH(LARGE(Checklist!$AE$5:$AE$304,8),Checklist!$AE$5:$AE$304,0))="","",INDEX(Checklist!$A$5:$A$304,MATCH(LARGE(Checklist!$AE$5:$AE$304,8),Checklist!$AE$5:$AE$304,0))),""),"") -> 7679821-77.2026.8.26.0265 | C17: =IFERROR(IF(LARGE(Checklist!$AE$5:$AE$304,8)>0,IF(INDEX(Checklist!$B$5:$B$304,MATCH(LARGE(Checklist!$AE$5:$AE$304,8),Checklist!$AE$5:$AE$304,0))="","",INDEX(Checklist!$B$5:$B$304,MATCH(LARGE(Checklist!$AE$5:$AE$304,8),Checklist!$AE$5:$AE$304,0))),""),"") -> Helena Duarte | D17: =IFERROR(IF(LARGE(Checklist!$AE$5:$AE$304,8)>0,IF(INDEX(Checklist!$D$5:$D$304,MATCH(LARGE(Checklist!$AE$5:$AE$304,8),Checklist!$AE$5:$AE$304,0))="","",INDEX(Checklist!$D$5:$D$304,MATCH(LARGE(Checklist!$AE$5:$AE$304,8),Checklist!$AE$5:$AE$304,0))),""),"") -> Em andamento | E17: =IFERROR(IF(LARGE(Checklist!$AE$5:$AE$304,8)>0,IF(INDEX(Checklist!$C$5:$C$304,MATCH(LARGE(Checklist!$AE$5:$AE$304,8),Checklist!$AE$5:$AE$304,0))="","",INDEX(Checklist!$C$5:$C$304,MATCH(LARGE(Checklist!$AE$5:$AE$304,8),Checklist!$AE$5:$AE$304,0))),""),"") -> Rafael Lima | F17: =IFERROR(IF(LARGE(Checklist!$AE$5:$AE$304,8)>0,IF(INDEX(Checklist!$Y$5:$Y$304,MATCH(LARGE(Checklist!$AE$5:$AE$304,8),Checklist!$AE$5:$AE$304,0))="","",INDEX(Checklist!$Y$5:$Y$304,MATCH(LARGE(Checklist!$AE$5:$AE$304,8),Checklist!$AE$5:$AE$304,0))),""),"") -> 0.88888889 | G17: =IFERROR(IF(LARGE(Checklist!$AE$5:$AE$304,8)>0,IF(INDEX(Checklist!$Z$5:$Z$304,MATCH(LARGE(Checklist!$AE$5:$AE$304,8),Checklist!$AE$5:$AE$304,0))="","",INDEX(Checklist!$Z$5:$Z$304,MATCH(LARGE(Checklist!$AE$5:$AE$304,8),Checklist!$AE$5:$AE$304,0))),""),"") | H17: =IFERROR(IF(LARGE(Checklist!$AE$5:$AE$304,8)>0,IF(INDEX(Checklist!$AC$5:$AC$304,MATCH(LARGE(Checklist!$AE$5:$AE$304,8),Checklist!$AE$5:$AE$304,0))="","",INDEX(Checklist!$AC$5:$AC$304,MATCH(LARGE(Checklist!$AE$5:$AE$304,8),Checklist!$AE$5:$AE$304,0))),""),"") -> 1 | I17: =IFERROR(IF(LARGE(Checklist!$AE$5:$AE$304,8)>0,IF(INDEX(Checklist!$AD$5:$AD$304,MATCH(LARGE(Checklist!$AE$5:$AE$304,8),Checklist!$AE$5:$AE$304,0))="","",INDEX(Checklist!$AD$5:$AD$304,MATCH(LARGE(Checklist!$AE$5:$AE$304,8),Checklist!$AE$5:$AE$304,0))),""),"") -> Honorário e forma de pagamento definidos
A18: 9 | B18: =IFERROR(IF(LARGE(Checklist!$AE$5:$AE$304,9)>0,IF(INDEX(Checklist!$A$5:$A$304,MATCH(LARGE(Checklist!$AE$5:$AE$304,9),Checklist!$AE$5:$AE$304,0))="","",INDEX(Checklist!$A$5:$A$304,MATCH(LARGE(Checklist!$AE$5:$AE$304,9),Checklist!$AE$5:$AE$304,0))),""),"") -> 9778116-95.2025.8.26.0106 | C18: =IFERROR(IF(LARGE(Checklist!$AE$5:$AE$304,9)>0,IF(INDEX(Checklist!$B$5:$B$304,MATCH(LARGE(Checklist!$AE$5:$AE$304,9),Checklist!$AE$5:$AE$304,0))="","",INDEX(Checklist!$B$5:$B$304,MATCH(LARGE(Checklist!$AE$5:$AE$304,9),Checklist!$AE$5:$AE$304,0))),""),"") -> Construtora Horizonte | D18: =IFERROR(IF(LARGE(Checklist!$AE$5:$AE$304,9)>0,IF(INDEX(Checklist!$D$5:$D$304,MATCH(LARGE(Checklist!$AE$5:$AE$304,9),Checklist!$AE$5:$AE$304,0))="","",INDEX(Checklist!$D$5:$D$304,MATCH(LARGE(Checklist!$AE$5:$AE$304,9),Checklist!$AE$5:$AE$304,0))),""),"") -> Encerrado | E18: =IFERROR(IF(LARGE(Checklist!$AE$5:$AE$304,9)>0,IF(INDEX(Checklist!$C$5:$C$304,MATCH(LARGE(Checklist!$AE$5:$AE$304,9),Checklist!$AE$5:$AE$304,0))="","",INDEX(Checklist!$C$5:$C$304,MATCH(LARGE(Checklist!$AE$5:$AE$304,9),Checklist!$AE$5:$AE$304,0))),""),"") -> Marina Ferraz | F18: =IFERROR(IF(LARGE(Checklist!$AE$5:$AE$304,9)>0,IF(INDEX(Checklist!$Y$5:$Y$304,MATCH(LARGE(Checklist!$AE$5:$AE$304,9),Checklist!$AE$5:$AE$304,0))="","",INDEX(Checklist!$Y$5:$Y$304,MATCH(LARGE(Checklist!$AE$5:$AE$304,9),Checklist!$AE$5:$AE$304,0))),""),"") -> 1 | G18: =IFERROR(IF(LARGE(Checklist!$AE$5:$AE$304,9)>0,IF(INDEX(Checklist!$Z$5:$Z$304,MATCH(LARGE(Checklist!$AE$5:$AE$304,9),Checklist!$AE$5:$AE$304,0))="","",INDEX(Checklist!$Z$5:$Z$304,MATCH(LARGE(Checklist!$AE$5:$AE$304,9),Checklist!$AE$5:$AE$304,0))),""),"") -> 0.875 | H18: =IFERROR(IF(LARGE(Checklist!$AE$5:$AE$304,9)>0,IF(INDEX(Checklist!$AC$5:$AC$304,MATCH(LARGE(Checklist!$AE$5:$AE$304,9),Checklist!$AE$5:$AE$304,0))="","",INDEX(Checklist!$AC$5:$AC$304,MATCH(LARGE(Checklist!$AE$5:$AE$304,9),Checklist!$AE$5:$AE$304,0))),""),"") -> 1 | I18: =IFERROR(IF(LARGE(Checklist!$AE$5:$AE$304,9)>0,IF(INDEX(Checklist!$AD$5:$AD$304,MATCH(LARGE(Checklist!$AE$5:$AE$304,9),Checklist!$AE$5:$AE$304,0))="","",INDEX(Checklist!$AD$5:$AD$304,MATCH(LARGE(Checklist!$AE$5:$AE$304,9),Checklist!$AE$5:$AE$304,0))),""),"") -> Pasta arquivada
A19: 10 | B19: =IFERROR(IF(LARGE(Checklist!$AE$5:$AE$304,10)>0,IF(INDEX(Checklist!$A$5:$A$304,MATCH(LARGE(Checklist!$AE$5:$AE$304,10),Checklist!$AE$5:$AE$304,0))="","",INDEX(Checklist!$A$5:$A$304,MATCH(LARGE(Checklist!$AE$5:$AE$304,10),Checklist!$AE$5:$AE$304,0))),""),"") -> 5211189-81.2025.8.26.0412 | C19: =IFERROR(IF(LARGE(Checklist!$AE$5:$AE$304,10)>0,IF(INDEX(Checklist!$B$5:$B$304,MATCH(LARGE(Checklist!$AE$5:$AE$304,10),Checklist!$AE$5:$AE$304,0))="","",INDEX(Checklist!$B$5:$B$304,MATCH(LARGE(Checklist!$AE$5:$AE$304,10),Checklist!$AE$5:$AE$304,0))),""),"") -> Fernanda Castro | D19: =IFERROR(IF(LARGE(Checklist!$AE$5:$AE$304,10)>0,IF(INDEX(Checklist!$D$5:$D$304,MATCH(LARGE(Checklist!$AE$5:$AE$304,10),Checklist!$AE$5:$AE$304,0))="","",INDEX(Checklist!$D$5:$D$304,MATCH(LARGE(Checklist!$AE$5:$AE$304,10),Checklist!$AE$5:$AE$304,0))),""),"") -> Encerrado | E19: =IFERROR(IF(LARGE(Checklist!$AE$5:$AE$304,10)>0,IF(INDEX(Checklist!$C$5:$C$304,MATCH(LARGE(Checklist!$AE$5:$AE$304,10),Checklist!$AE$5:$AE$304,0))="","",INDEX(Checklist!$C$5:$C$304,MATCH(LARGE(Checklist!$AE$5:$AE$304,10),Checklist!$AE$5:$AE$304,0))),""),"") -> Marina Ferraz | F19: =IFERROR(IF(LARGE(Checklist!$AE$5:$AE$304,10)>0,IF(INDEX(Checklist!$Y$5:$Y$304,MATCH(LARGE(Checklist!$AE$5:$AE$304,10),Checklist!$AE$5:$AE$304,0))="","",INDEX(Checklist!$Y$5:$Y$304,MATCH(LARGE(Checklist!$AE$5:$AE$304,10),Checklist!$AE$5:$AE$304,0))),""),"") -> 1 | G19: =IFERROR(IF(LARGE(Checklist!$AE$5:$AE$304,10)>0,IF(INDEX(Checklist!$Z$5:$Z$304,MATCH(LARGE(Checklist!$AE$5:$AE$304,10),Checklist!$AE$5:$AE$304,0))="","",INDEX(Checklist!$Z$5:$Z$304,MATCH(LARGE(Checklist!$AE$5:$AE$304,10),Checklist!$AE$5:$AE$304,0))),""),"") -> 0.875 | H19: =IFERROR(IF(LARGE(Checklist!$AE$5:$AE$304,10)>0,IF(INDEX(Checklist!$AC$5:$AC$304,MATCH(LARGE(Checklist!$AE$5:$AE$304,10),Checklist!$AE$5:$AE$304,0))="","",INDEX(Checklist!$AC$5:$AC$304,MATCH(LARGE(Checklist!$AE$5:$AE$304,10),Checklist!$AE$5:$AE$304,0))),""),"") -> 1 | I19: =IFERROR(IF(LARGE(Checklist!$AE$5:$AE$304,10)>0,IF(INDEX(Checklist!$AD$5:$AD$304,MATCH(LARGE(Checklist!$AE$5:$AE$304,10),Checklist!$AE$5:$AE$304,0))="","",INDEX(Checklist!$AD$5:$AD$304,MATCH(LARGE(Checklist!$AE$5:$AE$304,10),Checklist!$AE$5:$AE$304,0))),""),"") -> Avaliação do cliente pedida
A20: 11 | B20: =IFERROR(IF(LARGE(Checklist!$AE$5:$AE$304,11)>0,IF(INDEX(Checklist!$A$5:$A$304,MATCH(LARGE(Checklist!$AE$5:$AE$304,11),Checklist!$AE$5:$AE$304,0))="","",INDEX(Checklist!$A$5:$A$304,MATCH(LARGE(Checklist!$AE$5:$AE$304,11),Checklist!$AE$5:$AE$304,0))),""),"") | C20: =IFERROR(IF(LARGE(Checklist!$AE$5:$AE$304,11)>0,IF(INDEX(Checklist!$B$5:$B$304,MATCH(LARGE(Checklist!$AE$5:$AE$304,11),Checklist!$AE$5:$AE$304,0))="","",INDEX(Checklist!$B$5:$B$304,MATCH(LARGE(Checklist!$AE$5:$AE$304,11),Checklist!$AE$5:$AE$304,0))),""),"") | D20: =IFERROR(IF(LARGE(Checklist!$AE$5:$AE$304,11)>0,IF(INDEX(Checklist!$D$5:$D$304,MATCH(LARGE(Checklist!$AE$5:$AE$304,11),Checklist!$AE$5:$AE$304,0))="","",INDEX(Checklist!$D$5:$D$304,MATCH(LARGE(Checklist!$AE$5:$AE$304,11),Checklist!$AE$5:$AE$304,0))),""),"") | E20: =IFERROR(IF(LARGE(Checklist!$AE$5:$AE$304,11)>0,IF(INDEX(Checklist!$C$5:$C$304,MATCH(LARGE(Checklist!$AE$5:$AE$304,11),Checklist!$AE$5:$AE$304,0))="","",INDEX(Checklist!$C$5:$C$304,MATCH(LARGE(Checklist!$AE$5:$AE$304,11),Checklist!$AE$5:$AE$304,0))),""),"") | F20: =IFERROR(IF(LARGE(Checklist!$AE$5:$AE$304,11)>0,IF(INDEX(Checklist!$Y$5:$Y$304,MATCH(LARGE(Checklist!$AE$5:$AE$304,11),Checklist!$AE$5:$AE$304,0))="","",INDEX(Checklist!$Y$5:$Y$304,MATCH(LARGE(Checklist!$AE$5:$AE$304,11),Checklist!$AE$5:$AE$304,0))),""),"") | G20: =IFERROR(IF(LARGE(Checklist!$AE$5:$AE$304,11)>0,IF(INDEX(Checklist!$Z$5:$Z$304,MATCH(LARGE(Checklist!$AE$5:$AE$304,11),Checklist!$AE$5:$AE$304,0))="","",INDEX(Checklist!$Z$5:$Z$304,MATCH(LARGE(Checklist!$AE$5:$AE$304,11),Checklist!$AE$5:$AE$304,0))),""),"") | H20: =IFERROR(IF(LARGE(Checklist!$AE$5:$AE$304,11)>0,IF(INDEX(Checklist!$AC$5:$AC$304,MATCH(LARGE(Checklist!$AE$5:$AE$304,11),Checklist!$AE$5:$AE$304,0))="","",INDEX(Checklist!$AC$5:$AC$304,MATCH(LARGE(Checklist!$AE$5:$AE$304,11),Checklist!$AE$5:$AE$304,0))),""),"") | I20: =IFERROR(IF(LARGE(Checklist!$AE$5:$AE$304,11)>0,IF(INDEX(Checklist!$AD$5:$AD$304,MATCH(LARGE(Checklist!$AE$5:$AE$304,11),Checklist!$AE$5:$AE$304,0))="","",INDEX(Checklist!$AD$5:$AD$304,MATCH(LARGE(Checklist!$AE$5:$AE$304,11),Checklist!$AE$5:$AE$304,0))),""),"")
A21: 12 | B21: =IFERROR(IF(LARGE(Checklist!$AE$5:$AE$304,12)>0,IF(INDEX(Checklist!$A$5:$A$304,MATCH(LARGE(Checklist!$AE$5:$AE$304,12),Checklist!$AE$5:$AE$304,0))="","",INDEX(Checklist!$A$5:$A$304,MATCH(LARGE(Checklist!$AE$5:$AE$304,12),Checklist!$AE$5:$AE$304,0))),""),"") | C21: =IFERROR(IF(LARGE(Checklist!$AE$5:$AE$304,12)>0,IF(INDEX(Checklist!$B$5:$B$304,MATCH(LARGE(Checklist!$AE$5:$AE$304,12),Checklist!$AE$5:$AE$304,0))="","",INDEX(Checklist!$B$5:$B$304,MATCH(LARGE(Checklist!$AE$5:$AE$304,12),Checklist!$AE$5:$AE$304,0))),""),"") | D21: =IFERROR(IF(LARGE(Checklist!$AE$5:$AE$304,12)>0,IF(INDEX(Checklist!$D$5:$D$304,MATCH(LARGE(Checklist!$AE$5:$AE$304,12),Checklist!$AE$5:$AE$304,0))="","",INDEX(Checklist!$D$5:$D$304,MATCH(LARGE(Checklist!$AE$5:$AE$304,12),Checklist!$AE$5:$AE$304,0))),""),"") | E21: =IFERROR(IF(LARGE(Checklist!$AE$5:$AE$304,12)>0,IF(INDEX(Checklist!$C$5:$C$304,MATCH(LARGE(Checklist!$AE$5:$AE$304,12),Checklist!$AE$5:$AE$304,0))="","",INDEX(Checklist!$C$5:$C$304,MATCH(LARGE(Checklist!$AE$5:$AE$304,12),Checklist!$AE$5:$AE$304,0))),""),"") | F21: =IFERROR(IF(LARGE(Checklist!$AE$5:$AE$304,12)>0,IF(INDEX(Checklist!$Y$5:$Y$304,MATCH(LARGE(Checklist!$AE$5:$AE$304,12),Checklist!$AE$5:$AE$304,0))="","",INDEX(Checklist!$Y$5:$Y$304,MATCH(LARGE(Checklist!$AE$5:$AE$304,12),Checklist!$AE$5:$AE$304,0))),""),"") | G21: =IFERROR(IF(LARGE(Checklist!$AE$5:$AE$304,12)>0,IF(INDEX(Checklist!$Z$5:$Z$304,MATCH(LARGE(Checklist!$AE$5:$AE$304,12),Checklist!$AE$5:$AE$304,0))="","",INDEX(Checklist!$Z$5:$Z$304,MATCH(LARGE(Checklist!$AE$5:$AE$304,12),Checklist!$AE$5:$AE$304,0))),""),"") | H21: =IFERROR(IF(LARGE(Checklist!$AE$5:$AE$304,12)>0,IF(INDEX(Checklist!$AC$5:$AC$304,MATCH(LARGE(Checklist!$AE$5:$AE$304,12),Checklist!$AE$5:$AE$304,0))="","",INDEX(Checklist!$AC$5:$AC$304,MATCH(LARGE(Checklist!$AE$5:$AE$304,12),Checklist!$AE$5:$AE$304,0))),""),"") | I21: =IFERROR(IF(LARGE(Checklist!$AE$5:$AE$304,12)>0,IF(INDEX(Checklist!$AD$5:$AD$304,MATCH(LARGE(Checklist!$AE$5:$AE$304,12),Checklist!$AE$5:$AE$304,0))="","",INDEX(Checklist!$AD$5:$AD$304,MATCH(LARGE(Checklist!$AE$5:$AE$304,12),Checklist!$AE$5:$AE$304,0))),""),"")
A22: 13 | B22: =IFERROR(IF(LARGE(Checklist!$AE$5:$AE$304,13)>0,IF(INDEX(Checklist!$A$5:$A$304,MATCH(LARGE(Checklist!$AE$5:$AE$304,13),Checklist!$AE$5:$AE$304,0))="","",INDEX(Checklist!$A$5:$A$304,MATCH(LARGE(Checklist!$AE$5:$AE$304,13),Checklist!$AE$5:$AE$304,0))),""),"") | C22: =IFERROR(IF(LARGE(Checklist!$AE$5:$AE$304,13)>0,IF(INDEX(Checklist!$B$5:$B$304,MATCH(LARGE(Checklist!$AE$5:$AE$304,13),Checklist!$AE$5:$AE$304,0))="","",INDEX(Checklist!$B$5:$B$304,MATCH(LARGE(Checklist!$AE$5:$AE$304,13),Checklist!$AE$5:$AE$304,0))),""),"") | D22: =IFERROR(IF(LARGE(Checklist!$AE$5:$AE$304,13)>0,IF(INDEX(Checklist!$D$5:$D$304,MATCH(LARGE(Checklist!$AE$5:$AE$304,13),Checklist!$AE$5:$AE$304,0))="","",INDEX(Checklist!$D$5:$D$304,MATCH(LARGE(Checklist!$AE$5:$AE$304,13),Checklist!$AE$5:$AE$304,0))),""),"") | E22: =IFERROR(IF(LARGE(Checklist!$AE$5:$AE$304,13)>0,IF(INDEX(Checklist!$C$5:$C$304,MATCH(LARGE(Checklist!$AE$5:$AE$304,13),Checklist!$AE$5:$AE$304,0))="","",INDEX(Checklist!$C$5:$C$304,MATCH(LARGE(Checklist!$AE$5:$AE$304,13),Checklist!$AE$5:$AE$304,0))),""),"") | F22: =IFERROR(IF(LARGE(Checklist!$AE$5:$AE$304,13)>0,IF(INDEX(Checklist!$Y$5:$Y$304,MATCH(LARGE(Checklist!$AE$5:$AE$304,13),Checklist!$AE$5:$AE$304,0))="","",INDEX(Checklist!$Y$5:$Y$304,MATCH(LARGE(Checklist!$AE$5:$AE$304,13),Checklist!$AE$5:$AE$304,0))),""),"") | G22: =IFERROR(IF(LARGE(Checklist!$AE$5:$AE$304,13)>0,IF(INDEX(Checklist!$Z$5:$Z$304,MATCH(LARGE(Checklist!$AE$5:$AE$304,13),Checklist!$AE$5:$AE$304,0))="","",INDEX(Checklist!$Z$5:$Z$304,MATCH(LARGE(Checklist!$AE$5:$AE$304,13),Checklist!$AE$5:$AE$304,0))),""),"") | H22: =IFERROR(IF(LARGE(Checklist!$AE$5:$AE$304,13)>0,IF(INDEX(Checklist!$AC$5:$AC$304,MATCH(LARGE(Checklist!$AE$5:$AE$304,13),Checklist!$AE$5:$AE$304,0))="","",INDEX(Checklist!$AC$5:$AC$304,MATCH(LARGE(Checklist!$AE$5:$AE$304,13),Checklist!$AE$5:$AE$304,0))),""),"") | I22: =IFERROR(IF(LARGE(Checklist!$AE$5:$AE$304,13)>0,IF(INDEX(Checklist!$AD$5:$AD$304,MATCH(LARGE(Checklist!$AE$5:$AE$304,13),Checklist!$AE$5:$AE$304,0))="","",INDEX(Checklist!$AD$5:$AD$304,MATCH(LARGE(Checklist!$AE$5:$AE$304,13),Checklist!$AE$5:$AE$304,0))),""),"")
A23: 14 | B23: =IFERROR(IF(LARGE(Checklist!$AE$5:$AE$304,14)>0,IF(INDEX(Checklist!$A$5:$A$304,MATCH(LARGE(Checklist!$AE$5:$AE$304,14),Checklist!$AE$5:$AE$304,0))="","",INDEX(Checklist!$A$5:$A$304,MATCH(LARGE(Checklist!$AE$5:$AE$304,14),Checklist!$AE$5:$AE$304,0))),""),"") | C23: =IFERROR(IF(LARGE(Checklist!$AE$5:$AE$304,14)>0,IF(INDEX(Checklist!$B$5:$B$304,MATCH(LARGE(Checklist!$AE$5:$AE$304,14),Checklist!$AE$5:$AE$304,0))="","",INDEX(Checklist!$B$5:$B$304,MATCH(LARGE(Checklist!$AE$5:$AE$304,14),Checklist!$AE$5:$AE$304,0))),""),"") | D23: =IFERROR(IF(LARGE(Checklist!$AE$5:$AE$304,14)>0,IF(INDEX(Checklist!$D$5:$D$304,MATCH(LARGE(Checklist!$AE$5:$AE$304,14),Checklist!$AE$5:$AE$304,0))="","",INDEX(Checklist!$D$5:$D$304,MATCH(LARGE(Checklist!$AE$5:$AE$304,14),Checklist!$AE$5:$AE$304,0))),""),"") | E23: =IFERROR(IF(LARGE(Checklist!$AE$5:$AE$304,14)>0,IF(INDEX(Checklist!$C$5:$C$304,MATCH(LARGE(Checklist!$AE$5:$AE$304,14),Checklist!$AE$5:$AE$304,0))="","",INDEX(Checklist!$C$5:$C$304,MATCH(LARGE(Checklist!$AE$5:$AE$304,14),Checklist!$AE$5:$AE$304,0))),""),"") | F23: =IFERROR(IF(LARGE(Checklist!$AE$5:$AE$304,14)>0,IF(INDEX(Checklist!$Y$5:$Y$304,MATCH(LARGE(Checklist!$AE$5:$AE$304,14),Checklist!$AE$5:$AE$304,0))="","",INDEX(Checklist!$Y$5:$Y$304,MATCH(LARGE(Checklist!$AE$5:$AE$304,14),Checklist!$AE$5:$AE$304,0))),""),"") | G23: =IFERROR(IF(LARGE(Checklist!$AE$5:$AE$304,14)>0,IF(INDEX(Checklist!$Z$5:$Z$304,MATCH(LARGE(Checklist!$AE$5:$AE$304,14),Checklist!$AE$5:$AE$304,0))="","",INDEX(Checklist!$Z$5:$Z$304,MATCH(LARGE(Checklist!$AE$5:$AE$304,14),Checklist!$AE$5:$AE$304,0))),""),"") | H23: =IFERROR(IF(LARGE(Checklist!$AE$5:$AE$304,14)>0,IF(INDEX(Checklist!$AC$5:$AC$304,MATCH(LARGE(Checklist!$AE$5:$AE$304,14),Checklist!$AE$5:$AE$304,0))="","",INDEX(Checklist!$AC$5:$AC$304,MATCH(LARGE(Checklist!$AE$5:$AE$304,14),Checklist!$AE$5:$AE$304,0))),""),"") | I23: =IFERROR(IF(LARGE(Checklist!$AE$5:$AE$304,14)>0,IF(INDEX(Checklist!$AD$5:$AD$304,MATCH(LARGE(Checklist!$AE$5:$AE$304,14),Checklist!$AE$5:$AE$304,0))="","",INDEX(Checklist!$AD$5:$AD$304,MATCH(LARGE(Checklist!$AE$5:$AE$304,14),Checklist!$AE$5:$AE$304,0))),""),"")
A24: 15 | B24: =IFERROR(IF(LARGE(Checklist!$AE$5:$AE$304,15)>0,IF(INDEX(Checklist!$A$5:$A$304,MATCH(LARGE(Checklist!$AE$5:$AE$304,15),Checklist!$AE$5:$AE$304,0))="","",INDEX(Checklist!$A$5:$A$304,MATCH(LARGE(Checklist!$AE$5:$AE$304,15),Checklist!$AE$5:$AE$304,0))),""),"") | C24: =IFERROR(IF(LARGE(Checklist!$AE$5:$AE$304,15)>0,IF(INDEX(Checklist!$B$5:$B$304,MATCH(LARGE(Checklist!$AE$5:$AE$304,15),Checklist!$AE$5:$AE$304,0))="","",INDEX(Checklist!$B$5:$B$304,MATCH(LARGE(Checklist!$AE$5:$AE$304,15),Checklist!$AE$5:$AE$304,0))),""),"") | D24: =IFERROR(IF(LARGE(Checklist!$AE$5:$AE$304,15)>0,IF(INDEX(Checklist!$D$5:$D$304,MATCH(LARGE(Checklist!$AE$5:$AE$304,15),Checklist!$AE$5:$AE$304,0))="","",INDEX(Checklist!$D$5:$D$304,MATCH(LARGE(Checklist!$AE$5:$AE$304,15),Checklist!$AE$5:$AE$304,0))),""),"") | E24: =IFERROR(IF(LARGE(Checklist!$AE$5:$AE$304,15)>0,IF(INDEX(Checklist!$C$5:$C$304,MATCH(LARGE(Checklist!$AE$5:$AE$304,15),Checklist!$AE$5:$AE$304,0))="","",INDEX(Checklist!$C$5:$C$304,MATCH(LARGE(Checklist!$AE$5:$AE$304,15),Checklist!$AE$5:$AE$304,0))),""),"") | F24: =IFERROR(IF(LARGE(Checklist!$AE$5:$AE$304,15)>0,IF(INDEX(Checklist!$Y$5:$Y$304,MATCH(LARGE(Checklist!$AE$5:$AE$304,15),Checklist!$AE$5:$AE$304,0))="","",INDEX(Checklist!$Y$5:$Y$304,MATCH(LARGE(Checklist!$AE$5:$AE$304,15),Checklist!$AE$5:$AE$304,0))),""),"") | G24: =IFERROR(IF(LARGE(Checklist!$AE$5:$AE$304,15)>0,IF(INDEX(Checklist!$Z$5:$Z$304,MATCH(LARGE(Checklist!$AE$5:$AE$304,15),Checklist!$AE$5:$AE$304,0))="","",INDEX(Checklist!$Z$5:$Z$304,MATCH(LARGE(Checklist!$AE$5:$AE$304,15),Checklist!$AE$5:$AE$304,0))),""),"") | H24: =IFERROR(IF(LARGE(Checklist!$AE$5:$AE$304,15)>0,IF(INDEX(Checklist!$AC$5:$AC$304,MATCH(LARGE(Checklist!$AE$5:$AE$304,15),Checklist!$AE$5:$AE$304,0))="","",INDEX(Checklist!$AC$5:$AC$304,MATCH(LARGE(Checklist!$AE$5:$AE$304,15),Checklist!$AE$5:$AE$304,0))),""),"") | I24: =IFERROR(IF(LARGE(Checklist!$AE$5:$AE$304,15)>0,IF(INDEX(Checklist!$AD$5:$AD$304,MATCH(LARGE(Checklist!$AE$5:$AE$304,15),Checklist!$AE$5:$AE$304,0))="","",INDEX(Checklist!$AD$5:$AD$304,MATCH(LARGE(Checklist!$AE$5:$AE$304,15),Checklist!$AE$5:$AE$304,0))),""),"")
A26: Item mais esquecido
A27: Abertura: conta todos os casos cadastrados. Encerramento: só os casos com situação Encerrado. Item pendente muitas vezes é sinal de que a rotina de abertura precisa mudar.
A28: Item de abertura | C28: Pendente em | D28: Feito em | E28: N/A | G28: Item de encerramento | H28: Pendente em | I28: Feito em | J28: N/A
A29: =IF(Config!$B$10="","",Config!$B$10) -> Contrato de honorários assinado | C29: =IF(Config!$B$10="","",COUNTIFS(Checklist!$A$5:$A$304,"<>",Checklist!$E$5:$E$304,"<>Sim",Checklist!$E$5:$E$304,"<>N/A")) -> 1 | D29: =IF(Config!$B$10="","",COUNTIFS(Checklist!$A$5:$A$304,"<>",Checklist!$E$5:$E$304,"Sim")) -> 37 | E29: =IF(Config!$B$10="","",COUNTIFS(Checklist!$A$5:$A$304,"<>",Checklist!$E$5:$E$304,"N/A")) -> 0 | G29: =IF(Config!$D$10="","",Config!$D$10) -> Última parcela cobrada e recebida | H29: =IF(Config!$D$10="","",COUNTIFS(Checklist!$D$5:$D$304,"Encerrado",Checklist!$O$5:$O$304,"<>Sim",Checklist!$O$5:$O$304,"<>N/A")) -> 0 | I29: =IF(Config!$D$10="","",COUNTIFS(Checklist!$D$5:$D$304,"Encerrado",Checklist!$O$5:$O$304,"Sim")) -> 8 | J29: =IF(Config!$D$10="","",COUNTIFS(Checklist!$D$5:$D$304,"Encerrado",Checklist!$O$5:$O$304,"N/A")) -> 0
A30: =IF(Config!$B$11="","",Config!$B$11) -> Procuração recebida | C30: =IF(Config!$B$11="","",COUNTIFS(Checklist!$A$5:$A$304,"<>",Checklist!$F$5:$F$304,"<>Sim",Checklist!$F$5:$F$304,"<>N/A")) -> 1 | D30: =IF(Config!$B$11="","",COUNTIFS(Checklist!$A$5:$A$304,"<>",Checklist!$F$5:$F$304,"Sim")) -> 30 | E30: =IF(Config!$B$11="","",COUNTIFS(Checklist!$A$5:$A$304,"<>",Checklist!$F$5:$F$304,"N/A")) -> 7 | G30: =IF(Config!$D$11="","",Config!$D$11) -> Cliente avisado do encerramento | H30: =IF(Config!$D$11="","",COUNTIFS(Checklist!$D$5:$D$304,"Encerrado",Checklist!$P$5:$P$304,"<>Sim",Checklist!$P$5:$P$304,"<>N/A")) -> 0 | I30: =IF(Config!$D$11="","",COUNTIFS(Checklist!$D$5:$D$304,"Encerrado",Checklist!$P$5:$P$304,"Sim")) -> 8 | J30: =IF(Config!$D$11="","",COUNTIFS(Checklist!$D$5:$D$304,"Encerrado",Checklist!$P$5:$P$304,"N/A")) -> 0
A31: =IF(Config!$B$12="","",Config!$B$12) -> Documentos do cliente recebidos | C31: =IF(Config!$B$12="","",COUNTIFS(Checklist!$A$5:$A$304,"<>",Checklist!$G$5:$G$304,"<>Sim",Checklist!$G$5:$G$304,"<>N/A")) -> 1 | D31: =IF(Config!$B$12="","",COUNTIFS(Checklist!$A$5:$A$304,"<>",Checklist!$G$5:$G$304,"Sim")) -> 37 | E31: =IF(Config!$B$12="","",COUNTIFS(Checklist!$A$5:$A$304,"<>",Checklist!$G$5:$G$304,"N/A")) -> 0 | G31: =IF(Config!$D$12="","",Config!$D$12) -> Documentos devolvidos ao cliente | H31: =IF(Config!$D$12="","",COUNTIFS(Checklist!$D$5:$D$304,"Encerrado",Checklist!$Q$5:$Q$304,"<>Sim",Checklist!$Q$5:$Q$304,"<>N/A")) -> 1 | I31: =IF(Config!$D$12="","",COUNTIFS(Checklist!$D$5:$D$304,"Encerrado",Checklist!$Q$5:$Q$304,"Sim")) -> 7 | J31: =IF(Config!$D$12="","",COUNTIFS(Checklist!$D$5:$D$304,"Encerrado",Checklist!$Q$5:$Q$304,"N/A")) -> 0
A32: =IF(Config!$B$13="","",Config!$B$13) -> Honorário e forma de pagamento definidos | C32: =IF(Config!$B$13="","",COUNTIFS(Checklist!$A$5:$A$304,"<>",Checklist!$H$5:$H$304,"<>Sim",Checklist!$H$5:$H$304,"<>N/A")) -> 1 | D32: =IF(Config!$B$13="","",COUNTIFS(Checklist!$A$5:$A$304,"<>",Checklist!$H$5:$H$304,"Sim")) -> 37 | E32: =IF(Config!$B$13="","",COUNTIFS(Checklist!$A$5:$A$304,"<>",Checklist!$H$5:$H$304,"N/A")) -> 0 | G32: =IF(Config!$D$13="","",Config!$D$13) -> Pasta arquivada | H32: =IF(Config!$D$13="","",COUNTIFS(Checklist!$D$5:$D$304,"Encerrado",Checklist!$R$5:$R$304,"<>Sim",Checklist!$R$5:$R$304,"<>N/A")) -> 1 | I32: =IF(Config!$D$13="","",COUNTIFS(Checklist!$D$5:$D$304,"Encerrado",Checklist!$R$5:$R$304,"Sim")) -> 7 | J32: =IF(Config!$D$13="","",COUNTIFS(Checklist!$D$5:$D$304,"Encerrado",Checklist!$R$5:$R$304,"N/A")) -> 0
A33: =IF(Config!$B$14="","",Config!$B$14) -> Caso cadastrado no caixa e na carteira | C33: =IF(Config!$B$14="","",COUNTIFS(Checklist!$A$5:$A$304,"<>",Checklist!$I$5:$I$304,"<>Sim",Checklist!$I$5:$I$304,"<>N/A")) -> 2 | D33: =IF(Config!$B$14="","",COUNTIFS(Checklist!$A$5:$A$304,"<>",Checklist!$I$5:$I$304,"Sim")) -> 36 | E33: =IF(Config!$B$14="","",COUNTIFS(Checklist!$A$5:$A$304,"<>",Checklist!$I$5:$I$304,"N/A")) -> 0 | G33: =IF(Config!$D$14="","",Config!$D$14) -> Caso marcado como encerrado na carteira | H33: =IF(Config!$D$14="","",COUNTIFS(Checklist!$D$5:$D$304,"Encerrado",Checklist!$S$5:$S$304,"<>Sim",Checklist!$S$5:$S$304,"<>N/A")) -> 0 | I33: =IF(Config!$D$14="","",COUNTIFS(Checklist!$D$5:$D$304,"Encerrado",Checklist!$S$5:$S$304,"Sim")) -> 8 | J33: =IF(Config!$D$14="","",COUNTIFS(Checklist!$D$5:$D$304,"Encerrado",Checklist!$S$5:$S$304,"N/A")) -> 0
A34: =IF(Config!$B$15="","",Config!$B$15) -> Responsável definido | C34: =IF(Config!$B$15="","",COUNTIFS(Checklist!$A$5:$A$304,"<>",Checklist!$J$5:$J$304,"<>Sim",Checklist!$J$5:$J$304,"<>N/A")) -> 0 | D34: =IF(Config!$B$15="","",COUNTIFS(Checklist!$A$5:$A$304,"<>",Checklist!$J$5:$J$304,"Sim")) -> 38 | E34: =IF(Config!$B$15="","",COUNTIFS(Checklist!$A$5:$A$304,"<>",Checklist!$J$5:$J$304,"N/A")) -> 0 | G34: =IF(Config!$D$15="","",Config!$D$15) -> Avaliação do cliente pedida | H34: =IF(Config!$D$15="","",COUNTIFS(Checklist!$D$5:$D$304,"Encerrado",Checklist!$T$5:$T$304,"<>Sim",Checklist!$T$5:$T$304,"<>N/A")) -> 2 | I34: =IF(Config!$D$15="","",COUNTIFS(Checklist!$D$5:$D$304,"Encerrado",Checklist!$T$5:$T$304,"Sim")) -> 6 | J34: =IF(Config!$D$15="","",COUNTIFS(Checklist!$D$5:$D$304,"Encerrado",Checklist!$T$5:$T$304,"N/A")) -> 0
A35: =IF(Config!$B$16="","",Config!$B$16) -> Primeiro prazo na agenda | C35: =IF(Config!$B$16="","",COUNTIFS(Checklist!$A$5:$A$304,"<>",Checklist!$K$5:$K$304,"<>Sim",Checklist!$K$5:$K$304,"<>N/A")) -> 0 | D35: =IF(Config!$B$16="","",COUNTIFS(Checklist!$A$5:$A$304,"<>",Checklist!$K$5:$K$304,"Sim")) -> 31 | E35: =IF(Config!$B$16="","",COUNTIFS(Checklist!$A$5:$A$304,"<>",Checklist!$K$5:$K$304,"N/A")) -> 7 | G35: =IF(Config!$D$16="","",Config!$D$16) -> Prazos do caso baixados na agenda | H35: =IF(Config!$D$16="","",COUNTIFS(Checklist!$D$5:$D$304,"Encerrado",Checklist!$U$5:$U$304,"<>Sim",Checklist!$U$5:$U$304,"<>N/A")) -> 0 | I35: =IF(Config!$D$16="","",COUNTIFS(Checklist!$D$5:$D$304,"Encerrado",Checklist!$U$5:$U$304,"Sim")) -> 8 | J35: =IF(Config!$D$16="","",COUNTIFS(Checklist!$D$5:$D$304,"Encerrado",Checklist!$U$5:$U$304,"N/A")) -> 0
A36: =IF(Config!$B$17="","",Config!$B$17) -> Canal de contato combinado com o cliente | C36: =IF(Config!$B$17="","",COUNTIFS(Checklist!$A$5:$A$304,"<>",Checklist!$L$5:$L$304,"<>Sim",Checklist!$L$5:$L$304,"<>N/A")) -> 1 | D36: =IF(Config!$B$17="","",COUNTIFS(Checklist!$A$5:$A$304,"<>",Checklist!$L$5:$L$304,"Sim")) -> 37 | E36: =IF(Config!$B$17="","",COUNTIFS(Checklist!$A$5:$A$304,"<>",Checklist!$L$5:$L$304,"N/A")) -> 0 | G36: =IF(Config!$D$17="","",Config!$D$17) -> Horas do caso fechadas | H36: =IF(Config!$D$17="","",COUNTIFS(Checklist!$D$5:$D$304,"Encerrado",Checklist!$V$5:$V$304,"<>Sim",Checklist!$V$5:$V$304,"<>N/A")) -> 0 | I36: =IF(Config!$D$17="","",COUNTIFS(Checklist!$D$5:$D$304,"Encerrado",Checklist!$V$5:$V$304,"Sim")) -> 8 | J36: =IF(Config!$D$17="","",COUNTIFS(Checklist!$D$5:$D$304,"Encerrado",Checklist!$V$5:$V$304,"N/A")) -> 0
A37: =IF(Config!$B$18="","",Config!$B$18) -> Pasta do caso criada (física ou digital) | C37: =IF(Config!$B$18="","",COUNTIFS(Checklist!$A$5:$A$304,"<>",Checklist!$M$5:$M$304,"<>Sim",Checklist!$M$5:$M$304,"<>N/A")) -> 1 | D37: =IF(Config!$B$18="","",COUNTIFS(Checklist!$A$5:$A$304,"<>",Checklist!$M$5:$M$304,"Sim")) -> 37 | E37: =IF(Config!$B$18="","",COUNTIFS(Checklist!$A$5:$A$304,"<>",Checklist!$M$5:$M$304,"N/A")) -> 0 | G37: =IF(Config!$D$18="","",Config!$D$18) | H37: =IF(Config!$D$18="","",COUNTIFS(Checklist!$D$5:$D$304,"Encerrado",Checklist!$W$5:$W$304,"<>Sim",Checklist!$W$5:$W$304,"<>N/A")) | I37: =IF(Config!$D$18="","",COUNTIFS(Checklist!$D$5:$D$304,"Encerrado",Checklist!$W$5:$W$304,"Sim")) | J37: =IF(Config!$D$18="","",COUNTIFS(Checklist!$D$5:$D$304,"Encerrado",Checklist!$W$5:$W$304,"N/A"))
A38: =IF(Config!$B$19="","",Config!$B$19) | C38: =IF(Config!$B$19="","",COUNTIFS(Checklist!$A$5:$A$304,"<>",Checklist!$N$5:$N$304,"<>Sim",Checklist!$N$5:$N$304,"<>N/A")) | D38: =IF(Config!$B$19="","",COUNTIFS(Checklist!$A$5:$A$304,"<>",Checklist!$N$5:$N$304,"Sim")) | E38: =IF(Config!$B$19="","",COUNTIFS(Checklist!$A$5:$A$304,"<>",Checklist!$N$5:$N$304,"N/A")) | G38: =IF(Config!$D$19="","",Config!$D$19) | H38: =IF(Config!$D$19="","",COUNTIFS(Checklist!$D$5:$D$304,"Encerrado",Checklist!$X$5:$X$304,"<>Sim",Checklist!$X$5:$X$304,"<>N/A")) | I38: =IF(Config!$D$19="","",COUNTIFS(Checklist!$D$5:$D$304,"Encerrado",Checklist!$X$5:$X$304,"Sim")) | J38: =IF(Config!$D$19="","",COUNTIFS(Checklist!$D$5:$D$304,"Encerrado",Checklist!$X$5:$X$304,"N/A"))
A41: Por responsável
A42: Responsável | C42: Casos | D42: Em andamento | E42: Encerrados | F42: Com pendência | G42: Itens pendentes
A43: =IF(Config!$F$10="","",Config!$F$10) -> Marina Ferraz | C43: =IF(Config!$F$10="","",COUNTIFS(Checklist!$C$5:$C$304,Config!$F$10,Checklist!$A$5:$A$304,"<>")) -> 19 | D43: =IF(Config!$F$10="","",COUNTIFS(Checklist!$C$5:$C$304,Config!$F$10,Checklist!$D$5:$D$304,"Em andamento")) -> 15 | E43: =IF(Config!$F$10="","",COUNTIFS(Checklist!$C$5:$C$304,Config!$F$10,Checklist!$D$5:$D$304,"Encerrado")) -> 4 | F43: =IF(Config!$F$10="","",COUNTIFS(Checklist!$C$5:$C$304,Config!$F$10,Checklist!$AC$5:$AC$304,">0")) -> 4 | G43: =IF(Config!$F$10="","",SUMIFS(Checklist!$AC$5:$AC$304,Checklist!$C$5:$C$304,Config!$F$10)) -> 4
A44: =IF(Config!$F$11="","",Config!$F$11) -> Rafael Lima | C44: =IF(Config!$F$11="","",COUNTIFS(Checklist!$C$5:$C$304,Config!$F$11,Checklist!$A$5:$A$304,"<>")) -> 19 | D44: =IF(Config!$F$11="","",COUNTIFS(Checklist!$C$5:$C$304,Config!$F$11,Checklist!$D$5:$D$304,"Em andamento")) -> 15 | E44: =IF(Config!$F$11="","",COUNTIFS(Checklist!$C$5:$C$304,Config!$F$11,Checklist!$D$5:$D$304,"Encerrado")) -> 4 | F44: =IF(Config!$F$11="","",COUNTIFS(Checklist!$C$5:$C$304,Config!$F$11,Checklist!$AC$5:$AC$304,">0")) -> 6 | G44: =IF(Config!$F$11="","",SUMIFS(Checklist!$AC$5:$AC$304,Checklist!$C$5:$C$304,Config!$F$11)) -> 8
A45: =IF(Config!$F$12="","",Config!$F$12) -> Júlia Prado | C45: =IF(Config!$F$12="","",COUNTIFS(Checklist!$C$5:$C$304,Config!$F$12,Checklist!$A$5:$A$304,"<>")) -> 0 | D45: =IF(Config!$F$12="","",COUNTIFS(Checklist!$C$5:$C$304,Config!$F$12,Checklist!$D$5:$D$304,"Em andamento")) -> 0 | E45: =IF(Config!$F$12="","",COUNTIFS(Checklist!$C$5:$C$304,Config!$F$12,Checklist!$D$5:$D$304,"Encerrado")) -> 0 | F45: =IF(Config!$F$12="","",COUNTIFS(Checklist!$C$5:$C$304,Config!$F$12,Checklist!$AC$5:$AC$304,">0")) -> 0 | G45: =IF(Config!$F$12="","",SUMIFS(Checklist!$AC$5:$AC$304,Checklist!$C$5:$C$304,Config!$F$12)) -> 0
...

Sheet Config
A1: Configurações
A2: Células amarelas: você preenche. Os itens cadastrados aqui viram as colunas da aba Checklist.
A4: Escritório | B4: Ferraz & Lima Advocacia (exemplo fictício)
A5: Data de referência (hoje) | B5: 46279 | C5: O exemplo está congelado em 14/09/2026, para os arquivos do kit mostrarem a mesma foto. Ao usar com os seus dados, troque por =HOJE().
A9: Itens de abertura (até 10) | D9: Itens de encerramento (até 10) | F9: Responsáveis (até 10)
B10: Contrato de honorários assinado | D10: Última parcela cobrada e recebida | F10: Marina Ferraz
B11: Procuração recebida | D11: Cliente avisado do encerramento | F11: Rafael Lima
B12: Documentos do cliente recebidos | D12: Documentos devolvidos ao cliente | F12: Júlia Prado
B13: Honorário e forma de pagamento definidos | D13: Pasta arquivada
B14: Caso cadastrado no caixa e na carteira | D14: Caso marcado como encerrado na carteira
B15: Responsável definido | D15: Avaliação do cliente pedida
B16: Primeiro prazo na agenda | D16: Prazos do caso baixados na agenda
B17: Canal de contato combinado com o cliente | D17: Horas do caso fechadas
B18: Pasta do caso criada (física ou digital)
A21: Itens cadastrados | B21: =COUNTA($B$10:$B$19) -> 9 | D21: =COUNTA($D$10:$D$19) -> 8
A23: Preencha de cima para baixo, sem pular linha: as listas param na última linha preenchida e os itens vazios não contam no percentual.
A24: Os itens são administrativos (o que precisa estar em ordem para o caso começar e terminar sem pendência). Ajuste ao jeito do escritório.

Sheet Checklist
A1: Checklist por caso
A2: Uma linha por caso (copie número, cliente e responsável da planilha 13 · Carteira, aba Casos: a 13 é a fonte). Em cada item marque Sim, Não ou N/A (não se aplica). Vazio conta como pendente. Os itens de encerramento só contam quando a situação é Encerrado.
E3: Abertura | O3: Encerramento
A4: Número | B4: Cliente | C4: Responsável | D4: Situação | E4: =IF(Config!$B$10="","",Config!$B$10) -> Contrato de honorários assinado | F4: =IF(Config!$B$11="","",Config!$B$11) -> Procuração recebida | G4: =IF(Config!$B$12="","",Config!$B$12) -> Documentos do cliente recebidos | H4: =IF(Config!$B$13="","",Config!$B$13) -> Honorário e forma de pagamento definidos | I4: =IF(Config!$B$14="","",Config!$B$14) -> Caso cadastrado no caixa e na carteira | J4: =IF(Config!$B$15="","",Config!$B$15) -> Responsável definido | K4: =IF(Config!$B$16="","",Config!$B$16) -> Primeiro prazo na agenda | L4: =IF(Config!$B$17="","",Config!$B$17) -> Canal de contato combinado com o cliente | M4: =IF(Config!$B$18="","",Config!$B$18) -> Pasta do caso criada (física ou digital) | N4: =IF(Config!$B$19="","",Config!$B$19) | O4: =IF(Config!$D$10="","",Config!$D$10) -> Última parcela cobrada e recebida | P4: =IF(Config!$D$11="","",Config!$D$11) -> Cliente avisado do encerramento | Q4: =IF(Config!$D$12="","",Config!$D$12) -> Documentos devolvidos ao cliente | R4: =IF(Config!$D$13="","",Config!$D$13) -> Pasta arquivada | S4: =IF(Config!$D$14="","",Config!$D$14) -> Caso marcado como encerrado na carteira | T4: =IF(Config!$D$15="","",Config!$D$15) -> Avaliação do cliente pedida | U4: =IF(Config!$D$16="","",Config!$D$16) -> Prazos do caso baixados na agenda | V4: =IF(Config!$D$17="","",Config!$D$17) -> Horas do caso fechadas | W4: =IF(Config!$D$18="","",Config!$D$18) | X4: =IF(Config!$D$19="","",Config!$D$19) | Y4: % abertura | Z4: % encerramento | AA4: Pendências de abertura | AB4: Pendências de encerramento | AC4: Pendências | AD4: O que falta | AE4: Chave | AF4: Auxiliar
A5: CONS-2026-01 | B5: Padaria do Sol Ltda | C5: Marina Ferraz | D5: Em andamento | E5: Sim | F5: N/A | G5: Sim | H5: Sim | I5: Sim | J5: Sim | K5: N/A | L5: Sim | M5: Sim | Y5: =IF(A5="","",IFERROR(COUNTIF(E5:N5,"Sim")/(Config!$B$21-COUNTIF(E5:N5,"N/A")),"")) -> 1 | Z5: =IF(OR(A5="",D5<>"Encerrado"),"",IFERROR(COUNTIF(O5:X5,"Sim")/(Config!$D$21-COUNTIF(O5:X5,"N/A")),"")) | AA5: =IF(A5="","",MAX(0,Config!$B$21-COUNTIF(E5:N5,"Sim")-COUNTIF(E5:N5,"N/A"))) -> 0 | AB5: =IF(OR(A5="",D5<>"Encerrado"),"",MAX(0,Config!$D$21-COUNTIF(O5:X5,"Sim")-COUNTIF(O5:X5,"N/A"))) | AC5: =IF(A5="","",AA5+IF(AB5="",0,AB5)) -> 0 | AD5: =IF(OR(A5="",AF5=""),"",LEFT(AF5,LEN(AF5)-2)) | AE5: =IF(OR(A5="",AC5=0),0,AC5*100-ROW()/100000) -> 0 | AF5: =IF(A5="","",IF(AND(Config!$B$10<>"",E5<>"Sim",E5<>"N/A"),Config!$B$10&"; ","")&IF(AND(Config!$B$11<>"",F5<>"Sim",F5<>"N/A"),Config!$B$11&"; ","")&IF(AND(Config!$B$12<>"",G5<>"Sim",G5<>"N/A"),Config!$B$12&"; ","")&IF(AND(Config!$B$13<>"",H5<>"Sim",H5<>"N/A"),Config!$B$13&"; ","")&IF(AND(Config!$B$14<>"",I5<>"Sim",I5<>"N/A"),Config!$B$14&"; ","")&IF(AND(Config!$B$15<>"",J5<>"Sim",J5<>"N/A"),Config!$B$15&"; ","")&IF(AND(Config!$B$16<>"",K5<>"Sim",K5<>"N/A"),Config!$B$16&"; ","")&IF(AND(Config!$B$17<>"",L5<>"Sim",L5<>"N/A"),Config!$B$17&"; ","")&IF(AND(Config!$B$18<>"",M5<>"Sim",M5<>"N/A"),Config!$B$18&"; ","")&IF(AND(Config!$B$19<>"",N5<>"Sim",N5<>"N/A"),Config!$B$19&"; ","")&IF(AND($D5="Encerrado",Config!$D$10<>"",O5<>"Sim",O5<>"N/A"),Config!$D$10&"; ","")&IF(AND($D5="Encerrado",Config!$D$11<>"",P5<>"Sim",P5<>"N/A"),Config!$D$11&"; ","")&IF(AND($D5="Encerrado",Config!$D$12<>"",Q5<>"Sim",Q5<>"N/A"),Config!$D$12&"; ","")&IF(AND($D5="Encerrado",Config!$D$13<>"",R5<>"Sim",R5<>"N/A"),Config!$D$13&"; ","")&IF(AND($D5="Encerrado",Config!$D$14<>"",S5<>"Sim",S5<>"N/A"),Config!$D$14&"; ","")&IF(AND($D5="Encerrado",Config!$D$15<>"",T5<>"Sim",T5<>"N/A"),Config!$D$15&"; ","")&IF(AND($D5="Encerrado",Config!$D$16<>"",U5<>"Sim",U5<>"N/A"),Config!$D$16&"; ","")&IF(AND($D5="Encerrado",Config!$D$17<>"",V5<>"Sim",V5<>"N/A"),Config!$D$17&"; ","")&IF(AND($D5="Encerrado",Config!$D$18<>"",W5<>"Sim",W5<>"N/A"),Config!$D$18&"; ","")&IF(AND($D5="Encerrado",Config!$D$19<>"",X5<>"Sim",X5<>"N/A"),Config!$D$19&"; ",""))
A6: 2998500-50.2026.8.26.0515 | B6: Ana Beatriz Moreira | C6: Rafael Lima | D6: Em andamento | E6: Não | F6: Sim | G6: Sim | H6: Sim | I6: Sim | J6: Sim | K6: Sim | L6: Sim | M6: Sim | Y6: =IF(A6="","",IFERROR(COUNTIF(E6:N6,"Sim")/(Config!$B$21-COUNTIF(E6:N6,"N/A")),"")) -> 0.88888889 | Z6: =IF(OR(A6="",D6<>"Encerrado"),"",IFERROR(COUNTIF(O6:X6,"Sim")/(Config!$D$21-COUNTIF(O6:X6,"N/A")),"")) | AA6: =IF(A6="","",MAX(0,Config!$B$21-COUNTIF(E6:N6,"Sim")-COUNTIF(E6:N6,"N/A"))) -> 1 | AB6: =IF(OR(A6="",D6<>"Encerrado"),"",MAX(0,Config!$D$21-COUNTIF(O6:X6,"Sim")-COUNTIF(O6:X6,"N/A"))) | AC6: =IF(A6="","",AA6+IF(AB6="",0,AB6)) -> 1 | AD6: =IF(OR(A6="",AF6=""),"",LEFT(AF6,LEN(AF6)-2)) -> Contrato de honorários assinado | AE6: =IF(OR(A6="",AC6=0),0,AC6*100-ROW()/100000) -> 99.99994 | AF6: =IF(A6="","",IF(AND(Config!$B$10<>"",E6<>"Sim",E6<>"N/A"),Config!$B$10&"; ","")&IF(AND(Config!$B$11<>"",F6<>"Sim",F6<>"N/A"),Config!$B$11&"; ","")&IF(AND(Config!$B$12<>"",G6<>"Sim",G6<>"N/A"),Config!$B$12&"; ","")&IF(AND(Config!$B$13<>"",H6<>"Sim",H6<>"N/A"),Config!$B$13&"; ","")&IF(AND(Config!$B$14<>"",I6<>"Sim",I6<>"N/A"),Config!$B$14&"; ","")&IF(AND(Config!$B$15<>"",J6<>"Sim",J6<>"N/A"),Config!$B$15&"; ","")&IF(AND(Config!$B$16<>"",K6<>"Sim",K6<>"N/A"),Config!$B$16&"; ","")&IF(AND(Config!$B$17<>"",L6<>"Sim",L6<>"N/A"),Config!$B$17&"; ","")&IF(AND(Config!$B$18<>"",M6<>"Sim",M6<>"N/A"),Config!$B$18&"; ","")&IF(AND(Config!$B$19<>"",N6<>"Sim",N6<>"N/A"),Config!$B$19&"; ","")&IF(AND($D6="Encerrado",Config!$D$10<>"",O6<>"Sim",O6<>"N/A"),Config!$D$10&"; ","")&IF(AND($D6="Encerrado",Config!$D$11<>"",P6<>"Sim",P6<>"N/A"),Config!$D$11&"; ","")&IF(AND($D6="Encerrado",Config!$D$12<>"",Q6<>"Sim",Q6<>"N/A"),Config!$D$12&"; ","")&IF(AND($D6="Encerrado",Config!$D$13<>"",R6<>"Sim",R6<>"N/A"),Config!$D$13&"; ","")&IF(AND($D6="Encerrado",Config!$D$14<>"",S6<>"Sim",S6<>"N/A"),Config!$D$14&"; ","")&IF(AND($D6="Encerrado",Config!$D$15<>"",T6<>"Sim",T6<>"N/A"),Config!$D$15&"; ","")&IF(AND($D6="Encerrado",Config!$D$16<>"",U6<>"Sim",U6<>"N/A"),Config!$D$16&"; ","")&IF(AND($D6="Encerrado",Config!$D$17<>"",V6<>"Sim",V6<>"N/A"),Config!$D$17&"; ","")&IF(AND($D6="Encerrado",Config!$D$18<>"",W6<>"Sim",W6<>"N/A"),Config!$D$18&"; ","")&IF(AND($D6="Encerrado",Config!$D$19<>"",X6<>"Sim",X6<>"N/A"),Config!$D$19&"; ","")) -> Contrato de honorários assinado;
A7: 9586960-92.2026.8.26.0106 | B7: Construtora Horizonte | C7: Marina Ferraz | D7: Em andamento | E7: Sim | F7: Sim | G7: Sim | H7: Sim | I7: Sim | J7: Sim | K7: Sim | L7: Sim | M7: Sim | Y7: =IF(A7="","",IFERROR(COUNTIF(E7:N7,"Sim")/(Config!$B$21-COUNTIF(E7:N7,"N/A")),"")) -> 1 | Z7: =IF(OR(A7="",D7<>"Encerrado"),"",IFERROR(COUNTIF(O7:X7,"Sim")/(Config!$D$21-COUNTIF(O7:X7,"N/A")),"")) | AA7: =IF(A7="","",MAX(0,Config!$B$21-COUNTIF(E7:N7,"Sim")-COUNTIF(E7:N7,"N/A"))) -> 0 | AB7: =IF(OR(A7="",D7<>"Encerrado"),"",MAX(0,Config!$D$21-COUNTIF(O7:X7,"Sim")-COUNTIF(O7:X7,"N/A"))) | AC7: =IF(A7="","",AA7+IF(AB7="",0,AB7)) -> 0 | AD7: =IF(OR(A7="",AF7=""),"",LEFT(AF7,LEN(AF7)-2)) | AE7: =IF(OR(A7="",AC7=0),0,AC7*100-ROW()/100000) -> 0 | AF7: =IF(A7="","",IF(AND(Config!$B$10<>"",E7<>"Sim",E7<>"N/A"),Config!$B$10&"; ","")&IF(AND(Config!$B$11<>"",F7<>"Sim",F7<>"N/A"),Config!$B$11&"; ","")&IF(AND(Config!$B$12<>"",G7<>"Sim",G7<>"N/A"),Config!$B$12&"; ","")&IF(AND(Config!$B$13<>"",H7<>"Sim",H7<>"N/A"),Config!$B$13&"; ","")&IF(AND(Config!$B$14<>"",I7<>"Sim",I7<>"N/A"),Config!$B$14&"; ","")&IF(AND(Config!$B$15<>"",J7<>"Sim",J7<>"N/A"),Config!$B$15&"; ","")&IF(AND(Config!$B$16<>"",K7<>"Sim",K7<>"N/A"),Config!$B$16&"; ","")&IF(AND(Config!$B$17<>"",L7<>"Sim",L7<>"N/A"),Config!$B$17&"; ","")&IF(AND(Config!$B$18<>"",M7<>"Sim",M7<>"N/A"),Config!$B$18&"; ","")&IF(AND(Config!$B$19<>"",N7<>"Sim",N7<>"N/A"),Config!$B$19&"; ","")&IF(AND($D7="Encerrado",Config!$D$10<>"",O7<>"Sim",O7<>"N/A"),Config!$D$10&"; ","")&IF(AND($D7="Encerrado",Config!$D$11<>"",P7<>"Sim",P7<>"N/A"),Config!$D$11&"; ","")&IF(AND($D7="Encerrado",Config!$D$12<>"",Q7<>"Sim",Q7<>"N/A"),Config!$D$12&"; ","")&IF(AND($D7="Encerrado",Config!$D$13<>"",R7<>"Sim",R7<>"N/A"),Config!$D$13&"; ","")&IF(AND($D7="Encerrado",Config!$D$14<>"",S7<>"Sim",S7<>"N/A"),Config!$D$14&"; ","")&IF(AND($D7="Encerrado",Config!$D$15<>"",T7<>"Sim",T7<>"N/A"),Config!$D$15&"; ","")&IF(AND($D7="Encerrado",Config!$D$16<>"",U7<>"Sim",U7<>"N/A"),Config!$D$16&"; ","")&IF(AND($D7="Encerrado",Config!$D$17<>"",V7<>"Sim",V7<>"N/A"),Config!$D$17&"; ","")&IF(AND($D7="Encerrado",Config!$D$18<>"",W7<>"Sim",W7<>"N/A"),Config!$D$18&"; ","")&IF(AND($D7="Encerrado",Config!$D$19<>"",X7<>"Sim",X7<>"N/A"),Config!$D$19&"; ",""))
