Workbook

Sheet Como usar
A1: Caixa do escritório
A2: Kit de Gestão para Advogados · Seu Sócio Gestor · versão 1.0 (setembro de 2026)
A4: O que esta planilha faz | B4: Você lança o que entra (honorários por cliente e caso) e o que sai (custo fixo, pró-labore, impostos, custas). Ela mostra o mês: entrou, saiu, sobrou, saldo acumulado, a receber, a pagar; para onde foi o dinheiro por categoria, quanto veio de cada cliente e o ano mês a mês com gráfico.
A5: Passo 1 | B5: Em Config, preencha o nome do escritório, o ano, o saldo que havia em caixa antes do primeiro lançamento e o mês do painel. Ajuste categorias e clientes de cima para baixo, sem pular linha.
A6: Passo 2 | B6: Em Lançamentos, uma linha por movimento: data, tipo (entrada ou saída), categoria, cliente, caso, descrição, valor, forma e Pago?. Honorário faturado e ainda não recebido entra com Pago? = Não e aparece em A receber; quando cair na conta, troque para Sim.
A7: Passo 3 | B7: Em Painel, escolha o mês em Config e leia de cima para baixo. Só o que está com Pago? = Sim conta como caixa; o resto é previsão.
A8: Rotina de sexta | B8: 15 minutos: lançar o que entrou e saiu na semana, conferir A receber contra o extrato e marcar Sim no que caiu. No fechamento do mês, olhar Sobrou e Saldo acumulado antes de decidir retirada extra ou gasto grande.
A9: Ligação com as outras planilhas | B9: O total de entradas do mês alimenta a planilha 10 (provisão de impostos) e a 17 (painel); as saídas de pró-labore, a 11; o saldo acumulado e o custo fixo, a 12 (reserva); as entradas por categoria, a 18 (resultado). Cada arquivo tem a própria aba de entrada amarela: copie os números do painel. Cada honorário lançado aqui é uma parcela marcada como paga na 14.
A10: Com a IA | B10: Copie "Para onde foi o dinheiro" e "O ano, mês a mês" e use o prompt "Caixa 01 · Explicar o mês do caixa" da biblioteca do kit. Nunca cole nome de cliente ou número de processo na IA sem necessidade: use a coluna Categoria.
A11: Legenda | B11: Células amarelas: você preenche. Brancas: calculadas. Não é preciso mexer em nada fora do amarelo.
A12: Proteção | B12: Fórmulas protegidas sem senha. Para editar: Revisar > Desproteger planilha (Excel) ou Dados > Proteger intervalos (Google Sheets).
A13: Requisitos | B13: Excel 2016 ou mais novo, Microsoft 365 ou Google Sheets (só funções do Excel 2007+; nada de MÍNIMOSES, MÁXIMOSES ou UNIRTEXTO). No celular abre nos aplicativos; para preencher, use o computador.
A14: Google Sheets | B14: Faça upload no Google Drive e abra com o Google Sheets. Fórmulas, listas, cores e gráficos funcionam.
A15: Exemplos | B15: Ferraz & Lima Advocacia é um escritório fictício. Clientes, processos, nomes e valores são inventados. Apague-os antes de começar. Datas de prazo do exemplo são relativas a hoje.
A16: Suporte | B16: suporte@seusociogestor.com.br · resposta em até 5 dias úteis · reembolso em até 7 dias pelo mesmo canal.

Sheet Painel
A1: =Config!B4&" · Caixa do escritório · "&Config!B6&" de "&Config!B5 -> Ferraz & Lima Advocacia (exemplo fictício) · Caixa do escritório · Setembro de 2026
A2: Nada para digitar aqui. Escolha o mês em Config; tudo vem de Lançamentos. Só o que está com Pago? = Sim conta como caixa.
A4: Entrou no mês | C4: Saiu no mês | E4: Sobrou no mês | G4: Saldo acumulado | I4: A receber (Pago? = Não) | K4: A pagar (Pago? = Não)
A5: =SUMIFS(Lançamentos!$G$5:$G$604,Lançamentos!$B$5:$B$604,"Entrada",Lançamentos!$I$5:$I$604,"Sim",Lançamentos!$J$5:$J$604,Config!$B$7,Lançamentos!$K$5:$K$604,Config!$B$5) -> 5220 | C5: =SUMIFS(Lançamentos!$G$5:$G$604,Lançamentos!$B$5:$B$604,"Saída",Lançamentos!$I$5:$I$604,"Sim",Lançamentos!$J$5:$J$604,Config!$B$7,Lançamentos!$K$5:$K$604,Config!$B$5) -> 5320 | E5: =A5-C5 -> -100 | G5: =Config!$B$8+SUMIFS(Lançamentos!$G$5:$G$604,Lançamentos!$B$5:$B$604,"Entrada",Lançamentos!$I$5:$I$604,"Sim",Lançamentos!$A$5:$A$604,"<="&DATE(Config!$B$5,Config!$B$7+1,0))-SUMIFS(Lançamentos!$G$5:$G$604,Lançamentos!$B$5:$B$604,"Saída",Lançamentos!$I$5:$I$604,"Sim",Lançamentos!$A$5:$A$604,"<="&DATE(Config!$B$5,Config!$B$7+1,0)) -> 43683 | I5: =SUMIFS(Lançamentos!$G$5:$G$604,Lançamentos!$B$5:$B$604,"Entrada",Lançamentos!$I$5:$I$604,"Não") -> 27330 | K5: =SUMIFS(Lançamentos!$G$5:$G$604,Lançamentos!$B$5:$B$604,"Saída",Lançamentos!$I$5:$I$604,"Não") -> 15402
A7: Para onde foi o dinheiro
A8: Categoria de saída | B8: Valor no mês | C8: % do total | D8: Mês anterior | E8: Acumulado no ano | F8: Barra
A9: =IF(Config!$F$5="","",Config!$F$5) -> Pró-labore dos sócios | B9: =IF(Config!$F$5="","",SUMIFS(Lançamentos!$G$5:$G$604,Lançamentos!$B$5:$B$604,"Saída",Lançamentos!$I$5:$I$604,"Sim",Lançamentos!$J$5:$J$604,Config!$B$7,Lançamentos!$K$5:$K$604,Config!$B$5,Lançamentos!$C$5:$C$604,Config!$F$5)) -> 0 | C9: =IF(OR(Config!$F$5="",$C$5=0),"",B9/$C$5) -> 0 | D9: =IF(Config!$F$5="","",IF(Config!$B$7=1,SUMIFS(Lançamentos!$G$5:$G$604,Lançamentos!$B$5:$B$604,"Saída",Lançamentos!$I$5:$I$604,"Sim",Lançamentos!$J$5:$J$604,12,Lançamentos!$K$5:$K$604,Config!$B$5-1,Lançamentos!$C$5:$C$604,Config!$F$5),SUMIFS(Lançamentos!$G$5:$G$604,Lançamentos!$B$5:$B$604,"Saída",Lançamentos!$I$5:$I$604,"Sim",Lançamentos!$J$5:$J$604,Config!$B$7-1,Lançamentos!$K$5:$K$604,Config!$B$5,Lançamentos!$C$5:$C$604,Config!$F$5))) -> 12000 | E9: =IF(Config!$F$5="","",SUMIFS(Lançamentos!$G$5:$G$604,Lançamentos!$B$5:$B$604,"Saída",Lançamentos!$I$5:$I$604,"Sim",Lançamentos!$C$5:$C$604,Config!$F$5,Lançamentos!$K$5:$K$604,Config!$B$5,Lançamentos!$J$5:$J$604,"<="&Config!$B$7)) -> 112405 | F9: =IF(C9="","",REPT("█",ROUND(C9*40,0)))
A10: =IF(Config!$F$6="","",Config!$F$6) -> Aluguel e condomínio | B10: =IF(Config!$F$6="","",SUMIFS(Lançamentos!$G$5:$G$604,Lançamentos!$B$5:$B$604,"Saída",Lançamentos!$I$5:$I$604,"Sim",Lançamentos!$J$5:$J$604,Config!$B$7,Lançamentos!$K$5:$K$604,Config!$B$5,Lançamentos!$C$5:$C$604,Config!$F$6)) -> 2800 | C10: =IF(OR(Config!$F$6="",$C$5=0),"",B10/$C$5) -> 0.52631579 | D10: =IF(Config!$F$6="","",IF(Config!$B$7=1,SUMIFS(Lançamentos!$G$5:$G$604,Lançamentos!$B$5:$B$604,"Saída",Lançamentos!$I$5:$I$604,"Sim",Lançamentos!$J$5:$J$604,12,Lançamentos!$K$5:$K$604,Config!$B$5-1,Lançamentos!$C$5:$C$604,Config!$F$6),SUMIFS(Lançamentos!$G$5:$G$604,Lançamentos!$B$5:$B$604,"Saída",Lançamentos!$I$5:$I$604,"Sim",Lançamentos!$J$5:$J$604,Config!$B$7-1,Lançamentos!$K$5:$K$604,Config!$B$5,Lançamentos!$C$5:$C$604,Config!$F$6))) -> 2800 | E10: =IF(Config!$F$6="","",SUMIFS(Lançamentos!$G$5:$G$604,Lançamentos!$B$5:$B$604,"Saída",Lançamentos!$I$5:$I$604,"Sim",Lançamentos!$C$5:$C$604,Config!$F$6,Lançamentos!$K$5:$K$604,Config!$B$5,Lançamentos!$J$5:$J$604,"<="&Config!$B$7)) -> 25200 | F10: =IF(C10="","",REPT("█",ROUND(C10*40,0))) -> █████████████████████
A11: =IF(Config!$F$7="","",Config!$F$7) -> Contador | B11: =IF(Config!$F$7="","",SUMIFS(Lançamentos!$G$5:$G$604,Lançamentos!$B$5:$B$604,"Saída",Lançamentos!$I$5:$I$604,"Sim",Lançamentos!$J$5:$J$604,Config!$B$7,Lançamentos!$K$5:$K$604,Config!$B$5,Lançamentos!$C$5:$C$604,Config!$F$7)) -> 600 | C11: =IF(OR(Config!$F$7="",$C$5=0),"",B11/$C$5) -> 0.11278195 | D11: =IF(Config!$F$7="","",IF(Config!$B$7=1,SUMIFS(Lançamentos!$G$5:$G$604,Lançamentos!$B$5:$B$604,"Saída",Lançamentos!$I$5:$I$604,"Sim",Lançamentos!$J$5:$J$604,12,Lançamentos!$K$5:$K$604,Config!$B$5-1,Lançamentos!$C$5:$C$604,Config!$F$7),SUMIFS(Lançamentos!$G$5:$G$604,Lançamentos!$B$5:$B$604,"Saída",Lançamentos!$I$5:$I$604,"Sim",Lançamentos!$J$5:$J$604,Config!$B$7-1,Lançamentos!$K$5:$K$604,Config!$B$5,Lançamentos!$C$5:$C$604,Config!$F$7))) -> 600 | E11: =IF(Config!$F$7="","",SUMIFS(Lançamentos!$G$5:$G$604,Lançamentos!$B$5:$B$604,"Saída",Lançamentos!$I$5:$I$604,"Sim",Lançamentos!$C$5:$C$604,Config!$F$7,Lançamentos!$K$5:$K$604,Config!$B$5,Lançamentos!$J$5:$J$604,"<="&Config!$B$7)) -> 5400 | F11: =IF(C11="","",REPT("█",ROUND(C11*40,0))) -> █████
A12: =IF(Config!$F$8="","",Config!$F$8) -> Sistemas e assinaturas | B12: =IF(Config!$F$8="","",SUMIFS(Lançamentos!$G$5:$G$604,Lançamentos!$B$5:$B$604,"Saída",Lançamentos!$I$5:$I$604,"Sim",Lançamentos!$J$5:$J$604,Config!$B$7,Lançamentos!$K$5:$K$604,Config!$B$5,Lançamentos!$C$5:$C$604,Config!$F$8)) -> 450 | C12: =IF(OR(Config!$F$8="",$C$5=0),"",B12/$C$5) -> 0.084586466 | D12: =IF(Config!$F$8="","",IF(Config!$B$7=1,SUMIFS(Lançamentos!$G$5:$G$604,Lançamentos!$B$5:$B$604,"Saída",Lançamentos!$I$5:$I$604,"Sim",Lançamentos!$J$5:$J$604,12,Lançamentos!$K$5:$K$604,Config!$B$5-1,Lançamentos!$C$5:$C$604,Config!$F$8),SUMIFS(Lançamentos!$G$5:$G$604,Lançamentos!$B$5:$B$604,"Saída",Lançamentos!$I$5:$I$604,"Sim",Lançamentos!$J$5:$J$604,Config!$B$7-1,Lançamentos!$K$5:$K$604,Config!$B$5,Lançamentos!$C$5:$C$604,Config!$F$8))) -> 450 | E12: =IF(Config!$F$8="","",SUMIFS(Lançamentos!$G$5:$G$604,Lançamentos!$B$5:$B$604,"Saída",Lançamentos!$I$5:$I$604,"Sim",Lançamentos!$C$5:$C$604,Config!$F$8,Lançamentos!$K$5:$K$604,Config!$B$5,Lançamentos!$J$5:$J$604,"<="&Config!$B$7)) -> 4050 | F12: =IF(C12="","",REPT("█",ROUND(C12*40,0))) -> ███
A13: =IF(Config!$F$9="","",Config!$F$9) -> Telefone e internet | B13: =IF(Config!$F$9="","",SUMIFS(Lançamentos!$G$5:$G$604,Lançamentos!$B$5:$B$604,"Saída",Lançamentos!$I$5:$I$604,"Sim",Lançamentos!$J$5:$J$604,Config!$B$7,Lançamentos!$K$5:$K$604,Config!$B$5,Lançamentos!$C$5:$C$604,Config!$F$9)) -> 0 | C13: =IF(OR(Config!$F$9="",$C$5=0),"",B13/$C$5) -> 0 | D13: =IF(Config!$F$9="","",IF(Config!$B$7=1,SUMIFS(Lançamentos!$G$5:$G$604,Lançamentos!$B$5:$B$604,"Saída",Lançamentos!$I$5:$I$604,"Sim",Lançamentos!$J$5:$J$604,12,Lançamentos!$K$5:$K$604,Config!$B$5-1,Lançamentos!$C$5:$C$604,Config!$F$9),SUMIFS(Lançamentos!$G$5:$G$604,Lançamentos!$B$5:$B$604,"Saída",Lançamentos!$I$5:$I$604,"Sim",Lançamentos!$J$5:$J$604,Config!$B$7-1,Lançamentos!$K$5:$K$604,Config!$B$5,Lançamentos!$C$5:$C$604,Config!$F$9))) -> 220 | E13: =IF(Config!$F$9="","",SUMIFS(Lançamentos!$G$5:$G$604,Lançamentos!$B$5:$B$604,"Saída",Lançamentos!$I$5:$I$604,"Sim",Lançamentos!$C$5:$C$604,Config!$F$9,Lançamentos!$K$5:$K$604,Config!$B$5,Lançamentos!$J$5:$J$604,"<="&Config!$B$7)) -> 1760 | F13: =IF(C13="","",REPT("█",ROUND(C13*40,0)))
A14: =IF(Config!$F$10="","",Config!$F$10) -> Anuidades OAB e cursos | B14: =IF(Config!$F$10="","",SUMIFS(Lançamentos!$G$5:$G$604,Lançamentos!$B$5:$B$604,"Saída",Lançamentos!$I$5:$I$604,"Sim",Lançamentos!$J$5:$J$604,Config!$B$7,Lançamentos!$K$5:$K$604,Config!$B$5,Lançamentos!$C$5:$C$604,Config!$F$10)) -> 0 | C14: =IF(OR(Config!$F$10="",$C$5=0),"",B14/$C$5) -> 0 | D14: =IF(Config!$F$10="","",IF(Config!$B$7=1,SUMIFS(Lançamentos!$G$5:$G$604,Lançamentos!$B$5:$B$604,"Saída",Lançamentos!$I$5:$I$604,"Sim",Lançamentos!$J$5:$J$604,12,Lançamentos!$K$5:$K$604,Config!$B$5-1,Lançamentos!$C$5:$C$604,Config!$F$10),SUMIFS(Lançamentos!$G$5:$G$604,Lançamentos!$B$5:$B$604,"Saída",Lançamentos!$I$5:$I$604,"Sim",Lançamentos!$J$5:$J$604,Config!$B$7-1,Lançamentos!$K$5:$K$604,Config!$B$5,Lançamentos!$C$5:$C$604,Config!$F$10))) -> 250 | E14: =IF(Config!$F$10="","",SUMIFS(Lançamentos!$G$5:$G$604,Lançamentos!$B$5:$B$604,"Saída",Lançamentos!$I$5:$I$604,"Sim",Lançamentos!$C$5:$C$604,Config!$F$10,Lançamentos!$K$5:$K$604,Config!$B$5,Lançamentos!$J$5:$J$604,"<="&Config!$B$7)) -> 2000 | F14: =IF(C14="","",REPT("█",ROUND(C14*40,0)))
A15: =IF(Config!$F$11="","",Config!$F$11) -> Marketing e site | B15: =IF(Config!$F$11="","",SUMIFS(Lançamentos!$G$5:$G$604,Lançamentos!$B$5:$B$604,"Saída",Lançamentos!$I$5:$I$604,"Sim",Lançamentos!$J$5:$J$604,Config!$B$7,Lançamentos!$K$5:$K$604,Config!$B$5,Lançamentos!$C$5:$C$604,Config!$F$11)) -> 0 | C15: =IF(OR(Config!$F$11="",$C$5=0),"",B15/$C$5) -> 0 | D15: =IF(Config!$F$11="","",IF(Config!$B$7=1,SUMIFS(Lançamentos!$G$5:$G$604,Lançamentos!$B$5:$B$604,"Saída",Lançamentos!$I$5:$I$604,"Sim",Lançamentos!$J$5:$J$604,12,Lançamentos!$K$5:$K$604,Config!$B$5-1,Lançamentos!$C$5:$C$604,Config!$F$11),SUMIFS(Lançamentos!$G$5:$G$604,Lançamentos!$B$5:$B$604,"Saída",Lançamentos!$I$5:$I$604,"Sim",Lançamentos!$J$5:$J$604,Config!$B$7-1,Lançamentos!$K$5:$K$604,Config!$B$5,Lançamentos!$C$5:$C$604,Config!$F$11))) -> 400 | E15: =IF(Config!$F$11="","",SUMIFS(Lançamentos!$G$5:$G$604,Lançamentos!$B$5:$B$604,"Saída",Lançamentos!$I$5:$I$604,"Sim",Lançamentos!$C$5:$C$604,Config!$F$11,Lançamentos!$K$5:$K$604,Config!$B$5,Lançamentos!$J$5:$J$604,"<="&Config!$B$7)) -> 3200 | F15: =IF(C15="","",REPT("█",ROUND(C15*40,0)))
A16: =IF(Config!$F$12="","",Config!$F$12) -> Estagiária (bolsa) | B16: =IF(Config!$F$12="","",SUMIFS(Lançamentos!$G$5:$G$604,Lançamentos!$B$5:$B$604,"Saída",Lançamentos!$I$5:$I$604,"Sim",Lançamentos!$J$5:$J$604,Config!$B$7,Lançamentos!$K$5:$K$604,Config!$B$5,Lançamentos!$C$5:$C$604,Config!$F$12)) -> 1400 | C16: =IF(OR(Config!$F$12="",$C$5=0),"",B16/$C$5) -> 0.26315789 | D16: =IF(Config!$F$12="","",IF(Config!$B$7=1,SUMIFS(Lançamentos!$G$5:$G$604,Lançamentos!$B$5:$B$604,"Saída",Lançamentos!$I$5:$I$604,"Sim",Lançamentos!$J$5:$J$604,12,Lançamentos!$K$5:$K$604,Config!$B$5-1,Lançamentos!$C$5:$C$604,Config!$F$12),SUMIFS(Lançamentos!$G$5:$G$604,Lançamentos!$B$5:$B$604,"Saída",Lançamentos!$I$5:$I$604,"Sim",Lançamentos!$J$5:$J$604,Config!$B$7-1,Lançamentos!$K$5:$K$604,Config!$B$5,Lançamentos!$C$5:$C$604,Config!$F$12))) -> 1400 | E16: =IF(Config!$F$12="","",SUMIFS(Lançamentos!$G$5:$G$604,Lançamentos!$B$5:$B$604,"Saída",Lançamentos!$I$5:$I$604,"Sim",Lançamentos!$C$5:$C$604,Config!$F$12,Lançamentos!$K$5:$K$604,Config!$B$5,Lançamentos!$J$5:$J$604,"<="&Config!$B$7)) -> 12600 | F16: =IF(C16="","",REPT("█",ROUND(C16*40,0))) -> ███████████
A17: =IF(Config!$F$13="","",Config!$F$13) -> Material, correio e outros | B17: =IF(Config!$F$13="","",SUMIFS(Lançamentos!$G$5:$G$604,Lançamentos!$B$5:$B$604,"Saída",Lançamentos!$I$5:$I$604,"Sim",Lançamentos!$J$5:$J$604,Config!$B$7,Lançamentos!$K$5:$K$604,Config!$B$5,Lançamentos!$C$5:$C$604,Config!$F$13)) -> 0 | C17: =IF(OR(Config!$F$13="",$C$5=0),"",B17/$C$5) -> 0 | D17: =IF(Config!$F$13="","",IF(Config!$B$7=1,SUMIFS(Lançamentos!$G$5:$G$604,Lançamentos!$B$5:$B$604,"Saída",Lançamentos!$I$5:$I$604,"Sim",Lançamentos!$J$5:$J$604,12,Lançamentos!$K$5:$K$604,Config!$B$5-1,Lançamentos!$C$5:$C$604,Config!$F$13),SUMIFS(Lançamentos!$G$5:$G$604,Lançamentos!$B$5:$B$604,"Saída",Lançamentos!$I$5:$I$604,"Sim",Lançamentos!$J$5:$J$604,Config!$B$7-1,Lançamentos!$K$5:$K$604,Config!$B$5,Lançamentos!$C$5:$C$604,Config!$F$13))) -> 380 | E17: =IF(Config!$F$13="","",SUMIFS(Lançamentos!$G$5:$G$604,Lançamentos!$B$5:$B$604,"Saída",Lançamentos!$I$5:$I$604,"Sim",Lançamentos!$C$5:$C$604,Config!$F$13,Lançamentos!$K$5:$K$604,Config!$B$5,Lançamentos!$J$5:$J$604,"<="&Config!$B$7)) -> 3040 | F17: =IF(C17="","",REPT("█",ROUND(C17*40,0)))
A18: =IF(Config!$F$14="","",Config!$F$14) -> Impostos e taxas | B18: =IF(Config!$F$14="","",SUMIFS(Lançamentos!$G$5:$G$604,Lançamentos!$B$5:$B$604,"Saída",Lançamentos!$I$5:$I$604,"Sim",Lançamentos!$J$5:$J$604,Config!$B$7,Lançamentos!$K$5:$K$604,Config!$B$5,Lançamentos!$C$5:$C$604,Config!$F$14)) -> 0 | C18: =IF(OR(Config!$F$14="",$C$5=0),"",B18/$C$5) -> 0 | D18: =IF(Config!$F$14="","",IF(Config!$B$7=1,SUMIFS(Lançamentos!$G$5:$G$604,Lançamentos!$B$5:$B$604,"Saída",Lançamentos!$I$5:$I$604,"Sim",Lançamentos!$J$5:$J$604,12,Lançamentos!$K$5:$K$604,Config!$B$5-1,Lançamentos!$C$5:$C$604,Config!$F$14),SUMIFS(Lançamentos!$G$5:$G$604,Lançamentos!$B$5:$B$604,"Saída",Lançamentos!$I$5:$I$604,"Sim",Lançamentos!$J$5:$J$604,Config!$B$7-1,Lançamentos!$K$5:$K$604,Config!$B$5,Lançamentos!$C$5:$C$604,Config!$F$14))) -> 2357 | E18: =IF(Config!$F$14="","",SUMIFS(Lançamentos!$G$5:$G$604,Lançamentos!$B$5:$B$604,"Saída",Lançamentos!$I$5:$I$604,"Sim",Lançamentos!$C$5:$C$604,Config!$F$14,Lançamentos!$K$5:$K$604,Config!$B$5,Lançamentos!$J$5:$J$604,"<="&Config!$B$7)) -> 16087 | F18: =IF(C18="","",REPT("█",ROUND(C18*40,0)))
A19: =IF(Config!$F$15="","",Config!$F$15) -> Custas e despesas de processo | B19: =IF(Config!$F$15="","",SUMIFS(Lançamentos!$G$5:$G$604,Lançamentos!$B$5:$B$604,"Saída",Lançamentos!$I$5:$I$604,"Sim",Lançamentos!$J$5:$J$604,Config!$B$7,Lançamentos!$K$5:$K$604,Config!$B$5,Lançamentos!$C$5:$C$604,Config!$F$15)) -> 70 | C19: =IF(OR(Config!$F$15="",$C$5=0),"",B19/$C$5) -> 0.013157895 | D19: =IF(Config!$F$15="","",IF(Config!$B$7=1,SUMIFS(Lançamentos!$G$5:$G$604,Lançamentos!$B$5:$B$604,"Saída",Lançamentos!$I$5:$I$604,"Sim",Lançamentos!$J$5:$J$604,12,Lançamentos!$K$5:$K$604,Config!$B$5-1,Lançamentos!$C$5:$C$604,Config!$F$15),SUMIFS(Lançamentos!$G$5:$G$604,Lançamentos!$B$5:$B$604,"Saída",Lançamentos!$I$5:$I$604,"Sim",Lançamentos!$J$5:$J$604,Config!$B$7-1,Lançamentos!$K$5:$K$604,Config!$B$5,Lançamentos!$C$5:$C$604,Config!$F$15))) -> 380 | E19: =IF(Config!$F$15="","",SUMIFS(Lançamentos!$G$5:$G$604,Lançamentos!$B$5:$B$604,"Saída",Lançamentos!$I$5:$I$604,"Sim",Lançamentos!$C$5:$C$604,Config!$F$15,Lançamentos!$K$5:$K$604,Config!$B$5,Lançamentos!$J$5:$J$604,"<="&Config!$B$7)) -> 2875 | F19: =IF(C19="","",REPT("█",ROUND(C19*40,0))) -> █
A20: =IF(Config!$F$16="","",Config!$F$16) -> Deslocamento e viagens | B20: =IF(Config!$F$16="","",SUMIFS(Lançamentos!$G$5:$G$604,Lançamentos!$B$5:$B$604,"Saída",Lançamentos!$I$5:$I$604,"Sim",Lançamentos!$J$5:$J$604,Config!$B$7,Lançamentos!$K$5:$K$604,Config!$B$5,Lançamentos!$C$5:$C$604,Config!$F$16)) -> 0 | C20: =IF(OR(Config!$F$16="",$C$5=0),"",B20/$C$5) -> 0 | D20: =IF(Config!$F$16="","",IF(Config!$B$7=1,SUMIFS(Lançamentos!$G$5:$G$604,Lançamentos!$B$5:$B$604,"Saída",Lançamentos!$I$5:$I$604,"Sim",Lançamentos!$J$5:$J$604,12,Lançamentos!$K$5:$K$604,Config!$B$5-1,Lançamentos!$C$5:$C$604,Config!$F$16),SUMIFS(Lançamentos!$G$5:$G$604,Lançamentos!$B$5:$B$604,"Saída",Lançamentos!$I$5:$I$604,"Sim",Lançamentos!$J$5:$J$604,Config!$B$7-1,Lançamentos!$K$5:$K$604,Config!$B$5,Lançamentos!$C$5:$C$604,Config!$F$16))) -> 180 | E20: =IF(Config!$F$16="","",SUMIFS(Lançamentos!$G$5:$G$604,Lançamentos!$B$5:$B$604,"Saída",Lançamentos!$I$5:$I$604,"Sim",Lançamentos!$C$5:$C$604,Config!$F$16,Lançamentos!$K$5:$K$604,Config!$B$5,Lançamentos!$J$5:$J$604,"<="&Config!$B$7)) -> 730 | F20: =IF(C20="","",REPT("█",ROUND(C20*40,0)))
A21: =IF(Config!$F$17="","",Config!$F$17) -> Outras saídas | B21: =IF(Config!$F$17="","",SUMIFS(Lançamentos!$G$5:$G$604,Lançamentos!$B$5:$B$604,"Saída",Lançamentos!$I$5:$I$604,"Sim",Lançamentos!$J$5:$J$604,Config!$B$7,Lançamentos!$K$5:$K$604,Config!$B$5,Lançamentos!$C$5:$C$604,Config!$F$17)) -> 0 | C21: =IF(OR(Config!$F$17="",$C$5=0),"",B21/$C$5) -> 0 | D21: =IF(Config!$F$17="","",IF(Config!$B$7=1,SUMIFS(Lançamentos!$G$5:$G$604,Lançamentos!$B$5:$B$604,"Saída",Lançamentos!$I$5:$I$604,"Sim",Lançamentos!$J$5:$J$604,12,Lançamentos!$K$5:$K$604,Config!$B$5-1,Lançamentos!$C$5:$C$604,Config!$F$17),SUMIFS(Lançamentos!$G$5:$G$604,Lançamentos!$B$5:$B$604,"Saída",Lançamentos!$I$5:$I$604,"Sim",Lançamentos!$J$5:$J$604,Config!$B$7-1,Lançamentos!$K$5:$K$604,Config!$B$5,Lançamentos!$C$5:$C$604,Config!$F$17))) -> 480 | E21: =IF(Config!$F$17="","",SUMIFS(Lançamentos!$G$5:$G$604,Lançamentos!$B$5:$B$604,"Saída",Lançamentos!$I$5:$I$604,"Sim",Lançamentos!$C$5:$C$604,Config!$F$17,Lançamentos!$K$5:$K$604,Config!$B$5,Lançamentos!$J$5:$J$604,"<="&Config!$B$7)) -> 2040 | F21: =IF(C21="","",REPT("█",ROUND(C21*40,0)))
A22: =IF(Config!$F$18="","",Config!$F$18) | B22: =IF(Config!$F$18="","",SUMIFS(Lançamentos!$G$5:$G$604,Lançamentos!$B$5:$B$604,"Saída",Lançamentos!$I$5:$I$604,"Sim",Lançamentos!$J$5:$J$604,Config!$B$7,Lançamentos!$K$5:$K$604,Config!$B$5,Lançamentos!$C$5:$C$604,Config!$F$18)) | C22: =IF(OR(Config!$F$18="",$C$5=0),"",B22/$C$5) | D22: =IF(Config!$F$18="","",IF(Config!$B$7=1,SUMIFS(Lançamentos!$G$5:$G$604,Lançamentos!$B$5:$B$604,"Saída",Lançamentos!$I$5:$I$604,"Sim",Lançamentos!$J$5:$J$604,12,Lançamentos!$K$5:$K$604,Config!$B$5-1,Lançamentos!$C$5:$C$604,Config!$F$18),SUMIFS(Lançamentos!$G$5:$G$604,Lançamentos!$B$5:$B$604,"Saída",Lançamentos!$I$5:$I$604,"Sim",Lançamentos!$J$5:$J$604,Config!$B$7-1,Lançamentos!$K$5:$K$604,Config!$B$5,Lançamentos!$C$5:$C$604,Config!$F$18))) | E22: =IF(Config!$F$18="","",SUMIFS(Lançamentos!$G$5:$G$604,Lançamentos!$B$5:$B$604,"Saída",Lançamentos!$I$5:$I$604,"Sim",Lançamentos!$C$5:$C$604,Config!$F$18,Lançamentos!$K$5:$K$604,Config!$B$5,Lançamentos!$J$5:$J$604,"<="&Config!$B$7)) | F22: =IF(C22="","",REPT("█",ROUND(C22*40,0)))
A23: =IF(Config!$F$19="","",Config!$F$19) | B23: =IF(Config!$F$19="","",SUMIFS(Lançamentos!$G$5:$G$604,Lançamentos!$B$5:$B$604,"Saída",Lançamentos!$I$5:$I$604,"Sim",Lançamentos!$J$5:$J$604,Config!$B$7,Lançamentos!$K$5:$K$604,Config!$B$5,Lançamentos!$C$5:$C$604,Config!$F$19)) | C23: =IF(OR(Config!$F$19="",$C$5=0),"",B23/$C$5) | D23: =IF(Config!$F$19="","",IF(Config!$B$7=1,SUMIFS(Lançamentos!$G$5:$G$604,Lançamentos!$B$5:$B$604,"Saída",Lançamentos!$I$5:$I$604,"Sim",Lançamentos!$J$5:$J$604,12,Lançamentos!$K$5:$K$604,Config!$B$5-1,Lançamentos!$C$5:$C$604,Config!$F$19),SUMIFS(Lançamentos!$G$5:$G$604,Lançamentos!$B$5:$B$604,"Saída",Lançamentos!$I$5:$I$604,"Sim",Lançamentos!$J$5:$J$604,Config!$B$7-1,Lançamentos!$K$5:$K$604,Config!$B$5,Lançamentos!$C$5:$C$604,Config!$F$19))) | E23: =IF(Config!$F$19="","",SUMIFS(Lançamentos!$G$5:$G$604,Lançamentos!$B$5:$B$604,"Saída",Lançamentos!$I$5:$I$604,"Sim",Lançamentos!$C$5:$C$604,Config!$F$19,Lançamentos!$K$5:$K$604,Config!$B$5,Lançamentos!$J$5:$J$604,"<="&Config!$B$7)) | F23: =IF(C23="","",REPT("█",ROUND(C23*40,0)))
A24: =IF(Config!$F$20="","",Config!$F$20) | B24: =IF(Config!$F$20="","",SUMIFS(Lançamentos!$G$5:$G$604,Lançamentos!$B$5:$B$604,"Saída",Lançamentos!$I$5:$I$604,"Sim",Lançamentos!$J$5:$J$604,Config!$B$7,Lançamentos!$K$5:$K$604,Config!$B$5,Lançamentos!$C$5:$C$604,Config!$F$20)) | C24: =IF(OR(Config!$F$20="",$C$5=0),"",B24/$C$5) | D24: =IF(Config!$F$20="","",IF(Config!$B$7=1,SUMIFS(Lançamentos!$G$5:$G$604,Lançamentos!$B$5:$B$604,"Saída",Lançamentos!$I$5:$I$604,"Sim",Lançamentos!$J$5:$J$604,12,Lançamentos!$K$5:$K$604,Config!$B$5-1,Lançamentos!$C$5:$C$604,Config!$F$20),SUMIFS(Lançamentos!$G$5:$G$604,Lançamentos!$B$5:$B$604,"Saída",Lançamentos!$I$5:$I$604,"Sim",Lançamentos!$J$5:$J$604,Config!$B$7-1,Lançamentos!$K$5:$K$604,Config!$B$5,Lançamentos!$C$5:$C$604,Config!$F$20))) | E24: =IF(Config!$F$20="","",SUMIFS(Lançamentos!$G$5:$G$604,Lançamentos!$B$5:$B$604,"Saída",Lançamentos!$I$5:$I$604,"Sim",Lançamentos!$C$5:$C$604,Config!$F$20,Lançamentos!$K$5:$K$604,Config!$B$5,Lançamentos!$J$5:$J$604,"<="&Config!$B$7)) | F24: =IF(C24="","",REPT("█",ROUND(C24*40,0)))
A25: Total | B25: =SUM(B9:B24) -> 5320 | D25: =SUM(D9:D24) -> 21897 | E25: =SUM(E9:E24) -> 191387
A27: De onde veio o dinheiro
A28: Categoria de entrada | B28: Valor no mês | C28: % do total | D28: Mês anterior | E28: Acumulado no ano | F28: Barra
A29: =IF(Config!$D$5="","",Config!$D$5) -> Honorários fixos | B29: =IF(Config!$D$5="","",SUMIFS(Lançamentos!$G$5:$G$604,Lançamentos!$B$5:$B$604,"Entrada",Lançamentos!$I$5:$I$604,"Sim",Lançamentos!$J$5:$J$604,Config!$B$7,Lançamentos!$K$5:$K$604,Config!$B$5,Lançamentos!$C$5:$C$604,Config!$D$5)) -> 1000 | C29: =IF(OR(Config!$D$5="",$A$5=0),"",B29/$A$5) -> 0.19157088 | D29: =IF(Config!$D$5="","",IF(Config!$B$7=1,SUMIFS(Lançamentos!$G$5:$G$604,Lançamentos!$B$5:$B$604,"Entrada",Lançamentos!$I$5:$I$604,"Sim",Lançamentos!$J$5:$J$604,12,Lançamentos!$K$5:$K$604,Config!$B$5-1,Lançamentos!$C$5:$C$604,Config!$D$5),SUMIFS(Lançamentos!$G$5:$G$604,Lançamentos!$B$5:$B$604,"Entrada",Lançamentos!$I$5:$I$604,"Sim",Lançamentos!$J$5:$J$604,Config!$B$7-1,Lançamentos!$K$5:$K$604,Config!$B$5,Lançamentos!$C$5:$C$604,Config!$D$5))) -> 15300 | E29: =IF(Config!$D$5="","",SUMIFS(Lançamentos!$G$5:$G$604,Lançamentos!$B$5:$B$604,"Entrada",Lançamentos!$I$5:$I$604,"Sim",Lançamentos!$C$5:$C$604,Config!$D$5,Lançamentos!$K$5:$K$604,Config!$B$5,Lançamentos!$J$5:$J$604,"<="&Config!$B$7)) -> 124450 | F29: =IF(C29="","",REPT("█",ROUND(C29*40,0))) -> ████████
A30: =IF(Config!$D$6="","",Config!$D$6) -> Honorários por hora | B30: =IF(Config!$D$6="","",SUMIFS(Lançamentos!$G$5:$G$604,Lançamentos!$B$5:$B$604,"Entrada",Lançamentos!$I$5:$I$604,"Sim",Lançamentos!$J$5:$J$604,Config!$B$7,Lançamentos!$K$5:$K$604,Config!$B$5,Lançamentos!$C$5:$C$604,Config!$D$6)) -> 0 | C30: =IF(OR(Config!$D$6="",$A$5=0),"",B30/$A$5) -> 0 | D30: =IF(Config!$D$6="","",IF(Config!$B$7=1,SUMIFS(Lançamentos!$G$5:$G$604,Lançamentos!$B$5:$B$604,"Entrada",Lançamentos!$I$5:$I$604,"Sim",Lançamentos!$J$5:$J$604,12,Lançamentos!$K$5:$K$604,Config!$B$5-1,Lançamentos!$C$5:$C$604,Config!$D$6),SUMIFS(Lançamentos!$G$5:$G$604,Lançamentos!$B$5:$B$604,"Entrada",Lançamentos!$I$5:$I$604,"Sim",Lançamentos!$J$5:$J$604,Config!$B$7-1,Lançamentos!$K$5:$K$604,Config!$B$5,Lançamentos!$C$5:$C$604,Config!$D$6))) -> 0 | E30: =IF(Config!$D$6="","",SUMIFS(Lançamentos!$G$5:$G$604,Lançamentos!$B$5:$B$604,"Entrada",Lançamentos!$I$5:$I$604,"Sim",Lançamentos!$C$5:$C$604,Config!$D$6,Lançamentos!$K$5:$K$604,Config!$B$5,Lançamentos!$J$5:$J$604,"<="&Config!$B$7)) -> 18900 | F30: =IF(C30="","",REPT("█",ROUND(C30*40,0)))
A31: =IF(Config!$D$7="","",Config!$D$7) -> Honorários de êxito | B31: =IF(Config!$D$7="","",SUMIFS(Lançamentos!$G$5:$G$604,Lançamentos!$B$5:$B$604,"Entrada",Lançamentos!$I$5:$I$604,"Sim",Lançamentos!$J$5:$J$604,Config!$B$7,Lançamentos!$K$5:$K$604,Config!$B$5,Lançamentos!$C$5:$C$604,Config!$D$7)) -> 0 | C31: =IF(OR(Config!$D$7="",$A$5=0),"",B31/$A$5) -> 0 | D31: =IF(Config!$D$7="","",IF(Config!$B$7=1,SUMIFS(Lançamentos!$G$5:$G$604,Lançamentos!$B$5:$B$604,"Entrada",Lançamentos!$I$5:$I$604,"Sim",Lançamentos!$J$5:$J$604,12,Lançamentos!$K$5:$K$604,Config!$B$5-1,Lançamentos!$C$5:$C$604,Config!$D$7),SUMIFS(Lançamentos!$G$5:$G$604,Lançamentos!$B$5:$B$604,"Entrada",Lançamentos!$I$5:$I$604,"Sim",Lançamentos!$J$5:$J$604,Config!$B$7-1,Lançamentos!$K$5:$K$604,Config!$B$5,Lançamentos!$C$5:$C$604,Config!$D$7))) -> 0 | E31: =IF(Config!$D$7="","",SUMIFS(Lançamentos!$G$5:$G$604,Lançamentos!$B$5:$B$604,"Entrada",Lançamentos!$I$5:$I$604,"Sim",Lançamentos!$C$5:$C$604,Config!$D$7,Lançamentos!$K$5:$K$604,Config!$B$5,Lançamentos!$J$5:$J$604,"<="&Config!$B$7)) -> 27000 | F31: =IF(C31="","",REPT("█",ROUND(C31*40,0)))
A32: =IF(Config!$D$8="","",Config!$D$8) -> Consultoria e pareceres | B32: =IF(Config!$D$8="","",SUMIFS(Lançamentos!$G$5:$G$604,Lançamentos!$B$5:$B$604,"Entrada",Lançamentos!$I$5:$I$604,"Sim",Lançamentos!$J$5:$J$604,Config!$B$7,Lançamentos!$K$5:$K$604,Config!$B$5,Lançamentos!$C$5:$C$604,Config!$D$8)) -> 4220 | C32: =IF(OR(Config!$D$8="",$A$5=0),"",B32/$A$5) -> 0.80842912 | D32: =IF(Config!$D$8="","",IF(Config!$B$7=1,SUMIFS(Lançamentos!$G$5:$G$604,Lançamentos!$B$5:$B$604,"Entrada",Lançamentos!$I$5:$I$604,"Sim",Lançamentos!$J$5:$J$604,12,Lançamentos!$K$5:$K$604,Config!$B$5-1,Lançamentos!$C$5:$C$604,Config!$D$8),SUMIFS(Lançamentos!$G$5:$G$604,Lançamentos!$B$5:$B$604,"Entrada",Lançamentos!$I$5:$I$604,"Sim",Lançamentos!$J$5:$J$604,Config!$B$7-1,Lançamentos!$K$5:$K$604,Config!$B$5,Lançamentos!$C$5:$C$604,Config!$D$8))) -> 11290 | E32: =IF(Config!$D$8="","",SUMIFS(Lançamentos!$G$5:$G$604,Lançamentos!$B$5:$B$604,"Entrada",Lançamentos!$I$5:$I$604,"Sim",Lançamentos!$C$5:$C$604,Config!$D$8,Lançamentos!$K$5:$K$604,Config!$B$5,Lançamentos!$J$5:$J$604,"<="&Config!$B$7)) -> 40610 | F32: =IF(C32="","",REPT("█",ROUND(C32*40,0))) -> ████████████████████████████████
A33: =IF(Config!$D$9="","",Config!$D$9) -> Reembolso de custas | B33: =IF(Config!$D$9="","",SUMIFS(Lançamentos!$G$5:$G$604,Lançamentos!$B$5:$B$604,"Entrada",Lançamentos!$I$5:$I$604,"Sim",Lançamentos!$J$5:$J$604,Config!$B$7,Lançamentos!$K$5:$K$604,Config!$B$5,Lançamentos!$C$5:$C$604,Config!$D$9)) -> 0 | C33: =IF(OR(Config!$D$9="",$A$5=0),"",B33/$A$5) -> 0 | D33: =IF(Config!$D$9="","",IF(Config!$B$7=1,SUMIFS(Lançamentos!$G$5:$G$604,Lançamentos!$B$5:$B$604,"Entrada",Lançamentos!$I$5:$I$604,"Sim",Lançamentos!$J$5:$J$604,12,Lançamentos!$K$5:$K$604,Config!$B$5-1,Lançamentos!$C$5:$C$604,Config!$D$9),SUMIFS(Lançamentos!$G$5:$G$604,Lançamentos!$B$5:$B$604,"Entrada",Lançamentos!$I$5:$I$604,"Sim",Lançamentos!$J$5:$J$604,Config!$B$7-1,Lançamentos!$K$5:$K$604,Config!$B$5,Lançamentos!$C$5:$C$604,Config!$D$9))) -> 310 | E33: =IF(Config!$D$9="","",SUMIFS(Lançamentos!$G$5:$G$604,Lançamentos!$B$5:$B$604,"Entrada",Lançamentos!$I$5:$I$604,"Sim",Lançamentos!$C$5:$C$604,Config!$D$9,Lançamentos!$K$5:$K$604,Config!$B$5,Lançamentos!$J$5:$J$604,"<="&Config!$B$7)) -> 1630 | F33: =IF(C33="","",REPT("█",ROUND(C33*40,0)))
A34: =IF(Config!$D$10="","",Config!$D$10) -> Outras entradas | B34: =IF(Config!$D$10="","",SUMIFS(Lançamentos!$G$5:$G$604,Lançamentos!$B$5:$B$604,"Entrada",Lançamentos!$I$5:$I$604,"Sim",Lançamentos!$J$5:$J$604,Config!$B$7,Lançamentos!$K$5:$K$604,Config!$B$5,Lançamentos!$C$5:$C$604,Config!$D$10)) -> 0 | C34: =IF(OR(Config!$D$10="",$A$5=0),"",B34/$A$5) -> 0 | D34: =IF(Config!$D$10="","",IF(Config!$B$7=1,SUMIFS(Lançamentos!$G$5:$G$604,Lançamentos!$B$5:$B$604,"Entrada",Lançamentos!$I$5:$I$604,"Sim",Lançamentos!$J$5:$J$604,12,Lançamentos!$K$5:$K$604,Config!$B$5-1,Lançamentos!$C$5:$C$604,Config!$D$10),SUMIFS(Lançamentos!$G$5:$G$604,Lançamentos!$B$5:$B$604,"Entrada",Lançamentos!$I$5:$I$604,"Sim",Lançamentos!$J$5:$J$604,Config!$B$7-1,Lançamentos!$K$5:$K$604,Config!$B$5,Lançamentos!$C$5:$C$604,Config!$D$10))) -> 0 | E34: =IF(Config!$D$10="","",SUMIFS(Lançamentos!$G$5:$G$604,Lançamentos!$B$5:$B$604,"Entrada",Lançamentos!$I$5:$I$604,"Sim",Lançamentos!$C$5:$C$604,Config!$D$10,Lançamentos!$K$5:$K$604,Config!$B$5,Lançamentos!$J$5:$J$604,"<="&Config!$B$7)) -> 480 | F34: =IF(C34="","",REPT("█",ROUND(C34*40,0)))
A35: =IF(Config!$D$11="","",Config!$D$11) | B35: =IF(Config!$D$11="","",SUMIFS(Lançamentos!$G$5:$G$604,Lançamentos!$B$5:$B$604,"Entrada",Lançamentos!$I$5:$I$604,"Sim",Lançamentos!$J$5:$J$604,Config!$B$7,Lançamentos!$K$5:$K$604,Config!$B$5,Lançamentos!$C$5:$C$604,Config!$D$11)) | C35: =IF(OR(Config!$D$11="",$A$5=0),"",B35/$A$5) | D35: =IF(Config!$D$11="","",IF(Config!$B$7=1,SUMIFS(Lançamentos!$G$5:$G$604,Lançamentos!$B$5:$B$604,"Entrada",Lançamentos!$I$5:$I$604,"Sim",Lançamentos!$J$5:$J$604,12,Lançamentos!$K$5:$K$604,Config!$B$5-1,Lançamentos!$C$5:$C$604,Config!$D$11),SUMIFS(Lançamentos!$G$5:$G$604,Lançamentos!$B$5:$B$604,"Entrada",Lançamentos!$I$5:$I$604,"Sim",Lançamentos!$J$5:$J$604,Config!$B$7-1,Lançamentos!$K$5:$K$604,Config!$B$5,Lançamentos!$C$5:$C$604,Config!$D$11))) | E35: =IF(Config!$D$11="","",SUMIFS(Lançamentos!$G$5:$G$604,Lançamentos!$B$5:$B$604,"Entrada",Lançamentos!$I$5:$I$604,"Sim",Lançamentos!$C$5:$C$604,Config!$D$11,Lançamentos!$K$5:$K$604,Config!$B$5,Lançamentos!$J$5:$J$604,"<="&Config!$B$7)) | F35: =IF(C35="","",REPT("█",ROUND(C35*40,0)))
A36: =IF(Config!$D$12="","",Config!$D$12) | B36: =IF(Config!$D$12="","",SUMIFS(Lançamentos!$G$5:$G$604,Lançamentos!$B$5:$B$604,"Entrada",Lançamentos!$I$5:$I$604,"Sim",Lançamentos!$J$5:$J$604,Config!$B$7,Lançamentos!$K$5:$K$604,Config!$B$5,Lançamentos!$C$5:$C$604,Config!$D$12)) | C36: =IF(OR(Config!$D$12="",$A$5=0),"",B36/$A$5) | D36: =IF(Config!$D$12="","",IF(Config!$B$7=1,SUMIFS(Lançamentos!$G$5:$G$604,Lançamentos!$B$5:$B$604,"Entrada",Lançamentos!$I$5:$I$604,"Sim",Lançamentos!$J$5:$J$604,12,Lançamentos!$K$5:$K$604,Config!$B$5-1,Lançamentos!$C$5:$C$604,Config!$D$12),SUMIFS(Lançamentos!$G$5:$G$604,Lançamentos!$B$5:$B$604,"Entrada",Lançamentos!$I$5:$I$604,"Sim",Lançamentos!$J$5:$J$604,Config!$B$7-1,Lançamentos!$K$5:$K$604,Config!$B$5,Lançamentos!$C$5:$C$604,Config!$D$12))) | E36: =IF(Config!$D$12="","",SUMIFS(Lançamentos!$G$5:$G$604,Lançamentos!$B$5:$B$604,"Entrada",Lançamentos!$I$5:$I$604,"Sim",Lançamentos!$C$5:$C$604,Config!$D$12,Lançamentos!$K$5:$K$604,Config!$B$5,Lançamentos!$J$5:$J$604,"<="&Config!$B$7)) | F36: =IF(C36="","",REPT("█",ROUND(C36*40,0)))
A37: =IF(Config!$D$13="","",Config!$D$13) | B37: =IF(Config!$D$13="","",SUMIFS(Lançamentos!$G$5:$G$604,Lançamentos!$B$5:$B$604,"Entrada",Lançamentos!$I$5:$I$604,"Sim",Lançamentos!$J$5:$J$604,Config!$B$7,Lançamentos!$K$5:$K$604,Config!$B$5,Lançamentos!$C$5:$C$604,Config!$D$13)) | C37: =IF(OR(Config!$D$13="",$A$5=0),"",B37/$A$5) | D37: =IF(Config!$D$13="","",IF(Config!$B$7=1,SUMIFS(Lançamentos!$G$5:$G$604,Lançamentos!$B$5:$B$604,"Entrada",Lançamentos!$I$5:$I$604,"Sim",Lançamentos!$J$5:$J$604,12,Lançamentos!$K$5:$K$604,Config!$B$5-1,Lançamentos!$C$5:$C$604,Config!$D$13),SUMIFS(Lançamentos!$G$5:$G$604,Lançamentos!$B$5:$B$604,"Entrada",Lançamentos!$I$5:$I$604,"Sim",Lançamentos!$J$5:$J$604,Config!$B$7-1,Lançamentos!$K$5:$K$604,Config!$B$5,Lançamentos!$C$5:$C$604,Config!$D$13))) | E37: =IF(Config!$D$13="","",SUMIFS(Lançamentos!$G$5:$G$604,Lançamentos!$B$5:$B$604,"Entrada",Lançamentos!$I$5:$I$604,"Sim",Lançamentos!$C$5:$C$604,Config!$D$13,Lançamentos!$K$5:$K$604,Config!$B$5,Lançamentos!$J$5:$J$604,"<="&Config!$B$7)) | F37: =IF(C37="","",REPT("█",ROUND(C37*40,0)))
A38: =IF(Config!$D$14="","",Config!$D$14) | B38: =IF(Config!$D$14="","",SUMIFS(Lançamentos!$G$5:$G$604,Lançamentos!$B$5:$B$604,"Entrada",Lançamentos!$I$5:$I$604,"Sim",Lançamentos!$J$5:$J$604,Config!$B$7,Lançamentos!$K$5:$K$604,Config!$B$5,Lançamentos!$C$5:$C$604,Config!$D$14)) | C38: =IF(OR(Config!$D$14="",$A$5=0),"",B38/$A$5) | D38: =IF(Config!$D$14="","",IF(Config!$B$7=1,SUMIFS(Lançamentos!$G$5:$G$604,Lançamentos!$B$5:$B$604,"Entrada",Lançamentos!$I$5:$I$604,"Sim",Lançamentos!$J$5:$J$604,12,Lançamentos!$K$5:$K$604,Config!$B$5-1,Lançamentos!$C$5:$C$604,Config!$D$14),SUMIFS(Lançamentos!$G$5:$G$604,Lançamentos!$B$5:$B$604,"Entrada",Lançamentos!$I$5:$I$604,"Sim",Lançamentos!$J$5:$J$604,Config!$B$7-1,Lançamentos!$K$5:$K$604,Config!$B$5,Lançamentos!$C$5:$C$604,Config!$D$14))) | E38: =IF(Config!$D$14="","",SUMIFS(Lançamentos!$G$5:$G$604,Lançamentos!$B$5:$B$604,"Entrada",Lançamentos!$I$5:$I$604,"Sim",Lançamentos!$C$5:$C$604,Config!$D$14,Lançamentos!$K$5:$K$604,Config!$B$5,Lançamentos!$J$5:$J$604,"<="&Config!$B$7)) | F38: =IF(C38="","",REPT("█",ROUND(C38*40,0)))
A39: =IF(Config!$D$15="","",Config!$D$15) | B39: =IF(Config!$D$15="","",SUMIFS(Lançamentos!$G$5:$G$604,Lançamentos!$B$5:$B$604,"Entrada",Lançamentos!$I$5:$I$604,"Sim",Lançamentos!$J$5:$J$604,Config!$B$7,Lançamentos!$K$5:$K$604,Config!$B$5,Lançamentos!$C$5:$C$604,Config!$D$15)) | C39: =IF(OR(Config!$D$15="",$A$5=0),"",B39/$A$5) | D39: =IF(Config!$D$15="","",IF(Config!$B$7=1,SUMIFS(Lançamentos!$G$5:$G$604,Lançamentos!$B$5:$B$604,"Entrada",Lançamentos!$I$5:$I$604,"Sim",Lançamentos!$J$5:$J$604,12,Lançamentos!$K$5:$K$604,Config!$B$5-1,Lançamentos!$C$5:$C$604,Config!$D$15),SUMIFS(Lançamentos!$G$5:$G$604,Lançamentos!$B$5:$B$604,"Entrada",Lançamentos!$I$5:$I$604,"Sim",Lançamentos!$J$5:$J$604,Config!$B$7-1,Lançamentos!$K$5:$K$604,Config!$B$5,Lançamentos!$C$5:$C$604,Config!$D$15))) | E39: =IF(Config!$D$15="","",SUMIFS(Lançamentos!$G$5:$G$604,Lançamentos!$B$5:$B$604,"Entrada",Lançamentos!$I$5:$I$604,"Sim",Lançamentos!$C$5:$C$604,Config!$D$15,Lançamentos!$K$5:$K$604,Config!$B$5,Lançamentos!$J$5:$J$604,"<="&Config!$B$7)) | F39: =IF(C39="","",REPT("█",ROUND(C39*40,0)))
A40: =IF(Config!$D$16="","",Config!$D$16) | B40: =IF(Config!$D$16="","",SUMIFS(Lançamentos!$G$5:$G$604,Lançamentos!$B$5:$B$604,"Entrada",Lançamentos!$I$5:$I$604,"Sim",Lançamentos!$J$5:$J$604,Config!$B$7,Lançamentos!$K$5:$K$604,Config!$B$5,Lançamentos!$C$5:$C$604,Config!$D$16)) | C40: =IF(OR(Config!$D$16="",$A$5=0),"",B40/$A$5) | D40: =IF(Config!$D$16="","",IF(Config!$B$7=1,SUMIFS(Lançamentos!$G$5:$G$604,Lançamentos!$B$5:$B$604,"Entrada",Lançamentos!$I$5:$I$604,"Sim",Lançamentos!$J$5:$J$604,12,Lançamentos!$K$5:$K$604,Config!$B$5-1,Lançamentos!$C$5:$C$604,Config!$D$16),SUMIFS(Lançamentos!$G$5:$G$604,Lançamentos!$B$5:$B$604,"Entrada",Lançamentos!$I$5:$I$604,"Sim",Lançamentos!$J$5:$J$604,Config!$B$7-1,Lançamentos!$K$5:$K$604,Config!$B$5,Lançamentos!$C$5:$C$604,Config!$D$16))) | E40: =IF(Config!$D$16="","",SUMIFS(Lançamentos!$G$5:$G$604,Lançamentos!$B$5:$B$604,"Entrada",Lançamentos!$I$5:$I$604,"Sim",Lançamentos!$C$5:$C$604,Config!$D$16,Lançamentos!$K$5:$K$604,Config!$B$5,Lançamentos!$J$5:$J$604,"<="&Config!$B$7)) | F40: =IF(C40="","",REPT("█",ROUND(C40*40,0)))
A41: Total | B41: =SUM(B29:B40) -> 5220 | D41: =SUM(D29:D40) -> 26900 | E41: =SUM(E29:E40) -> 213070
A43: Por cliente
A44: Cliente | B44: Entrou no mês | C44: Entrou no ano | D44: % do ano | E44: A receber (Pago? = Não) | F44: Custas pagas no ano
...

Sheet Config
A1: Configurações
A2: Células amarelas: você preenche. Categorias e clientes alimentam as listas de Lançamentos e o Painel.
A4: Escritório | B4: Ferraz & Lima Advocacia (exemplo fictício) | D4: Categorias de entrada (até 12) | F4: Categorias de saída (até 16) | H4: Todas as categorias (automático) | J4: Clientes (até 30) | L4: Meses
A5: Ano do painel | B5: 2026 | D5: Honorários fixos | F5: Pró-labore dos sócios | H5: =IF(1<=COUNTA($D$5:$D$16),INDEX($D$5:$D$16,1),IF(1<=COUNTA($D$5:$D$16)+COUNTA($F$5:$F$20),INDEX($F$5:$F$20,1-COUNTA($D$5:$D$16)),"")) -> Honorários fixos | J5: Padaria do Sol Ltda | L5: Janeiro
A6: Mês do painel | B6: Setembro | D6: Honorários por hora | F6: Aluguel e condomínio | H6: =IF(2<=COUNTA($D$5:$D$16),INDEX($D$5:$D$16,2),IF(2<=COUNTA($D$5:$D$16)+COUNTA($F$5:$F$20),INDEX($F$5:$F$20,2-COUNTA($D$5:$D$16)),"")) -> Honorários por hora | J6: Ana Beatriz Moreira | L6: Fevereiro
A7: Número do mês | B7: =MATCH(B6,$L$5:$L$16,0) -> 9 | D7: Honorários de êxito | F7: Contador | H7: =IF(3<=COUNTA($D$5:$D$16),INDEX($D$5:$D$16,3),IF(3<=COUNTA($D$5:$D$16)+COUNTA($F$5:$F$20),INDEX($F$5:$F$20,3-COUNTA($D$5:$D$16)),"")) -> Honorários de êxito | J7: Construtora Horizonte | L7: Março
A8: Saldo em caixa antes do 1º lançamento | B8: 22000 | D8: Consultoria e pareceres | F8: Sistemas e assinaturas | H8: =IF(4<=COUNTA($D$5:$D$16),INDEX($D$5:$D$16,4),IF(4<=COUNTA($D$5:$D$16)+COUNTA($F$5:$F$20),INDEX($F$5:$F$20,4-COUNTA($D$5:$D$16)),"")) -> Consultoria e pareceres | J8: Carlos Eduardo Nunes | L8: Abril
A9: Data de referência | B9: =TODAY() -> 46279 | D9: Reembolso de custas | F9: Telefone e internet | H9: =IF(5<=COUNTA($D$5:$D$16),INDEX($D$5:$D$16,5),IF(5<=COUNTA($D$5:$D$16)+COUNTA($F$5:$F$20),INDEX($F$5:$F$20,5-COUNTA($D$5:$D$16)),"")) -> Reembolso de custas | J9: Loja Verde Comércio | L9: Maio
D10: Outras entradas | F10: Anuidades OAB e cursos | H10: =IF(6<=COUNTA($D$5:$D$16),INDEX($D$5:$D$16,6),IF(6<=COUNTA($D$5:$D$16)+COUNTA($F$5:$F$20),INDEX($F$5:$F$20,6-COUNTA($D$5:$D$16)),"")) -> Outras entradas | J10: Fernanda Castro | L10: Junho
F11: Marketing e site | H11: =IF(7<=COUNTA($D$5:$D$16),INDEX($D$5:$D$16,7),IF(7<=COUNTA($D$5:$D$16)+COUNTA($F$5:$F$20),INDEX($F$5:$F$20,7-COUNTA($D$5:$D$16)),"")) -> Pró-labore dos sócios | J11: Bistrô 42 | L11: Julho
F12: Estagiária (bolsa) | H12: =IF(8<=COUNTA($D$5:$D$16),INDEX($D$5:$D$16,8),IF(8<=COUNTA($D$5:$D$16)+COUNTA($F$5:$F$20),INDEX($F$5:$F$20,8-COUNTA($D$5:$D$16)),"")) -> Aluguel e condomínio | J12: Roberto Almeida | L12: Agosto
F13: Material, correio e outros | H13: =IF(9<=COUNTA($D$5:$D$16),INDEX($D$5:$D$16,9),IF(9<=COUNTA($D$5:$D$16)+COUNTA($F$5:$F$20),INDEX($F$5:$F$20,9-COUNTA($D$5:$D$16)),"")) -> Contador | J13: Clínica Bem-Estar | L13: Setembro
F14: Impostos e taxas | H14: =IF(10<=COUNTA($D$5:$D$16),INDEX($D$5:$D$16,10),IF(10<=COUNTA($D$5:$D$16)+COUNTA($F$5:$F$20),INDEX($F$5:$F$20,10-COUNTA($D$5:$D$16)),"")) -> Sistemas e assinaturas | J14: Marcos Vinícius Teles | L14: Outubro
F15: Custas e despesas de processo | H15: =IF(11<=COUNTA($D$5:$D$16),INDEX($D$5:$D$16,11),IF(11<=COUNTA($D$5:$D$16)+COUNTA($F$5:$F$20),INDEX($F$5:$F$20,11-COUNTA($D$5:$D$16)),"")) -> Telefone e internet | J15: Transportadora Rota Sul | L15: Novembro
F16: Deslocamento e viagens | H16: =IF(12<=COUNTA($D$5:$D$16),INDEX($D$5:$D$16,12),IF(12<=COUNTA($D$5:$D$16)+COUNTA($F$5:$F$20),INDEX($F$5:$F$20,12-COUNTA($D$5:$D$16)),"")) -> Anuidades OAB e cursos | J16: Patrícia Gomes | L16: Dezembro
F17: Outras saídas | H17: =IF(13<=COUNTA($D$5:$D$16),INDEX($D$5:$D$16,13),IF(13<=COUNTA($D$5:$D$16)+COUNTA($F$5:$F$20),INDEX($F$5:$F$20,13-COUNTA($D$5:$D$16)),"")) -> Marketing e site | J17: Escola Aurora
H18: =IF(14<=COUNTA($D$5:$D$16),INDEX($D$5:$D$16,14),IF(14<=COUNTA($D$5:$D$16)+COUNTA($F$5:$F$20),INDEX($F$5:$F$20,14-COUNTA($D$5:$D$16)),"")) -> Estagiária (bolsa) | J18: José Antônio Ribeiro
H19: =IF(15<=COUNTA($D$5:$D$16),INDEX($D$5:$D$16,15),IF(15<=COUNTA($D$5:$D$16)+COUNTA($F$5:$F$20),INDEX($F$5:$F$20,15-COUNTA($D$5:$D$16)),"")) -> Material, correio e outros | J19: Oficina Mecânica Central
H20: =IF(16<=COUNTA($D$5:$D$16),INDEX($D$5:$D$16,16),IF(16<=COUNTA($D$5:$D$16)+COUNTA($F$5:$F$20),INDEX($F$5:$F$20,16-COUNTA($D$5:$D$16)),"")) -> Impostos e taxas | J20: Luciana Farias
H21: =IF(17<=COUNTA($D$5:$D$16),INDEX($D$5:$D$16,17),IF(17<=COUNTA($D$5:$D$16)+COUNTA($F$5:$F$20),INDEX($F$5:$F$20,17-COUNTA($D$5:$D$16)),"")) -> Custas e despesas de processo | J21: Agência Prisma
H22: =IF(18<=COUNTA($D$5:$D$16),INDEX($D$5:$D$16,18),IF(18<=COUNTA($D$5:$D$16)+COUNTA($F$5:$F$20),INDEX($F$5:$F$20,18-COUNTA($D$5:$D$16)),"")) -> Deslocamento e viagens | J22: Helena Duarte
H23: =IF(19<=COUNTA($D$5:$D$16),INDEX($D$5:$D$16,19),IF(19<=COUNTA($D$5:$D$16)+COUNTA($F$5:$F$20),INDEX($F$5:$F$20,19-COUNTA($D$5:$D$16)),"")) -> Outras saídas
H24: =IF(20<=COUNTA($D$5:$D$16),INDEX($D$5:$D$16,20),IF(20<=COUNTA($D$5:$D$16)+COUNTA($F$5:$F$20),INDEX($F$5:$F$20,20-COUNTA($D$5:$D$16)),""))
H25: =IF(21<=COUNTA($D$5:$D$16),INDEX($D$5:$D$16,21),IF(21<=COUNTA($D$5:$D$16)+COUNTA($F$5:$F$20),INDEX($F$5:$F$20,21-COUNTA($D$5:$D$16)),""))
H26: =IF(22<=COUNTA($D$5:$D$16),INDEX($D$5:$D$16,22),IF(22<=COUNTA($D$5:$D$16)+COUNTA($F$5:$F$20),INDEX($F$5:$F$20,22-COUNTA($D$5:$D$16)),""))
H27: =IF(23<=COUNTA($D$5:$D$16),INDEX($D$5:$D$16,23),IF(23<=COUNTA($D$5:$D$16)+COUNTA($F$5:$F$20),INDEX($F$5:$F$20,23-COUNTA($D$5:$D$16)),""))
H28: =IF(24<=COUNTA($D$5:$D$16),INDEX($D$5:$D$16,24),IF(24<=COUNTA($D$5:$D$16)+COUNTA($F$5:$F$20),INDEX($F$5:$F$20,24-COUNTA($D$5:$D$16)),""))
H29: =IF(25<=COUNTA($D$5:$D$16),INDEX($D$5:$D$16,25),IF(25<=COUNTA($D$5:$D$16)+COUNTA($F$5:$F$20),INDEX($F$5:$F$20,25-COUNTA($D$5:$D$16)),""))
H30: =IF(26<=COUNTA($D$5:$D$16),INDEX($D$5:$D$16,26),IF(26<=COUNTA($D$5:$D$16)+COUNTA($F$5:$F$20),INDEX($F$5:$F$20,26-COUNTA($D$5:$D$16)),""))
H31: =IF(27<=COUNTA($D$5:$D$16),INDEX($D$5:$D$16,27),IF(27<=COUNTA($D$5:$D$16)+COUNTA($F$5:$F$20),INDEX($F$5:$F$20,27-COUNTA($D$5:$D$16)),""))
H32: =IF(28<=COUNTA($D$5:$D$16),INDEX($D$5:$D$16,28),IF(28<=COUNTA($D$5:$D$16)+COUNTA($F$5:$F$20),INDEX($F$5:$F$20,28-COUNTA($D$5:$D$16)),""))
A37: Preencha categorias e clientes de cima para baixo, sem pular linha: as listas suspensas de Lançamentos param na última linha preenchida.
A38: Saldo antes do 1º lançamento: o que havia na conta do escritório na data do primeiro lançamento (no exemplo, 01/01/2026, já contando honorários recebidos em 2025).
A39: Pró-labore dos sócios é uma categoria de saída como qualquer outra: o que sai do caixa do escritório para a pessoa física. A separação detalhada fica na planilha 11.
A40: Exemplo: cada entrada de honorários é uma parcela paga da planilha 14 (Parcelas), dos casos da 13 (Carteira). Pago? = Não são as parcelas já vencidas e as que vencem até o fim do mês (faturadas); o cronograma completo fica na 14. Lançamentos pagos vão até 11/09/2026 (a última sexta).

Sheet Lançamentos
A1: Lançamentos
A2: Uma linha por entrada ou saída. Preencha o amarelo; mês e ano são calculados. Pago? = Não fica em A receber / A pagar e só entra no caixa quando virar Sim.
A4: Data | B4: Tipo | C4: Categoria | D4: Cliente | E4: Caso (nº ou referência) | F4: Descrição | G4: Valor | H4: Forma | I4: Pago? | J4: Mês | K4: Ano
A5: 46027 | B5: Saída | C5: Aluguel e condomínio | F5: Aluguel e condomínio da sala | G5: 2800 | H5: Boleto | I5: Sim | J5: =IF(A5="","",MONTH(A5)) -> 1 | K5: =IF(A5="","",YEAR(A5)) -> 2026
A6: 46027 | B6: Saída | C6: Estagiária (bolsa) | F6: Bolsa da estagiária · Júlia Prado | G6: 1400 | H6: Cartão | I6: Sim | J6: =IF(A6="","",MONTH(A6)) -> 1 | K6: =IF(A6="","",YEAR(A6)) -> 2026
A7: 46029 | B7: Entrada | C7: Honorários fixos | D7: Transportadora Rota Sul | E7: 9225646-96.2025.8.26.0322 | F7: Honorários · parcela 1 | G7: 2000 | H7: Pix | I7: Sim | J7: =IF(A7="","",MONTH(A7)) -> 1 | K7: =IF(A7="","",YEAR(A7)) -> 2026
A8: 46030 | B8: Saída | C8: Sistemas e assinaturas | F8: Sistemas e assinaturas | G8: 450 | H8: Cartão | I8: Sim | J8: =IF(A8="","",MONTH(A8)) -> 1 | K8: =IF(A8="","",YEAR(A8)) -> 2026
A9: 46032 | B9: Saída | C9: Contador | F9: Honorários do contador | G9: 600 | H9: Boleto | I9: Sim | J9: =IF(A9="","",MONTH(A9)) -> 1 | K9: =IF(A9="","",YEAR(A9)) -> 2026
A10: 46034 | B10: Entrada | C10: Consultoria e pareceres | D10: Clínica Bem-Estar | E10: CONS-2025-05 | F10: Fatura de horas · 2 | G10: 2520 | H10: Boleto | I10: Sim | J10: =IF(A10="","",MONTH(A10)) -> 1 | K10: =IF(A10="","",YEAR(A10)) -> 2026
A11: 46034 | B11: Entrada | C11: Honorários fixos | D11: Roberto Almeida | E11: 5025425-10.2025.8.26.0629 | F11: Honorários · parcela 1 | G11: 3000 | H11: Pix | I11: Sim | J11: =IF(A11="","",MONTH(A11)) -> 1 | K11: =IF(A11="","",YEAR(A11)) -> 2026
A12: 46034 | B12: Entrada | C12: Honorários fixos | D12: Oficina Mecânica Central | E12: 8663770-96.2025.8.26.0481 | F12: Honorários · parcela 8 | G12: 800 | H12: Pix | I12: Sim | J12: =IF(A12="","",MONTH(A12)) -> 1 | K12: =IF(A12="","",YEAR(A12)) -> 2026
A13: 46034 | B13: Entrada | C13: Honorários por hora | D13: Agência Prisma | E13: 9362688-24.2025.8.26.0436 | F13: Fatura de horas · 1 | G13: 2880 | H13: Boleto | I13: Sim | J13: =IF(A13="","",MONTH(A13)) -> 1 | K13: =IF(A13="","",YEAR(A13)) -> 2026
A14: 46034 | B14: Saída | C14: Telefone e internet | F14: Telefone e internet | G14: 220 | H14: Boleto | I14: Sim | J14: =IF(A14="","",MONTH(A14)) -> 1 | K14: =IF(A14="","",YEAR(A14)) -> 2026
A15: 46036 | B15: Saída | C15: Custas e despesas de processo | D15: José Antônio Ribeiro | E15: 5900991-46.2026.8.26.0469 | F15: Custas iniciais | G15: 260 | H15: Boleto | I15: Sim | J15: =IF(A15="","",MONTH(A15)) -> 1 | K15: =IF(A15="","",YEAR(A15)) -> 2026
A16: 46037 | B16: Entrada | C16: Honorários fixos | D16: Fernanda Castro | E16: 5211189-81.2025.8.26.0412 | F16: Honorários · parcela 3 | G16: 1400 | H16: Pix | I16: Sim | J16: =IF(A16="","",MONTH(A16)) -> 1 | K16: =IF(A16="","",YEAR(A16)) -> 2026
A17: 46037 | B17: Saída | C17: Anuidades OAB e cursos | F17: Anuidades OAB e cursos | G17: 250 | H17: Cartão | I17: Sim | J17: =IF(A17="","",MONTH(A17)) -> 1 | K17: =IF(A17="","",YEAR(A17)) -> 2026
A18: 46040 | B18: Saída | C18: Material, correio e outros | F18: Material, correio e outros | G18: 380 | H18: Cartão | I18: Sim | J18: =IF(A18="","",MONTH(A18)) -> 1 | K18: =IF(A18="","",YEAR(A18)) -> 2026
A19: 46041 | B19: Entrada | C19: Honorários fixos | D19: Bistrô 42 | E19: 8056747-83.2026.8.26.0561 | F19: Honorários · entrada | G19: 3200 | H19: Pix | I19: Sim | J19: =IF(A19="","",MONTH(A19)) -> 1 | K19: =IF(A19="","",YEAR(A19)) -> 2026
A20: 46041 | B20: Entrada | C20: Honorários fixos | D20: Padaria do Sol Ltda | E20: 4766902-26.2025.8.26.0051 | F20: Honorários · parcela 2 | G20: 2250 | H20: Pix | I20: Sim | J20: =IF(A20="","",MONTH(A20)) -> 1 | K20: =IF(A20="","",YEAR(A20)) -> 2026
A21: 46042 | B21: Saída | C21: Impostos e taxas | F21: Guia de impostos do mês anterior (alíquota efetiva combinada com o contador) | G21: 1648 | H21: Boleto | I21: Sim | J21: =IF(A21="","",MONTH(A21)) -> 1 | K21: =IF(A21="","",YEAR(A21)) -> 2026
A22: 46042 | B22: Saída | C22: Marketing e site | F22: Marketing e site | G22: 400 | H22: Cartão | I22: Sim | J22: =IF(A22="","",MONTH(A22)) -> 1 | K22: =IF(A22="","",YEAR(A22)) -> 2026
A23: 46044 | B23: Entrada | C23: Honorários fixos | D23: Loja Verde Comércio | E23: 9088515-39.2025.8.26.0125 | F23: Honorários · parcela 4 | G23: 1000 | H23: Pix | I23: Sim | J23: =IF(A23="","",MONTH(A23)) -> 1 | K23: =IF(A23="","",YEAR(A23)) -> 2026
A24: 46045 | B24: Entrada | C24: Honorários fixos | D24: Oficina Mecânica Central | E24: 3363714-92.2025.8.26.0592 | F24: Honorários · parcela 2 | G24: 2000 | H24: Pix | I24: Sim | J24: =IF(A24="","",MONTH(A24)) -> 1 | K24: =IF(A24="","",YEAR(A24)) -> 2026
A25: 46050 | B25: Saída | C25: Pró-labore dos sócios | F25: Pró-labore · Marina Ferraz | G25: 6000 | H25: Transferência | I25: Sim | J25: =IF(A25="","",MONTH(A25)) -> 1 | K25: =IF(A25="","",YEAR(A25)) -> 2026
A26: 46050 | B26: Saída | C26: Pró-labore dos sócios | F26: Pró-labore · Rafael Lima | G26: 6000 | H26: Transferência | I26: Sim | J26: =IF(A26="","",MONTH(A26)) -> 1 | K26: =IF(A26="","",YEAR(A26)) -> 2026
A27: 46055 | B27: Entrada | C27: Honorários fixos | D27: Escola Aurora | E27: 6710873-21.2025.8.26.0571 | F27: Honorários · parcela 3 | G27: 1200 | H27: Pix | I27: Sim | J27: =IF(A27="","",MONTH(A27)) -> 2 | K27: =IF(A27="","",YEAR(A27)) -> 2026
A28: 46058 | B28: Saída | C28: Aluguel e condomínio | F28: Aluguel e condomínio da sala | G28: 2800 | H28: Boleto | I28: Sim | J28: =IF(A28="","",MONTH(A28)) -> 2 | K28: =IF(A28="","",YEAR(A28)) -> 2026
A29: 46058 | B29: Saída | C29: Estagiária (bolsa) | F29: Bolsa da estagiária · Júlia Prado | G29: 1400 | H29: Cartão | I29: Sim | J29: =IF(A29="","",MONTH(A29)) -> 2 | K29: =IF(A29="","",YEAR(A29)) -> 2026
A30: 46059 | B30: Entrada | C30: Honorários de êxito | D30: Marcos Vinícius Teles | E30: 8204296-70.2025.8.26.0146 | F30: Honorários de êxito (fim do caso) | G30: 6500 | H30: Pix | I30: Sim | J30: =IF(A30="","",MONTH(A30)) -> 2 | K30: =IF(A30="","",YEAR(A30)) -> 2026
A31: 46059 | B31: Entrada | C31: Honorários fixos | D31: Transportadora Rota Sul | E31: 9225646-96.2025.8.26.0322 | F31: Honorários · parcela 2 | G31: 2000 | H31: Pix | I31: Sim | J31: =IF(A31="","",MONTH(A31)) -> 2 | K31: =IF(A31="","",YEAR(A31)) -> 2026
A32: 46059 | B32: Saída | C32: Outras saídas | F32: Despesa pessoal · Marina Ferraz · plano de saúde particular (a acertar) | G32: 480 | H32: Boleto | I32: Sim | J32: =IF(A32="","",MONTH(A32)) -> 2 | K32: =IF(A32="","",YEAR(A32)) -> 2026
A33: 46061 | B33: Saída | C33: Sistemas e assinaturas | F33: Sistemas e assinaturas | G33: 450 | H33: Cartão | I33: Sim | J33: =IF(A33="","",MONTH(A33)) -> 2 | K33: =IF(A33="","",YEAR(A33)) -> 2026
A34: 46062 | B34: Entrada | C34: Honorários fixos | D34: Roberto Almeida | E34: 5025425-10.2025.8.26.0629 | F34: Honorários · parcela 2 | G34: 3000 | H34: Pix | I34: Sim | J34: =IF(A34="","",MONTH(A34)) -> 2 | K34: =IF(A34="","",YEAR(A34)) -> 2026
A35: 46062 | B35: Saída | C35: Custas e despesas de processo | D35: Construtora Horizonte | E35: 9778116-95.2025.8.26.0106 | F35: Honorários periciais adiantados | G35: 780 | H35: Boleto | I35: Sim | J35: =IF(A35="","",MONTH(A35)) -> 2 | K35: =IF(A35="","",YEAR(A35)) -> 2026
A36: 46063 | B36: Entrada | C36: Consultoria e pareceres | D36: Clínica Bem-Estar | E36: CONS-2025-05 | F36: Fatura de horas · 3 | G36: 1980 | H36: Boleto | I36: Sim | J36: =IF(A36="","",MONTH(A36)) -> 2 | K36: =IF(A36="","",YEAR(A36)) -> 2026
A37: 46063 | B37: Entrada | C37: Honorários por hora | D37: Agência Prisma | E37: 9362688-24.2025.8.26.0436 | F37: Fatura de horas · 2 | G37: 3240 | H37: Boleto | I37: Sim | J37: =IF(A37="","",MONTH(A37)) -> 2 | K37: =IF(A37="","",YEAR(A37)) -> 2026
A38: 46063 | B38: Saída | C38: Contador | F38: Honorários do contador | G38: 600 | H38: Boleto | I38: Sim | J38: =IF(A38="","",MONTH(A38)) -> 2 | K38: =IF(A38="","",YEAR(A38)) -> 2026
A39: 46065 | B39: Entrada | C39: Honorários fixos | D39: Oficina Mecânica Central | E39: 8663770-96.2025.8.26.0481 | F39: Honorários · parcela 9 | G39: 800 | H39: Pix | I39: Sim | J39: =IF(A39="","",MONTH(A39)) -> 2 | K39: =IF(A39="","",YEAR(A39)) -> 2026
A40: 46065 | B40: Saída | C40: Telefone e internet | F40: Telefone e internet | G40: 220 | H40: Boleto | I40: Sim | J40: =IF(A40="","",MONTH(A40)) -> 2 | K40: =IF(A40="","",YEAR(A40)) -> 2026
A41: 46066 | B41: Entrada | C41: Honorários fixos | D41: Fernanda Castro | E41: 5211189-81.2025.8.26.0412 | F41: Honorários · parcela 4 (vencida) | G41: 1400 | H41: Boleto | I41: Não | J41: =IF(A41="","",MONTH(A41)) -> 2 | K41: =IF(A41="","",YEAR(A41)) -> 2026
...
