Workbook

Sheet Como usar
A1: Carteira de Clientes e Casos
A2: Kit de Gestão para Advogados · Seu Sócio Gestor · versão 1.0 (setembro de 2026)
A4: O que esta planilha faz | B4: Você cadastra os clientes e os casos com valor contratado e recebido; ela calcula o que falta receber, agrupa por área, responsável e modalidade, mostra os cinco maiores clientes e separa casos ativos de encerrados. Responde "quanto ainda vai entrar?".
A5: Passo 1 | B5: Em Config, confira o nome do escritório e as listas: áreas, fases, responsáveis e modalidades de honorário. Preencha de cima para baixo, sem pular linha.
A6: Passo 2 | B6: Em Clientes, uma linha por cliente, com tipo (PF ou PJ) e área principal. O nome daqui alimenta a lista de clientes em Casos.
A7: Passo 3 | B7: Em Casos, uma linha por caso: número do processo (ou uma referência sua, para consultivo), cliente, área, fase, responsável, modalidade, valor contratado, recebido até hoje e data de abertura. Atualize o recebido a cada pagamento.
A8: Passo 4 | B8: Em Painel, leia contratado, recebido e a receber, os totais por área e por responsável, o top 5 de clientes e ativos × encerrados. Nada para digitar lá.
A9: Rotina | B9: Sexta-feira, 10 minutos: atualizar recebidos e fases. Dia 1 do mês: copiar o Painel para o Resumo do mês (planilha 20).
A10: Com a IA | B10: Copie a tabela "Por área" e o "Top 5 clientes" e use o prompt "Resumir a carteira" da biblioteca para preparar a reunião de sócios ou a conversa com o contador.
A11: Legenda | B11: Células amarelas: você preenche. Brancas: calculadas. Não é preciso mexer em nada fora do amarelo.
A12: Proteção | B12: Fórmulas protegidas sem senha. Para editar: Revisar > Desproteger planilha (Excel) ou Dados > Proteger intervalos (Google Sheets).
A13: Requisitos | B13: Excel 2019 ou mais novo, Microsoft 365 ou Google Sheets. No celular abre nos aplicativos; para preencher, use o computador.
A14: Google Sheets | B14: Faça upload no Google Drive e abra com o Google Sheets. Fórmulas, listas, cores e gráficos funcionam.
A15: Exemplos | B15: Ferraz & Lima Advocacia é um escritório fictício. Clientes, processos, nomes e valores são inventados. Apague-os antes de começar. Datas de prazo do exemplo são relativas a hoje.
A16: Suporte | B16: suporte@seusociogestor.com.br · resposta em até 5 dias úteis · reembolso em até 7 dias pelo mesmo canal.

Sheet Painel
A1: =Config!$B$4&" · Carteira de clientes e casos · "&TEXT(DAY(Config!$B$5),"00")&"/"&TEXT(MONTH(Config!$B$5),"00")&"/"&YEAR(Config!$B$5)
A2: Nada para digitar aqui: tudo vem de Casos, Clientes e Config.
A4: Contratado (R$) | C4: Recebido (R$) | E4: A receber (R$) | G4: % recebido | I4: Casos ativos | K4: Casos encerrados
A5: =SUM(Casos!$H$5:$H$204) | C5: =SUM(Casos!$I$5:$I$204) | E5: =SUM(Casos!$H$5:$H$204)-SUM(Casos!$I$5:$I$204) | G5: =IFERROR(C5/A5,0) | I5: =COUNTIFS(Casos!$L$5:$L$204,"Ativo") | K5: =COUNTIFS(Casos!$L$5:$L$204,"Encerrado")
A7: Por área
A8: Área | B8: Casos | C8: Ativos | D8: Contratado (R$) | E8: Recebido (R$) | F8: A receber (R$) | G8: % recebido | H8: Barra
A9: =IF(Config!$A$9="","",Config!$A$9) | B9: =IF(Config!$A$9="","",COUNTIFS(Casos!$D$5:$D$204,Config!$A$9)) | C9: =IF(Config!$A$9="","",COUNTIFS(Casos!$D$5:$D$204,Config!$A$9,Casos!$L$5:$L$204,"Ativo")) | D9: =IF(Config!$A$9="","",SUMIFS(Casos!$H$5:$H$204,Casos!$D$5:$D$204,Config!$A$9)) | E9: =IF(Config!$A$9="","",SUMIFS(Casos!$I$5:$I$204,Casos!$D$5:$D$204,Config!$A$9)) | F9: =IF(Config!$A$9="","",D9-E9) | G9: =IF(OR(Config!$A$9="",D9=0),"",E9/D9) | H9: =IF(Config!$A$9="","",REPT("█",ROUND(IFERROR(D9/MAX($D$9:$D$18),0)*20,0)))
A10: =IF(Config!$A$10="","",Config!$A$10) | B10: =IF(Config!$A$10="","",COUNTIFS(Casos!$D$5:$D$204,Config!$A$10)) | C10: =IF(Config!$A$10="","",COUNTIFS(Casos!$D$5:$D$204,Config!$A$10,Casos!$L$5:$L$204,"Ativo")) | D10: =IF(Config!$A$10="","",SUMIFS(Casos!$H$5:$H$204,Casos!$D$5:$D$204,Config!$A$10)) | E10: =IF(Config!$A$10="","",SUMIFS(Casos!$I$5:$I$204,Casos!$D$5:$D$204,Config!$A$10)) | F10: =IF(Config!$A$10="","",D10-E10) | G10: =IF(OR(Config!$A$10="",D10=0),"",E10/D10) | H10: =IF(Config!$A$10="","",REPT("█",ROUND(IFERROR(D10/MAX($D$9:$D$18),0)*20,0)))
A11: =IF(Config!$A$11="","",Config!$A$11) | B11: =IF(Config!$A$11="","",COUNTIFS(Casos!$D$5:$D$204,Config!$A$11)) | C11: =IF(Config!$A$11="","",COUNTIFS(Casos!$D$5:$D$204,Config!$A$11,Casos!$L$5:$L$204,"Ativo")) | D11: =IF(Config!$A$11="","",SUMIFS(Casos!$H$5:$H$204,Casos!$D$5:$D$204,Config!$A$11)) | E11: =IF(Config!$A$11="","",SUMIFS(Casos!$I$5:$I$204,Casos!$D$5:$D$204,Config!$A$11)) | F11: =IF(Config!$A$11="","",D11-E11) | G11: =IF(OR(Config!$A$11="",D11=0),"",E11/D11) | H11: =IF(Config!$A$11="","",REPT("█",ROUND(IFERROR(D11/MAX($D$9:$D$18),0)*20,0)))
A12: =IF(Config!$A$12="","",Config!$A$12) | B12: =IF(Config!$A$12="","",COUNTIFS(Casos!$D$5:$D$204,Config!$A$12)) | C12: =IF(Config!$A$12="","",COUNTIFS(Casos!$D$5:$D$204,Config!$A$12,Casos!$L$5:$L$204,"Ativo")) | D12: =IF(Config!$A$12="","",SUMIFS(Casos!$H$5:$H$204,Casos!$D$5:$D$204,Config!$A$12)) | E12: =IF(Config!$A$12="","",SUMIFS(Casos!$I$5:$I$204,Casos!$D$5:$D$204,Config!$A$12)) | F12: =IF(Config!$A$12="","",D12-E12) | G12: =IF(OR(Config!$A$12="",D12=0),"",E12/D12) | H12: =IF(Config!$A$12="","",REPT("█",ROUND(IFERROR(D12/MAX($D$9:$D$18),0)*20,0)))
A13: =IF(Config!$A$13="","",Config!$A$13) | B13: =IF(Config!$A$13="","",COUNTIFS(Casos!$D$5:$D$204,Config!$A$13)) | C13: =IF(Config!$A$13="","",COUNTIFS(Casos!$D$5:$D$204,Config!$A$13,Casos!$L$5:$L$204,"Ativo")) | D13: =IF(Config!$A$13="","",SUMIFS(Casos!$H$5:$H$204,Casos!$D$5:$D$204,Config!$A$13)) | E13: =IF(Config!$A$13="","",SUMIFS(Casos!$I$5:$I$204,Casos!$D$5:$D$204,Config!$A$13)) | F13: =IF(Config!$A$13="","",D13-E13) | G13: =IF(OR(Config!$A$13="",D13=0),"",E13/D13) | H13: =IF(Config!$A$13="","",REPT("█",ROUND(IFERROR(D13/MAX($D$9:$D$18),0)*20,0)))
A14: =IF(Config!$A$14="","",Config!$A$14) | B14: =IF(Config!$A$14="","",COUNTIFS(Casos!$D$5:$D$204,Config!$A$14)) | C14: =IF(Config!$A$14="","",COUNTIFS(Casos!$D$5:$D$204,Config!$A$14,Casos!$L$5:$L$204,"Ativo")) | D14: =IF(Config!$A$14="","",SUMIFS(Casos!$H$5:$H$204,Casos!$D$5:$D$204,Config!$A$14)) | E14: =IF(Config!$A$14="","",SUMIFS(Casos!$I$5:$I$204,Casos!$D$5:$D$204,Config!$A$14)) | F14: =IF(Config!$A$14="","",D14-E14) | G14: =IF(OR(Config!$A$14="",D14=0),"",E14/D14) | H14: =IF(Config!$A$14="","",REPT("█",ROUND(IFERROR(D14/MAX($D$9:$D$18),0)*20,0)))
A15: =IF(Config!$A$15="","",Config!$A$15) | B15: =IF(Config!$A$15="","",COUNTIFS(Casos!$D$5:$D$204,Config!$A$15)) | C15: =IF(Config!$A$15="","",COUNTIFS(Casos!$D$5:$D$204,Config!$A$15,Casos!$L$5:$L$204,"Ativo")) | D15: =IF(Config!$A$15="","",SUMIFS(Casos!$H$5:$H$204,Casos!$D$5:$D$204,Config!$A$15)) | E15: =IF(Config!$A$15="","",SUMIFS(Casos!$I$5:$I$204,Casos!$D$5:$D$204,Config!$A$15)) | F15: =IF(Config!$A$15="","",D15-E15) | G15: =IF(OR(Config!$A$15="",D15=0),"",E15/D15) | H15: =IF(Config!$A$15="","",REPT("█",ROUND(IFERROR(D15/MAX($D$9:$D$18),0)*20,0)))
A16: =IF(Config!$A$16="","",Config!$A$16) | B16: =IF(Config!$A$16="","",COUNTIFS(Casos!$D$5:$D$204,Config!$A$16)) | C16: =IF(Config!$A$16="","",COUNTIFS(Casos!$D$5:$D$204,Config!$A$16,Casos!$L$5:$L$204,"Ativo")) | D16: =IF(Config!$A$16="","",SUMIFS(Casos!$H$5:$H$204,Casos!$D$5:$D$204,Config!$A$16)) | E16: =IF(Config!$A$16="","",SUMIFS(Casos!$I$5:$I$204,Casos!$D$5:$D$204,Config!$A$16)) | F16: =IF(Config!$A$16="","",D16-E16) | G16: =IF(OR(Config!$A$16="",D16=0),"",E16/D16) | H16: =IF(Config!$A$16="","",REPT("█",ROUND(IFERROR(D16/MAX($D$9:$D$18),0)*20,0)))
A17: =IF(Config!$A$17="","",Config!$A$17) | B17: =IF(Config!$A$17="","",COUNTIFS(Casos!$D$5:$D$204,Config!$A$17)) | C17: =IF(Config!$A$17="","",COUNTIFS(Casos!$D$5:$D$204,Config!$A$17,Casos!$L$5:$L$204,"Ativo")) | D17: =IF(Config!$A$17="","",SUMIFS(Casos!$H$5:$H$204,Casos!$D$5:$D$204,Config!$A$17)) | E17: =IF(Config!$A$17="","",SUMIFS(Casos!$I$5:$I$204,Casos!$D$5:$D$204,Config!$A$17)) | F17: =IF(Config!$A$17="","",D17-E17) | G17: =IF(OR(Config!$A$17="",D17=0),"",E17/D17) | H17: =IF(Config!$A$17="","",REPT("█",ROUND(IFERROR(D17/MAX($D$9:$D$18),0)*20,0)))
A18: =IF(Config!$A$18="","",Config!$A$18) | B18: =IF(Config!$A$18="","",COUNTIFS(Casos!$D$5:$D$204,Config!$A$18)) | C18: =IF(Config!$A$18="","",COUNTIFS(Casos!$D$5:$D$204,Config!$A$18,Casos!$L$5:$L$204,"Ativo")) | D18: =IF(Config!$A$18="","",SUMIFS(Casos!$H$5:$H$204,Casos!$D$5:$D$204,Config!$A$18)) | E18: =IF(Config!$A$18="","",SUMIFS(Casos!$I$5:$I$204,Casos!$D$5:$D$204,Config!$A$18)) | F18: =IF(Config!$A$18="","",D18-E18) | G18: =IF(OR(Config!$A$18="",D18=0),"",E18/D18) | H18: =IF(Config!$A$18="","",REPT("█",ROUND(IFERROR(D18/MAX($D$9:$D$18),0)*20,0)))
A20: Por responsável
A21: Responsável | B21: Casos | C21: Ativos | D21: Contratado (R$) | E21: Recebido (R$) | F21: A receber (R$) | G21: % recebido | H21: Barra
A22: =IF(Config!$E$9="","",Config!$E$9) | B22: =IF(Config!$E$9="","",COUNTIFS(Casos!$F$5:$F$204,Config!$E$9)) | C22: =IF(Config!$E$9="","",COUNTIFS(Casos!$F$5:$F$204,Config!$E$9,Casos!$L$5:$L$204,"Ativo")) | D22: =IF(Config!$E$9="","",SUMIFS(Casos!$H$5:$H$204,Casos!$F$5:$F$204,Config!$E$9)) | E22: =IF(Config!$E$9="","",SUMIFS(Casos!$I$5:$I$204,Casos!$F$5:$F$204,Config!$E$9)) | F22: =IF(Config!$E$9="","",D22-E22) | G22: =IF(OR(Config!$E$9="",D22=0),"",E22/D22) | H22: =IF(Config!$E$9="","",REPT("█",ROUND(IFERROR(D22/MAX($D$22:$D$31),0)*20,0)))
A23: =IF(Config!$E$10="","",Config!$E$10) | B23: =IF(Config!$E$10="","",COUNTIFS(Casos!$F$5:$F$204,Config!$E$10)) | C23: =IF(Config!$E$10="","",COUNTIFS(Casos!$F$5:$F$204,Config!$E$10,Casos!$L$5:$L$204,"Ativo")) | D23: =IF(Config!$E$10="","",SUMIFS(Casos!$H$5:$H$204,Casos!$F$5:$F$204,Config!$E$10)) | E23: =IF(Config!$E$10="","",SUMIFS(Casos!$I$5:$I$204,Casos!$F$5:$F$204,Config!$E$10)) | F23: =IF(Config!$E$10="","",D23-E23) | G23: =IF(OR(Config!$E$10="",D23=0),"",E23/D23) | H23: =IF(Config!$E$10="","",REPT("█",ROUND(IFERROR(D23/MAX($D$22:$D$31),0)*20,0)))
A24: =IF(Config!$E$11="","",Config!$E$11) | B24: =IF(Config!$E$11="","",COUNTIFS(Casos!$F$5:$F$204,Config!$E$11)) | C24: =IF(Config!$E$11="","",COUNTIFS(Casos!$F$5:$F$204,Config!$E$11,Casos!$L$5:$L$204,"Ativo")) | D24: =IF(Config!$E$11="","",SUMIFS(Casos!$H$5:$H$204,Casos!$F$5:$F$204,Config!$E$11)) | E24: =IF(Config!$E$11="","",SUMIFS(Casos!$I$5:$I$204,Casos!$F$5:$F$204,Config!$E$11)) | F24: =IF(Config!$E$11="","",D24-E24) | G24: =IF(OR(Config!$E$11="",D24=0),"",E24/D24) | H24: =IF(Config!$E$11="","",REPT("█",ROUND(IFERROR(D24/MAX($D$22:$D$31),0)*20,0)))
A25: =IF(Config!$E$12="","",Config!$E$12) | B25: =IF(Config!$E$12="","",COUNTIFS(Casos!$F$5:$F$204,Config!$E$12)) | C25: =IF(Config!$E$12="","",COUNTIFS(Casos!$F$5:$F$204,Config!$E$12,Casos!$L$5:$L$204,"Ativo")) | D25: =IF(Config!$E$12="","",SUMIFS(Casos!$H$5:$H$204,Casos!$F$5:$F$204,Config!$E$12)) | E25: =IF(Config!$E$12="","",SUMIFS(Casos!$I$5:$I$204,Casos!$F$5:$F$204,Config!$E$12)) | F25: =IF(Config!$E$12="","",D25-E25) | G25: =IF(OR(Config!$E$12="",D25=0),"",E25/D25) | H25: =IF(Config!$E$12="","",REPT("█",ROUND(IFERROR(D25/MAX($D$22:$D$31),0)*20,0)))
A26: =IF(Config!$E$13="","",Config!$E$13) | B26: =IF(Config!$E$13="","",COUNTIFS(Casos!$F$5:$F$204,Config!$E$13)) | C26: =IF(Config!$E$13="","",COUNTIFS(Casos!$F$5:$F$204,Config!$E$13,Casos!$L$5:$L$204,"Ativo")) | D26: =IF(Config!$E$13="","",SUMIFS(Casos!$H$5:$H$204,Casos!$F$5:$F$204,Config!$E$13)) | E26: =IF(Config!$E$13="","",SUMIFS(Casos!$I$5:$I$204,Casos!$F$5:$F$204,Config!$E$13)) | F26: =IF(Config!$E$13="","",D26-E26) | G26: =IF(OR(Config!$E$13="",D26=0),"",E26/D26) | H26: =IF(Config!$E$13="","",REPT("█",ROUND(IFERROR(D26/MAX($D$22:$D$31),0)*20,0)))
A27: =IF(Config!$E$14="","",Config!$E$14) | B27: =IF(Config!$E$14="","",COUNTIFS(Casos!$F$5:$F$204,Config!$E$14)) | C27: =IF(Config!$E$14="","",COUNTIFS(Casos!$F$5:$F$204,Config!$E$14,Casos!$L$5:$L$204,"Ativo")) | D27: =IF(Config!$E$14="","",SUMIFS(Casos!$H$5:$H$204,Casos!$F$5:$F$204,Config!$E$14)) | E27: =IF(Config!$E$14="","",SUMIFS(Casos!$I$5:$I$204,Casos!$F$5:$F$204,Config!$E$14)) | F27: =IF(Config!$E$14="","",D27-E27) | G27: =IF(OR(Config!$E$14="",D27=0),"",E27/D27) | H27: =IF(Config!$E$14="","",REPT("█",ROUND(IFERROR(D27/MAX($D$22:$D$31),0)*20,0)))
A28: =IF(Config!$E$15="","",Config!$E$15) | B28: =IF(Config!$E$15="","",COUNTIFS(Casos!$F$5:$F$204,Config!$E$15)) | C28: =IF(Config!$E$15="","",COUNTIFS(Casos!$F$5:$F$204,Config!$E$15,Casos!$L$5:$L$204,"Ativo")) | D28: =IF(Config!$E$15="","",SUMIFS(Casos!$H$5:$H$204,Casos!$F$5:$F$204,Config!$E$15)) | E28: =IF(Config!$E$15="","",SUMIFS(Casos!$I$5:$I$204,Casos!$F$5:$F$204,Config!$E$15)) | F28: =IF(Config!$E$15="","",D28-E28) | G28: =IF(OR(Config!$E$15="",D28=0),"",E28/D28) | H28: =IF(Config!$E$15="","",REPT("█",ROUND(IFERROR(D28/MAX($D$22:$D$31),0)*20,0)))
A29: =IF(Config!$E$16="","",Config!$E$16) | B29: =IF(Config!$E$16="","",COUNTIFS(Casos!$F$5:$F$204,Config!$E$16)) | C29: =IF(Config!$E$16="","",COUNTIFS(Casos!$F$5:$F$204,Config!$E$16,Casos!$L$5:$L$204,"Ativo")) | D29: =IF(Config!$E$16="","",SUMIFS(Casos!$H$5:$H$204,Casos!$F$5:$F$204,Config!$E$16)) | E29: =IF(Config!$E$16="","",SUMIFS(Casos!$I$5:$I$204,Casos!$F$5:$F$204,Config!$E$16)) | F29: =IF(Config!$E$16="","",D29-E29) | G29: =IF(OR(Config!$E$16="",D29=0),"",E29/D29) | H29: =IF(Config!$E$16="","",REPT("█",ROUND(IFERROR(D29/MAX($D$22:$D$31),0)*20,0)))
A30: =IF(Config!$E$17="","",Config!$E$17) | B30: =IF(Config!$E$17="","",COUNTIFS(Casos!$F$5:$F$204,Config!$E$17)) | C30: =IF(Config!$E$17="","",COUNTIFS(Casos!$F$5:$F$204,Config!$E$17,Casos!$L$5:$L$204,"Ativo")) | D30: =IF(Config!$E$17="","",SUMIFS(Casos!$H$5:$H$204,Casos!$F$5:$F$204,Config!$E$17)) | E30: =IF(Config!$E$17="","",SUMIFS(Casos!$I$5:$I$204,Casos!$F$5:$F$204,Config!$E$17)) | F30: =IF(Config!$E$17="","",D30-E30) | G30: =IF(OR(Config!$E$17="",D30=0),"",E30/D30) | H30: =IF(Config!$E$17="","",REPT("█",ROUND(IFERROR(D30/MAX($D$22:$D$31),0)*20,0)))
A31: =IF(Config!$E$18="","",Config!$E$18) | B31: =IF(Config!$E$18="","",COUNTIFS(Casos!$F$5:$F$204,Config!$E$18)) | C31: =IF(Config!$E$18="","",COUNTIFS(Casos!$F$5:$F$204,Config!$E$18,Casos!$L$5:$L$204,"Ativo")) | D31: =IF(Config!$E$18="","",SUMIFS(Casos!$H$5:$H$204,Casos!$F$5:$F$204,Config!$E$18)) | E31: =IF(Config!$E$18="","",SUMIFS(Casos!$I$5:$I$204,Casos!$F$5:$F$204,Config!$E$18)) | F31: =IF(Config!$E$18="","",D31-E31) | G31: =IF(OR(Config!$E$18="",D31=0),"",E31/D31) | H31: =IF(Config!$E$18="","",REPT("█",ROUND(IFERROR(D31/MAX($D$22:$D$31),0)*20,0)))
A33: Por modalidade de honorário
A34: Modalidade de honorário | B34: Casos | C34: Ativos | D34: Contratado (R$) | E34: Recebido (R$) | F34: A receber (R$) | G34: % recebido | H34: Barra
A35: =IF(Config!$G$9="","",Config!$G$9) | B35: =IF(Config!$G$9="","",COUNTIFS(Casos!$G$5:$G$204,Config!$G$9)) | C35: =IF(Config!$G$9="","",COUNTIFS(Casos!$G$5:$G$204,Config!$G$9,Casos!$L$5:$L$204,"Ativo")) | D35: =IF(Config!$G$9="","",SUMIFS(Casos!$H$5:$H$204,Casos!$G$5:$G$204,Config!$G$9)) | E35: =IF(Config!$G$9="","",SUMIFS(Casos!$I$5:$I$204,Casos!$G$5:$G$204,Config!$G$9)) | F35: =IF(Config!$G$9="","",D35-E35) | G35: =IF(OR(Config!$G$9="",D35=0),"",E35/D35) | H35: =IF(Config!$G$9="","",REPT("█",ROUND(IFERROR(D35/MAX($D$35:$D$44),0)*20,0)))
A36: =IF(Config!$G$10="","",Config!$G$10) | B36: =IF(Config!$G$10="","",COUNTIFS(Casos!$G$5:$G$204,Config!$G$10)) | C36: =IF(Config!$G$10="","",COUNTIFS(Casos!$G$5:$G$204,Config!$G$10,Casos!$L$5:$L$204,"Ativo")) | D36: =IF(Config!$G$10="","",SUMIFS(Casos!$H$5:$H$204,Casos!$G$5:$G$204,Config!$G$10)) | E36: =IF(Config!$G$10="","",SUMIFS(Casos!$I$5:$I$204,Casos!$G$5:$G$204,Config!$G$10)) | F36: =IF(Config!$G$10="","",D36-E36) | G36: =IF(OR(Config!$G$10="",D36=0),"",E36/D36) | H36: =IF(Config!$G$10="","",REPT("█",ROUND(IFERROR(D36/MAX($D$35:$D$44),0)*20,0)))
A37: =IF(Config!$G$11="","",Config!$G$11) | B37: =IF(Config!$G$11="","",COUNTIFS(Casos!$G$5:$G$204,Config!$G$11)) | C37: =IF(Config!$G$11="","",COUNTIFS(Casos!$G$5:$G$204,Config!$G$11,Casos!$L$5:$L$204,"Ativo")) | D37: =IF(Config!$G$11="","",SUMIFS(Casos!$H$5:$H$204,Casos!$G$5:$G$204,Config!$G$11)) | E37: =IF(Config!$G$11="","",SUMIFS(Casos!$I$5:$I$204,Casos!$G$5:$G$204,Config!$G$11)) | F37: =IF(Config!$G$11="","",D37-E37) | G37: =IF(OR(Config!$G$11="",D37=0),"",E37/D37) | H37: =IF(Config!$G$11="","",REPT("█",ROUND(IFERROR(D37/MAX($D$35:$D$44),0)*20,0)))
A38: =IF(Config!$G$12="","",Config!$G$12) | B38: =IF(Config!$G$12="","",COUNTIFS(Casos!$G$5:$G$204,Config!$G$12)) | C38: =IF(Config!$G$12="","",COUNTIFS(Casos!$G$5:$G$204,Config!$G$12,Casos!$L$5:$L$204,"Ativo")) | D38: =IF(Config!$G$12="","",SUMIFS(Casos!$H$5:$H$204,Casos!$G$5:$G$204,Config!$G$12)) | E38: =IF(Config!$G$12="","",SUMIFS(Casos!$I$5:$I$204,Casos!$G$5:$G$204,Config!$G$12)) | F38: =IF(Config!$G$12="","",D38-E38) | G38: =IF(OR(Config!$G$12="",D38=0),"",E38/D38) | H38: =IF(Config!$G$12="","",REPT("█",ROUND(IFERROR(D38/MAX($D$35:$D$44),0)*20,0)))
A39: =IF(Config!$G$13="","",Config!$G$13) | B39: =IF(Config!$G$13="","",COUNTIFS(Casos!$G$5:$G$204,Config!$G$13)) | C39: =IF(Config!$G$13="","",COUNTIFS(Casos!$G$5:$G$204,Config!$G$13,Casos!$L$5:$L$204,"Ativo")) | D39: =IF(Config!$G$13="","",SUMIFS(Casos!$H$5:$H$204,Casos!$G$5:$G$204,Config!$G$13)) | E39: =IF(Config!$G$13="","",SUMIFS(Casos!$I$5:$I$204,Casos!$G$5:$G$204,Config!$G$13)) | F39: =IF(Config!$G$13="","",D39-E39) | G39: =IF(OR(Config!$G$13="",D39=0),"",E39/D39) | H39: =IF(Config!$G$13="","",REPT("█",ROUND(IFERROR(D39/MAX($D$35:$D$44),0)*20,0)))
A40: =IF(Config!$G$14="","",Config!$G$14) | B40: =IF(Config!$G$14="","",COUNTIFS(Casos!$G$5:$G$204,Config!$G$14)) | C40: =IF(Config!$G$14="","",COUNTIFS(Casos!$G$5:$G$204,Config!$G$14,Casos!$L$5:$L$204,"Ativo")) | D40: =IF(Config!$G$14="","",SUMIFS(Casos!$H$5:$H$204,Casos!$G$5:$G$204,Config!$G$14)) | E40: =IF(Config!$G$14="","",SUMIFS(Casos!$I$5:$I$204,Casos!$G$5:$G$204,Config!$G$14)) | F40: =IF(Config!$G$14="","",D40-E40) | G40: =IF(OR(Config!$G$14="",D40=0),"",E40/D40) | H40: =IF(Config!$G$14="","",REPT("█",ROUND(IFERROR(D40/MAX($D$35:$D$44),0)*20,0)))
A41: =IF(Config!$G$15="","",Config!$G$15) | B41: =IF(Config!$G$15="","",COUNTIFS(Casos!$G$5:$G$204,Config!$G$15)) | C41: =IF(Config!$G$15="","",COUNTIFS(Casos!$G$5:$G$204,Config!$G$15,Casos!$L$5:$L$204,"Ativo")) | D41: =IF(Config!$G$15="","",SUMIFS(Casos!$H$5:$H$204,Casos!$G$5:$G$204,Config!$G$15)) | E41: =IF(Config!$G$15="","",SUMIFS(Casos!$I$5:$I$204,Casos!$G$5:$G$204,Config!$G$15)) | F41: =IF(Config!$G$15="","",D41-E41) | G41: =IF(OR(Config!$G$15="",D41=0),"",E41/D41) | H41: =IF(Config!$G$15="","",REPT("█",ROUND(IFERROR(D41/MAX($D$35:$D$44),0)*20,0)))
A42: =IF(Config!$G$16="","",Config!$G$16) | B42: =IF(Config!$G$16="","",COUNTIFS(Casos!$G$5:$G$204,Config!$G$16)) | C42: =IF(Config!$G$16="","",COUNTIFS(Casos!$G$5:$G$204,Config!$G$16,Casos!$L$5:$L$204,"Ativo")) | D42: =IF(Config!$G$16="","",SUMIFS(Casos!$H$5:$H$204,Casos!$G$5:$G$204,Config!$G$16)) | E42: =IF(Config!$G$16="","",SUMIFS(Casos!$I$5:$I$204,Casos!$G$5:$G$204,Config!$G$16)) | F42: =IF(Config!$G$16="","",D42-E42) | G42: =IF(OR(Config!$G$16="",D42=0),"",E42/D42) | H42: =IF(Config!$G$16="","",REPT("█",ROUND(IFERROR(D42/MAX($D$35:$D$44),0)*20,0)))
A43: =IF(Config!$G$17="","",Config!$G$17) | B43: =IF(Config!$G$17="","",COUNTIFS(Casos!$G$5:$G$204,Config!$G$17)) | C43: =IF(Config!$G$17="","",COUNTIFS(Casos!$G$5:$G$204,Config!$G$17,Casos!$L$5:$L$204,"Ativo")) | D43: =IF(Config!$G$17="","",SUMIFS(Casos!$H$5:$H$204,Casos!$G$5:$G$204,Config!$G$17)) | E43: =IF(Config!$G$17="","",SUMIFS(Casos!$I$5:$I$204,Casos!$G$5:$G$204,Config!$G$17)) | F43: =IF(Config!$G$17="","",D43-E43) | G43: =IF(OR(Config!$G$17="",D43=0),"",E43/D43) | H43: =IF(Config!$G$17="","",REPT("█",ROUND(IFERROR(D43/MAX($D$35:$D$44),0)*20,0)))
A44: =IF(Config!$G$18="","",Config!$G$18) | B44: =IF(Config!$G$18="","",COUNTIFS(Casos!$G$5:$G$204,Config!$G$18)) | C44: =IF(Config!$G$18="","",COUNTIFS(Casos!$G$5:$G$204,Config!$G$18,Casos!$L$5:$L$204,"Ativo")) | D44: =IF(Config!$G$18="","",SUMIFS(Casos!$H$5:$H$204,Casos!$G$5:$G$204,Config!$G$18)) | E44: =IF(Config!$G$18="","",SUMIFS(Casos!$I$5:$I$204,Casos!$G$5:$G$204,Config!$G$18)) | F44: =IF(Config!$G$18="","",D44-E44) | G44: =IF(OR(Config!$G$18="",D44=0),"",E44/D44) | H44: =IF(Config!$G$18="","",REPT("█",ROUND(IFERROR(D44/MAX($D$35:$D$44),0)*20,0)))
...

Sheet Config
A1: Configurações
A2: Células amarelas: você preenche. As listas alimentam os campos de escolha em Casos e Clientes.
A4: Escritório | B4: Ferraz & Lima Advocacia (exemplo fictício)
A5: Data de referência (hoje) | B5: =TODAY()
A6: Fase que encerra o caso | B6: Encerrado
A8: Áreas de atuação | C8: Fases do caso | E8: Responsáveis | G8: Modalidades de honorário
A9: Cível | C9: Consultivo | E9: Marina Ferraz | G9: Fixo
A10: Trabalhista | C10: Inicial | E10: Rafael Lima | G10: Hora
A11: Previdenciário | C11: Instrução | E11: Júlia Prado | G11: Êxito
A12: Empresarial | C12: Sentença | G12: Misto
A13: Família | C13: Recurso
C14: Execução
C15: Acordo
C16: Encerrado
A20: Preencha cada lista de cima para baixo, sem pular linha: as listas suspensas das outras abas param na primeira célula vazia. Até 10 itens por lista.
A21: Fase que encerra o caso: os casos nessa fase contam como Encerrados no Painel; todos os outros contam como Ativos.

Sheet Clientes
A1: Clientes
A2: Uma linha por cliente (pessoa física ou jurídica). Casos, valores e último caso aberto vêm de Casos.
A4: Cliente | B4: Tipo | C4: Área principal | D4: Casos | E4: Casos ativos | F4: Contratado (R$) | G4: Recebido (R$) | H4: A receber (R$) | I4: % recebido | J4: Último caso aberto
A5: Padaria do Sol Ltda | B5: PJ | C5: Empresarial | D5: =IF(A5="","",COUNTIFS(Casos!$B$5:$B$204,A5)) | E5: =IF(A5="","",COUNTIFS(Casos!$B$5:$B$204,A5,Casos!$L$5:$L$204,"Ativo")) | F5: =IF(A5="","",SUMIFS(Casos!$H$5:$H$204,Casos!$B$5:$B$204,A5)) | G5: =IF(A5="","",SUMIFS(Casos!$I$5:$I$204,Casos!$B$5:$B$204,A5)) | H5: =IF(A5="","",F5-G5) | I5: =IF(OR(A5="",F5=0),"",G5/F5) | J5: =IF(A5="","",IF(_xlfn.MAXIFS(Casos!$K$5:$K$204,Casos!$B$5:$B$204,A5)=0,"",_xlfn.MAXIFS(Casos!$K$5:$K$204,Casos!$B$5:$B$204,A5))) | K5: =IF(OR(A5="",F5=0),0,F5-ROW()/100000)
A6: Ana Beatriz Moreira | B6: PF | C6: Trabalhista | D6: =IF(A6="","",COUNTIFS(Casos!$B$5:$B$204,A6)) | E6: =IF(A6="","",COUNTIFS(Casos!$B$5:$B$204,A6,Casos!$L$5:$L$204,"Ativo")) | F6: =IF(A6="","",SUMIFS(Casos!$H$5:$H$204,Casos!$B$5:$B$204,A6)) | G6: =IF(A6="","",SUMIFS(Casos!$I$5:$I$204,Casos!$B$5:$B$204,A6)) | H6: =IF(A6="","",F6-G6) | I6: =IF(OR(A6="",F6=0),"",G6/F6) | J6: =IF(A6="","",IF(_xlfn.MAXIFS(Casos!$K$5:$K$204,Casos!$B$5:$B$204,A6)=0,"",_xlfn.MAXIFS(Casos!$K$5:$K$204,Casos!$B$5:$B$204,A6))) | K6: =IF(OR(A6="",F6=0),0,F6-ROW()/100000)
A7: Construtora Horizonte | B7: PJ | C7: Cível | D7: =IF(A7="","",COUNTIFS(Casos!$B$5:$B$204,A7)) | E7: =IF(A7="","",COUNTIFS(Casos!$B$5:$B$204,A7,Casos!$L$5:$L$204,"Ativo")) | F7: =IF(A7="","",SUMIFS(Casos!$H$5:$H$204,Casos!$B$5:$B$204,A7)) | G7: =IF(A7="","",SUMIFS(Casos!$I$5:$I$204,Casos!$B$5:$B$204,A7)) | H7: =IF(A7="","",F7-G7) | I7: =IF(OR(A7="",F7=0),"",G7/F7) | J7: =IF(A7="","",IF(_xlfn.MAXIFS(Casos!$K$5:$K$204,Casos!$B$5:$B$204,A7)=0,"",_xlfn.MAXIFS(Casos!$K$5:$K$204,Casos!$B$5:$B$204,A7))) | K7: =IF(OR(A7="",F7=0),0,F7-ROW()/100000)
A8: Carlos Eduardo Nunes | B8: PF | C8: Previdenciário | D8: =IF(A8="","",COUNTIFS(Casos!$B$5:$B$204,A8)) | E8: =IF(A8="","",COUNTIFS(Casos!$B$5:$B$204,A8,Casos!$L$5:$L$204,"Ativo")) | F8: =IF(A8="","",SUMIFS(Casos!$H$5:$H$204,Casos!$B$5:$B$204,A8)) | G8: =IF(A8="","",SUMIFS(Casos!$I$5:$I$204,Casos!$B$5:$B$204,A8)) | H8: =IF(A8="","",F8-G8) | I8: =IF(OR(A8="",F8=0),"",G8/F8) | J8: =IF(A8="","",IF(_xlfn.MAXIFS(Casos!$K$5:$K$204,Casos!$B$5:$B$204,A8)=0,"",_xlfn.MAXIFS(Casos!$K$5:$K$204,Casos!$B$5:$B$204,A8))) | K8: =IF(OR(A8="",F8=0),0,F8-ROW()/100000)
A9: Loja Verde Comércio | B9: PJ | C9: Empresarial | D9: =IF(A9="","",COUNTIFS(Casos!$B$5:$B$204,A9)) | E9: =IF(A9="","",COUNTIFS(Casos!$B$5:$B$204,A9,Casos!$L$5:$L$204,"Ativo")) | F9: =IF(A9="","",SUMIFS(Casos!$H$5:$H$204,Casos!$B$5:$B$204,A9)) | G9: =IF(A9="","",SUMIFS(Casos!$I$5:$I$204,Casos!$B$5:$B$204,A9)) | H9: =IF(A9="","",F9-G9) | I9: =IF(OR(A9="",F9=0),"",G9/F9) | J9: =IF(A9="","",IF(_xlfn.MAXIFS(Casos!$K$5:$K$204,Casos!$B$5:$B$204,A9)=0,"",_xlfn.MAXIFS(Casos!$K$5:$K$204,Casos!$B$5:$B$204,A9))) | K9: =IF(OR(A9="",F9=0),0,F9-ROW()/100000)
A10: Fernanda Castro | B10: PF | C10: Família | D10: =IF(A10="","",COUNTIFS(Casos!$B$5:$B$204,A10)) | E10: =IF(A10="","",COUNTIFS(Casos!$B$5:$B$204,A10,Casos!$L$5:$L$204,"Ativo")) | F10: =IF(A10="","",SUMIFS(Casos!$H$5:$H$204,Casos!$B$5:$B$204,A10)) | G10: =IF(A10="","",SUMIFS(Casos!$I$5:$I$204,Casos!$B$5:$B$204,A10)) | H10: =IF(A10="","",F10-G10) | I10: =IF(OR(A10="",F10=0),"",G10/F10) | J10: =IF(A10="","",IF(_xlfn.MAXIFS(Casos!$K$5:$K$204,Casos!$B$5:$B$204,A10)=0,"",_xlfn.MAXIFS(Casos!$K$5:$K$204,Casos!$B$5:$B$204,A10))) | K10: =IF(OR(A10="",F10=0),0,F10-ROW()/100000)
A11: Bistrô 42 | B11: PJ | C11: Trabalhista | D11: =IF(A11="","",COUNTIFS(Casos!$B$5:$B$204,A11)) | E11: =IF(A11="","",COUNTIFS(Casos!$B$5:$B$204,A11,Casos!$L$5:$L$204,"Ativo")) | F11: =IF(A11="","",SUMIFS(Casos!$H$5:$H$204,Casos!$B$5:$B$204,A11)) | G11: =IF(A11="","",SUMIFS(Casos!$I$5:$I$204,Casos!$B$5:$B$204,A11)) | H11: =IF(A11="","",F11-G11) | I11: =IF(OR(A11="",F11=0),"",G11/F11) | J11: =IF(A11="","",IF(_xlfn.MAXIFS(Casos!$K$5:$K$204,Casos!$B$5:$B$204,A11)=0,"",_xlfn.MAXIFS(Casos!$K$5:$K$204,Casos!$B$5:$B$204,A11))) | K11: =IF(OR(A11="",F11=0),0,F11-ROW()/100000)
A12: Roberto Almeida | B12: PF | C12: Cível | D12: =IF(A12="","",COUNTIFS(Casos!$B$5:$B$204,A12)) | E12: =IF(A12="","",COUNTIFS(Casos!$B$5:$B$204,A12,Casos!$L$5:$L$204,"Ativo")) | F12: =IF(A12="","",SUMIFS(Casos!$H$5:$H$204,Casos!$B$5:$B$204,A12)) | G12: =IF(A12="","",SUMIFS(Casos!$I$5:$I$204,Casos!$B$5:$B$204,A12)) | H12: =IF(A12="","",F12-G12) | I12: =IF(OR(A12="",F12=0),"",G12/F12) | J12: =IF(A12="","",IF(_xlfn.MAXIFS(Casos!$K$5:$K$204,Casos!$B$5:$B$204,A12)=0,"",_xlfn.MAXIFS(Casos!$K$5:$K$204,Casos!$B$5:$B$204,A12))) | K12: =IF(OR(A12="",F12=0),0,F12-ROW()/100000)
A13: Clínica Bem-Estar | B13: PJ | C13: Empresarial | D13: =IF(A13="","",COUNTIFS(Casos!$B$5:$B$204,A13)) | E13: =IF(A13="","",COUNTIFS(Casos!$B$5:$B$204,A13,Casos!$L$5:$L$204,"Ativo")) | F13: =IF(A13="","",SUMIFS(Casos!$H$5:$H$204,Casos!$B$5:$B$204,A13)) | G13: =IF(A13="","",SUMIFS(Casos!$I$5:$I$204,Casos!$B$5:$B$204,A13)) | H13: =IF(A13="","",F13-G13) | I13: =IF(OR(A13="",F13=0),"",G13/F13) | J13: =IF(A13="","",IF(_xlfn.MAXIFS(Casos!$K$5:$K$204,Casos!$B$5:$B$204,A13)=0,"",_xlfn.MAXIFS(Casos!$K$5:$K$204,Casos!$B$5:$B$204,A13))) | K13: =IF(OR(A13="",F13=0),0,F13-ROW()/100000)
A14: Marcos Vinícius Teles | B14: PF | C14: Previdenciário | D14: =IF(A14="","",COUNTIFS(Casos!$B$5:$B$204,A14)) | E14: =IF(A14="","",COUNTIFS(Casos!$B$5:$B$204,A14,Casos!$L$5:$L$204,"Ativo")) | F14: =IF(A14="","",SUMIFS(Casos!$H$5:$H$204,Casos!$B$5:$B$204,A14)) | G14: =IF(A14="","",SUMIFS(Casos!$I$5:$I$204,Casos!$B$5:$B$204,A14)) | H14: =IF(A14="","",F14-G14) | I14: =IF(OR(A14="",F14=0),"",G14/F14) | J14: =IF(A14="","",IF(_xlfn.MAXIFS(Casos!$K$5:$K$204,Casos!$B$5:$B$204,A14)=0,"",_xlfn.MAXIFS(Casos!$K$5:$K$204,Casos!$B$5:$B$204,A14))) | K14: =IF(OR(A14="",F14=0),0,F14-ROW()/100000)
A15: Transportadora Rota Sul | B15: PJ | C15: Trabalhista | D15: =IF(A15="","",COUNTIFS(Casos!$B$5:$B$204,A15)) | E15: =IF(A15="","",COUNTIFS(Casos!$B$5:$B$204,A15,Casos!$L$5:$L$204,"Ativo")) | F15: =IF(A15="","",SUMIFS(Casos!$H$5:$H$204,Casos!$B$5:$B$204,A15)) | G15: =IF(A15="","",SUMIFS(Casos!$I$5:$I$204,Casos!$B$5:$B$204,A15)) | H15: =IF(A15="","",F15-G15) | I15: =IF(OR(A15="",F15=0),"",G15/F15) | J15: =IF(A15="","",IF(_xlfn.MAXIFS(Casos!$K$5:$K$204,Casos!$B$5:$B$204,A15)=0,"",_xlfn.MAXIFS(Casos!$K$5:$K$204,Casos!$B$5:$B$204,A15))) | K15: =IF(OR(A15="",F15=0),0,F15-ROW()/100000)
A16: Patrícia Gomes | B16: PF | C16: Família | D16: =IF(A16="","",COUNTIFS(Casos!$B$5:$B$204,A16)) | E16: =IF(A16="","",COUNTIFS(Casos!$B$5:$B$204,A16,Casos!$L$5:$L$204,"Ativo")) | F16: =IF(A16="","",SUMIFS(Casos!$H$5:$H$204,Casos!$B$5:$B$204,A16)) | G16: =IF(A16="","",SUMIFS(Casos!$I$5:$I$204,Casos!$B$5:$B$204,A16)) | H16: =IF(A16="","",F16-G16) | I16: =IF(OR(A16="",F16=0),"",G16/F16) | J16: =IF(A16="","",IF(_xlfn.MAXIFS(Casos!$K$5:$K$204,Casos!$B$5:$B$204,A16)=0,"",_xlfn.MAXIFS(Casos!$K$5:$K$204,Casos!$B$5:$B$204,A16))) | K16: =IF(OR(A16="",F16=0),0,F16-ROW()/100000)
... A22: Helena Duarte | B22: PF | C22: Trabalhista | D22: =IF(A22="","",COUNTIFS(Casos!$B$5:$B$204,A22)) | E22: =IF(A22="","",COUNTIFS(Casos!$B$5:$B$204,A22,Casos!$L$5:$L$204,"Ativo")) | F22: =IF(A22="","",SUMIFS(Casos!$H$5:$H$204,Casos!$B$5:$B$204,A22)) | G22: =IF(A22="","",SUMIFS(Casos!$I$5:$I$204,Casos!$B$5:$B$204,A22)) | H22: =IF(A22="","",F22-G22) | I22: =IF(OR(A22="",F22=0),"",G22/F22) | J22: =IF(A22="","",IF(_xlfn.MAXIFS(Casos!$K$5:$K$204,Casos!$B$5:$B$204,A22)=0,"",_xlfn.MAXIFS(Casos!$K$5:$K$204,Casos!$B$5:$B$204,A22))) | K22: =IF(OR(A22="",F22=0),0,F22-ROW()/100000)
D23: =IF(A23="","",COUNTIFS(Casos!$B$5:$B$204,A23)) | E23: =IF(A23="","",COUNTIFS(Casos!$B$5:$B$204,A23,Casos!$L$5:$L$204,"Ativo")) | F23: =IF(A23="","",SUMIFS(Casos!$H$5:$H$204,Casos!$B$5:$B$204,A23)) | G23: =IF(A23="","",SUMIFS(Casos!$I$5:$I$204,Casos!$B$5:$B$204,A23)) | H23: =IF(A23="","",F23-G23) | I23: =IF(OR(A23="",F23=0),"",G23/F23) | J23: =IF(A23="","",IF(_xlfn.MAXIFS(Casos!$K$5:$K$204,Casos!$B$5:$B$204,A23)=0,"",_xlfn.MAXIFS(Casos!$K$5:$K$204,Casos!$B$5:$B$204,A23))) | K23: =IF(OR(A23="",F23=0),0,F23-ROW()/100000)
D24: =IF(A24="","",COUNTIFS(Casos!$B$5:$B$204,A24)) | E24: =IF(A24="","",COUNTIFS(Casos!$B$5:$B$204,A24,Casos!$L$5:$L$204,"Ativo")) | F24: =IF(A24="","",SUMIFS(Casos!$H$5:$H$204,Casos!$B$5:$B$204,A24)) | G24: =IF(A24="","",SUMIFS(Casos!$I$5:$I$204,Casos!$B$5:$B$204,A24)) | H24: =IF(A24="","",F24-G24) | I24: =IF(OR(A24="",F24=0),"",G24/F24) | J24: =IF(A24="","",IF(_xlfn.MAXIFS(Casos!$K$5:$K$204,Casos!$B$5:$B$204,A24)=0,"",_xlfn.MAXIFS(Casos!$K$5:$K$204,Casos!$B$5:$B$204,A24))) | K24: =IF(OR(A24="",F24=0),0,F24-ROW()/100000)
D25: =IF(A25="","",COUNTIFS(Casos!$B$5:$B$204,A25)) | E25: =IF(A25="","",COUNTIFS(Casos!$B$5:$B$204,A25,Casos!$L$5:$L$204,"Ativo")) | F25: =IF(A25="","",SUMIFS(Casos!$H$5:$H$204,Casos!$B$5:$B$204,A25)) | G25: =IF(A25="","",SUMIFS(Casos!$I$5:$I$204,Casos!$B$5:$B$204,A25)) | H25: =IF(A25="","",F25-G25) | I25: =IF(OR(A25="",F25=0),"",G25/F25) | J25: =IF(A25="","",IF(_xlfn.MAXIFS(Casos!$K$5:$K$204,Casos!$B$5:$B$204,A25)=0,"",_xlfn.MAXIFS(Casos!$K$5:$K$204,Casos!$B$5:$B$204,A25))) | K25: =IF(OR(A25="",F25=0),0,F25-ROW()/100000)
D26: =IF(A26="","",COUNTIFS(Casos!$B$5:$B$204,A26)) | E26: =IF(A26="","",COUNTIFS(Casos!$B$5:$B$204,A26,Casos!$L$5:$L$204,"Ativo")) | F26: =IF(A26="","",SUMIFS(Casos!$H$5:$H$204,Casos!$B$5:$B$204,A26)) | G26: =IF(A26="","",SUMIFS(Casos!$I$5:$I$204,Casos!$B$5:$B$204,A26)) | H26: =IF(A26="","",F26-G26) | I26: =IF(OR(A26="",F26=0),"",G26/F26) | J26: =IF(A26="","",IF(_xlfn.MAXIFS(Casos!$K$5:$K$204,Casos!$B$5:$B$204,A26)=0,"",_xlfn.MAXIFS(Casos!$K$5:$K$204,Casos!$B$5:$B$204,A26))) | K26: =IF(OR(A26="",F26=0),0,F26-ROW()/100000)
D27: =IF(A27="","",COUNTIFS(Casos!$B$5:$B$204,A27)) | E27: =IF(A27="","",COUNTIFS(Casos!$B$5:$B$204,A27,Casos!$L$5:$L$204,"Ativo")) | F27: =IF(A27="","",SUMIFS(Casos!$H$5:$H$204,Casos!$B$5:$B$204,A27)) | G27: =IF(A27="","",SUMIFS(Casos!$I$5:$I$204,Casos!$B$5:$B$204,A27)) | H27: =IF(A27="","",F27-G27) | I27: =IF(OR(A27="",F27=0),"",G27/F27) | J27: =IF(A27="","",IF(_xlfn.MAXIFS(Casos!$K$5:$K$204,Casos!$B$5:$B$204,A27)=0,"",_xlfn.MAXIFS(Casos!$K$5:$K$204,Casos!$B$5:$B$204,A27))) | K27: =IF(OR(A27="",F27=0),0,F27-ROW()/100000)
D28: =IF(A28="","",COUNTIFS(Casos!$B$5:$B$204,A28)) | E28: =IF(A28="","",COUNTIFS(Casos!$B$5:$B$204,A28,Casos!$L$5:$L$204,"Ativo")) | F28: =IF(A28="","",SUMIFS(Casos!$H$5:$H$204,Casos!$B$5:$B$204,A28)) | G28: =IF(A28="","",SUMIFS(Casos!$I$5:$I$204,Casos!$B$5:$B$204,A28)) | H28: =IF(A28="","",F28-G28) | I28: =IF(OR(A28="",F28=0),"",G28/F28) | J28: =IF(A28="","",IF(_xlfn.MAXIFS(Casos!$K$5:$K$204,Casos!$B$5:$B$204,A28)=0,"",_xlfn.MAXIFS(Casos!$K$5:$K$204,Casos!$B$5:$B$204,A28))) | K28: =IF(OR(A28="",F28=0),0,F28-ROW()/100000)
D29: =IF(A29="","",COUNTIFS(Casos!$B$5:$B$204,A29)) | E29: =IF(A29="","",COUNTIFS(Casos!$B$5:$B$204,A29,Casos!$L$5:$L$204,"Ativo")) | F29: =IF(A29="","",SUMIFS(Casos!$H$5:$H$204,Casos!$B$5:$B$204,A29)) | G29: =IF(A29="","",SUMIFS(Casos!$I$5:$I$204,Casos!$B$5:$B$204,A29)) | H29: =IF(A29="","",F29-G29) | I29: =IF(OR(A29="",F29=0),"",G29/F29) | J29: =IF(A29="","",IF(_xlfn.MAXIFS(Casos!$K$5:$K$204,Casos!$B$5:$B$204,A29)=0,"",_xlfn.MAXIFS(Casos!$K$5:$K$204,Casos!$B$5:$B$204,A29))) | K29: =IF(OR(A29="",F29=0),0,F29-ROW()/100000)
D30: =IF(A30="","",COUNTIFS(Casos!$B$5:$B$204,A30)) | E30: =IF(A30="","",COUNTIFS(Casos!$B$5:$B$204,A30,Casos!$L$5:$L$204,"Ativo")) | F30: =IF(A30="","",SUMIFS(Casos!$H$5:$H$204,Casos!$B$5:$B$204,A30)) | G30: =IF(A30="","",SUMIFS(Casos!$I$5:$I$204,Casos!$B$5:$B$204,A30)) | H30: =IF(A30="","",F30-G30) | I30: =IF(OR(A30="",F30=0),"",G30/F30) | J30: =IF(A30="","",IF(_xlfn.MAXIFS(Casos!$K$5:$K$204,Casos!$B$5:$B$204,A30)=0,"",_xlfn.MAXIFS(Casos!$K$5:$K$204,Casos!$B$5:$B$204,A30))) | K30: =IF(OR(A30="",F30=0),0,F30-ROW()/100000)
D31: =IF(A31="","",COUNTIFS(Casos!$B$5:$B$204,A31)) | E31: =IF(A31="","",COUNTIFS(Casos!$B$5:$B$204,A31,Casos!$L$5:$L$204,"Ativo")) | F31: =IF(A31="","",SUMIFS(Casos!$H$5:$H$204,Casos!$B$5:$B$204,A31)) | G31: =IF(A31="","",SUMIFS(Casos!$I$5:$I$204,Casos!$B$5:$B$204,A31)) | H31: =IF(A31="","",F31-G31) | I31: =IF(OR(A31="",F31=0),"",G31/F31) | J31: =IF(A31="","",IF(_xlfn.MAXIFS(Casos!$K$5:$K$204,Casos!$B$5:$B$204,A31)=0,"",_xlfn.MAXIFS(Casos!$K$5:$K$204,Casos!$B$5:$B$204,A31))) | K31: =IF(OR(A31="",F31=0),0,F31-ROW()/100000)
D32: =IF(A32="","",COUNTIFS(Casos!$B$5:$B$204,A32)) | E32: =IF(A32="","",COUNTIFS(Casos!$B$5:$B$204,A32,Casos!$L$5:$L$204,"Ativo")) | F32: =IF(A32="","",SUMIFS(Casos!$H$5:$H$204,Casos!$B$5:$B$204,A32)) | G32: =IF(A32="","",SUMIFS(Casos!$I$5:$I$204,Casos!$B$5:$B$204,A32)) | H32: =IF(A32="","",F32-G32) | I32: =IF(OR(A32="",F32=0),"",G32/F32) | J32: =IF(A32="","",IF(_xlfn.MAXIFS(Casos!$K$5:$K$204,Casos!$B$5:$B$204,A32)=0,"",_xlfn.MAXIFS(Casos!$K$5:$K$204,Casos!$B$5:$B$204,A32))) | K32: =IF(OR(A32="",F32=0),0,F32-ROW()/100000)
D33: =IF(A33="","",COUNTIFS(Casos!$B$5:$B$204,A33)) | E33: =IF(A33="","",COUNTIFS(Casos!$B$5:$B$204,A33,Casos!$L$5:$L$204,"Ativo")) | F33: =IF(A33="","",SUMIFS(Casos!$H$5:$H$204,Casos!$B$5:$B$204,A33)) | G33: =IF(A33="","",SUMIFS(Casos!$I$5:$I$204,Casos!$B$5:$B$204,A33)) | H33: =IF(A33="","",F33-G33) | I33: =IF(OR(A33="",F33=0),"",G33/F33) | J33: =IF(A33="","",IF(_xlfn.MAXIFS(Casos!$K$5:$K$204,Casos!$B$5:$B$204,A33)=0,"",_xlfn.MAXIFS(Casos!$K$5:$K$204,Casos!$B$5:$B$204,A33))) | K33: =IF(OR(A33="",F33=0),0,F33-ROW()/100000)
D34: =IF(A34="","",COUNTIFS(Casos!$B$5:$B$204,A34)) | E34: =IF(A34="","",COUNTIFS(Casos!$B$5:$B$204,A34,Casos!$L$5:$L$204,"Ativo")) | F34: =IF(A34="","",SUMIFS(Casos!$H$5:$H$204,Casos!$B$5:$B$204,A34)) | G34: =IF(A34="","",SUMIFS(Casos!$I$5:$I$204,Casos!$B$5:$B$204,A34)) | H34: =IF(A34="","",F34-G34) | I34: =IF(OR(A34="",F34=0),"",G34/F34) | J34: =IF(A34="","",IF(_xlfn.MAXIFS(Casos!$K$5:$K$204,Casos!$B$5:$B$204,A34)=0,"",_xlfn.MAXIFS(Casos!$K$5:$K$204,Casos!$B$5:$B$204,A34))) | K34: =IF(OR(A34="",F34=0),0,F34-ROW()/100000)
... D64: =IF(A64="","",COUNTIFS(Casos!$B$5:$B$204,A64)) | E64: =IF(A64="","",COUNTIFS(Casos!$B$5:$B$204,A64,Casos!$L$5:$L$204,"Ativo")) | F64: =IF(A64="","",SUMIFS(Casos!$H$5:$H$204,Casos!$B$5:$B$204,A64)) | G64: =IF(A64="","",SUMIFS(Casos!$I$5:$I$204,Casos!$B$5:$B$204,A64)) | H64: =IF(A64="","",F64-G64) | I64: =IF(OR(A64="",F64=0),"",G64/F64) | J64: =IF(A64="","",IF(_xlfn.MAXIFS(Casos!$K$5:$K$204,Casos!$B$5:$B$204,A64)=0,"",_xlfn.MAXIFS(Casos!$K$5:$K$204,Casos!$B$5:$B$204,A64))) | K64: =IF(OR(A64="",F64=0),0,F64-ROW()/100000)

Sheet Casos
A1: Casos
A2: Uma linha por caso. Cliente, área, fase, responsável e modalidade vêm de listas; tipo, a receber e situação são calculados.
A4: Número do processo ou referência | B4: Cliente | C4: Tipo | D4: Área | E4: Fase | F4: Responsável | G4: Modalidade | H4: Valor contratado (R$) | I4: Recebido (R$) | J4: A receber (R$) | K4: Abertura | L4: Situação | M4: % recebido
A5: 9236009-85.2026.8.26.0452 | B5: Padaria do Sol Ltda | C5: =IF(B5="","",IFERROR(INDEX(Clientes!$B$5:$B$64,MATCH(B5,Clientes!$A$5:$A$64,0)),"")) | D5: Empresarial | E5: Inicial | F5: Marina Ferraz | G5: Êxito | H5: 14400 | I5: 0 | J5: =IF(B5="","",H5-I5) | K5: 46154 | L5: =IF(B5="","",IF(E5=Config!$B$6,"Encerrado","Ativo")) | M5: =IF(OR(B5="",H5=0,H5=""),"",I5/H5)
A6: 9225646-96.2026.8.26.0322 | B6: Ana Beatriz Moreira | C6: =IF(B6="","",IFERROR(INDEX(Clientes!$B$5:$B$64,MATCH(B6,Clientes!$A$5:$A$64,0)),"")) | D6: Trabalhista | E6: Sentença | F6: Rafael Lima | G6: Fixo | H6: 8000 | I6: 4800 | J6: =IF(B6="","",H6-I6) | K6: 46146 | L6: =IF(B6="","",IF(E6=Config!$B$6,"Encerrado","Ativo")) | M6: =IF(OR(B6="",H6=0,H6=""),"",I6/H6)
A7: 6710873-21.2025.8.26.0571 | B7: Construtora Horizonte | C7: =IF(B7="","",IFERROR(INDEX(Clientes!$B$5:$B$64,MATCH(B7,Clientes!$A$5:$A$64,0)),"")) | D7: Cível | E7: Sentença | F7: Marina Ferraz | G7: Misto | H7: 8100 | I7: 8100 | J7: =IF(B7="","",H7-I7) | K7: 45894 | L7: =IF(B7="","",IF(E7=Config!$B$6,"Encerrado","Ativo")) | M7: =IF(OR(B7="",H7=0,H7=""),"",I7/H7)
A8: 8735513-64.2025.8.26.0093 | B8: Carlos Eduardo Nunes | C8: =IF(B8="","",IFERROR(INDEX(Clientes!$B$5:$B$64,MATCH(B8,Clientes!$A$5:$A$64,0)),"")) | D8: Previdenciário | E8: Recurso | F8: Rafael Lima | G8: Êxito | H8: 5700 | I8: 0 | J8: =IF(B8="","",H8-I8) | K8: 45943 | L8: =IF(B8="","",IF(E8=Config!$B$6,"Encerrado","Ativo")) | M8: =IF(OR(B8="",H8=0,H8=""),"",I8/H8)
A9: 9802211-43.2025.8.26.0431 | B9: Loja Verde Comércio | C9: =IF(B9="","",IFERROR(INDEX(Clientes!$B$5:$B$64,MATCH(B9,Clientes!$A$5:$A$64,0)),"")) | D9: Empresarial | E9: Acordo | F9: Marina Ferraz | G9: Misto | H9: 19600 | I9: 19600 | J9: =IF(B9="","",H9-I9) | K9: 45824 | L9: =IF(B9="","",IF(E9=Config!$B$6,"Encerrado","Ativo")) | M9: =IF(OR(B9="",H9=0,H9=""),"",I9/H9)
A10: 9778116-95.2026.8.26.0106 | B10: Fernanda Castro | C10: =IF(B10="","",IFERROR(INDEX(Clientes!$B$5:$B$64,MATCH(B10,Clientes!$A$5:$A$64,0)),"")) | D10: Família | E10: Encerrado | F10: Marina Ferraz | G10: Fixo | H10: 9000 | I10: 9000 | J10: =IF(B10="","",H10-I10) | K10: 46127 | L10: =IF(B10="","",IF(E10=Config!$B$6,"Encerrado","Ativo")) | M10: =IF(OR(B10="",H10=0,H10=""),"",I10/H10)
A11: 8875326-79.2026.8.26.0258 | B11: Bistrô 42 | C11: =IF(B11="","",IFERROR(INDEX(Clientes!$B$5:$B$64,MATCH(B11,Clientes!$A$5:$A$64,0)),"")) | D11: Trabalhista | E11: Acordo | F11: Rafael Lima | G11: Misto | H11: 4600 | I11: 4600 | J11: =IF(B11="","",H11-I11) | K11: 46025 | L11: =IF(B11="","",IF(E11=Config!$B$6,"Encerrado","Ativo")) | M11: =IF(OR(B11="",H11=0,H11=""),"",I11/H11)
A12: 4397912-47.2025.8.26.0276 | B12: Roberto Almeida | C12: =IF(B12="","",IFERROR(INDEX(Clientes!$B$5:$B$64,MATCH(B12,Clientes!$A$5:$A$64,0)),"")) | D12: Cível | E12: Acordo | F12: Marina Ferraz | G12: Êxito | H12: 11300 | I12: 11300 | J12: =IF(B12="","",H12-I12) | K12: 45746 | L12: =IF(B12="","",IF(E12=Config!$B$6,"Encerrado","Ativo")) | M12: =IF(OR(B12="",H12=0,H12=""),"",I12/H12)
A13: 4352718-43.2025.8.26.0498 | B13: Clínica Bem-Estar | C13: =IF(B13="","",IFERROR(INDEX(Clientes!$B$5:$B$64,MATCH(B13,Clientes!$A$5:$A$64,0)),"")) | D13: Empresarial | E13: Consultivo | F13: Marina Ferraz | G13: Fixo | H13: 9300 | I13: 4650 | J13: =IF(B13="","",H13-I13) | K13: 45790 | L13: =IF(B13="","",IF(E13=Config!$B$6,"Encerrado","Ativo")) | M13: =IF(OR(B13="",H13=0,H13=""),"",I13/H13)
A14: 2650441-66.2026.8.26.0528 | B14: Marcos Vinícius Teles | C14: =IF(B14="","",IFERROR(INDEX(Clientes!$B$5:$B$64,MATCH(B14,Clientes!$A$5:$A$64,0)),"")) | D14: Previdenciário | E14: Encerrado | F14: Rafael Lima | G14: Misto | H14: 7800 | I14: 7800 | J14: =IF(B14="","",H14-I14) | K14: 46225 | L14: =IF(B14="","",IF(E14=Config!$B$6,"Encerrado","Ativo")) | M14: =IF(OR(B14="",H14=0,H14=""),"",I14/H14)
A15: 5470559-73.2026.8.26.0380 | B15: Transportadora Rota Sul | C15: =IF(B15="","",IFERROR(INDEX(Clientes!$B$5:$B$64,MATCH(B15,Clientes!$A$5:$A$64,0)),"")) | D15: Trabalhista | E15: Recurso | F15: Rafael Lima | G15: Misto | H15: 10200 | I15: 6120 | J15: =IF(B15="","",H15-I15) | K15: 46072 | L15: =IF(B15="","",IF(E15=Config!$B$6,"Encerrado","Ativo")) | M15: =IF(OR(B15="",H15=0,H15=""),"",I15/H15)
A16: 8570388-84.2025.8.26.0560 | B16: Patrícia Gomes | C16: =IF(B16="","",IFERROR(INDEX(Clientes!$B$5:$B$64,MATCH(B16,Clientes!$A$5:$A$64,0)),"")) | D16: Família | E16: Inicial | F16: Marina Ferraz | G16: Hora | H16: 10400 | I16: 0 | J16: =IF(B16="","",H16-I16) | K16: 45838 | L16: =IF(B16="","",IF(E16=Config!$B$6,"Encerrado","Ativo")) | M16: =IF(OR(B16="",H16=0,H16=""),"",I16/H16)
... A42: 7598076-58.2025.8.26.0552 | B42: Ana Beatriz Moreira | C42: =IF(B42="","",IFERROR(INDEX(Clientes!$B$5:$B$64,MATCH(B42,Clientes!$A$5:$A$64,0)),"")) | D42: Família | E42: Encerrado | F42: Marina Ferraz | G42: Hora | H42: 11300 | I42: 11300 | J42: =IF(B42="","",H42-I42) | K42: 45945 | L42: =IF(B42="","",IF(E42=Config!$B$6,"Encerrado","Ativo")) | M42: =IF(OR(B42="",H42=0,H42=""),"",I42/H42)
C43: =IF(B43="","",IFERROR(INDEX(Clientes!$B$5:$B$64,MATCH(B43,Clientes!$A$5:$A$64,0)),"")) | J43: =IF(B43="","",H43-I43) | L43: =IF(B43="","",IF(E43=Config!$B$6,"Encerrado","Ativo")) | M43: =IF(OR(B43="",H43=0,H43=""),"",I43/H43)
C44: =IF(B44="","",IFERROR(INDEX(Clientes!$B$5:$B$64,MATCH(B44,Clientes!$A$5:$A$64,0)),"")) | J44: =IF(B44="","",H44-I44) | L44: =IF(B44="","",IF(E44=Config!$B$6,"Encerrado","Ativo")) | M44: =IF(OR(B44="",H44=0,H44=""),"",I44/H44)
C45: =IF(B45="","",IFERROR(INDEX(Clientes!$B$5:$B$64,MATCH(B45,Clientes!$A$5:$A$64,0)),"")) | J45: =IF(B45="","",H45-I45) | L45: =IF(B45="","",IF(E45=Config!$B$6,"Encerrado","Ativo")) | M45: =IF(OR(B45="",H45=0,H45=""),"",I45/H45)
C46: =IF(B46="","",IFERROR(INDEX(Clientes!$B$5:$B$64,MATCH(B46,Clientes!$A$5:$A$64,0)),"")) | J46: =IF(B46="","",H46-I46) | L46: =IF(B46="","",IF(E46=Config!$B$6,"Encerrado","Ativo")) | M46: =IF(OR(B46="",H46=0,H46=""),"",I46/H46)
C47: =IF(B47="","",IFERROR(INDEX(Clientes!$B$5:$B$64,MATCH(B47,Clientes!$A$5:$A$64,0)),"")) | J47: =IF(B47="","",H47-I47) | L47: =IF(B47="","",IF(E47=Config!$B$6,"Encerrado","Ativo")) | M47: =IF(OR(B47="",H47=0,H47=""),"",I47/H47)
C48: =IF(B48="","",IFERROR(INDEX(Clientes!$B$5:$B$64,MATCH(B48,Clientes!$A$5:$A$64,0)),"")) | J48: =IF(B48="","",H48-I48) | L48: =IF(B48="","",IF(E48=Config!$B$6,"Encerrado","Ativo")) | M48: =IF(OR(B48="",H48=0,H48=""),"",I48/H48)
C49: =IF(B49="","",IFERROR(INDEX(Clientes!$B$5:$B$64,MATCH(B49,Clientes!$A$5:$A$64,0)),"")) | J49: =IF(B49="","",H49-I49) | L49: =IF(B49="","",IF(E49=Config!$B$6,"Encerrado","Ativo")) | M49: =IF(OR(B49="",H49=0,H49=""),"",I49/H49)
C50: =IF(B50="","",IFERROR(INDEX(Clientes!$B$5:$B$64,MATCH(B50,Clientes!$A$5:$A$64,0)),"")) | J50: =IF(B50="","",H50-I50) | L50: =IF(B50="","",IF(E50=Config!$B$6,"Encerrado","Ativo")) | M50: =IF(OR(B50="",H50=0,H50=""),"",I50/H50)
C51: =IF(B51="","",IFERROR(INDEX(Clientes!$B$5:$B$64,MATCH(B51,Clientes!$A$5:$A$64,0)),"")) | J51: =IF(B51="","",H51-I51) | L51: =IF(B51="","",IF(E51=Config!$B$6,"Encerrado","Ativo")) | M51: =IF(OR(B51="",H51=0,H51=""),"",I51/H51)
C52: =IF(B52="","",IFERROR(INDEX(Clientes!$B$5:$B$64,MATCH(B52,Clientes!$A$5:$A$64,0)),"")) | J52: =IF(B52="","",H52-I52) | L52: =IF(B52="","",IF(E52=Config!$B$6,"Encerrado","Ativo")) | M52: =IF(OR(B52="",H52=0,H52=""),"",I52/H52)
C53: =IF(B53="","",IFERROR(INDEX(Clientes!$B$5:$B$64,MATCH(B53,Clientes!$A$5:$A$64,0)),"")) | J53: =IF(B53="","",H53-I53) | L53: =IF(B53="","",IF(E53=Config!$B$6,"Encerrado","Ativo")) | M53: =IF(OR(B53="",H53=0,H53=""),"",I53/H53)
C54: =IF(B54="","",IFERROR(INDEX(Clientes!$B$5:$B$64,MATCH(B54,Clientes!$A$5:$A$64,0)),"")) | J54: =IF(B54="","",H54-I54) | L54: =IF(B54="","",IF(E54=Config!$B$6,"Encerrado","Ativo")) | M54: =IF(OR(B54="",H54=0,H54=""),"",I54/H54)
... C204: =IF(B204="","",IFERROR(INDEX(Clientes!$B$5:$B$64,MATCH(B204,Clientes!$A$5:$A$64,0)),"")) | J204: =IF(B204="","",H204-I204) | L204: =IF(B204="","",IF(E204=Config!$B$6,"Encerrado","Ativo")) | M204: =IF(OR(B204="",H204=0,H204=""),"",I204/H204)
A206: Recebido em vermelho: está maior que o valor contratado; confira o contrato ou o valor lançado. Linhas cinza: casos encerrados.
