Workbook

Sheet Como usar
A1: Horas por Caso e por Pessoa
A2: Kit de Gestão para Advogados · Seu Sócio Gestor · versão 1.0 (setembro de 2026)
A4: O que esta planilha faz | B4: Cada pessoa lança as horas por caso; ela transforma em custo pelo custo-hora, compara com as horas estimadas e o valor contratado, mostra a margem de cada caso com um semáforo ("consome mais do que paga") e a ocupação de cada pessoa no mês.
A5: Passo 1 | B5: Em Config, cadastre as pessoas com custo mensal e meta de horas faturáveis, os custos fixos do escritório (da planilha 05) e as atividades. O custo-hora é calculado.
A6: Passo 2 | B6: Em Casos, cole a lista da planilha 13 (Carteira) com valor contratado e horas estimadas. Se o caso já vinha de antes, anote as horas gastas até aqui. Trabalho interno (gestão, captação) entra como modalidade Interno.
A7: Passo 3 | B7: Em Lançamentos, uma linha por pessoa, por dia, por caso: data, pessoa, caso, atividade, horas e se é faturável. Dois minutos no fim do dia bastam.
A8: Passo 4 | B8: Em Painel, escolha o mês em Config. "Casos para olhar primeiro" mostra os que consomem mais do que pagam; "Por pessoa" mostra horas, % faturável e ocupação contra a meta; "Todos os casos" traz o semáforo completo.
A9: Rotina | B9: Cada pessoa lança no fim do dia ou na sexta (10 minutos). Dia 1 do mês: olhar a margem por caso antes de precificar a próxima proposta (planilha 06).
A10: Exemplo | B10: No exemplo o mês do painel é agosto de 2026, o último mês completo; setembro está lançado até o dia 14. Os lançamentos vão de julho a setembro; o que veio antes está em "horas gastas antes".
A11: Com a IA | B11: Copie "Casos para olhar primeiro" e use o prompt "Revisar a proposta de honorários" ou "Explicar o mês ao sócio" da biblioteca. Para justificar horas a um cliente, copie os lançamentos do caso e peça um resumo por atividade.
A12: Legenda | B12: Células amarelas: você preenche. Brancas: calculadas. Não é preciso mexer em nada fora do amarelo.
A13: Proteção | B13: Fórmulas protegidas sem senha. Para editar: Revisar > Desproteger planilha (Excel) ou Dados > Proteger intervalos (Google Sheets).
A14: Requisitos | B14: Excel 2019 ou mais novo, Microsoft 365 ou Google Sheets. No celular abre nos aplicativos; para preencher, use o computador.
A15: Google Sheets | B15: Faça upload no Google Drive e abra com o Google Sheets. Fórmulas, listas, cores e gráficos funcionam.
... A17: Suporte | B17: suporte@seusociogestor.com.br · resposta em até 5 dias úteis · reembolso em até 7 dias pelo mesmo canal.

Sheet Painel
A1: =Config!$B$4&" · Horas por caso · "&Config!$B$6&" de "&Config!$B$5
A2: Nada para digitar aqui. Escolha o mês em Config; tudo vem de Lançamentos e Casos.
A4: Horas no mês | C4: Faturáveis no mês | E4: Custo das horas no mês | G4: Ocupação da equipe | I4: Consomem mais do que pagam
A5: =SUMIFS(Lançamentos!$E$5:$E$604,Lançamentos!$I$5:$I$604,Config!$B$7,Lançamentos!$J$5:$J$604,Config!$B$5) | C5: =IFERROR(SUMIFS(Lançamentos!$E$5:$E$604,Lançamentos!$I$5:$I$604,Config!$B$7,Lançamentos!$J$5:$J$604,Config!$B$5,Lançamentos!$F$5:$F$604,"Sim")/A5,0) | E5: =SUMIFS(Lançamentos!$H$5:$H$604,Lançamentos!$I$5:$I$604,Config!$B$7,Lançamentos!$J$5:$J$604,Config!$B$5) | G5: =IFERROR(SUMIFS(Lançamentos!$E$5:$E$604,Lançamentos!$I$5:$I$604,Config!$B$7,Lançamentos!$J$5:$J$604,Config!$B$5,Lançamentos!$F$5:$F$604,"Sim")/SUMIFS(Config!$C$12:$C$21,Config!$A$12:$A$21,"<>"),0) | I5: =COUNTIF($L$32:$L$91,"Consome mais do que paga")
A7: Ocupação = horas faturáveis lançadas no mês ÷ soma das metas de horas faturáveis (Config). Custo das horas = horas × custo-hora de quem lançou.
A9: Casos para olhar primeiro (todo o período)
A10: Casos em que o custo das horas já chegou perto do valor contratado, passou dele ou estourou as horas estimadas. Ordem: custo ÷ contratado, do maior para o menor.
A11: # | B11: Caso | C11: Cliente | D11: Responsável | E11: Horas estimadas | F11: Horas gastas | G11: Custo das horas | H11: Valor contratado | I11: Margem (R$) | J11: Situação
A12: 1 | B12: =IFERROR(IF(LARGE($M$32:$M$91,1)>0,INDEX($A$32:$A$91,MATCH(LARGE($M$32:$M$91,1),$M$32:$M$91,0)),""),"") | C12: =IFERROR(IF(LARGE($M$32:$M$91,1)>0,INDEX($B$32:$B$91,MATCH(LARGE($M$32:$M$91,1),$M$32:$M$91,0)),""),"") | D12: =IFERROR(IF(LARGE($M$32:$M$91,1)>0,INDEX($C$32:$C$91,MATCH(LARGE($M$32:$M$91,1),$M$32:$M$91,0)),""),"") | E12: =IFERROR(IF(LARGE($M$32:$M$91,1)>0,INDEX($E$32:$E$91,MATCH(LARGE($M$32:$M$91,1),$M$32:$M$91,0)),""),"") | F12: =IFERROR(IF(LARGE($M$32:$M$91,1)>0,INDEX($F$32:$F$91,MATCH(LARGE($M$32:$M$91,1),$M$32:$M$91,0)),""),"") | G12: =IFERROR(IF(LARGE($M$32:$M$91,1)>0,INDEX($H$32:$H$91,MATCH(LARGE($M$32:$M$91,1),$M$32:$M$91,0)),""),"") | H12: =IFERROR(IF(LARGE($M$32:$M$91,1)>0,INDEX($I$32:$I$91,MATCH(LARGE($M$32:$M$91,1),$M$32:$M$91,0)),""),"") | I12: =IFERROR(IF(LARGE($M$32:$M$91,1)>0,INDEX($J$32:$J$91,MATCH(LARGE($M$32:$M$91,1),$M$32:$M$91,0)),""),"") | J12: =IFERROR(IF(LARGE($M$32:$M$91,1)>0,INDEX($L$32:$L$91,MATCH(LARGE($M$32:$M$91,1),$M$32:$M$91,0)),""),"")
A13: 2 | B13: =IFERROR(IF(LARGE($M$32:$M$91,2)>0,INDEX($A$32:$A$91,MATCH(LARGE($M$32:$M$91,2),$M$32:$M$91,0)),""),"") | C13: =IFERROR(IF(LARGE($M$32:$M$91,2)>0,INDEX($B$32:$B$91,MATCH(LARGE($M$32:$M$91,2),$M$32:$M$91,0)),""),"") | D13: =IFERROR(IF(LARGE($M$32:$M$91,2)>0,INDEX($C$32:$C$91,MATCH(LARGE($M$32:$M$91,2),$M$32:$M$91,0)),""),"") | E13: =IFERROR(IF(LARGE($M$32:$M$91,2)>0,INDEX($E$32:$E$91,MATCH(LARGE($M$32:$M$91,2),$M$32:$M$91,0)),""),"") | F13: =IFERROR(IF(LARGE($M$32:$M$91,2)>0,INDEX($F$32:$F$91,MATCH(LARGE($M$32:$M$91,2),$M$32:$M$91,0)),""),"") | G13: =IFERROR(IF(LARGE($M$32:$M$91,2)>0,INDEX($H$32:$H$91,MATCH(LARGE($M$32:$M$91,2),$M$32:$M$91,0)),""),"") | H13: =IFERROR(IF(LARGE($M$32:$M$91,2)>0,INDEX($I$32:$I$91,MATCH(LARGE($M$32:$M$91,2),$M$32:$M$91,0)),""),"") | I13: =IFERROR(IF(LARGE($M$32:$M$91,2)>0,INDEX($J$32:$J$91,MATCH(LARGE($M$32:$M$91,2),$M$32:$M$91,0)),""),"") | J13: =IFERROR(IF(LARGE($M$32:$M$91,2)>0,INDEX($L$32:$L$91,MATCH(LARGE($M$32:$M$91,2),$M$32:$M$91,0)),""),"")
A14: 3 | B14: =IFERROR(IF(LARGE($M$32:$M$91,3)>0,INDEX($A$32:$A$91,MATCH(LARGE($M$32:$M$91,3),$M$32:$M$91,0)),""),"") | C14: =IFERROR(IF(LARGE($M$32:$M$91,3)>0,INDEX($B$32:$B$91,MATCH(LARGE($M$32:$M$91,3),$M$32:$M$91,0)),""),"") | D14: =IFERROR(IF(LARGE($M$32:$M$91,3)>0,INDEX($C$32:$C$91,MATCH(LARGE($M$32:$M$91,3),$M$32:$M$91,0)),""),"") | E14: =IFERROR(IF(LARGE($M$32:$M$91,3)>0,INDEX($E$32:$E$91,MATCH(LARGE($M$32:$M$91,3),$M$32:$M$91,0)),""),"") | F14: =IFERROR(IF(LARGE($M$32:$M$91,3)>0,INDEX($F$32:$F$91,MATCH(LARGE($M$32:$M$91,3),$M$32:$M$91,0)),""),"") | G14: =IFERROR(IF(LARGE($M$32:$M$91,3)>0,INDEX($H$32:$H$91,MATCH(LARGE($M$32:$M$91,3),$M$32:$M$91,0)),""),"") | H14: =IFERROR(IF(LARGE($M$32:$M$91,3)>0,INDEX($I$32:$I$91,MATCH(LARGE($M$32:$M$91,3),$M$32:$M$91,0)),""),"") | I14: =IFERROR(IF(LARGE($M$32:$M$91,3)>0,INDEX($J$32:$J$91,MATCH(LARGE($M$32:$M$91,3),$M$32:$M$91,0)),""),"") | J14: =IFERROR(IF(LARGE($M$32:$M$91,3)>0,INDEX($L$32:$L$91,MATCH(LARGE($M$32:$M$91,3),$M$32:$M$91,0)),""),"")
A15: 4 | B15: =IFERROR(IF(LARGE($M$32:$M$91,4)>0,INDEX($A$32:$A$91,MATCH(LARGE($M$32:$M$91,4),$M$32:$M$91,0)),""),"") | C15: =IFERROR(IF(LARGE($M$32:$M$91,4)>0,INDEX($B$32:$B$91,MATCH(LARGE($M$32:$M$91,4),$M$32:$M$91,0)),""),"") | D15: =IFERROR(IF(LARGE($M$32:$M$91,4)>0,INDEX($C$32:$C$91,MATCH(LARGE($M$32:$M$91,4),$M$32:$M$91,0)),""),"") | E15: =IFERROR(IF(LARGE($M$32:$M$91,4)>0,INDEX($E$32:$E$91,MATCH(LARGE($M$32:$M$91,4),$M$32:$M$91,0)),""),"") | F15: =IFERROR(IF(LARGE($M$32:$M$91,4)>0,INDEX($F$32:$F$91,MATCH(LARGE($M$32:$M$91,4),$M$32:$M$91,0)),""),"") | G15: =IFERROR(IF(LARGE($M$32:$M$91,4)>0,INDEX($H$32:$H$91,MATCH(LARGE($M$32:$M$91,4),$M$32:$M$91,0)),""),"") | H15: =IFERROR(IF(LARGE($M$32:$M$91,4)>0,INDEX($I$32:$I$91,MATCH(LARGE($M$32:$M$91,4),$M$32:$M$91,0)),""),"") | I15: =IFERROR(IF(LARGE($M$32:$M$91,4)>0,INDEX($J$32:$J$91,MATCH(LARGE($M$32:$M$91,4),$M$32:$M$91,0)),""),"") | J15: =IFERROR(IF(LARGE($M$32:$M$91,4)>0,INDEX($L$32:$L$91,MATCH(LARGE($M$32:$M$91,4),$M$32:$M$91,0)),""),"")
A16: 5 | B16: =IFERROR(IF(LARGE($M$32:$M$91,5)>0,INDEX($A$32:$A$91,MATCH(LARGE($M$32:$M$91,5),$M$32:$M$91,0)),""),"") | C16: =IFERROR(IF(LARGE($M$32:$M$91,5)>0,INDEX($B$32:$B$91,MATCH(LARGE($M$32:$M$91,5),$M$32:$M$91,0)),""),"") | D16: =IFERROR(IF(LARGE($M$32:$M$91,5)>0,INDEX($C$32:$C$91,MATCH(LARGE($M$32:$M$91,5),$M$32:$M$91,0)),""),"") | E16: =IFERROR(IF(LARGE($M$32:$M$91,5)>0,INDEX($E$32:$E$91,MATCH(LARGE($M$32:$M$91,5),$M$32:$M$91,0)),""),"") | F16: =IFERROR(IF(LARGE($M$32:$M$91,5)>0,INDEX($F$32:$F$91,MATCH(LARGE($M$32:$M$91,5),$M$32:$M$91,0)),""),"") | G16: =IFERROR(IF(LARGE($M$32:$M$91,5)>0,INDEX($H$32:$H$91,MATCH(LARGE($M$32:$M$91,5),$M$32:$M$91,0)),""),"") | H16: =IFERROR(IF(LARGE($M$32:$M$91,5)>0,INDEX($I$32:$I$91,MATCH(LARGE($M$32:$M$91,5),$M$32:$M$91,0)),""),"") | I16: =IFERROR(IF(LARGE($M$32:$M$91,5)>0,INDEX($J$32:$J$91,MATCH(LARGE($M$32:$M$91,5),$M$32:$M$91,0)),""),"") | J16: =IFERROR(IF(LARGE($M$32:$M$91,5)>0,INDEX($L$32:$L$91,MATCH(LARGE($M$32:$M$91,5),$M$32:$M$91,0)),""),"")
A17: 6 | B17: =IFERROR(IF(LARGE($M$32:$M$91,6)>0,INDEX($A$32:$A$91,MATCH(LARGE($M$32:$M$91,6),$M$32:$M$91,0)),""),"") | C17: =IFERROR(IF(LARGE($M$32:$M$91,6)>0,INDEX($B$32:$B$91,MATCH(LARGE($M$32:$M$91,6),$M$32:$M$91,0)),""),"") | D17: =IFERROR(IF(LARGE($M$32:$M$91,6)>0,INDEX($C$32:$C$91,MATCH(LARGE($M$32:$M$91,6),$M$32:$M$91,0)),""),"") | E17: =IFERROR(IF(LARGE($M$32:$M$91,6)>0,INDEX($E$32:$E$91,MATCH(LARGE($M$32:$M$91,6),$M$32:$M$91,0)),""),"") | F17: =IFERROR(IF(LARGE($M$32:$M$91,6)>0,INDEX($F$32:$F$91,MATCH(LARGE($M$32:$M$91,6),$M$32:$M$91,0)),""),"") | G17: =IFERROR(IF(LARGE($M$32:$M$91,6)>0,INDEX($H$32:$H$91,MATCH(LARGE($M$32:$M$91,6),$M$32:$M$91,0)),""),"") | H17: =IFERROR(IF(LARGE($M$32:$M$91,6)>0,INDEX($I$32:$I$91,MATCH(LARGE($M$32:$M$91,6),$M$32:$M$91,0)),""),"") | I17: =IFERROR(IF(LARGE($M$32:$M$91,6)>0,INDEX($J$32:$J$91,MATCH(LARGE($M$32:$M$91,6),$M$32:$M$91,0)),""),"") | J17: =IFERROR(IF(LARGE($M$32:$M$91,6)>0,INDEX($L$32:$L$91,MATCH(LARGE($M$32:$M$91,6),$M$32:$M$91,0)),""),"")
A18: 7 | B18: =IFERROR(IF(LARGE($M$32:$M$91,7)>0,INDEX($A$32:$A$91,MATCH(LARGE($M$32:$M$91,7),$M$32:$M$91,0)),""),"") | C18: =IFERROR(IF(LARGE($M$32:$M$91,7)>0,INDEX($B$32:$B$91,MATCH(LARGE($M$32:$M$91,7),$M$32:$M$91,0)),""),"") | D18: =IFERROR(IF(LARGE($M$32:$M$91,7)>0,INDEX($C$32:$C$91,MATCH(LARGE($M$32:$M$91,7),$M$32:$M$91,0)),""),"") | E18: =IFERROR(IF(LARGE($M$32:$M$91,7)>0,INDEX($E$32:$E$91,MATCH(LARGE($M$32:$M$91,7),$M$32:$M$91,0)),""),"") | F18: =IFERROR(IF(LARGE($M$32:$M$91,7)>0,INDEX($F$32:$F$91,MATCH(LARGE($M$32:$M$91,7),$M$32:$M$91,0)),""),"") | G18: =IFERROR(IF(LARGE($M$32:$M$91,7)>0,INDEX($H$32:$H$91,MATCH(LARGE($M$32:$M$91,7),$M$32:$M$91,0)),""),"") | H18: =IFERROR(IF(LARGE($M$32:$M$91,7)>0,INDEX($I$32:$I$91,MATCH(LARGE($M$32:$M$91,7),$M$32:$M$91,0)),""),"") | I18: =IFERROR(IF(LARGE($M$32:$M$91,7)>0,INDEX($J$32:$J$91,MATCH(LARGE($M$32:$M$91,7),$M$32:$M$91,0)),""),"") | J18: =IFERROR(IF(LARGE($M$32:$M$91,7)>0,INDEX($L$32:$L$91,MATCH(LARGE($M$32:$M$91,7),$M$32:$M$91,0)),""),"")
A19: 8 | B19: =IFERROR(IF(LARGE($M$32:$M$91,8)>0,INDEX($A$32:$A$91,MATCH(LARGE($M$32:$M$91,8),$M$32:$M$91,0)),""),"") | C19: =IFERROR(IF(LARGE($M$32:$M$91,8)>0,INDEX($B$32:$B$91,MATCH(LARGE($M$32:$M$91,8),$M$32:$M$91,0)),""),"") | D19: =IFERROR(IF(LARGE($M$32:$M$91,8)>0,INDEX($C$32:$C$91,MATCH(LARGE($M$32:$M$91,8),$M$32:$M$91,0)),""),"") | E19: =IFERROR(IF(LARGE($M$32:$M$91,8)>0,INDEX($E$32:$E$91,MATCH(LARGE($M$32:$M$91,8),$M$32:$M$91,0)),""),"") | F19: =IFERROR(IF(LARGE($M$32:$M$91,8)>0,INDEX($F$32:$F$91,MATCH(LARGE($M$32:$M$91,8),$M$32:$M$91,0)),""),"") | G19: =IFERROR(IF(LARGE($M$32:$M$91,8)>0,INDEX($H$32:$H$91,MATCH(LARGE($M$32:$M$91,8),$M$32:$M$91,0)),""),"") | H19: =IFERROR(IF(LARGE($M$32:$M$91,8)>0,INDEX($I$32:$I$91,MATCH(LARGE($M$32:$M$91,8),$M$32:$M$91,0)),""),"") | I19: =IFERROR(IF(LARGE($M$32:$M$91,8)>0,INDEX($J$32:$J$91,MATCH(LARGE($M$32:$M$91,8),$M$32:$M$91,0)),""),"") | J19: =IFERROR(IF(LARGE($M$32:$M$91,8)>0,INDEX($L$32:$L$91,MATCH(LARGE($M$32:$M$91,8),$M$32:$M$91,0)),""),"")
A21: ="Por pessoa em "&Config!$B$6
A22: Pessoa | B22: Horas lançadas | C22: Faturáveis | D22: % faturável | E22: Meta faturável/mês | F22: % da meta | G22: Custo no mês (R$) | H22: Custo-hora (R$)
A23: =IF(Config!$A$12="","",Config!$A$12) | B23: =IF(Config!$A$12="","",SUMIFS(Lançamentos!$E$5:$E$604,Lançamentos!$B$5:$B$604,Config!$A$12,Lançamentos!$I$5:$I$604,Config!$B$7,Lançamentos!$J$5:$J$604,Config!$B$5)) | C23: =IF(Config!$A$12="","",SUMIFS(Lançamentos!$E$5:$E$604,Lançamentos!$B$5:$B$604,Config!$A$12,Lançamentos!$I$5:$I$604,Config!$B$7,Lançamentos!$J$5:$J$604,Config!$B$5,Lançamentos!$F$5:$F$604,"Sim")) | D23: =IF(OR(Config!$A$12="",B23=0),"",C23/B23) | E23: =IF(Config!$A$12="","",Config!$C$12) | F23: =IF(OR(Config!$A$12="",E23=0,E23=""),"",C23/E23) | G23: =IF(Config!$A$12="","",SUMIFS(Lançamentos!$H$5:$H$604,Lançamentos!$B$5:$B$604,Config!$A$12,Lançamentos!$I$5:$I$604,Config!$B$7,Lançamentos!$J$5:$J$604,Config!$B$5)) | H23: =IF(Config!$A$12="","",Config!$D$12)
A24: =IF(Config!$A$13="","",Config!$A$13) | B24: =IF(Config!$A$13="","",SUMIFS(Lançamentos!$E$5:$E$604,Lançamentos!$B$5:$B$604,Config!$A$13,Lançamentos!$I$5:$I$604,Config!$B$7,Lançamentos!$J$5:$J$604,Config!$B$5)) | C24: =IF(Config!$A$13="","",SUMIFS(Lançamentos!$E$5:$E$604,Lançamentos!$B$5:$B$604,Config!$A$13,Lançamentos!$I$5:$I$604,Config!$B$7,Lançamentos!$J$5:$J$604,Config!$B$5,Lançamentos!$F$5:$F$604,"Sim")) | D24: =IF(OR(Config!$A$13="",B24=0),"",C24/B24) | E24: =IF(Config!$A$13="","",Config!$C$13) | F24: =IF(OR(Config!$A$13="",E24=0,E24=""),"",C24/E24) | G24: =IF(Config!$A$13="","",SUMIFS(Lançamentos!$H$5:$H$604,Lançamentos!$B$5:$B$604,Config!$A$13,Lançamentos!$I$5:$I$604,Config!$B$7,Lançamentos!$J$5:$J$604,Config!$B$5)) | H24: =IF(Config!$A$13="","",Config!$D$13)
A25: =IF(Config!$A$14="","",Config!$A$14) | B25: =IF(Config!$A$14="","",SUMIFS(Lançamentos!$E$5:$E$604,Lançamentos!$B$5:$B$604,Config!$A$14,Lançamentos!$I$5:$I$604,Config!$B$7,Lançamentos!$J$5:$J$604,Config!$B$5)) | C25: =IF(Config!$A$14="","",SUMIFS(Lançamentos!$E$5:$E$604,Lançamentos!$B$5:$B$604,Config!$A$14,Lançamentos!$I$5:$I$604,Config!$B$7,Lançamentos!$J$5:$J$604,Config!$B$5,Lançamentos!$F$5:$F$604,"Sim")) | D25: =IF(OR(Config!$A$14="",B25=0),"",C25/B25) | E25: =IF(Config!$A$14="","",Config!$C$14) | F25: =IF(OR(Config!$A$14="",E25=0,E25=""),"",C25/E25) | G25: =IF(Config!$A$14="","",SUMIFS(Lançamentos!$H$5:$H$604,Lançamentos!$B$5:$B$604,Config!$A$14,Lançamentos!$I$5:$I$604,Config!$B$7,Lançamentos!$J$5:$J$604,Config!$B$5)) | H25: =IF(Config!$A$14="","",Config!$D$14)
A26: =IF(Config!$A$15="","",Config!$A$15) | B26: =IF(Config!$A$15="","",SUMIFS(Lançamentos!$E$5:$E$604,Lançamentos!$B$5:$B$604,Config!$A$15,Lançamentos!$I$5:$I$604,Config!$B$7,Lançamentos!$J$5:$J$604,Config!$B$5)) | C26: =IF(Config!$A$15="","",SUMIFS(Lançamentos!$E$5:$E$604,Lançamentos!$B$5:$B$604,Config!$A$15,Lançamentos!$I$5:$I$604,Config!$B$7,Lançamentos!$J$5:$J$604,Config!$B$5,Lançamentos!$F$5:$F$604,"Sim")) | D26: =IF(OR(Config!$A$15="",B26=0),"",C26/B26) | E26: =IF(Config!$A$15="","",Config!$C$15) | F26: =IF(OR(Config!$A$15="",E26=0,E26=""),"",C26/E26) | G26: =IF(Config!$A$15="","",SUMIFS(Lançamentos!$H$5:$H$604,Lançamentos!$B$5:$B$604,Config!$A$15,Lançamentos!$I$5:$I$604,Config!$B$7,Lançamentos!$J$5:$J$604,Config!$B$5)) | H26: =IF(Config!$A$15="","",Config!$D$15)
A27: =IF(Config!$A$16="","",Config!$A$16) | B27: =IF(Config!$A$16="","",SUMIFS(Lançamentos!$E$5:$E$604,Lançamentos!$B$5:$B$604,Config!$A$16,Lançamentos!$I$5:$I$604,Config!$B$7,Lançamentos!$J$5:$J$604,Config!$B$5)) | C27: =IF(Config!$A$16="","",SUMIFS(Lançamentos!$E$5:$E$604,Lançamentos!$B$5:$B$604,Config!$A$16,Lançamentos!$I$5:$I$604,Config!$B$7,Lançamentos!$J$5:$J$604,Config!$B$5,Lançamentos!$F$5:$F$604,"Sim")) | D27: =IF(OR(Config!$A$16="",B27=0),"",C27/B27) | E27: =IF(Config!$A$16="","",Config!$C$16) | F27: =IF(OR(Config!$A$16="",E27=0,E27=""),"",C27/E27) | G27: =IF(Config!$A$16="","",SUMIFS(Lançamentos!$H$5:$H$604,Lançamentos!$B$5:$B$604,Config!$A$16,Lançamentos!$I$5:$I$604,Config!$B$7,Lançamentos!$J$5:$J$604,Config!$B$5)) | H27: =IF(Config!$A$16="","",Config!$D$16)
A28: =IF(Config!$A$17="","",Config!$A$17) | B28: =IF(Config!$A$17="","",SUMIFS(Lançamentos!$E$5:$E$604,Lançamentos!$B$5:$B$604,Config!$A$17,Lançamentos!$I$5:$I$604,Config!$B$7,Lançamentos!$J$5:$J$604,Config!$B$5)) | C28: =IF(Config!$A$17="","",SUMIFS(Lançamentos!$E$5:$E$604,Lançamentos!$B$5:$B$604,Config!$A$17,Lançamentos!$I$5:$I$604,Config!$B$7,Lançamentos!$J$5:$J$604,Config!$B$5,Lançamentos!$F$5:$F$604,"Sim")) | D28: =IF(OR(Config!$A$17="",B28=0),"",C28/B28) | E28: =IF(Config!$A$17="","",Config!$C$17) | F28: =IF(OR(Config!$A$17="",E28=0,E28=""),"",C28/E28) | G28: =IF(Config!$A$17="","",SUMIFS(Lançamentos!$H$5:$H$604,Lançamentos!$B$5:$B$604,Config!$A$17,Lançamentos!$I$5:$I$604,Config!$B$7,Lançamentos!$J$5:$J$604,Config!$B$5)) | H28: =IF(Config!$A$17="","",Config!$D$17)
A29: =IF(Config!$A$18="","",Config!$A$18) | B29: =IF(Config!$A$18="","",SUMIFS(Lançamentos!$E$5:$E$604,Lançamentos!$B$5:$B$604,Config!$A$18,Lançamentos!$I$5:$I$604,Config!$B$7,Lançamentos!$J$5:$J$604,Config!$B$5)) | C29: =IF(Config!$A$18="","",SUMIFS(Lançamentos!$E$5:$E$604,Lançamentos!$B$5:$B$604,Config!$A$18,Lançamentos!$I$5:$I$604,Config!$B$7,Lançamentos!$J$5:$J$604,Config!$B$5,Lançamentos!$F$5:$F$604,"Sim")) | D29: =IF(OR(Config!$A$18="",B29=0),"",C29/B29) | E29: =IF(Config!$A$18="","",Config!$C$18) | F29: =IF(OR(Config!$A$18="",E29=0,E29=""),"",C29/E29) | G29: =IF(Config!$A$18="","",SUMIFS(Lançamentos!$H$5:$H$604,Lançamentos!$B$5:$B$604,Config!$A$18,Lançamentos!$I$5:$I$604,Config!$B$7,Lançamentos!$J$5:$J$604,Config!$B$5)) | H29: =IF(Config!$A$18="","",Config!$D$18)
A30: Todos os casos (todo o período) | B30: =IF(Config!$A$19="","",SUMIFS(Lançamentos!$E$5:$E$604,Lançamentos!$B$5:$B$604,Config!$A$19,Lançamentos!$I$5:$I$604,Config!$B$7,Lançamentos!$J$5:$J$604,Config!$B$5)) | C30: =IF(Config!$A$19="","",SUMIFS(Lançamentos!$E$5:$E$604,Lançamentos!$B$5:$B$604,Config!$A$19,Lançamentos!$I$5:$I$604,Config!$B$7,Lançamentos!$J$5:$J$604,Config!$B$5,Lançamentos!$F$5:$F$604,"Sim")) | D30: =IF(OR(Config!$A$19="",B30=0),"",C30/B30) | E30: Mostra os 60 primeiros casos da aba Casos; horas gastas = horas de antes + lançadas aqui. | F30: =IF(OR(Config!$A$19="",E30=0,E30=""),"",C30/E30) | G30: =IF(Config!$A$19="","",SUMIFS(Lançamentos!$H$5:$H$604,Lançamentos!$B$5:$B$604,Config!$A$19,Lançamentos!$I$5:$I$604,Config!$B$7,Lançamentos!$J$5:$J$604,Config!$B$5)) | H30: =IF(Config!$A$19="","",Config!$D$19)
A31: Caso | B31: Cliente | C31: Responsável | D31: Modalidade | E31: Horas estimadas | F31: Horas gastas | G31: % das estimadas | H31: Custo das horas (R$) | I31: Valor contratado (R$) | J31: Margem (R$) | K31: Margem (%) | L31: Situação
A32: =IF(Casos!$A$5="","",Casos!$A$5) | B32: =IF(Casos!$A$5="","",Casos!$B$5) | C32: =IF(Casos!$A$5="","",Casos!$D$5) | D32: =IF(Casos!$A$5="","",Casos!$E$5) | E32: =IF(Casos!$A$5="","",N(Casos!$G$5)) | F32: =IF(Casos!$A$5="","",N(Casos!$H$5)+SUMIFS(Lançamentos!$E$5:$E$604,Lançamentos!$C$5:$C$604,Casos!$A$5)) | G32: =IF(OR(Casos!$A$5="",E32=0),"",F32/E32) | H32: =IF(Casos!$A$5="","",N(Casos!$H$5)*Config!$B$23+SUMIFS(Lançamentos!$H$5:$H$604,Lançamentos!$C$5:$C$604,Casos!$A$5)) | I32: =IF(Casos!$A$5="","",N(Casos!$F$5)) | J32: =IF(OR(Casos!$A$5="",D32="Interno"),"",I32-H32) | K32: =IF(OR(Casos!$A$5="",D32="Interno",I32=0),"",J32/I32) | L32: =IF(Casos!$A$5="","",IF(D32="Interno","Interno",IF(F32=0,"Sem horas",IF(H32>I32,"Consome mais do que paga",IF(AND(G32<>"",G32>1),"Estourou as horas",IF(AND(K32<>"",K32<0.2),"Margem baixa",IF(AND(G32<>"",G32>0.85),"Perto do limite","Saudável"))))))) | M32: =IF(OR(L32="Consome mais do que paga",L32="Margem baixa",L32="Estourou as horas"),IFERROR(H32/I32,9)+ROW()/1000000,0)
A33: =IF(Casos!$A$6="","",Casos!$A$6) | B33: =IF(Casos!$A$6="","",Casos!$B$6) | C33: =IF(Casos!$A$6="","",Casos!$D$6) | D33: =IF(Casos!$A$6="","",Casos!$E$6) | E33: =IF(Casos!$A$6="","",N(Casos!$G$6)) | F33: =IF(Casos!$A$6="","",N(Casos!$H$6)+SUMIFS(Lançamentos!$E$5:$E$604,Lançamentos!$C$5:$C$604,Casos!$A$6)) | G33: =IF(OR(Casos!$A$6="",E33=0),"",F33/E33) | H33: =IF(Casos!$A$6="","",N(Casos!$H$6)*Config!$B$23+SUMIFS(Lançamentos!$H$5:$H$604,Lançamentos!$C$5:$C$604,Casos!$A$6)) | I33: =IF(Casos!$A$6="","",N(Casos!$F$6)) | J33: =IF(OR(Casos!$A$6="",D33="Interno"),"",I33-H33) | K33: =IF(OR(Casos!$A$6="",D33="Interno",I33=0),"",J33/I33) | L33: =IF(Casos!$A$6="","",IF(D33="Interno","Interno",IF(F33=0,"Sem horas",IF(H33>I33,"Consome mais do que paga",IF(AND(G33<>"",G33>1),"Estourou as horas",IF(AND(K33<>"",K33<0.2),"Margem baixa",IF(AND(G33<>"",G33>0.85),"Perto do limite","Saudável"))))))) | M33: =IF(OR(L33="Consome mais do que paga",L33="Margem baixa",L33="Estourou as horas"),IFERROR(H33/I33,9)+ROW()/1000000,0)
A34: =IF(Casos!$A$7="","",Casos!$A$7) | B34: =IF(Casos!$A$7="","",Casos!$B$7) | C34: =IF(Casos!$A$7="","",Casos!$D$7) | D34: =IF(Casos!$A$7="","",Casos!$E$7) | E34: =IF(Casos!$A$7="","",N(Casos!$G$7)) | F34: =IF(Casos!$A$7="","",N(Casos!$H$7)+SUMIFS(Lançamentos!$E$5:$E$604,Lançamentos!$C$5:$C$604,Casos!$A$7)) | G34: =IF(OR(Casos!$A$7="",E34=0),"",F34/E34) | H34: =IF(Casos!$A$7="","",N(Casos!$H$7)*Config!$B$23+SUMIFS(Lançamentos!$H$5:$H$604,Lançamentos!$C$5:$C$604,Casos!$A$7)) | I34: =IF(Casos!$A$7="","",N(Casos!$F$7)) | J34: =IF(OR(Casos!$A$7="",D34="Interno"),"",I34-H34) | K34: =IF(OR(Casos!$A$7="",D34="Interno",I34=0),"",J34/I34) | L34: =IF(Casos!$A$7="","",IF(D34="Interno","Interno",IF(F34=0,"Sem horas",IF(H34>I34,"Consome mais do que paga",IF(AND(G34<>"",G34>1),"Estourou as horas",IF(AND(K34<>"",K34<0.2),"Margem baixa",IF(AND(G34<>"",G34>0.85),"Perto do limite","Saudável"))))))) | M34: =IF(OR(L34="Consome mais do que paga",L34="Margem baixa",L34="Estourou as horas"),IFERROR(H34/I34,9)+ROW()/1000000,0)
A35: =IF(Casos!$A$8="","",Casos!$A$8) | B35: =IF(Casos!$A$8="","",Casos!$B$8) | C35: =IF(Casos!$A$8="","",Casos!$D$8) | D35: =IF(Casos!$A$8="","",Casos!$E$8) | E35: =IF(Casos!$A$8="","",N(Casos!$G$8)) | F35: =IF(Casos!$A$8="","",N(Casos!$H$8)+SUMIFS(Lançamentos!$E$5:$E$604,Lançamentos!$C$5:$C$604,Casos!$A$8)) | G35: =IF(OR(Casos!$A$8="",E35=0),"",F35/E35) | H35: =IF(Casos!$A$8="","",N(Casos!$H$8)*Config!$B$23+SUMIFS(Lançamentos!$H$5:$H$604,Lançamentos!$C$5:$C$604,Casos!$A$8)) | I35: =IF(Casos!$A$8="","",N(Casos!$F$8)) | J35: =IF(OR(Casos!$A$8="",D35="Interno"),"",I35-H35) | K35: =IF(OR(Casos!$A$8="",D35="Interno",I35=0),"",J35/I35) | L35: =IF(Casos!$A$8="","",IF(D35="Interno","Interno",IF(F35=0,"Sem horas",IF(H35>I35,"Consome mais do que paga",IF(AND(G35<>"",G35>1),"Estourou as horas",IF(AND(K35<>"",K35<0.2),"Margem baixa",IF(AND(G35<>"",G35>0.85),"Perto do limite","Saudável"))))))) | M35: =IF(OR(L35="Consome mais do que paga",L35="Margem baixa",L35="Estourou as horas"),IFERROR(H35/I35,9)+ROW()/1000000,0)
A36: =IF(Casos!$A$9="","",Casos!$A$9) | B36: =IF(Casos!$A$9="","",Casos!$B$9) | C36: =IF(Casos!$A$9="","",Casos!$D$9) | D36: =IF(Casos!$A$9="","",Casos!$E$9) | E36: =IF(Casos!$A$9="","",N(Casos!$G$9)) | F36: =IF(Casos!$A$9="","",N(Casos!$H$9)+SUMIFS(Lançamentos!$E$5:$E$604,Lançamentos!$C$5:$C$604,Casos!$A$9)) | G36: =IF(OR(Casos!$A$9="",E36=0),"",F36/E36) | H36: =IF(Casos!$A$9="","",N(Casos!$H$9)*Config!$B$23+SUMIFS(Lançamentos!$H$5:$H$604,Lançamentos!$C$5:$C$604,Casos!$A$9)) | I36: =IF(Casos!$A$9="","",N(Casos!$F$9)) | J36: =IF(OR(Casos!$A$9="",D36="Interno"),"",I36-H36) | K36: =IF(OR(Casos!$A$9="",D36="Interno",I36=0),"",J36/I36) | L36: =IF(Casos!$A$9="","",IF(D36="Interno","Interno",IF(F36=0,"Sem horas",IF(H36>I36,"Consome mais do que paga",IF(AND(G36<>"",G36>1),"Estourou as horas",IF(AND(K36<>"",K36<0.2),"Margem baixa",IF(AND(G36<>"",G36>0.85),"Perto do limite","Saudável"))))))) | M36: =IF(OR(L36="Consome mais do que paga",L36="Margem baixa",L36="Estourou as horas"),IFERROR(H36/I36,9)+ROW()/1000000,0)
A37: =IF(Casos!$A$10="","",Casos!$A$10) | B37: =IF(Casos!$A$10="","",Casos!$B$10) | C37: =IF(Casos!$A$10="","",Casos!$D$10) | D37: =IF(Casos!$A$10="","",Casos!$E$10) | E37: =IF(Casos!$A$10="","",N(Casos!$G$10)) | F37: =IF(Casos!$A$10="","",N(Casos!$H$10)+SUMIFS(Lançamentos!$E$5:$E$604,Lançamentos!$C$5:$C$604,Casos!$A$10)) | G37: =IF(OR(Casos!$A$10="",E37=0),"",F37/E37) | H37: =IF(Casos!$A$10="","",N(Casos!$H$10)*Config!$B$23+SUMIFS(Lançamentos!$H$5:$H$604,Lançamentos!$C$5:$C$604,Casos!$A$10)) | I37: =IF(Casos!$A$10="","",N(Casos!$F$10)) | J37: =IF(OR(Casos!$A$10="",D37="Interno"),"",I37-H37) | K37: =IF(OR(Casos!$A$10="",D37="Interno",I37=0),"",J37/I37) | L37: =IF(Casos!$A$10="","",IF(D37="Interno","Interno",IF(F37=0,"Sem horas",IF(H37>I37,"Consome mais do que paga",IF(AND(G37<>"",G37>1),"Estourou as horas",IF(AND(K37<>"",K37<0.2),"Margem baixa",IF(AND(G37<>"",G37>0.85),"Perto do limite","Saudável"))))))) | M37: =IF(OR(L37="Consome mais do que paga",L37="Margem baixa",L37="Estourou as horas"),IFERROR(H37/I37,9)+ROW()/1000000,0)
A38: =IF(Casos!$A$11="","",Casos!$A$11) | B38: =IF(Casos!$A$11="","",Casos!$B$11) | C38: =IF(Casos!$A$11="","",Casos!$D$11) | D38: =IF(Casos!$A$11="","",Casos!$E$11) | E38: =IF(Casos!$A$11="","",N(Casos!$G$11)) | F38: =IF(Casos!$A$11="","",N(Casos!$H$11)+SUMIFS(Lançamentos!$E$5:$E$604,Lançamentos!$C$5:$C$604,Casos!$A$11)) | G38: =IF(OR(Casos!$A$11="",E38=0),"",F38/E38) | H38: =IF(Casos!$A$11="","",N(Casos!$H$11)*Config!$B$23+SUMIFS(Lançamentos!$H$5:$H$604,Lançamentos!$C$5:$C$604,Casos!$A$11)) | I38: =IF(Casos!$A$11="","",N(Casos!$F$11)) | J38: =IF(OR(Casos!$A$11="",D38="Interno"),"",I38-H38) | K38: =IF(OR(Casos!$A$11="",D38="Interno",I38=0),"",J38/I38) | L38: =IF(Casos!$A$11="","",IF(D38="Interno","Interno",IF(F38=0,"Sem horas",IF(H38>I38,"Consome mais do que paga",IF(AND(G38<>"",G38>1),"Estourou as horas",IF(AND(K38<>"",K38<0.2),"Margem baixa",IF(AND(G38<>"",G38>0.85),"Perto do limite","Saudável"))))))) | M38: =IF(OR(L38="Consome mais do que paga",L38="Margem baixa",L38="Estourou as horas"),IFERROR(H38/I38,9)+ROW()/1000000,0)
A39: =IF(Casos!$A$12="","",Casos!$A$12) | B39: =IF(Casos!$A$12="","",Casos!$B$12) | C39: =IF(Casos!$A$12="","",Casos!$D$12) | D39: =IF(Casos!$A$12="","",Casos!$E$12) | E39: =IF(Casos!$A$12="","",N(Casos!$G$12)) | F39: =IF(Casos!$A$12="","",N(Casos!$H$12)+SUMIFS(Lançamentos!$E$5:$E$604,Lançamentos!$C$5:$C$604,Casos!$A$12)) | G39: =IF(OR(Casos!$A$12="",E39=0),"",F39/E39) | H39: =IF(Casos!$A$12="","",N(Casos!$H$12)*Config!$B$23+SUMIFS(Lançamentos!$H$5:$H$604,Lançamentos!$C$5:$C$604,Casos!$A$12)) | I39: =IF(Casos!$A$12="","",N(Casos!$F$12)) | J39: =IF(OR(Casos!$A$12="",D39="Interno"),"",I39-H39) | K39: =IF(OR(Casos!$A$12="",D39="Interno",I39=0),"",J39/I39) | L39: =IF(Casos!$A$12="","",IF(D39="Interno","Interno",IF(F39=0,"Sem horas",IF(H39>I39,"Consome mais do que paga",IF(AND(G39<>"",G39>1),"Estourou as horas",IF(AND(K39<>"",K39<0.2),"Margem baixa",IF(AND(G39<>"",G39>0.85),"Perto do limite","Saudável"))))))) | M39: =IF(OR(L39="Consome mais do que paga",L39="Margem baixa",L39="Estourou as horas"),IFERROR(H39/I39,9)+ROW()/1000000,0)
A40: =IF(Casos!$A$13="","",Casos!$A$13) | B40: =IF(Casos!$A$13="","",Casos!$B$13) | C40: =IF(Casos!$A$13="","",Casos!$D$13) | D40: =IF(Casos!$A$13="","",Casos!$E$13) | E40: =IF(Casos!$A$13="","",N(Casos!$G$13)) | F40: =IF(Casos!$A$13="","",N(Casos!$H$13)+SUMIFS(Lançamentos!$E$5:$E$604,Lançamentos!$C$5:$C$604,Casos!$A$13)) | G40: =IF(OR(Casos!$A$13="",E40=0),"",F40/E40) | H40: =IF(Casos!$A$13="","",N(Casos!$H$13)*Config!$B$23+SUMIFS(Lançamentos!$H$5:$H$604,Lançamentos!$C$5:$C$604,Casos!$A$13)) | I40: =IF(Casos!$A$13="","",N(Casos!$F$13)) | J40: =IF(OR(Casos!$A$13="",D40="Interno"),"",I40-H40) | K40: =IF(OR(Casos!$A$13="",D40="Interno",I40=0),"",J40/I40) | L40: =IF(Casos!$A$13="","",IF(D40="Interno","Interno",IF(F40=0,"Sem horas",IF(H40>I40,"Consome mais do que paga",IF(AND(G40<>"",G40>1),"Estourou as horas",IF(AND(K40<>"",K40<0.2),"Margem baixa",IF(AND(G40<>"",G40>0.85),"Perto do limite","Saudável"))))))) | M40: =IF(OR(L40="Consome mais do que paga",L40="Margem baixa",L40="Estourou as horas"),IFERROR(H40/I40,9)+ROW()/1000000,0)
A41: =IF(Casos!$A$14="","",Casos!$A$14) | B41: =IF(Casos!$A$14="","",Casos!$B$14) | C41: =IF(Casos!$A$14="","",Casos!$D$14) | D41: =IF(Casos!$A$14="","",Casos!$E$14) | E41: =IF(Casos!$A$14="","",N(Casos!$G$14)) | F41: =IF(Casos!$A$14="","",N(Casos!$H$14)+SUMIFS(Lançamentos!$E$5:$E$604,Lançamentos!$C$5:$C$604,Casos!$A$14)) | G41: =IF(OR(Casos!$A$14="",E41=0),"",F41/E41) | H41: =IF(Casos!$A$14="","",N(Casos!$H$14)*Config!$B$23+SUMIFS(Lançamentos!$H$5:$H$604,Lançamentos!$C$5:$C$604,Casos!$A$14)) | I41: =IF(Casos!$A$14="","",N(Casos!$F$14)) | J41: =IF(OR(Casos!$A$14="",D41="Interno"),"",I41-H41) | K41: =IF(OR(Casos!$A$14="",D41="Interno",I41=0),"",J41/I41) | L41: =IF(Casos!$A$14="","",IF(D41="Interno","Interno",IF(F41=0,"Sem horas",IF(H41>I41,"Consome mais do que paga",IF(AND(G41<>"",G41>1),"Estourou as horas",IF(AND(K41<>"",K41<0.2),"Margem baixa",IF(AND(G41<>"",G41>0.85),"Perto do limite","Saudável"))))))) | M41: =IF(OR(L41="Consome mais do que paga",L41="Margem baixa",L41="Estourou as horas"),IFERROR(H41/I41,9)+ROW()/1000000,0)
A42: =IF(Casos!$A$15="","",Casos!$A$15) | B42: =IF(Casos!$A$15="","",Casos!$B$15) | C42: =IF(Casos!$A$15="","",Casos!$D$15) | D42: =IF(Casos!$A$15="","",Casos!$E$15) | E42: =IF(Casos!$A$15="","",N(Casos!$G$15)) | F42: =IF(Casos!$A$15="","",N(Casos!$H$15)+SUMIFS(Lançamentos!$E$5:$E$604,Lançamentos!$C$5:$C$604,Casos!$A$15)) | G42: =IF(OR(Casos!$A$15="",E42=0),"",F42/E42) | H42: =IF(Casos!$A$15="","",N(Casos!$H$15)*Config!$B$23+SUMIFS(Lançamentos!$H$5:$H$604,Lançamentos!$C$5:$C$604,Casos!$A$15)) | I42: =IF(Casos!$A$15="","",N(Casos!$F$15)) | J42: =IF(OR(Casos!$A$15="",D42="Interno"),"",I42-H42) | K42: =IF(OR(Casos!$A$15="",D42="Interno",I42=0),"",J42/I42) | L42: =IF(Casos!$A$15="","",IF(D42="Interno","Interno",IF(F42=0,"Sem horas",IF(H42>I42,"Consome mais do que paga",IF(AND(G42<>"",G42>1),"Estourou as horas",IF(AND(K42<>"",K42<0.2),"Margem baixa",IF(AND(G42<>"",G42>0.85),"Perto do limite","Saudável"))))))) | M42: =IF(OR(L42="Consome mais do que paga",L42="Margem baixa",L42="Estourou as horas"),IFERROR(H42/I42,9)+ROW()/1000000,0)
A43: =IF(Casos!$A$16="","",Casos!$A$16) | B43: =IF(Casos!$A$16="","",Casos!$B$16) | C43: =IF(Casos!$A$16="","",Casos!$D$16) | D43: =IF(Casos!$A$16="","",Casos!$E$16) | E43: =IF(Casos!$A$16="","",N(Casos!$G$16)) | F43: =IF(Casos!$A$16="","",N(Casos!$H$16)+SUMIFS(Lançamentos!$E$5:$E$604,Lançamentos!$C$5:$C$604,Casos!$A$16)) | G43: =IF(OR(Casos!$A$16="",E43=0),"",F43/E43) | H43: =IF(Casos!$A$16="","",N(Casos!$H$16)*Config!$B$23+SUMIFS(Lançamentos!$H$5:$H$604,Lançamentos!$C$5:$C$604,Casos!$A$16)) | I43: =IF(Casos!$A$16="","",N(Casos!$F$16)) | J43: =IF(OR(Casos!$A$16="",D43="Interno"),"",I43-H43) | K43: =IF(OR(Casos!$A$16="",D43="Interno",I43=0),"",J43/I43) | L43: =IF(Casos!$A$16="","",IF(D43="Interno","Interno",IF(F43=0,"Sem horas",IF(H43>I43,"Consome mais do que paga",IF(AND(G43<>"",G43>1),"Estourou as horas",IF(AND(K43<>"",K43<0.2),"Margem baixa",IF(AND(G43<>"",G43>0.85),"Perto do limite","Saudável"))))))) | M43: =IF(OR(L43="Consome mais do que paga",L43="Margem baixa",L43="Estourou as horas"),IFERROR(H43/I43,9)+ROW()/1000000,0)
A44: =IF(Casos!$A$17="","",Casos!$A$17) | B44: =IF(Casos!$A$17="","",Casos!$B$17) | C44: =IF(Casos!$A$17="","",Casos!$D$17) | D44: =IF(Casos!$A$17="","",Casos!$E$17) | E44: =IF(Casos!$A$17="","",N(Casos!$G$17)) | F44: =IF(Casos!$A$17="","",N(Casos!$H$17)+SUMIFS(Lançamentos!$E$5:$E$604,Lançamentos!$C$5:$C$604,Casos!$A$17)) | G44: =IF(OR(Casos!$A$17="",E44=0),"",F44/E44) | H44: =IF(Casos!$A$17="","",N(Casos!$H$17)*Config!$B$23+SUMIFS(Lançamentos!$H$5:$H$604,Lançamentos!$C$5:$C$604,Casos!$A$17)) | I44: =IF(Casos!$A$17="","",N(Casos!$F$17)) | J44: =IF(OR(Casos!$A$17="",D44="Interno"),"",I44-H44) | K44: =IF(OR(Casos!$A$17="",D44="Interno",I44=0),"",J44/I44) | L44: =IF(Casos!$A$17="","",IF(D44="Interno","Interno",IF(F44=0,"Sem horas",IF(H44>I44,"Consome mais do que paga",IF(AND(G44<>"",G44>1),"Estourou as horas",IF(AND(K44<>"",K44<0.2),"Margem baixa",IF(AND(G44<>"",G44>0.85),"Perto do limite","Saudável"))))))) | M44: =IF(OR(L44="Consome mais do que paga",L44="Margem baixa",L44="Estourou as horas"),IFERROR(H44/I44,9)+ROW()/1000000,0)
...

Sheet Config
A1: Configurações
A2: Células amarelas: você preenche. Custo-hora de cada pessoa = custo mensal ÷ horas faturáveis + rateio dos custos fixos por hora.
A4: Escritório | B4: Ferraz & Lima Advocacia (exemplo fictício) | H4: Meses
A5: Ano | B5: 2026 | H5: Janeiro
A6: Mês do painel | B6: Agosto | H6: Fevereiro
A7: Número do mês | B7: =MATCH(B6,$H$5:$H$16,0) | H7: Março
A8: Custos fixos mensais, sem a equipe (R$) | B8: 5100 | C8: Copie da planilha 05 (Custo-hora): aluguel, contador, sistemas, telefone, anuidades, marketing e outros. Sem pró-labore e sem salários. | H8: Abril
H9: Maio
A10: Pessoas (até 10) | H10: Junho
A11: Pessoa | B11: Custo mensal (R$) | C11: Horas faturáveis por mês (meta) | D11: Custo-hora (R$) | F11: Atividades (até 12) | H11: Julho
A12: Marina Ferraz | B12: 6000 | C12: 110 | D12: =IF(OR(A12="",C12=0,C12=""),"",B12/C12+IFERROR($B$8/SUM($C$12:$C$21),0)) | F12: Reunião com cliente | H12: Agosto
A13: Rafael Lima | B13: 6000 | C13: 110 | D13: =IF(OR(A13="",C13=0,C13=""),"",B13/C13+IFERROR($B$8/SUM($C$12:$C$21),0)) | F13: Audiência | H13: Setembro
A14: Júlia Prado | B14: 1400 | C14: 60 | D14: =IF(OR(A14="",C14=0,C14=""),"",B14/C14+IFERROR($B$8/SUM($C$12:$C$21),0)) | F14: Elaboração de documento | H14: Outubro
D15: =IF(OR(A15="",C15=0,C15=""),"",B15/C15+IFERROR($B$8/SUM($C$12:$C$21),0)) | F15: Pesquisa e estudo do caso | H15: Novembro
D16: =IF(OR(A16="",C16=0,C16=""),"",B16/C16+IFERROR($B$8/SUM($C$12:$C$21),0)) | F16: Análise de documentos | H16: Dezembro
D17: =IF(OR(A17="",C17=0,C17=""),"",B17/C17+IFERROR($B$8/SUM($C$12:$C$21),0)) | F17: Atendimento por telefone ou WhatsApp
D18: =IF(OR(A18="",C18=0,C18=""),"",B18/C18+IFERROR($B$8/SUM($C$12:$C$21),0)) | F18: Diligência externa
D19: =IF(OR(A19="",C19=0,C19=""),"",B19/C19+IFERROR($B$8/SUM($C$12:$C$21),0)) | F19: Deslocamento
D20: =IF(OR(A20="",C20=0,C20=""),"",B20/C20+IFERROR($B$8/SUM($C$12:$C$21),0)) | F20: Administrativo do caso
D21: =IF(OR(A21="",C21=0,C21=""),"",B21/C21+IFERROR($B$8/SUM($C$12:$C$21),0)) | F21: Gestão do escritório
F22: Captação e propostas
A23: Custo-hora médio do escritório (R$) | B23: =IFERROR(($B$8+SUMIFS($B$12:$B$21,$A$12:$A$21,"<>"))/SUM($C$12:$C$21),0)
F24: Preencha de cima para baixo, sem pular linha.
A26: Custo mensal: pró-labore do sócio, ou salário mais encargos, ou a bolsa. Horas faturáveis por mês: quantas horas a pessoa consegue dedicar a casos (110 para um sócio que também administra; 60 para estagiário). O custo-hora médio vale para as horas lançadas antes de começar a usar esta planilha.

Sheet Casos
A1: Casos (entrada)
A2: Copie daqui da planilha 13 (Carteira): número, cliente, responsável, modalidade, valor e horas estimadas. Trabalho interno entra como modalidade Interno.
A4: Número do processo ou referência | B4: Cliente | C4: Área | D4: Responsável | E4: Modalidade | F4: Valor contratado (R$) | G4: Horas estimadas | H4: Horas gastas antes de usar esta planilha | I4: Fase
A5: 9236009-85.2026.8.26.0452 | B5: Padaria do Sol Ltda | C5: Empresarial | D5: Marina Ferraz | E5: Êxito | F5: 14400 | G5: 63 | H5: 36.5 | I5: Inicial
A6: 9225646-96.2026.8.26.0322 | B6: Ana Beatriz Moreira | C6: Trabalhista | D6: Rafael Lima | E6: Fixo | F6: 8000 | G6: 42 | H6: 24 | I6: Sentença
A7: 6710873-21.2025.8.26.0571 | B7: Construtora Horizonte | C7: Cível | D7: Marina Ferraz | E7: Misto | F7: 8100 | G7: 45 | H7: 48.5 | I7: Sentença
A8: 8735513-64.2025.8.26.0093 | B8: Carlos Eduardo Nunes | C8: Previdenciário | D8: Rafael Lima | E8: Êxito | F8: 5700 | G8: 25 | H8: 22.5 | I8: Recurso
A9: 9802211-43.2025.8.26.0431 | B9: Loja Verde Comércio | C9: Empresarial | D9: Marina Ferraz | E9: Misto | F9: 19600 | G9: 91 | H9: 84.5 | I9: Acordo
A10: 9778116-95.2026.8.26.0106 | B10: Fernanda Castro | C10: Família | D10: Marina Ferraz | E10: Fixo | F10: 9000 | G10: 38 | H10: 32.5 | I10: Encerrado
A11: 8875326-79.2026.8.26.0258 | B11: Bistrô 42 | C11: Trabalhista | D11: Rafael Lima | E11: Misto | F11: 4600 | G11: 24 | H11: 15.5 | I11: Acordo
A12: 4397912-47.2025.8.26.0276 | B12: Roberto Almeida | C12: Cível | D12: Marina Ferraz | E12: Êxito | F12: 11300 | G12: 60 | H12: 57 | I12: Acordo
A13: 4352718-43.2025.8.26.0498 | B13: Clínica Bem-Estar | C13: Empresarial | D13: Marina Ferraz | E13: Fixo | F13: 9300 | G13: 54 | H13: 8 | I13: Consultivo
A14: 2650441-66.2026.8.26.0528 | B14: Marcos Vinícius Teles | C14: Previdenciário | D14: Rafael Lima | E14: Misto | F14: 7800 | G14: 41 | H14: 3.5 | I14: Encerrado
A15: 5470559-73.2026.8.26.0380 | B15: Transportadora Rota Sul | C15: Trabalhista | D15: Rafael Lima | E15: Misto | F15: 10200 | G15: 54 | H15: 41.5 | I15: Recurso
A16: 8570388-84.2025.8.26.0560 | B16: Patrícia Gomes | C16: Família | D16: Marina Ferraz | E16: Hora | F16: 10400 | G16: 46 | H16: 26.5 | I16: Inicial
... A42: 7598076-58.2025.8.26.0552 | B42: Ana Beatriz Moreira | C42: Família | D42: Marina Ferraz | E42: Hora | F42: 11300 | G42: 63 | H42: 14.5 | I42: Encerrado
A43: Gestão do escritório | B43: Escritório (sem cliente) | C43: — | D43: Marina Ferraz | E43: Interno | F43: 0 | G43: 0 | H43: 0
A44: Captação e propostas | B44: Escritório (sem cliente) | C44: — | D44: Marina Ferraz | E44: Interno | F44: 0 | G44: 0 | H44: 0
A206: Horas gastas antes: se o caso já vinha de antes, anote quantas horas ele consumiu até o dia em que você começou a lançar aqui (uma estimativa honesta serve). Elas entram no total do caso pelo custo-hora médio.

Sheet Lançamentos
A1: Lançamentos de horas
A2: Uma linha por pessoa, por dia, por caso. Pessoa, caso e atividade vêm de listas; cliente, custo e mês são calculados.
A4: Data | B4: Pessoa | C4: Caso | D4: Atividade | E4: Horas | F4: Faturável? | G4: Cliente | H4: Custo (R$) | I4: Mês | J4: Ano
A5: 46204 | B5: Rafael Lima | C5: 9236009-85.2026.8.26.0452 | D5: Análise de documentos | E5: 3 | F5: Sim | G5: =IF(C5="","",IFERROR(INDEX(Casos!$B$5:$B$204,MATCH(C5,Casos!$A$5:$A$204,0)),"")) | H5: =IF(OR(B5="",E5=""),"",E5*IFERROR(INDEX(Config!$D$12:$D$21,MATCH(B5,Config!$A$12:$A$21,0)),Config!$B$23)) | I5: =IF(A5="","",MONTH(A5)) | J5: =IF(A5="","",YEAR(A5))
A6: 46205 | B6: Júlia Prado | C6: 9717671-36.2026.8.26.0445 | D6: Diligência externa | E6: 1.5 | F6: Sim | G6: =IF(C6="","",IFERROR(INDEX(Casos!$B$5:$B$204,MATCH(C6,Casos!$A$5:$A$204,0)),"")) | H6: =IF(OR(B6="",E6=""),"",E6*IFERROR(INDEX(Config!$D$12:$D$21,MATCH(B6,Config!$A$12:$A$21,0)),Config!$B$23)) | I6: =IF(A6="","",MONTH(A6)) | J6: =IF(A6="","",YEAR(A6))
A7: 46205 | B7: Marina Ferraz | C7: 6545676-47.2025.8.26.0126 | D7: Diligência externa | E7: 1.5 | F7: Sim | G7: =IF(C7="","",IFERROR(INDEX(Casos!$B$5:$B$204,MATCH(C7,Casos!$A$5:$A$204,0)),"")) | H7: =IF(OR(B7="",E7=""),"",E7*IFERROR(INDEX(Config!$D$12:$D$21,MATCH(B7,Config!$A$12:$A$21,0)),Config!$B$23)) | I7: =IF(A7="","",MONTH(A7)) | J7: =IF(A7="","",YEAR(A7))
A8: 46205 | B8: Rafael Lima | C8: 3930894-43.2025.8.26.0476 | D8: Audiência | E8: 2.5 | F8: Sim | G8: =IF(C8="","",IFERROR(INDEX(Casos!$B$5:$B$204,MATCH(C8,Casos!$A$5:$A$204,0)),"")) | H8: =IF(OR(B8="",E8=""),"",E8*IFERROR(INDEX(Config!$D$12:$D$21,MATCH(B8,Config!$A$12:$A$21,0)),Config!$B$23)) | I8: =IF(A8="","",MONTH(A8)) | J8: =IF(A8="","",YEAR(A8))
A9: 46206 | B9: Júlia Prado | C9: 9236009-85.2026.8.26.0452 | D9: Análise de documentos | E9: 2.5 | F9: Sim | G9: =IF(C9="","",IFERROR(INDEX(Casos!$B$5:$B$204,MATCH(C9,Casos!$A$5:$A$204,0)),"")) | H9: =IF(OR(B9="",E9=""),"",E9*IFERROR(INDEX(Config!$D$12:$D$21,MATCH(B9,Config!$A$12:$A$21,0)),Config!$B$23)) | I9: =IF(A9="","",MONTH(A9)) | J9: =IF(A9="","",YEAR(A9))
A10: 46206 | B10: Júlia Prado | C10: 9236009-85.2026.8.26.0452 | D10: Análise de documentos | E10: 3 | F10: Sim | G10: =IF(C10="","",IFERROR(INDEX(Casos!$B$5:$B$204,MATCH(C10,Casos!$A$5:$A$204,0)),"")) | H10: =IF(OR(B10="",E10=""),"",E10*IFERROR(INDEX(Config!$D$12:$D$21,MATCH(B10,Config!$A$12:$A$21,0)),Config!$B$23)) | I10: =IF(A10="","",MONTH(A10)) | J10: =IF(A10="","",YEAR(A10))
A11: 46206 | B11: Rafael Lima | C11: 5470559-73.2026.8.26.0380 | D11: Deslocamento | E11: 3 | F11: Não | G11: =IF(C11="","",IFERROR(INDEX(Casos!$B$5:$B$204,MATCH(C11,Casos!$A$5:$A$204,0)),"")) | H11: =IF(OR(B11="",E11=""),"",E11*IFERROR(INDEX(Config!$D$12:$D$21,MATCH(B11,Config!$A$12:$A$21,0)),Config!$B$23)) | I11: =IF(A11="","",MONTH(A11)) | J11: =IF(A11="","",YEAR(A11))
A12: 46209 | B12: Marina Ferraz | C12: 7598076-58.2025.8.26.0552 | D12: Administrativo do caso | E12: 0.5 | F12: Sim | G12: =IF(C12="","",IFERROR(INDEX(Casos!$B$5:$B$204,MATCH(C12,Casos!$A$5:$A$204,0)),"")) | H12: =IF(OR(B12="",E12=""),"",E12*IFERROR(INDEX(Config!$D$12:$D$21,MATCH(B12,Config!$A$12:$A$21,0)),Config!$B$23)) | I12: =IF(A12="","",MONTH(A12)) | J12: =IF(A12="","",YEAR(A12))
A13: 46209 | B13: Rafael Lima | C13: 9225646-96.2026.8.26.0322 | D13: Diligência externa | E13: 2 | F13: Sim | G13: =IF(C13="","",IFERROR(INDEX(Casos!$B$5:$B$204,MATCH(C13,Casos!$A$5:$A$204,0)),"")) | H13: =IF(OR(B13="",E13=""),"",E13*IFERROR(INDEX(Config!$D$12:$D$21,MATCH(B13,Config!$A$12:$A$21,0)),Config!$B$23)) | I13: =IF(A13="","",MONTH(A13)) | J13: =IF(A13="","",YEAR(A13))
A14: 46209 | B14: Rafael Lima | C14: Gestão do escritório | D14: Gestão do escritório | E14: 2.5 | F14: Não | G14: =IF(C14="","",IFERROR(INDEX(Casos!$B$5:$B$204,MATCH(C14,Casos!$A$5:$A$204,0)),"")) | H14: =IF(OR(B14="",E14=""),"",E14*IFERROR(INDEX(Config!$D$12:$D$21,MATCH(B14,Config!$A$12:$A$21,0)),Config!$B$23)) | I14: =IF(A14="","",MONTH(A14)) | J14: =IF(A14="","",YEAR(A14))
A15: 46210 | B15: Júlia Prado | C15: 8986364-51.2026.8.26.0700 | D15: Elaboração de documento | E15: 3.5 | F15: Sim | G15: =IF(C15="","",IFERROR(INDEX(Casos!$B$5:$B$204,MATCH(C15,Casos!$A$5:$A$204,0)),"")) | H15: =IF(OR(B15="",E15=""),"",E15*IFERROR(INDEX(Config!$D$12:$D$21,MATCH(B15,Config!$A$12:$A$21,0)),Config!$B$23)) | I15: =IF(A15="","",MONTH(A15)) | J15: =IF(A15="","",YEAR(A15))
A16: 46210 | B16: Marina Ferraz | C16: 8986364-51.2026.8.26.0700 | D16: Elaboração de documento | E16: 2.5 | F16: Sim | G16: =IF(C16="","",IFERROR(INDEX(Casos!$B$5:$B$204,MATCH(C16,Casos!$A$5:$A$204,0)),"")) | H16: =IF(OR(B16="",E16=""),"",E16*IFERROR(INDEX(Config!$D$12:$D$21,MATCH(B16,Config!$A$12:$A$21,0)),Config!$B$23)) | I16: =IF(A16="","",MONTH(A16)) | J16: =IF(A16="","",YEAR(A16))
... A259: 46279 | B259: Rafael Lima | C259: Captação e propostas | D259: Captação e propostas | E259: 1 | F259: Não | G259: =IF(C259="","",IFERROR(INDEX(Casos!$B$5:$B$204,MATCH(C259,Casos!$A$5:$A$204,0)),"")) | H259: =IF(OR(B259="",E259=""),"",E259*IFERROR(INDEX(Config!$D$12:$D$21,MATCH(B259,Config!$A$12:$A$21,0)),Config!$B$23)) | I259: =IF(A259="","",MONTH(A259)) | J259: =IF(A259="","",YEAR(A259))
G260: =IF(C260="","",IFERROR(INDEX(Casos!$B$5:$B$204,MATCH(C260,Casos!$A$5:$A$204,0)),"")) | H260: =IF(OR(B260="",E260=""),"",E260*IFERROR(INDEX(Config!$D$12:$D$21,MATCH(B260,Config!$A$12:$A$21,0)),Config!$B$23)) | I260: =IF(A260="","",MONTH(A260)) | J260: =IF(A260="","",YEAR(A260))
G261: =IF(C261="","",IFERROR(INDEX(Casos!$B$5:$B$204,MATCH(C261,Casos!$A$5:$A$204,0)),"")) | H261: =IF(OR(B261="",E261=""),"",E261*IFERROR(INDEX(Config!$D$12:$D$21,MATCH(B261,Config!$A$12:$A$21,0)),Config!$B$23)) | I261: =IF(A261="","",MONTH(A261)) | J261: =IF(A261="","",YEAR(A261))
G262: =IF(C262="","",IFERROR(INDEX(Casos!$B$5:$B$204,MATCH(C262,Casos!$A$5:$A$204,0)),"")) | H262: =IF(OR(B262="",E262=""),"",E262*IFERROR(INDEX(Config!$D$12:$D$21,MATCH(B262,Config!$A$12:$A$21,0)),Config!$B$23)) | I262: =IF(A262="","",MONTH(A262)) | J262: =IF(A262="","",YEAR(A262))
G263: =IF(C263="","",IFERROR(INDEX(Casos!$B$5:$B$204,MATCH(C263,Casos!$A$5:$A$204,0)),"")) | H263: =IF(OR(B263="",E263=""),"",E263*IFERROR(INDEX(Config!$D$12:$D$21,MATCH(B263,Config!$A$12:$A$21,0)),Config!$B$23)) | I263: =IF(A263="","",MONTH(A263)) | J263: =IF(A263="","",YEAR(A263))
G264: =IF(C264="","",IFERROR(INDEX(Casos!$B$5:$B$204,MATCH(C264,Casos!$A$5:$A$204,0)),"")) | H264: =IF(OR(B264="",E264=""),"",E264*IFERROR(INDEX(Config!$D$12:$D$21,MATCH(B264,Config!$A$12:$A$21,0)),Config!$B$23)) | I264: =IF(A264="","",MONTH(A264)) | J264: =IF(A264="","",YEAR(A264))
G265: =IF(C265="","",IFERROR(INDEX(Casos!$B$5:$B$204,MATCH(C265,Casos!$A$5:$A$204,0)),"")) | H265: =IF(OR(B265="",E265=""),"",E265*IFERROR(INDEX(Config!$D$12:$D$21,MATCH(B265,Config!$A$12:$A$21,0)),Config!$B$23)) | I265: =IF(A265="","",MONTH(A265)) | J265: =IF(A265="","",YEAR(A265))
G266: =IF(C266="","",IFERROR(INDEX(Casos!$B$5:$B$204,MATCH(C266,Casos!$A$5:$A$204,0)),"")) | H266: =IF(OR(B266="",E266=""),"",E266*IFERROR(INDEX(Config!$D$12:$D$21,MATCH(B266,Config!$A$12:$A$21,0)),Config!$B$23)) | I266: =IF(A266="","",MONTH(A266)) | J266: =IF(A266="","",YEAR(A266))
G267: =IF(C267="","",IFERROR(INDEX(Casos!$B$5:$B$204,MATCH(C267,Casos!$A$5:$A$204,0)),"")) | H267: =IF(OR(B267="",E267=""),"",E267*IFERROR(INDEX(Config!$D$12:$D$21,MATCH(B267,Config!$A$12:$A$21,0)),Config!$B$23)) | I267: =IF(A267="","",MONTH(A267)) | J267: =IF(A267="","",YEAR(A267))
G268: =IF(C268="","",IFERROR(INDEX(Casos!$B$5:$B$204,MATCH(C268,Casos!$A$5:$A$204,0)),"")) | H268: =IF(OR(B268="",E268=""),"",E268*IFERROR(INDEX(Config!$D$12:$D$21,MATCH(B268,Config!$A$12:$A$21,0)),Config!$B$23)) | I268: =IF(A268="","",MONTH(A268)) | J268: =IF(A268="","",YEAR(A268))
G269: =IF(C269="","",IFERROR(INDEX(Casos!$B$5:$B$204,MATCH(C269,Casos!$A$5:$A$204,0)),"")) | H269: =IF(OR(B269="",E269=""),"",E269*IFERROR(INDEX(Config!$D$12:$D$21,MATCH(B269,Config!$A$12:$A$21,0)),Config!$B$23)) | I269: =IF(A269="","",MONTH(A269)) | J269: =IF(A269="","",YEAR(A269))
G270: =IF(C270="","",IFERROR(INDEX(Casos!$B$5:$B$204,MATCH(C270,Casos!$A$5:$A$204,0)),"")) | H270: =IF(OR(B270="",E270=""),"",E270*IFERROR(INDEX(Config!$D$12:$D$21,MATCH(B270,Config!$A$12:$A$21,0)),Config!$B$23)) | I270: =IF(A270="","",MONTH(A270)) | J270: =IF(A270="","",YEAR(A270))
G271: =IF(C271="","",IFERROR(INDEX(Casos!$B$5:$B$204,MATCH(C271,Casos!$A$5:$A$204,0)),"")) | H271: =IF(OR(B271="",E271=""),"",E271*IFERROR(INDEX(Config!$D$12:$D$21,MATCH(B271,Config!$A$12:$A$21,0)),Config!$B$23)) | I271: =IF(A271="","",MONTH(A271)) | J271: =IF(A271="","",YEAR(A271))
... G604: =IF(C604="","",IFERROR(INDEX(Casos!$B$5:$B$204,MATCH(C604,Casos!$A$5:$A$204,0)),"")) | H604: =IF(OR(B604="",E604=""),"",E604*IFERROR(INDEX(Config!$D$12:$D$21,MATCH(B604,Config!$A$12:$A$21,0)),Config!$B$23)) | I604: =IF(A604="","",MONTH(A604)) | J604: =IF(A604="","",YEAR(A604))
A606: Faturável em vermelho: lançamento sem dizer se a hora é faturável. Faturável = hora que o cliente paga (direta ou dentro do valor fixo); reunião interna, deslocamento não cobrado e administração não são.
