Workbook

Sheet Como usar
A1: Faltas, remarcações e lista de retorno
A2: Kit de Gestão para Médicos · Seu Sócio Gestor · versão 1.0 (setembro de 2026)
A4: O que esta planilha faz | B4: Mede por que a agenda esvazia: taxa de falta por dia da semana, período, pagador e profissional, a série das últimas 8 semanas, quem faltou mais de uma vez no mês e a lista de retorno (pacientes que passaram do retorno previsto e não têm horário marcado).
A5: Passo 1 | B5: Em Config, confira as listas (iguais às da planilha 01) e, para cada procedimento, em quantos dias se espera o retorno. A data de referência fica em =HOJE().
A6: Passo 2 | B6: Em Agenda, cole as colunas A a K da Agenda da planilha 01 (a 01 é a fonte; não digite aqui uma agenda diferente). Toda sexta, cole de novo a agenda atualizada.
A7: Passo 3 | B7: Em Painel, escolha o mês em Config. Leia de cima para baixo: taxa de falta, onde ela é maior, a tendência semanal, a lista de retorno e os reincidentes.
A8: Rotina de segunda | B8: 4 minutos: a recepção liga ou manda mensagem para a lista de retorno (os 25 primeiros), oferece as vagas dos próximos 7 dias (Painel da 01) e registra as faltas da semana passada. Marque o retorno na 01: o paciente sai da lista sozinho. A rotina completa da semana (12 min na segunda, 18 na sexta) está na planilha 03.
A9: Limite e como estender | B9: A aba Agenda tem 3.000 linhas (5 a 3004), a mesma da planilha 01: cerca de 10 meses com 300 atendimentos por mês. Perto do fim, copie a última linha para baixo (desproteja a aba antes) e ajuste o número final nas fórmulas do Painel, ou comece um arquivo por ano junto com a 01.
A10: Ligação com as outras planilhas | B10: O Painel da clínica (17) copia a taxa de falta do mês e o tamanho da lista de retorno daqui. As metas do trimestre (19) acompanham os dois.
A11: Com a IA | B11: Copie "Por dia da semana" e "Por pagador" e use o prompt "Agenda 02 · Reduzir faltas sem brigar com o paciente" da biblioteca do kit; para a lista de retorno, "Agenda 03 · Mensagem de retorno educada" (sem nomes: a IA não precisa deles).
A12: Legenda | B12: Células amarelas: você preenche. Brancas: calculadas. Não é preciso mexer em nada fora do amarelo.
A13: Proteção | B13: Fórmulas protegidas sem senha. Para editar: Revisar > Desproteger planilha (Excel) ou Dados > Proteger intervalos (Google Sheets).
A14: Requisitos | B14: Excel 2016 ou mais novo, Microsoft 365 ou Google Sheets (só funções do Excel 2007+; nada de MÍNIMOSES, MÁXIMOSES ou UNIRTEXTO). No celular abre nos aplicativos; para preencher, use o computador.
A15: Dados de pacientes | B15: Guarde só o que a gestão precisa (nome, contato, valor, data). Nada de diagnóstico, prontuário ou exame nestas planilhas: o kit é gestão, não é prontuário. Veja o guia LGPD do kit antes de colar qualquer tabela em uma IA.
... A19: Suporte | B19: suporte@seusociogestor.com.br · resposta em até 5 dias úteis · reembolso em até 7 dias pelo mesmo canal.

Sheet Painel
A1: =Config!$B$4&" · Faltas, remarcações e lista de retorno · "&Config!$B$6&" de "&Config!$B$5 -> Clínica Vida Plena (exemplo fictício) · Faltas, remarcações e lista de retorno · Setembro de 2026
A2: Nada para digitar aqui. Escolha o mês em Config; tudo vem de Agenda. Taxa de falta = faltas ÷ (faltas + realizados).
A4: Taxa de falta no mês | C4: Faltas | E4: Realizados | G4: Cancelamentos | I4: Remarcações | K4: Na lista de retorno
A5: =IF(C5+E5=0,"",C5/(C5+E5)) -> 0.053097345 | C5: =COUNTIFS(Agenda!$H$5:$H$3004,"Falta",Agenda!$L$5:$L$3004,Config!$B$7,Agenda!$M$5:$M$3004,Config!$B$5) -> 6 | E5: =COUNTIFS(Agenda!$H$5:$H$3004,"Realizado",Agenda!$L$5:$L$3004,Config!$B$7,Agenda!$M$5:$M$3004,Config!$B$5) -> 107 | G5: =COUNTIFS(Agenda!$H$5:$H$3004,"Cancelado",Agenda!$L$5:$L$3004,Config!$B$7,Agenda!$M$5:$M$3004,Config!$B$5) -> 3 | I5: =COUNTIFS(Agenda!$H$5:$H$3004,"Remarcado",Agenda!$L$5:$L$3004,Config!$B$7,Agenda!$M$5:$M$3004,Config!$B$5) -> 0 | K5: =COUNTIF(Agenda!$T$5:$T$3004,"Sim") -> 8
A7: Cancelamento = o paciente avisou; remarcação = pediu outra data (o novo horário é outra linha). Falta = não veio e não avisou: é a que custa, porque o horário já não pode ser oferecido a ninguém. A lista de retorno vale para hoje, não só para o mês.
A9: Por dia da semana
A10: Dia da semana | B10: Realizados | C10: Faltas | D10: Taxa de falta | E10: Cancelamentos | F10: Remarcações | G10: Barra
A11: Segunda | B11: =IF(A11="","",COUNTIFS(Agenda!$N$5:$N$3004,A11,Agenda!$H$5:$H$3004,"Realizado",Agenda!$L$5:$L$3004,Config!$B$7,Agenda!$M$5:$M$3004,Config!$B$5)) -> 0 | C11: =IF(A11="","",COUNTIFS(Agenda!$N$5:$N$3004,A11,Agenda!$H$5:$H$3004,"Falta",Agenda!$L$5:$L$3004,Config!$B$7,Agenda!$M$5:$M$3004,Config!$B$5)) -> 0 | D11: =IF(A11="","",IF(B11+C11=0,"",C11/(B11+C11))) | E11: =IF(A11="","",COUNTIFS(Agenda!$N$5:$N$3004,A11,Agenda!$H$5:$H$3004,"Cancelado",Agenda!$L$5:$L$3004,Config!$B$7,Agenda!$M$5:$M$3004,Config!$B$5)) -> 0 | F11: =IF(A11="","",COUNTIFS(Agenda!$N$5:$N$3004,A11,Agenda!$H$5:$H$3004,"Remarcado",Agenda!$L$5:$L$3004,Config!$B$7,Agenda!$M$5:$M$3004,Config!$B$5)) -> 0 | G11: =IF(D11="","",REPT("█",ROUND(MIN(1,D11/0.25)*24,0)))
A12: Terça | B12: =IF(A12="","",COUNTIFS(Agenda!$N$5:$N$3004,A12,Agenda!$H$5:$H$3004,"Realizado",Agenda!$L$5:$L$3004,Config!$B$7,Agenda!$M$5:$M$3004,Config!$B$5)) -> 41 | C12: =IF(A12="","",COUNTIFS(Agenda!$N$5:$N$3004,A12,Agenda!$H$5:$H$3004,"Falta",Agenda!$L$5:$L$3004,Config!$B$7,Agenda!$M$5:$M$3004,Config!$B$5)) -> 2 | D12: =IF(A12="","",IF(B12+C12=0,"",C12/(B12+C12))) -> 0.046511628 | E12: =IF(A12="","",COUNTIFS(Agenda!$N$5:$N$3004,A12,Agenda!$H$5:$H$3004,"Cancelado",Agenda!$L$5:$L$3004,Config!$B$7,Agenda!$M$5:$M$3004,Config!$B$5)) -> 2 | F12: =IF(A12="","",COUNTIFS(Agenda!$N$5:$N$3004,A12,Agenda!$H$5:$H$3004,"Remarcado",Agenda!$L$5:$L$3004,Config!$B$7,Agenda!$M$5:$M$3004,Config!$B$5)) -> 0 | G12: =IF(D12="","",REPT("█",ROUND(MIN(1,D12/0.25)*24,0))) -> ████
A13: Quarta | B13: =IF(A13="","",COUNTIFS(Agenda!$N$5:$N$3004,A13,Agenda!$H$5:$H$3004,"Realizado",Agenda!$L$5:$L$3004,Config!$B$7,Agenda!$M$5:$M$3004,Config!$B$5)) -> 17 | C13: =IF(A13="","",COUNTIFS(Agenda!$N$5:$N$3004,A13,Agenda!$H$5:$H$3004,"Falta",Agenda!$L$5:$L$3004,Config!$B$7,Agenda!$M$5:$M$3004,Config!$B$5)) -> 0 | D13: =IF(A13="","",IF(B13+C13=0,"",C13/(B13+C13))) -> 0 | E13: =IF(A13="","",COUNTIFS(Agenda!$N$5:$N$3004,A13,Agenda!$H$5:$H$3004,"Cancelado",Agenda!$L$5:$L$3004,Config!$B$7,Agenda!$M$5:$M$3004,Config!$B$5)) -> 0 | F13: =IF(A13="","",COUNTIFS(Agenda!$N$5:$N$3004,A13,Agenda!$H$5:$H$3004,"Remarcado",Agenda!$L$5:$L$3004,Config!$B$7,Agenda!$M$5:$M$3004,Config!$B$5)) -> 0 | G13: =IF(D13="","",REPT("█",ROUND(MIN(1,D13/0.25)*24,0)))
A14: Quinta | B14: =IF(A14="","",COUNTIFS(Agenda!$N$5:$N$3004,A14,Agenda!$H$5:$H$3004,"Realizado",Agenda!$L$5:$L$3004,Config!$B$7,Agenda!$M$5:$M$3004,Config!$B$5)) -> 38 | C14: =IF(A14="","",COUNTIFS(Agenda!$N$5:$N$3004,A14,Agenda!$H$5:$H$3004,"Falta",Agenda!$L$5:$L$3004,Config!$B$7,Agenda!$M$5:$M$3004,Config!$B$5)) -> 2 | D14: =IF(A14="","",IF(B14+C14=0,"",C14/(B14+C14))) -> 0.05 | E14: =IF(A14="","",COUNTIFS(Agenda!$N$5:$N$3004,A14,Agenda!$H$5:$H$3004,"Cancelado",Agenda!$L$5:$L$3004,Config!$B$7,Agenda!$M$5:$M$3004,Config!$B$5)) -> 0 | F14: =IF(A14="","",COUNTIFS(Agenda!$N$5:$N$3004,A14,Agenda!$H$5:$H$3004,"Remarcado",Agenda!$L$5:$L$3004,Config!$B$7,Agenda!$M$5:$M$3004,Config!$B$5)) -> 0 | G14: =IF(D14="","",REPT("█",ROUND(MIN(1,D14/0.25)*24,0))) -> █████
A15: Sexta | B15: =IF(A15="","",COUNTIFS(Agenda!$N$5:$N$3004,A15,Agenda!$H$5:$H$3004,"Realizado",Agenda!$L$5:$L$3004,Config!$B$7,Agenda!$M$5:$M$3004,Config!$B$5)) -> 11 | C15: =IF(A15="","",COUNTIFS(Agenda!$N$5:$N$3004,A15,Agenda!$H$5:$H$3004,"Falta",Agenda!$L$5:$L$3004,Config!$B$7,Agenda!$M$5:$M$3004,Config!$B$5)) -> 2 | D15: =IF(A15="","",IF(B15+C15=0,"",C15/(B15+C15))) -> 0.15384615 | E15: =IF(A15="","",COUNTIFS(Agenda!$N$5:$N$3004,A15,Agenda!$H$5:$H$3004,"Cancelado",Agenda!$L$5:$L$3004,Config!$B$7,Agenda!$M$5:$M$3004,Config!$B$5)) -> 1 | F15: =IF(A15="","",COUNTIFS(Agenda!$N$5:$N$3004,A15,Agenda!$H$5:$H$3004,"Remarcado",Agenda!$L$5:$L$3004,Config!$B$7,Agenda!$M$5:$M$3004,Config!$B$5)) -> 0 | G15: =IF(D15="","",REPT("█",ROUND(MIN(1,D15/0.25)*24,0))) -> ███████████████
A16: Sábado | B16: =IF(A16="","",COUNTIFS(Agenda!$N$5:$N$3004,A16,Agenda!$H$5:$H$3004,"Realizado",Agenda!$L$5:$L$3004,Config!$B$7,Agenda!$M$5:$M$3004,Config!$B$5)) -> 0 | C16: =IF(A16="","",COUNTIFS(Agenda!$N$5:$N$3004,A16,Agenda!$H$5:$H$3004,"Falta",Agenda!$L$5:$L$3004,Config!$B$7,Agenda!$M$5:$M$3004,Config!$B$5)) -> 0 | D16: =IF(A16="","",IF(B16+C16=0,"",C16/(B16+C16))) | E16: =IF(A16="","",COUNTIFS(Agenda!$N$5:$N$3004,A16,Agenda!$H$5:$H$3004,"Cancelado",Agenda!$L$5:$L$3004,Config!$B$7,Agenda!$M$5:$M$3004,Config!$B$5)) -> 0 | F16: =IF(A16="","",COUNTIFS(Agenda!$N$5:$N$3004,A16,Agenda!$H$5:$H$3004,"Remarcado",Agenda!$L$5:$L$3004,Config!$B$7,Agenda!$M$5:$M$3004,Config!$B$5)) -> 0 | G16: =IF(D16="","",REPT("█",ROUND(MIN(1,D16/0.25)*24,0)))
A18: Por período
A19: Período | B19: Realizados | C19: Faltas | D19: Taxa de falta | E19: Cancelamentos | F19: Remarcações | G19: Barra
A20: Manhã | B20: =IF(A20="","",COUNTIFS(Agenda!$O$5:$O$3004,A20,Agenda!$H$5:$H$3004,"Realizado",Agenda!$L$5:$L$3004,Config!$B$7,Agenda!$M$5:$M$3004,Config!$B$5)) -> 41 | C20: =IF(A20="","",COUNTIFS(Agenda!$O$5:$O$3004,A20,Agenda!$H$5:$H$3004,"Falta",Agenda!$L$5:$L$3004,Config!$B$7,Agenda!$M$5:$M$3004,Config!$B$5)) -> 3 | D20: =IF(A20="","",IF(B20+C20=0,"",C20/(B20+C20))) -> 0.068181818 | E20: =IF(A20="","",COUNTIFS(Agenda!$O$5:$O$3004,A20,Agenda!$H$5:$H$3004,"Cancelado",Agenda!$L$5:$L$3004,Config!$B$7,Agenda!$M$5:$M$3004,Config!$B$5)) -> 2 | F20: =IF(A20="","",COUNTIFS(Agenda!$O$5:$O$3004,A20,Agenda!$H$5:$H$3004,"Remarcado",Agenda!$L$5:$L$3004,Config!$B$7,Agenda!$M$5:$M$3004,Config!$B$5)) -> 0 | G20: =IF(D20="","",REPT("█",ROUND(MIN(1,D20/0.25)*24,0))) -> ███████
A21: Tarde | B21: =IF(A21="","",COUNTIFS(Agenda!$O$5:$O$3004,A21,Agenda!$H$5:$H$3004,"Realizado",Agenda!$L$5:$L$3004,Config!$B$7,Agenda!$M$5:$M$3004,Config!$B$5)) -> 66 | C21: =IF(A21="","",COUNTIFS(Agenda!$O$5:$O$3004,A21,Agenda!$H$5:$H$3004,"Falta",Agenda!$L$5:$L$3004,Config!$B$7,Agenda!$M$5:$M$3004,Config!$B$5)) -> 3 | D21: =IF(A21="","",IF(B21+C21=0,"",C21/(B21+C21))) -> 0.043478261 | E21: =IF(A21="","",COUNTIFS(Agenda!$O$5:$O$3004,A21,Agenda!$H$5:$H$3004,"Cancelado",Agenda!$L$5:$L$3004,Config!$B$7,Agenda!$M$5:$M$3004,Config!$B$5)) -> 1 | F21: =IF(A21="","",COUNTIFS(Agenda!$O$5:$O$3004,A21,Agenda!$H$5:$H$3004,"Remarcado",Agenda!$L$5:$L$3004,Config!$B$7,Agenda!$M$5:$M$3004,Config!$B$5)) -> 0 | G21: =IF(D21="","",REPT("█",ROUND(MIN(1,D21/0.25)*24,0))) -> ████
A22: Noite | B22: =IF(A22="","",COUNTIFS(Agenda!$O$5:$O$3004,A22,Agenda!$H$5:$H$3004,"Realizado",Agenda!$L$5:$L$3004,Config!$B$7,Agenda!$M$5:$M$3004,Config!$B$5)) -> 0 | C22: =IF(A22="","",COUNTIFS(Agenda!$O$5:$O$3004,A22,Agenda!$H$5:$H$3004,"Falta",Agenda!$L$5:$L$3004,Config!$B$7,Agenda!$M$5:$M$3004,Config!$B$5)) -> 0 | D22: =IF(A22="","",IF(B22+C22=0,"",C22/(B22+C22))) | E22: =IF(A22="","",COUNTIFS(Agenda!$O$5:$O$3004,A22,Agenda!$H$5:$H$3004,"Cancelado",Agenda!$L$5:$L$3004,Config!$B$7,Agenda!$M$5:$M$3004,Config!$B$5)) -> 0 | F22: =IF(A22="","",COUNTIFS(Agenda!$O$5:$O$3004,A22,Agenda!$H$5:$H$3004,"Remarcado",Agenda!$L$5:$L$3004,Config!$B$7,Agenda!$M$5:$M$3004,Config!$B$5)) -> 0 | G22: =IF(D22="","",REPT("█",ROUND(MIN(1,D22/0.25)*24,0)))
A24: Por pagador
A25: Pagador | B25: Realizados | C25: Faltas | D25: Taxa de falta | E25: Cancelamentos | F25: Remarcações | G25: Barra
A26: =IF(Config!$F$5="","",Config!$F$5) -> Particular | B26: =IF(A26="","",COUNTIFS(Agenda!$F$5:$F$3004,A26,Agenda!$H$5:$H$3004,"Realizado",Agenda!$L$5:$L$3004,Config!$B$7,Agenda!$M$5:$M$3004,Config!$B$5)) -> 55 | C26: =IF(A26="","",COUNTIFS(Agenda!$F$5:$F$3004,A26,Agenda!$H$5:$H$3004,"Falta",Agenda!$L$5:$L$3004,Config!$B$7,Agenda!$M$5:$M$3004,Config!$B$5)) -> 2 | D26: =IF(A26="","",IF(B26+C26=0,"",C26/(B26+C26))) -> 0.035087719 | E26: =IF(A26="","",COUNTIFS(Agenda!$F$5:$F$3004,A26,Agenda!$H$5:$H$3004,"Cancelado",Agenda!$L$5:$L$3004,Config!$B$7,Agenda!$M$5:$M$3004,Config!$B$5)) -> 1 | F26: =IF(A26="","",COUNTIFS(Agenda!$F$5:$F$3004,A26,Agenda!$H$5:$H$3004,"Remarcado",Agenda!$L$5:$L$3004,Config!$B$7,Agenda!$M$5:$M$3004,Config!$B$5)) -> 0 | G26: =IF(D26="","",REPT("█",ROUND(MIN(1,D26/0.25)*24,0))) -> ███
A27: =IF(Config!$F$6="","",Config!$F$6) -> Saúde Total | B27: =IF(A27="","",COUNTIFS(Agenda!$F$5:$F$3004,A27,Agenda!$H$5:$H$3004,"Realizado",Agenda!$L$5:$L$3004,Config!$B$7,Agenda!$M$5:$M$3004,Config!$B$5)) -> 26 | C27: =IF(A27="","",COUNTIFS(Agenda!$F$5:$F$3004,A27,Agenda!$H$5:$H$3004,"Falta",Agenda!$L$5:$L$3004,Config!$B$7,Agenda!$M$5:$M$3004,Config!$B$5)) -> 2 | D27: =IF(A27="","",IF(B27+C27=0,"",C27/(B27+C27))) -> 0.071428571 | E27: =IF(A27="","",COUNTIFS(Agenda!$F$5:$F$3004,A27,Agenda!$H$5:$H$3004,"Cancelado",Agenda!$L$5:$L$3004,Config!$B$7,Agenda!$M$5:$M$3004,Config!$B$5)) -> 0 | F27: =IF(A27="","",COUNTIFS(Agenda!$F$5:$F$3004,A27,Agenda!$H$5:$H$3004,"Remarcado",Agenda!$L$5:$L$3004,Config!$B$7,Agenda!$M$5:$M$3004,Config!$B$5)) -> 0 | G27: =IF(D27="","",REPT("█",ROUND(MIN(1,D27/0.25)*24,0))) -> ███████
A28: =IF(Config!$F$7="","",Config!$F$7) -> MediPlan | B28: =IF(A28="","",COUNTIFS(Agenda!$F$5:$F$3004,A28,Agenda!$H$5:$H$3004,"Realizado",Agenda!$L$5:$L$3004,Config!$B$7,Agenda!$M$5:$M$3004,Config!$B$5)) -> 19 | C28: =IF(A28="","",COUNTIFS(Agenda!$F$5:$F$3004,A28,Agenda!$H$5:$H$3004,"Falta",Agenda!$L$5:$L$3004,Config!$B$7,Agenda!$M$5:$M$3004,Config!$B$5)) -> 1 | D28: =IF(A28="","",IF(B28+C28=0,"",C28/(B28+C28))) -> 0.05 | E28: =IF(A28="","",COUNTIFS(Agenda!$F$5:$F$3004,A28,Agenda!$H$5:$H$3004,"Cancelado",Agenda!$L$5:$L$3004,Config!$B$7,Agenda!$M$5:$M$3004,Config!$B$5)) -> 1 | F28: =IF(A28="","",COUNTIFS(Agenda!$F$5:$F$3004,A28,Agenda!$H$5:$H$3004,"Remarcado",Agenda!$L$5:$L$3004,Config!$B$7,Agenda!$M$5:$M$3004,Config!$B$5)) -> 0 | G28: =IF(D28="","",REPT("█",ROUND(MIN(1,D28/0.25)*24,0))) -> █████
A29: =IF(Config!$F$8="","",Config!$F$8) -> Vida Care | B29: =IF(A29="","",COUNTIFS(Agenda!$F$5:$F$3004,A29,Agenda!$H$5:$H$3004,"Realizado",Agenda!$L$5:$L$3004,Config!$B$7,Agenda!$M$5:$M$3004,Config!$B$5)) -> 7 | C29: =IF(A29="","",COUNTIFS(Agenda!$F$5:$F$3004,A29,Agenda!$H$5:$H$3004,"Falta",Agenda!$L$5:$L$3004,Config!$B$7,Agenda!$M$5:$M$3004,Config!$B$5)) -> 1 | D29: =IF(A29="","",IF(B29+C29=0,"",C29/(B29+C29))) -> 0.125 | E29: =IF(A29="","",COUNTIFS(Agenda!$F$5:$F$3004,A29,Agenda!$H$5:$H$3004,"Cancelado",Agenda!$L$5:$L$3004,Config!$B$7,Agenda!$M$5:$M$3004,Config!$B$5)) -> 1 | F29: =IF(A29="","",COUNTIFS(Agenda!$F$5:$F$3004,A29,Agenda!$H$5:$H$3004,"Remarcado",Agenda!$L$5:$L$3004,Config!$B$7,Agenda!$M$5:$M$3004,Config!$B$5)) -> 0 | G29: =IF(D29="","",REPT("█",ROUND(MIN(1,D29/0.25)*24,0))) -> ████████████
A30: =IF(Config!$F$9="","",Config!$F$9) | B30: =IF(A30="","",COUNTIFS(Agenda!$F$5:$F$3004,A30,Agenda!$H$5:$H$3004,"Realizado",Agenda!$L$5:$L$3004,Config!$B$7,Agenda!$M$5:$M$3004,Config!$B$5)) | C30: =IF(A30="","",COUNTIFS(Agenda!$F$5:$F$3004,A30,Agenda!$H$5:$H$3004,"Falta",Agenda!$L$5:$L$3004,Config!$B$7,Agenda!$M$5:$M$3004,Config!$B$5)) | D30: =IF(A30="","",IF(B30+C30=0,"",C30/(B30+C30))) | E30: =IF(A30="","",COUNTIFS(Agenda!$F$5:$F$3004,A30,Agenda!$H$5:$H$3004,"Cancelado",Agenda!$L$5:$L$3004,Config!$B$7,Agenda!$M$5:$M$3004,Config!$B$5)) | F30: =IF(A30="","",COUNTIFS(Agenda!$F$5:$F$3004,A30,Agenda!$H$5:$H$3004,"Remarcado",Agenda!$L$5:$L$3004,Config!$B$7,Agenda!$M$5:$M$3004,Config!$B$5)) | G30: =IF(D30="","",REPT("█",ROUND(MIN(1,D30/0.25)*24,0)))
A31: =IF(Config!$F$10="","",Config!$F$10) | B31: =IF(A31="","",COUNTIFS(Agenda!$F$5:$F$3004,A31,Agenda!$H$5:$H$3004,"Realizado",Agenda!$L$5:$L$3004,Config!$B$7,Agenda!$M$5:$M$3004,Config!$B$5)) | C31: =IF(A31="","",COUNTIFS(Agenda!$F$5:$F$3004,A31,Agenda!$H$5:$H$3004,"Falta",Agenda!$L$5:$L$3004,Config!$B$7,Agenda!$M$5:$M$3004,Config!$B$5)) | D31: =IF(A31="","",IF(B31+C31=0,"",C31/(B31+C31))) | E31: =IF(A31="","",COUNTIFS(Agenda!$F$5:$F$3004,A31,Agenda!$H$5:$H$3004,"Cancelado",Agenda!$L$5:$L$3004,Config!$B$7,Agenda!$M$5:$M$3004,Config!$B$5)) | F31: =IF(A31="","",COUNTIFS(Agenda!$F$5:$F$3004,A31,Agenda!$H$5:$H$3004,"Remarcado",Agenda!$L$5:$L$3004,Config!$B$7,Agenda!$M$5:$M$3004,Config!$B$5)) | G31: =IF(D31="","",REPT("█",ROUND(MIN(1,D31/0.25)*24,0)))
A33: Por profissional
A34: Profissional | B34: Realizados | C34: Faltas | D34: Taxa de falta | E34: Cancelamentos | F34: Remarcações | G34: Barra
A35: =IF(Config!$D$5="","",Config!$D$5) -> Dra. Carolina Mendes | B35: =IF(A35="","",COUNTIFS(Agenda!$C$5:$C$3004,A35,Agenda!$H$5:$H$3004,"Realizado",Agenda!$L$5:$L$3004,Config!$B$7,Agenda!$M$5:$M$3004,Config!$B$5)) -> 47 | C35: =IF(A35="","",COUNTIFS(Agenda!$C$5:$C$3004,A35,Agenda!$H$5:$H$3004,"Falta",Agenda!$L$5:$L$3004,Config!$B$7,Agenda!$M$5:$M$3004,Config!$B$5)) -> 1 | D35: =IF(A35="","",IF(B35+C35=0,"",C35/(B35+C35))) -> 0.020833333 | E35: =IF(A35="","",COUNTIFS(Agenda!$C$5:$C$3004,A35,Agenda!$H$5:$H$3004,"Cancelado",Agenda!$L$5:$L$3004,Config!$B$7,Agenda!$M$5:$M$3004,Config!$B$5)) -> 1 | F35: =IF(A35="","",COUNTIFS(Agenda!$C$5:$C$3004,A35,Agenda!$H$5:$H$3004,"Remarcado",Agenda!$L$5:$L$3004,Config!$B$7,Agenda!$M$5:$M$3004,Config!$B$5)) -> 0 | G35: =IF(D35="","",REPT("█",ROUND(MIN(1,D35/0.25)*24,0))) -> ██
A36: =IF(Config!$D$6="","",Config!$D$6) -> Dr. Paulo Andrade | B36: =IF(A36="","",COUNTIFS(Agenda!$C$5:$C$3004,A36,Agenda!$H$5:$H$3004,"Realizado",Agenda!$L$5:$L$3004,Config!$B$7,Agenda!$M$5:$M$3004,Config!$B$5)) -> 36 | C36: =IF(A36="","",COUNTIFS(Agenda!$C$5:$C$3004,A36,Agenda!$H$5:$H$3004,"Falta",Agenda!$L$5:$L$3004,Config!$B$7,Agenda!$M$5:$M$3004,Config!$B$5)) -> 4 | D36: =IF(A36="","",IF(B36+C36=0,"",C36/(B36+C36))) -> 0.1 | E36: =IF(A36="","",COUNTIFS(Agenda!$C$5:$C$3004,A36,Agenda!$H$5:$H$3004,"Cancelado",Agenda!$L$5:$L$3004,Config!$B$7,Agenda!$M$5:$M$3004,Config!$B$5)) -> 2 | F36: =IF(A36="","",COUNTIFS(Agenda!$C$5:$C$3004,A36,Agenda!$H$5:$H$3004,"Remarcado",Agenda!$L$5:$L$3004,Config!$B$7,Agenda!$M$5:$M$3004,Config!$B$5)) -> 0 | G36: =IF(D36="","",REPT("█",ROUND(MIN(1,D36/0.25)*24,0))) -> ██████████
A37: =IF(Config!$D$7="","",Config!$D$7) -> Dra. Renata Sousa | B37: =IF(A37="","",COUNTIFS(Agenda!$C$5:$C$3004,A37,Agenda!$H$5:$H$3004,"Realizado",Agenda!$L$5:$L$3004,Config!$B$7,Agenda!$M$5:$M$3004,Config!$B$5)) -> 24 | C37: =IF(A37="","",COUNTIFS(Agenda!$C$5:$C$3004,A37,Agenda!$H$5:$H$3004,"Falta",Agenda!$L$5:$L$3004,Config!$B$7,Agenda!$M$5:$M$3004,Config!$B$5)) -> 1 | D37: =IF(A37="","",IF(B37+C37=0,"",C37/(B37+C37))) -> 0.04 | E37: =IF(A37="","",COUNTIFS(Agenda!$C$5:$C$3004,A37,Agenda!$H$5:$H$3004,"Cancelado",Agenda!$L$5:$L$3004,Config!$B$7,Agenda!$M$5:$M$3004,Config!$B$5)) -> 0 | F37: =IF(A37="","",COUNTIFS(Agenda!$C$5:$C$3004,A37,Agenda!$H$5:$H$3004,"Remarcado",Agenda!$L$5:$L$3004,Config!$B$7,Agenda!$M$5:$M$3004,Config!$B$5)) -> 0 | G37: =IF(D37="","",REPT("█",ROUND(MIN(1,D37/0.25)*24,0))) -> ████
A38: =IF(Config!$D$8="","",Config!$D$8) | B38: =IF(A38="","",COUNTIFS(Agenda!$C$5:$C$3004,A38,Agenda!$H$5:$H$3004,"Realizado",Agenda!$L$5:$L$3004,Config!$B$7,Agenda!$M$5:$M$3004,Config!$B$5)) | C38: =IF(A38="","",COUNTIFS(Agenda!$C$5:$C$3004,A38,Agenda!$H$5:$H$3004,"Falta",Agenda!$L$5:$L$3004,Config!$B$7,Agenda!$M$5:$M$3004,Config!$B$5)) | D38: =IF(A38="","",IF(B38+C38=0,"",C38/(B38+C38))) | E38: =IF(A38="","",COUNTIFS(Agenda!$C$5:$C$3004,A38,Agenda!$H$5:$H$3004,"Cancelado",Agenda!$L$5:$L$3004,Config!$B$7,Agenda!$M$5:$M$3004,Config!$B$5)) | F38: =IF(A38="","",COUNTIFS(Agenda!$C$5:$C$3004,A38,Agenda!$H$5:$H$3004,"Remarcado",Agenda!$L$5:$L$3004,Config!$B$7,Agenda!$M$5:$M$3004,Config!$B$5)) | G38: =IF(D38="","",REPT("█",ROUND(MIN(1,D38/0.25)*24,0)))
A39: =IF(Config!$D$9="","",Config!$D$9) | B39: =IF(A39="","",COUNTIFS(Agenda!$C$5:$C$3004,A39,Agenda!$H$5:$H$3004,"Realizado",Agenda!$L$5:$L$3004,Config!$B$7,Agenda!$M$5:$M$3004,Config!$B$5)) | C39: =IF(A39="","",COUNTIFS(Agenda!$C$5:$C$3004,A39,Agenda!$H$5:$H$3004,"Falta",Agenda!$L$5:$L$3004,Config!$B$7,Agenda!$M$5:$M$3004,Config!$B$5)) | D39: =IF(A39="","",IF(B39+C39=0,"",C39/(B39+C39))) | E39: =IF(A39="","",COUNTIFS(Agenda!$C$5:$C$3004,A39,Agenda!$H$5:$H$3004,"Cancelado",Agenda!$L$5:$L$3004,Config!$B$7,Agenda!$M$5:$M$3004,Config!$B$5)) | F39: =IF(A39="","",COUNTIFS(Agenda!$C$5:$C$3004,A39,Agenda!$H$5:$H$3004,"Remarcado",Agenda!$L$5:$L$3004,Config!$B$7,Agenda!$M$5:$M$3004,Config!$B$5)) | G39: =IF(D39="","",REPT("█",ROUND(MIN(1,D39/0.25)*24,0)))
A40: =IF(Config!$D$10="","",Config!$D$10) | B40: =IF(A40="","",COUNTIFS(Agenda!$C$5:$C$3004,A40,Agenda!$H$5:$H$3004,"Realizado",Agenda!$L$5:$L$3004,Config!$B$7,Agenda!$M$5:$M$3004,Config!$B$5)) | C40: =IF(A40="","",COUNTIFS(Agenda!$C$5:$C$3004,A40,Agenda!$H$5:$H$3004,"Falta",Agenda!$L$5:$L$3004,Config!$B$7,Agenda!$M$5:$M$3004,Config!$B$5)) | D40: =IF(A40="","",IF(B40+C40=0,"",C40/(B40+C40))) | E40: =IF(A40="","",COUNTIFS(Agenda!$C$5:$C$3004,A40,Agenda!$H$5:$H$3004,"Cancelado",Agenda!$L$5:$L$3004,Config!$B$7,Agenda!$M$5:$M$3004,Config!$B$5)) | F40: =IF(A40="","",COUNTIFS(Agenda!$C$5:$C$3004,A40,Agenda!$H$5:$H$3004,"Remarcado",Agenda!$L$5:$L$3004,Config!$B$7,Agenda!$M$5:$M$3004,Config!$B$5)) | G40: =IF(D40="","",REPT("█",ROUND(MIN(1,D40/0.25)*24,0)))
A41: =IF(Config!$D$11="","",Config!$D$11) | B41: =IF(A41="","",COUNTIFS(Agenda!$C$5:$C$3004,A41,Agenda!$H$5:$H$3004,"Realizado",Agenda!$L$5:$L$3004,Config!$B$7,Agenda!$M$5:$M$3004,Config!$B$5)) | C41: =IF(A41="","",COUNTIFS(Agenda!$C$5:$C$3004,A41,Agenda!$H$5:$H$3004,"Falta",Agenda!$L$5:$L$3004,Config!$B$7,Agenda!$M$5:$M$3004,Config!$B$5)) | D41: =IF(A41="","",IF(B41+C41=0,"",C41/(B41+C41))) | E41: =IF(A41="","",COUNTIFS(Agenda!$C$5:$C$3004,A41,Agenda!$H$5:$H$3004,"Cancelado",Agenda!$L$5:$L$3004,Config!$B$7,Agenda!$M$5:$M$3004,Config!$B$5)) | F41: =IF(A41="","",COUNTIFS(Agenda!$C$5:$C$3004,A41,Agenda!$H$5:$H$3004,"Remarcado",Agenda!$L$5:$L$3004,Config!$B$7,Agenda!$M$5:$M$3004,Config!$B$5)) | G41: =IF(D41="","",REPT("█",ROUND(MIN(1,D41/0.25)*24,0)))
A42: =IF(Config!$D$12="","",Config!$D$12) | B42: =IF(A42="","",COUNTIFS(Agenda!$C$5:$C$3004,A42,Agenda!$H$5:$H$3004,"Realizado",Agenda!$L$5:$L$3004,Config!$B$7,Agenda!$M$5:$M$3004,Config!$B$5)) | C42: =IF(A42="","",COUNTIFS(Agenda!$C$5:$C$3004,A42,Agenda!$H$5:$H$3004,"Falta",Agenda!$L$5:$L$3004,Config!$B$7,Agenda!$M$5:$M$3004,Config!$B$5)) | D42: =IF(A42="","",IF(B42+C42=0,"",C42/(B42+C42))) | E42: =IF(A42="","",COUNTIFS(Agenda!$C$5:$C$3004,A42,Agenda!$H$5:$H$3004,"Cancelado",Agenda!$L$5:$L$3004,Config!$B$7,Agenda!$M$5:$M$3004,Config!$B$5)) | F42: =IF(A42="","",COUNTIFS(Agenda!$C$5:$C$3004,A42,Agenda!$H$5:$H$3004,"Remarcado",Agenda!$L$5:$L$3004,Config!$B$7,Agenda!$M$5:$M$3004,Config!$B$5)) | G42: =IF(D42="","",REPT("█",ROUND(MIN(1,D42/0.25)*24,0)))
A43: Taxa acima de 10 % em vermelho. A barra vai até 25 %. Compare pagadores e dias antes de decidir a regra de confirmação (mensagem de véspera, lista de espera, política de remarcação).
A45: Últimas 8 semanas (segunda a domingo)
A46: Semana | B46: Segunda-feira | C46: Realizados | D46: Faltas | E46: Taxa de falta | F46: Cancelamentos | G46: Remarcações | H46: Barra
A47: ="S"&TEXT(B47,"dd/mm") -> S27/07 | B47: =Config!$B$8-WEEKDAY(Config!$B$8,2)+1-49 -> 46230 | C47: =COUNTIFS(Agenda!$A$5:$A$3004,">="&B47,Agenda!$A$5:$A$3004,"<="&B47+6,Agenda!$H$5:$H$3004,"Realizado") -> 57 | D47: =COUNTIFS(Agenda!$A$5:$A$3004,">="&B47,Agenda!$A$5:$A$3004,"<="&B47+6,Agenda!$H$5:$H$3004,"Falta") -> 7 | E47: =IF(C47+D47=0,"",D47/(C47+D47)) -> 0.109375 | F47: =COUNTIFS(Agenda!$A$5:$A$3004,">="&B47,Agenda!$A$5:$A$3004,"<="&B47+6,Agenda!$H$5:$H$3004,"Cancelado") -> 2 | G47: =COUNTIFS(Agenda!$A$5:$A$3004,">="&B47,Agenda!$A$5:$A$3004,"<="&B47+6,Agenda!$H$5:$H$3004,"Remarcado") -> 1 | H47: =IF(E47="","",REPT("█",ROUND(MIN(1,E47/0.25)*24,0))) -> ███████████
...

Sheet Config
A1: Configurações
A2: Células amarelas: você preenche. Listas iguais às da planilha 01; o retorno esperado por procedimento monta a lista de retorno.
A4: Clínica | B4: Clínica Vida Plena (exemplo fictício) | D4: Profissionais (até 8) | F4: Pagadores (até 6) | H4: Procedimentos (até 12) | I4: Retorno em (dias) | L4: Meses
A5: Ano do painel | B5: 2026 | D5: Dra. Carolina Mendes | F5: Particular | H5: Consulta | I5: 30 | L5: Janeiro
A6: Mês do painel | B6: Setembro | D6: Dr. Paulo Andrade | F6: Saúde Total | H6: Retorno | I6: 0 | L6: Fevereiro
A7: Número do mês | B7: =MATCH(B6,$L$5:$L$16,0) -> 9 | D7: Dra. Renata Sousa | F7: MediPlan | H7: ECG | I7: 0 | L7: Março
A8: Data de referência (hoje) | B8: 46279 | F8: Vida Care | H8: MAPA | I8: 0 | L8: Abril
A9: Lista de retorno: incluir quem passou do prazo há mais de (dias) | B9: 0 | C9: 0 = entra na lista no dia em que o retorno previsto passa. 7 = só uma semana depois. | H9: Holter | I9: 0 | L9: Maio
H10: Teste ergométrico | I10: 0 | L10: Junho
H11: Avaliação endócrina | I11: 45 | L11: Julho
L12: Agosto
L13: Setembro
L14: Outubro
L15: Novembro
L16: Dezembro
D18: Copie as listas da planilha 01 (Config). Retorno em (dias): em quantos dias se espera o paciente de volta depois desse procedimento (0 = não gera retorno). Preencha de cima para baixo, sem pular linha.

Sheet Agenda
A1: Agenda (cópia da planilha 01)
A2: Cole aqui as colunas A a K da Agenda da planilha 01 (a 01 é a fonte). As colunas brancas calculam faltas, retorno previsto e a lista de retorno.
A4: Data | B4: Hora | C4: Profissional | D4: Sala | E4: Paciente | F4: Pagador | G4: Procedimento | H4: Situação | I4: Forma de pagamento | J4: Parcelas (cartão) | K4: Observação | L4: Mês | M4: Ano | N4: Dia da semana | O4: Período | P4: Retorno em (dias) | Q4: Retorno previsto | R4: Voltou ou tem horário? | S4: Dias além do previsto | T4: Na lista de retorno?
A5: 46174 | B5: 0.33333333 | C5: Dra. Carolina Mendes | D5: Sala 1 | E5: Isabela Pinto | F5: Saúde Total | G5: Consulta | H5: Realizado | I5: Convênio | L5: =IF(A5="","",MONTH(A5)) -> 6 | M5: =IF(A5="","",YEAR(A5)) -> 2026 | N5: =IF(A5="","",CHOOSE(WEEKDAY(A5,2),"Segunda","Terça","Quarta","Quinta","Sexta","Sábado","Domingo")) -> Segunda | O5: =IF(B5="","",IF(B5<TIME(12,0,0),"Manhã",IF(B5<TIME(18,0,0),"Tarde","Noite"))) -> Manhã | P5: =IF(G5="","",IFERROR(INDEX(Config!$I$5:$I$16,MATCH(G5,Config!$H$5:$H$16,0)),0)) -> 30 | Q5: =IF(OR(H5<>"Realizado",P5="",P5=0),"",A5+P5) -> 46204 | R5: =IF(Q5="","",IF(COUNTIFS($E$5:$E$3004,E5,$A$5:$A$3004,">"&A5,$H$5:$H$3004,"<>Falta",$H$5:$H$3004,"<>Cancelado",$H$5:$H$3004,"<>Remarcado")>0,"Sim","Não")) -> Sim | S5: =IF(R5<>"Não","",IF(Q5+Config!$B$9<=Config!$B$8,Config!$B$8-Q5,"")) | T5: =IF(S5="","","Sim") | U5: =IF(T5="Sim",S5+ROW()/100000,0) -> 0 | V5: =IF(AND(H5="Falta",L5=Config!$B$7,M5=Config!$B$5,COUNTIFS($E$5:E5,E5,$H$5:H5,"Falta",$L$5:L5,Config!$B$7,$M$5:M5,Config!$B$5)=1),COUNTIFS($E$5:$E$3004,E5,$H$5:$H$3004,"Falta",$L$5:$L$3004,Config!$B$7,$M$5:$M$3004,Config!$B$5)*1000-ROW()/100000,0) -> 0
A6: 46174 | B6: 0.375 | C6: Dra. Carolina Mendes | D6: Sala 1 | E6: Tatiana Cunha | F6: Saúde Total | G6: Consulta | H6: Realizado | I6: Convênio | L6: =IF(A6="","",MONTH(A6)) -> 6 | M6: =IF(A6="","",YEAR(A6)) -> 2026 | N6: =IF(A6="","",CHOOSE(WEEKDAY(A6,2),"Segunda","Terça","Quarta","Quinta","Sexta","Sábado","Domingo")) -> Segunda | O6: =IF(B6="","",IF(B6<TIME(12,0,0),"Manhã",IF(B6<TIME(18,0,0),"Tarde","Noite"))) -> Manhã | P6: =IF(G6="","",IFERROR(INDEX(Config!$I$5:$I$16,MATCH(G6,Config!$H$5:$H$16,0)),0)) -> 30 | Q6: =IF(OR(H6<>"Realizado",P6="",P6=0),"",A6+P6) -> 46204 | R6: =IF(Q6="","",IF(COUNTIFS($E$5:$E$3004,E6,$A$5:$A$3004,">"&A6,$H$5:$H$3004,"<>Falta",$H$5:$H$3004,"<>Cancelado",$H$5:$H$3004,"<>Remarcado")>0,"Sim","Não")) -> Sim | S6: =IF(R6<>"Não","",IF(Q6+Config!$B$9<=Config!$B$8,Config!$B$8-Q6,"")) | T6: =IF(S6="","","Sim") | U6: =IF(T6="Sim",S6+ROW()/100000,0) -> 0 | V6: =IF(AND(H6="Falta",L6=Config!$B$7,M6=Config!$B$5,COUNTIFS($E$5:E6,E6,$H$5:H6,"Falta",$L$5:L6,Config!$B$7,$M$5:M6,Config!$B$5)=1),COUNTIFS($E$5:$E$3004,E6,$H$5:$H$3004,"Falta",$L$5:$L$3004,Config!$B$7,$M$5:$M$3004,Config!$B$5)*1000-ROW()/100000,0) -> 0
A7: 46174 | B7: 0.39583333 | C7: Dra. Carolina Mendes | D7: Sala 1 | E7: Débora Machado | F7: Saúde Total | G7: Consulta | H7: Realizado | I7: Convênio | L7: =IF(A7="","",MONTH(A7)) -> 6 | M7: =IF(A7="","",YEAR(A7)) -> 2026 | N7: =IF(A7="","",CHOOSE(WEEKDAY(A7,2),"Segunda","Terça","Quarta","Quinta","Sexta","Sábado","Domingo")) -> Segunda | O7: =IF(B7="","",IF(B7<TIME(12,0,0),"Manhã",IF(B7<TIME(18,0,0),"Tarde","Noite"))) -> Manhã | P7: =IF(G7="","",IFERROR(INDEX(Config!$I$5:$I$16,MATCH(G7,Config!$H$5:$H$16,0)),0)) -> 30 | Q7: =IF(OR(H7<>"Realizado",P7="",P7=0),"",A7+P7) -> 46204 | R7: =IF(Q7="","",IF(COUNTIFS($E$5:$E$3004,E7,$A$5:$A$3004,">"&A7,$H$5:$H$3004,"<>Falta",$H$5:$H$3004,"<>Cancelado",$H$5:$H$3004,"<>Remarcado")>0,"Sim","Não")) -> Sim | S7: =IF(R7<>"Não","",IF(Q7+Config!$B$9<=Config!$B$8,Config!$B$8-Q7,"")) | T7: =IF(S7="","","Sim") | U7: =IF(T7="Sim",S7+ROW()/100000,0) -> 0 | V7: =IF(AND(H7="Falta",L7=Config!$B$7,M7=Config!$B$5,COUNTIFS($E$5:E7,E7,$H$5:H7,"Falta",$L$5:L7,Config!$B$7,$M$5:M7,Config!$B$5)=1),COUNTIFS($E$5:$E$3004,E7,$H$5:$H$3004,"Falta",$L$5:$L$3004,Config!$B$7,$M$5:$M$3004,Config!$B$5)*1000-ROW()/100000,0) -> 0
A8: 46174 | B8: 0.41666667 | C8: Dra. Carolina Mendes | D8: Sala 1 | E8: Gustavo Ferreira | F8: Particular | G8: Retorno | H8: Realizado | I8: Sem cobrança | L8: =IF(A8="","",MONTH(A8)) -> 6 | M8: =IF(A8="","",YEAR(A8)) -> 2026 | N8: =IF(A8="","",CHOOSE(WEEKDAY(A8,2),"Segunda","Terça","Quarta","Quinta","Sexta","Sábado","Domingo")) -> Segunda | O8: =IF(B8="","",IF(B8<TIME(12,0,0),"Manhã",IF(B8<TIME(18,0,0),"Tarde","Noite"))) -> Manhã | P8: =IF(G8="","",IFERROR(INDEX(Config!$I$5:$I$16,MATCH(G8,Config!$H$5:$H$16,0)),0)) -> 0 | Q8: =IF(OR(H8<>"Realizado",P8="",P8=0),"",A8+P8) | R8: =IF(Q8="","",IF(COUNTIFS($E$5:$E$3004,E8,$A$5:$A$3004,">"&A8,$H$5:$H$3004,"<>Falta",$H$5:$H$3004,"<>Cancelado",$H$5:$H$3004,"<>Remarcado")>0,"Sim","Não")) | S8: =IF(R8<>"Não","",IF(Q8+Config!$B$9<=Config!$B$8,Config!$B$8-Q8,"")) | T8: =IF(S8="","","Sim") | U8: =IF(T8="Sim",S8+ROW()/100000,0) -> 0 | V8: =IF(AND(H8="Falta",L8=Config!$B$7,M8=Config!$B$5,COUNTIFS($E$5:E8,E8,$H$5:H8,"Falta",$L$5:L8,Config!$B$7,$M$5:M8,Config!$B$5)=1),COUNTIFS($E$5:$E$3004,E8,$H$5:$H$3004,"Falta",$L$5:$L$3004,Config!$B$7,$M$5:$M$3004,Config!$B$5)*1000-ROW()/100000,0) -> 0
A9: 46174 | B9: 0.45138889 | C9: Dra. Carolina Mendes | D9: Sala 1 | E9: Sérgio Batista | F9: MediPlan | G9: Consulta | H9: Falta | L9: =IF(A9="","",MONTH(A9)) -> 6 | M9: =IF(A9="","",YEAR(A9)) -> 2026 | N9: =IF(A9="","",CHOOSE(WEEKDAY(A9,2),"Segunda","Terça","Quarta","Quinta","Sexta","Sábado","Domingo")) -> Segunda | O9: =IF(B9="","",IF(B9<TIME(12,0,0),"Manhã",IF(B9<TIME(18,0,0),"Tarde","Noite"))) -> Manhã | P9: =IF(G9="","",IFERROR(INDEX(Config!$I$5:$I$16,MATCH(G9,Config!$H$5:$H$16,0)),0)) -> 30 | Q9: =IF(OR(H9<>"Realizado",P9="",P9=0),"",A9+P9) | R9: =IF(Q9="","",IF(COUNTIFS($E$5:$E$3004,E9,$A$5:$A$3004,">"&A9,$H$5:$H$3004,"<>Falta",$H$5:$H$3004,"<>Cancelado",$H$5:$H$3004,"<>Remarcado")>0,"Sim","Não")) | S9: =IF(R9<>"Não","",IF(Q9+Config!$B$9<=Config!$B$8,Config!$B$8-Q9,"")) | T9: =IF(S9="","","Sim") | U9: =IF(T9="Sim",S9+ROW()/100000,0) -> 0 | V9: =IF(AND(H9="Falta",L9=Config!$B$7,M9=Config!$B$5,COUNTIFS($E$5:E9,E9,$H$5:H9,"Falta",$L$5:L9,Config!$B$7,$M$5:M9,Config!$B$5)=1),COUNTIFS($E$5:$E$3004,E9,$H$5:$H$3004,"Falta",$L$5:$L$3004,Config!$B$7,$M$5:$M$3004,Config!$B$5)*1000-ROW()/100000,0) -> 0
A10: 46174 | B10: 0.60416667 | C10: Dr. Paulo Andrade | D10: Sala 2 | E10: Otávio Martins | F10: MediPlan | G10: Consulta | H10: Falta | L10: =IF(A10="","",MONTH(A10)) -> 6 | M10: =IF(A10="","",YEAR(A10)) -> 2026 | N10: =IF(A10="","",CHOOSE(WEEKDAY(A10,2),"Segunda","Terça","Quarta","Quinta","Sexta","Sábado","Domingo")) -> Segunda | O10: =IF(B10="","",IF(B10<TIME(12,0,0),"Manhã",IF(B10<TIME(18,0,0),"Tarde","Noite"))) -> Tarde | P10: =IF(G10="","",IFERROR(INDEX(Config!$I$5:$I$16,MATCH(G10,Config!$H$5:$H$16,0)),0)) -> 30 | Q10: =IF(OR(H10<>"Realizado",P10="",P10=0),"",A10+P10) | R10: =IF(Q10="","",IF(COUNTIFS($E$5:$E$3004,E10,$A$5:$A$3004,">"&A10,$H$5:$H$3004,"<>Falta",$H$5:$H$3004,"<>Cancelado",$H$5:$H$3004,"<>Remarcado")>0,"Sim","Não")) | S10: =IF(R10<>"Não","",IF(Q10+Config!$B$9<=Config!$B$8,Config!$B$8-Q10,"")) | T10: =IF(S10="","","Sim") | U10: =IF(T10="Sim",S10+ROW()/100000,0) -> 0 | V10: =IF(AND(H10="Falta",L10=Config!$B$7,M10=Config!$B$5,COUNTIFS($E$5:E10,E10,$H$5:H10,"Falta",$L$5:L10,Config!$B$7,$M$5:M10,Config!$B$5)=1),COUNTIFS($E$5:$E$3004,E10,$H$5:$H$3004,"Falta",$L$5:$L$3004,Config!$B$7,$M$5:$M$3004,Config!$B$5)*1000-ROW()/100000,0) -> 0
A11: 46174 | B11: 0.625 | C11: Dr. Paulo Andrade | D11: Sala 2 | E11: Natália Martins | F11: Particular | G11: Consulta | H11: Falta | L11: =IF(A11="","",MONTH(A11)) -> 6 | M11: =IF(A11="","",YEAR(A11)) -> 2026 | N11: =IF(A11="","",CHOOSE(WEEKDAY(A11,2),"Segunda","Terça","Quarta","Quinta","Sexta","Sábado","Domingo")) -> Segunda | O11: =IF(B11="","",IF(B11<TIME(12,0,0),"Manhã",IF(B11<TIME(18,0,0),"Tarde","Noite"))) -> Tarde | P11: =IF(G11="","",IFERROR(INDEX(Config!$I$5:$I$16,MATCH(G11,Config!$H$5:$H$16,0)),0)) -> 30 | Q11: =IF(OR(H11<>"Realizado",P11="",P11=0),"",A11+P11) | R11: =IF(Q11="","",IF(COUNTIFS($E$5:$E$3004,E11,$A$5:$A$3004,">"&A11,$H$5:$H$3004,"<>Falta",$H$5:$H$3004,"<>Cancelado",$H$5:$H$3004,"<>Remarcado")>0,"Sim","Não")) | S11: =IF(R11<>"Não","",IF(Q11+Config!$B$9<=Config!$B$8,Config!$B$8-Q11,"")) | T11: =IF(S11="","","Sim") | U11: =IF(T11="Sim",S11+ROW()/100000,0) -> 0 | V11: =IF(AND(H11="Falta",L11=Config!$B$7,M11=Config!$B$5,COUNTIFS($E$5:E11,E11,$H$5:H11,"Falta",$L$5:L11,Config!$B$7,$M$5:M11,Config!$B$5)=1),COUNTIFS($E$5:$E$3004,E11,$H$5:$H$3004,"Falta",$L$5:$L$3004,Config!$B$7,$M$5:$M$3004,Config!$B$5)*1000-ROW()/100000,0) -> 0
A12: 46174 | B12: 0.64583333 | C12: Dr. Paulo Andrade | D12: Sala 2 | E12: Otávio Martins | F12: MediPlan | G12: Consulta | H12: Realizado | I12: Convênio | L12: =IF(A12="","",MONTH(A12)) -> 6 | M12: =IF(A12="","",YEAR(A12)) -> 2026 | N12: =IF(A12="","",CHOOSE(WEEKDAY(A12,2),"Segunda","Terça","Quarta","Quinta","Sexta","Sábado","Domingo")) -> Segunda | O12: =IF(B12="","",IF(B12<TIME(12,0,0),"Manhã",IF(B12<TIME(18,0,0),"Tarde","Noite"))) -> Tarde | P12: =IF(G12="","",IFERROR(INDEX(Config!$I$5:$I$16,MATCH(G12,Config!$H$5:$H$16,0)),0)) -> 30 | Q12: =IF(OR(H12<>"Realizado",P12="",P12=0),"",A12+P12) -> 46204 | R12: =IF(Q12="","",IF(COUNTIFS($E$5:$E$3004,E12,$A$5:$A$3004,">"&A12,$H$5:$H$3004,"<>Falta",$H$5:$H$3004,"<>Cancelado",$H$5:$H$3004,"<>Remarcado")>0,"Sim","Não")) -> Sim | S12: =IF(R12<>"Não","",IF(Q12+Config!$B$9<=Config!$B$8,Config!$B$8-Q12,"")) | T12: =IF(S12="","","Sim") | U12: =IF(T12="Sim",S12+ROW()/100000,0) -> 0 | V12: =IF(AND(H12="Falta",L12=Config!$B$7,M12=Config!$B$5,COUNTIFS($E$5:E12,E12,$H$5:H12,"Falta",$L$5:L12,Config!$B$7,$M$5:M12,Config!$B$5)=1),COUNTIFS($E$5:$E$3004,E12,$H$5:$H$3004,"Falta",$L$5:$L$3004,Config!$B$7,$M$5:$M$3004,Config!$B$5)*1000-ROW()/100000,0) -> 0
A13: 46174 | B13: 0.66666667 | C13: Dr. Paulo Andrade | D13: Sala 2 | E13: Cláudia Santos | F13: Particular | G13: MAPA | H13: Realizado | I13: Pix | L13: =IF(A13="","",MONTH(A13)) -> 6 | M13: =IF(A13="","",YEAR(A13)) -> 2026 | N13: =IF(A13="","",CHOOSE(WEEKDAY(A13,2),"Segunda","Terça","Quarta","Quinta","Sexta","Sábado","Domingo")) -> Segunda | O13: =IF(B13="","",IF(B13<TIME(12,0,0),"Manhã",IF(B13<TIME(18,0,0),"Tarde","Noite"))) -> Tarde | P13: =IF(G13="","",IFERROR(INDEX(Config!$I$5:$I$16,MATCH(G13,Config!$H$5:$H$16,0)),0)) -> 0 | Q13: =IF(OR(H13<>"Realizado",P13="",P13=0),"",A13+P13) | R13: =IF(Q13="","",IF(COUNTIFS($E$5:$E$3004,E13,$A$5:$A$3004,">"&A13,$H$5:$H$3004,"<>Falta",$H$5:$H$3004,"<>Cancelado",$H$5:$H$3004,"<>Remarcado")>0,"Sim","Não")) | S13: =IF(R13<>"Não","",IF(Q13+Config!$B$9<=Config!$B$8,Config!$B$8-Q13,"")) | T13: =IF(S13="","","Sim") | U13: =IF(T13="Sim",S13+ROW()/100000,0) -> 0 | V13: =IF(AND(H13="Falta",L13=Config!$B$7,M13=Config!$B$5,COUNTIFS($E$5:E13,E13,$H$5:H13,"Falta",$L$5:L13,Config!$B$7,$M$5:M13,Config!$B$5)=1),COUNTIFS($E$5:$E$3004,E13,$H$5:$H$3004,"Falta",$L$5:$L$3004,Config!$B$7,$M$5:$M$3004,Config!$B$5)*1000-ROW()/100000,0) -> 0
A14: 46174 | B14: 0.68055556 | C14: Dr. Paulo Andrade | D14: Sala 2 | E14: Mateus Martins | F14: Vida Care | G14: Consulta | H14: Realizado | I14: Convênio | L14: =IF(A14="","",MONTH(A14)) -> 6 | M14: =IF(A14="","",YEAR(A14)) -> 2026 | N14: =IF(A14="","",CHOOSE(WEEKDAY(A14,2),"Segunda","Terça","Quarta","Quinta","Sexta","Sábado","Domingo")) -> Segunda | O14: =IF(B14="","",IF(B14<TIME(12,0,0),"Manhã",IF(B14<TIME(18,0,0),"Tarde","Noite"))) -> Tarde | P14: =IF(G14="","",IFERROR(INDEX(Config!$I$5:$I$16,MATCH(G14,Config!$H$5:$H$16,0)),0)) -> 30 | Q14: =IF(OR(H14<>"Realizado",P14="",P14=0),"",A14+P14) -> 46204 | R14: =IF(Q14="","",IF(COUNTIFS($E$5:$E$3004,E14,$A$5:$A$3004,">"&A14,$H$5:$H$3004,"<>Falta",$H$5:$H$3004,"<>Cancelado",$H$5:$H$3004,"<>Remarcado")>0,"Sim","Não")) -> Sim | S14: =IF(R14<>"Não","",IF(Q14+Config!$B$9<=Config!$B$8,Config!$B$8-Q14,"")) | T14: =IF(S14="","","Sim") | U14: =IF(T14="Sim",S14+ROW()/100000,0) -> 0 | V14: =IF(AND(H14="Falta",L14=Config!$B$7,M14=Config!$B$5,COUNTIFS($E$5:E14,E14,$H$5:H14,"Falta",$L$5:L14,Config!$B$7,$M$5:M14,Config!$B$5)=1),COUNTIFS($E$5:$E$3004,E14,$H$5:$H$3004,"Falta",$L$5:$L$3004,Config!$B$7,$M$5:$M$3004,Config!$B$5)*1000-ROW()/100000,0) -> 0
A15: 46174 | B15: 0.70138889 | C15: Dr. Paulo Andrade | D15: Sala 2 | E15: Wagner Lima | F15: Particular | G15: Retorno | H15: Realizado | I15: Sem cobrança | L15: =IF(A15="","",MONTH(A15)) -> 6 | M15: =IF(A15="","",YEAR(A15)) -> 2026 | N15: =IF(A15="","",CHOOSE(WEEKDAY(A15,2),"Segunda","Terça","Quarta","Quinta","Sexta","Sábado","Domingo")) -> Segunda | O15: =IF(B15="","",IF(B15<TIME(12,0,0),"Manhã",IF(B15<TIME(18,0,0),"Tarde","Noite"))) -> Tarde | P15: =IF(G15="","",IFERROR(INDEX(Config!$I$5:$I$16,MATCH(G15,Config!$H$5:$H$16,0)),0)) -> 0 | Q15: =IF(OR(H15<>"Realizado",P15="",P15=0),"",A15+P15) | R15: =IF(Q15="","",IF(COUNTIFS($E$5:$E$3004,E15,$A$5:$A$3004,">"&A15,$H$5:$H$3004,"<>Falta",$H$5:$H$3004,"<>Cancelado",$H$5:$H$3004,"<>Remarcado")>0,"Sim","Não")) | S15: =IF(R15<>"Não","",IF(Q15+Config!$B$9<=Config!$B$8,Config!$B$8-Q15,"")) | T15: =IF(S15="","","Sim") | U15: =IF(T15="Sim",S15+ROW()/100000,0) -> 0 | V15: =IF(AND(H15="Falta",L15=Config!$B$7,M15=Config!$B$5,COUNTIFS($E$5:E15,E15,$H$5:H15,"Falta",$L$5:L15,Config!$B$7,$M$5:M15,Config!$B$5)=1),COUNTIFS($E$5:$E$3004,E15,$H$5:$H$3004,"Falta",$L$5:$L$3004,Config!$B$7,$M$5:$M$3004,Config!$B$5)*1000-ROW()/100000,0) -> 0
A16: 46174 | B16: 0.71527778 | C16: Dr. Paulo Andrade | D16: Sala 2 | E16: Fábio Martins | F16: MediPlan | G16: Retorno | H16: Realizado | I16: Sem cobrança | L16: =IF(A16="","",MONTH(A16)) -> 6 | M16: =IF(A16="","",YEAR(A16)) -> 2026 | N16: =IF(A16="","",CHOOSE(WEEKDAY(A16,2),"Segunda","Terça","Quarta","Quinta","Sexta","Sábado","Domingo")) -> Segunda | O16: =IF(B16="","",IF(B16<TIME(12,0,0),"Manhã",IF(B16<TIME(18,0,0),"Tarde","Noite"))) -> Tarde | P16: =IF(G16="","",IFERROR(INDEX(Config!$I$5:$I$16,MATCH(G16,Config!$H$5:$H$16,0)),0)) -> 0 | Q16: =IF(OR(H16<>"Realizado",P16="",P16=0),"",A16+P16) | R16: =IF(Q16="","",IF(COUNTIFS($E$5:$E$3004,E16,$A$5:$A$3004,">"&A16,$H$5:$H$3004,"<>Falta",$H$5:$H$3004,"<>Cancelado",$H$5:$H$3004,"<>Remarcado")>0,"Sim","Não")) | S16: =IF(R16<>"Não","",IF(Q16+Config!$B$9<=Config!$B$8,Config!$B$8-Q16,"")) | T16: =IF(S16="","","Sim") | U16: =IF(T16="Sim",S16+ROW()/100000,0) -> 0 | V16: =IF(AND(H16="Falta",L16=Config!$B$7,M16=Config!$B$5,COUNTIFS($E$5:E16,E16,$H$5:H16,"Falta",$L$5:L16,Config!$B$7,$M$5:M16,Config!$B$5)=1),COUNTIFS($E$5:$E$3004,E16,$H$5:$H$3004,"Falta",$L$5:$L$3004,Config!$B$7,$M$5:$M$3004,Config!$B$5)*1000-ROW()/100000,0) -> 0
A17: 46174 | B17: 0.72916667 | C17: Dr. Paulo Andrade | D17: Sala 2 | E17: Leandro Ferreira | F17: Saúde Total | G17: Holter | H17: Realizado | I17: Convênio | L17: =IF(A17="","",MONTH(A17)) -> 6 | M17: =IF(A17="","",YEAR(A17)) -> 2026 | N17: =IF(A17="","",CHOOSE(WEEKDAY(A17,2),"Segunda","Terça","Quarta","Quinta","Sexta","Sábado","Domingo")) -> Segunda | O17: =IF(B17="","",IF(B17<TIME(12,0,0),"Manhã",IF(B17<TIME(18,0,0),"Tarde","Noite"))) -> Tarde | P17: =IF(G17="","",IFERROR(INDEX(Config!$I$5:$I$16,MATCH(G17,Config!$H$5:$H$16,0)),0)) -> 0 | Q17: =IF(OR(H17<>"Realizado",P17="",P17=0),"",A17+P17) | R17: =IF(Q17="","",IF(COUNTIFS($E$5:$E$3004,E17,$A$5:$A$3004,">"&A17,$H$5:$H$3004,"<>Falta",$H$5:$H$3004,"<>Cancelado",$H$5:$H$3004,"<>Remarcado")>0,"Sim","Não")) | S17: =IF(R17<>"Não","",IF(Q17+Config!$B$9<=Config!$B$8,Config!$B$8-Q17,"")) | T17: =IF(S17="","","Sim") | U17: =IF(T17="Sim",S17+ROW()/100000,0) -> 0 | V17: =IF(AND(H17="Falta",L17=Config!$B$7,M17=Config!$B$5,COUNTIFS($E$5:E17,E17,$H$5:H17,"Falta",$L$5:L17,Config!$B$7,$M$5:M17,Config!$B$5)=1),COUNTIFS($E$5:$E$3004,E17,$H$5:$H$3004,"Falta",$L$5:$L$3004,Config!$B$7,$M$5:$M$3004,Config!$B$5)*1000-ROW()/100000,0) -> 0
A18: 46175 | B18: 0.33333333 | C18: Dra. Carolina Mendes | D18: Sala 1 | E18: Ricardo Melo | F18: Saúde Total | G18: Retorno | H18: Realizado | I18: Sem cobrança | L18: =IF(A18="","",MONTH(A18)) -> 6 | M18: =IF(A18="","",YEAR(A18)) -> 2026 | N18: =IF(A18="","",CHOOSE(WEEKDAY(A18,2),"Segunda","Terça","Quarta","Quinta","Sexta","Sábado","Domingo")) -> Terça | O18: =IF(B18="","",IF(B18<TIME(12,0,0),"Manhã",IF(B18<TIME(18,0,0),"Tarde","Noite"))) -> Manhã | P18: =IF(G18="","",IFERROR(INDEX(Config!$I$5:$I$16,MATCH(G18,Config!$H$5:$H$16,0)),0)) -> 0 | Q18: =IF(OR(H18<>"Realizado",P18="",P18=0),"",A18+P18) | R18: =IF(Q18="","",IF(COUNTIFS($E$5:$E$3004,E18,$A$5:$A$3004,">"&A18,$H$5:$H$3004,"<>Falta",$H$5:$H$3004,"<>Cancelado",$H$5:$H$3004,"<>Remarcado")>0,"Sim","Não")) | S18: =IF(R18<>"Não","",IF(Q18+Config!$B$9<=Config!$B$8,Config!$B$8-Q18,"")) | T18: =IF(S18="","","Sim") | U18: =IF(T18="Sim",S18+ROW()/100000,0) -> 0 | V18: =IF(AND(H18="Falta",L18=Config!$B$7,M18=Config!$B$5,COUNTIFS($E$5:E18,E18,$H$5:H18,"Falta",$L$5:L18,Config!$B$7,$M$5:M18,Config!$B$5)=1),COUNTIFS($E$5:$E$3004,E18,$H$5:$H$3004,"Falta",$L$5:$L$3004,Config!$B$7,$M$5:$M$3004,Config!$B$5)*1000-ROW()/100000,0) -> 0
A19: 46175 | B19: 0.34722222 | C19: Dra. Carolina Mendes | D19: Sala 1 | E19: Sérgio Batista | F19: MediPlan | G19: Consulta | H19: Realizado | I19: Convênio | L19: =IF(A19="","",MONTH(A19)) -> 6 | M19: =IF(A19="","",YEAR(A19)) -> 2026 | N19: =IF(A19="","",CHOOSE(WEEKDAY(A19,2),"Segunda","Terça","Quarta","Quinta","Sexta","Sábado","Domingo")) -> Terça | O19: =IF(B19="","",IF(B19<TIME(12,0,0),"Manhã",IF(B19<TIME(18,0,0),"Tarde","Noite"))) -> Manhã | P19: =IF(G19="","",IFERROR(INDEX(Config!$I$5:$I$16,MATCH(G19,Config!$H$5:$H$16,0)),0)) -> 30 | Q19: =IF(OR(H19<>"Realizado",P19="",P19=0),"",A19+P19) -> 46205 | R19: =IF(Q19="","",IF(COUNTIFS($E$5:$E$3004,E19,$A$5:$A$3004,">"&A19,$H$5:$H$3004,"<>Falta",$H$5:$H$3004,"<>Cancelado",$H$5:$H$3004,"<>Remarcado")>0,"Sim","Não")) -> Sim | S19: =IF(R19<>"Não","",IF(Q19+Config!$B$9<=Config!$B$8,Config!$B$8-Q19,"")) | T19: =IF(S19="","","Sim") | U19: =IF(T19="Sim",S19+ROW()/100000,0) -> 0 | V19: =IF(AND(H19="Falta",L19=Config!$B$7,M19=Config!$B$5,COUNTIFS($E$5:E19,E19,$H$5:H19,"Falta",$L$5:L19,Config!$B$7,$M$5:M19,Config!$B$5)=1),COUNTIFS($E$5:$E$3004,E19,$H$5:$H$3004,"Falta",$L$5:$L$3004,Config!$B$7,$M$5:$M$3004,Config!$B$5)*1000-ROW()/100000,0) -> 0
A20: 46175 | B20: 0.36805556 | C20: Dra. Carolina Mendes | D20: Sala 1 | E20: Otávio Nascimento | F20: Particular | G20: Consulta | H20: Realizado | I20: Cartão de crédito | L20: =IF(A20="","",MONTH(A20)) -> 6 | M20: =IF(A20="","",YEAR(A20)) -> 2026 | N20: =IF(A20="","",CHOOSE(WEEKDAY(A20,2),"Segunda","Terça","Quarta","Quinta","Sexta","Sábado","Domingo")) -> Terça | O20: =IF(B20="","",IF(B20<TIME(12,0,0),"Manhã",IF(B20<TIME(18,0,0),"Tarde","Noite"))) -> Manhã | P20: =IF(G20="","",IFERROR(INDEX(Config!$I$5:$I$16,MATCH(G20,Config!$H$5:$H$16,0)),0)) -> 30 | Q20: =IF(OR(H20<>"Realizado",P20="",P20=0),"",A20+P20) -> 46205 | R20: =IF(Q20="","",IF(COUNTIFS($E$5:$E$3004,E20,$A$5:$A$3004,">"&A20,$H$5:$H$3004,"<>Falta",$H$5:$H$3004,"<>Cancelado",$H$5:$H$3004,"<>Remarcado")>0,"Sim","Não")) -> Sim | S20: =IF(R20<>"Não","",IF(Q20+Config!$B$9<=Config!$B$8,Config!$B$8-Q20,"")) | T20: =IF(S20="","","Sim") | U20: =IF(T20="Sim",S20+ROW()/100000,0) -> 0 | V20: =IF(AND(H20="Falta",L20=Config!$B$7,M20=Config!$B$5,COUNTIFS($E$5:E20,E20,$H$5:H20,"Falta",$L$5:L20,Config!$B$7,$M$5:M20,Config!$B$5)=1),COUNTIFS($E$5:$E$3004,E20,$H$5:$H$3004,"Falta",$L$5:$L$3004,Config!$B$7,$M$5:$M$3004,Config!$B$5)*1000-ROW()/100000,0) -> 0
A21: 46175 | B21: 0.38888889 | C21: Dra. Carolina Mendes | D21: Sala 1 | E21: Leandro Oliveira | F21: Particular | G21: Consulta | H21: Cancelado | L21: =IF(A21="","",MONTH(A21)) -> 6 | M21: =IF(A21="","",YEAR(A21)) -> 2026 | N21: =IF(A21="","",CHOOSE(WEEKDAY(A21,2),"Segunda","Terça","Quarta","Quinta","Sexta","Sábado","Domingo")) -> Terça | O21: =IF(B21="","",IF(B21<TIME(12,0,0),"Manhã",IF(B21<TIME(18,0,0),"Tarde","Noite"))) -> Manhã | P21: =IF(G21="","",IFERROR(INDEX(Config!$I$5:$I$16,MATCH(G21,Config!$H$5:$H$16,0)),0)) -> 30 | Q21: =IF(OR(H21<>"Realizado",P21="",P21=0),"",A21+P21) | R21: =IF(Q21="","",IF(COUNTIFS($E$5:$E$3004,E21,$A$5:$A$3004,">"&A21,$H$5:$H$3004,"<>Falta",$H$5:$H$3004,"<>Cancelado",$H$5:$H$3004,"<>Remarcado")>0,"Sim","Não")) | S21: =IF(R21<>"Não","",IF(Q21+Config!$B$9<=Config!$B$8,Config!$B$8-Q21,"")) | T21: =IF(S21="","","Sim") | U21: =IF(T21="Sim",S21+ROW()/100000,0) -> 0 | V21: =IF(AND(H21="Falta",L21=Config!$B$7,M21=Config!$B$5,COUNTIFS($E$5:E21,E21,$H$5:H21,"Falta",$L$5:L21,Config!$B$7,$M$5:M21,Config!$B$5)=1),COUNTIFS($E$5:$E$3004,E21,$H$5:$H$3004,"Falta",$L$5:$L$3004,Config!$B$7,$M$5:$M$3004,Config!$B$5)*1000-ROW()/100000,0) -> 0
A22: 46175 | B22: 0.40972222 | C22: Dra. Carolina Mendes | D22: Sala 1 | E22: Leandro Oliveira | F22: Particular | G22: Consulta | H22: Realizado | I22: Pix | L22: =IF(A22="","",MONTH(A22)) -> 6 | M22: =IF(A22="","",YEAR(A22)) -> 2026 | N22: =IF(A22="","",CHOOSE(WEEKDAY(A22,2),"Segunda","Terça","Quarta","Quinta","Sexta","Sábado","Domingo")) -> Terça | O22: =IF(B22="","",IF(B22<TIME(12,0,0),"Manhã",IF(B22<TIME(18,0,0),"Tarde","Noite"))) -> Manhã | P22: =IF(G22="","",IFERROR(INDEX(Config!$I$5:$I$16,MATCH(G22,Config!$H$5:$H$16,0)),0)) -> 30 | Q22: =IF(OR(H22<>"Realizado",P22="",P22=0),"",A22+P22) -> 46205 | R22: =IF(Q22="","",IF(COUNTIFS($E$5:$E$3004,E22,$A$5:$A$3004,">"&A22,$H$5:$H$3004,"<>Falta",$H$5:$H$3004,"<>Cancelado",$H$5:$H$3004,"<>Remarcado")>0,"Sim","Não")) -> Sim | S22: =IF(R22<>"Não","",IF(Q22+Config!$B$9<=Config!$B$8,Config!$B$8-Q22,"")) | T22: =IF(S22="","","Sim") | U22: =IF(T22="Sim",S22+ROW()/100000,0) -> 0 | V22: =IF(AND(H22="Falta",L22=Config!$B$7,M22=Config!$B$5,COUNTIFS($E$5:E22,E22,$H$5:H22,"Falta",$L$5:L22,Config!$B$7,$M$5:M22,Config!$B$5)=1),COUNTIFS($E$5:$E$3004,E22,$H$5:$H$3004,"Falta",$L$5:$L$3004,Config!$B$7,$M$5:$M$3004,Config!$B$5)*1000-ROW()/100000,0) -> 0
A23: 46175 | B23: 0.43055556 | C23: Dra. Carolina Mendes | D23: Sala 1 | E23: Carlos Castro | F23: Saúde Total | G23: Consulta | H23: Realizado | I23: Convênio | L23: =IF(A23="","",MONTH(A23)) -> 6 | M23: =IF(A23="","",YEAR(A23)) -> 2026 | N23: =IF(A23="","",CHOOSE(WEEKDAY(A23,2),"Segunda","Terça","Quarta","Quinta","Sexta","Sábado","Domingo")) -> Terça | O23: =IF(B23="","",IF(B23<TIME(12,0,0),"Manhã",IF(B23<TIME(18,0,0),"Tarde","Noite"))) -> Manhã | P23: =IF(G23="","",IFERROR(INDEX(Config!$I$5:$I$16,MATCH(G23,Config!$H$5:$H$16,0)),0)) -> 30 | Q23: =IF(OR(H23<>"Realizado",P23="",P23=0),"",A23+P23) -> 46205 | R23: =IF(Q23="","",IF(COUNTIFS($E$5:$E$3004,E23,$A$5:$A$3004,">"&A23,$H$5:$H$3004,"<>Falta",$H$5:$H$3004,"<>Cancelado",$H$5:$H$3004,"<>Remarcado")>0,"Sim","Não")) -> Sim | S23: =IF(R23<>"Não","",IF(Q23+Config!$B$9<=Config!$B$8,Config!$B$8-Q23,"")) | T23: =IF(S23="","","Sim") | U23: =IF(T23="Sim",S23+ROW()/100000,0) -> 0 | V23: =IF(AND(H23="Falta",L23=Config!$B$7,M23=Config!$B$5,COUNTIFS($E$5:E23,E23,$H$5:H23,"Falta",$L$5:L23,Config!$B$7,$M$5:M23,Config!$B$5)=1),COUNTIFS($E$5:$E$3004,E23,$H$5:$H$3004,"Falta",$L$5:$L$3004,Config!$B$7,$M$5:$M$3004,Config!$B$5)*1000-ROW()/100000,0) -> 0
A24: 46175 | B24: 0.45138889 | C24: Dra. Carolina Mendes | D24: Sala 1 | E24: Cláudia Costa | F24: Particular | G24: Consulta | H24: Realizado | I24: Pix | L24: =IF(A24="","",MONTH(A24)) -> 6 | M24: =IF(A24="","",YEAR(A24)) -> 2026 | N24: =IF(A24="","",CHOOSE(WEEKDAY(A24,2),"Segunda","Terça","Quarta","Quinta","Sexta","Sábado","Domingo")) -> Terça | O24: =IF(B24="","",IF(B24<TIME(12,0,0),"Manhã",IF(B24<TIME(18,0,0),"Tarde","Noite"))) -> Manhã | P24: =IF(G24="","",IFERROR(INDEX(Config!$I$5:$I$16,MATCH(G24,Config!$H$5:$H$16,0)),0)) -> 30 | Q24: =IF(OR(H24<>"Realizado",P24="",P24=0),"",A24+P24) -> 46205 | R24: =IF(Q24="","",IF(COUNTIFS($E$5:$E$3004,E24,$A$5:$A$3004,">"&A24,$H$5:$H$3004,"<>Falta",$H$5:$H$3004,"<>Cancelado",$H$5:$H$3004,"<>Remarcado")>0,"Sim","Não")) -> Sim | S24: =IF(R24<>"Não","",IF(Q24+Config!$B$9<=Config!$B$8,Config!$B$8-Q24,"")) | T24: =IF(S24="","","Sim") | U24: =IF(T24="Sim",S24+ROW()/100000,0) -> 0 | V24: =IF(AND(H24="Falta",L24=Config!$B$7,M24=Config!$B$5,COUNTIFS($E$5:E24,E24,$H$5:H24,"Falta",$L$5:L24,Config!$B$7,$M$5:M24,Config!$B$5)=1),COUNTIFS($E$5:$E$3004,E24,$H$5:$H$3004,"Falta",$L$5:$L$3004,Config!$B$7,$M$5:$M$3004,Config!$B$5)*1000-ROW()/100000,0) -> 0
A25: 46175 | B25: 0.47222222 | C25: Dra. Carolina Mendes | D25: Sala 1 | E25: Lucas Xavier | F25: Saúde Total | G25: Consulta | H25: Realizado | I25: Convênio | L25: =IF(A25="","",MONTH(A25)) -> 6 | M25: =IF(A25="","",YEAR(A25)) -> 2026 | N25: =IF(A25="","",CHOOSE(WEEKDAY(A25,2),"Segunda","Terça","Quarta","Quinta","Sexta","Sábado","Domingo")) -> Terça | O25: =IF(B25="","",IF(B25<TIME(12,0,0),"Manhã",IF(B25<TIME(18,0,0),"Tarde","Noite"))) -> Manhã | P25: =IF(G25="","",IFERROR(INDEX(Config!$I$5:$I$16,MATCH(G25,Config!$H$5:$H$16,0)),0)) -> 30 | Q25: =IF(OR(H25<>"Realizado",P25="",P25=0),"",A25+P25) -> 46205 | R25: =IF(Q25="","",IF(COUNTIFS($E$5:$E$3004,E25,$A$5:$A$3004,">"&A25,$H$5:$H$3004,"<>Falta",$H$5:$H$3004,"<>Cancelado",$H$5:$H$3004,"<>Remarcado")>0,"Sim","Não")) -> Sim | S25: =IF(R25<>"Não","",IF(Q25+Config!$B$9<=Config!$B$8,Config!$B$8-Q25,"")) | T25: =IF(S25="","","Sim") | U25: =IF(T25="Sim",S25+ROW()/100000,0) -> 0 | V25: =IF(AND(H25="Falta",L25=Config!$B$7,M25=Config!$B$5,COUNTIFS($E$5:E25,E25,$H$5:H25,"Falta",$L$5:L25,Config!$B$7,$M$5:M25,Config!$B$5)=1),COUNTIFS($E$5:$E$3004,E25,$H$5:$H$3004,"Falta",$L$5:$L$3004,Config!$B$7,$M$5:$M$3004,Config!$B$5)*1000-ROW()/100000,0) -> 0
A26: 46175 | B26: 0.58333333 | C26: Dra. Renata Sousa | D26: Sala 1 | E26: Rafael Nascimento | F26: Saúde Total | G26: Avaliação endócrina | H26: Realizado | I26: Convênio | L26: =IF(A26="","",MONTH(A26)) -> 6 | M26: =IF(A26="","",YEAR(A26)) -> 2026 | N26: =IF(A26="","",CHOOSE(WEEKDAY(A26,2),"Segunda","Terça","Quarta","Quinta","Sexta","Sábado","Domingo")) -> Terça | O26: =IF(B26="","",IF(B26<TIME(12,0,0),"Manhã",IF(B26<TIME(18,0,0),"Tarde","Noite"))) -> Tarde | P26: =IF(G26="","",IFERROR(INDEX(Config!$I$5:$I$16,MATCH(G26,Config!$H$5:$H$16,0)),0)) -> 45 | Q26: =IF(OR(H26<>"Realizado",P26="",P26=0),"",A26+P26) -> 46220 | R26: =IF(Q26="","",IF(COUNTIFS($E$5:$E$3004,E26,$A$5:$A$3004,">"&A26,$H$5:$H$3004,"<>Falta",$H$5:$H$3004,"<>Cancelado",$H$5:$H$3004,"<>Remarcado")>0,"Sim","Não")) -> Sim | S26: =IF(R26<>"Não","",IF(Q26+Config!$B$9<=Config!$B$8,Config!$B$8-Q26,"")) | T26: =IF(S26="","","Sim") | U26: =IF(T26="Sim",S26+ROW()/100000,0) -> 0 | V26: =IF(AND(H26="Falta",L26=Config!$B$7,M26=Config!$B$5,COUNTIFS($E$5:E26,E26,$H$5:H26,"Falta",$L$5:L26,Config!$B$7,$M$5:M26,Config!$B$5)=1),COUNTIFS($E$5:$E$3004,E26,$H$5:$H$3004,"Falta",$L$5:$L$3004,Config!$B$7,$M$5:$M$3004,Config!$B$5)*1000-ROW()/100000,0) -> 0
A27: 46175 | B27: 0.58333333 | C27: Dr. Paulo Andrade | D27: Sala 2 | E27: Sérgio Teixeira | F27: MediPlan | G27: Retorno | H27: Realizado | I27: Sem cobrança | L27: =IF(A27="","",MONTH(A27)) -> 6 | M27: =IF(A27="","",YEAR(A27)) -> 2026 | N27: =IF(A27="","",CHOOSE(WEEKDAY(A27,2),"Segunda","Terça","Quarta","Quinta","Sexta","Sábado","Domingo")) -> Terça | O27: =IF(B27="","",IF(B27<TIME(12,0,0),"Manhã",IF(B27<TIME(18,0,0),"Tarde","Noite"))) -> Tarde | P27: =IF(G27="","",IFERROR(INDEX(Config!$I$5:$I$16,MATCH(G27,Config!$H$5:$H$16,0)),0)) -> 0 | Q27: =IF(OR(H27<>"Realizado",P27="",P27=0),"",A27+P27) | R27: =IF(Q27="","",IF(COUNTIFS($E$5:$E$3004,E27,$A$5:$A$3004,">"&A27,$H$5:$H$3004,"<>Falta",$H$5:$H$3004,"<>Cancelado",$H$5:$H$3004,"<>Remarcado")>0,"Sim","Não")) | S27: =IF(R27<>"Não","",IF(Q27+Config!$B$9<=Config!$B$8,Config!$B$8-Q27,"")) | T27: =IF(S27="","","Sim") | U27: =IF(T27="Sim",S27+ROW()/100000,0) -> 0 | V27: =IF(AND(H27="Falta",L27=Config!$B$7,M27=Config!$B$5,COUNTIFS($E$5:E27,E27,$H$5:H27,"Falta",$L$5:L27,Config!$B$7,$M$5:M27,Config!$B$5)=1),COUNTIFS($E$5:$E$3004,E27,$H$5:$H$3004,"Falta",$L$5:$L$3004,Config!$B$7,$M$5:$M$3004,Config!$B$5)*1000-ROW()/100000,0) -> 0
A28: 46175 | B28: 0.61111111 | C28: Dra. Renata Sousa | D28: Sala 1 | E28: Roberta Lima | F28: Particular | G28: Retorno | H28: Realizado | I28: Sem cobrança | L28: =IF(A28="","",MONTH(A28)) -> 6 | M28: =IF(A28="","",YEAR(A28)) -> 2026 | N28: =IF(A28="","",CHOOSE(WEEKDAY(A28,2),"Segunda","Terça","Quarta","Quinta","Sexta","Sábado","Domingo")) -> Terça | O28: =IF(B28="","",IF(B28<TIME(12,0,0),"Manhã",IF(B28<TIME(18,0,0),"Tarde","Noite"))) -> Tarde | P28: =IF(G28="","",IFERROR(INDEX(Config!$I$5:$I$16,MATCH(G28,Config!$H$5:$H$16,0)),0)) -> 0 | Q28: =IF(OR(H28<>"Realizado",P28="",P28=0),"",A28+P28) | R28: =IF(Q28="","",IF(COUNTIFS($E$5:$E$3004,E28,$A$5:$A$3004,">"&A28,$H$5:$H$3004,"<>Falta",$H$5:$H$3004,"<>Cancelado",$H$5:$H$3004,"<>Remarcado")>0,"Sim","Não")) | S28: =IF(R28<>"Não","",IF(Q28+Config!$B$9<=Config!$B$8,Config!$B$8-Q28,"")) | T28: =IF(S28="","","Sim") | U28: =IF(T28="Sim",S28+ROW()/100000,0) -> 0 | V28: =IF(AND(H28="Falta",L28=Config!$B$7,M28=Config!$B$5,COUNTIFS($E$5:E28,E28,$H$5:H28,"Falta",$L$5:L28,Config!$B$7,$M$5:M28,Config!$B$5)=1),COUNTIFS($E$5:$E$3004,E28,$H$5:$H$3004,"Falta",$L$5:$L$3004,Config!$B$7,$M$5:$M$3004,Config!$B$5)*1000-ROW()/100000,0) -> 0
A29: 46175 | B29: 0.625 | C29: Dra. Renata Sousa | D29: Sala 1 | E29: Beatriz Monteiro | F29: Particular | G29: Retorno | H29: Realizado | I29: Sem cobrança | L29: =IF(A29="","",MONTH(A29)) -> 6 | M29: =IF(A29="","",YEAR(A29)) -> 2026 | N29: =IF(A29="","",CHOOSE(WEEKDAY(A29,2),"Segunda","Terça","Quarta","Quinta","Sexta","Sábado","Domingo")) -> Terça | O29: =IF(B29="","",IF(B29<TIME(12,0,0),"Manhã",IF(B29<TIME(18,0,0),"Tarde","Noite"))) -> Tarde | P29: =IF(G29="","",IFERROR(INDEX(Config!$I$5:$I$16,MATCH(G29,Config!$H$5:$H$16,0)),0)) -> 0 | Q29: =IF(OR(H29<>"Realizado",P29="",P29=0),"",A29+P29) | R29: =IF(Q29="","",IF(COUNTIFS($E$5:$E$3004,E29,$A$5:$A$3004,">"&A29,$H$5:$H$3004,"<>Falta",$H$5:$H$3004,"<>Cancelado",$H$5:$H$3004,"<>Remarcado")>0,"Sim","Não")) | S29: =IF(R29<>"Não","",IF(Q29+Config!$B$9<=Config!$B$8,Config!$B$8-Q29,"")) | T29: =IF(S29="","","Sim") | U29: =IF(T29="Sim",S29+ROW()/100000,0) -> 0 | V29: =IF(AND(H29="Falta",L29=Config!$B$7,M29=Config!$B$5,COUNTIFS($E$5:E29,E29,$H$5:H29,"Falta",$L$5:L29,Config!$B$7,$M$5:M29,Config!$B$5)=1),COUNTIFS($E$5:$E$3004,E29,$H$5:$H$3004,"Falta",$L$5:$L$3004,Config!$B$7,$M$5:$M$3004,Config!$B$5)*1000-ROW()/100000,0) -> 0
A30: 46175 | B30: 0.63888889 | C30: Dra. Renata Sousa | D30: Sala 1 | E30: Eduardo Pereira | F30: Particular | G30: Avaliação endócrina | H30: Realizado | I30: Pix | L30: =IF(A30="","",MONTH(A30)) -> 6 | M30: =IF(A30="","",YEAR(A30)) -> 2026 | N30: =IF(A30="","",CHOOSE(WEEKDAY(A30,2),"Segunda","Terça","Quarta","Quinta","Sexta","Sábado","Domingo")) -> Terça | O30: =IF(B30="","",IF(B30<TIME(12,0,0),"Manhã",IF(B30<TIME(18,0,0),"Tarde","Noite"))) -> Tarde | P30: =IF(G30="","",IFERROR(INDEX(Config!$I$5:$I$16,MATCH(G30,Config!$H$5:$H$16,0)),0)) -> 45 | Q30: =IF(OR(H30<>"Realizado",P30="",P30=0),"",A30+P30) -> 46220 | R30: =IF(Q30="","",IF(COUNTIFS($E$5:$E$3004,E30,$A$5:$A$3004,">"&A30,$H$5:$H$3004,"<>Falta",$H$5:$H$3004,"<>Cancelado",$H$5:$H$3004,"<>Remarcado")>0,"Sim","Não")) -> Sim | S30: =IF(R30<>"Não","",IF(Q30+Config!$B$9<=Config!$B$8,Config!$B$8-Q30,"")) | T30: =IF(S30="","","Sim") | U30: =IF(T30="Sim",S30+ROW()/100000,0) -> 0 | V30: =IF(AND(H30="Falta",L30=Config!$B$7,M30=Config!$B$5,COUNTIFS($E$5:E30,E30,$H$5:H30,"Falta",$L$5:L30,Config!$B$7,$M$5:M30,Config!$B$5)=1),COUNTIFS($E$5:$E$3004,E30,$H$5:$H$3004,"Falta",$L$5:$L$3004,Config!$B$7,$M$5:$M$3004,Config!$B$5)*1000-ROW()/100000,0) -> 0
A31: 46175 | B31: 0.63888889 | C31: Dr. Paulo Andrade | D31: Sala 2 | E31: Wagner Costa | F31: Particular | G31: Consulta | H31: Realizado | I31: A prazo | L31: =IF(A31="","",MONTH(A31)) -> 6 | M31: =IF(A31="","",YEAR(A31)) -> 2026 | N31: =IF(A31="","",CHOOSE(WEEKDAY(A31,2),"Segunda","Terça","Quarta","Quinta","Sexta","Sábado","Domingo")) -> Terça | O31: =IF(B31="","",IF(B31<TIME(12,0,0),"Manhã",IF(B31<TIME(18,0,0),"Tarde","Noite"))) -> Tarde | P31: =IF(G31="","",IFERROR(INDEX(Config!$I$5:$I$16,MATCH(G31,Config!$H$5:$H$16,0)),0)) -> 30 | Q31: =IF(OR(H31<>"Realizado",P31="",P31=0),"",A31+P31) -> 46205 | R31: =IF(Q31="","",IF(COUNTIFS($E$5:$E$3004,E31,$A$5:$A$3004,">"&A31,$H$5:$H$3004,"<>Falta",$H$5:$H$3004,"<>Cancelado",$H$5:$H$3004,"<>Remarcado")>0,"Sim","Não")) -> Sim | S31: =IF(R31<>"Não","",IF(Q31+Config!$B$9<=Config!$B$8,Config!$B$8-Q31,"")) | T31: =IF(S31="","","Sim") | U31: =IF(T31="Sim",S31+ROW()/100000,0) -> 0 | V31: =IF(AND(H31="Falta",L31=Config!$B$7,M31=Config!$B$5,COUNTIFS($E$5:E31,E31,$H$5:H31,"Falta",$L$5:L31,Config!$B$7,$M$5:M31,Config!$B$5)=1),COUNTIFS($E$5:$E$3004,E31,$H$5:$H$3004,"Falta",$L$5:$L$3004,Config!$B$7,$M$5:$M$3004,Config!$B$5)*1000-ROW()/100000,0) -> 0
A32: 46175 | B32: 0.65972222 | C32: Dr. Paulo Andrade | D32: Sala 2 | E32: Fábio Correia | F32: Particular | G32: Retorno | H32: Realizado | I32: Sem cobrança | L32: =IF(A32="","",MONTH(A32)) -> 6 | M32: =IF(A32="","",YEAR(A32)) -> 2026 | N32: =IF(A32="","",CHOOSE(WEEKDAY(A32,2),"Segunda","Terça","Quarta","Quinta","Sexta","Sábado","Domingo")) -> Terça | O32: =IF(B32="","",IF(B32<TIME(12,0,0),"Manhã",IF(B32<TIME(18,0,0),"Tarde","Noite"))) -> Tarde | P32: =IF(G32="","",IFERROR(INDEX(Config!$I$5:$I$16,MATCH(G32,Config!$H$5:$H$16,0)),0)) -> 0 | Q32: =IF(OR(H32<>"Realizado",P32="",P32=0),"",A32+P32) | R32: =IF(Q32="","",IF(COUNTIFS($E$5:$E$3004,E32,$A$5:$A$3004,">"&A32,$H$5:$H$3004,"<>Falta",$H$5:$H$3004,"<>Cancelado",$H$5:$H$3004,"<>Remarcado")>0,"Sim","Não")) | S32: =IF(R32<>"Não","",IF(Q32+Config!$B$9<=Config!$B$8,Config!$B$8-Q32,"")) | T32: =IF(S32="","","Sim") | U32: =IF(T32="Sim",S32+ROW()/100000,0) -> 0 | V32: =IF(AND(H32="Falta",L32=Config!$B$7,M32=Config!$B$5,COUNTIFS($E$5:E32,E32,$H$5:H32,"Falta",$L$5:L32,Config!$B$7,$M$5:M32,Config!$B$5)=1),COUNTIFS($E$5:$E$3004,E32,$H$5:$H$3004,"Falta",$L$5:$L$3004,Config!$B$7,$M$5:$M$3004,Config!$B$5)*1000-ROW()/100000,0) -> 0
A33: 46175 | B33: 0.66666667 | C33: Dra. Renata Sousa | D33: Sala 1 | E33: Rafael Pereira | F33: Particular | G33: Avaliação endócrina | H33: Realizado | I33: Pix | L33: =IF(A33="","",MONTH(A33)) -> 6 | M33: =IF(A33="","",YEAR(A33)) -> 2026 | N33: =IF(A33="","",CHOOSE(WEEKDAY(A33,2),"Segunda","Terça","Quarta","Quinta","Sexta","Sábado","Domingo")) -> Terça | O33: =IF(B33="","",IF(B33<TIME(12,0,0),"Manhã",IF(B33<TIME(18,0,0),"Tarde","Noite"))) -> Tarde | P33: =IF(G33="","",IFERROR(INDEX(Config!$I$5:$I$16,MATCH(G33,Config!$H$5:$H$16,0)),0)) -> 45 | Q33: =IF(OR(H33<>"Realizado",P33="",P33=0),"",A33+P33) -> 46220 | R33: =IF(Q33="","",IF(COUNTIFS($E$5:$E$3004,E33,$A$5:$A$3004,">"&A33,$H$5:$H$3004,"<>Falta",$H$5:$H$3004,"<>Cancelado",$H$5:$H$3004,"<>Remarcado")>0,"Sim","Não")) -> Sim | S33: =IF(R33<>"Não","",IF(Q33+Config!$B$9<=Config!$B$8,Config!$B$8-Q33,"")) | T33: =IF(S33="","","Sim") | U33: =IF(T33="Sim",S33+ROW()/100000,0) -> 0 | V33: =IF(AND(H33="Falta",L33=Config!$B$7,M33=Config!$B$5,COUNTIFS($E$5:E33,E33,$H$5:H33,"Falta",$L$5:L33,Config!$B$7,$M$5:M33,Config!$B$5)=1),COUNTIFS($E$5:$E$3004,E33,$H$5:$H$3004,"Falta",$L$5:$L$3004,Config!$B$7,$M$5:$M$3004,Config!$B$5)*1000-ROW()/100000,0) -> 0
