Workbook

Sheet Como usar
A1: Rotina da semana da clínica
A2: Kit de Gestão para Médicos · Seu Sócio Gestor · versão 1.0 (setembro de 2026)
A4: O que esta planilha faz | B4: Fixa a rotina de gestão em dois momentos curtos: segunda (agenda, faltas e retornos) e sexta (caixa, guias, orçamentos e painel). Você marca, semana a semana, o que foi feito; o Painel mostra a aderência das últimas 4 semanas, por dia e por rotina.
A5: Passo 1 | B5: Em Config, troque a data de referência por =HOJE() (no exemplo ela está congelada em 14/09/2026), a segunda-feira da semana 1 (sugestão: a primeira do ano) e as pessoas da clínica.
A6: Passo 2 | B6: Em Rotina, ajuste as linhas: dia, rotina, minutos e responsável. O exemplo soma 30 minutos por semana (3 rotinas de segunda = 12 min; 5 de sexta = 18 min), a maior parte com a recepção; mantenha curto, o que é longo não vira hábito. O checklist do dia (04) é da recepção e corre por fora destes 30 minutos.
A7: Passo 3 | B7: Toda segunda e toda sexta, depois de fazer a rotina, marque Sim (ou Não, se pulou) na coluna da semana. A coluna da semana atual fica destacada em amarelo.
A8: Passo 4 | B8: Em Painel, veja a aderência das últimas 4 semanas registradas, a série das últimas 8 e qual rotina está sendo pulada. Menos de 70% em vermelho.
A9: Exemplo | B9: A clínica fictícia registrou de 20/07 a 07/09/2026 (S29 a S36). O Painel sempre olha as últimas semanas registradas, então o exemplo continua fazendo sentido em qualquer data. Em janeiro de 2027, troque a segunda-feira da semana 1 em Config (veja a nota lá).
A10: Com a IA | B10: Copie a tabela "Por rotina" e use o prompt "Agenda 05 · Rotina da recepção em 30 minutos por semana" da biblioteca do kit.
A11: Legenda | B11: Células amarelas: você preenche. Brancas: calculadas. Não é preciso mexer em nada fora do amarelo.
A12: Proteção | B12: Fórmulas protegidas sem senha. Para editar: Revisar > Desproteger planilha (Excel) ou Dados > Proteger intervalos (Google Sheets).
A13: Requisitos | B13: Excel 2016 ou mais novo, Microsoft 365 ou Google Sheets (só funções do Excel 2007+; nada de MÍNIMOSES, MÁXIMOSES ou UNIRTEXTO). No celular abre nos aplicativos; para preencher, use o computador.
A14: Dados de pacientes | B14: Guarde só o que a gestão precisa (nome, contato, valor, data). Nada de diagnóstico, prontuário ou exame nestas planilhas: o kit é gestão, não é prontuário. Veja o guia LGPD do kit antes de colar qualquer tabela em uma IA.
A15: Google Sheets | B15: Faça upload no Google Drive e abra com o Google Sheets. Fórmulas, listas, cores, semáforos e gráficos funcionam: as regras de cor que dependem do mês escolhido em Config usam INDIRECT, que é a forma que o Sheets aceita para regra condicional apontar para outra aba.
... A18: Suporte | B18: suporte@seusociogestor.com.br · resposta em até 5 dias úteis · reembolso em até 7 dias pelo mesmo canal.

Sheet Painel
A1: =Config!$B$4&" · Aderência à rotina · "&TEXT(DAY(Config!$B$5),"00")&"/"&TEXT(MONTH(Config!$B$5),"00")&"/"&YEAR(Config!$B$5) -> Clínica Vida Plena (exemplo fictício) · Aderência à rotina · 14/09/2026
A2: Nada para digitar aqui: tudo vem de Config e Rotina. Aderência = rotinas feitas ÷ rotinas planejadas nas últimas 4 semanas registradas.
A4: Aderência (últimas 4 semanas) | C4: Semana atual | E4: Última registrada | G4: Minutos por semana | J4: Última semana registrada | K4: =SUMPRODUCT(MAX((Rotina!$E$31:$BD$31>0)*Rotina!$E$2:$BD$2)) -> 36
A5: =IF(OR($K$4=0,$K$7=0),"",SUMPRODUCT((Rotina!$E$2:$BD$2>=$K$4-3)*(Rotina!$E$2:$BD$2<=$K$4)*Rotina!$E$30:$BD$30)/($K$6*$K$7)) -> 0.84375 | C5: ="S"&$K$5&" · "&TEXT(DAY(Config!$B$6+7*($K$5-1)),"00")&"/"&TEXT(MONTH(Config!$B$6+7*($K$5-1)),"00") -> S37 · 14/09 | E5: =IF($K$4=0,"nenhuma","S"&$K$4&" · "&TEXT(DAY(Config!$B$6+7*($K$4-1)),"00")&"/"&TEXT(MONTH(Config!$B$6+7*($K$4-1)),"00")) -> S36 · 07/09 | G5: =SUM(Rotina!$C$5:$C$28) -> 30 | J5: Semana da data de referência | K5: =MIN(52,MAX(1,INT((Config!$B$5-Config!$B$6)/7)+1)) -> 37
J6: Semanas consideradas | K6: =MIN(4,K4) -> 4
A7: Por dia da semana (últimas 4 semanas registradas) | J7: Rotinas planejadas | K7: =COUNTA(Rotina!$B$5:$B$28) -> 8
A8: Dia | B8: Rotinas | C8: Minutos | D8: Feitas | E8: Planejadas | F8: Aderência
A9: Segunda | B9: =COUNTIFS(Rotina!$A$5:$A$28,A9,Rotina!$B$5:$B$28,"<>") -> 3 | C9: =SUMIFS(Rotina!$C$5:$C$28,Rotina!$A$5:$A$28,A9,Rotina!$B$5:$B$28,"<>") -> 12 | D9: =IF($K$4=0,"",SUMIFS($E$29:$E$52,$A$29:$A$52,A9)) -> 12 | E9: =IF($K$4=0,"",B9*$K$6) -> 12 | F9: =IF(OR(E9="",E9=0),"",D9/E9) -> 1
A10: Terça | B10: =COUNTIFS(Rotina!$A$5:$A$28,A10,Rotina!$B$5:$B$28,"<>") -> 0 | C10: =SUMIFS(Rotina!$C$5:$C$28,Rotina!$A$5:$A$28,A10,Rotina!$B$5:$B$28,"<>") -> 0 | D10: =IF($K$4=0,"",SUMIFS($E$29:$E$52,$A$29:$A$52,A10)) -> 0 | E10: =IF($K$4=0,"",B10*$K$6) -> 0 | F10: =IF(OR(E10="",E10=0),"",D10/E10)
A11: Quarta | B11: =COUNTIFS(Rotina!$A$5:$A$28,A11,Rotina!$B$5:$B$28,"<>") -> 0 | C11: =SUMIFS(Rotina!$C$5:$C$28,Rotina!$A$5:$A$28,A11,Rotina!$B$5:$B$28,"<>") -> 0 | D11: =IF($K$4=0,"",SUMIFS($E$29:$E$52,$A$29:$A$52,A11)) -> 0 | E11: =IF($K$4=0,"",B11*$K$6) -> 0 | F11: =IF(OR(E11="",E11=0),"",D11/E11)
A12: Quinta | B12: =COUNTIFS(Rotina!$A$5:$A$28,A12,Rotina!$B$5:$B$28,"<>") -> 0 | C12: =SUMIFS(Rotina!$C$5:$C$28,Rotina!$A$5:$A$28,A12,Rotina!$B$5:$B$28,"<>") -> 0 | D12: =IF($K$4=0,"",SUMIFS($E$29:$E$52,$A$29:$A$52,A12)) -> 0 | E12: =IF($K$4=0,"",B12*$K$6) -> 0 | F12: =IF(OR(E12="",E12=0),"",D12/E12)
A13: Sexta | B13: =COUNTIFS(Rotina!$A$5:$A$28,A13,Rotina!$B$5:$B$28,"<>") -> 5 | C13: =SUMIFS(Rotina!$C$5:$C$28,Rotina!$A$5:$A$28,A13,Rotina!$B$5:$B$28,"<>") -> 18 | D13: =IF($K$4=0,"",SUMIFS($E$29:$E$52,$A$29:$A$52,A13)) -> 15 | E13: =IF($K$4=0,"",B13*$K$6) -> 20 | F13: =IF(OR(E13="",E13=0),"",D13/E13) -> 0.75
A15: Últimas 8 semanas registradas
A16: Semana | B16: Segunda-feira | C16: Feitas | D16: Planejadas | E16: Aderência | F16: Minutos | G16: Barra
A17: =IF(($K$4-7)<1,"","S"&($K$4-7)) -> S29 | B17: =IF(A17="","",INDEX(Rotina!$E$3:$BD$3,($K$4-7))) -> 46223 | C17: =IF(A17="","",INDEX(Rotina!$E$30:$BD$30,($K$4-7))) -> 4 | D17: =IF(A17="","",INDEX(Rotina!$E$32:$BD$32,($K$4-7))) -> 8 | E17: =IF(OR(A17="",D17=0),"",C17/D17) -> 0.5 | F17: =IF(A17="","",INDEX(Rotina!$E$34:$BD$34,($K$4-7))) -> 15 | G17: =IF(E17="","",REPT("█",ROUND(E17*10,0))) -> █████
A18: =IF(($K$4-6)<1,"","S"&($K$4-6)) -> S30 | B18: =IF(A18="","",INDEX(Rotina!$E$3:$BD$3,($K$4-6))) -> 46230 | C18: =IF(A18="","",INDEX(Rotina!$E$30:$BD$30,($K$4-6))) -> 7 | D18: =IF(A18="","",INDEX(Rotina!$E$32:$BD$32,($K$4-6))) -> 8 | E18: =IF(OR(A18="",D18=0),"",C18/D18) -> 0.875 | F18: =IF(A18="","",INDEX(Rotina!$E$34:$BD$34,($K$4-6))) -> 27 | G18: =IF(E18="","",REPT("█",ROUND(E18*10,0))) -> █████████
A19: =IF(($K$4-5)<1,"","S"&($K$4-5)) -> S31 | B19: =IF(A19="","",INDEX(Rotina!$E$3:$BD$3,($K$4-5))) -> 46237 | C19: =IF(A19="","",INDEX(Rotina!$E$30:$BD$30,($K$4-5))) -> 6 | D19: =IF(A19="","",INDEX(Rotina!$E$32:$BD$32,($K$4-5))) -> 8 | E19: =IF(OR(A19="",D19=0),"",C19/D19) -> 0.75 | F19: =IF(A19="","",INDEX(Rotina!$E$34:$BD$34,($K$4-5))) -> 23 | G19: =IF(E19="","",REPT("█",ROUND(E19*10,0))) -> ████████
A20: =IF(($K$4-4)<1,"","S"&($K$4-4)) -> S32 | B20: =IF(A20="","",INDEX(Rotina!$E$3:$BD$3,($K$4-4))) -> 46244 | C20: =IF(A20="","",INDEX(Rotina!$E$30:$BD$30,($K$4-4))) -> 8 | D20: =IF(A20="","",INDEX(Rotina!$E$32:$BD$32,($K$4-4))) -> 8 | E20: =IF(OR(A20="",D20=0),"",C20/D20) -> 1 | F20: =IF(A20="","",INDEX(Rotina!$E$34:$BD$34,($K$4-4))) -> 30 | G20: =IF(E20="","",REPT("█",ROUND(E20*10,0))) -> ██████████
A21: =IF(($K$4-3)<1,"","S"&($K$4-3)) -> S33 | B21: =IF(A21="","",INDEX(Rotina!$E$3:$BD$3,($K$4-3))) -> 46251 | C21: =IF(A21="","",INDEX(Rotina!$E$30:$BD$30,($K$4-3))) -> 6 | D21: =IF(A21="","",INDEX(Rotina!$E$32:$BD$32,($K$4-3))) -> 8 | E21: =IF(OR(A21="",D21=0),"",C21/D21) -> 0.75 | F21: =IF(A21="","",INDEX(Rotina!$E$34:$BD$34,($K$4-3))) -> 22 | G21: =IF(E21="","",REPT("█",ROUND(E21*10,0))) -> ████████
A22: =IF(($K$4-2)<1,"","S"&($K$4-2)) -> S34 | B22: =IF(A22="","",INDEX(Rotina!$E$3:$BD$3,($K$4-2))) -> 46258 | C22: =IF(A22="","",INDEX(Rotina!$E$30:$BD$30,($K$4-2))) -> 7 | D22: =IF(A22="","",INDEX(Rotina!$E$32:$BD$32,($K$4-2))) -> 8 | E22: =IF(OR(A22="",D22=0),"",C22/D22) -> 0.875 | F22: =IF(A22="","",INDEX(Rotina!$E$34:$BD$34,($K$4-2))) -> 27 | G22: =IF(E22="","",REPT("█",ROUND(E22*10,0))) -> █████████
A23: =IF(($K$4-1)<1,"","S"&($K$4-1)) -> S35 | B23: =IF(A23="","",INDEX(Rotina!$E$3:$BD$3,($K$4-1))) -> 46265 | C23: =IF(A23="","",INDEX(Rotina!$E$30:$BD$30,($K$4-1))) -> 7 | D23: =IF(A23="","",INDEX(Rotina!$E$32:$BD$32,($K$4-1))) -> 8 | E23: =IF(OR(A23="",D23=0),"",C23/D23) -> 0.875 | F23: =IF(A23="","",INDEX(Rotina!$E$34:$BD$34,($K$4-1))) -> 25 | G23: =IF(E23="","",REPT("█",ROUND(E23*10,0))) -> █████████
A24: =IF(($K$4-0)<1,"","S"&($K$4-0)) -> S36 | B24: =IF(A24="","",INDEX(Rotina!$E$3:$BD$3,($K$4-0))) -> 46272 | C24: =IF(A24="","",INDEX(Rotina!$E$30:$BD$30,($K$4-0))) -> 7 | D24: =IF(A24="","",INDEX(Rotina!$E$32:$BD$32,($K$4-0))) -> 8 | E24: =IF(OR(A24="",D24=0),"",C24/D24) -> 0.875 | F24: =IF(A24="","",INDEX(Rotina!$E$34:$BD$34,($K$4-0))) -> 27 | G24: =IF(E24="","",REPT("█",ROUND(E24*10,0))) -> █████████
A26: Por rotina (últimas 4 semanas registradas)
A27: A rotina mais pulada é a que merece ser encurtada, delegada ou trocada de dia.
A28: Dia | B28: Rotina | C28: Minutos | D28: Responsável | E28: Feitas | F28: De | G28: Aderência | H28: Atenção
A29: =IF(Rotina!$B5="","",Rotina!$A5) -> Segunda | B29: =IF(Rotina!$B5="","",Rotina!$B5) -> Abrir a Agenda (01): olhar as vagas dos próximos 7 dias e a ocupação da semana | C29: =IF(Rotina!$B5="","",Rotina!$C5) -> 4 | D29: =IF(Rotina!$B5="","",Rotina!$D5) -> Bruna Carvalho | E29: =IF(OR(Rotina!$B5="",$K$4=0),"",SUMPRODUCT((Rotina!$E$5:$BD$5="Sim")*(Rotina!$E$2:$BD$2>=$K$4-3)*(Rotina!$E$2:$BD$2<=$K$4))) -> 4 | F29: =IF(E29="","",$K$6) -> 4 | G29: =IF(OR(E29="",F29=0),"",E29/F29) -> 1 | H29: =IF(G29="","",IF(G29<0.5,"Pulada na maioria das semanas",IF(G29<0.75,"Pulada às vezes","")))
A30: =IF(Rotina!$B6="","",Rotina!$A6) -> Segunda | B30: =IF(Rotina!$B6="","",Rotina!$B6) -> Confirmar por mensagem os agendados da semana | C30: =IF(Rotina!$B6="","",Rotina!$C6) -> 4 | D30: =IF(Rotina!$B6="","",Rotina!$D6) -> Bruna Carvalho | E30: =IF(OR(Rotina!$B6="",$K$4=0),"",SUMPRODUCT((Rotina!$E$6:$BD$6="Sim")*(Rotina!$E$2:$BD$2>=$K$4-3)*(Rotina!$E$2:$BD$2<=$K$4))) -> 4 | F30: =IF(E30="","",$K$6) -> 4 | G30: =IF(OR(E30="",F30=0),"",E30/F30) -> 1 | H30: =IF(G30="","",IF(G30<0.5,"Pulada na maioria das semanas",IF(G30<0.75,"Pulada às vezes","")))
A31: =IF(Rotina!$B7="","",Rotina!$A7) -> Segunda | B31: =IF(Rotina!$B7="","",Rotina!$B7) -> Ligar para a lista de retorno (02) e registrar as faltas da semana passada | C31: =IF(Rotina!$B7="","",Rotina!$C7) -> 4 | D31: =IF(Rotina!$B7="","",Rotina!$D7) -> Bruna Carvalho | E31: =IF(OR(Rotina!$B7="",$K$4=0),"",SUMPRODUCT((Rotina!$E$7:$BD$7="Sim")*(Rotina!$E$2:$BD$2>=$K$4-3)*(Rotina!$E$2:$BD$2<=$K$4))) -> 4 | F31: =IF(E31="","",$K$6) -> 4 | G31: =IF(OR(E31="",F31=0),"",E31/F31) -> 1 | H31: =IF(G31="","",IF(G31<0.5,"Pulada na maioria das semanas",IF(G31<0.75,"Pulada às vezes","")))
A32: =IF(Rotina!$B8="","",Rotina!$A8) -> Sexta | B32: =IF(Rotina!$B8="","",Rotina!$B8) -> Conferir os fechamentos da semana no Caixa (09) | C32: =IF(Rotina!$B8="","",Rotina!$C8) -> 5 | D32: =IF(Rotina!$B8="","",Rotina!$D8) -> Dra. Carolina Mendes | E32: =IF(OR(Rotina!$B8="",$K$4=0),"",SUMPRODUCT((Rotina!$E$8:$BD$8="Sim")*(Rotina!$E$2:$BD$2>=$K$4-3)*(Rotina!$E$2:$BD$2<=$K$4))) -> 2 | F32: =IF(E32="","",$K$6) -> 4 | G32: =IF(OR(E32="",F32=0),"",E32/F32) -> 0.5 | H32: =IF(G32="","",IF(G32<0.5,"Pulada na maioria das semanas",IF(G32<0.75,"Pulada às vezes",""))) -> Pulada às vezes
A33: =IF(Rotina!$B9="","",Rotina!$A9) -> Sexta | B33: =IF(Rotina!$B9="","",Rotina!$B9) -> Marcar parcelas recebidas e enviar a cobrança educada (14) | C33: =IF(Rotina!$B9="","",Rotina!$C9) -> 4 | D33: =IF(Rotina!$B9="","",Rotina!$D9) -> Bruna Carvalho | E33: =IF(OR(Rotina!$B9="",$K$4=0),"",SUMPRODUCT((Rotina!$E$9:$BD$9="Sim")*(Rotina!$E$2:$BD$2>=$K$4-3)*(Rotina!$E$2:$BD$2<=$K$4))) -> 4 | F33: =IF(E33="","",$K$6) -> 4 | G33: =IF(OR(E33="",F33=0),"",E33/F33) -> 1 | H33: =IF(G33="","",IF(G33<0.5,"Pulada na maioria das semanas",IF(G33<0.75,"Pulada às vezes","")))
A34: =IF(Rotina!$B10="","",Rotina!$A10) -> Sexta | B34: =IF(Rotina!$B10="","",Rotina!$B10) -> Separar as guias da semana e atualizar os lotes (13) | C34: =IF(Rotina!$B10="","",Rotina!$C10) -> 3 | D34: =IF(Rotina!$B10="","",Rotina!$D10) -> Bruna Carvalho | E34: =IF(OR(Rotina!$B10="",$K$4=0),"",SUMPRODUCT((Rotina!$E$10:$BD$10="Sim")*(Rotina!$E$2:$BD$2>=$K$4-3)*(Rotina!$E$2:$BD$2<=$K$4))) -> 4 | F34: =IF(E34="","",$K$6) -> 4 | G34: =IF(OR(E34="",F34=0),"",E34/F34) -> 1 | H34: =IF(G34="","",IF(G34<0.5,"Pulada na maioria das semanas",IF(G34<0.75,"Pulada às vezes","")))
A35: =IF(Rotina!$B11="","",Rotina!$A11) -> Sexta | B35: =IF(Rotina!$B11="","",Rotina!$B11) -> Atualizar os orçamentos apresentados e aprovados (15) | C35: =IF(Rotina!$B11="","",Rotina!$C11) -> 3 | D35: =IF(Rotina!$B11="","",Rotina!$D11) -> Bruna Carvalho | E35: =IF(OR(Rotina!$B11="",$K$4=0),"",SUMPRODUCT((Rotina!$E$11:$BD$11="Sim")*(Rotina!$E$2:$BD$2>=$K$4-3)*(Rotina!$E$2:$BD$2<=$K$4))) -> 2 | F35: =IF(E35="","",$K$6) -> 4 | G35: =IF(OR(E35="",F35=0),"",E35/F35) -> 0.5 | H35: =IF(G35="","",IF(G35<0.5,"Pulada na maioria das semanas",IF(G35<0.75,"Pulada às vezes",""))) -> Pulada às vezes
A36: =IF(Rotina!$B12="","",Rotina!$A12) -> Sexta | B36: =IF(Rotina!$B12="","",Rotina!$B12) -> Olhar o Painel da clínica (17) e anotar até 3 decisões | C36: =IF(Rotina!$B12="","",Rotina!$C12) -> 3 | D36: =IF(Rotina!$B12="","",Rotina!$D12) -> Dr. Paulo Andrade | E36: =IF(OR(Rotina!$B12="",$K$4=0),"",SUMPRODUCT((Rotina!$E$12:$BD$12="Sim")*(Rotina!$E$2:$BD$2>=$K$4-3)*(Rotina!$E$2:$BD$2<=$K$4))) -> 3 | F36: =IF(E36="","",$K$6) -> 4 | G36: =IF(OR(E36="",F36=0),"",E36/F36) -> 0.75 | H36: =IF(G36="","",IF(G36<0.5,"Pulada na maioria das semanas",IF(G36<0.75,"Pulada às vezes","")))
A37: =IF(Rotina!$B13="","",Rotina!$A13) | B37: =IF(Rotina!$B13="","",Rotina!$B13) | C37: =IF(Rotina!$B13="","",Rotina!$C13) | D37: =IF(Rotina!$B13="","",Rotina!$D13) | E37: =IF(OR(Rotina!$B13="",$K$4=0),"",SUMPRODUCT((Rotina!$E$13:$BD$13="Sim")*(Rotina!$E$2:$BD$2>=$K$4-3)*(Rotina!$E$2:$BD$2<=$K$4))) | F37: =IF(E37="","",$K$6) | G37: =IF(OR(E37="",F37=0),"",E37/F37) | H37: =IF(G37="","",IF(G37<0.5,"Pulada na maioria das semanas",IF(G37<0.75,"Pulada às vezes","")))
A38: =IF(Rotina!$B14="","",Rotina!$A14) | B38: =IF(Rotina!$B14="","",Rotina!$B14) | C38: =IF(Rotina!$B14="","",Rotina!$C14) | D38: =IF(Rotina!$B14="","",Rotina!$D14) | E38: =IF(OR(Rotina!$B14="",$K$4=0),"",SUMPRODUCT((Rotina!$E$14:$BD$14="Sim")*(Rotina!$E$2:$BD$2>=$K$4-3)*(Rotina!$E$2:$BD$2<=$K$4))) | F38: =IF(E38="","",$K$6) | G38: =IF(OR(E38="",F38=0),"",E38/F38) | H38: =IF(G38="","",IF(G38<0.5,"Pulada na maioria das semanas",IF(G38<0.75,"Pulada às vezes","")))
A39: =IF(Rotina!$B15="","",Rotina!$A15) | B39: =IF(Rotina!$B15="","",Rotina!$B15) | C39: =IF(Rotina!$B15="","",Rotina!$C15) | D39: =IF(Rotina!$B15="","",Rotina!$D15) | E39: =IF(OR(Rotina!$B15="",$K$4=0),"",SUMPRODUCT((Rotina!$E$15:$BD$15="Sim")*(Rotina!$E$2:$BD$2>=$K$4-3)*(Rotina!$E$2:$BD$2<=$K$4))) | F39: =IF(E39="","",$K$6) | G39: =IF(OR(E39="",F39=0),"",E39/F39) | H39: =IF(G39="","",IF(G39<0.5,"Pulada na maioria das semanas",IF(G39<0.75,"Pulada às vezes","")))
A40: =IF(Rotina!$B16="","",Rotina!$A16) | B40: =IF(Rotina!$B16="","",Rotina!$B16) | C40: =IF(Rotina!$B16="","",Rotina!$C16) | D40: =IF(Rotina!$B16="","",Rotina!$D16) | E40: =IF(OR(Rotina!$B16="",$K$4=0),"",SUMPRODUCT((Rotina!$E$16:$BD$16="Sim")*(Rotina!$E$2:$BD$2>=$K$4-3)*(Rotina!$E$2:$BD$2<=$K$4))) | F40: =IF(E40="","",$K$6) | G40: =IF(OR(E40="",F40=0),"",E40/F40) | H40: =IF(G40="","",IF(G40<0.5,"Pulada na maioria das semanas",IF(G40<0.75,"Pulada às vezes","")))
A41: =IF(Rotina!$B17="","",Rotina!$A17) | B41: =IF(Rotina!$B17="","",Rotina!$B17) | C41: =IF(Rotina!$B17="","",Rotina!$C17) | D41: =IF(Rotina!$B17="","",Rotina!$D17) | E41: =IF(OR(Rotina!$B17="",$K$4=0),"",SUMPRODUCT((Rotina!$E$17:$BD$17="Sim")*(Rotina!$E$2:$BD$2>=$K$4-3)*(Rotina!$E$2:$BD$2<=$K$4))) | F41: =IF(E41="","",$K$6) | G41: =IF(OR(E41="",F41=0),"",E41/F41) | H41: =IF(G41="","",IF(G41<0.5,"Pulada na maioria das semanas",IF(G41<0.75,"Pulada às vezes","")))
A42: =IF(Rotina!$B18="","",Rotina!$A18) | B42: =IF(Rotina!$B18="","",Rotina!$B18) | C42: =IF(Rotina!$B18="","",Rotina!$C18) | D42: =IF(Rotina!$B18="","",Rotina!$D18) | E42: =IF(OR(Rotina!$B18="",$K$4=0),"",SUMPRODUCT((Rotina!$E$18:$BD$18="Sim")*(Rotina!$E$2:$BD$2>=$K$4-3)*(Rotina!$E$2:$BD$2<=$K$4))) | F42: =IF(E42="","",$K$6) | G42: =IF(OR(E42="",F42=0),"",E42/F42) | H42: =IF(G42="","",IF(G42<0.5,"Pulada na maioria das semanas",IF(G42<0.75,"Pulada às vezes","")))
A43: =IF(Rotina!$B19="","",Rotina!$A19) | B43: =IF(Rotina!$B19="","",Rotina!$B19) | C43: =IF(Rotina!$B19="","",Rotina!$C19) | D43: =IF(Rotina!$B19="","",Rotina!$D19) | E43: =IF(OR(Rotina!$B19="",$K$4=0),"",SUMPRODUCT((Rotina!$E$19:$BD$19="Sim")*(Rotina!$E$2:$BD$2>=$K$4-3)*(Rotina!$E$2:$BD$2<=$K$4))) | F43: =IF(E43="","",$K$6) | G43: =IF(OR(E43="",F43=0),"",E43/F43) | H43: =IF(G43="","",IF(G43<0.5,"Pulada na maioria das semanas",IF(G43<0.75,"Pulada às vezes","")))
...

Sheet Config
A1: Configurações
A2: Células amarelas: você preenche.
A4: Clínica | B4: Clínica Vida Plena (exemplo fictício)
A5: Data de referência (hoje) | B5: 46279 | C5: O exemplo está congelado em 14/09/2026, para os arquivos do kit mostrarem a mesma foto. Ao usar com os seus dados, troque por =HOJE().
A6: Segunda-feira da semana 1 | B6: 46027 | C6: Sugestão: a primeira segunda-feira do ano. As 52 colunas da aba Rotina contam a partir daqui. O exemplo está preenchido de 20/07 a 07/09/2026 (S29 a S36).
C7: Virada do ano: em janeiro de 2027, salve uma cópia desta planilha, troque a data acima pela primeira segunda-feira de 2027 (04/01/2027) e limpe as marcações da aba Rotina. As 52 semanas recomeçam.
A8: Responsáveis (até 10)
B9: Dra. Carolina Mendes
B10: Dr. Paulo Andrade
B11: Bruna Carvalho
A20: Preencha de cima para baixo, sem pular linha: a lista suspensa para na última linha preenchida.

Sheet Rotina
A1: Rotina da semana
A2: Linhas: as rotinas fixas de segunda (agenda) e de sexta (caixa e painel). Colunas: uma por semana. Marque Sim ou Não em cada semana; os totais e o Painel são calculados. | E2: 1 | F2: 2 | G2: 3 | H2: 4 | I2: 5 | J2: 6 | K2: 7 | L2: 8 | M2: 9 | N2: 10 | O2: 11 | P2: 12 | Q2: 13 | R2: 14 | S2: 15 | T2: 16 | U2: 17 | V2: 18 | W2: 19 | X2: 20 | Y2: 21 | Z2: 22 | AA2: 23 | AB2: 24 | AC2: 25 | AD2: 26 | AE2: 27 | AF2: 28 | AG2: 29 | AH2: 30 | AI2: 31 | AJ2: 32 | AK2: 33 | AL2: 34 | AM2: 35 | AN2: 36 | AO2: 37 | AP2: 38 | AQ2: 39 | AR2: 40 | AS2: 41 | AT2: 42 | AU2: 43 | AV2: 44 | AW2: 45 | AX2: 46 | AY2: 47 | AZ2: 48 | BA2: 49 | BB2: 50 | BC2: 51 | BD2: 52
A3: Semana começa em | E3: =Config!$B$6+0 -> 46027 | F3: =Config!$B$6+7 -> 46034 | G3: =Config!$B$6+14 -> 46041 | H3: =Config!$B$6+21 -> 46048 | I3: =Config!$B$6+28 -> 46055 | J3: =Config!$B$6+35 -> 46062 | K3: =Config!$B$6+42 -> 46069 | L3: =Config!$B$6+49 -> 46076 | M3: =Config!$B$6+56 -> 46083 | N3: =Config!$B$6+63 -> 46090 | O3: =Config!$B$6+70 -> 46097 | P3: =Config!$B$6+77 -> 46104 | Q3: =Config!$B$6+84 -> 46111 | R3: =Config!$B$6+91 -> 46118 | S3: =Config!$B$6+98 -> 46125 | T3: =Config!$B$6+105 -> 46132 | U3: =Config!$B$6+112 -> 46139 | V3: =Config!$B$6+119 -> 46146 | W3: =Config!$B$6+126 -> 46153 | X3: =Config!$B$6+133 -> 46160 | Y3: =Config!$B$6+140 -> 46167 | Z3: =Config!$B$6+147 -> 46174 | AA3: =Config!$B$6+154 -> 46181 | AB3: =Config!$B$6+161 -> 46188 | AC3: =Config!$B$6+168 -> 46195 | AD3: =Config!$B$6+175 -> 46202 | AE3: =Config!$B$6+182 -> 46209 | AF3: =Config!$B$6+189 -> 46216 | AG3: =Config!$B$6+196 -> 46223 | AH3: =Config!$B$6+203 -> 46230 | AI3: =Config!$B$6+210 -> 46237 | AJ3: =Config!$B$6+217 -> 46244 | AK3: =Config!$B$6+224 -> 46251 | AL3: =Config!$B$6+231 -> 46258 | AM3: =Config!$B$6+238 -> 46265 | AN3: =Config!$B$6+245 -> 46272 | AO3: =Config!$B$6+252 -> 46279 | AP3: =Config!$B$6+259 -> 46286 | AQ3: =Config!$B$6+266 -> 46293 | AR3: =Config!$B$6+273 -> 46300 | AS3: =Config!$B$6+280 -> 46307 | AT3: =Config!$B$6+287 -> 46314 | AU3: =Config!$B$6+294 -> 46321 | AV3: =Config!$B$6+301 -> 46328 | AW3: =Config!$B$6+308 -> 46335 | AX3: =Config!$B$6+315 -> 46342 | AY3: =Config!$B$6+322 -> 46349 | AZ3: =Config!$B$6+329 -> 46356 | BA3: =Config!$B$6+336 -> 46363 | BB3: =Config!$B$6+343 -> 46370 | BC3: =Config!$B$6+350 -> 46377 | BD3: =Config!$B$6+357 -> 46384
A4: Dia | B4: Rotina | C4: Minutos | D4: Responsável | E4: S1 | F4: S2 | G4: S3 | H4: S4 | I4: S5 | J4: S6 | K4: S7 | L4: S8 | M4: S9 | N4: S10 | O4: S11 | P4: S12 | Q4: S13 | R4: S14 | S4: S15 | T4: S16 | U4: S17 | V4: S18 | W4: S19 | X4: S20 | Y4: S21 | Z4: S22 | AA4: S23 | AB4: S24 | AC4: S25 | AD4: S26 | AE4: S27 | AF4: S28 | AG4: S29 | AH4: S30 | AI4: S31 | AJ4: S32 | AK4: S33 | AL4: S34 | AM4: S35 | AN4: S36 | AO4: S37 | AP4: S38 | AQ4: S39 | AR4: S40 | AS4: S41 | AT4: S42 | AU4: S43 | AV4: S44 | AW4: S45 | AX4: S46 | AY4: S47 | AZ4: S48 | BA4: S49 | BB4: S50 | BC4: S51 | BD4: S52
A5: Segunda | B5: Abrir a Agenda (01): olhar as vagas dos próximos 7 dias e a ocupação da semana | C5: 4 | D5: Bruna Carvalho | AG5: Sim | AH5: Sim | AI5: Sim | AJ5: Sim | AK5: Sim | AL5: Sim | AM5: Sim | AN5: Sim
A6: Segunda | B6: Confirmar por mensagem os agendados da semana | C6: 4 | D6: Bruna Carvalho | AG6: Não | AH6: Sim | AI6: Sim | AJ6: Sim | AK6: Sim | AL6: Sim | AM6: Sim | AN6: Sim
A7: Segunda | B7: Ligar para a lista de retorno (02) e registrar as faltas da semana passada | C7: 4 | D7: Bruna Carvalho | AG7: Não | AH7: Sim | AI7: Não | AJ7: Sim | AK7: Sim | AL7: Sim | AM7: Sim | AN7: Sim
A8: Sexta | B8: Conferir os fechamentos da semana no Caixa (09) | C8: 5 | D8: Dra. Carolina Mendes | AG8: Sim | AH8: Sim | AI8: Sim | AJ8: Sim | AK8: Não | AL8: Sim | AM8: Não | AN8: Sim
A9: Sexta | B9: Marcar parcelas recebidas e enviar a cobrança educada (14) | C9: 4 | D9: Bruna Carvalho | AG9: Não | AH9: Sim | AI9: Sim | AJ9: Sim | AK9: Sim | AL9: Sim | AM9: Sim | AN9: Sim
A10: Sexta | B10: Separar as guias da semana e atualizar os lotes (13) | C10: 3 | D10: Bruna Carvalho | AG10: Sim | AH10: Sim | AI10: Sim | AJ10: Sim | AK10: Sim | AL10: Sim | AM10: Sim | AN10: Sim
A11: Sexta | B11: Atualizar os orçamentos apresentados e aprovados (15) | C11: 3 | D11: Bruna Carvalho | AG11: Sim | AH11: Não | AI11: Sim | AJ11: Sim | AK11: Não | AL11: Sim | AM11: Sim | AN11: Não
A12: Sexta | B12: Olhar o Painel da clínica (17) e anotar até 3 decisões | C12: 3 | D12: Dr. Paulo Andrade | AG12: Não | AH12: Sim | AI12: Não | AJ12: Sim | AK12: Sim | AL12: Não | AM12: Sim | AN12: Sim
B30: Feitas na semana | E30: =COUNTIF(E5:E28,"Sim") -> 0 | F30: =COUNTIF(F5:F28,"Sim") -> 0 | G30: =COUNTIF(G5:G28,"Sim") -> 0 | H30: =COUNTIF(H5:H28,"Sim") -> 0 | I30: =COUNTIF(I5:I28,"Sim") -> 0 | J30: =COUNTIF(J5:J28,"Sim") -> 0 | K30: =COUNTIF(K5:K28,"Sim") -> 0 | L30: =COUNTIF(L5:L28,"Sim") -> 0 | ... BD30: =COUNTIF(BD5:BD28,"Sim") -> 0
B31: Registradas (Sim ou Não) | E31: =COUNTIF(E5:E28,"Sim")+COUNTIF(E5:E28,"Não") -> 0 | F31: =COUNTIF(F5:F28,"Sim")+COUNTIF(F5:F28,"Não") -> 0 | G31: =COUNTIF(G5:G28,"Sim")+COUNTIF(G5:G28,"Não") -> 0 | H31: =COUNTIF(H5:H28,"Sim")+COUNTIF(H5:H28,"Não") -> 0 | I31: =COUNTIF(I5:I28,"Sim")+COUNTIF(I5:I28,"Não") -> 0 | J31: =COUNTIF(J5:J28,"Sim")+COUNTIF(J5:J28,"Não") -> 0 | K31: =COUNTIF(K5:K28,"Sim")+COUNTIF(K5:K28,"Não") -> 0 | L31: =COUNTIF(L5:L28,"Sim")+COUNTIF(L5:L28,"Não") -> 0 | ... BD31: =COUNTIF(BD5:BD28,"Sim")+COUNTIF(BD5:BD28,"Não") -> 0
B32: Planejadas | E32: =COUNTA($B$5:$B$28) -> 8 | F32: =COUNTA($B$5:$B$28) -> 8 | G32: =COUNTA($B$5:$B$28) -> 8 | H32: =COUNTA($B$5:$B$28) -> 8 | I32: =COUNTA($B$5:$B$28) -> 8 | J32: =COUNTA($B$5:$B$28) -> 8 | K32: =COUNTA($B$5:$B$28) -> 8 | L32: =COUNTA($B$5:$B$28) -> 8 | ... BD32: =COUNTA($B$5:$B$28) -> 8
B33: % da semana | E33: =IF(E31=0,"",E30/E32) | F33: =IF(F31=0,"",F30/F32) | G33: =IF(G31=0,"",G30/G32) | H33: =IF(H31=0,"",H30/H32) | I33: =IF(I31=0,"",I30/I32) | J33: =IF(J31=0,"",J30/J32) | K33: =IF(K31=0,"",K30/K32) | L33: =IF(L31=0,"",L30/L32) | ... BD33: =IF(BD31=0,"",BD30/BD32)
B34: Minutos feitos | E34: =SUMIF(E5:E28,"Sim",$C$5:$C$28) -> 0 | F34: =SUMIF(F5:F28,"Sim",$C$5:$C$28) -> 0 | G34: =SUMIF(G5:G28,"Sim",$C$5:$C$28) -> 0 | H34: =SUMIF(H5:H28,"Sim",$C$5:$C$28) -> 0 | I34: =SUMIF(I5:I28,"Sim",$C$5:$C$28) -> 0 | J34: =SUMIF(J5:J28,"Sim",$C$5:$C$28) -> 0 | K34: =SUMIF(K5:K28,"Sim",$C$5:$C$28) -> 0 | L34: =SUMIF(L5:L28,"Sim",$C$5:$C$28) -> 0 | ... BD34: =SUMIF(BD5:BD28,"Sim",$C$5:$C$28) -> 0
B35: Sim = feita; Não = pulada; vazio = semana ainda não registrada. Só as semanas registradas entram no Painel.
B36: Quem lança o caixa: a recepção lança o fechamento do dia na planilha 09 todo dia, no fechamento (planilha 04 · Checklist do dia). Na sexta a sócia só CONFERE os cinco fechamentos da semana contra o extrato — por isso a rotina de sexta diz "conferir", e não "lançar".
