Workbook

Sheet Como usar
A1: Simulador convênio × particular
A2: Kit de Gestão para Médicos · Seu Sócio Gestor · versão 1.0 (setembro de 2026)
A4: O que esta planilha faz | B4: Responde "vale a pena este convênio?" para um procedimento: pega o valor de tabela de cada pagador, tira a glosa esperada, o custo do dinheiro pelo prazo de pagamento e os impostos, compara com o custo cheio do atendimento (custo-hora da 05 + material) e mostra o líquido por hora contra a hora mínima. Depois faz a leitura oposta: com horários vazios, o que cada pagador ainda contribui.
A5: Passo 1 | B5: Em Config, copie o custo-hora, a alíquota e a margem mínima da planilha 05; digite o custo do dinheiro (% ao mês); cadastre os pagadores com prazo de pagamento e glosa esperada (Painel da 13) e os procedimentos com tempo e material (iguais à 06).
A6: Passo 2 | B6: Em Simulador, escolha o procedimento e copie o valor de tabela de cada pagador da planilha 08 · Tabela de preços (o particular é o preço praticado). A 08 é a fonte única da tabela no kit: mudou um preço, atualize 08 → 06 → 07 → 01, nessa ordem. Leia o quadro 2 (agenda cheia): margem, líquido por hora e o veredito de cada pagador.
A7: Passo 3 | B7: Leia o quadro 3 (agenda vazia): a contribuição por atendimento e quantos atendimentos do convênio equivalem a um particular. Compare com as horas vazias do mês (01). No quadro 4, digite os atendimentos do mês por pagador e veja o resultado do mix.
A8: Rotina | B8: Antes de renovar, aceitar ou descredenciar um convênio, e uma vez por semestre para os que já estão. Leva 15 minutos por procedimento. No exemplo: consulta, com as tabelas da 08 e as consultas realizadas em agosto.
A9: Com a IA | B9: Copie os quadros 2 e 3 e use o prompt "Preço 03 · Vale a pena este convênio?" da biblioteca do kit para preparar os argumentos da negociação de tabela (sem prometer descredenciamento: é decisão da clínica, com contrato).
A10: Legenda | B10: Células amarelas: você preenche. Brancas: calculadas. Não é preciso mexer em nada fora do amarelo.
A11: Proteção | B11: Fórmulas protegidas sem senha. Para editar: Revisar > Desproteger planilha (Excel) ou Dados > Proteger intervalos (Google Sheets).
A12: Requisitos | B12: Excel 2016 ou mais novo, Microsoft 365 ou Google Sheets (só funções do Excel 2007+; nada de MÍNIMOSES, MÁXIMOSES ou UNIRTEXTO). No celular abre nos aplicativos; para preencher, use o computador.
A13: Dados de pacientes | B13: Guarde só o que a gestão precisa (nome, contato, valor, data). Nada de diagnóstico, prontuário ou exame nestas planilhas: o kit é gestão, não é prontuário. Veja o guia LGPD do kit antes de colar qualquer tabela em uma IA.
A14: Google Sheets | B14: Faça upload no Google Drive e abra com o Google Sheets. Fórmulas, listas, cores, semáforos e gráficos funcionam: as regras de cor que dependem do mês escolhido em Config usam INDIRECT, que é a forma que o Sheets aceita para regra condicional apontar para outra aba.
A15: Exemplos | B15: Clínica Vida Plena é uma clínica fictícia. Pacientes, convênios, nomes, contatos e valores são inventados; não há nenhum dado clínico. Apague o exemplo antes de começar.
... A17: Suporte | B17: suporte@seusociogestor.com.br · resposta em até 5 dias úteis · reembolso em até 7 dias pelo mesmo canal.

Sheet Simulador
A1: =Config!$B$3&" · Simulador convênio × particular · "&TEXT(DAY(Config!$B$4),"00")&"/"&TEXT(MONTH(Config!$B$4),"00")&"/"&YEAR(Config!$B$4) -> Clínica Vida Plena (exemplo fictício) · Simulador convênio × particular · 14/09/2026
A2: Escolha o procedimento e digite o valor de tabela de cada pagador (amarelo). O resto é calculado: glosa, custo do dinheiro pelo prazo, impostos, custo cheio, margem e as duas leituras (agenda cheia × agenda vazia).
A4: Custo cheio do atendimento | C4: Hora mínima (05) | E4: Particular · líquido por hora | G4: Melhor convênio (líquido/hora) | J4: Pior convênio (líquido/hora)
A5: =$B$13 -> 130.66667 | C5: =$B$14 -> 338.98305 | E5: =IF(L19="","",L19) -> 534 | G5: =IFERROR(INDEX($A$20:$A$24,MATCH(MAX($L$20:$L$24),$L$20:$L$24,0))&": R$ "&FIXED(MAX($L$20:$L$24),0),"") -> Saúde Total: R$ 161 | J5: =IFERROR(INDEX($A$20:$A$24,MATCH(MIN($L$20:$L$24),$L$20:$L$24,0))&": R$ "&FIXED(MIN($L$20:$L$24),0),"") -> Vida Care: R$ 110
A7: 1. O procedimento
A8: Procedimento | B8: Consulta | C8: Os valores de tabela do quadro 2 saem da planilha 08 · Tabela de preços (a fonte única da tabela no kit): copie de lá, não digite um preço diferente aqui.
A9: Minutos | B9: =IFERROR(INDEX(Config!$B$19:$B$30,MATCH(B8,Config!$A$19:$A$30,0)),"") -> 30
A10: Gera retorno? | B10: =IFERROR(INDEX(Config!$C$19:$C$30,MATCH(B8,Config!$A$19:$A$30,0)),"") -> Sim
A11: Material (R$) | B11: =IFERROR(INDEX(Config!$D$19:$D$30,MATCH(B8,Config!$A$19:$A$30,0)),0) -> 4
A12: Tempo com retorno embutido (min) | B12: =IF(B9="","",B9+IF(B10="Sim",Config!$E$19*Config!$F$19,0)) -> 38
A13: Custo cheio do atendimento (R$) | B13: =IF(B12="","",B12/60*Config!$B$5+B11) -> 130.66667 | C13: Tempo (com retorno) ÷ 60 × custo-hora + material. É o custo com a estrutura inteira rateada: a leitura de agenda cheia.
A14: Hora mínima a cobrar (R$) | B14: =IFERROR(Config!$B$5/(1-Config!$B$6-Config!$B$7),"") -> 338.98305
A15: Preço mínimo deste procedimento (R$) | B15: =IF(B13="","",IFERROR(B13/(1-Config!$B$6-Config!$B$7),"")) -> 221.46893 | C15: Custo cheio ÷ (1 − impostos − margem mínima). O mesmo número da planilha 06.
A17: 2. O que cada pagador paga por este procedimento
A18: Pagador | B18: Valor de tabela (R$) | C18: Prazo (dias) | D18: Glosa esperada | E18: Valor após glosa | F18: Custo do dinheiro (R$) | G18: Impostos (R$) | H18: Valor líquido (R$) | I18: Custo cheio (R$) | J18: Margem (R$) | K18: Margem (%) | L18: Líquido por hora (R$) | M18: Contra a hora mínima | N18: Leitura com agenda cheia
A19: =IF(Config!$A$10="","",Config!$A$10) -> Particular | B19: 380 | C19: =IF(Config!$A$10="","",Config!$B$10) -> 0 | D19: =IF(Config!$A$10="","",Config!$C$10) -> 0 | E19: =IF(OR(Config!$A$10="",B19=""),"",B19*(1-D19)) -> 380 | F19: =IF(E19="","",E19*Config!$B$8*C19/30) -> 0 | G19: =IF(E19="","",E19*Config!$B$6) -> 41.8 | H19: =IF(E19="","",E19-F19-G19) -> 338.2 | I19: =IF(E19="","",$B$13) -> 130.66667 | J19: =IF(E19="","",H19-I19) -> 207.53333 | K19: =IF(OR(E19="",B19=0),"",J19/B19) -> 0.54614035 | L19: =IF(OR(E19="",$B$12=0),"",H19/($B$12/60)) -> 534 | M19: =IF(L19="","",L19/$B$14-1) -> 0.5753 | N19: =IF(E19="","",IF(J19<0,"Não cobre o custo cheio",IF(K19<Config!$B$7,"Cobre o custo, não a margem mínima","Cobre custo e margem"))) -> Cobre custo e margem
A20: =IF(Config!$A$11="","",Config!$A$11) -> Saúde Total | B20: 120 | C20: =IF(Config!$A$11="","",Config!$B$11) -> 30 | D20: =IF(Config!$A$11="","",Config!$C$11) -> 0.03 | E20: =IF(OR(Config!$A$11="",B20=""),"",B20*(1-D20)) -> 116.4 | F20: =IF(E20="","",E20*Config!$B$8*C20/30) -> 1.746 | G20: =IF(E20="","",E20*Config!$B$6) -> 12.804 | H20: =IF(E20="","",E20-F20-G20) -> 101.85 | I20: =IF(E20="","",$B$13) -> 130.66667 | J20: =IF(E20="","",H20-I20) -> -28.816667 | K20: =IF(OR(E20="",B20=0),"",J20/B20) -> -0.24013889 | L20: =IF(OR(E20="",$B$12=0),"",H20/($B$12/60)) -> 160.81579 | M20: =IF(L20="","",L20/$B$14-1) -> -0.52559342 | N20: =IF(E20="","",IF(J20<0,"Não cobre o custo cheio",IF(K20<Config!$B$7,"Cobre o custo, não a margem mínima","Cobre custo e margem"))) -> Não cobre o custo cheio
A21: =IF(Config!$A$12="","",Config!$A$12) -> MediPlan | B21: 100 | C21: =IF(Config!$A$12="","",Config!$B$12) -> 45 | D21: =IF(Config!$A$12="","",Config!$C$12) -> 0.06 | E21: =IF(OR(Config!$A$12="",B21=""),"",B21*(1-D21)) -> 94 | F21: =IF(E21="","",E21*Config!$B$8*C21/30) -> 2.115 | G21: =IF(E21="","",E21*Config!$B$6) -> 10.34 | H21: =IF(E21="","",E21-F21-G21) -> 81.545 | I21: =IF(E21="","",$B$13) -> 130.66667 | J21: =IF(E21="","",H21-I21) -> -49.121667 | K21: =IF(OR(E21="",B21=0),"",J21/B21) -> -0.49121667 | L21: =IF(OR(E21="",$B$12=0),"",H21/($B$12/60)) -> 128.75526 | M21: =IF(L21="","",L21/$B$14-1) -> -0.62017197 | N21: =IF(E21="","",IF(J21<0,"Não cobre o custo cheio",IF(K21<Config!$B$7,"Cobre o custo, não a margem mínima","Cobre custo e margem"))) -> Não cobre o custo cheio
A22: =IF(Config!$A$13="","",Config!$A$13) -> Vida Care | B22: 90 | C22: =IF(Config!$A$13="","",Config!$B$13) -> 60 | D22: =IF(Config!$A$13="","",Config!$C$13) -> 0.1 | E22: =IF(OR(Config!$A$13="",B22=""),"",B22*(1-D22)) -> 81 | F22: =IF(E22="","",E22*Config!$B$8*C22/30) -> 2.43 | G22: =IF(E22="","",E22*Config!$B$6) -> 8.91 | H22: =IF(E22="","",E22-F22-G22) -> 69.66 | I22: =IF(E22="","",$B$13) -> 130.66667 | J22: =IF(E22="","",H22-I22) -> -61.006667 | K22: =IF(OR(E22="",B22=0),"",J22/B22) -> -0.67785185 | L22: =IF(OR(E22="",$B$12=0),"",H22/($B$12/60)) -> 109.98947 | M22: =IF(L22="","",L22/$B$14-1) -> -0.67553105 | N22: =IF(E22="","",IF(J22<0,"Não cobre o custo cheio",IF(K22<Config!$B$7,"Cobre o custo, não a margem mínima","Cobre custo e margem"))) -> Não cobre o custo cheio
A23: =IF(Config!$A$14="","",Config!$A$14) | C23: =IF(Config!$A$14="","",Config!$B$14) | D23: =IF(Config!$A$14="","",Config!$C$14) | E23: =IF(OR(Config!$A$14="",B23=""),"",B23*(1-D23)) | F23: =IF(E23="","",E23*Config!$B$8*C23/30) | G23: =IF(E23="","",E23*Config!$B$6) | H23: =IF(E23="","",E23-F23-G23) | I23: =IF(E23="","",$B$13) | J23: =IF(E23="","",H23-I23) | K23: =IF(OR(E23="",B23=0),"",J23/B23) | L23: =IF(OR(E23="",$B$12=0),"",H23/($B$12/60)) | M23: =IF(L23="","",L23/$B$14-1) | N23: =IF(E23="","",IF(J23<0,"Não cobre o custo cheio",IF(K23<Config!$B$7,"Cobre o custo, não a margem mínima","Cobre custo e margem")))
A24: =IF(Config!$A$15="","",Config!$A$15) | C24: =IF(Config!$A$15="","",Config!$B$15) | D24: =IF(Config!$A$15="","",Config!$C$15) | E24: =IF(OR(Config!$A$15="",B24=""),"",B24*(1-D24)) | F24: =IF(E24="","",E24*Config!$B$8*C24/30) | G24: =IF(E24="","",E24*Config!$B$6) | H24: =IF(E24="","",E24-F24-G24) | I24: =IF(E24="","",$B$13) | J24: =IF(E24="","",H24-I24) | K24: =IF(OR(E24="",B24=0),"",J24/B24) | L24: =IF(OR(E24="",$B$12=0),"",H24/($B$12/60)) | M24: =IF(L24="","",L24/$B$14-1) | N24: =IF(E24="","",IF(J24<0,"Não cobre o custo cheio",IF(K24<Config!$B$7,"Cobre o custo, não a margem mínima","Cobre custo e margem")))
A25: Valor líquido = tabela − glosa esperada − custo do dinheiro (juros × prazo ÷ 30) − impostos. Margem = líquido − custo cheio. Líquido por hora compara pagadores com a hora mínima da 05: é o número para negociar tabela ou decidir descredenciar.
A28: 3. A outra leitura: e se o horário ficaria vazio?
A29: Com agenda vazia o custo fixo já está pago: o que importa é a contribuição (líquido − material). Com agenda cheia, cada horário de convênio toma o lugar de um particular, e vale a leitura do quadro 2.
A30: Pagador | B30: Valor líquido (R$) | C30: Material (R$) | D30: Contribuição por atendimento (R$) | E30: Contribuição por hora (R$) | F30: Atendimentos deste pagador = 1 particular | G30: Leitura com agenda vazia
A31: =A19 -> Particular | B31: =IF(H19="","",H19) -> 338.2 | C31: =IF(H19="","",$B$11) -> 4 | D31: =IF(B31="","",B31-C31) -> 334.2 | E31: =IF(OR(D31="",$B$12=0),"",D31/($B$12/60)) -> 527.68421 | F31: =IF(OR(D31="",D31<=0,$D$31=""),"",$D$31/D31) -> 1 | G31: =IF(D31="","",IF(D31<=0,"Nem com agenda vazia: perde dinheiro a cada atendimento",IF(C19>45,"Contribui, mas o prazo pesa no caixa: só com reserva (12)","Contribui: melhor que o horário vazio"))) -> Contribui: melhor que o horário vazio
A32: =A20 -> Saúde Total | B32: =IF(H20="","",H20) -> 101.85 | C32: =IF(H20="","",$B$11) -> 4 | D32: =IF(B32="","",B32-C32) -> 97.85 | E32: =IF(OR(D32="",$B$12=0),"",D32/($B$12/60)) -> 154.5 | F32: =IF(OR(D32="",D32<=0,$D$31=""),"",$D$31/D32) -> 3.4154318 | G32: =IF(D32="","",IF(D32<=0,"Nem com agenda vazia: perde dinheiro a cada atendimento",IF(C20>45,"Contribui, mas o prazo pesa no caixa: só com reserva (12)","Contribui: melhor que o horário vazio"))) -> Contribui: melhor que o horário vazio
A33: =A21 -> MediPlan | B33: =IF(H21="","",H21) -> 81.545 | C33: =IF(H21="","",$B$11) -> 4 | D33: =IF(B33="","",B33-C33) -> 77.545 | E33: =IF(OR(D33="",$B$12=0),"",D33/($B$12/60)) -> 122.43947 | F33: =IF(OR(D33="",D33<=0,$D$31=""),"",$D$31/D33) -> 4.3097556 | G33: =IF(D33="","",IF(D33<=0,"Nem com agenda vazia: perde dinheiro a cada atendimento",IF(C21>45,"Contribui, mas o prazo pesa no caixa: só com reserva (12)","Contribui: melhor que o horário vazio"))) -> Contribui: melhor que o horário vazio
A34: =A22 -> Vida Care | B34: =IF(H22="","",H22) -> 69.66 | C34: =IF(H22="","",$B$11) -> 4 | D34: =IF(B34="","",B34-C34) -> 65.66 | E34: =IF(OR(D34="",$B$12=0),"",D34/($B$12/60)) -> 103.67368 | F34: =IF(OR(D34="",D34<=0,$D$31=""),"",$D$31/D34) -> 5.0898568 | G34: =IF(D34="","",IF(D34<=0,"Nem com agenda vazia: perde dinheiro a cada atendimento",IF(C22>45,"Contribui, mas o prazo pesa no caixa: só com reserva (12)","Contribui: melhor que o horário vazio"))) -> Contribui, mas o prazo pesa no caixa: só com reserva (12)
A35: =A23 | B35: =IF(H23="","",H23) | C35: =IF(H23="","",$B$11) | D35: =IF(B35="","",B35-C35) | E35: =IF(OR(D35="",$B$12=0),"",D35/($B$12/60)) | F35: =IF(OR(D35="",D35<=0,$D$31=""),"",$D$31/D35) | G35: =IF(D35="","",IF(D35<=0,"Nem com agenda vazia: perde dinheiro a cada atendimento",IF(C23>45,"Contribui, mas o prazo pesa no caixa: só com reserva (12)","Contribui: melhor que o horário vazio")))
A36: =A24 | B36: =IF(H24="","",H24) | C36: =IF(H24="","",$B$11) | D36: =IF(B36="","",B36-C36) | E36: =IF(OR(D36="",$B$12=0),"",D36/($B$12/60)) | F36: =IF(OR(D36="",D36<=0,$D$31=""),"",$D$31/D36) | G36: =IF(D36="","",IF(D36<=0,"Nem com agenda vazia: perde dinheiro a cada atendimento",IF(C24>45,"Contribui, mas o prazo pesa no caixa: só com reserva (12)","Contribui: melhor que o horário vazio")))
A37: "Atendimentos = 1 particular": quantos atendimentos deste pagador rendem a contribuição de um particular. Compare com as horas vazias do mês (Painel da 01) antes de aceitar ou descredenciar um convênio.
A40: 4. O mês inteiro: mix de pagadores para este procedimento
A41: Amarelo: quantos atendimentos de cada pagador no mês (no exemplo, as consultas realizadas em agosto de 2026, Painel da 01 por pagador). A planilha soma o líquido, o custo cheio e o resultado.
A42: Pagador | B42: Atendimentos no mês | C42: Horas | D42: Líquido no mês (R$) | E42: Custo cheio no mês (R$) | F42: Resultado (R$) | G42: % dos atendimentos | H42: % do líquido
A43: =A19 -> Particular | B43: 62 | C43: =IF(OR(A43="",B43=""),"",B43*$B$12/60) -> 39.266667 | D43: =IF(OR(A43="",B43="",H19=""),"",B43*H19) -> 20968.4 | E43: =IF(D43="","",B43*$B$13) -> 8101.3333 | F43: =IF(D43="","",D43-E43) -> 12867.067 | G43: =IF(OR(D43="",$B$49=0),"",B43/$B$49) -> 0.47692308 | H43: =IF(OR(D43="",$D$49=0),"",D43/$D$49) -> 0.78046406
A44: =A20 -> Saúde Total | B44: 25 | C44: =IF(OR(A44="",B44=""),"",B44*$B$12/60) -> 15.833333 | D44: =IF(OR(A44="",B44="",H20=""),"",B44*H20) -> 2546.25 | E44: =IF(D44="","",B44*$B$13) -> 3266.6667 | F44: =IF(D44="","",D44-E44) -> -720.41667 | G44: =IF(OR(D44="",$B$49=0),"",B44/$B$49) -> 0.19230769 | H44: =IF(OR(D44="",$D$49=0),"",D44/$D$49) -> 0.094773879
A45: =A21 -> MediPlan | B45: 30 | C45: =IF(OR(A45="",B45=""),"",B45*$B$12/60) -> 19 | D45: =IF(OR(A45="",B45="",H21=""),"",B45*H21) -> 2446.35 | E45: =IF(D45="","",B45*$B$13) -> 3920 | F45: =IF(D45="","",D45-E45) -> -1473.65 | G45: =IF(OR(D45="",$B$49=0),"",B45/$B$49) -> 0.23076923 | H45: =IF(OR(D45="",$D$49=0),"",D45/$D$49) -> 0.091055505
A46: =A22 -> Vida Care | B46: 13 | C46: =IF(OR(A46="",B46=""),"",B46*$B$12/60) -> 8.2333333 | D46: =IF(OR(A46="",B46="",H22=""),"",B46*H22) -> 905.58 | E46: =IF(D46="","",B46*$B$13) -> 1698.6667 | F46: =IF(D46="","",D46-E46) -> -793.08667 | G46: =IF(OR(D46="",$B$49=0),"",B46/$B$49) -> 0.1 | H46: =IF(OR(D46="",$D$49=0),"",D46/$D$49) -> 0.03370656
A47: =A23 | C47: =IF(OR(A47="",B47=""),"",B47*$B$12/60) | D47: =IF(OR(A47="",B47="",H23=""),"",B47*H23) | E47: =IF(D47="","",B47*$B$13) | F47: =IF(D47="","",D47-E47) | G47: =IF(OR(D47="",$B$49=0),"",B47/$B$49) | H47: =IF(OR(D47="",$D$49=0),"",D47/$D$49)
...

Sheet Config
A1: Configurações
A2: Células amarelas: você preenche. Custo-hora da planilha 05; pagadores com prazo e glosa esperada; procedimentos com tempo e material (iguais à 06).
A3: Nome da clínica | B3: Clínica Vida Plena (exemplo fictício)
A4: Data de referência | B4: 46279
A5: Custo da hora de atendimento (R$) | B5: 200 | C5: Copie do Painel da planilha 05. No exemplo, R$ 200,00.
A6: Impostos sobre o que entra (%) | B6: 0.11 | C6: A mesma alíquota efetiva das planilhas 05 e 06 (exemplo: 11 %). Só imposto: a taxa da maquininha não entra aqui (o convênio não passa na maquininha; o cartão é conciliado na 16).
A7: Margem mínima sobre o preço (%) | B7: 0.3 | C7: A mesma margem mínima da 05 e da 06.
A8: Custo do dinheiro (% ao mês) | B8: 0.015 | C8: O que custa esperar 30, 45 ou 60 dias pelo dinheiro: juros do cheque especial ou da antecipação, ou o rendimento que o dinheiro parado deixa de dar. 1,5 % ao mês é um exemplo; use o seu.
A9: Pagador | B9: Prazo de pagamento (dias) | C9: Glosa esperada (%) | D9: Observação
A10: Particular | B10: 0 | C10: 0 | D10: À vista no dia (Pix, dinheiro, cartão)
A11: Saúde Total | B11: 30 | C11: 0.03 | D11: Prazo contratual a partir do envio do lote; glosa = histórico da planilha 13
A12: MediPlan | B12: 45 | C12: 0.06 | D12: Prazo contratual a partir do envio do lote; glosa = histórico da planilha 13
A13: Vida Care | B13: 60 | C13: 0.1 | D13: Prazo contratual a partir do envio do lote; glosa = histórico da planilha 13
A16: Preencha de cima para baixo, sem pular linha. Glosa esperada: quanto o convênio costuma não pagar do que foi enviado (Painel da planilha 13, por convênio). Prazo: dias entre o envio do lote e o pagamento.
A18: Procedimento | B18: Minutos | C18: Gera retorno? | D18: Material (R$) | E18: Retornos por consulta | F18: Minutos do retorno
A19: Consulta | B19: 30 | C19: Sim | D19: 4 | E19: 0.4 | F19: 20
A20: Retorno | B20: 20 | C20: Não | D20: 2 | E20: Só na primeira linha: valem para todos os procedimentos que geram retorno (iguais à planilha 06).
A21: ECG | B21: 20 | C21: Não | D21: 8
A22: MAPA | B22: 20 | C22: Não | D22: 15
A23: Holter | B23: 20 | C23: Não | D23: 18
A24: Teste ergométrico | B24: 40 | C24: Não | D24: 25
A25: Avaliação endócrina | B25: 40 | C25: Sim | D25: 4
