Workbook

Sheet Como usar
A1: Reserva de três meses e metas de caixa
A2: Kit de Gestão para Médicos · Seu Sócio Gestor · versão 1.0 (setembro de 2026)
A4: O que esta planilha faz | B4: Calcula a reserva que a clínica precisa (meses de custo fixo), mostra quanto já tem, quantos meses cobre hoje, quando chega à meta com o aporte planejado (mês a mês, com gráfico) e acompanha três metas de caixa do trimestre com barra de progresso.
A5: Passo 1 | B5: Em Config, digite a meta em meses (3 é um bom começo) e, para os últimos 3 meses, o custo fixo + pró-labore de cada um, copiado de "Para onde foi o dinheiro" no Painel da planilha 09 (as oito linhas de custo fixo mais a linha "Pró-labore dos sócios"). Depois o saldo em caixa, os compromissos ainda não pagos, o que já está guardado numa conta separada e o aporte mensal que cabe.
A6: Passo 2 | B6: Ainda em Config, escreva as três metas de caixa do trimestre: nome, valor alvo, valor atual e prazo. Metas que se medem em reais e crescem até o alvo.
A7: Passo 3 | B7: Em Painel: meta, reserva, falta, meses cobertos, semáforo e o mês em que a meta é atingida. A projeção mostra 24 meses; a linha verde é o mês da virada.
A8: Rotina | B8: É uma planilha MENSAL, não entra nos 30 minutos semanais da planilha 03: no fechamento de cada mês, 10 minutos para transferir o aporte para a conta da reserva, atualizar o saldo, o custo fixo + pró-labore e o valor atual das três metas em Config.
A9: Com a IA | B9: Copie o Painel e use o prompt "Caixa 08 · Plano para a reserva de três meses" da biblioteca do kit para decidir aporte e metas do próximo trimestre com o sócio.
A10: Números em texto | B10: As frases do Painel montam os valores com TEXTO e FIXED, então os separadores seguem o idioma do Excel: milhar com ponto e decimal com vírgula em português. Os números vêm sempre das células; nenhum valor de exemplo está escrito dentro do texto.
A11: Legenda | B11: Células amarelas: você preenche. Brancas: calculadas. Não é preciso mexer em nada fora do amarelo.
A12: Proteção | B12: Fórmulas protegidas sem senha. Para editar: Revisar > Desproteger planilha (Excel) ou Dados > Proteger intervalos (Google Sheets).
A13: Requisitos | B13: Excel 2016 ou mais novo, Microsoft 365 ou Google Sheets (só funções do Excel 2007+; nada de MÍNIMOSES, MÁXIMOSES ou UNIRTEXTO). No celular abre nos aplicativos; para preencher, use o computador.
A14: Dados de pacientes | B14: Guarde só o que a gestão precisa (nome, contato, valor, data). Nada de diagnóstico, prontuário ou exame nestas planilhas: o kit é gestão, não é prontuário. Veja o guia LGPD do kit antes de colar qualquer tabela em uma IA.
A15: Google Sheets | B15: Faça upload no Google Drive e abra com o Google Sheets. Fórmulas, listas, cores, semáforos e gráficos funcionam: as regras de cor que dependem do mês escolhido em Config usam INDIRECT, que é a forma que o Sheets aceita para regra condicional apontar para outra aba.
... A18: Suporte | B18: suporte@seusociogestor.com.br · resposta em até 5 dias úteis · reembolso em até 7 dias pelo mesmo canal.

Sheet Painel
A1: =Config!B4&" · Reserva e metas de caixa · "&TEXT(DAY(Config!B5),"00")&"/"&TEXT(MONTH(Config!B5),"00")&"/"&YEAR(Config!B5) -> Clínica Vida Plena (exemplo fictício) · Reserva e metas de caixa · 14/09/2026
A2: Nada para digitar aqui. Meta, custo fixo, saldo e aporte vêm de Config.
A4: Meta de reserva | C4: Reserva hoje | E4: Falta guardar | G4: Meses de custo fixo + pró-labore cobertos | I4: Meta prevista para
A5: =Config!$B$8*Config!$B$16 -> 91909 | C5: =Config!$B$22 -> 14000 | E5: =MAX(0,A5-C5) -> 77909 | G5: =IF(Config!$B$16=0,0,C5/Config!$B$16) -> 0.45697375 | I5: =IF(C5>=A5,"Já atingida",IFERROR(INDEX(A10:A39,MATCH("Meta atingida",F10:F39,0)),"Depois de 24 meses")) -> Novembro/2028
A7: Semáforo | B7: =IF(G5<1,"Vermelho: menos de 1 mês de custo fixo + pró-labore guardado",IF(G5<Config!$B$8,"Amarelo: abaixo da meta",IF(G5<Config!$B$8+1,"Verde: meta atingida","Verde: acima da meta"))) -> Vermelho: menos de 1 mês de custo fixo + pró-labore guardado | G7: ="Contando o caixa livre (R$ "&FIXED(Config!$B$21,0)&"): "&FIXED(IF(Config!$B$16=0,0,(C5+Config!$B$21)/Config!$B$16),1)&" meses" -> Contando o caixa livre (R$ 12.003): 0,8 meses
A8: Projeção da reserva, mês a mês
A9: Mês | B9: Saldo no início | C9: Aporte | D9: Saldo no fim | E9: % da meta | F9: Atingiu? | G9: Barra
A10: =INDEX(Config!$H$5:$H$16,MOD(MATCH(Config!$B$6,Config!$H$5:$H$16,0)+0-1,12)+1)&"/"&(Config!$B$7+INT((MATCH(Config!$B$6,Config!$H$5:$H$16,0)+0-1)/12)) -> Outubro/2026 | B10: =Config!$B$22 -> 14000 | C10: =Config!$B$9 -> 3000 | D10: =B10+C10 -> 17000 | E10: =IF($A$5=0,"",D10/$A$5) -> 0.18496556 | F10: =IF(D10>=$A$5,IF(B10<$A$5,"Meta atingida","Acima da meta"),"") | G10: =IF(E10="","",REPT("█",ROUND(MIN(1,E10)*30,0))) -> ██████ | J10: =$A$5 -> 91909
A11: =INDEX(Config!$H$5:$H$16,MOD(MATCH(Config!$B$6,Config!$H$5:$H$16,0)+1-1,12)+1)&"/"&(Config!$B$7+INT((MATCH(Config!$B$6,Config!$H$5:$H$16,0)+1-1)/12)) -> Novembro/2026 | B11: =D10 -> 17000 | C11: =Config!$B$9 -> 3000 | D11: =B11+C11 -> 20000 | E11: =IF($A$5=0,"",D11/$A$5) -> 0.21760655 | F11: =IF(D11>=$A$5,IF(B11<$A$5,"Meta atingida","Acima da meta"),"") | G11: =IF(E11="","",REPT("█",ROUND(MIN(1,E11)*30,0))) -> ███████ | J11: =$A$5 -> 91909
A12: =INDEX(Config!$H$5:$H$16,MOD(MATCH(Config!$B$6,Config!$H$5:$H$16,0)+2-1,12)+1)&"/"&(Config!$B$7+INT((MATCH(Config!$B$6,Config!$H$5:$H$16,0)+2-1)/12)) -> Dezembro/2026 | B12: =D11 -> 20000 | C12: =Config!$B$9 -> 3000 | D12: =B12+C12 -> 23000 | E12: =IF($A$5=0,"",D12/$A$5) -> 0.25024753 | F12: =IF(D12>=$A$5,IF(B12<$A$5,"Meta atingida","Acima da meta"),"") | G12: =IF(E12="","",REPT("█",ROUND(MIN(1,E12)*30,0))) -> ████████ | J12: =$A$5 -> 91909
A13: =INDEX(Config!$H$5:$H$16,MOD(MATCH(Config!$B$6,Config!$H$5:$H$16,0)+3-1,12)+1)&"/"&(Config!$B$7+INT((MATCH(Config!$B$6,Config!$H$5:$H$16,0)+3-1)/12)) -> Janeiro/2027 | B13: =D12 -> 23000 | C13: =Config!$B$9 -> 3000 | D13: =B13+C13 -> 26000 | E13: =IF($A$5=0,"",D13/$A$5) -> 0.28288851 | F13: =IF(D13>=$A$5,IF(B13<$A$5,"Meta atingida","Acima da meta"),"") | G13: =IF(E13="","",REPT("█",ROUND(MIN(1,E13)*30,0))) -> ████████ | J13: =$A$5 -> 91909
A14: =INDEX(Config!$H$5:$H$16,MOD(MATCH(Config!$B$6,Config!$H$5:$H$16,0)+4-1,12)+1)&"/"&(Config!$B$7+INT((MATCH(Config!$B$6,Config!$H$5:$H$16,0)+4-1)/12)) -> Fevereiro/2027 | B14: =D13 -> 26000 | C14: =Config!$B$9 -> 3000 | D14: =B14+C14 -> 29000 | E14: =IF($A$5=0,"",D14/$A$5) -> 0.31552949 | F14: =IF(D14>=$A$5,IF(B14<$A$5,"Meta atingida","Acima da meta"),"") | G14: =IF(E14="","",REPT("█",ROUND(MIN(1,E14)*30,0))) -> █████████ | J14: =$A$5 -> 91909
A15: =INDEX(Config!$H$5:$H$16,MOD(MATCH(Config!$B$6,Config!$H$5:$H$16,0)+5-1,12)+1)&"/"&(Config!$B$7+INT((MATCH(Config!$B$6,Config!$H$5:$H$16,0)+5-1)/12)) -> Março/2027 | B15: =D14 -> 29000 | C15: =Config!$B$9 -> 3000 | D15: =B15+C15 -> 32000 | E15: =IF($A$5=0,"",D15/$A$5) -> 0.34817047 | F15: =IF(D15>=$A$5,IF(B15<$A$5,"Meta atingida","Acima da meta"),"") | G15: =IF(E15="","",REPT("█",ROUND(MIN(1,E15)*30,0))) -> ██████████ | J15: =$A$5 -> 91909
A16: =INDEX(Config!$H$5:$H$16,MOD(MATCH(Config!$B$6,Config!$H$5:$H$16,0)+6-1,12)+1)&"/"&(Config!$B$7+INT((MATCH(Config!$B$6,Config!$H$5:$H$16,0)+6-1)/12)) -> Abril/2027 | B16: =D15 -> 32000 | C16: =Config!$B$9 -> 3000 | D16: =B16+C16 -> 35000 | E16: =IF($A$5=0,"",D16/$A$5) -> 0.38081145 | F16: =IF(D16>=$A$5,IF(B16<$A$5,"Meta atingida","Acima da meta"),"") | G16: =IF(E16="","",REPT("█",ROUND(MIN(1,E16)*30,0))) -> ███████████ | J16: =$A$5 -> 91909
A17: =INDEX(Config!$H$5:$H$16,MOD(MATCH(Config!$B$6,Config!$H$5:$H$16,0)+7-1,12)+1)&"/"&(Config!$B$7+INT((MATCH(Config!$B$6,Config!$H$5:$H$16,0)+7-1)/12)) -> Maio/2027 | B17: =D16 -> 35000 | C17: =Config!$B$9 -> 3000 | D17: =B17+C17 -> 38000 | E17: =IF($A$5=0,"",D17/$A$5) -> 0.41345244 | F17: =IF(D17>=$A$5,IF(B17<$A$5,"Meta atingida","Acima da meta"),"") | G17: =IF(E17="","",REPT("█",ROUND(MIN(1,E17)*30,0))) -> ████████████ | J17: =$A$5 -> 91909
A18: =INDEX(Config!$H$5:$H$16,MOD(MATCH(Config!$B$6,Config!$H$5:$H$16,0)+8-1,12)+1)&"/"&(Config!$B$7+INT((MATCH(Config!$B$6,Config!$H$5:$H$16,0)+8-1)/12)) -> Junho/2027 | B18: =D17 -> 38000 | C18: =Config!$B$9 -> 3000 | D18: =B18+C18 -> 41000 | E18: =IF($A$5=0,"",D18/$A$5) -> 0.44609342 | F18: =IF(D18>=$A$5,IF(B18<$A$5,"Meta atingida","Acima da meta"),"") | G18: =IF(E18="","",REPT("█",ROUND(MIN(1,E18)*30,0))) -> █████████████ | J18: =$A$5 -> 91909
A19: =INDEX(Config!$H$5:$H$16,MOD(MATCH(Config!$B$6,Config!$H$5:$H$16,0)+9-1,12)+1)&"/"&(Config!$B$7+INT((MATCH(Config!$B$6,Config!$H$5:$H$16,0)+9-1)/12)) -> Julho/2027 | B19: =D18 -> 41000 | C19: =Config!$B$9 -> 3000 | D19: =B19+C19 -> 44000 | E19: =IF($A$5=0,"",D19/$A$5) -> 0.4787344 | F19: =IF(D19>=$A$5,IF(B19<$A$5,"Meta atingida","Acima da meta"),"") | G19: =IF(E19="","",REPT("█",ROUND(MIN(1,E19)*30,0))) -> ██████████████ | J19: =$A$5 -> 91909
A20: =INDEX(Config!$H$5:$H$16,MOD(MATCH(Config!$B$6,Config!$H$5:$H$16,0)+10-1,12)+1)&"/"&(Config!$B$7+INT((MATCH(Config!$B$6,Config!$H$5:$H$16,0)+10-1)/12)) -> Agosto/2027 | B20: =D19 -> 44000 | C20: =Config!$B$9 -> 3000 | D20: =B20+C20 -> 47000 | E20: =IF($A$5=0,"",D20/$A$5) -> 0.51137538 | F20: =IF(D20>=$A$5,IF(B20<$A$5,"Meta atingida","Acima da meta"),"") | G20: =IF(E20="","",REPT("█",ROUND(MIN(1,E20)*30,0))) -> ███████████████ | J20: =$A$5 -> 91909
A21: =INDEX(Config!$H$5:$H$16,MOD(MATCH(Config!$B$6,Config!$H$5:$H$16,0)+11-1,12)+1)&"/"&(Config!$B$7+INT((MATCH(Config!$B$6,Config!$H$5:$H$16,0)+11-1)/12)) -> Setembro/2027 | B21: =D20 -> 47000 | C21: =Config!$B$9 -> 3000 | D21: =B21+C21 -> 50000 | E21: =IF($A$5=0,"",D21/$A$5) -> 0.54401636 | F21: =IF(D21>=$A$5,IF(B21<$A$5,"Meta atingida","Acima da meta"),"") | G21: =IF(E21="","",REPT("█",ROUND(MIN(1,E21)*30,0))) -> ████████████████ | J21: =$A$5 -> 91909
A22: =INDEX(Config!$H$5:$H$16,MOD(MATCH(Config!$B$6,Config!$H$5:$H$16,0)+12-1,12)+1)&"/"&(Config!$B$7+INT((MATCH(Config!$B$6,Config!$H$5:$H$16,0)+12-1)/12)) -> Outubro/2027 | B22: =D21 -> 50000 | C22: =Config!$B$9 -> 3000 | D22: =B22+C22 -> 53000 | E22: =IF($A$5=0,"",D22/$A$5) -> 0.57665735 | F22: =IF(D22>=$A$5,IF(B22<$A$5,"Meta atingida","Acima da meta"),"") | G22: =IF(E22="","",REPT("█",ROUND(MIN(1,E22)*30,0))) -> █████████████████ | J22: =$A$5 -> 91909
A23: =INDEX(Config!$H$5:$H$16,MOD(MATCH(Config!$B$6,Config!$H$5:$H$16,0)+13-1,12)+1)&"/"&(Config!$B$7+INT((MATCH(Config!$B$6,Config!$H$5:$H$16,0)+13-1)/12)) -> Novembro/2027 | B23: =D22 -> 53000 | C23: =Config!$B$9 -> 3000 | D23: =B23+C23 -> 56000 | E23: =IF($A$5=0,"",D23/$A$5) -> 0.60929833 | F23: =IF(D23>=$A$5,IF(B23<$A$5,"Meta atingida","Acima da meta"),"") | G23: =IF(E23="","",REPT("█",ROUND(MIN(1,E23)*30,0))) -> ██████████████████ | J23: =$A$5 -> 91909
A24: =INDEX(Config!$H$5:$H$16,MOD(MATCH(Config!$B$6,Config!$H$5:$H$16,0)+14-1,12)+1)&"/"&(Config!$B$7+INT((MATCH(Config!$B$6,Config!$H$5:$H$16,0)+14-1)/12)) -> Dezembro/2027 | B24: =D23 -> 56000 | C24: =Config!$B$9 -> 3000 | D24: =B24+C24 -> 59000 | E24: =IF($A$5=0,"",D24/$A$5) -> 0.64193931 | F24: =IF(D24>=$A$5,IF(B24<$A$5,"Meta atingida","Acima da meta"),"") | G24: =IF(E24="","",REPT("█",ROUND(MIN(1,E24)*30,0))) -> ███████████████████ | J24: =$A$5 -> 91909
A25: =INDEX(Config!$H$5:$H$16,MOD(MATCH(Config!$B$6,Config!$H$5:$H$16,0)+15-1,12)+1)&"/"&(Config!$B$7+INT((MATCH(Config!$B$6,Config!$H$5:$H$16,0)+15-1)/12)) -> Janeiro/2028 | B25: =D24 -> 59000 | C25: =Config!$B$9 -> 3000 | D25: =B25+C25 -> 62000 | E25: =IF($A$5=0,"",D25/$A$5) -> 0.67458029 | F25: =IF(D25>=$A$5,IF(B25<$A$5,"Meta atingida","Acima da meta"),"") | G25: =IF(E25="","",REPT("█",ROUND(MIN(1,E25)*30,0))) -> ████████████████████ | J25: =$A$5 -> 91909
A26: =INDEX(Config!$H$5:$H$16,MOD(MATCH(Config!$B$6,Config!$H$5:$H$16,0)+16-1,12)+1)&"/"&(Config!$B$7+INT((MATCH(Config!$B$6,Config!$H$5:$H$16,0)+16-1)/12)) -> Fevereiro/2028 | B26: =D25 -> 62000 | C26: =Config!$B$9 -> 3000 | D26: =B26+C26 -> 65000 | E26: =IF($A$5=0,"",D26/$A$5) -> 0.70722127 | F26: =IF(D26>=$A$5,IF(B26<$A$5,"Meta atingida","Acima da meta"),"") | G26: =IF(E26="","",REPT("█",ROUND(MIN(1,E26)*30,0))) -> █████████████████████ | J26: =$A$5 -> 91909
A27: =INDEX(Config!$H$5:$H$16,MOD(MATCH(Config!$B$6,Config!$H$5:$H$16,0)+17-1,12)+1)&"/"&(Config!$B$7+INT((MATCH(Config!$B$6,Config!$H$5:$H$16,0)+17-1)/12)) -> Março/2028 | B27: =D26 -> 65000 | C27: =Config!$B$9 -> 3000 | D27: =B27+C27 -> 68000 | E27: =IF($A$5=0,"",D27/$A$5) -> 0.73986226 | F27: =IF(D27>=$A$5,IF(B27<$A$5,"Meta atingida","Acima da meta"),"") | G27: =IF(E27="","",REPT("█",ROUND(MIN(1,E27)*30,0))) -> ██████████████████████ | J27: =$A$5 -> 91909
A28: =INDEX(Config!$H$5:$H$16,MOD(MATCH(Config!$B$6,Config!$H$5:$H$16,0)+18-1,12)+1)&"/"&(Config!$B$7+INT((MATCH(Config!$B$6,Config!$H$5:$H$16,0)+18-1)/12)) -> Abril/2028 | B28: =D27 -> 68000 | C28: =Config!$B$9 -> 3000 | D28: =B28+C28 -> 71000 | E28: =IF($A$5=0,"",D28/$A$5) -> 0.77250324 | F28: =IF(D28>=$A$5,IF(B28<$A$5,"Meta atingida","Acima da meta"),"") | G28: =IF(E28="","",REPT("█",ROUND(MIN(1,E28)*30,0))) -> ███████████████████████ | J28: =$A$5 -> 91909
A29: =INDEX(Config!$H$5:$H$16,MOD(MATCH(Config!$B$6,Config!$H$5:$H$16,0)+19-1,12)+1)&"/"&(Config!$B$7+INT((MATCH(Config!$B$6,Config!$H$5:$H$16,0)+19-1)/12)) -> Maio/2028 | B29: =D28 -> 71000 | C29: =Config!$B$9 -> 3000 | D29: =B29+C29 -> 74000 | E29: =IF($A$5=0,"",D29/$A$5) -> 0.80514422 | F29: =IF(D29>=$A$5,IF(B29<$A$5,"Meta atingida","Acima da meta"),"") | G29: =IF(E29="","",REPT("█",ROUND(MIN(1,E29)*30,0))) -> ████████████████████████ | J29: =$A$5 -> 91909
A30: =INDEX(Config!$H$5:$H$16,MOD(MATCH(Config!$B$6,Config!$H$5:$H$16,0)+20-1,12)+1)&"/"&(Config!$B$7+INT((MATCH(Config!$B$6,Config!$H$5:$H$16,0)+20-1)/12)) -> Junho/2028 | B30: =D29 -> 74000 | C30: =Config!$B$9 -> 3000 | D30: =B30+C30 -> 77000 | E30: =IF($A$5=0,"",D30/$A$5) -> 0.8377852 | F30: =IF(D30>=$A$5,IF(B30<$A$5,"Meta atingida","Acima da meta"),"") | G30: =IF(E30="","",REPT("█",ROUND(MIN(1,E30)*30,0))) -> █████████████████████████ | J30: =$A$5 -> 91909
A31: =INDEX(Config!$H$5:$H$16,MOD(MATCH(Config!$B$6,Config!$H$5:$H$16,0)+21-1,12)+1)&"/"&(Config!$B$7+INT((MATCH(Config!$B$6,Config!$H$5:$H$16,0)+21-1)/12)) -> Julho/2028 | B31: =D30 -> 77000 | C31: =Config!$B$9 -> 3000 | D31: =B31+C31 -> 80000 | E31: =IF($A$5=0,"",D31/$A$5) -> 0.87042618 | F31: =IF(D31>=$A$5,IF(B31<$A$5,"Meta atingida","Acima da meta"),"") | G31: =IF(E31="","",REPT("█",ROUND(MIN(1,E31)*30,0))) -> ██████████████████████████ | J31: =$A$5 -> 91909
A32: =INDEX(Config!$H$5:$H$16,MOD(MATCH(Config!$B$6,Config!$H$5:$H$16,0)+22-1,12)+1)&"/"&(Config!$B$7+INT((MATCH(Config!$B$6,Config!$H$5:$H$16,0)+22-1)/12)) -> Agosto/2028 | B32: =D31 -> 80000 | C32: =Config!$B$9 -> 3000 | D32: =B32+C32 -> 83000 | E32: =IF($A$5=0,"",D32/$A$5) -> 0.90306716 | F32: =IF(D32>=$A$5,IF(B32<$A$5,"Meta atingida","Acima da meta"),"") | G32: =IF(E32="","",REPT("█",ROUND(MIN(1,E32)*30,0))) -> ███████████████████████████ | J32: =$A$5 -> 91909
A33: =INDEX(Config!$H$5:$H$16,MOD(MATCH(Config!$B$6,Config!$H$5:$H$16,0)+23-1,12)+1)&"/"&(Config!$B$7+INT((MATCH(Config!$B$6,Config!$H$5:$H$16,0)+23-1)/12)) -> Setembro/2028 | B33: =D32 -> 83000 | C33: =Config!$B$9 -> 3000 | D33: =B33+C33 -> 86000 | E33: =IF($A$5=0,"",D33/$A$5) -> 0.93570815 | F33: =IF(D33>=$A$5,IF(B33<$A$5,"Meta atingida","Acima da meta"),"") | G33: =IF(E33="","",REPT("█",ROUND(MIN(1,E33)*30,0))) -> ████████████████████████████ | J33: =$A$5 -> 91909
A34: =INDEX(Config!$H$5:$H$16,MOD(MATCH(Config!$B$6,Config!$H$5:$H$16,0)+24-1,12)+1)&"/"&(Config!$B$7+INT((MATCH(Config!$B$6,Config!$H$5:$H$16,0)+24-1)/12)) -> Outubro/2028 | B34: =D33 -> 86000 | C34: =Config!$B$9 -> 3000 | D34: =B34+C34 -> 89000 | E34: =IF($A$5=0,"",D34/$A$5) -> 0.96834913 | F34: =IF(D34>=$A$5,IF(B34<$A$5,"Meta atingida","Acima da meta"),"") | G34: =IF(E34="","",REPT("█",ROUND(MIN(1,E34)*30,0))) -> █████████████████████████████ | J34: =$A$5 -> 91909
A35: =INDEX(Config!$H$5:$H$16,MOD(MATCH(Config!$B$6,Config!$H$5:$H$16,0)+25-1,12)+1)&"/"&(Config!$B$7+INT((MATCH(Config!$B$6,Config!$H$5:$H$16,0)+25-1)/12)) -> Novembro/2028 | B35: =D34 -> 89000 | C35: =Config!$B$9 -> 3000 | D35: =B35+C35 -> 92000 | E35: =IF($A$5=0,"",D35/$A$5) -> 1.0009901 | F35: =IF(D35>=$A$5,IF(B35<$A$5,"Meta atingida","Acima da meta"),"") -> Meta atingida | G35: =IF(E35="","",REPT("█",ROUND(MIN(1,E35)*30,0))) -> ██████████████████████████████ | J35: =$A$5 -> 91909
A36: =INDEX(Config!$H$5:$H$16,MOD(MATCH(Config!$B$6,Config!$H$5:$H$16,0)+26-1,12)+1)&"/"&(Config!$B$7+INT((MATCH(Config!$B$6,Config!$H$5:$H$16,0)+26-1)/12)) -> Dezembro/2028 | B36: =D35 -> 92000 | C36: =Config!$B$9 -> 3000 | D36: =B36+C36 -> 95000 | E36: =IF($A$5=0,"",D36/$A$5) -> 1.0336311 | F36: =IF(D36>=$A$5,IF(B36<$A$5,"Meta atingida","Acima da meta"),"") -> Acima da meta | G36: =IF(E36="","",REPT("█",ROUND(MIN(1,E36)*30,0))) -> ██████████████████████████████ | J36: =$A$5 -> 91909
A37: =INDEX(Config!$H$5:$H$16,MOD(MATCH(Config!$B$6,Config!$H$5:$H$16,0)+27-1,12)+1)&"/"&(Config!$B$7+INT((MATCH(Config!$B$6,Config!$H$5:$H$16,0)+27-1)/12)) -> Janeiro/2029 | B37: =D36 -> 95000 | C37: =Config!$B$9 -> 3000 | D37: =B37+C37 -> 98000 | E37: =IF($A$5=0,"",D37/$A$5) -> 1.0662721 | F37: =IF(D37>=$A$5,IF(B37<$A$5,"Meta atingida","Acima da meta"),"") -> Acima da meta | G37: =IF(E37="","",REPT("█",ROUND(MIN(1,E37)*30,0))) -> ██████████████████████████████ | J37: =$A$5 -> 91909
A38: =INDEX(Config!$H$5:$H$16,MOD(MATCH(Config!$B$6,Config!$H$5:$H$16,0)+28-1,12)+1)&"/"&(Config!$B$7+INT((MATCH(Config!$B$6,Config!$H$5:$H$16,0)+28-1)/12)) -> Fevereiro/2029 | B38: =D37 -> 98000 | C38: =Config!$B$9 -> 3000 | D38: =B38+C38 -> 101000 | E38: =IF($A$5=0,"",D38/$A$5) -> 1.0989131 | F38: =IF(D38>=$A$5,IF(B38<$A$5,"Meta atingida","Acima da meta"),"") -> Acima da meta | G38: =IF(E38="","",REPT("█",ROUND(MIN(1,E38)*30,0))) -> ██████████████████████████████ | J38: =$A$5 -> 91909
A39: =INDEX(Config!$H$5:$H$16,MOD(MATCH(Config!$B$6,Config!$H$5:$H$16,0)+29-1,12)+1)&"/"&(Config!$B$7+INT((MATCH(Config!$B$6,Config!$H$5:$H$16,0)+29-1)/12)) -> Março/2029 | B39: =D38 -> 101000 | C39: =Config!$B$9 -> 3000 | D39: =B39+C39 -> 104000 | E39: =IF($A$5=0,"",D39/$A$5) -> 1.131554 | F39: =IF(D39>=$A$5,IF(B39<$A$5,"Meta atingida","Acima da meta"),"") -> Acima da meta | G39: =IF(E39="","",REPT("█",ROUND(MIN(1,E39)*30,0))) -> ██████████████████████████████ | J39: =$A$5 -> 91909
A40: Aporte igual todo mês, sem rendimento. Quando a reserva bater a meta, decida com o sócio o que fazer com o aporte: manter, reduzir ou virar distribuição.
A41: Metas de caixa do trimestre
A42: Meta | B42: Valor alvo | C42: Valor atual | D42: Progresso | E42: Barra | F42: Prazo | G42: Dias restantes | H42: Situação
...

Sheet Config
A1: Configurações
A2: Células amarelas: você preenche. Custo fixo, saldo e reserva vêm do Painel da planilha 09; o resto é decisão da clínica.
A4: Clínica | B4: Clínica Vida Plena (exemplo fictício) | H4: Meses
A5: Data de referência | B5: 46279 | H5: Janeiro
A6: Mês de início da projeção | B6: Outubro | H6: Fevereiro
A7: Ano de início da projeção | B7: 2026 | H7: Março
A8: Meta de reserva (meses de custo fixo + pró-labore) | B8: 3 | D8: Três meses do que a clínica paga todo mês mesmo parada — custo fixo MAIS o pró-labore dos sócios — é a meta usual para uma clínica pequena: convênio atrasa, agenda esvazia em janeiro e julho, equipamento quebra. Atenção ao nome: "custo fixo" nas planilhas 05, 09 e 18 é só a estrutura (R$ 10.000 no exemplo); aqui é custo fixo + pró-labore (R$ 28.000 num mês sem retirada extra). | H8: Abril
A9: Aporte mensal planejado para a reserva | B9: 3000 | H9: Maio
H10: Junho
A11: Custo fixo + pró-labore dos últimos 3 meses (o que sai todo mês, mesmo com a agenda vazia) | H11: Julho
A12: Mês | B12: Custo fixo + pró-labore do mês | H12: Agosto
A13: Junho | B13: 29500 | D13: ="Copie de “Para onde foi o dinheiro” (Painel da planilha 09), somando as oito linhas de custo fixo (aluguel, recepção, contador, sistema, energia, limpeza, marketing, anuidades) com a linha “Pró-labore dos sócios” inteira, como ela aparece lá. Impostos, materiais, taxas de cartão e repasse ficam fora (variam com o movimento). No exemplo, "&"R$ "&FIXED($B$13,0)&" em "&$A$13&" e "&"R$ "&FIXED($B$14,0)&" em "&$A$14&" vêm acima dos "&"R$ "&FIXED($B$15,0)&" de "&$A$15&": a linha de pró-labore da 09 traz também a retirada extra de 19/06 e a distribuição de lucro paga em 10/07, então a média fica um pouco acima do mês normal e a meta de reserva sai mais conservadora. Se preferir dimensionar pelo mês normal, use os três meses sem retirada extra." -> Copie de “Para onde foi o dinheiro” (Painel da planilha 09), somando as oito linhas de custo fixo (aluguel, recepção, contador, sistema, energia, limpeza, marketing, anuidades) com a linha “Pró-labore dos sócios” inteira, como ela aparece lá. Impostos, materiais, taxas de cartão e repasse ficam fora (variam com o movimento). No exemplo, R$ 29.500 em Junho e R$ 34.409 em Julho vêm acima dos R$ 28.000 de Agosto: a linha de pró-labore da 09 traz também a retirada extra de 19/06 e a distribuição de lucro paga em 10/07, então a média fica um pouco acima do mês normal e a meta de reserva sai mais conservadora. Se preferir dimensionar pelo mês normal, use os três meses sem retirada extra. | H13: Setembro
A14: Julho | B14: 34409 | H14: Outubro
A15: Agosto | B15: 28000 | H15: Novembro
A16: Custo fixo + pró-labore médio | B16: =IFERROR(AVERAGE(B13:B15),0) -> 30636.333 | H16: Dezembro
A18: Situação hoje
A19: Saldo em caixa da clínica (conta corrente) | B19: 38605.81 | D19: Saldo acumulado (setembro) e A pagar do Painel da planilha 09, em 14/09/2026.
A20: Compromissos já lançados e ainda não pagos | B20: 26603
A21: Caixa livre | B21: =B19-B20 -> 12002.81
A22: Reserva já guardada (conta separada) | B22: 14000 | D22: O que já está numa conta separada só para a reserva. Se ainda não separou, deixe 0.
A24: Metas de caixa do trimestre (3)
A25: Meta | B25: Valor alvo | C25: Valor atual | D25: Prazo
A26: Reserva com 1 mês de custo fixo + pró-labore | B26: 28000 | C26: 14000 | D26: 46387
A27: Receber R$ 130.000 no trimestre | B27: 130000 | C27: 121022 | D27: 46295
A28: Conta de provisão de impostos com o saldo de agosto (planilha 10) | B28: 18209 | C28: 17500 | D28: 46295
A31: Metas que se medem em reais e crescem até o alvo (reserva, recebimentos, provisão separada). Atualize o valor atual toda sexta. No exemplo os prazos são datas fixas (fim do trimestre e do ano).
