Workbook

Sheet Como usar
A1: Orçamentos apresentados × aprovados
A2: Kit de Gestão para Médicos · Seu Sócio Gestor · versão 1.0 (setembro de 2026)
A4: O que esta planilha faz | B4: O funil da recepção: cada orçamento de exame ou pacote particular apresentado ao paciente, com valor e etapa; a previsão ponderada, o aprovado no trimestre contra a meta, a taxa de aprovação, quem retomar primeiro, os resultados por tipo e profissional e os motivos de recusa.
A5: Passo 1 | B5: Em Config, preencha a meta de orçamentos aprovados no trimestre, o limite de "parado" (7 dias é um bom padrão), os tipos, motivos de recusa, profissionais e itens mais comuns. Ajuste as probabilidades por etapa se a sua experiência for diferente.
A6: Passo 2 | B6: Em Orçamentos, uma linha por orçamento: data, paciente, profissional, tipo, itens, valor e etapa. Sempre que o paciente responder, atualize a etapa.
A7: Passo 3 | B7: Ao decidir, mude a etapa para Aprovado, Recusado ou Sem retorno e preencha a data. Se recusado, anote o motivo: é a parte mais valiosa da planilha. Aprovado vira horário na agenda (01) e, se for a prazo, parcela na 14.
A8: Passo 4 | B8: Em Painel, veja o funil, a previsão ponderada, a lista "Retomar contato primeiro", a taxa de aprovação por tipo e profissional e os motivos de recusa.
A9: Rotina | B9: Sexta-feira, 10 minutos: atualizar etapas, retomar os parados. Dia 1 do mês: comparar o aprovado com a meta e olhar os motivos de recusa. O Painel da clínica (17) copia "Em aberto" e "Aprovado no mês" daqui.
A10: Com a IA | B10: Copie "Motivos de recusa" e use o prompt "Recebíveis 05 · Por que os orçamentos não fecham" da biblioteca; para retomar um contato, "Agenda 04 · Mensagem de retomada de orçamento" (sem nome do paciente). Nenhum prompt do kit escreve promessa de resultado.
A11: Exemplo | B11: O funil traz os orçamentos de junho a setembro de 2026: os aprovados são exames realizados ou agendados na planilha 01 (mesmo paciente e data); os abertos têm datas relativas a hoje.
A12: Legenda | B12: Células amarelas: você preenche. Brancas: calculadas. Não é preciso mexer em nada fora do amarelo.
A13: Proteção | B13: Fórmulas protegidas sem senha. Para editar: Revisar > Desproteger planilha (Excel) ou Dados > Proteger intervalos (Google Sheets).
A14: Requisitos | B14: Excel 2016 ou mais novo, Microsoft 365 ou Google Sheets (só funções do Excel 2007+; nada de MÍNIMOSES, MÁXIMOSES ou UNIRTEXTO). No celular abre nos aplicativos; para preencher, use o computador.
A15: Dados de pacientes | B15: Guarde só o que a gestão precisa (nome, contato, valor, data). Nada de diagnóstico, prontuário ou exame nestas planilhas: o kit é gestão, não é prontuário. Veja o guia LGPD do kit antes de colar qualquer tabela em uma IA.
... A18: Suporte | B18: suporte@seusociogestor.com.br · resposta em até 5 dias úteis · reembolso em até 7 dias pelo mesmo canal.

Sheet Painel
A1: =Config!$B$4&" · Orçamentos apresentados × aprovados · "&TEXT(DAY(Config!$B$5),"00")&"/"&TEXT(MONTH(Config!$B$5),"00")&"/"&YEAR(Config!$B$5) -> Clínica Vida Plena (exemplo fictício) · Orçamentos apresentados × aprovados · 14/09/2026
A2: Nada para digitar aqui: tudo vem de Orçamentos e Config.
A4: Em aberto (R$) | C4: Previsão ponderada | E4: Aprovado no trimestre | G4: % da meta | I4: Taxa de aprovação | K4: Dias até decidir (média)
A5: =SUMIFS(Orçamentos!$F$5:$F$304,Orçamentos!$G$5:$G$304,"<>Aprovado",Orçamentos!$G$5:$G$304,"<>Recusado",Orçamentos!$G$5:$G$304,"<>Sem retorno",Orçamentos!$G$5:$G$304,"<>") -> 3460 | C5: =SUMIFS(Orçamentos!$L$5:$L$304,Orçamentos!$G$5:$G$304,"<>Aprovado",Orçamentos!$G$5:$G$304,"<>Recusado",Orçamentos!$G$5:$G$304,"<>Sem retorno",Orçamentos!$G$5:$G$304,"<>") -> 1318 | E5: =SUMIFS(Orçamentos!$F$5:$F$304,Orçamentos!$G$5:$G$304,"Aprovado",Orçamentos!$H$5:$H$304,">="&DATE(YEAR(Config!$B$5),3*INT((MONTH(Config!$B$5)-1)/3)+1,1)) -> 8510 | G5: =IFERROR(E5/Config!$B$6,0) -> 0.47277778 | I5: =IFERROR(COUNTIFS(Orçamentos!$G$5:$G$304,"Aprovado")/(COUNTIFS(Orçamentos!$G$5:$G$304,"Aprovado")+COUNTIFS(Orçamentos!$G$5:$G$304,"Recusado")+COUNTIFS(Orçamentos!$G$5:$G$304,"Sem retorno")),0) -> 0.72413793 | K5: =IFERROR(AVERAGEIFS(Orçamentos!$N$5:$N$304,Orçamentos!$G$5:$G$304,"Aprovado"),0) -> 5.9047619
A7: Taxa de aprovação = aprovados ÷ (aprovados + recusados + sem retorno). Dias até decidir = da apresentação à decisão, média dos aprovados. Aprovado no trimestre soma pela data da decisão.
A9: Funil por etapa
A10: Etapa | B10: Orçamentos | C10: Valor (R$) | D10: Ponderado (R$) | E10: Barra
A11: =Config!$A$10 -> Apresentado | B11: =COUNTIFS(Orçamentos!$G$5:$G$304,A11) -> 3 | C11: =SUMIFS(Orçamentos!$F$5:$F$304,Orçamentos!$G$5:$G$304,A11) -> 2060 | D11: =SUMIFS(Orçamentos!$L$5:$L$304,Orçamentos!$G$5:$G$304,A11) -> 618 | E11: =REPT("█",ROUND(IFERROR(C11/MAX($C$11:$C$15),0)*30,0)) -> ███████
A12: =Config!$A$11 -> Em análise | B12: =COUNTIFS(Orçamentos!$G$5:$G$304,A12) -> 3 | C12: =SUMIFS(Orçamentos!$F$5:$F$304,Orçamentos!$G$5:$G$304,A12) -> 1400 | D12: =SUMIFS(Orçamentos!$L$5:$L$304,Orçamentos!$G$5:$G$304,A12) -> 700 | E12: =REPT("█",ROUND(IFERROR(C12/MAX($C$11:$C$15),0)*30,0)) -> █████
A13: Aprovado (total) | B13: =COUNTIFS(Orçamentos!$G$5:$G$304,"Aprovado") -> 21 | C13: =SUMIFS(Orçamentos!$F$5:$F$304,Orçamentos!$G$5:$G$304,"Aprovado") -> 8510 | E13: =REPT("█",ROUND(IFERROR(C13/MAX($C$11:$C$15),0)*30,0)) -> ██████████████████████████████
A14: Recusado (total) | B14: =COUNTIFS(Orçamentos!$G$5:$G$304,"Recusado") -> 5 | C14: =SUMIFS(Orçamentos!$F$5:$F$304,Orçamentos!$G$5:$G$304,"Recusado") -> 1860 | E14: =REPT("█",ROUND(IFERROR(C14/MAX($C$11:$C$15),0)*30,0)) -> ███████
A15: Sem retorno (total) | B15: =COUNTIFS(Orçamentos!$G$5:$G$304,"Sem retorno") -> 3 | C15: =SUMIFS(Orçamentos!$F$5:$F$304,Orçamentos!$G$5:$G$304,"Sem retorno") -> 1660 | E15: =REPT("█",ROUND(IFERROR(C15/MAX($C$11:$C$15),0)*30,0)) -> ██████
A16: Valor médio dos aprovados | B16: =IFERROR(C13/B13,0) -> 405.2381
A18: Retomar contato primeiro
A19: Orçamentos abertos parados há mais tempo; os de maior valor primeiro. Sem insistência: uma mensagem educada perguntando se ficou alguma dúvida.
A20: # | B20: Paciente | C20: Itens | D20: Etapa | E20: Valor (R$) | F20: Dias em aberto | G20: Situação | H20: Profissional
A21: 1 | B21: =IFERROR(IF(LARGE(Orçamentos!$Q$5:$Q$304,1)>0,INDEX(Orçamentos!$B$5:$B$304,MATCH(LARGE(Orçamentos!$Q$5:$Q$304,1),Orçamentos!$Q$5:$Q$304,0)),""),"") -> Mariana Reis | C21: =IFERROR(IF(LARGE(Orçamentos!$Q$5:$Q$304,1)>0,INDEX(Orçamentos!$E$5:$E$304,MATCH(LARGE(Orçamentos!$Q$5:$Q$304,1),Orçamentos!$Q$5:$Q$304,0)),""),"") -> MAPA + Holter | D21: =IFERROR(IF(LARGE(Orçamentos!$Q$5:$Q$304,1)>0,INDEX(Orçamentos!$G$5:$G$304,MATCH(LARGE(Orçamentos!$Q$5:$Q$304,1),Orçamentos!$Q$5:$Q$304,0)),""),"") -> Em análise | E21: =IFERROR(IF(LARGE(Orçamentos!$Q$5:$Q$304,1)>0,INDEX(Orçamentos!$F$5:$F$304,MATCH(LARGE(Orçamentos!$Q$5:$Q$304,1),Orçamentos!$Q$5:$Q$304,0)),""),"") -> 650 | F21: =IFERROR(IF(LARGE(Orçamentos!$Q$5:$Q$304,1)>0,INDEX(Orçamentos!$M$5:$M$304,MATCH(LARGE(Orçamentos!$Q$5:$Q$304,1),Orçamentos!$Q$5:$Q$304,0)),""),"") -> 12 | G21: =IFERROR(IF(LARGE(Orçamentos!$Q$5:$Q$304,1)>0,INDEX(Orçamentos!$O$5:$O$304,MATCH(LARGE(Orçamentos!$Q$5:$Q$304,1),Orçamentos!$Q$5:$Q$304,0)),""),"") -> Parado | H21: =IFERROR(IF(LARGE(Orçamentos!$Q$5:$Q$304,1)>0,INDEX(Orçamentos!$C$5:$C$304,MATCH(LARGE(Orçamentos!$Q$5:$Q$304,1),Orçamentos!$Q$5:$Q$304,0)),""),"") -> Dr. Paulo Andrade
A22: 2 | B22: =IFERROR(IF(LARGE(Orçamentos!$Q$5:$Q$304,2)>0,INDEX(Orçamentos!$B$5:$B$304,MATCH(LARGE(Orçamentos!$Q$5:$Q$304,2),Orçamentos!$Q$5:$Q$304,0)),""),"") -> Beatriz Monteiro | C22: =IFERROR(IF(LARGE(Orçamentos!$Q$5:$Q$304,2)>0,INDEX(Orçamentos!$E$5:$E$304,MATCH(LARGE(Orçamentos!$Q$5:$Q$304,2),Orçamentos!$Q$5:$Q$304,0)),""),"") -> Avaliação endócrina + retorno | D22: =IFERROR(IF(LARGE(Orçamentos!$Q$5:$Q$304,2)>0,INDEX(Orçamentos!$G$5:$G$304,MATCH(LARGE(Orçamentos!$Q$5:$Q$304,2),Orçamentos!$Q$5:$Q$304,0)),""),"") -> Em análise | E22: =IFERROR(IF(LARGE(Orçamentos!$Q$5:$Q$304,2)>0,INDEX(Orçamentos!$F$5:$F$304,MATCH(LARGE(Orçamentos!$Q$5:$Q$304,2),Orçamentos!$Q$5:$Q$304,0)),""),"") -> 400 | F22: =IFERROR(IF(LARGE(Orçamentos!$Q$5:$Q$304,2)>0,INDEX(Orçamentos!$M$5:$M$304,MATCH(LARGE(Orçamentos!$Q$5:$Q$304,2),Orçamentos!$Q$5:$Q$304,0)),""),"") -> 9 | G22: =IFERROR(IF(LARGE(Orçamentos!$Q$5:$Q$304,2)>0,INDEX(Orçamentos!$O$5:$O$304,MATCH(LARGE(Orçamentos!$Q$5:$Q$304,2),Orçamentos!$Q$5:$Q$304,0)),""),"") -> Parado | H22: =IFERROR(IF(LARGE(Orçamentos!$Q$5:$Q$304,2)>0,INDEX(Orçamentos!$C$5:$C$304,MATCH(LARGE(Orçamentos!$Q$5:$Q$304,2),Orçamentos!$Q$5:$Q$304,0)),""),"") -> Dra. Renata Sousa
A23: 3 | B23: =IFERROR(IF(LARGE(Orçamentos!$Q$5:$Q$304,3)>0,INDEX(Orçamentos!$B$5:$B$304,MATCH(LARGE(Orçamentos!$Q$5:$Q$304,3),Orçamentos!$Q$5:$Q$304,0)),""),"") -> Rafael Dias | C23: =IFERROR(IF(LARGE(Orçamentos!$Q$5:$Q$304,3)>0,INDEX(Orçamentos!$E$5:$E$304,MATCH(LARGE(Orçamentos!$Q$5:$Q$304,3),Orçamentos!$Q$5:$Q$304,0)),""),"") -> Holter | D23: =IFERROR(IF(LARGE(Orçamentos!$Q$5:$Q$304,3)>0,INDEX(Orçamentos!$G$5:$G$304,MATCH(LARGE(Orçamentos!$Q$5:$Q$304,3),Orçamentos!$Q$5:$Q$304,0)),""),"") -> Em análise | E23: =IFERROR(IF(LARGE(Orçamentos!$Q$5:$Q$304,3)>0,INDEX(Orçamentos!$F$5:$F$304,MATCH(LARGE(Orçamentos!$Q$5:$Q$304,3),Orçamentos!$Q$5:$Q$304,0)),""),"") -> 350 | F23: =IFERROR(IF(LARGE(Orçamentos!$Q$5:$Q$304,3)>0,INDEX(Orçamentos!$M$5:$M$304,MATCH(LARGE(Orçamentos!$Q$5:$Q$304,3),Orçamentos!$Q$5:$Q$304,0)),""),"") -> 6 | G23: =IFERROR(IF(LARGE(Orçamentos!$Q$5:$Q$304,3)>0,INDEX(Orçamentos!$O$5:$O$304,MATCH(LARGE(Orçamentos!$Q$5:$Q$304,3),Orçamentos!$Q$5:$Q$304,0)),""),"") -> Ativo | H23: =IFERROR(IF(LARGE(Orçamentos!$Q$5:$Q$304,3)>0,INDEX(Orçamentos!$C$5:$C$304,MATCH(LARGE(Orçamentos!$Q$5:$Q$304,3),Orçamentos!$Q$5:$Q$304,0)),""),"") -> Dr. Paulo Andrade
A24: 4 | B24: =IFERROR(IF(LARGE(Orçamentos!$Q$5:$Q$304,4)>0,INDEX(Orçamentos!$B$5:$B$304,MATCH(LARGE(Orçamentos!$Q$5:$Q$304,4),Orçamentos!$Q$5:$Q$304,0)),""),"") -> Roberta Lima | C24: =IFERROR(IF(LARGE(Orçamentos!$Q$5:$Q$304,4)>0,INDEX(Orçamentos!$E$5:$E$304,MATCH(LARGE(Orçamentos!$Q$5:$Q$304,4),Orçamentos!$Q$5:$Q$304,0)),""),"") -> Consulta + ECG + teste ergométrico | D24: =IFERROR(IF(LARGE(Orçamentos!$Q$5:$Q$304,4)>0,INDEX(Orçamentos!$G$5:$G$304,MATCH(LARGE(Orçamentos!$Q$5:$Q$304,4),Orçamentos!$Q$5:$Q$304,0)),""),"") -> Apresentado | E24: =IFERROR(IF(LARGE(Orçamentos!$Q$5:$Q$304,4)>0,INDEX(Orçamentos!$F$5:$F$304,MATCH(LARGE(Orçamentos!$Q$5:$Q$304,4),Orçamentos!$Q$5:$Q$304,0)),""),"") -> 960 | F24: =IFERROR(IF(LARGE(Orçamentos!$Q$5:$Q$304,4)>0,INDEX(Orçamentos!$M$5:$M$304,MATCH(LARGE(Orçamentos!$Q$5:$Q$304,4),Orçamentos!$Q$5:$Q$304,0)),""),"") -> 3 | G24: =IFERROR(IF(LARGE(Orçamentos!$Q$5:$Q$304,4)>0,INDEX(Orçamentos!$O$5:$O$304,MATCH(LARGE(Orçamentos!$Q$5:$Q$304,4),Orçamentos!$Q$5:$Q$304,0)),""),"") -> Ativo | H24: =IFERROR(IF(LARGE(Orçamentos!$Q$5:$Q$304,4)>0,INDEX(Orçamentos!$C$5:$C$304,MATCH(LARGE(Orçamentos!$Q$5:$Q$304,4),Orçamentos!$Q$5:$Q$304,0)),""),"") -> Dr. Paulo Andrade
A25: 5 | B25: =IFERROR(IF(LARGE(Orçamentos!$Q$5:$Q$304,5)>0,INDEX(Orçamentos!$B$5:$B$304,MATCH(LARGE(Orçamentos!$Q$5:$Q$304,5),Orçamentos!$Q$5:$Q$304,0)),""),"") -> Wagner Costa | C25: =IFERROR(IF(LARGE(Orçamentos!$Q$5:$Q$304,5)>0,INDEX(Orçamentos!$E$5:$E$304,MATCH(LARGE(Orçamentos!$Q$5:$Q$304,5),Orçamentos!$Q$5:$Q$304,0)),""),"") -> Teste ergométrico | D25: =IFERROR(IF(LARGE(Orçamentos!$Q$5:$Q$304,5)>0,INDEX(Orçamentos!$G$5:$G$304,MATCH(LARGE(Orçamentos!$Q$5:$Q$304,5),Orçamentos!$Q$5:$Q$304,0)),""),"") -> Apresentado | E25: =IFERROR(IF(LARGE(Orçamentos!$Q$5:$Q$304,5)>0,INDEX(Orçamentos!$F$5:$F$304,MATCH(LARGE(Orçamentos!$Q$5:$Q$304,5),Orçamentos!$Q$5:$Q$304,0)),""),"") -> 450 | F25: =IFERROR(IF(LARGE(Orçamentos!$Q$5:$Q$304,5)>0,INDEX(Orçamentos!$M$5:$M$304,MATCH(LARGE(Orçamentos!$Q$5:$Q$304,5),Orçamentos!$Q$5:$Q$304,0)),""),"") -> 1 | G25: =IFERROR(IF(LARGE(Orçamentos!$Q$5:$Q$304,5)>0,INDEX(Orçamentos!$O$5:$O$304,MATCH(LARGE(Orçamentos!$Q$5:$Q$304,5),Orçamentos!$Q$5:$Q$304,0)),""),"") -> Ativo | H25: =IFERROR(IF(LARGE(Orçamentos!$Q$5:$Q$304,5)>0,INDEX(Orçamentos!$C$5:$C$304,MATCH(LARGE(Orçamentos!$Q$5:$Q$304,5),Orçamentos!$Q$5:$Q$304,0)),""),"") -> Dr. Paulo Andrade
A26: 6 | B26: =IFERROR(IF(LARGE(Orçamentos!$Q$5:$Q$304,6)>0,INDEX(Orçamentos!$B$5:$B$304,MATCH(LARGE(Orçamentos!$Q$5:$Q$304,6),Orçamentos!$Q$5:$Q$304,0)),""),"") -> Fábio Correia | C26: =IFERROR(IF(LARGE(Orçamentos!$Q$5:$Q$304,6)>0,INDEX(Orçamentos!$E$5:$E$304,MATCH(LARGE(Orçamentos!$Q$5:$Q$304,6),Orçamentos!$Q$5:$Q$304,0)),""),"") -> MAPA + Holter | D26: =IFERROR(IF(LARGE(Orçamentos!$Q$5:$Q$304,6)>0,INDEX(Orçamentos!$G$5:$G$304,MATCH(LARGE(Orçamentos!$Q$5:$Q$304,6),Orçamentos!$Q$5:$Q$304,0)),""),"") -> Apresentado | E26: =IFERROR(IF(LARGE(Orçamentos!$Q$5:$Q$304,6)>0,INDEX(Orçamentos!$F$5:$F$304,MATCH(LARGE(Orçamentos!$Q$5:$Q$304,6),Orçamentos!$Q$5:$Q$304,0)),""),"") -> 650 | F26: =IFERROR(IF(LARGE(Orçamentos!$Q$5:$Q$304,6)>0,INDEX(Orçamentos!$M$5:$M$304,MATCH(LARGE(Orçamentos!$Q$5:$Q$304,6),Orçamentos!$Q$5:$Q$304,0)),""),"") -> 0 | G26: =IFERROR(IF(LARGE(Orçamentos!$Q$5:$Q$304,6)>0,INDEX(Orçamentos!$O$5:$O$304,MATCH(LARGE(Orçamentos!$Q$5:$Q$304,6),Orçamentos!$Q$5:$Q$304,0)),""),"") -> Ativo | H26: =IFERROR(IF(LARGE(Orçamentos!$Q$5:$Q$304,6)>0,INDEX(Orçamentos!$C$5:$C$304,MATCH(LARGE(Orçamentos!$Q$5:$Q$304,6),Orçamentos!$Q$5:$Q$304,0)),""),"") -> Dr. Paulo Andrade
A27: 7 | B27: =IFERROR(IF(LARGE(Orçamentos!$Q$5:$Q$304,7)>0,INDEX(Orçamentos!$B$5:$B$304,MATCH(LARGE(Orçamentos!$Q$5:$Q$304,7),Orçamentos!$Q$5:$Q$304,0)),""),"") | C27: =IFERROR(IF(LARGE(Orçamentos!$Q$5:$Q$304,7)>0,INDEX(Orçamentos!$E$5:$E$304,MATCH(LARGE(Orçamentos!$Q$5:$Q$304,7),Orçamentos!$Q$5:$Q$304,0)),""),"") | D27: =IFERROR(IF(LARGE(Orçamentos!$Q$5:$Q$304,7)>0,INDEX(Orçamentos!$G$5:$G$304,MATCH(LARGE(Orçamentos!$Q$5:$Q$304,7),Orçamentos!$Q$5:$Q$304,0)),""),"") | E27: =IFERROR(IF(LARGE(Orçamentos!$Q$5:$Q$304,7)>0,INDEX(Orçamentos!$F$5:$F$304,MATCH(LARGE(Orçamentos!$Q$5:$Q$304,7),Orçamentos!$Q$5:$Q$304,0)),""),"") | F27: =IFERROR(IF(LARGE(Orçamentos!$Q$5:$Q$304,7)>0,INDEX(Orçamentos!$M$5:$M$304,MATCH(LARGE(Orçamentos!$Q$5:$Q$304,7),Orçamentos!$Q$5:$Q$304,0)),""),"") | G27: =IFERROR(IF(LARGE(Orçamentos!$Q$5:$Q$304,7)>0,INDEX(Orçamentos!$O$5:$O$304,MATCH(LARGE(Orçamentos!$Q$5:$Q$304,7),Orçamentos!$Q$5:$Q$304,0)),""),"") | H27: =IFERROR(IF(LARGE(Orçamentos!$Q$5:$Q$304,7)>0,INDEX(Orçamentos!$C$5:$C$304,MATCH(LARGE(Orçamentos!$Q$5:$Q$304,7),Orçamentos!$Q$5:$Q$304,0)),""),"")
A28: 8 | B28: =IFERROR(IF(LARGE(Orçamentos!$Q$5:$Q$304,8)>0,INDEX(Orçamentos!$B$5:$B$304,MATCH(LARGE(Orçamentos!$Q$5:$Q$304,8),Orçamentos!$Q$5:$Q$304,0)),""),"") | C28: =IFERROR(IF(LARGE(Orçamentos!$Q$5:$Q$304,8)>0,INDEX(Orçamentos!$E$5:$E$304,MATCH(LARGE(Orçamentos!$Q$5:$Q$304,8),Orçamentos!$Q$5:$Q$304,0)),""),"") | D28: =IFERROR(IF(LARGE(Orçamentos!$Q$5:$Q$304,8)>0,INDEX(Orçamentos!$G$5:$G$304,MATCH(LARGE(Orçamentos!$Q$5:$Q$304,8),Orçamentos!$Q$5:$Q$304,0)),""),"") | E28: =IFERROR(IF(LARGE(Orçamentos!$Q$5:$Q$304,8)>0,INDEX(Orçamentos!$F$5:$F$304,MATCH(LARGE(Orçamentos!$Q$5:$Q$304,8),Orçamentos!$Q$5:$Q$304,0)),""),"") | F28: =IFERROR(IF(LARGE(Orçamentos!$Q$5:$Q$304,8)>0,INDEX(Orçamentos!$M$5:$M$304,MATCH(LARGE(Orçamentos!$Q$5:$Q$304,8),Orçamentos!$Q$5:$Q$304,0)),""),"") | G28: =IFERROR(IF(LARGE(Orçamentos!$Q$5:$Q$304,8)>0,INDEX(Orçamentos!$O$5:$O$304,MATCH(LARGE(Orçamentos!$Q$5:$Q$304,8),Orçamentos!$Q$5:$Q$304,0)),""),"") | H28: =IFERROR(IF(LARGE(Orçamentos!$Q$5:$Q$304,8)>0,INDEX(Orçamentos!$C$5:$C$304,MATCH(LARGE(Orçamentos!$Q$5:$Q$304,8),Orçamentos!$Q$5:$Q$304,0)),""),"")
A30: Por tipo
A31: Tipo | B31: Orçamentos | C31: Aprovados | D31: Recusados / sem retorno | E31: Taxa de aprovação | F31: Valor aprovado (R$) | G31: Em aberto (R$)
A32: =IF(Config!$A$18="","",Config!$A$18) -> Check-up cardiológico | B32: =IF(Config!$A$18="","",COUNTIFS(Orçamentos!$D$5:$D$304,Config!$A$18)) -> 3 | C32: =IF(Config!$A$18="","",COUNTIFS(Orçamentos!$D$5:$D$304,Config!$A$18,Orçamentos!$G$5:$G$304,"Aprovado")) -> 1 | D32: =IF(Config!$A$18="","",COUNTIFS(Orçamentos!$D$5:$D$304,Config!$A$18,Orçamentos!$G$5:$G$304,"Recusado")+COUNTIFS(Orçamentos!$D$5:$D$304,Config!$A$18,Orçamentos!$G$5:$G$304,"Sem retorno")) -> 1 | E32: =IF(Config!$A$18="","",IFERROR(C32/(C32+D32),0)) -> 0.5 | F32: =IF(Config!$A$18="","",SUMIFS(Orçamentos!$F$5:$F$304,Orçamentos!$D$5:$D$304,Config!$A$18,Orçamentos!$G$5:$G$304,"Aprovado")) -> 960 | G32: =IF(Config!$A$18="","",SUMIFS(Orçamentos!$F$5:$F$304,Orçamentos!$D$5:$D$304,Config!$A$18,Orçamentos!$G$5:$G$304,"<>Aprovado",Orçamentos!$G$5:$G$304,"<>Recusado",Orçamentos!$G$5:$G$304,"<>Sem retorno",Orçamentos!$G$5:$G$304,"<>")) -> 960
A33: =IF(Config!$A$19="","",Config!$A$19) -> Exame cardiológico | B33: =IF(Config!$A$19="","",COUNTIFS(Orçamentos!$D$5:$D$304,Config!$A$19)) -> 28 | C33: =IF(Config!$A$19="","",COUNTIFS(Orçamentos!$D$5:$D$304,Config!$A$19,Orçamentos!$G$5:$G$304,"Aprovado")) -> 20 | D33: =IF(Config!$A$19="","",COUNTIFS(Orçamentos!$D$5:$D$304,Config!$A$19,Orçamentos!$G$5:$G$304,"Recusado")+COUNTIFS(Orçamentos!$D$5:$D$304,Config!$A$19,Orçamentos!$G$5:$G$304,"Sem retorno")) -> 4 | E33: =IF(Config!$A$19="","",IFERROR(C33/(C33+D33),0)) -> 0.83333333 | F33: =IF(Config!$A$19="","",SUMIFS(Orçamentos!$F$5:$F$304,Orçamentos!$D$5:$D$304,Config!$A$19,Orçamentos!$G$5:$G$304,"Aprovado")) -> 7550 | G33: =IF(Config!$A$19="","",SUMIFS(Orçamentos!$F$5:$F$304,Orçamentos!$D$5:$D$304,Config!$A$19,Orçamentos!$G$5:$G$304,"<>Aprovado",Orçamentos!$G$5:$G$304,"<>Recusado",Orçamentos!$G$5:$G$304,"<>Sem retorno",Orçamentos!$G$5:$G$304,"<>")) -> 2100
A34: =IF(Config!$A$20="","",Config!$A$20) -> Avaliação endócrina | B34: =IF(Config!$A$20="","",COUNTIFS(Orçamentos!$D$5:$D$304,Config!$A$20)) -> 2 | C34: =IF(Config!$A$20="","",COUNTIFS(Orçamentos!$D$5:$D$304,Config!$A$20,Orçamentos!$G$5:$G$304,"Aprovado")) -> 0 | D34: =IF(Config!$A$20="","",COUNTIFS(Orçamentos!$D$5:$D$304,Config!$A$20,Orçamentos!$G$5:$G$304,"Recusado")+COUNTIFS(Orçamentos!$D$5:$D$304,Config!$A$20,Orçamentos!$G$5:$G$304,"Sem retorno")) -> 1 | E34: =IF(Config!$A$20="","",IFERROR(C34/(C34+D34),0)) -> 0 | F34: =IF(Config!$A$20="","",SUMIFS(Orçamentos!$F$5:$F$304,Orçamentos!$D$5:$D$304,Config!$A$20,Orçamentos!$G$5:$G$304,"Aprovado")) -> 0 | G34: =IF(Config!$A$20="","",SUMIFS(Orçamentos!$F$5:$F$304,Orçamentos!$D$5:$D$304,Config!$A$20,Orçamentos!$G$5:$G$304,"<>Aprovado",Orçamentos!$G$5:$G$304,"<>Recusado",Orçamentos!$G$5:$G$304,"<>Sem retorno",Orçamentos!$G$5:$G$304,"<>")) -> 400
A35: =IF(Config!$A$21="","",Config!$A$21) -> Pacote de consultas | B35: =IF(Config!$A$21="","",COUNTIFS(Orçamentos!$D$5:$D$304,Config!$A$21)) -> 2 | C35: =IF(Config!$A$21="","",COUNTIFS(Orçamentos!$D$5:$D$304,Config!$A$21,Orçamentos!$G$5:$G$304,"Aprovado")) -> 0 | D35: =IF(Config!$A$21="","",COUNTIFS(Orçamentos!$D$5:$D$304,Config!$A$21,Orçamentos!$G$5:$G$304,"Recusado")+COUNTIFS(Orçamentos!$D$5:$D$304,Config!$A$21,Orçamentos!$G$5:$G$304,"Sem retorno")) -> 2 | E35: =IF(Config!$A$21="","",IFERROR(C35/(C35+D35),0)) -> 0 | F35: =IF(Config!$A$21="","",SUMIFS(Orçamentos!$F$5:$F$304,Orçamentos!$D$5:$D$304,Config!$A$21,Orçamentos!$G$5:$G$304,"Aprovado")) -> 0 | G35: =IF(Config!$A$21="","",SUMIFS(Orçamentos!$F$5:$F$304,Orçamentos!$D$5:$D$304,Config!$A$21,Orçamentos!$G$5:$G$304,"<>Aprovado",Orçamentos!$G$5:$G$304,"<>Recusado",Orçamentos!$G$5:$G$304,"<>Sem retorno",Orçamentos!$G$5:$G$304,"<>")) -> 0
A36: =IF(Config!$A$22="","",Config!$A$22) | B36: =IF(Config!$A$22="","",COUNTIFS(Orçamentos!$D$5:$D$304,Config!$A$22)) | C36: =IF(Config!$A$22="","",COUNTIFS(Orçamentos!$D$5:$D$304,Config!$A$22,Orçamentos!$G$5:$G$304,"Aprovado")) | D36: =IF(Config!$A$22="","",COUNTIFS(Orçamentos!$D$5:$D$304,Config!$A$22,Orçamentos!$G$5:$G$304,"Recusado")+COUNTIFS(Orçamentos!$D$5:$D$304,Config!$A$22,Orçamentos!$G$5:$G$304,"Sem retorno")) | E36: =IF(Config!$A$22="","",IFERROR(C36/(C36+D36),0)) | F36: =IF(Config!$A$22="","",SUMIFS(Orçamentos!$F$5:$F$304,Orçamentos!$D$5:$D$304,Config!$A$22,Orçamentos!$G$5:$G$304,"Aprovado")) | G36: =IF(Config!$A$22="","",SUMIFS(Orçamentos!$F$5:$F$304,Orçamentos!$D$5:$D$304,Config!$A$22,Orçamentos!$G$5:$G$304,"<>Aprovado",Orçamentos!$G$5:$G$304,"<>Recusado",Orçamentos!$G$5:$G$304,"<>Sem retorno",Orçamentos!$G$5:$G$304,"<>"))
A37: =IF(Config!$A$23="","",Config!$A$23) | B37: =IF(Config!$A$23="","",COUNTIFS(Orçamentos!$D$5:$D$304,Config!$A$23)) | C37: =IF(Config!$A$23="","",COUNTIFS(Orçamentos!$D$5:$D$304,Config!$A$23,Orçamentos!$G$5:$G$304,"Aprovado")) | D37: =IF(Config!$A$23="","",COUNTIFS(Orçamentos!$D$5:$D$304,Config!$A$23,Orçamentos!$G$5:$G$304,"Recusado")+COUNTIFS(Orçamentos!$D$5:$D$304,Config!$A$23,Orçamentos!$G$5:$G$304,"Sem retorno")) | E37: =IF(Config!$A$23="","",IFERROR(C37/(C37+D37),0)) | F37: =IF(Config!$A$23="","",SUMIFS(Orçamentos!$F$5:$F$304,Orçamentos!$D$5:$D$304,Config!$A$23,Orçamentos!$G$5:$G$304,"Aprovado")) | G37: =IF(Config!$A$23="","",SUMIFS(Orçamentos!$F$5:$F$304,Orçamentos!$D$5:$D$304,Config!$A$23,Orçamentos!$G$5:$G$304,"<>Aprovado",Orçamentos!$G$5:$G$304,"<>Recusado",Orçamentos!$G$5:$G$304,"<>Sem retorno",Orçamentos!$G$5:$G$304,"<>"))
A38: =IF(Config!$A$24="","",Config!$A$24) | B38: =IF(Config!$A$24="","",COUNTIFS(Orçamentos!$D$5:$D$304,Config!$A$24)) | C38: =IF(Config!$A$24="","",COUNTIFS(Orçamentos!$D$5:$D$304,Config!$A$24,Orçamentos!$G$5:$G$304,"Aprovado")) | D38: =IF(Config!$A$24="","",COUNTIFS(Orçamentos!$D$5:$D$304,Config!$A$24,Orçamentos!$G$5:$G$304,"Recusado")+COUNTIFS(Orçamentos!$D$5:$D$304,Config!$A$24,Orçamentos!$G$5:$G$304,"Sem retorno")) | E38: =IF(Config!$A$24="","",IFERROR(C38/(C38+D38),0)) | F38: =IF(Config!$A$24="","",SUMIFS(Orçamentos!$F$5:$F$304,Orçamentos!$D$5:$D$304,Config!$A$24,Orçamentos!$G$5:$G$304,"Aprovado")) | G38: =IF(Config!$A$24="","",SUMIFS(Orçamentos!$F$5:$F$304,Orçamentos!$D$5:$D$304,Config!$A$24,Orçamentos!$G$5:$G$304,"<>Aprovado",Orçamentos!$G$5:$G$304,"<>Recusado",Orçamentos!$G$5:$G$304,"<>Sem retorno",Orçamentos!$G$5:$G$304,"<>"))
A39: =IF(Config!$A$25="","",Config!$A$25) | B39: =IF(Config!$A$25="","",COUNTIFS(Orçamentos!$D$5:$D$304,Config!$A$25)) | C39: =IF(Config!$A$25="","",COUNTIFS(Orçamentos!$D$5:$D$304,Config!$A$25,Orçamentos!$G$5:$G$304,"Aprovado")) | D39: =IF(Config!$A$25="","",COUNTIFS(Orçamentos!$D$5:$D$304,Config!$A$25,Orçamentos!$G$5:$G$304,"Recusado")+COUNTIFS(Orçamentos!$D$5:$D$304,Config!$A$25,Orçamentos!$G$5:$G$304,"Sem retorno")) | E39: =IF(Config!$A$25="","",IFERROR(C39/(C39+D39),0)) | F39: =IF(Config!$A$25="","",SUMIFS(Orçamentos!$F$5:$F$304,Orçamentos!$D$5:$D$304,Config!$A$25,Orçamentos!$G$5:$G$304,"Aprovado")) | G39: =IF(Config!$A$25="","",SUMIFS(Orçamentos!$F$5:$F$304,Orçamentos!$D$5:$D$304,Config!$A$25,Orçamentos!$G$5:$G$304,"<>Aprovado",Orçamentos!$G$5:$G$304,"<>Recusado",Orçamentos!$G$5:$G$304,"<>Sem retorno",Orçamentos!$G$5:$G$304,"<>"))
A40: =IF(Config!$A$26="","",Config!$A$26) | B40: =IF(Config!$A$26="","",COUNTIFS(Orçamentos!$D$5:$D$304,Config!$A$26)) | C40: =IF(Config!$A$26="","",COUNTIFS(Orçamentos!$D$5:$D$304,Config!$A$26,Orçamentos!$G$5:$G$304,"Aprovado")) | D40: =IF(Config!$A$26="","",COUNTIFS(Orçamentos!$D$5:$D$304,Config!$A$26,Orçamentos!$G$5:$G$304,"Recusado")+COUNTIFS(Orçamentos!$D$5:$D$304,Config!$A$26,Orçamentos!$G$5:$G$304,"Sem retorno")) | E40: =IF(Config!$A$26="","",IFERROR(C40/(C40+D40),0)) | F40: =IF(Config!$A$26="","",SUMIFS(Orçamentos!$F$5:$F$304,Orçamentos!$D$5:$D$304,Config!$A$26,Orçamentos!$G$5:$G$304,"Aprovado")) | G40: =IF(Config!$A$26="","",SUMIFS(Orçamentos!$F$5:$F$304,Orçamentos!$D$5:$D$304,Config!$A$26,Orçamentos!$G$5:$G$304,"<>Aprovado",Orçamentos!$G$5:$G$304,"<>Recusado",Orçamentos!$G$5:$G$304,"<>Sem retorno",Orçamentos!$G$5:$G$304,"<>"))
A41: =IF(Config!$A$27="","",Config!$A$27) | B41: =IF(Config!$A$27="","",COUNTIFS(Orçamentos!$D$5:$D$304,Config!$A$27)) | C41: =IF(Config!$A$27="","",COUNTIFS(Orçamentos!$D$5:$D$304,Config!$A$27,Orçamentos!$G$5:$G$304,"Aprovado")) | D41: =IF(Config!$A$27="","",COUNTIFS(Orçamentos!$D$5:$D$304,Config!$A$27,Orçamentos!$G$5:$G$304,"Recusado")+COUNTIFS(Orçamentos!$D$5:$D$304,Config!$A$27,Orçamentos!$G$5:$G$304,"Sem retorno")) | E41: =IF(Config!$A$27="","",IFERROR(C41/(C41+D41),0)) | F41: =IF(Config!$A$27="","",SUMIFS(Orçamentos!$F$5:$F$304,Orçamentos!$D$5:$D$304,Config!$A$27,Orçamentos!$G$5:$G$304,"Aprovado")) | G41: =IF(Config!$A$27="","",SUMIFS(Orçamentos!$F$5:$F$304,Orçamentos!$D$5:$D$304,Config!$A$27,Orçamentos!$G$5:$G$304,"<>Aprovado",Orçamentos!$G$5:$G$304,"<>Recusado",Orçamentos!$G$5:$G$304,"<>Sem retorno",Orçamentos!$G$5:$G$304,"<>"))
A43: Motivos de recusa
A44: Motivo | B44: Recusados | C44: Valor (R$) | D44: % dos recusados | F44: Profissional | G44: Orçamentos | H44: Aprovados | I44: Taxa de aprovação | J44: Valor aprovado (R$)
A45: =IF(Config!$C$18="","",Config!$C$18) -> Preço | B45: =IF(Config!$C$18="","",COUNTIFS(Orçamentos!$I$5:$I$304,Config!$C$18,Orçamentos!$G$5:$G$304,"Recusado")+COUNTIFS(Orçamentos!$I$5:$I$304,Config!$C$18,Orçamentos!$G$5:$G$304,"Sem retorno")) -> 2 | C45: =IF(Config!$C$18="","",SUMIFS(Orçamentos!$F$5:$F$304,Orçamentos!$I$5:$I$304,Config!$C$18,Orçamentos!$G$5:$G$304,"Recusado")+SUMIFS(Orçamentos!$F$5:$F$304,Orçamentos!$I$5:$I$304,Config!$C$18,Orçamentos!$G$5:$G$304,"Sem retorno")) -> 680 | D45: =IF(Config!$C$18="","",IFERROR(B45/($B$14+$B$15),0)) -> 0.25 | F45: =IF(Config!$E$18="","",Config!$E$18) -> Dra. Carolina Mendes | G45: =IF(Config!$E$18="","",COUNTIFS(Orçamentos!$C$5:$C$304,Config!$E$18)) -> 2 | H45: =IF(Config!$E$18="","",COUNTIFS(Orçamentos!$C$5:$C$304,Config!$E$18,Orçamentos!$G$5:$G$304,"Aprovado")) -> 0 | I45: =IF(Config!$E$18="","",IFERROR(H45/(H45+COUNTIFS(Orçamentos!$C$5:$C$304,Config!$E$18,Orçamentos!$G$5:$G$304,"Recusado")+COUNTIFS(Orçamentos!$C$5:$C$304,Config!$E$18,Orçamentos!$G$5:$G$304,"Sem retorno")),0)) -> 0 | J45: =IF(Config!$E$18="","",SUMIFS(Orçamentos!$F$5:$F$304,Orçamentos!$C$5:$C$304,Config!$E$18,Orçamentos!$G$5:$G$304,"Aprovado")) -> 0
A46: =IF(Config!$C$19="","",Config!$C$19) -> Vai fazer pelo convênio | B46: =IF(Config!$C$19="","",COUNTIFS(Orçamentos!$I$5:$I$304,Config!$C$19,Orçamentos!$G$5:$G$304,"Recusado")+COUNTIFS(Orçamentos!$I$5:$I$304,Config!$C$19,Orçamentos!$G$5:$G$304,"Sem retorno")) -> 1 | C46: =IF(Config!$C$19="","",SUMIFS(Orçamentos!$F$5:$F$304,Orçamentos!$I$5:$I$304,Config!$C$19,Orçamentos!$G$5:$G$304,"Recusado")+SUMIFS(Orçamentos!$F$5:$F$304,Orçamentos!$I$5:$I$304,Config!$C$19,Orçamentos!$G$5:$G$304,"Sem retorno")) -> 350 | D46: =IF(Config!$C$19="","",IFERROR(B46/($B$14+$B$15),0)) -> 0.125 | F46: =IF(Config!$E$19="","",Config!$E$19) -> Dr. Paulo Andrade | G46: =IF(Config!$E$19="","",COUNTIFS(Orçamentos!$C$5:$C$304,Config!$E$19)) -> 31 | H46: =IF(Config!$E$19="","",COUNTIFS(Orçamentos!$C$5:$C$304,Config!$E$19,Orçamentos!$G$5:$G$304,"Aprovado")) -> 21 | I46: =IF(Config!$E$19="","",IFERROR(H46/(H46+COUNTIFS(Orçamentos!$C$5:$C$304,Config!$E$19,Orçamentos!$G$5:$G$304,"Recusado")+COUNTIFS(Orçamentos!$C$5:$C$304,Config!$E$19,Orçamentos!$G$5:$G$304,"Sem retorno")),0)) -> 0.80769231 | J46: =IF(Config!$E$19="","",SUMIFS(Orçamentos!$F$5:$F$304,Orçamentos!$C$5:$C$304,Config!$E$19,Orçamentos!$G$5:$G$304,"Aprovado")) -> 8510
...

Sheet Config
A1: Configurações
A2: Células amarelas: você preenche. As probabilidades por etapa alimentam a previsão ponderada.
A4: Clínica | B4: Clínica Vida Plena (exemplo fictício)
A5: Data de referência (hoje) | B5: =TODAY() -> 46279
A6: Meta de orçamentos aprovados no trimestre (R$) | B6: 18000
A7: Orçamento parado há mais de (dias) | B7: 7
A9: Etapa | B9: Probabilidade de aprovar
A10: Apresentado | B10: 0.3
A11: Em análise | B11: 0.5
A12: Aprovado | B12: 1
A13: Recusado | B13: 0
A14: Sem retorno | B14: 0
A15: Etapas fixas: apresentado → em análise → aprovado, recusado ou sem retorno. Ajuste só as probabilidades, pela sua experiência.
A17: Tipos de orçamento | C17: Motivos de recusa | E17: Profissionais | G17: Itens mais comuns
A18: Check-up cardiológico | C18: Preço | E18: Dra. Carolina Mendes | G18: Consulta + ECG + teste ergométrico
A19: Exame cardiológico | C19: Vai fazer pelo convênio | E19: Dr. Paulo Andrade | G19: MAPA
A20: Avaliação endócrina | C20: Vai pensar / sem retorno | E20: Dra. Renata Sousa | G20: Holter
A21: Pacote de consultas | C21: Fez em outro lugar | G21: MAPA + Holter
C22: Sem indicação no momento | G22: Teste ergométrico
G23: Avaliação endócrina + retorno
G24: Consulta + 2 retornos (acompanhamento)
A29: Preencha cada lista de cima para baixo, sem pular linha: as listas suspensas de Orçamentos param na primeira célula vazia. Até 10 itens por lista. Itens é texto livre; a lista só sugere.
A30: Orçamento aqui é o valor apresentado ao paciente para exames e pacotes particulares (nome administrativo; sem indicação clínica). Aprovado vira horário na agenda (01).

Sheet Orçamentos
A1: Orçamentos
A2: Uma linha por orçamento apresentado. Atualize a etapa conforme a resposta; ao decidir, marque Aprovado, Recusado ou Sem retorno, a data e, se recusado, o motivo.
A4: Data | B4: Paciente | C4: Profissional | D4: Tipo | E4: Itens | F4: Valor (R$) | G4: Etapa | H4: Data da decisão | I4: Motivo (se recusado) | J4: Observação | K4: Probabilidade | L4: Valor ponderado | M4: Dias em aberto | N4: Dias até decidir | O4: Situação | P4: Mês
A5: 46206 | B5: Gustavo Ferreira | C5: Dr. Paulo Andrade | D5: Exame cardiológico | E5: Holter | F5: 350 | G5: Aprovado | H5: 46212 | J5: Agendado para 09/07 | K5: =IF(G5="","",IFERROR(INDEX(Config!$B$10:$B$14,MATCH(G5,Config!$A$10:$A$14,0)),0)) -> 1 | L5: =IF(OR(G5="",F5=""),"",F5*K5) -> 350 | M5: =IF(OR(G5="",G5="Aprovado",G5="Recusado",G5="Sem retorno",A5=""),"",Config!$B$5-A5) | N5: =IF(AND(OR(G5="Aprovado",G5="Recusado"),H5<>"",A5<>""),H5-A5,"") -> 6 | O5: =IF(G5="","",IF(OR(G5="Aprovado",G5="Recusado",G5="Sem retorno"),G5,IF(AND(M5<>"",M5>Config!$B$7),"Parado","Ativo"))) -> Aprovado | P5: =IF(A5="","",DATE(YEAR(A5),MONTH(A5),1)) -> 46204 | Q5: =IF(OR(G5="",O5="Aprovado",O5="Recusado",O5="Sem retorno"),0,IF(O5="Parado",2000,1000)+MIN(N(M5),500)+N(F5)/1000000-ROW()/100000) -> 0
A6: =TODAY()-70 -> 46209 | B6: Ana Costa | C6: Dr. Paulo Andrade | D6: Exame cardiológico | E6: MAPA | F6: 300 | G6: Recusado | H6: =TODAY()-61 -> 46218 | I6: Preço | K6: =IF(G6="","",IFERROR(INDEX(Config!$B$10:$B$14,MATCH(G6,Config!$A$10:$A$14,0)),0)) -> 0 | L6: =IF(OR(G6="",F6=""),"",F6*K6) -> 0 | M6: =IF(OR(G6="",G6="Aprovado",G6="Recusado",G6="Sem retorno",A6=""),"",Config!$B$5-A6) | N6: =IF(AND(OR(G6="Aprovado",G6="Recusado"),H6<>"",A6<>""),H6-A6,"") -> 9 | O6: =IF(G6="","",IF(OR(G6="Aprovado",G6="Recusado",G6="Sem retorno"),G6,IF(AND(M6<>"",M6>Config!$B$7),"Parado","Ativo"))) -> Recusado | P6: =IF(A6="","",DATE(YEAR(A6),MONTH(A6),1)) -> 46204 | Q6: =IF(OR(G6="",O6="Aprovado",O6="Recusado",O6="Sem retorno"),0,IF(O6="Parado",2000,1000)+MIN(N(M6),500)+N(F6)/1000000-ROW()/100000) -> 0
A7: 46213 | B7: Lucas Lopes | C7: Dr. Paulo Andrade | D7: Exame cardiológico | E7: Teste ergométrico | F7: 450 | G7: Aprovado | H7: 46226 | J7: Agendado para 24/07 | K7: =IF(G7="","",IFERROR(INDEX(Config!$B$10:$B$14,MATCH(G7,Config!$A$10:$A$14,0)),0)) -> 1 | L7: =IF(OR(G7="",F7=""),"",F7*K7) -> 450 | M7: =IF(OR(G7="",G7="Aprovado",G7="Recusado",G7="Sem retorno",A7=""),"",Config!$B$5-A7) | N7: =IF(AND(OR(G7="Aprovado",G7="Recusado"),H7<>"",A7<>""),H7-A7,"") -> 13 | O7: =IF(G7="","",IF(OR(G7="Aprovado",G7="Recusado",G7="Sem retorno"),G7,IF(AND(M7<>"",M7>Config!$B$7),"Parado","Ativo"))) -> Aprovado | P7: =IF(A7="","",DATE(YEAR(A7),MONTH(A7),1)) -> 46204 | Q7: =IF(OR(G7="",O7="Aprovado",O7="Recusado",O7="Sem retorno"),0,IF(O7="Parado",2000,1000)+MIN(N(M7),500)+N(F7)/1000000-ROW()/100000) -> 0
A8: 46218 | B8: Eduardo Lima | C8: Dr. Paulo Andrade | D8: Exame cardiológico | E8: Teste ergométrico | F8: 450 | G8: Aprovado | H8: 46226 | J8: Agendado para 24/07 | K8: =IF(G8="","",IFERROR(INDEX(Config!$B$10:$B$14,MATCH(G8,Config!$A$10:$A$14,0)),0)) -> 1 | L8: =IF(OR(G8="",F8=""),"",F8*K8) -> 450 | M8: =IF(OR(G8="",G8="Aprovado",G8="Recusado",G8="Sem retorno",A8=""),"",Config!$B$5-A8) | N8: =IF(AND(OR(G8="Aprovado",G8="Recusado"),H8<>"",A8<>""),H8-A8,"") -> 8 | O8: =IF(G8="","",IF(OR(G8="Aprovado",G8="Recusado",G8="Sem retorno"),G8,IF(AND(M8<>"",M8>Config!$B$7),"Parado","Ativo"))) -> Aprovado | P8: =IF(A8="","",DATE(YEAR(A8),MONTH(A8),1)) -> 46204 | Q8: =IF(OR(G8="",O8="Aprovado",O8="Recusado",O8="Sem retorno"),0,IF(O8="Parado",2000,1000)+MIN(N(M8),500)+N(F8)/1000000-ROW()/100000) -> 0
A9: 46219 | B9: Débora Ramos | C9: Dr. Paulo Andrade | D9: Exame cardiológico | E9: Teste ergométrico | F9: 450 | G9: Aprovado | H9: 46223 | J9: Agendado para 20/07 | K9: =IF(G9="","",IFERROR(INDEX(Config!$B$10:$B$14,MATCH(G9,Config!$A$10:$A$14,0)),0)) -> 1 | L9: =IF(OR(G9="",F9=""),"",F9*K9) -> 450 | M9: =IF(OR(G9="",G9="Aprovado",G9="Recusado",G9="Sem retorno",A9=""),"",Config!$B$5-A9) | N9: =IF(AND(OR(G9="Aprovado",G9="Recusado"),H9<>"",A9<>""),H9-A9,"") -> 4 | O9: =IF(G9="","",IF(OR(G9="Aprovado",G9="Recusado",G9="Sem retorno"),G9,IF(AND(M9<>"",M9>Config!$B$7),"Parado","Ativo"))) -> Aprovado | P9: =IF(A9="","",DATE(YEAR(A9),MONTH(A9),1)) -> 46204 | Q9: =IF(OR(G9="",O9="Aprovado",O9="Recusado",O9="Sem retorno"),0,IF(O9="Parado",2000,1000)+MIN(N(M9),500)+N(F9)/1000000-ROW()/100000) -> 0
A10: 46220 | B10: Otávio Nascimento | C10: Dr. Paulo Andrade | D10: Exame cardiológico | E10: Holter | F10: 350 | G10: Aprovado | H10: 46227 | J10: Agendado para 28/07 | K10: =IF(G10="","",IFERROR(INDEX(Config!$B$10:$B$14,MATCH(G10,Config!$A$10:$A$14,0)),0)) -> 1 | L10: =IF(OR(G10="",F10=""),"",F10*K10) -> 350 | M10: =IF(OR(G10="",G10="Aprovado",G10="Recusado",G10="Sem retorno",A10=""),"",Config!$B$5-A10) | N10: =IF(AND(OR(G10="Aprovado",G10="Recusado"),H10<>"",A10<>""),H10-A10,"") -> 7 | O10: =IF(G10="","",IF(OR(G10="Aprovado",G10="Recusado",G10="Sem retorno"),G10,IF(AND(M10<>"",M10>Config!$B$7),"Parado","Ativo"))) -> Aprovado | P10: =IF(A10="","",DATE(YEAR(A10),MONTH(A10),1)) -> 46204 | Q10: =IF(OR(G10="",O10="Aprovado",O10="Recusado",O10="Sem retorno"),0,IF(O10="Parado",2000,1000)+MIN(N(M10),500)+N(F10)/1000000-ROW()/100000) -> 0
A11: =TODAY()-55 -> 46224 | B11: Carlos Freitas | C11: Dr. Paulo Andrade | D11: Exame cardiológico | E11: Holter | F11: 350 | G11: Recusado | H11: =TODAY()-46 -> 46233 | I11: Vai fazer pelo convênio | K11: =IF(G11="","",IFERROR(INDEX(Config!$B$10:$B$14,MATCH(G11,Config!$A$10:$A$14,0)),0)) -> 0 | L11: =IF(OR(G11="",F11=""),"",F11*K11) -> 0 | M11: =IF(OR(G11="",G11="Aprovado",G11="Recusado",G11="Sem retorno",A11=""),"",Config!$B$5-A11) | N11: =IF(AND(OR(G11="Aprovado",G11="Recusado"),H11<>"",A11<>""),H11-A11,"") -> 9 | O11: =IF(G11="","",IF(OR(G11="Aprovado",G11="Recusado",G11="Sem retorno"),G11,IF(AND(M11<>"",M11>Config!$B$7),"Parado","Ativo"))) -> Recusado | P11: =IF(A11="","",DATE(YEAR(A11),MONTH(A11),1)) -> 46204 | Q11: =IF(OR(G11="",O11="Aprovado",O11="Recusado",O11="Sem retorno"),0,IF(O11="Parado",2000,1000)+MIN(N(M11),500)+N(F11)/1000000-ROW()/100000) -> 0
A12: 46230 | B12: Wagner Santos | C12: Dr. Paulo Andrade | D12: Exame cardiológico | E12: MAPA | F12: 300 | G12: Aprovado | H12: 46234 | J12: Agendado para 03/08 | K12: =IF(G12="","",IFERROR(INDEX(Config!$B$10:$B$14,MATCH(G12,Config!$A$10:$A$14,0)),0)) -> 1 | L12: =IF(OR(G12="",F12=""),"",F12*K12) -> 300 | M12: =IF(OR(G12="",G12="Aprovado",G12="Recusado",G12="Sem retorno",A12=""),"",Config!$B$5-A12) | N12: =IF(AND(OR(G12="Aprovado",G12="Recusado"),H12<>"",A12<>""),H12-A12,"") -> 4 | O12: =IF(G12="","",IF(OR(G12="Aprovado",G12="Recusado",G12="Sem retorno"),G12,IF(AND(M12<>"",M12>Config!$B$7),"Parado","Ativo"))) -> Aprovado | P12: =IF(A12="","",DATE(YEAR(A12),MONTH(A12),1)) -> 46204 | Q12: =IF(OR(G12="",O12="Aprovado",O12="Recusado",O12="Sem retorno"),0,IF(O12="Parado",2000,1000)+MIN(N(M12),500)+N(F12)/1000000-ROW()/100000) -> 0
A13: 46232 | B13: Marcelo Moreira | C13: Dr. Paulo Andrade | D13: Exame cardiológico | E13: Holter | F13: 350 | G13: Aprovado | H13: 46241 | J13: Agendado para 10/08 | K13: =IF(G13="","",IFERROR(INDEX(Config!$B$10:$B$14,MATCH(G13,Config!$A$10:$A$14,0)),0)) -> 1 | L13: =IF(OR(G13="",F13=""),"",F13*K13) -> 350 | M13: =IF(OR(G13="",G13="Aprovado",G13="Recusado",G13="Sem retorno",A13=""),"",Config!$B$5-A13) | N13: =IF(AND(OR(G13="Aprovado",G13="Recusado"),H13<>"",A13<>""),H13-A13,"") -> 9 | O13: =IF(G13="","",IF(OR(G13="Aprovado",G13="Recusado",G13="Sem retorno"),G13,IF(AND(M13<>"",M13>Config!$B$7),"Parado","Ativo"))) -> Aprovado | P13: =IF(A13="","",DATE(YEAR(A13),MONTH(A13),1)) -> 46204 | Q13: =IF(OR(G13="",O13="Aprovado",O13="Recusado",O13="Sem retorno"),0,IF(O13="Parado",2000,1000)+MIN(N(M13),500)+N(F13)/1000000-ROW()/100000) -> 0
A14: 46233 | B14: Otávio Cardoso | C14: Dr. Paulo Andrade | D14: Exame cardiológico | E14: Teste ergométrico | F14: 450 | G14: Aprovado | H14: 46238 | J14: Agendado para 06/08 | K14: =IF(G14="","",IFERROR(INDEX(Config!$B$10:$B$14,MATCH(G14,Config!$A$10:$A$14,0)),0)) -> 1 | L14: =IF(OR(G14="",F14=""),"",F14*K14) -> 450 | M14: =IF(OR(G14="",G14="Aprovado",G14="Recusado",G14="Sem retorno",A14=""),"",Config!$B$5-A14) | N14: =IF(AND(OR(G14="Aprovado",G14="Recusado"),H14<>"",A14<>""),H14-A14,"") -> 5 | O14: =IF(G14="","",IF(OR(G14="Aprovado",G14="Recusado",G14="Sem retorno"),G14,IF(AND(M14<>"",M14>Config!$B$7),"Parado","Ativo"))) -> Aprovado | P14: =IF(A14="","",DATE(YEAR(A14),MONTH(A14),1)) -> 46204 | Q14: =IF(OR(G14="",O14="Aprovado",O14="Recusado",O14="Sem retorno"),0,IF(O14="Parado",2000,1000)+MIN(N(M14),500)+N(F14)/1000000-ROW()/100000) -> 0
A15: 46234 | B15: Regina Duarte | C15: Dr. Paulo Andrade | D15: Exame cardiológico | E15: Teste ergométrico | F15: 450 | G15: Aprovado | H15: 46241 | J15: Agendado para 11/08 | K15: =IF(G15="","",IFERROR(INDEX(Config!$B$10:$B$14,MATCH(G15,Config!$A$10:$A$14,0)),0)) -> 1 | L15: =IF(OR(G15="",F15=""),"",F15*K15) -> 450 | M15: =IF(OR(G15="",G15="Aprovado",G15="Recusado",G15="Sem retorno",A15=""),"",Config!$B$5-A15) | N15: =IF(AND(OR(G15="Aprovado",G15="Recusado"),H15<>"",A15<>""),H15-A15,"") -> 7 | O15: =IF(G15="","",IF(OR(G15="Aprovado",G15="Recusado",G15="Sem retorno"),G15,IF(AND(M15<>"",M15>Config!$B$7),"Parado","Ativo"))) -> Aprovado | P15: =IF(A15="","",DATE(YEAR(A15),MONTH(A15),1)) -> 46204 | Q15: =IF(OR(G15="",O15="Aprovado",O15="Recusado",O15="Sem retorno"),0,IF(O15="Parado",2000,1000)+MIN(N(M15),500)+N(F15)/1000000-ROW()/100000) -> 0
A16: 46234 | B16: Regina Teixeira | C16: Dr. Paulo Andrade | D16: Check-up cardiológico | E16: Consulta + ECG + teste ergométrico | F16: 960 | G16: Aprovado | H16: 46251 | J16: Agendado para 20/08 | K16: =IF(G16="","",IFERROR(INDEX(Config!$B$10:$B$14,MATCH(G16,Config!$A$10:$A$14,0)),0)) -> 1 | L16: =IF(OR(G16="",F16=""),"",F16*K16) -> 960 | M16: =IF(OR(G16="",G16="Aprovado",G16="Recusado",G16="Sem retorno",A16=""),"",Config!$B$5-A16) | N16: =IF(AND(OR(G16="Aprovado",G16="Recusado"),H16<>"",A16<>""),H16-A16,"") -> 17 | O16: =IF(G16="","",IF(OR(G16="Aprovado",G16="Recusado",G16="Sem retorno"),G16,IF(AND(M16<>"",M16>Config!$B$7),"Parado","Ativo"))) -> Aprovado | P16: =IF(A16="","",DATE(YEAR(A16),MONTH(A16),1)) -> 46204 | Q16: =IF(OR(G16="",O16="Aprovado",O16="Recusado",O16="Sem retorno"),0,IF(O16="Parado",2000,1000)+MIN(N(M16),500)+N(F16)/1000000-ROW()/100000) -> 0
A17: =TODAY()-45 -> 46234 | B17: Cláudia Costa | C17: Dra. Carolina Mendes | D17: Pacote de consultas | E17: Consulta + 2 retornos (acompanhamento) | F17: 380 | G17: Recusado | H17: =TODAY()-42 -> 46237 | I17: Sem indicação no momento | K17: =IF(G17="","",IFERROR(INDEX(Config!$B$10:$B$14,MATCH(G17,Config!$A$10:$A$14,0)),0)) -> 0 | L17: =IF(OR(G17="",F17=""),"",F17*K17) -> 0 | M17: =IF(OR(G17="",G17="Aprovado",G17="Recusado",G17="Sem retorno",A17=""),"",Config!$B$5-A17) | N17: =IF(AND(OR(G17="Aprovado",G17="Recusado"),H17<>"",A17<>""),H17-A17,"") -> 3 | O17: =IF(G17="","",IF(OR(G17="Aprovado",G17="Recusado",G17="Sem retorno"),G17,IF(AND(M17<>"",M17>Config!$B$7),"Parado","Ativo"))) -> Recusado | P17: =IF(A17="","",DATE(YEAR(A17),MONTH(A17),1)) -> 46204 | Q17: =IF(OR(G17="",O17="Aprovado",O17="Recusado",O17="Sem retorno"),0,IF(O17="Parado",2000,1000)+MIN(N(M17),500)+N(F17)/1000000-ROW()/100000) -> 0
A18: =TODAY()-40 -> 46239 | B18: Eduardo Lima | C18: Dr. Paulo Andrade | D18: Check-up cardiológico | E18: Consulta + ECG + teste ergométrico | F18: 960 | G18: Sem retorno | H18: =TODAY()-37 -> 46242 | I18: Vai pensar / sem retorno | K18: =IF(G18="","",IFERROR(INDEX(Config!$B$10:$B$14,MATCH(G18,Config!$A$10:$A$14,0)),0)) -> 0 | L18: =IF(OR(G18="",F18=""),"",F18*K18) -> 0 | M18: =IF(OR(G18="",G18="Aprovado",G18="Recusado",G18="Sem retorno",A18=""),"",Config!$B$5-A18) | N18: =IF(AND(OR(G18="Aprovado",G18="Recusado"),H18<>"",A18<>""),H18-A18,"") | O18: =IF(G18="","",IF(OR(G18="Aprovado",G18="Recusado",G18="Sem retorno"),G18,IF(AND(M18<>"",M18>Config!$B$7),"Parado","Ativo"))) -> Sem retorno | P18: =IF(A18="","",DATE(YEAR(A18),MONTH(A18),1)) -> 46235 | Q18: =IF(OR(G18="",O18="Aprovado",O18="Recusado",O18="Sem retorno"),0,IF(O18="Parado",2000,1000)+MIN(N(M18),500)+N(F18)/1000000-ROW()/100000) -> 0
A19: 46241 | B19: Paulo Reis | C19: Dr. Paulo Andrade | D19: Exame cardiológico | E19: Holter | F19: 350 | G19: Aprovado | H19: 46259 | J19: Agendado para 25/08 | K19: =IF(G19="","",IFERROR(INDEX(Config!$B$10:$B$14,MATCH(G19,Config!$A$10:$A$14,0)),0)) -> 1 | L19: =IF(OR(G19="",F19=""),"",F19*K19) -> 350 | M19: =IF(OR(G19="",G19="Aprovado",G19="Recusado",G19="Sem retorno",A19=""),"",Config!$B$5-A19) | N19: =IF(AND(OR(G19="Aprovado",G19="Recusado"),H19<>"",A19<>""),H19-A19,"") -> 18 | O19: =IF(G19="","",IF(OR(G19="Aprovado",G19="Recusado",G19="Sem retorno"),G19,IF(AND(M19<>"",M19>Config!$B$7),"Parado","Ativo"))) -> Aprovado | P19: =IF(A19="","",DATE(YEAR(A19),MONTH(A19),1)) -> 46235 | Q19: =IF(OR(G19="",O19="Aprovado",O19="Recusado",O19="Sem retorno"),0,IF(O19="Parado",2000,1000)+MIN(N(M19),500)+N(F19)/1000000-ROW()/100000) -> 0
A20: 46245 | B20: Viviane Ribeiro | C20: Dr. Paulo Andrade | D20: Exame cardiológico | E20: Teste ergométrico | F20: 450 | G20: Aprovado | H20: 46251 | J20: Agendado para 20/08 | K20: =IF(G20="","",IFERROR(INDEX(Config!$B$10:$B$14,MATCH(G20,Config!$A$10:$A$14,0)),0)) -> 1 | L20: =IF(OR(G20="",F20=""),"",F20*K20) -> 450 | M20: =IF(OR(G20="",G20="Aprovado",G20="Recusado",G20="Sem retorno",A20=""),"",Config!$B$5-A20) | N20: =IF(AND(OR(G20="Aprovado",G20="Recusado"),H20<>"",A20<>""),H20-A20,"") -> 6 | O20: =IF(G20="","",IF(OR(G20="Aprovado",G20="Recusado",G20="Sem retorno"),G20,IF(AND(M20<>"",M20>Config!$B$7),"Parado","Ativo"))) -> Aprovado | P20: =IF(A20="","",DATE(YEAR(A20),MONTH(A20),1)) -> 46235 | Q20: =IF(OR(G20="",O20="Aprovado",O20="Recusado",O20="Sem retorno"),0,IF(O20="Parado",2000,1000)+MIN(N(M20),500)+N(F20)/1000000-ROW()/100000) -> 0
A21: =TODAY()-32 -> 46247 | B21: Fábio Machado | C21: Dr. Paulo Andrade | D21: Exame cardiológico | E21: Teste ergométrico | F21: 450 | G21: Recusado | H21: =TODAY()-25 -> 46254 | I21: Fez em outro lugar | K21: =IF(G21="","",IFERROR(INDEX(Config!$B$10:$B$14,MATCH(G21,Config!$A$10:$A$14,0)),0)) -> 0 | L21: =IF(OR(G21="",F21=""),"",F21*K21) -> 0 | M21: =IF(OR(G21="",G21="Aprovado",G21="Recusado",G21="Sem retorno",A21=""),"",Config!$B$5-A21) | N21: =IF(AND(OR(G21="Aprovado",G21="Recusado"),H21<>"",A21<>""),H21-A21,"") -> 7 | O21: =IF(G21="","",IF(OR(G21="Aprovado",G21="Recusado",G21="Sem retorno"),G21,IF(AND(M21<>"",M21>Config!$B$7),"Parado","Ativo"))) -> Recusado | P21: =IF(A21="","",DATE(YEAR(A21),MONTH(A21),1)) -> 46235 | Q21: =IF(OR(G21="",O21="Aprovado",O21="Recusado",O21="Sem retorno"),0,IF(O21="Parado",2000,1000)+MIN(N(M21),500)+N(F21)/1000000-ROW()/100000) -> 0
A22: 46248 | B22: Renato Dias | C22: Dr. Paulo Andrade | D22: Exame cardiológico | E22: Holter | F22: 350 | G22: Aprovado | H22: 46261 | J22: Agendado para 27/08 | K22: =IF(G22="","",IFERROR(INDEX(Config!$B$10:$B$14,MATCH(G22,Config!$A$10:$A$14,0)),0)) -> 1 | L22: =IF(OR(G22="",F22=""),"",F22*K22) -> 350 | M22: =IF(OR(G22="",G22="Aprovado",G22="Recusado",G22="Sem retorno",A22=""),"",Config!$B$5-A22) | N22: =IF(AND(OR(G22="Aprovado",G22="Recusado"),H22<>"",A22<>""),H22-A22,"") -> 13 | O22: =IF(G22="","",IF(OR(G22="Aprovado",G22="Recusado",G22="Sem retorno"),G22,IF(AND(M22<>"",M22>Config!$B$7),"Parado","Ativo"))) -> Aprovado | P22: =IF(A22="","",DATE(YEAR(A22),MONTH(A22),1)) -> 46235 | Q22: =IF(OR(G22="",O22="Aprovado",O22="Recusado",O22="Sem retorno"),0,IF(O22="Parado",2000,1000)+MIN(N(M22),500)+N(F22)/1000000-ROW()/100000) -> 0
A23: 46251 | B23: Fernanda Freitas | C23: Dr. Paulo Andrade | D23: Exame cardiológico | E23: Teste ergométrico | F23: 450 | G23: Aprovado | H23: 46269 | J23: Agendado para 04/09 | K23: =IF(G23="","",IFERROR(INDEX(Config!$B$10:$B$14,MATCH(G23,Config!$A$10:$A$14,0)),0)) -> 1 | L23: =IF(OR(G23="",F23=""),"",F23*K23) -> 450 | M23: =IF(OR(G23="",G23="Aprovado",G23="Recusado",G23="Sem retorno",A23=""),"",Config!$B$5-A23) | N23: =IF(AND(OR(G23="Aprovado",G23="Recusado"),H23<>"",A23<>""),H23-A23,"") -> 18 | O23: =IF(G23="","",IF(OR(G23="Aprovado",G23="Recusado",G23="Sem retorno"),G23,IF(AND(M23<>"",M23>Config!$B$7),"Parado","Ativo"))) -> Aprovado | P23: =IF(A23="","",DATE(YEAR(A23),MONTH(A23),1)) -> 46235 | Q23: =IF(OR(G23="",O23="Aprovado",O23="Recusado",O23="Sem retorno"),0,IF(O23="Parado",2000,1000)+MIN(N(M23),500)+N(F23)/1000000-ROW()/100000) -> 0
A24: =TODAY()-26 -> 46253 | B24: Beatriz Gomes | C24: Dra. Renata Sousa | D24: Avaliação endócrina | E24: Avaliação endócrina + retorno | F24: 400 | G24: Sem retorno | H24: =TODAY()-22 -> 46257 | I24: Vai pensar / sem retorno | K24: =IF(G24="","",IFERROR(INDEX(Config!$B$10:$B$14,MATCH(G24,Config!$A$10:$A$14,0)),0)) -> 0 | L24: =IF(OR(G24="",F24=""),"",F24*K24) -> 0 | M24: =IF(OR(G24="",G24="Aprovado",G24="Recusado",G24="Sem retorno",A24=""),"",Config!$B$5-A24) | N24: =IF(AND(OR(G24="Aprovado",G24="Recusado"),H24<>"",A24<>""),H24-A24,"") | O24: =IF(G24="","",IF(OR(G24="Aprovado",G24="Recusado",G24="Sem retorno"),G24,IF(AND(M24<>"",M24>Config!$B$7),"Parado","Ativo"))) -> Sem retorno | P24: =IF(A24="","",DATE(YEAR(A24),MONTH(A24),1)) -> 46235 | Q24: =IF(OR(G24="",O24="Aprovado",O24="Recusado",O24="Sem retorno"),0,IF(O24="Parado",2000,1000)+MIN(N(M24),500)+N(F24)/1000000-ROW()/100000) -> 0
A25: 46254 | B25: Roberta Araújo | C25: Dr. Paulo Andrade | D25: Exame cardiológico | E25: Holter | F25: 350 | G25: Aprovado | H25: 46255 | J25: Agendado para 25/08 | K25: =IF(G25="","",IFERROR(INDEX(Config!$B$10:$B$14,MATCH(G25,Config!$A$10:$A$14,0)),0)) -> 1 | L25: =IF(OR(G25="",F25=""),"",F25*K25) -> 350 | M25: =IF(OR(G25="",G25="Aprovado",G25="Recusado",G25="Sem retorno",A25=""),"",Config!$B$5-A25) | N25: =IF(AND(OR(G25="Aprovado",G25="Recusado"),H25<>"",A25<>""),H25-A25,"") -> 1 | O25: =IF(G25="","",IF(OR(G25="Aprovado",G25="Recusado",G25="Sem retorno"),G25,IF(AND(M25<>"",M25>Config!$B$7),"Parado","Ativo"))) -> Aprovado | P25: =IF(A25="","",DATE(YEAR(A25),MONTH(A25),1)) -> 46235 | Q25: =IF(OR(G25="",O25="Aprovado",O25="Recusado",O25="Sem retorno"),0,IF(O25="Parado",2000,1000)+MIN(N(M25),500)+N(F25)/1000000-ROW()/100000) -> 0
A26: 46255 | B26: Eduardo Lima | C26: Dr. Paulo Andrade | D26: Exame cardiológico | E26: MAPA | F26: 300 | G26: Aprovado | H26: 46273 | J26: Agendado para 10/09 | K26: =IF(G26="","",IFERROR(INDEX(Config!$B$10:$B$14,MATCH(G26,Config!$A$10:$A$14,0)),0)) -> 1 | L26: =IF(OR(G26="",F26=""),"",F26*K26) -> 300 | M26: =IF(OR(G26="",G26="Aprovado",G26="Recusado",G26="Sem retorno",A26=""),"",Config!$B$5-A26) | N26: =IF(AND(OR(G26="Aprovado",G26="Recusado"),H26<>"",A26<>""),H26-A26,"") -> 18 | O26: =IF(G26="","",IF(OR(G26="Aprovado",G26="Recusado",G26="Sem retorno"),G26,IF(AND(M26<>"",M26>Config!$B$7),"Parado","Ativo"))) -> Aprovado | P26: =IF(A26="","",DATE(YEAR(A26),MONTH(A26),1)) -> 46235 | Q26: =IF(OR(G26="",O26="Aprovado",O26="Recusado",O26="Sem retorno"),0,IF(O26="Parado",2000,1000)+MIN(N(M26),500)+N(F26)/1000000-ROW()/100000) -> 0
A27: 46259 | B27: Rafael Dias | C27: Dr. Paulo Andrade | D27: Exame cardiológico | E27: MAPA | F27: 300 | G27: Aprovado | H27: 46269 | J27: Agendado para 04/09 | K27: =IF(G27="","",IFERROR(INDEX(Config!$B$10:$B$14,MATCH(G27,Config!$A$10:$A$14,0)),0)) -> 1 | L27: =IF(OR(G27="",F27=""),"",F27*K27) -> 300 | M27: =IF(OR(G27="",G27="Aprovado",G27="Recusado",G27="Sem retorno",A27=""),"",Config!$B$5-A27) | N27: =IF(AND(OR(G27="Aprovado",G27="Recusado"),H27<>"",A27<>""),H27-A27,"") -> 10 | O27: =IF(G27="","",IF(OR(G27="Aprovado",G27="Recusado",G27="Sem retorno"),G27,IF(AND(M27<>"",M27>Config!$B$7),"Parado","Ativo"))) -> Aprovado | P27: =IF(A27="","",DATE(YEAR(A27),MONTH(A27),1)) -> 46235 | Q27: =IF(OR(G27="",O27="Aprovado",O27="Recusado",O27="Sem retorno"),0,IF(O27="Parado",2000,1000)+MIN(N(M27),500)+N(F27)/1000000-ROW()/100000) -> 0
A28: =TODAY()-20 -> 46259 | B28: Carlos Fernandes | C28: Dra. Carolina Mendes | D28: Pacote de consultas | E28: Consulta + 2 retornos (acompanhamento) | F28: 380 | G28: Recusado | H28: =TODAY()-13 -> 46266 | I28: Preço | K28: =IF(G28="","",IFERROR(INDEX(Config!$B$10:$B$14,MATCH(G28,Config!$A$10:$A$14,0)),0)) -> 0 | L28: =IF(OR(G28="",F28=""),"",F28*K28) -> 0 | M28: =IF(OR(G28="",G28="Aprovado",G28="Recusado",G28="Sem retorno",A28=""),"",Config!$B$5-A28) | N28: =IF(AND(OR(G28="Aprovado",G28="Recusado"),H28<>"",A28<>""),H28-A28,"") -> 7 | O28: =IF(G28="","",IF(OR(G28="Aprovado",G28="Recusado",G28="Sem retorno"),G28,IF(AND(M28<>"",M28>Config!$B$7),"Parado","Ativo"))) -> Recusado | P28: =IF(A28="","",DATE(YEAR(A28),MONTH(A28),1)) -> 46235 | Q28: =IF(OR(G28="",O28="Aprovado",O28="Recusado",O28="Sem retorno"),0,IF(O28="Parado",2000,1000)+MIN(N(M28),500)+N(F28)/1000000-ROW()/100000) -> 0
A29: =TODAY()-16 -> 46263 | B29: Patrícia Dias | C29: Dr. Paulo Andrade | D29: Exame cardiológico | E29: MAPA | F29: 300 | G29: Sem retorno | H29: =TODAY()-12 -> 46267 | I29: Vai pensar / sem retorno | K29: =IF(G29="","",IFERROR(INDEX(Config!$B$10:$B$14,MATCH(G29,Config!$A$10:$A$14,0)),0)) -> 0 | L29: =IF(OR(G29="",F29=""),"",F29*K29) -> 0 | M29: =IF(OR(G29="",G29="Aprovado",G29="Recusado",G29="Sem retorno",A29=""),"",Config!$B$5-A29) | N29: =IF(AND(OR(G29="Aprovado",G29="Recusado"),H29<>"",A29<>""),H29-A29,"") | O29: =IF(G29="","",IF(OR(G29="Aprovado",G29="Recusado",G29="Sem retorno"),G29,IF(AND(M29<>"",M29>Config!$B$7),"Parado","Ativo"))) -> Sem retorno | P29: =IF(A29="","",DATE(YEAR(A29),MONTH(A29),1)) -> 46235 | Q29: =IF(OR(G29="",O29="Aprovado",O29="Recusado",O29="Sem retorno"),0,IF(O29="Parado",2000,1000)+MIN(N(M29),500)+N(F29)/1000000-ROW()/100000) -> 0
A30: =TODAY()-12 -> 46267 | B30: Mariana Reis | C30: Dr. Paulo Andrade | D30: Exame cardiológico | E30: MAPA + Holter | F30: 650 | G30: Em análise | K30: =IF(G30="","",IFERROR(INDEX(Config!$B$10:$B$14,MATCH(G30,Config!$A$10:$A$14,0)),0)) -> 0.5 | L30: =IF(OR(G30="",F30=""),"",F30*K30) -> 325 | M30: =IF(OR(G30="",G30="Aprovado",G30="Recusado",G30="Sem retorno",A30=""),"",Config!$B$5-A30) -> 12 | N30: =IF(AND(OR(G30="Aprovado",G30="Recusado"),H30<>"",A30<>""),H30-A30,"") | O30: =IF(G30="","",IF(OR(G30="Aprovado",G30="Recusado",G30="Sem retorno"),G30,IF(AND(M30<>"",M30>Config!$B$7),"Parado","Ativo"))) -> Parado | P30: =IF(A30="","",DATE(YEAR(A30),MONTH(A30),1)) -> 46266 | Q30: =IF(OR(G30="",O30="Aprovado",O30="Recusado",O30="Sem retorno"),0,IF(O30="Parado",2000,1000)+MIN(N(M30),500)+N(F30)/1000000-ROW()/100000) -> 2012.0004
A31: =TODAY()-9 -> 46270 | B31: Beatriz Monteiro | C31: Dra. Renata Sousa | D31: Avaliação endócrina | E31: Avaliação endócrina + retorno | F31: 400 | G31: Em análise | K31: =IF(G31="","",IFERROR(INDEX(Config!$B$10:$B$14,MATCH(G31,Config!$A$10:$A$14,0)),0)) -> 0.5 | L31: =IF(OR(G31="",F31=""),"",F31*K31) -> 200 | M31: =IF(OR(G31="",G31="Aprovado",G31="Recusado",G31="Sem retorno",A31=""),"",Config!$B$5-A31) -> 9 | N31: =IF(AND(OR(G31="Aprovado",G31="Recusado"),H31<>"",A31<>""),H31-A31,"") | O31: =IF(G31="","",IF(OR(G31="Aprovado",G31="Recusado",G31="Sem retorno"),G31,IF(AND(M31<>"",M31>Config!$B$7),"Parado","Ativo"))) -> Parado | P31: =IF(A31="","",DATE(YEAR(A31),MONTH(A31),1)) -> 46266 | Q31: =IF(OR(G31="",O31="Aprovado",O31="Recusado",O31="Sem retorno"),0,IF(O31="Parado",2000,1000)+MIN(N(M31),500)+N(F31)/1000000-ROW()/100000) -> 2009.0001
A32: =TODAY()-6 -> 46273 | B32: Rafael Dias | C32: Dr. Paulo Andrade | D32: Exame cardiológico | E32: Holter | F32: 350 | G32: Em análise | K32: =IF(G32="","",IFERROR(INDEX(Config!$B$10:$B$14,MATCH(G32,Config!$A$10:$A$14,0)),0)) -> 0.5 | L32: =IF(OR(G32="",F32=""),"",F32*K32) -> 175 | M32: =IF(OR(G32="",G32="Aprovado",G32="Recusado",G32="Sem retorno",A32=""),"",Config!$B$5-A32) -> 6 | N32: =IF(AND(OR(G32="Aprovado",G32="Recusado"),H32<>"",A32<>""),H32-A32,"") | O32: =IF(G32="","",IF(OR(G32="Aprovado",G32="Recusado",G32="Sem retorno"),G32,IF(AND(M32<>"",M32>Config!$B$7),"Parado","Ativo"))) -> Ativo | P32: =IF(A32="","",DATE(YEAR(A32),MONTH(A32),1)) -> 46266 | Q32: =IF(OR(G32="",O32="Aprovado",O32="Recusado",O32="Sem retorno"),0,IF(O32="Parado",2000,1000)+MIN(N(M32),500)+N(F32)/1000000-ROW()/100000) -> 1006
A33: =TODAY()-3 -> 46276 | B33: Roberta Lima | C33: Dr. Paulo Andrade | D33: Check-up cardiológico | E33: Consulta + ECG + teste ergométrico | F33: 960 | G33: Apresentado | K33: =IF(G33="","",IFERROR(INDEX(Config!$B$10:$B$14,MATCH(G33,Config!$A$10:$A$14,0)),0)) -> 0.3 | L33: =IF(OR(G33="",F33=""),"",F33*K33) -> 288 | M33: =IF(OR(G33="",G33="Aprovado",G33="Recusado",G33="Sem retorno",A33=""),"",Config!$B$5-A33) -> 3 | N33: =IF(AND(OR(G33="Aprovado",G33="Recusado"),H33<>"",A33<>""),H33-A33,"") | O33: =IF(G33="","",IF(OR(G33="Aprovado",G33="Recusado",G33="Sem retorno"),G33,IF(AND(M33<>"",M33>Config!$B$7),"Parado","Ativo"))) -> Ativo | P33: =IF(A33="","",DATE(YEAR(A33),MONTH(A33),1)) -> 46266 | Q33: =IF(OR(G33="",O33="Aprovado",O33="Recusado",O33="Sem retorno"),0,IF(O33="Parado",2000,1000)+MIN(N(M33),500)+N(F33)/1000000-ROW()/100000) -> 1003.0006
A34: =TODAY()-1 -> 46278 | B34: Wagner Costa | C34: Dr. Paulo Andrade | D34: Exame cardiológico | E34: Teste ergométrico | F34: 450 | G34: Apresentado | K34: =IF(G34="","",IFERROR(INDEX(Config!$B$10:$B$14,MATCH(G34,Config!$A$10:$A$14,0)),0)) -> 0.3 | L34: =IF(OR(G34="",F34=""),"",F34*K34) -> 135 | M34: =IF(OR(G34="",G34="Aprovado",G34="Recusado",G34="Sem retorno",A34=""),"",Config!$B$5-A34) -> 1 | N34: =IF(AND(OR(G34="Aprovado",G34="Recusado"),H34<>"",A34<>""),H34-A34,"") | O34: =IF(G34="","",IF(OR(G34="Aprovado",G34="Recusado",G34="Sem retorno"),G34,IF(AND(M34<>"",M34>Config!$B$7),"Parado","Ativo"))) -> Ativo | P34: =IF(A34="","",DATE(YEAR(A34),MONTH(A34),1)) -> 46266 | Q34: =IF(OR(G34="",O34="Aprovado",O34="Recusado",O34="Sem retorno"),0,IF(O34="Parado",2000,1000)+MIN(N(M34),500)+N(F34)/1000000-ROW()/100000) -> 1001.0001
A35: =TODAY() -> 46279 | B35: Fábio Correia | C35: Dr. Paulo Andrade | D35: Exame cardiológico | E35: MAPA + Holter | F35: 650 | G35: Apresentado | K35: =IF(G35="","",IFERROR(INDEX(Config!$B$10:$B$14,MATCH(G35,Config!$A$10:$A$14,0)),0)) -> 0.3 | L35: =IF(OR(G35="",F35=""),"",F35*K35) -> 195 | M35: =IF(OR(G35="",G35="Aprovado",G35="Recusado",G35="Sem retorno",A35=""),"",Config!$B$5-A35) -> 0 | N35: =IF(AND(OR(G35="Aprovado",G35="Recusado"),H35<>"",A35<>""),H35-A35,"") | O35: =IF(G35="","",IF(OR(G35="Aprovado",G35="Recusado",G35="Sem retorno"),G35,IF(AND(M35<>"",M35>Config!$B$7),"Parado","Ativo"))) -> Ativo | P35: =IF(A35="","",DATE(YEAR(A35),MONTH(A35),1)) -> 46266 | Q35: =IF(OR(G35="",O35="Aprovado",O35="Recusado",O35="Sem retorno"),0,IF(O35="Parado",2000,1000)+MIN(N(M35),500)+N(F35)/1000000-ROW()/100000) -> 1000.0003
A36: 46280 | B36: Ana Costa | C36: Dr. Paulo Andrade | D36: Exame cardiológico | E36: Holter | F36: 350 | G36: Aprovado | H36: 46276 | J36: Agendado para 21/09 | K36: =IF(G36="","",IFERROR(INDEX(Config!$B$10:$B$14,MATCH(G36,Config!$A$10:$A$14,0)),0)) -> 1 | L36: =IF(OR(G36="",F36=""),"",F36*K36) -> 350 | M36: =IF(OR(G36="",G36="Aprovado",G36="Recusado",G36="Sem retorno",A36=""),"",Config!$B$5-A36) | N36: =IF(AND(OR(G36="Aprovado",G36="Recusado"),H36<>"",A36<>""),H36-A36,"") -> -4 | O36: =IF(G36="","",IF(OR(G36="Aprovado",G36="Recusado",G36="Sem retorno"),G36,IF(AND(M36<>"",M36>Config!$B$7),"Parado","Ativo"))) -> Aprovado | P36: =IF(A36="","",DATE(YEAR(A36),MONTH(A36),1)) -> 46266 | Q36: =IF(OR(G36="",O36="Aprovado",O36="Recusado",O36="Sem retorno"),0,IF(O36="Parado",2000,1000)+MIN(N(M36),500)+N(F36)/1000000-ROW()/100000) -> 0
A37: 46283 | B37: Viviane Ribeiro | C37: Dr. Paulo Andrade | D37: Exame cardiológico | E37: MAPA | F37: 300 | G37: Aprovado | H37: 46276 | J37: Agendado para 05/10 | K37: =IF(G37="","",IFERROR(INDEX(Config!$B$10:$B$14,MATCH(G37,Config!$A$10:$A$14,0)),0)) -> 1 | L37: =IF(OR(G37="",F37=""),"",F37*K37) -> 300 | M37: =IF(OR(G37="",G37="Aprovado",G37="Recusado",G37="Sem retorno",A37=""),"",Config!$B$5-A37) | N37: =IF(AND(OR(G37="Aprovado",G37="Recusado"),H37<>"",A37<>""),H37-A37,"") -> -7 | O37: =IF(G37="","",IF(OR(G37="Aprovado",G37="Recusado",G37="Sem retorno"),G37,IF(AND(M37<>"",M37>Config!$B$7),"Parado","Ativo"))) -> Aprovado | P37: =IF(A37="","",DATE(YEAR(A37),MONTH(A37),1)) -> 46266 | Q37: =IF(OR(G37="",O37="Aprovado",O37="Recusado",O37="Sem retorno"),0,IF(O37="Parado",2000,1000)+MIN(N(M37),500)+N(F37)/1000000-ROW()/100000) -> 0
A38: 46286 | B38: Wagner Costa | C38: Dr. Paulo Andrade | D38: Exame cardiológico | E38: MAPA | F38: 300 | G38: Aprovado | H38: 46276 | J38: Agendado para 01/10 | K38: =IF(G38="","",IFERROR(INDEX(Config!$B$10:$B$14,MATCH(G38,Config!$A$10:$A$14,0)),0)) -> 1 | L38: =IF(OR(G38="",F38=""),"",F38*K38) -> 300 | M38: =IF(OR(G38="",G38="Aprovado",G38="Recusado",G38="Sem retorno",A38=""),"",Config!$B$5-A38) | N38: =IF(AND(OR(G38="Aprovado",G38="Recusado"),H38<>"",A38<>""),H38-A38,"") -> -10 | O38: =IF(G38="","",IF(OR(G38="Aprovado",G38="Recusado",G38="Sem retorno"),G38,IF(AND(M38<>"",M38>Config!$B$7),"Parado","Ativo"))) -> Aprovado | P38: =IF(A38="","",DATE(YEAR(A38),MONTH(A38),1)) -> 46266 | Q38: =IF(OR(G38="",O38="Aprovado",O38="Recusado",O38="Sem retorno"),0,IF(O38="Parado",2000,1000)+MIN(N(M38),500)+N(F38)/1000000-ROW()/100000) -> 0
A39: 46295 | B39: Gisele Ribeiro | C39: Dr. Paulo Andrade | D39: Exame cardiológico | E39: Teste ergométrico | F39: 450 | G39: Aprovado | H39: 46276 | J39: Agendado para 05/10 | K39: =IF(G39="","",IFERROR(INDEX(Config!$B$10:$B$14,MATCH(G39,Config!$A$10:$A$14,0)),0)) -> 1 | L39: =IF(OR(G39="",F39=""),"",F39*K39) -> 450 | M39: =IF(OR(G39="",G39="Aprovado",G39="Recusado",G39="Sem retorno",A39=""),"",Config!$B$5-A39) | N39: =IF(AND(OR(G39="Aprovado",G39="Recusado"),H39<>"",A39<>""),H39-A39,"") -> -19 | O39: =IF(G39="","",IF(OR(G39="Aprovado",G39="Recusado",G39="Sem retorno"),G39,IF(AND(M39<>"",M39>Config!$B$7),"Parado","Ativo"))) -> Aprovado | P39: =IF(A39="","",DATE(YEAR(A39),MONTH(A39),1)) -> 46266 | Q39: =IF(OR(G39="",O39="Aprovado",O39="Recusado",O39="Sem retorno"),0,IF(O39="Parado",2000,1000)+MIN(N(M39),500)+N(F39)/1000000-ROW()/100000) -> 0
K40: =IF(G40="","",IFERROR(INDEX(Config!$B$10:$B$14,MATCH(G40,Config!$A$10:$A$14,0)),0)) | L40: =IF(OR(G40="",F40=""),"",F40*K40) | M40: =IF(OR(G40="",G40="Aprovado",G40="Recusado",G40="Sem retorno",A40=""),"",Config!$B$5-A40) | N40: =IF(AND(OR(G40="Aprovado",G40="Recusado"),H40<>"",A40<>""),H40-A40,"") | O40: =IF(G40="","",IF(OR(G40="Aprovado",G40="Recusado",G40="Sem retorno"),G40,IF(AND(M40<>"",M40>Config!$B$7),"Parado","Ativo"))) | P40: =IF(A40="","",DATE(YEAR(A40),MONTH(A40),1)) | Q40: =IF(OR(G40="",O40="Aprovado",O40="Recusado",O40="Sem retorno"),0,IF(O40="Parado",2000,1000)+MIN(N(M40),500)+N(F40)/1000000-ROW()/100000) -> 0
