Workbook

Sheet Como usar
A1: Conciliação de cartão e taxas
A2: Kit de Gestão para Médicos · Seu Sócio Gestor · versão 1.0 (setembro de 2026)
A4: O que esta planilha faz | B4: Cada pagamento no cartão ou no Pix com a taxa da operadora, o valor líquido e o dia em que cai na conta. Mostra quanto as taxas comem no mês (e a quantas consultas equivalem), o que ainda vai cair, o que já deveria ter caído e não foi conferido, e o dia a dia para bater com o extrato.
A5: Passo 1 | B5: Em Config, digite as taxas e os prazos da sua operadora (contrato da maquininha ou extrato), se antecipa o crédito e o preço da consulta particular (só para a comparação).
A6: Passo 2 | B6: Em Vendas, uma linha por pagamento: data, paciente, procedimento, tipo, parcelas e valor bruto (copie da Agenda da 01, filtrando os particulares pagos com Pix ou cartão). Toda sexta, marque Sim em "Conferido no extrato?" para o que caiu na conta.
A7: Passo 3 | B7: Em Painel, escolha o mês em Config: vendas, taxas, líquido, por tipo, dia a dia e a lista "Falta conferir". No fechamento do mês, lance o total de taxas como saída "Taxas de cartão" no caixa (09).
A8: Rotina | B8: Sexta-feira, 10 minutos: conferir o extrato da operadora contra "Cai na conta neste dia" e marcar as conferidas. Uma vez por semestre: comparar a taxa média com outra operadora.
A9: Ligação com as outras planilhas | B9: O caixa (09) registra o bruto no dia da venda; as taxas do mês são a saída do fim do mês (o total deste Painel). O resultado mensal (18) mostra as taxas como despesa variável. No exemplo o Painel está em agosto (mês fechado); setembro está em andamento.
A10: Com a IA | B10: Copie "Por tipo de pagamento" e use o prompt "Caixa 09 · A taxa da maquininha está comendo a margem?" da biblioteca do kit para decidir entre absorver a taxa, oferecer desconto no Pix ou trocar de operadora.
A11: Legenda | B11: Células amarelas: você preenche. Brancas: calculadas. Não é preciso mexer em nada fora do amarelo.
A12: Proteção | B12: Fórmulas protegidas sem senha. Para editar: Revisar > Desproteger planilha (Excel) ou Dados > Proteger intervalos (Google Sheets).
A13: Requisitos | B13: Excel 2016 ou mais novo, Microsoft 365 ou Google Sheets (só funções do Excel 2007+; nada de MÍNIMOSES, MÁXIMOSES ou UNIRTEXTO). No celular abre nos aplicativos; para preencher, use o computador.
A14: Dados de pacientes | B14: Guarde só o que a gestão precisa (nome, contato, valor, data). Nada de diagnóstico, prontuário ou exame nestas planilhas: o kit é gestão, não é prontuário. Veja o guia LGPD do kit antes de colar qualquer tabela em uma IA.
A15: Google Sheets | B15: Faça upload no Google Drive e abra com o Google Sheets. Fórmulas, listas, cores e gráficos funcionam.
... A17: Suporte | B17: suporte@seusociogestor.com.br · resposta em até 5 dias úteis · reembolso em até 7 dias pelo mesmo canal.

Sheet Painel
A1: =Config!$B$4&" · Conciliação de cartão e taxas · "&Config!$B$6&" de "&Config!$B$5 -> Clínica Vida Plena (exemplo fictício) · Conciliação de cartão e taxas · Agosto de 2026
A2: Nada para digitar aqui. Escolha o mês em Config; tudo vem de Vendas. Taxas por mês da venda; a receber por previsão na conta.
A4: Vendas no mês (bruto) | C4: Taxas no mês | E4: Taxa média | G4: Líquido no mês | I4: Ainda vai cair (todas as vendas) | K4: A conferir
A5: =SUMIFS(Vendas!$F$5:$F$604,Vendas!$L$5:$L$604,Config!$B$7,Vendas!$M$5:$M$604,Config!$B$5) -> 31820 | C5: =SUMIFS(Vendas!$I$5:$I$604,Vendas!$L$5:$L$604,Config!$B$7,Vendas!$M$5:$M$604,Config!$B$5) -> 484.12 | E5: =IF(A5=0,"",C5/A5) -> 0.015214331 | G5: =A5-C5 -> 31335.88 | I5: =SUMIFS(Vendas!$J$5:$J$604,Vendas!$N$5:$N$604,"A cair") -> 10898.71 | K5: =SUMIFS(Vendas!$J$5:$J$604,Vendas!$N$5:$N$604,"A conferir") -> 4047.84
A7: ="As taxas do mês equivalem a "&FIXED(IF(Config!$B$9=0,0,C5/Config!$B$9),1)&" consultas particulares. Lance este total no caixa (09) como saída 'Taxas de cartão' no fim do mês." -> As taxas do mês equivalem a 1.3 consultas particulares. Lance este total no caixa (09) como saída 'Taxas de cartão' no fim do mês.
A9: Por tipo de pagamento no mês
A10: Tipo | B10: Vendas | C10: Bruto (R$) | D10: Taxas (R$) | E10: Taxa média | F10: Líquido (R$) | G10: % do bruto | H10: Barra
A11: Pix | B11: =COUNTIFS(Vendas!$D$5:$D$604,"Pix",Vendas!$L$5:$L$604,Config!$B$7,Vendas!$M$5:$M$604,Config!$B$5) -> 37 | C11: =SUMIFS(Vendas!$F$5:$F$604,Vendas!$D$5:$D$604,"Pix",Vendas!$L$5:$L$604,Config!$B$7,Vendas!$M$5:$M$604,Config!$B$5) -> 13380 | D11: =SUMIFS(Vendas!$I$5:$I$604,Vendas!$D$5:$D$604,"Pix",Vendas!$L$5:$L$604,Config!$B$7,Vendas!$M$5:$M$604,Config!$B$5) -> 0 | E11: =IF(C11=0,"",D11/C11) -> 0 | F11: =C11-D11 -> 13380 | G11: =IF($A$5=0,"",C11/$A$5) -> 0.42049026 | H11: =IF(G11="","",REPT("█",ROUND(G11*30,0))) -> █████████████
A12: Cartão de débito | B12: =COUNTIFS(Vendas!$D$5:$D$604,"Cartão de débito",Vendas!$L$5:$L$604,Config!$B$7,Vendas!$M$5:$M$604,Config!$B$5) -> 22 | C12: =SUMIFS(Vendas!$F$5:$F$604,Vendas!$D$5:$D$604,"Cartão de débito",Vendas!$L$5:$L$604,Config!$B$7,Vendas!$M$5:$M$604,Config!$B$5) -> 8090 | D12: =SUMIFS(Vendas!$I$5:$I$604,Vendas!$D$5:$D$604,"Cartão de débito",Vendas!$L$5:$L$604,Config!$B$7,Vendas!$M$5:$M$604,Config!$B$5) -> 121.35 | E12: =IF(C12=0,"",D12/C12) -> 0.015 | F12: =C12-D12 -> 7968.65 | G12: =IF($A$5=0,"",C12/$A$5) -> 0.25424261 | H12: =IF(G12="","",REPT("█",ROUND(G12*30,0))) -> ████████
A13: Cartão de crédito à vista | B13: =COUNTIFS(Vendas!$D$5:$D$604,"Cartão de crédito",Vendas!$E$5:$E$604,"<2",Vendas!$L$5:$L$604,Config!$B$7,Vendas!$M$5:$M$604,Config!$B$5) -> 0 | C13: =SUMIFS(Vendas!$F$5:$F$604,Vendas!$D$5:$D$604,"Cartão de crédito",Vendas!$E$5:$E$604,"<2",Vendas!$L$5:$L$604,Config!$B$7,Vendas!$M$5:$M$604,Config!$B$5) -> 0 | D13: =SUMIFS(Vendas!$I$5:$I$604,Vendas!$D$5:$D$604,"Cartão de crédito",Vendas!$E$5:$E$604,"<2",Vendas!$L$5:$L$604,Config!$B$7,Vendas!$M$5:$M$604,Config!$B$5) -> 0 | E13: =IF(C13=0,"",D13/C13) | F13: =C13-D13 -> 0 | G13: =IF($A$5=0,"",C13/$A$5) -> 0 | H13: =IF(G13="","",REPT("█",ROUND(G13*30,0)))
A14: Cartão de crédito parcelado | B14: =COUNTIFS(Vendas!$D$5:$D$604,"Cartão de crédito",Vendas!$E$5:$E$604,">1",Vendas!$L$5:$L$604,Config!$B$7,Vendas!$M$5:$M$604,Config!$B$5) -> 12 | C14: =SUMIFS(Vendas!$F$5:$F$604,Vendas!$D$5:$D$604,"Cartão de crédito",Vendas!$E$5:$E$604,">1",Vendas!$L$5:$L$604,Config!$B$7,Vendas!$M$5:$M$604,Config!$B$5) -> 4510 | D14: =SUMIFS(Vendas!$I$5:$I$604,Vendas!$D$5:$D$604,"Cartão de crédito",Vendas!$E$5:$E$604,">1",Vendas!$L$5:$L$604,Config!$B$7,Vendas!$M$5:$M$604,Config!$B$5) -> 175.89 | E14: =IF(C14=0,"",D14/C14) -> 0.039 | F14: =C14-D14 -> 4334.11 | G14: =IF($A$5=0,"",C14/$A$5) -> 0.14173476 | H14: =IF(G14="","",REPT("█",ROUND(G14*30,0))) -> ████
A15: Total | B15: =SUM(B11:B14) -> 71 | C15: =SUM(C11:C14) -> 25980 | D15: =SUM(D11:D14) -> 297.24 | F15: =SUM(F11:F14) -> 25682.76
A16: Parcelado custa mais e demora mais. Se o parcelado pesa, vale oferecer desconto no Pix em vez de absorver a taxa; a decisão é da clínica.
A18: Dia a dia do mês: vendas, taxas e previsão de crédito
A19: Dia | B19: Data | C19: Vendas | D19: Bruto (R$) | E19: Taxas (R$) | F19: Líquido (R$) | G19: Cai na conta neste dia (R$) | H19: Conferido?
A20: 1 | B20: =IF(1>DAY(DATE(Config!$B$5,Config!$B$7+1,0)),"",DATE(Config!$B$5,Config!$B$7,1)) -> 46235 | C20: =IF(B20="","",COUNTIFS(Vendas!$A$5:$A$604,B20)) -> 0 | D20: =IF(B20="","",SUMIFS(Vendas!$F$5:$F$604,Vendas!$A$5:$A$604,B20)) -> 0 | E20: =IF(B20="","",SUMIFS(Vendas!$I$5:$I$604,Vendas!$A$5:$A$604,B20)) -> 0 | F20: =IF(B20="","",D20-E20) -> 0 | G20: =IF(B20="","",SUMIFS(Vendas!$J$5:$J$604,Vendas!$K$5:$K$604,B20)) -> 1862.22 | H20: =IF(OR(B20="",G20=0),"",IF(COUNTIFS(Vendas!$K$5:$K$604,B20,Vendas!$N$5:$N$604,"A conferir")>0,"Falta conferir",IF(COUNTIFS(Vendas!$K$5:$K$604,B20,Vendas!$N$5:$N$604,"A cair")>0,"A cair","Conferido"))) -> Conferido
A21: 2 | B21: =IF(2>DAY(DATE(Config!$B$5,Config!$B$7+1,0)),"",DATE(Config!$B$5,Config!$B$7,2)) -> 46236 | C21: =IF(B21="","",COUNTIFS(Vendas!$A$5:$A$604,B21)) -> 0 | D21: =IF(B21="","",SUMIFS(Vendas!$F$5:$F$604,Vendas!$A$5:$A$604,B21)) -> 0 | E21: =IF(B21="","",SUMIFS(Vendas!$I$5:$I$604,Vendas!$A$5:$A$604,B21)) -> 0 | F21: =IF(B21="","",D21-E21) -> 0 | G21: =IF(B21="","",SUMIFS(Vendas!$J$5:$J$604,Vendas!$K$5:$K$604,B21)) -> 0 | H21: =IF(OR(B21="",G21=0),"",IF(COUNTIFS(Vendas!$K$5:$K$604,B21,Vendas!$N$5:$N$604,"A conferir")>0,"Falta conferir",IF(COUNTIFS(Vendas!$K$5:$K$604,B21,Vendas!$N$5:$N$604,"A cair")>0,"A cair","Conferido")))
A22: 3 | B22: =IF(3>DAY(DATE(Config!$B$5,Config!$B$7+1,0)),"",DATE(Config!$B$5,Config!$B$7,3)) -> 46237 | C22: =IF(B22="","",COUNTIFS(Vendas!$A$5:$A$604,B22)) -> 2 | D22: =IF(B22="","",SUMIFS(Vendas!$F$5:$F$604,Vendas!$A$5:$A$604,B22)) -> 680 | E22: =IF(B22="","",SUMIFS(Vendas!$I$5:$I$604,Vendas!$A$5:$A$604,B22)) -> 16.66 | F22: =IF(B22="","",D22-E22) -> 663.34 | G22: =IF(B22="","",SUMIFS(Vendas!$J$5:$J$604,Vendas!$K$5:$K$604,B22)) -> 0 | H22: =IF(OR(B22="",G22=0),"",IF(COUNTIFS(Vendas!$K$5:$K$604,B22,Vendas!$N$5:$N$604,"A conferir")>0,"Falta conferir",IF(COUNTIFS(Vendas!$K$5:$K$604,B22,Vendas!$N$5:$N$604,"A cair")>0,"A cair","Conferido")))
A23: 4 | B23: =IF(4>DAY(DATE(Config!$B$5,Config!$B$7+1,0)),"",DATE(Config!$B$5,Config!$B$7,4)) -> 46238 | C23: =IF(B23="","",COUNTIFS(Vendas!$A$5:$A$604,B23)) -> 8 | D23: =IF(B23="","",SUMIFS(Vendas!$F$5:$F$604,Vendas!$A$5:$A$604,B23)) -> 3060 | E23: =IF(B23="","",SUMIFS(Vendas!$I$5:$I$604,Vendas!$A$5:$A$604,B23)) -> 47.42 | F23: =IF(B23="","",D23-E23) -> 3012.58 | G23: =IF(B23="","",SUMIFS(Vendas!$J$5:$J$604,Vendas!$K$5:$K$604,B23)) -> 1055.5 | H23: =IF(OR(B23="",G23=0),"",IF(COUNTIFS(Vendas!$K$5:$K$604,B23,Vendas!$N$5:$N$604,"A conferir")>0,"Falta conferir",IF(COUNTIFS(Vendas!$K$5:$K$604,B23,Vendas!$N$5:$N$604,"A cair")>0,"A cair","Conferido"))) -> Conferido
A24: 5 | B24: =IF(5>DAY(DATE(Config!$B$5,Config!$B$7+1,0)),"",DATE(Config!$B$5,Config!$B$7,5)) -> 46239 | C24: =IF(B24="","",COUNTIFS(Vendas!$A$5:$A$604,B24)) -> 3 | D24: =IF(B24="","",SUMIFS(Vendas!$F$5:$F$604,Vendas!$A$5:$A$604,B24)) -> 1140 | E24: =IF(B24="","",SUMIFS(Vendas!$I$5:$I$604,Vendas!$A$5:$A$604,B24)) -> 20.52 | F24: =IF(B24="","",D24-E24) -> 1119.48 | G24: =IF(B24="","",SUMIFS(Vendas!$J$5:$J$604,Vendas!$K$5:$K$604,B24)) -> 2629.92 | H24: =IF(OR(B24="",G24=0),"",IF(COUNTIFS(Vendas!$K$5:$K$604,B24,Vendas!$N$5:$N$604,"A conferir")>0,"Falta conferir",IF(COUNTIFS(Vendas!$K$5:$K$604,B24,Vendas!$N$5:$N$604,"A cair")>0,"A cair","Conferido"))) -> Conferido
A25: 6 | B25: =IF(6>DAY(DATE(Config!$B$5,Config!$B$7+1,0)),"",DATE(Config!$B$5,Config!$B$7,6)) -> 46240 | C25: =IF(B25="","",COUNTIFS(Vendas!$A$5:$A$604,B25)) -> 5 | D25: =IF(B25="","",SUMIFS(Vendas!$F$5:$F$604,Vendas!$A$5:$A$604,B25)) -> 2010 | E25: =IF(B25="","",SUMIFS(Vendas!$I$5:$I$604,Vendas!$A$5:$A$604,B25)) -> 36.12 | F25: =IF(B25="","",D25-E25) -> 1973.88 | G25: =IF(B25="","",SUMIFS(Vendas!$J$5:$J$604,Vendas!$K$5:$K$604,B25)) -> 1959.98 | H25: =IF(OR(B25="",G25=0),"",IF(COUNTIFS(Vendas!$K$5:$K$604,B25,Vendas!$N$5:$N$604,"A conferir")>0,"Falta conferir",IF(COUNTIFS(Vendas!$K$5:$K$604,B25,Vendas!$N$5:$N$604,"A cair")>0,"A cair","Conferido"))) -> Conferido
A26: 7 | B26: =IF(7>DAY(DATE(Config!$B$5,Config!$B$7+1,0)),"",DATE(Config!$B$5,Config!$B$7,7)) -> 46241 | C26: =IF(B26="","",COUNTIFS(Vendas!$A$5:$A$604,B26)) -> 2 | D26: =IF(B26="","",SUMIFS(Vendas!$F$5:$F$604,Vendas!$A$5:$A$604,B26)) -> 510 | E26: =IF(B26="","",SUMIFS(Vendas!$I$5:$I$604,Vendas!$A$5:$A$604,B26)) -> 12.16 | F26: =IF(B26="","",D26-E26) -> 497.84 | G26: =IF(B26="","",SUMIFS(Vendas!$J$5:$J$604,Vendas!$K$5:$K$604,B26)) -> 872.14 | H26: =IF(OR(B26="",G26=0),"",IF(COUNTIFS(Vendas!$K$5:$K$604,B26,Vendas!$N$5:$N$604,"A conferir")>0,"Falta conferir",IF(COUNTIFS(Vendas!$K$5:$K$604,B26,Vendas!$N$5:$N$604,"A cair")>0,"A cair","Conferido"))) -> Conferido
A27: 8 | B27: =IF(8>DAY(DATE(Config!$B$5,Config!$B$7+1,0)),"",DATE(Config!$B$5,Config!$B$7,8)) -> 46242 | C27: =IF(B27="","",COUNTIFS(Vendas!$A$5:$A$604,B27)) -> 0 | D27: =IF(B27="","",SUMIFS(Vendas!$F$5:$F$604,Vendas!$A$5:$A$604,B27)) -> 0 | E27: =IF(B27="","",SUMIFS(Vendas!$I$5:$I$604,Vendas!$A$5:$A$604,B27)) -> 0 | F27: =IF(B27="","",D27-E27) -> 0 | G27: =IF(B27="","",SUMIFS(Vendas!$J$5:$J$604,Vendas!$K$5:$K$604,B27)) -> 1248.72 | H27: =IF(OR(B27="",G27=0),"",IF(COUNTIFS(Vendas!$K$5:$K$604,B27,Vendas!$N$5:$N$604,"A conferir")>0,"Falta conferir",IF(COUNTIFS(Vendas!$K$5:$K$604,B27,Vendas!$N$5:$N$604,"A cair")>0,"A cair","Conferido"))) -> Conferido
A28: 9 | B28: =IF(9>DAY(DATE(Config!$B$5,Config!$B$7+1,0)),"",DATE(Config!$B$5,Config!$B$7,9)) -> 46243 | C28: =IF(B28="","",COUNTIFS(Vendas!$A$5:$A$604,B28)) -> 0 | D28: =IF(B28="","",SUMIFS(Vendas!$F$5:$F$604,Vendas!$A$5:$A$604,B28)) -> 0 | E28: =IF(B28="","",SUMIFS(Vendas!$I$5:$I$604,Vendas!$A$5:$A$604,B28)) -> 0 | F28: =IF(B28="","",D28-E28) -> 0 | G28: =IF(B28="","",SUMIFS(Vendas!$J$5:$J$604,Vendas!$K$5:$K$604,B28)) -> 0 | H28: =IF(OR(B28="",G28=0),"",IF(COUNTIFS(Vendas!$K$5:$K$604,B28,Vendas!$N$5:$N$604,"A conferir")>0,"Falta conferir",IF(COUNTIFS(Vendas!$K$5:$K$604,B28,Vendas!$N$5:$N$604,"A cair")>0,"A cair","Conferido")))
A29: 10 | B29: =IF(10>DAY(DATE(Config!$B$5,Config!$B$7+1,0)),"",DATE(Config!$B$5,Config!$B$7,10)) -> 46244 | C29: =IF(B29="","",COUNTIFS(Vendas!$A$5:$A$604,B29)) -> 3 | D29: =IF(B29="","",SUMIFS(Vendas!$F$5:$F$604,Vendas!$A$5:$A$604,B29)) -> 860 | E29: =IF(B29="","",SUMIFS(Vendas!$I$5:$I$604,Vendas!$A$5:$A$604,B29)) -> 17.41 | F29: =IF(B29="","",D29-E29) -> 842.59 | G29: =IF(B29="","",SUMIFS(Vendas!$J$5:$J$604,Vendas!$K$5:$K$604,B29)) -> 130 | H29: =IF(OR(B29="",G29=0),"",IF(COUNTIFS(Vendas!$K$5:$K$604,B29,Vendas!$N$5:$N$604,"A conferir")>0,"Falta conferir",IF(COUNTIFS(Vendas!$K$5:$K$604,B29,Vendas!$N$5:$N$604,"A cair")>0,"A cair","Conferido"))) -> Conferido
A30: 11 | B30: =IF(11>DAY(DATE(Config!$B$5,Config!$B$7+1,0)),"",DATE(Config!$B$5,Config!$B$7,11)) -> 46245 | C30: =IF(B30="","",COUNTIFS(Vendas!$A$5:$A$604,B30)) -> 7 | D30: =IF(B30="","",SUMIFS(Vendas!$F$5:$F$604,Vendas!$A$5:$A$604,B30)) -> 2490 | E30: =IF(B30="","",SUMIFS(Vendas!$I$5:$I$604,Vendas!$A$5:$A$604,B30)) -> 45.03 | F30: =IF(B30="","",D30-E30) -> 2444.97 | G30: =IF(B30="","",SUMIFS(Vendas!$J$5:$J$604,Vendas!$K$5:$K$604,B30)) -> 1324.75 | H30: =IF(OR(B30="",G30=0),"",IF(COUNTIFS(Vendas!$K$5:$K$604,B30,Vendas!$N$5:$N$604,"A conferir")>0,"Falta conferir",IF(COUNTIFS(Vendas!$K$5:$K$604,B30,Vendas!$N$5:$N$604,"A cair")>0,"A cair","Conferido"))) -> Conferido
A31: 12 | B31: =IF(12>DAY(DATE(Config!$B$5,Config!$B$7+1,0)),"",DATE(Config!$B$5,Config!$B$7,12)) -> 46246 | C31: =IF(B31="","",COUNTIFS(Vendas!$A$5:$A$604,B31)) -> 4 | D31: =IF(B31="","",SUMIFS(Vendas!$F$5:$F$604,Vendas!$A$5:$A$604,B31)) -> 1520 | E31: =IF(B31="","",SUMIFS(Vendas!$I$5:$I$604,Vendas!$A$5:$A$604,B31)) -> 24.32 | F31: =IF(B31="","",D31-E31) -> 1495.68 | G31: =IF(B31="","",SUMIFS(Vendas!$J$5:$J$604,Vendas!$K$5:$K$604,B31)) -> 1595.77 | H31: =IF(OR(B31="",G31=0),"",IF(COUNTIFS(Vendas!$K$5:$K$604,B31,Vendas!$N$5:$N$604,"A conferir")>0,"Falta conferir",IF(COUNTIFS(Vendas!$K$5:$K$604,B31,Vendas!$N$5:$N$604,"A cair")>0,"A cair","Conferido"))) -> Conferido
A32: 13 | B32: =IF(13>DAY(DATE(Config!$B$5,Config!$B$7+1,0)),"",DATE(Config!$B$5,Config!$B$7,13)) -> 46247 | C32: =IF(B32="","",COUNTIFS(Vendas!$A$5:$A$604,B32)) -> 8 | D32: =IF(B32="","",SUMIFS(Vendas!$F$5:$F$604,Vendas!$A$5:$A$604,B32)) -> 3120 | E32: =IF(B32="","",SUMIFS(Vendas!$I$5:$I$604,Vendas!$A$5:$A$604,B32)) -> 24.16 | F32: =IF(B32="","",D32-E32) -> 3095.84 | G32: =IF(B32="","",SUMIFS(Vendas!$J$5:$J$604,Vendas!$K$5:$K$604,B32)) -> 4262.52 | H32: =IF(OR(B32="",G32=0),"",IF(COUNTIFS(Vendas!$K$5:$K$604,B32,Vendas!$N$5:$N$604,"A conferir")>0,"Falta conferir",IF(COUNTIFS(Vendas!$K$5:$K$604,B32,Vendas!$N$5:$N$604,"A cair")>0,"A cair","Conferido"))) -> Conferido
A33: 14 | B33: =IF(14>DAY(DATE(Config!$B$5,Config!$B$7+1,0)),"",DATE(Config!$B$5,Config!$B$7,14)) -> 46248 | C33: =IF(B33="","",COUNTIFS(Vendas!$A$5:$A$604,B33)) -> 0 | D33: =IF(B33="","",SUMIFS(Vendas!$F$5:$F$604,Vendas!$A$5:$A$604,B33)) -> 0 | E33: =IF(B33="","",SUMIFS(Vendas!$I$5:$I$604,Vendas!$A$5:$A$604,B33)) -> 0 | F33: =IF(B33="","",D33-E33) -> 0 | G33: =IF(B33="","",SUMIFS(Vendas!$J$5:$J$604,Vendas!$K$5:$K$604,B33)) -> 1155.84 | H33: =IF(OR(B33="",G33=0),"",IF(COUNTIFS(Vendas!$K$5:$K$604,B33,Vendas!$N$5:$N$604,"A conferir")>0,"Falta conferir",IF(COUNTIFS(Vendas!$K$5:$K$604,B33,Vendas!$N$5:$N$604,"A cair")>0,"A cair","Conferido"))) -> Conferido
A34: 15 | B34: =IF(15>DAY(DATE(Config!$B$5,Config!$B$7+1,0)),"",DATE(Config!$B$5,Config!$B$7,15)) -> 46249 | C34: =IF(B34="","",COUNTIFS(Vendas!$A$5:$A$604,B34)) -> 0 | D34: =IF(B34="","",SUMIFS(Vendas!$F$5:$F$604,Vendas!$A$5:$A$604,B34)) -> 0 | E34: =IF(B34="","",SUMIFS(Vendas!$I$5:$I$604,Vendas!$A$5:$A$604,B34)) -> 0 | F34: =IF(B34="","",D34-E34) -> 0 | G34: =IF(B34="","",SUMIFS(Vendas!$J$5:$J$604,Vendas!$K$5:$K$604,B34)) -> 1122.88 | H34: =IF(OR(B34="",G34=0),"",IF(COUNTIFS(Vendas!$K$5:$K$604,B34,Vendas!$N$5:$N$604,"A conferir")>0,"Falta conferir",IF(COUNTIFS(Vendas!$K$5:$K$604,B34,Vendas!$N$5:$N$604,"A cair")>0,"A cair","Conferido"))) -> Conferido
A35: 16 | B35: =IF(16>DAY(DATE(Config!$B$5,Config!$B$7+1,0)),"",DATE(Config!$B$5,Config!$B$7,16)) -> 46250 | C35: =IF(B35="","",COUNTIFS(Vendas!$A$5:$A$604,B35)) -> 0 | D35: =IF(B35="","",SUMIFS(Vendas!$F$5:$F$604,Vendas!$A$5:$A$604,B35)) -> 0 | E35: =IF(B35="","",SUMIFS(Vendas!$I$5:$I$604,Vendas!$A$5:$A$604,B35)) -> 0 | F35: =IF(B35="","",D35-E35) -> 0 | G35: =IF(B35="","",SUMIFS(Vendas!$J$5:$J$604,Vendas!$K$5:$K$604,B35)) -> 367.84 | H35: =IF(OR(B35="",G35=0),"",IF(COUNTIFS(Vendas!$K$5:$K$604,B35,Vendas!$N$5:$N$604,"A conferir")>0,"Falta conferir",IF(COUNTIFS(Vendas!$K$5:$K$604,B35,Vendas!$N$5:$N$604,"A cair")>0,"A cair","Conferido"))) -> Conferido
A36: 17 | B36: =IF(17>DAY(DATE(Config!$B$5,Config!$B$7+1,0)),"",DATE(Config!$B$5,Config!$B$7,17)) -> 46251 | C36: =IF(B36="","",COUNTIFS(Vendas!$A$5:$A$604,B36)) -> 3 | D36: =IF(B36="","",SUMIFS(Vendas!$F$5:$F$604,Vendas!$A$5:$A$604,B36)) -> 1060 | E36: =IF(B36="","",SUMIFS(Vendas!$I$5:$I$604,Vendas!$A$5:$A$604,B36)) -> 17.4 | F36: =IF(B36="","",D36-E36) -> 1042.6 | G36: =IF(B36="","",SUMIFS(Vendas!$J$5:$J$604,Vendas!$K$5:$K$604,B36)) -> 380 | H36: =IF(OR(B36="",G36=0),"",IF(COUNTIFS(Vendas!$K$5:$K$604,B36,Vendas!$N$5:$N$604,"A conferir")>0,"Falta conferir",IF(COUNTIFS(Vendas!$K$5:$K$604,B36,Vendas!$N$5:$N$604,"A cair")>0,"A cair","Conferido"))) -> Conferido
A37: 18 | B37: =IF(18>DAY(DATE(Config!$B$5,Config!$B$7+1,0)),"",DATE(Config!$B$5,Config!$B$7,18)) -> 46252 | C37: =IF(B37="","",COUNTIFS(Vendas!$A$5:$A$604,B37)) -> 4 | D37: =IF(B37="","",SUMIFS(Vendas!$F$5:$F$604,Vendas!$A$5:$A$604,B37)) -> 1540 | E37: =IF(B37="","",SUMIFS(Vendas!$I$5:$I$604,Vendas!$A$5:$A$604,B37)) -> 20.52 | F37: =IF(B37="","",D37-E37) -> 1519.48 | G37: =IF(B37="","",SUMIFS(Vendas!$J$5:$J$604,Vendas!$K$5:$K$604,B37)) -> 1154.3 | H37: =IF(OR(B37="",G37=0),"",IF(COUNTIFS(Vendas!$K$5:$K$604,B37,Vendas!$N$5:$N$604,"A conferir")>0,"Falta conferir",IF(COUNTIFS(Vendas!$K$5:$K$604,B37,Vendas!$N$5:$N$604,"A cair")>0,"A cair","Conferido"))) -> Conferido
A38: 19 | B38: =IF(19>DAY(DATE(Config!$B$5,Config!$B$7+1,0)),"",DATE(Config!$B$5,Config!$B$7,19)) -> 46253 | C38: =IF(B38="","",COUNTIFS(Vendas!$A$5:$A$604,B38)) -> 2 | D38: =IF(B38="","",SUMIFS(Vendas!$F$5:$F$604,Vendas!$A$5:$A$604,B38)) -> 760 | E38: =IF(B38="","",SUMIFS(Vendas!$I$5:$I$604,Vendas!$A$5:$A$604,B38)) -> 5.7 | F38: =IF(B38="","",D38-E38) -> 754.3 | G38: =IF(B38="","",SUMIFS(Vendas!$J$5:$J$604,Vendas!$K$5:$K$604,B38)) -> 1489.98 | H38: =IF(OR(B38="",G38=0),"",IF(COUNTIFS(Vendas!$K$5:$K$604,B38,Vendas!$N$5:$N$604,"A conferir")>0,"Falta conferir",IF(COUNTIFS(Vendas!$K$5:$K$604,B38,Vendas!$N$5:$N$604,"A cair")>0,"A cair","Conferido"))) -> Conferido
A39: 20 | B39: =IF(20>DAY(DATE(Config!$B$5,Config!$B$7+1,0)),"",DATE(Config!$B$5,Config!$B$7,20)) -> 46254 | C39: =IF(B39="","",COUNTIFS(Vendas!$A$5:$A$604,B39)) -> 9 | D39: =IF(B39="","",SUMIFS(Vendas!$F$5:$F$604,Vendas!$A$5:$A$604,B39)) -> 3370 | E39: =IF(B39="","",SUMIFS(Vendas!$I$5:$I$604,Vendas!$A$5:$A$604,B39)) -> 34.4 | F39: =IF(B39="","",D39-E39) -> 3335.6 | G39: =IF(B39="","",SUMIFS(Vendas!$J$5:$J$604,Vendas!$K$5:$K$604,B39)) -> 3664.52 | H39: =IF(OR(B39="",G39=0),"",IF(COUNTIFS(Vendas!$K$5:$K$604,B39,Vendas!$N$5:$N$604,"A conferir")>0,"Falta conferir",IF(COUNTIFS(Vendas!$K$5:$K$604,B39,Vendas!$N$5:$N$604,"A cair")>0,"A cair","Conferido"))) -> Conferido
A40: 21 | B40: =IF(21>DAY(DATE(Config!$B$5,Config!$B$7+1,0)),"",DATE(Config!$B$5,Config!$B$7,21)) -> 46255 | C40: =IF(B40="","",COUNTIFS(Vendas!$A$5:$A$604,B40)) -> 0 | D40: =IF(B40="","",SUMIFS(Vendas!$F$5:$F$604,Vendas!$A$5:$A$604,B40)) -> 0 | E40: =IF(B40="","",SUMIFS(Vendas!$I$5:$I$604,Vendas!$A$5:$A$604,B40)) -> 0 | F40: =IF(B40="","",D40-E40) -> 0 | G40: =IF(B40="","",SUMIFS(Vendas!$J$5:$J$604,Vendas!$K$5:$K$604,B40)) -> 1129.68 | H40: =IF(OR(B40="",G40=0),"",IF(COUNTIFS(Vendas!$K$5:$K$604,B40,Vendas!$N$5:$N$604,"A conferir")>0,"Falta conferir",IF(COUNTIFS(Vendas!$K$5:$K$604,B40,Vendas!$N$5:$N$604,"A cair")>0,"A cair","Conferido"))) -> Conferido
A41: 22 | B41: =IF(22>DAY(DATE(Config!$B$5,Config!$B$7+1,0)),"",DATE(Config!$B$5,Config!$B$7,22)) -> 46256 | C41: =IF(B41="","",COUNTIFS(Vendas!$A$5:$A$604,B41)) -> 0 | D41: =IF(B41="","",SUMIFS(Vendas!$F$5:$F$604,Vendas!$A$5:$A$604,B41)) -> 0 | E41: =IF(B41="","",SUMIFS(Vendas!$I$5:$I$604,Vendas!$A$5:$A$604,B41)) -> 0 | F41: =IF(B41="","",D41-E41) -> 0 | G41: =IF(B41="","",SUMIFS(Vendas!$J$5:$J$604,Vendas!$K$5:$K$604,B41)) -> 1485.26 | H41: =IF(OR(B41="",G41=0),"",IF(COUNTIFS(Vendas!$K$5:$K$604,B41,Vendas!$N$5:$N$604,"A conferir")>0,"Falta conferir",IF(COUNTIFS(Vendas!$K$5:$K$604,B41,Vendas!$N$5:$N$604,"A cair")>0,"A cair","Conferido"))) -> Conferido
A42: 23 | B42: =IF(23>DAY(DATE(Config!$B$5,Config!$B$7+1,0)),"",DATE(Config!$B$5,Config!$B$7,23)) -> 46257 | C42: =IF(B42="","",COUNTIFS(Vendas!$A$5:$A$604,B42)) -> 0 | D42: =IF(B42="","",SUMIFS(Vendas!$F$5:$F$604,Vendas!$A$5:$A$604,B42)) -> 0 | E42: =IF(B42="","",SUMIFS(Vendas!$I$5:$I$604,Vendas!$A$5:$A$604,B42)) -> 0 | F42: =IF(B42="","",D42-E42) -> 0 | G42: =IF(B42="","",SUMIFS(Vendas!$J$5:$J$604,Vendas!$K$5:$K$604,B42)) -> 0 | H42: =IF(OR(B42="",G42=0),"",IF(COUNTIFS(Vendas!$K$5:$K$604,B42,Vendas!$N$5:$N$604,"A conferir")>0,"Falta conferir",IF(COUNTIFS(Vendas!$K$5:$K$604,B42,Vendas!$N$5:$N$604,"A cair")>0,"A cair","Conferido")))
A43: 24 | B43: =IF(24>DAY(DATE(Config!$B$5,Config!$B$7+1,0)),"",DATE(Config!$B$5,Config!$B$7,24)) -> 46258 | C43: =IF(B43="","",COUNTIFS(Vendas!$A$5:$A$604,B43)) -> 7 | D43: =IF(B43="","",SUMIFS(Vendas!$F$5:$F$604,Vendas!$A$5:$A$604,B43)) -> 2410 | E43: =IF(B43="","",SUMIFS(Vendas!$I$5:$I$604,Vendas!$A$5:$A$604,B43)) -> 36.84 | F43: =IF(B43="","",D43-E43) -> 2373.16 | G43: =IF(B43="","",SUMIFS(Vendas!$J$5:$J$604,Vendas!$K$5:$K$604,B43)) -> 1140 | H43: =IF(OR(B43="",G43=0),"",IF(COUNTIFS(Vendas!$K$5:$K$604,B43,Vendas!$N$5:$N$604,"A conferir")>0,"Falta conferir",IF(COUNTIFS(Vendas!$K$5:$K$604,B43,Vendas!$N$5:$N$604,"A cair")>0,"A cair","Conferido"))) -> Conferido
A44: 25 | B44: =IF(25>DAY(DATE(Config!$B$5,Config!$B$7+1,0)),"",DATE(Config!$B$5,Config!$B$7,25)) -> 46259 | C44: =IF(B44="","",COUNTIFS(Vendas!$A$5:$A$604,B44)) -> 8 | D44: =IF(B44="","",SUMIFS(Vendas!$F$5:$F$604,Vendas!$A$5:$A$604,B44)) -> 3020 | E44: =IF(B44="","",SUMIFS(Vendas!$I$5:$I$604,Vendas!$A$5:$A$604,B44)) -> 76.09 | F44: =IF(B44="","",D44-E44) -> 2943.91 | G44: =IF(B44="","",SUMIFS(Vendas!$J$5:$J$604,Vendas!$K$5:$K$604,B44)) -> 1134.3 | H44: =IF(OR(B44="",G44=0),"",IF(COUNTIFS(Vendas!$K$5:$K$604,B44,Vendas!$N$5:$N$604,"A conferir")>0,"Falta conferir",IF(COUNTIFS(Vendas!$K$5:$K$604,B44,Vendas!$N$5:$N$604,"A cair")>0,"A cair","Conferido"))) -> Conferido
...

Sheet Config
A1: Configurações
A2: Células amarelas: você preenche. Taxas e prazos da sua operadora (o contrato da maquininha diz; confira no extrato).
A4: Clínica | B4: Clínica Vida Plena (exemplo fictício) | H4: Meses
A5: Ano do painel | B5: 2026 | H5: Janeiro
A6: Mês do painel | B6: Agosto | H6: Fevereiro
A7: Número do mês | B7: =MATCH(B6,$H$5:$H$16,0) -> 8 | H7: Março
A8: Data de referência (hoje) | B8: =TODAY() -> 46279 | H8: Abril
A9: Preço da consulta particular (para a comparação) | B9: 380 | H9: Maio
H10: Junho
A11: Tipo | B11: Taxa (%) | C11: Cai na conta em (dias) | D11: Observação | H11: Julho
A12: Pix | B12: 0 | C12: 0 | D12: Pix na conta PJ: no exemplo, sem taxa (alguns bancos cobram por recebimento). | H12: Agosto
A13: Cartão de débito | B13: 0.015 | C13: 1 | D13: Débito costuma cair no dia útil seguinte. | H13: Setembro
A14: Cartão de crédito | B14: 0.032 | C14: 30 | D14: Crédito à vista cai em 30 dias. | H14: Outubro
A15: Cartão de crédito parcelado | B15: 0.039 | C15: 30 | D15: Parcelado: cada parcela cai 30 dias depois da anterior; a taxa é maior. | H15: Novembro
H16: Dezembro
A17: Antecipar o crédito? (Sim/Não) | B17: Não | D17: Com antecipação, o crédito cai em 1 dia e a operadora cobra a taxa de antecipação sobre o valor pelo prazo antecipado. No exemplo, a clínica não antecipa.
A18: Taxa de antecipação (% ao mês) | B18: 0.018
A20: As taxas do exemplo são ilustrativas. Pegue as suas no contrato da maquininha ou no extrato da operadora; elas mudam por bandeira e por volume.

Sheet Vendas
A1: Vendas no cartão e no Pix
A2: Uma linha por pagamento (copie da Agenda da planilha 01: atendimentos particulares realizados com Pix ou cartão). Amarelo: data, paciente, procedimento, tipo, parcelas, valor bruto e a conferência no extrato.
A4: Data da venda | B4: Paciente | C4: Procedimento | D4: Tipo | E4: Parcelas | F4: Valor bruto (R$) | G4: Conferido no extrato? | H4: Taxa (%) | I4: Taxa (R$) | J4: Valor líquido (R$) | K4: Previsão na conta | L4: Mês | M4: Ano | N4: Situação
A5: 46204 | B5: Cláudia Santos | C5: Consulta | D5: Pix | F5: 380 | G5: Sim | H5: =IF(D5="","",IFERROR(INDEX(Config!$B$12:$B$15,MATCH(IF(AND(D5="Cartão de crédito",N(E5)>1),"Cartão de crédito parcelado",D5),Config!$A$12:$A$15,0)),0)+IF(AND(Config!$B$17="Sim",LEFT(D5,17)="Cartão de crédito"),Config!$B$18*IFERROR(INDEX(Config!$C$12:$C$15,MATCH(IF(AND(D5="Cartão de crédito",N(E5)>1),"Cartão de crédito parcelado",D5),Config!$A$12:$A$15,0)),0)/30*MAX(1,N(E5)),0)) -> 0 | I5: =IF(OR(D5="",F5=""),"",ROUND(F5*H5,2)) -> 0 | J5: =IF(I5="","",F5-I5) -> 380 | K5: =IF(OR(D5="",A5=""),"",A5+IF(AND(Config!$B$17="Sim",LEFT(D5,17)="Cartão de crédito"),1,IFERROR(INDEX(Config!$C$12:$C$15,MATCH(IF(AND(D5="Cartão de crédito",N(E5)>1),"Cartão de crédito parcelado",D5),Config!$A$12:$A$15,0)),0))) -> 46204 | L5: =IF(A5="","",MONTH(A5)) -> 7 | M5: =IF(A5="","",YEAR(A5)) -> 2026 | N5: =IF(K5="","",IF(G5="Sim","Conferido",IF(K5>Config!$B$8,"A cair","A conferir"))) -> Conferido | O5: =IF(N5="A conferir",(Config!$B$8-K5)*1000+N(F5)/1000+ROW()/100000,0) -> 0
A6: 46204 | B6: Lucas Lopes | C6: Consulta | D6: Cartão de débito | F6: 380 | G6: Sim | H6: =IF(D6="","",IFERROR(INDEX(Config!$B$12:$B$15,MATCH(IF(AND(D6="Cartão de crédito",N(E6)>1),"Cartão de crédito parcelado",D6),Config!$A$12:$A$15,0)),0)+IF(AND(Config!$B$17="Sim",LEFT(D6,17)="Cartão de crédito"),Config!$B$18*IFERROR(INDEX(Config!$C$12:$C$15,MATCH(IF(AND(D6="Cartão de crédito",N(E6)>1),"Cartão de crédito parcelado",D6),Config!$A$12:$A$15,0)),0)/30*MAX(1,N(E6)),0)) -> 0.015 | I6: =IF(OR(D6="",F6=""),"",ROUND(F6*H6,2)) -> 5.7 | J6: =IF(I6="","",F6-I6) -> 374.3 | K6: =IF(OR(D6="",A6=""),"",A6+IF(AND(Config!$B$17="Sim",LEFT(D6,17)="Cartão de crédito"),1,IFERROR(INDEX(Config!$C$12:$C$15,MATCH(IF(AND(D6="Cartão de crédito",N(E6)>1),"Cartão de crédito parcelado",D6),Config!$A$12:$A$15,0)),0))) -> 46205 | L6: =IF(A6="","",MONTH(A6)) -> 7 | M6: =IF(A6="","",YEAR(A6)) -> 2026 | N6: =IF(K6="","",IF(G6="Sim","Conferido",IF(K6>Config!$B$8,"A cair","A conferir"))) -> Conferido | O6: =IF(N6="A conferir",(Config!$B$8-K6)*1000+N(F6)/1000+ROW()/100000,0) -> 0
A7: 46204 | B7: Mônica Martins | C7: Consulta | D7: Pix | F7: 380 | G7: Sim | H7: =IF(D7="","",IFERROR(INDEX(Config!$B$12:$B$15,MATCH(IF(AND(D7="Cartão de crédito",N(E7)>1),"Cartão de crédito parcelado",D7),Config!$A$12:$A$15,0)),0)+IF(AND(Config!$B$17="Sim",LEFT(D7,17)="Cartão de crédito"),Config!$B$18*IFERROR(INDEX(Config!$C$12:$C$15,MATCH(IF(AND(D7="Cartão de crédito",N(E7)>1),"Cartão de crédito parcelado",D7),Config!$A$12:$A$15,0)),0)/30*MAX(1,N(E7)),0)) -> 0 | I7: =IF(OR(D7="",F7=""),"",ROUND(F7*H7,2)) -> 0 | J7: =IF(I7="","",F7-I7) -> 380 | K7: =IF(OR(D7="",A7=""),"",A7+IF(AND(Config!$B$17="Sim",LEFT(D7,17)="Cartão de crédito"),1,IFERROR(INDEX(Config!$C$12:$C$15,MATCH(IF(AND(D7="Cartão de crédito",N(E7)>1),"Cartão de crédito parcelado",D7),Config!$A$12:$A$15,0)),0))) -> 46204 | L7: =IF(A7="","",MONTH(A7)) -> 7 | M7: =IF(A7="","",YEAR(A7)) -> 2026 | N7: =IF(K7="","",IF(G7="Sim","Conferido",IF(K7>Config!$B$8,"A cair","A conferir"))) -> Conferido | O7: =IF(N7="A conferir",(Config!$B$8-K7)*1000+N(F7)/1000+ROW()/100000,0) -> 0
A8: 46205 | B8: Débora Ramos | C8: Consulta | D8: Cartão de crédito | F8: 380 | G8: Sim | H8: =IF(D8="","",IFERROR(INDEX(Config!$B$12:$B$15,MATCH(IF(AND(D8="Cartão de crédito",N(E8)>1),"Cartão de crédito parcelado",D8),Config!$A$12:$A$15,0)),0)+IF(AND(Config!$B$17="Sim",LEFT(D8,17)="Cartão de crédito"),Config!$B$18*IFERROR(INDEX(Config!$C$12:$C$15,MATCH(IF(AND(D8="Cartão de crédito",N(E8)>1),"Cartão de crédito parcelado",D8),Config!$A$12:$A$15,0)),0)/30*MAX(1,N(E8)),0)) -> 0.032 | I8: =IF(OR(D8="",F8=""),"",ROUND(F8*H8,2)) -> 12.16 | J8: =IF(I8="","",F8-I8) -> 367.84 | K8: =IF(OR(D8="",A8=""),"",A8+IF(AND(Config!$B$17="Sim",LEFT(D8,17)="Cartão de crédito"),1,IFERROR(INDEX(Config!$C$12:$C$15,MATCH(IF(AND(D8="Cartão de crédito",N(E8)>1),"Cartão de crédito parcelado",D8),Config!$A$12:$A$15,0)),0))) -> 46235 | L8: =IF(A8="","",MONTH(A8)) -> 7 | M8: =IF(A8="","",YEAR(A8)) -> 2026 | N8: =IF(K8="","",IF(G8="Sim","Conferido",IF(K8>Config!$B$8,"A cair","A conferir"))) -> Conferido | O8: =IF(N8="A conferir",(Config!$B$8-K8)*1000+N(F8)/1000+ROW()/100000,0) -> 0
A9: 46205 | B9: Mariana Nascimento | C9: Consulta | D9: Cartão de crédito | F9: 380 | G9: Sim | H9: =IF(D9="","",IFERROR(INDEX(Config!$B$12:$B$15,MATCH(IF(AND(D9="Cartão de crédito",N(E9)>1),"Cartão de crédito parcelado",D9),Config!$A$12:$A$15,0)),0)+IF(AND(Config!$B$17="Sim",LEFT(D9,17)="Cartão de crédito"),Config!$B$18*IFERROR(INDEX(Config!$C$12:$C$15,MATCH(IF(AND(D9="Cartão de crédito",N(E9)>1),"Cartão de crédito parcelado",D9),Config!$A$12:$A$15,0)),0)/30*MAX(1,N(E9)),0)) -> 0.032 | I9: =IF(OR(D9="",F9=""),"",ROUND(F9*H9,2)) -> 12.16 | J9: =IF(I9="","",F9-I9) -> 367.84 | K9: =IF(OR(D9="",A9=""),"",A9+IF(AND(Config!$B$17="Sim",LEFT(D9,17)="Cartão de crédito"),1,IFERROR(INDEX(Config!$C$12:$C$15,MATCH(IF(AND(D9="Cartão de crédito",N(E9)>1),"Cartão de crédito parcelado",D9),Config!$A$12:$A$15,0)),0))) -> 46235 | L9: =IF(A9="","",MONTH(A9)) -> 7 | M9: =IF(A9="","",YEAR(A9)) -> 2026 | N9: =IF(K9="","",IF(G9="Sim","Conferido",IF(K9>Config!$B$8,"A cair","A conferir"))) -> Conferido | O9: =IF(N9="A conferir",(Config!$B$8-K9)*1000+N(F9)/1000+ROW()/100000,0) -> 0
A10: 46205 | B10: Helena Moreira | C10: Consulta | D10: Cartão de crédito | F10: 380 | G10: Sim | H10: =IF(D10="","",IFERROR(INDEX(Config!$B$12:$B$15,MATCH(IF(AND(D10="Cartão de crédito",N(E10)>1),"Cartão de crédito parcelado",D10),Config!$A$12:$A$15,0)),0)+IF(AND(Config!$B$17="Sim",LEFT(D10,17)="Cartão de crédito"),Config!$B$18*IFERROR(INDEX(Config!$C$12:$C$15,MATCH(IF(AND(D10="Cartão de crédito",N(E10)>1),"Cartão de crédito parcelado",D10),Config!$A$12:$A$15,0)),0)/30*MAX(1,N(E10)),0)) -> 0.032 | I10: =IF(OR(D10="",F10=""),"",ROUND(F10*H10,2)) -> 12.16 | J10: =IF(I10="","",F10-I10) -> 367.84 | K10: =IF(OR(D10="",A10=""),"",A10+IF(AND(Config!$B$17="Sim",LEFT(D10,17)="Cartão de crédito"),1,IFERROR(INDEX(Config!$C$12:$C$15,MATCH(IF(AND(D10="Cartão de crédito",N(E10)>1),"Cartão de crédito parcelado",D10),Config!$A$12:$A$15,0)),0))) -> 46235 | L10: =IF(A10="","",MONTH(A10)) -> 7 | M10: =IF(A10="","",YEAR(A10)) -> 2026 | N10: =IF(K10="","",IF(G10="Sim","Conferido",IF(K10>Config!$B$8,"A cair","A conferir"))) -> Conferido | O10: =IF(N10="A conferir",(Config!$B$8-K10)*1000+N(F10)/1000+ROW()/100000,0) -> 0
A11: 46205 | B11: Gabriel Oliveira | C11: ECG | D11: Pix | F11: 130 | G11: Sim | H11: =IF(D11="","",IFERROR(INDEX(Config!$B$12:$B$15,MATCH(IF(AND(D11="Cartão de crédito",N(E11)>1),"Cartão de crédito parcelado",D11),Config!$A$12:$A$15,0)),0)+IF(AND(Config!$B$17="Sim",LEFT(D11,17)="Cartão de crédito"),Config!$B$18*IFERROR(INDEX(Config!$C$12:$C$15,MATCH(IF(AND(D11="Cartão de crédito",N(E11)>1),"Cartão de crédito parcelado",D11),Config!$A$12:$A$15,0)),0)/30*MAX(1,N(E11)),0)) -> 0 | I11: =IF(OR(D11="",F11=""),"",ROUND(F11*H11,2)) -> 0 | J11: =IF(I11="","",F11-I11) -> 130 | K11: =IF(OR(D11="",A11=""),"",A11+IF(AND(Config!$B$17="Sim",LEFT(D11,17)="Cartão de crédito"),1,IFERROR(INDEX(Config!$C$12:$C$15,MATCH(IF(AND(D11="Cartão de crédito",N(E11)>1),"Cartão de crédito parcelado",D11),Config!$A$12:$A$15,0)),0))) -> 46205 | L11: =IF(A11="","",MONTH(A11)) -> 7 | M11: =IF(A11="","",YEAR(A11)) -> 2026 | N11: =IF(K11="","",IF(G11="Sim","Conferido",IF(K11>Config!$B$8,"A cair","A conferir"))) -> Conferido | O11: =IF(N11="A conferir",(Config!$B$8-K11)*1000+N(F11)/1000+ROW()/100000,0) -> 0
A12: 46205 | B12: Beatriz Monteiro | C12: Avaliação endócrina | D12: Cartão de crédito | E12: 2 | F12: 400 | G12: Sim | H12: =IF(D12="","",IFERROR(INDEX(Config!$B$12:$B$15,MATCH(IF(AND(D12="Cartão de crédito",N(E12)>1),"Cartão de crédito parcelado",D12),Config!$A$12:$A$15,0)),0)+IF(AND(Config!$B$17="Sim",LEFT(D12,17)="Cartão de crédito"),Config!$B$18*IFERROR(INDEX(Config!$C$12:$C$15,MATCH(IF(AND(D12="Cartão de crédito",N(E12)>1),"Cartão de crédito parcelado",D12),Config!$A$12:$A$15,0)),0)/30*MAX(1,N(E12)),0)) -> 0.039 | I12: =IF(OR(D12="",F12=""),"",ROUND(F12*H12,2)) -> 15.6 | J12: =IF(I12="","",F12-I12) -> 384.4 | K12: =IF(OR(D12="",A12=""),"",A12+IF(AND(Config!$B$17="Sim",LEFT(D12,17)="Cartão de crédito"),1,IFERROR(INDEX(Config!$C$12:$C$15,MATCH(IF(AND(D12="Cartão de crédito",N(E12)>1),"Cartão de crédito parcelado",D12),Config!$A$12:$A$15,0)),0))) -> 46235 | L12: =IF(A12="","",MONTH(A12)) -> 7 | M12: =IF(A12="","",YEAR(A12)) -> 2026 | N12: =IF(K12="","",IF(G12="Sim","Conferido",IF(K12>Config!$B$8,"A cair","A conferir"))) -> Conferido | O12: =IF(N12="A conferir",(Config!$B$8-K12)*1000+N(F12)/1000+ROW()/100000,0) -> 0
A13: 46206 | B13: Renato Dias | C13: ECG | D13: Pix | F13: 130 | G13: Sim | H13: =IF(D13="","",IFERROR(INDEX(Config!$B$12:$B$15,MATCH(IF(AND(D13="Cartão de crédito",N(E13)>1),"Cartão de crédito parcelado",D13),Config!$A$12:$A$15,0)),0)+IF(AND(Config!$B$17="Sim",LEFT(D13,17)="Cartão de crédito"),Config!$B$18*IFERROR(INDEX(Config!$C$12:$C$15,MATCH(IF(AND(D13="Cartão de crédito",N(E13)>1),"Cartão de crédito parcelado",D13),Config!$A$12:$A$15,0)),0)/30*MAX(1,N(E13)),0)) -> 0 | I13: =IF(OR(D13="",F13=""),"",ROUND(F13*H13,2)) -> 0 | J13: =IF(I13="","",F13-I13) -> 130 | K13: =IF(OR(D13="",A13=""),"",A13+IF(AND(Config!$B$17="Sim",LEFT(D13,17)="Cartão de crédito"),1,IFERROR(INDEX(Config!$C$12:$C$15,MATCH(IF(AND(D13="Cartão de crédito",N(E13)>1),"Cartão de crédito parcelado",D13),Config!$A$12:$A$15,0)),0))) -> 46206 | L13: =IF(A13="","",MONTH(A13)) -> 7 | M13: =IF(A13="","",YEAR(A13)) -> 2026 | N13: =IF(K13="","",IF(G13="Sim","Conferido",IF(K13>Config!$B$8,"A cair","A conferir"))) -> Conferido | O13: =IF(N13="A conferir",(Config!$B$8-K13)*1000+N(F13)/1000+ROW()/100000,0) -> 0
A14: 46206 | B14: Wagner Costa | C14: Consulta | D14: Pix | F14: 380 | G14: Sim | H14: =IF(D14="","",IFERROR(INDEX(Config!$B$12:$B$15,MATCH(IF(AND(D14="Cartão de crédito",N(E14)>1),"Cartão de crédito parcelado",D14),Config!$A$12:$A$15,0)),0)+IF(AND(Config!$B$17="Sim",LEFT(D14,17)="Cartão de crédito"),Config!$B$18*IFERROR(INDEX(Config!$C$12:$C$15,MATCH(IF(AND(D14="Cartão de crédito",N(E14)>1),"Cartão de crédito parcelado",D14),Config!$A$12:$A$15,0)),0)/30*MAX(1,N(E14)),0)) -> 0 | I14: =IF(OR(D14="",F14=""),"",ROUND(F14*H14,2)) -> 0 | J14: =IF(I14="","",F14-I14) -> 380 | K14: =IF(OR(D14="",A14=""),"",A14+IF(AND(Config!$B$17="Sim",LEFT(D14,17)="Cartão de crédito"),1,IFERROR(INDEX(Config!$C$12:$C$15,MATCH(IF(AND(D14="Cartão de crédito",N(E14)>1),"Cartão de crédito parcelado",D14),Config!$A$12:$A$15,0)),0))) -> 46206 | L14: =IF(A14="","",MONTH(A14)) -> 7 | M14: =IF(A14="","",YEAR(A14)) -> 2026 | N14: =IF(K14="","",IF(G14="Sim","Conferido",IF(K14>Config!$B$8,"A cair","A conferir"))) -> Conferido | O14: =IF(N14="A conferir",(Config!$B$8-K14)*1000+N(F14)/1000+ROW()/100000,0) -> 0
A15: 46209 | B15: Wagner Lima | C15: Consulta | D15: Cartão de crédito | E15: 2 | F15: 380 | G15: Sim | H15: =IF(D15="","",IFERROR(INDEX(Config!$B$12:$B$15,MATCH(IF(AND(D15="Cartão de crédito",N(E15)>1),"Cartão de crédito parcelado",D15),Config!$A$12:$A$15,0)),0)+IF(AND(Config!$B$17="Sim",LEFT(D15,17)="Cartão de crédito"),Config!$B$18*IFERROR(INDEX(Config!$C$12:$C$15,MATCH(IF(AND(D15="Cartão de crédito",N(E15)>1),"Cartão de crédito parcelado",D15),Config!$A$12:$A$15,0)),0)/30*MAX(1,N(E15)),0)) -> 0.039 | I15: =IF(OR(D15="",F15=""),"",ROUND(F15*H15,2)) -> 14.82 | J15: =IF(I15="","",F15-I15) -> 365.18 | K15: =IF(OR(D15="",A15=""),"",A15+IF(AND(Config!$B$17="Sim",LEFT(D15,17)="Cartão de crédito"),1,IFERROR(INDEX(Config!$C$12:$C$15,MATCH(IF(AND(D15="Cartão de crédito",N(E15)>1),"Cartão de crédito parcelado",D15),Config!$A$12:$A$15,0)),0))) -> 46239 | L15: =IF(A15="","",MONTH(A15)) -> 7 | M15: =IF(A15="","",YEAR(A15)) -> 2026 | N15: =IF(K15="","",IF(G15="Sim","Conferido",IF(K15>Config!$B$8,"A cair","A conferir"))) -> Conferido | O15: =IF(N15="A conferir",(Config!$B$8-K15)*1000+N(F15)/1000+ROW()/100000,0) -> 0
A16: 46209 | B16: Paulo Reis | C16: Consulta | D16: Cartão de crédito | F16: 380 | G16: Sim | H16: =IF(D16="","",IFERROR(INDEX(Config!$B$12:$B$15,MATCH(IF(AND(D16="Cartão de crédito",N(E16)>1),"Cartão de crédito parcelado",D16),Config!$A$12:$A$15,0)),0)+IF(AND(Config!$B$17="Sim",LEFT(D16,17)="Cartão de crédito"),Config!$B$18*IFERROR(INDEX(Config!$C$12:$C$15,MATCH(IF(AND(D16="Cartão de crédito",N(E16)>1),"Cartão de crédito parcelado",D16),Config!$A$12:$A$15,0)),0)/30*MAX(1,N(E16)),0)) -> 0.032 | I16: =IF(OR(D16="",F16=""),"",ROUND(F16*H16,2)) -> 12.16 | J16: =IF(I16="","",F16-I16) -> 367.84 | K16: =IF(OR(D16="",A16=""),"",A16+IF(AND(Config!$B$17="Sim",LEFT(D16,17)="Cartão de crédito"),1,IFERROR(INDEX(Config!$C$12:$C$15,MATCH(IF(AND(D16="Cartão de crédito",N(E16)>1),"Cartão de crédito parcelado",D16),Config!$A$12:$A$15,0)),0))) -> 46239 | L16: =IF(A16="","",MONTH(A16)) -> 7 | M16: =IF(A16="","",YEAR(A16)) -> 2026 | N16: =IF(K16="","",IF(G16="Sim","Conferido",IF(K16>Config!$B$8,"A cair","A conferir"))) -> Conferido | O16: =IF(N16="A conferir",(Config!$B$8-K16)*1000+N(F16)/1000+ROW()/100000,0) -> 0
A17: 46210 | B17: Marcelo Santos | C17: Consulta | D17: Pix | F17: 380 | G17: Sim | H17: =IF(D17="","",IFERROR(INDEX(Config!$B$12:$B$15,MATCH(IF(AND(D17="Cartão de crédito",N(E17)>1),"Cartão de crédito parcelado",D17),Config!$A$12:$A$15,0)),0)+IF(AND(Config!$B$17="Sim",LEFT(D17,17)="Cartão de crédito"),Config!$B$18*IFERROR(INDEX(Config!$C$12:$C$15,MATCH(IF(AND(D17="Cartão de crédito",N(E17)>1),"Cartão de crédito parcelado",D17),Config!$A$12:$A$15,0)),0)/30*MAX(1,N(E17)),0)) -> 0 | I17: =IF(OR(D17="",F17=""),"",ROUND(F17*H17,2)) -> 0 | J17: =IF(I17="","",F17-I17) -> 380 | K17: =IF(OR(D17="",A17=""),"",A17+IF(AND(Config!$B$17="Sim",LEFT(D17,17)="Cartão de crédito"),1,IFERROR(INDEX(Config!$C$12:$C$15,MATCH(IF(AND(D17="Cartão de crédito",N(E17)>1),"Cartão de crédito parcelado",D17),Config!$A$12:$A$15,0)),0))) -> 46210 | L17: =IF(A17="","",MONTH(A17)) -> 7 | M17: =IF(A17="","",YEAR(A17)) -> 2026 | N17: =IF(K17="","",IF(G17="Sim","Conferido",IF(K17>Config!$B$8,"A cair","A conferir"))) -> Conferido | O17: =IF(N17="A conferir",(Config!$B$8-K17)*1000+N(F17)/1000+ROW()/100000,0) -> 0
A18: 46210 | B18: Regina Teixeira | C18: Consulta | D18: Pix | F18: 380 | G18: Sim | H18: =IF(D18="","",IFERROR(INDEX(Config!$B$12:$B$15,MATCH(IF(AND(D18="Cartão de crédito",N(E18)>1),"Cartão de crédito parcelado",D18),Config!$A$12:$A$15,0)),0)+IF(AND(Config!$B$17="Sim",LEFT(D18,17)="Cartão de crédito"),Config!$B$18*IFERROR(INDEX(Config!$C$12:$C$15,MATCH(IF(AND(D18="Cartão de crédito",N(E18)>1),"Cartão de crédito parcelado",D18),Config!$A$12:$A$15,0)),0)/30*MAX(1,N(E18)),0)) -> 0 | I18: =IF(OR(D18="",F18=""),"",ROUND(F18*H18,2)) -> 0 | J18: =IF(I18="","",F18-I18) -> 380 | K18: =IF(OR(D18="",A18=""),"",A18+IF(AND(Config!$B$17="Sim",LEFT(D18,17)="Cartão de crédito"),1,IFERROR(INDEX(Config!$C$12:$C$15,MATCH(IF(AND(D18="Cartão de crédito",N(E18)>1),"Cartão de crédito parcelado",D18),Config!$A$12:$A$15,0)),0))) -> 46210 | L18: =IF(A18="","",MONTH(A18)) -> 7 | M18: =IF(A18="","",YEAR(A18)) -> 2026 | N18: =IF(K18="","",IF(G18="Sim","Conferido",IF(K18>Config!$B$8,"A cair","A conferir"))) -> Conferido | O18: =IF(N18="A conferir",(Config!$B$8-K18)*1000+N(F18)/1000+ROW()/100000,0) -> 0
A19: 46210 | B19: Gisele Ribeiro | C19: Consulta | D19: Pix | F19: 380 | G19: Sim | H19: =IF(D19="","",IFERROR(INDEX(Config!$B$12:$B$15,MATCH(IF(AND(D19="Cartão de crédito",N(E19)>1),"Cartão de crédito parcelado",D19),Config!$A$12:$A$15,0)),0)+IF(AND(Config!$B$17="Sim",LEFT(D19,17)="Cartão de crédito"),Config!$B$18*IFERROR(INDEX(Config!$C$12:$C$15,MATCH(IF(AND(D19="Cartão de crédito",N(E19)>1),"Cartão de crédito parcelado",D19),Config!$A$12:$A$15,0)),0)/30*MAX(1,N(E19)),0)) -> 0 | I19: =IF(OR(D19="",F19=""),"",ROUND(F19*H19,2)) -> 0 | J19: =IF(I19="","",F19-I19) -> 380 | K19: =IF(OR(D19="",A19=""),"",A19+IF(AND(Config!$B$17="Sim",LEFT(D19,17)="Cartão de crédito"),1,IFERROR(INDEX(Config!$C$12:$C$15,MATCH(IF(AND(D19="Cartão de crédito",N(E19)>1),"Cartão de crédito parcelado",D19),Config!$A$12:$A$15,0)),0))) -> 46210 | L19: =IF(A19="","",MONTH(A19)) -> 7 | M19: =IF(A19="","",YEAR(A19)) -> 2026 | N19: =IF(K19="","",IF(G19="Sim","Conferido",IF(K19>Config!$B$8,"A cair","A conferir"))) -> Conferido | O19: =IF(N19="A conferir",(Config!$B$8-K19)*1000+N(F19)/1000+ROW()/100000,0) -> 0
A20: 46210 | B20: Beatriz Reis | C20: Avaliação endócrina | D20: Pix | F20: 400 | G20: Sim | H20: =IF(D20="","",IFERROR(INDEX(Config!$B$12:$B$15,MATCH(IF(AND(D20="Cartão de crédito",N(E20)>1),"Cartão de crédito parcelado",D20),Config!$A$12:$A$15,0)),0)+IF(AND(Config!$B$17="Sim",LEFT(D20,17)="Cartão de crédito"),Config!$B$18*IFERROR(INDEX(Config!$C$12:$C$15,MATCH(IF(AND(D20="Cartão de crédito",N(E20)>1),"Cartão de crédito parcelado",D20),Config!$A$12:$A$15,0)),0)/30*MAX(1,N(E20)),0)) -> 0 | I20: =IF(OR(D20="",F20=""),"",ROUND(F20*H20,2)) -> 0 | J20: =IF(I20="","",F20-I20) -> 400 | K20: =IF(OR(D20="",A20=""),"",A20+IF(AND(Config!$B$17="Sim",LEFT(D20,17)="Cartão de crédito"),1,IFERROR(INDEX(Config!$C$12:$C$15,MATCH(IF(AND(D20="Cartão de crédito",N(E20)>1),"Cartão de crédito parcelado",D20),Config!$A$12:$A$15,0)),0))) -> 46210 | L20: =IF(A20="","",MONTH(A20)) -> 7 | M20: =IF(A20="","",YEAR(A20)) -> 2026 | N20: =IF(K20="","",IF(G20="Sim","Conferido",IF(K20>Config!$B$8,"A cair","A conferir"))) -> Conferido | O20: =IF(N20="A conferir",(Config!$B$8-K20)*1000+N(F20)/1000+ROW()/100000,0) -> 0
A21: 46210 | B21: Marcelo Ferreira | C21: Consulta | D21: Cartão de crédito | F21: 380 | G21: Sim | H21: =IF(D21="","",IFERROR(INDEX(Config!$B$12:$B$15,MATCH(IF(AND(D21="Cartão de crédito",N(E21)>1),"Cartão de crédito parcelado",D21),Config!$A$12:$A$15,0)),0)+IF(AND(Config!$B$17="Sim",LEFT(D21,17)="Cartão de crédito"),Config!$B$18*IFERROR(INDEX(Config!$C$12:$C$15,MATCH(IF(AND(D21="Cartão de crédito",N(E21)>1),"Cartão de crédito parcelado",D21),Config!$A$12:$A$15,0)),0)/30*MAX(1,N(E21)),0)) -> 0.032 | I21: =IF(OR(D21="",F21=""),"",ROUND(F21*H21,2)) -> 12.16 | J21: =IF(I21="","",F21-I21) -> 367.84 | K21: =IF(OR(D21="",A21=""),"",A21+IF(AND(Config!$B$17="Sim",LEFT(D21,17)="Cartão de crédito"),1,IFERROR(INDEX(Config!$C$12:$C$15,MATCH(IF(AND(D21="Cartão de crédito",N(E21)>1),"Cartão de crédito parcelado",D21),Config!$A$12:$A$15,0)),0))) -> 46240 | L21: =IF(A21="","",MONTH(A21)) -> 7 | M21: =IF(A21="","",YEAR(A21)) -> 2026 | N21: =IF(K21="","",IF(G21="Sim","Conferido",IF(K21>Config!$B$8,"A cair","A conferir"))) -> Conferido | O21: =IF(N21="A conferir",(Config!$B$8-K21)*1000+N(F21)/1000+ROW()/100000,0) -> 0
A22: 46210 | B22: Lucas Cardoso | C22: Consulta | D22: Cartão de crédito | F22: 380 | G22: Sim | H22: =IF(D22="","",IFERROR(INDEX(Config!$B$12:$B$15,MATCH(IF(AND(D22="Cartão de crédito",N(E22)>1),"Cartão de crédito parcelado",D22),Config!$A$12:$A$15,0)),0)+IF(AND(Config!$B$17="Sim",LEFT(D22,17)="Cartão de crédito"),Config!$B$18*IFERROR(INDEX(Config!$C$12:$C$15,MATCH(IF(AND(D22="Cartão de crédito",N(E22)>1),"Cartão de crédito parcelado",D22),Config!$A$12:$A$15,0)),0)/30*MAX(1,N(E22)),0)) -> 0.032 | I22: =IF(OR(D22="",F22=""),"",ROUND(F22*H22,2)) -> 12.16 | J22: =IF(I22="","",F22-I22) -> 367.84 | K22: =IF(OR(D22="",A22=""),"",A22+IF(AND(Config!$B$17="Sim",LEFT(D22,17)="Cartão de crédito"),1,IFERROR(INDEX(Config!$C$12:$C$15,MATCH(IF(AND(D22="Cartão de crédito",N(E22)>1),"Cartão de crédito parcelado",D22),Config!$A$12:$A$15,0)),0))) -> 46240 | L22: =IF(A22="","",MONTH(A22)) -> 7 | M22: =IF(A22="","",YEAR(A22)) -> 2026 | N22: =IF(K22="","",IF(G22="Sim","Conferido",IF(K22>Config!$B$8,"A cair","A conferir"))) -> Conferido | O22: =IF(N22="A conferir",(Config!$B$8-K22)*1000+N(F22)/1000+ROW()/100000,0) -> 0
A23: 46211 | B23: Cláudia Santos | C23: Consulta | D23: Pix | F23: 380 | G23: Sim | H23: =IF(D23="","",IFERROR(INDEX(Config!$B$12:$B$15,MATCH(IF(AND(D23="Cartão de crédito",N(E23)>1),"Cartão de crédito parcelado",D23),Config!$A$12:$A$15,0)),0)+IF(AND(Config!$B$17="Sim",LEFT(D23,17)="Cartão de crédito"),Config!$B$18*IFERROR(INDEX(Config!$C$12:$C$15,MATCH(IF(AND(D23="Cartão de crédito",N(E23)>1),"Cartão de crédito parcelado",D23),Config!$A$12:$A$15,0)),0)/30*MAX(1,N(E23)),0)) -> 0 | I23: =IF(OR(D23="",F23=""),"",ROUND(F23*H23,2)) -> 0 | J23: =IF(I23="","",F23-I23) -> 380 | K23: =IF(OR(D23="",A23=""),"",A23+IF(AND(Config!$B$17="Sim",LEFT(D23,17)="Cartão de crédito"),1,IFERROR(INDEX(Config!$C$12:$C$15,MATCH(IF(AND(D23="Cartão de crédito",N(E23)>1),"Cartão de crédito parcelado",D23),Config!$A$12:$A$15,0)),0))) -> 46211 | L23: =IF(A23="","",MONTH(A23)) -> 7 | M23: =IF(A23="","",YEAR(A23)) -> 2026 | N23: =IF(K23="","",IF(G23="Sim","Conferido",IF(K23>Config!$B$8,"A cair","A conferir"))) -> Conferido | O23: =IF(N23="A conferir",(Config!$B$8-K23)*1000+N(F23)/1000+ROW()/100000,0) -> 0
A24: 46211 | B24: Otávio Nascimento | C24: Consulta | D24: Cartão de crédito | F24: 380 | G24: Sim | H24: =IF(D24="","",IFERROR(INDEX(Config!$B$12:$B$15,MATCH(IF(AND(D24="Cartão de crédito",N(E24)>1),"Cartão de crédito parcelado",D24),Config!$A$12:$A$15,0)),0)+IF(AND(Config!$B$17="Sim",LEFT(D24,17)="Cartão de crédito"),Config!$B$18*IFERROR(INDEX(Config!$C$12:$C$15,MATCH(IF(AND(D24="Cartão de crédito",N(E24)>1),"Cartão de crédito parcelado",D24),Config!$A$12:$A$15,0)),0)/30*MAX(1,N(E24)),0)) -> 0.032 | I24: =IF(OR(D24="",F24=""),"",ROUND(F24*H24,2)) -> 12.16 | J24: =IF(I24="","",F24-I24) -> 367.84 | K24: =IF(OR(D24="",A24=""),"",A24+IF(AND(Config!$B$17="Sim",LEFT(D24,17)="Cartão de crédito"),1,IFERROR(INDEX(Config!$C$12:$C$15,MATCH(IF(AND(D24="Cartão de crédito",N(E24)>1),"Cartão de crédito parcelado",D24),Config!$A$12:$A$15,0)),0))) -> 46241 | L24: =IF(A24="","",MONTH(A24)) -> 7 | M24: =IF(A24="","",YEAR(A24)) -> 2026 | N24: =IF(K24="","",IF(G24="Sim","Conferido",IF(K24>Config!$B$8,"A cair","A conferir"))) -> Conferido | O24: =IF(N24="A conferir",(Config!$B$8-K24)*1000+N(F24)/1000+ROW()/100000,0) -> 0
A25: 46212 | B25: Elaine Cardoso | C25: Consulta | D25: Cartão de crédito | F25: 380 | G25: Sim | H25: =IF(D25="","",IFERROR(INDEX(Config!$B$12:$B$15,MATCH(IF(AND(D25="Cartão de crédito",N(E25)>1),"Cartão de crédito parcelado",D25),Config!$A$12:$A$15,0)),0)+IF(AND(Config!$B$17="Sim",LEFT(D25,17)="Cartão de crédito"),Config!$B$18*IFERROR(INDEX(Config!$C$12:$C$15,MATCH(IF(AND(D25="Cartão de crédito",N(E25)>1),"Cartão de crédito parcelado",D25),Config!$A$12:$A$15,0)),0)/30*MAX(1,N(E25)),0)) -> 0.032 | I25: =IF(OR(D25="",F25=""),"",ROUND(F25*H25,2)) -> 12.16 | J25: =IF(I25="","",F25-I25) -> 367.84 | K25: =IF(OR(D25="",A25=""),"",A25+IF(AND(Config!$B$17="Sim",LEFT(D25,17)="Cartão de crédito"),1,IFERROR(INDEX(Config!$C$12:$C$15,MATCH(IF(AND(D25="Cartão de crédito",N(E25)>1),"Cartão de crédito parcelado",D25),Config!$A$12:$A$15,0)),0))) -> 46242 | L25: =IF(A25="","",MONTH(A25)) -> 7 | M25: =IF(A25="","",YEAR(A25)) -> 2026 | N25: =IF(K25="","",IF(G25="Sim","Conferido",IF(K25>Config!$B$8,"A cair","A conferir"))) -> Conferido | O25: =IF(N25="A conferir",(Config!$B$8-K25)*1000+N(F25)/1000+ROW()/100000,0) -> 0
A26: 46212 | B26: Roberta Araújo | C26: Consulta | D26: Pix | F26: 380 | G26: Sim | H26: =IF(D26="","",IFERROR(INDEX(Config!$B$12:$B$15,MATCH(IF(AND(D26="Cartão de crédito",N(E26)>1),"Cartão de crédito parcelado",D26),Config!$A$12:$A$15,0)),0)+IF(AND(Config!$B$17="Sim",LEFT(D26,17)="Cartão de crédito"),Config!$B$18*IFERROR(INDEX(Config!$C$12:$C$15,MATCH(IF(AND(D26="Cartão de crédito",N(E26)>1),"Cartão de crédito parcelado",D26),Config!$A$12:$A$15,0)),0)/30*MAX(1,N(E26)),0)) -> 0 | I26: =IF(OR(D26="",F26=""),"",ROUND(F26*H26,2)) -> 0 | J26: =IF(I26="","",F26-I26) -> 380 | K26: =IF(OR(D26="",A26=""),"",A26+IF(AND(Config!$B$17="Sim",LEFT(D26,17)="Cartão de crédito"),1,IFERROR(INDEX(Config!$C$12:$C$15,MATCH(IF(AND(D26="Cartão de crédito",N(E26)>1),"Cartão de crédito parcelado",D26),Config!$A$12:$A$15,0)),0))) -> 46212 | L26: =IF(A26="","",MONTH(A26)) -> 7 | M26: =IF(A26="","",YEAR(A26)) -> 2026 | N26: =IF(K26="","",IF(G26="Sim","Conferido",IF(K26>Config!$B$8,"A cair","A conferir"))) -> Conferido | O26: =IF(N26="A conferir",(Config!$B$8-K26)*1000+N(F26)/1000+ROW()/100000,0) -> 0
A27: 46212 | B27: Fábio Gomes | C27: Avaliação endócrina | D27: Cartão de crédito | F27: 400 | G27: Sim | H27: =IF(D27="","",IFERROR(INDEX(Config!$B$12:$B$15,MATCH(IF(AND(D27="Cartão de crédito",N(E27)>1),"Cartão de crédito parcelado",D27),Config!$A$12:$A$15,0)),0)+IF(AND(Config!$B$17="Sim",LEFT(D27,17)="Cartão de crédito"),Config!$B$18*IFERROR(INDEX(Config!$C$12:$C$15,MATCH(IF(AND(D27="Cartão de crédito",N(E27)>1),"Cartão de crédito parcelado",D27),Config!$A$12:$A$15,0)),0)/30*MAX(1,N(E27)),0)) -> 0.032 | I27: =IF(OR(D27="",F27=""),"",ROUND(F27*H27,2)) -> 12.8 | J27: =IF(I27="","",F27-I27) -> 387.2 | K27: =IF(OR(D27="",A27=""),"",A27+IF(AND(Config!$B$17="Sim",LEFT(D27,17)="Cartão de crédito"),1,IFERROR(INDEX(Config!$C$12:$C$15,MATCH(IF(AND(D27="Cartão de crédito",N(E27)>1),"Cartão de crédito parcelado",D27),Config!$A$12:$A$15,0)),0))) -> 46242 | L27: =IF(A27="","",MONTH(A27)) -> 7 | M27: =IF(A27="","",YEAR(A27)) -> 2026 | N27: =IF(K27="","",IF(G27="Sim","Conferido",IF(K27>Config!$B$8,"A cair","A conferir"))) -> Conferido | O27: =IF(N27="A conferir",(Config!$B$8-K27)*1000+N(F27)/1000+ROW()/100000,0) -> 0
... A35: 46216 | B35: Gisele Ribeiro | C35: ECG | D35: Cartão de crédito | F35: 130 | G35: Sim | H35: =IF(D35="","",IFERROR(INDEX(Config!$B$12:$B$15,MATCH(IF(AND(D35="Cartão de crédito",N(E35)>1),"Cartão de crédito parcelado",D35),Config!$A$12:$A$15,0)),0)+IF(AND(Config!$B$17="Sim",LEFT(D35,17)="Cartão de crédito"),Config!$B$18*IFERROR(INDEX(Config!$C$12:$C$15,MATCH(IF(AND(D35="Cartão de crédito",N(E35)>1),"Cartão de crédito parcelado",D35),Config!$A$12:$A$15,0)),0)/30*MAX(1,N(E35)),0)) -> 0.032 | I35: =IF(OR(D35="",F35=""),"",ROUND(F35*H35,2)) -> 4.16 | J35: =IF(I35="","",F35-I35) -> 125.84 | K35: =IF(OR(D35="",A35=""),"",A35+IF(AND(Config!$B$17="Sim",LEFT(D35,17)="Cartão de crédito"),1,IFERROR(INDEX(Config!$C$12:$C$15,MATCH(IF(AND(D35="Cartão de crédito",N(E35)>1),"Cartão de crédito parcelado",D35),Config!$A$12:$A$15,0)),0))) -> 46246 | L35: =IF(A35="","",MONTH(A35)) -> 7 | M35: =IF(A35="","",YEAR(A35)) -> 2026 | N35: =IF(K35="","",IF(G35="Sim","Conferido",IF(K35>Config!$B$8,"A cair","A conferir"))) -> Conferido | O35: =IF(N35="A conferir",(Config!$B$8-K35)*1000+N(F35)/1000+ROW()/100000,0) -> 0
A36: 46216 | B36: Henrique Ribeiro | C36: Consulta | D36: Cartão de crédito | E36: 2 | F36: 380 | G36: Sim | H36: =IF(D36="","",IFERROR(INDEX(Config!$B$12:$B$15,MATCH(IF(AND(D36="Cartão de crédito",N(E36)>1),"Cartão de crédito parcelado",D36),Config!$A$12:$A$15,0)),0)+IF(AND(Config!$B$17="Sim",LEFT(D36,17)="Cartão de crédito"),Config!$B$18*IFERROR(INDEX(Config!$C$12:$C$15,MATCH(IF(AND(D36="Cartão de crédito",N(E36)>1),"Cartão de crédito parcelado",D36),Config!$A$12:$A$15,0)),0)/30*MAX(1,N(E36)),0)) -> 0.039 | I36: =IF(OR(D36="",F36=""),"",ROUND(F36*H36,2)) -> 14.82 | J36: =IF(I36="","",F36-I36) -> 365.18 | K36: =IF(OR(D36="",A36=""),"",A36+IF(AND(Config!$B$17="Sim",LEFT(D36,17)="Cartão de crédito"),1,IFERROR(INDEX(Config!$C$12:$C$15,MATCH(IF(AND(D36="Cartão de crédito",N(E36)>1),"Cartão de crédito parcelado",D36),Config!$A$12:$A$15,0)),0))) -> 46246 | L36: =IF(A36="","",MONTH(A36)) -> 7 | M36: =IF(A36="","",YEAR(A36)) -> 2026 | N36: =IF(K36="","",IF(G36="Sim","Conferido",IF(K36>Config!$B$8,"A cair","A conferir"))) -> Conferido | O36: =IF(N36="A conferir",(Config!$B$8-K36)*1000+N(F36)/1000+ROW()/100000,0) -> 0
A37: 46216 | B37: Gabriel Oliveira | C37: Consulta | D37: Pix | F37: 380 | G37: Sim | H37: =IF(D37="","",IFERROR(INDEX(Config!$B$12:$B$15,MATCH(IF(AND(D37="Cartão de crédito",N(E37)>1),"Cartão de crédito parcelado",D37),Config!$A$12:$A$15,0)),0)+IF(AND(Config!$B$17="Sim",LEFT(D37,17)="Cartão de crédito"),Config!$B$18*IFERROR(INDEX(Config!$C$12:$C$15,MATCH(IF(AND(D37="Cartão de crédito",N(E37)>1),"Cartão de crédito parcelado",D37),Config!$A$12:$A$15,0)),0)/30*MAX(1,N(E37)),0)) -> 0 | I37: =IF(OR(D37="",F37=""),"",ROUND(F37*H37,2)) -> 0 | J37: =IF(I37="","",F37-I37) -> 380 | K37: =IF(OR(D37="",A37=""),"",A37+IF(AND(Config!$B$17="Sim",LEFT(D37,17)="Cartão de crédito"),1,IFERROR(INDEX(Config!$C$12:$C$15,MATCH(IF(AND(D37="Cartão de crédito",N(E37)>1),"Cartão de crédito parcelado",D37),Config!$A$12:$A$15,0)),0))) -> 46216 | L37: =IF(A37="","",MONTH(A37)) -> 7 | M37: =IF(A37="","",YEAR(A37)) -> 2026 | N37: =IF(K37="","",IF(G37="Sim","Conferido",IF(K37>Config!$B$8,"A cair","A conferir"))) -> Conferido | O37: =IF(N37="A conferir",(Config!$B$8-K37)*1000+N(F37)/1000+ROW()/100000,0) -> 0
A38: 46217 | B38: Regina Teixeira | C38: Consulta | D38: Pix | F38: 380 | G38: Sim | H38: =IF(D38="","",IFERROR(INDEX(Config!$B$12:$B$15,MATCH(IF(AND(D38="Cartão de crédito",N(E38)>1),"Cartão de crédito parcelado",D38),Config!$A$12:$A$15,0)),0)+IF(AND(Config!$B$17="Sim",LEFT(D38,17)="Cartão de crédito"),Config!$B$18*IFERROR(INDEX(Config!$C$12:$C$15,MATCH(IF(AND(D38="Cartão de crédito",N(E38)>1),"Cartão de crédito parcelado",D38),Config!$A$12:$A$15,0)),0)/30*MAX(1,N(E38)),0)) -> 0 | I38: =IF(OR(D38="",F38=""),"",ROUND(F38*H38,2)) -> 0 | J38: =IF(I38="","",F38-I38) -> 380 | K38: =IF(OR(D38="",A38=""),"",A38+IF(AND(Config!$B$17="Sim",LEFT(D38,17)="Cartão de crédito"),1,IFERROR(INDEX(Config!$C$12:$C$15,MATCH(IF(AND(D38="Cartão de crédito",N(E38)>1),"Cartão de crédito parcelado",D38),Config!$A$12:$A$15,0)),0))) -> 46217 | L38: =IF(A38="","",MONTH(A38)) -> 7 | M38: =IF(A38="","",YEAR(A38)) -> 2026 | N38: =IF(K38="","",IF(G38="Sim","Conferido",IF(K38>Config!$B$8,"A cair","A conferir"))) -> Conferido | O38: =IF(N38="A conferir",(Config!$B$8-K38)*1000+N(F38)/1000+ROW()/100000,0) -> 0
A39: 46217 | B39: Priscila Reis | C39: Avaliação endócrina | D39: Pix | F39: 400 | G39: Sim | H39: =IF(D39="","",IFERROR(INDEX(Config!$B$12:$B$15,MATCH(IF(AND(D39="Cartão de crédito",N(E39)>1),"Cartão de crédito parcelado",D39),Config!$A$12:$A$15,0)),0)+IF(AND(Config!$B$17="Sim",LEFT(D39,17)="Cartão de crédito"),Config!$B$18*IFERROR(INDEX(Config!$C$12:$C$15,MATCH(IF(AND(D39="Cartão de crédito",N(E39)>1),"Cartão de crédito parcelado",D39),Config!$A$12:$A$15,0)),0)/30*MAX(1,N(E39)),0)) -> 0 | I39: =IF(OR(D39="",F39=""),"",ROUND(F39*H39,2)) -> 0 | J39: =IF(I39="","",F39-I39) -> 400 | K39: =IF(OR(D39="",A39=""),"",A39+IF(AND(Config!$B$17="Sim",LEFT(D39,17)="Cartão de crédito"),1,IFERROR(INDEX(Config!$C$12:$C$15,MATCH(IF(AND(D39="Cartão de crédito",N(E39)>1),"Cartão de crédito parcelado",D39),Config!$A$12:$A$15,0)),0))) -> 46217 | L39: =IF(A39="","",MONTH(A39)) -> 7 | M39: =IF(A39="","",YEAR(A39)) -> 2026 | N39: =IF(K39="","",IF(G39="Sim","Conferido",IF(K39>Config!$B$8,"A cair","A conferir"))) -> Conferido | O39: =IF(N39="A conferir",(Config!$B$8-K39)*1000+N(F39)/1000+ROW()/100000,0) -> 0
A40: 46217 | B40: Cláudia Melo | C40: Avaliação endócrina | D40: Cartão de crédito | F40: 400 | G40: Sim | H40: =IF(D40="","",IFERROR(INDEX(Config!$B$12:$B$15,MATCH(IF(AND(D40="Cartão de crédito",N(E40)>1),"Cartão de crédito parcelado",D40),Config!$A$12:$A$15,0)),0)+IF(AND(Config!$B$17="Sim",LEFT(D40,17)="Cartão de crédito"),Config!$B$18*IFERROR(INDEX(Config!$C$12:$C$15,MATCH(IF(AND(D40="Cartão de crédito",N(E40)>1),"Cartão de crédito parcelado",D40),Config!$A$12:$A$15,0)),0)/30*MAX(1,N(E40)),0)) -> 0.032 | I40: =IF(OR(D40="",F40=""),"",ROUND(F40*H40,2)) -> 12.8 | J40: =IF(I40="","",F40-I40) -> 387.2 | K40: =IF(OR(D40="",A40=""),"",A40+IF(AND(Config!$B$17="Sim",LEFT(D40,17)="Cartão de crédito"),1,IFERROR(INDEX(Config!$C$12:$C$15,MATCH(IF(AND(D40="Cartão de crédito",N(E40)>1),"Cartão de crédito parcelado",D40),Config!$A$12:$A$15,0)),0))) -> 46247 | L40: =IF(A40="","",MONTH(A40)) -> 7 | M40: =IF(A40="","",YEAR(A40)) -> 2026 | N40: =IF(K40="","",IF(G40="Sim","Conferido",IF(K40>Config!$B$8,"A cair","A conferir"))) -> Conferido | O40: =IF(N40="A conferir",(Config!$B$8-K40)*1000+N(F40)/1000+ROW()/100000,0) -> 0
A41: 46217 | B41: Rafael Dias | C41: ECG | D41: Cartão de crédito | F41: 130 | G41: Sim | H41: =IF(D41="","",IFERROR(INDEX(Config!$B$12:$B$15,MATCH(IF(AND(D41="Cartão de crédito",N(E41)>1),"Cartão de crédito parcelado",D41),Config!$A$12:$A$15,0)),0)+IF(AND(Config!$B$17="Sim",LEFT(D41,17)="Cartão de crédito"),Config!$B$18*IFERROR(INDEX(Config!$C$12:$C$15,MATCH(IF(AND(D41="Cartão de crédito",N(E41)>1),"Cartão de crédito parcelado",D41),Config!$A$12:$A$15,0)),0)/30*MAX(1,N(E41)),0)) -> 0.032 | I41: =IF(OR(D41="",F41=""),"",ROUND(F41*H41,2)) -> 4.16 | J41: =IF(I41="","",F41-I41) -> 125.84 | K41: =IF(OR(D41="",A41=""),"",A41+IF(AND(Config!$B$17="Sim",LEFT(D41,17)="Cartão de crédito"),1,IFERROR(INDEX(Config!$C$12:$C$15,MATCH(IF(AND(D41="Cartão de crédito",N(E41)>1),"Cartão de crédito parcelado",D41),Config!$A$12:$A$15,0)),0))) -> 46247 | L41: =IF(A41="","",MONTH(A41)) -> 7 | M41: =IF(A41="","",YEAR(A41)) -> 2026 | N41: =IF(K41="","",IF(G41="Sim","Conferido",IF(K41>Config!$B$8,"A cair","A conferir"))) -> Conferido | O41: =IF(N41="A conferir",(Config!$B$8-K41)*1000+N(F41)/1000+ROW()/100000,0) -> 0
A42: 46217 | B42: Mônica Martins | C42: ECG | D42: Pix | F42: 130 | G42: Sim | H42: =IF(D42="","",IFERROR(INDEX(Config!$B$12:$B$15,MATCH(IF(AND(D42="Cartão de crédito",N(E42)>1),"Cartão de crédito parcelado",D42),Config!$A$12:$A$15,0)),0)+IF(AND(Config!$B$17="Sim",LEFT(D42,17)="Cartão de crédito"),Config!$B$18*IFERROR(INDEX(Config!$C$12:$C$15,MATCH(IF(AND(D42="Cartão de crédito",N(E42)>1),"Cartão de crédito parcelado",D42),Config!$A$12:$A$15,0)),0)/30*MAX(1,N(E42)),0)) -> 0 | I42: =IF(OR(D42="",F42=""),"",ROUND(F42*H42,2)) -> 0 | J42: =IF(I42="","",F42-I42) -> 130 | K42: =IF(OR(D42="",A42=""),"",A42+IF(AND(Config!$B$17="Sim",LEFT(D42,17)="Cartão de crédito"),1,IFERROR(INDEX(Config!$C$12:$C$15,MATCH(IF(AND(D42="Cartão de crédito",N(E42)>1),"Cartão de crédito parcelado",D42),Config!$A$12:$A$15,0)),0))) -> 46217 | L42: =IF(A42="","",MONTH(A42)) -> 7 | M42: =IF(A42="","",YEAR(A42)) -> 2026 | N42: =IF(K42="","",IF(G42="Sim","Conferido",IF(K42>Config!$B$8,"A cair","A conferir"))) -> Conferido | O42: =IF(N42="A conferir",(Config!$B$8-K42)*1000+N(F42)/1000+ROW()/100000,0) -> 0
