Workbook

Sheet Como usar
A1: Projetos e Prazos
A2: Kit IA no Trabalho · Completo · Seu Sócio Gestor · versão 1.0 (setembro de 2026)
A4: O que esta planilha faz | B4: Você cadastra os projetos e as etapas de cada um; ela diz o que está atrasado, o que vence em breve, quanto cada projeto avançou, quem está sobrecarregado e desenha a linha do tempo por semanas.
A5: Passo 1 | B5: Em Config, preencha o nome da equipe, troque a data de referência por =HOJE() (no exemplo ela está congelada em 14/09/2026), cadastre até 10 projetos (nome, cliente, responsável, início e prazo final) e as pessoas da equipe.
A6: Passo 2 | B6: Em Etapas, uma linha por etapa: projeto (lista), etapa, responsável (lista), início, fim previsto e % concluído. Quando terminar, marque 100% ou preencha o fim real.
A7: Passo 3 | B7: Em Painel, veja os projetos com atraso, a lista do que fazer primeiro e a carga por pessoa. Em Linha do tempo, veja as próximas 14 semanas.
A8: Rotina | B8: Segunda-feira, 10 minutos: atualize o % das etapas em andamento e olhe o Painel. Sexta: registre o que fechou.
A9: Com a IA | B9: Copie a tabela "O que fazer primeiro" e use o prompt "Organizar 03: prioridade quando tudo parece urgente". Para o cliente, copie "Por projeto" e use "Escrever 04: justificativa" ou "Escrever 07: resumo para quem não foi".
A10: Legenda | B10: Células amarelas: você preenche. Brancas: calculadas. Não é preciso mexer em nada fora do amarelo.
A11: Proteção | B11: Fórmulas protegidas sem senha. Para editar: Revisar > Desproteger planilha (Excel) ou Dados > Proteger intervalos (Google Sheets).
A12: Requisitos | B12: Excel 2016 ou mais novo, Microsoft 365 ou Google Sheets (só funções do Excel 2007+; nada de MÍNIMOSES, MÁXIMOSES ou UNIRTEXTO). No celular abre nos aplicativos; para preencher, use o computador.
A13: Google Sheets | B13: Faça upload no Google Drive e abra com o Google Sheets. Fórmulas, listas, cores e semáforos funcionam: as regras de cor que dependem do mês escolhido em Config usam INDIRECT, que é a forma que o Sheets aceita para regra condicional apontar para outra aba.
A14: Data de referência | B14: O exemplo está congelado em 14/09/2026, para todos os arquivos do kit mostrarem a mesma foto e os números fecharem entre eles. Ao começar a usar com os SEUS dados, troque em Config: a data de referência por =HOJE(), o ano, o mês do painel, o trimestre (onde houver) e a lista de feriados. Trocar só a data de referência deixa o resto apontando para 2026.
A15: Exemplos | B15: Prisma Comunicação é uma empresa fictícia. Nomes e valores são inventados. Apague-os antes de começar.
A16: Suporte | B16: suporte@seusociogestor.com.br · resposta em até 5 dias úteis · reembolso em até 7 dias pelo mesmo canal.

Sheet Painel
A1: =Config!B4&" · painel de "&TEXT(DAY(Config!B5),"00")&"/"&TEXT(MONTH(Config!B5),"00")&"/"&YEAR(Config!B5) -> Prisma Comunicação (exemplo fictício) · painel de 14/09/2026
A2: Nada para preencher aqui: tudo vem de Config e Etapas.
A4: Projetos ativos | C4: Etapas atrasadas | E4: Vencem em breve | G4: Concluído (média)
A5: =COUNTIFS(Config!$F$10:$F$19,"No prazo")+COUNTIFS(Config!$F$10:$F$19,"Com atraso") -> 4 | C5: =COUNTIFS(Etapas!$G$5:$G$304,"Atrasada") -> 2 | E5: =COUNTIFS(Etapas!$G$5:$G$304,"Vence em breve") -> 3 | G5: =IFERROR(AVERAGEIFS(Etapas!$L$5:$L$304,Etapas!$B$5:$B$304,"<>"),0) -> 0.545
A6: =IF(COUNTIF(Etapas!$G$5:$G$304,"Falta o prazo")=0,"","Atenção: "&COUNTIF(Etapas!$G$5:$G$304,"Falta o prazo")&" etapa(s) sem fim previsto na aba Etapas (em cinza lá). Elas não entram em atrasadas nem em 'vence em breve' até você preencher o prazo.")
A7: Por projeto
A8: Projeto | B8: Responsável | C8: Prazo final | D8: Etapas | E8: Concluídas | F8: Atrasadas | G8: % médio | H8: Situação
A9: =IF(Config!$A$10="","",Config!$A$10) -> Site novo · Loja Verde | B9: =IF(Config!$A$10="","",Config!$C$10) -> Ana | C9: =IF(Config!$A$10="","",Config!$E$10) -> 46304 | D9: =IF(Config!$A$10="","",COUNTIFS(Etapas!$A$5:$A$304,Config!$A$10)) -> 7 | E9: =IF(Config!$A$10="","",COUNTIFS(Etapas!$A$5:$A$304,Config!$A$10,Etapas!$G$5:$G$304,"Concluída")) -> 3 | F9: =IF(Config!$A$10="","",COUNTIFS(Etapas!$A$5:$A$304,Config!$A$10,Etapas!$G$5:$G$304,"Atrasada")) -> 1 | G9: =IF(OR(Config!$A$10="",D9=0),"",AVERAGEIFS(Etapas!$L$5:$L$304,Etapas!$A$5:$A$304,Config!$A$10)) -> 0.61428571 | H9: =IF(Config!$A$10="","",Config!$F$10) -> Com atraso
A10: =IF(Config!$A$11="","",Config!$A$11) -> Campanha de fim de ano · Bistrô 42 | B10: =IF(Config!$A$11="","",Config!$C$11) -> Carla | C10: =IF(Config!$A$11="","",Config!$E$11) -> 46346 | D10: =IF(Config!$A$11="","",COUNTIFS(Etapas!$A$5:$A$304,Config!$A$11)) -> 5 | E10: =IF(Config!$A$11="","",COUNTIFS(Etapas!$A$5:$A$304,Config!$A$11,Etapas!$G$5:$G$304,"Concluída")) -> 1 | F10: =IF(Config!$A$11="","",COUNTIFS(Etapas!$A$5:$A$304,Config!$A$11,Etapas!$G$5:$G$304,"Atrasada")) -> 0 | G10: =IF(OR(Config!$A$11="",D10=0),"",AVERAGEIFS(Etapas!$L$5:$L$304,Etapas!$A$5:$A$304,Config!$A$11)) -> 0.3 | H10: =IF(Config!$A$11="","",Config!$F$11) -> No prazo
A11: =IF(Config!$A$12="","",Config!$A$12) -> Relatório anual · Horizonte | B11: =IF(Config!$A$12="","",Config!$C$12) -> Ana | C11: =IF(Config!$A$12="","",Config!$E$12) -> 46295 | D11: =IF(Config!$A$12="","",COUNTIFS(Etapas!$A$5:$A$304,Config!$A$12)) -> 4 | E11: =IF(Config!$A$12="","",COUNTIFS(Etapas!$A$5:$A$304,Config!$A$12,Etapas!$G$5:$G$304,"Concluída")) -> 1 | F11: =IF(Config!$A$12="","",COUNTIFS(Etapas!$A$5:$A$304,Config!$A$12,Etapas!$G$5:$G$304,"Atrasada")) -> 0 | G11: =IF(OR(Config!$A$12="",D11=0),"",AVERAGEIFS(Etapas!$L$5:$L$304,Etapas!$A$5:$A$304,Config!$A$12)) -> 0.325 | H11: =IF(Config!$A$12="","",Config!$F$12) -> No prazo
A12: =IF(Config!$A$13="","",Config!$A$13) -> Identidade visual · Padaria do Sol | B12: =IF(Config!$A$13="","",Config!$C$13) -> Bruno | C12: =IF(Config!$A$13="","",Config!$E$13) -> 46270 | D12: =IF(Config!$A$13="","",COUNTIFS(Etapas!$A$5:$A$304,Config!$A$13)) -> 4 | E12: =IF(Config!$A$13="","",COUNTIFS(Etapas!$A$5:$A$304,Config!$A$13,Etapas!$G$5:$G$304,"Concluída")) -> 3 | F12: =IF(Config!$A$13="","",COUNTIFS(Etapas!$A$5:$A$304,Config!$A$13,Etapas!$G$5:$G$304,"Atrasada")) -> 1 | G12: =IF(OR(Config!$A$13="",D12=0),"",AVERAGEIFS(Etapas!$L$5:$L$304,Etapas!$A$5:$A$304,Config!$A$13)) -> 0.95 | H12: =IF(Config!$A$13="","",Config!$F$13) -> Com atraso
A13: =IF(Config!$A$14="","",Config!$A$14) | B13: =IF(Config!$A$14="","",Config!$C$14) | C13: =IF(Config!$A$14="","",Config!$E$14) | D13: =IF(Config!$A$14="","",COUNTIFS(Etapas!$A$5:$A$304,Config!$A$14)) | E13: =IF(Config!$A$14="","",COUNTIFS(Etapas!$A$5:$A$304,Config!$A$14,Etapas!$G$5:$G$304,"Concluída")) | F13: =IF(Config!$A$14="","",COUNTIFS(Etapas!$A$5:$A$304,Config!$A$14,Etapas!$G$5:$G$304,"Atrasada")) | G13: =IF(OR(Config!$A$14="",D13=0),"",AVERAGEIFS(Etapas!$L$5:$L$304,Etapas!$A$5:$A$304,Config!$A$14)) | H13: =IF(Config!$A$14="","",Config!$F$14)
A14: =IF(Config!$A$15="","",Config!$A$15) | B14: =IF(Config!$A$15="","",Config!$C$15) | C14: =IF(Config!$A$15="","",Config!$E$15) | D14: =IF(Config!$A$15="","",COUNTIFS(Etapas!$A$5:$A$304,Config!$A$15)) | E14: =IF(Config!$A$15="","",COUNTIFS(Etapas!$A$5:$A$304,Config!$A$15,Etapas!$G$5:$G$304,"Concluída")) | F14: =IF(Config!$A$15="","",COUNTIFS(Etapas!$A$5:$A$304,Config!$A$15,Etapas!$G$5:$G$304,"Atrasada")) | G14: =IF(OR(Config!$A$15="",D14=0),"",AVERAGEIFS(Etapas!$L$5:$L$304,Etapas!$A$5:$A$304,Config!$A$15)) | H14: =IF(Config!$A$15="","",Config!$F$15)
A15: =IF(Config!$A$16="","",Config!$A$16) | B15: =IF(Config!$A$16="","",Config!$C$16) | C15: =IF(Config!$A$16="","",Config!$E$16) | D15: =IF(Config!$A$16="","",COUNTIFS(Etapas!$A$5:$A$304,Config!$A$16)) | E15: =IF(Config!$A$16="","",COUNTIFS(Etapas!$A$5:$A$304,Config!$A$16,Etapas!$G$5:$G$304,"Concluída")) | F15: =IF(Config!$A$16="","",COUNTIFS(Etapas!$A$5:$A$304,Config!$A$16,Etapas!$G$5:$G$304,"Atrasada")) | G15: =IF(OR(Config!$A$16="",D15=0),"",AVERAGEIFS(Etapas!$L$5:$L$304,Etapas!$A$5:$A$304,Config!$A$16)) | H15: =IF(Config!$A$16="","",Config!$F$16)
A16: =IF(Config!$A$17="","",Config!$A$17) | B16: =IF(Config!$A$17="","",Config!$C$17) | C16: =IF(Config!$A$17="","",Config!$E$17) | D16: =IF(Config!$A$17="","",COUNTIFS(Etapas!$A$5:$A$304,Config!$A$17)) | E16: =IF(Config!$A$17="","",COUNTIFS(Etapas!$A$5:$A$304,Config!$A$17,Etapas!$G$5:$G$304,"Concluída")) | F16: =IF(Config!$A$17="","",COUNTIFS(Etapas!$A$5:$A$304,Config!$A$17,Etapas!$G$5:$G$304,"Atrasada")) | G16: =IF(OR(Config!$A$17="",D16=0),"",AVERAGEIFS(Etapas!$L$5:$L$304,Etapas!$A$5:$A$304,Config!$A$17)) | H16: =IF(Config!$A$17="","",Config!$F$17)
A17: =IF(Config!$A$18="","",Config!$A$18) | B17: =IF(Config!$A$18="","",Config!$C$18) | C17: =IF(Config!$A$18="","",Config!$E$18) | D17: =IF(Config!$A$18="","",COUNTIFS(Etapas!$A$5:$A$304,Config!$A$18)) | E17: =IF(Config!$A$18="","",COUNTIFS(Etapas!$A$5:$A$304,Config!$A$18,Etapas!$G$5:$G$304,"Concluída")) | F17: =IF(Config!$A$18="","",COUNTIFS(Etapas!$A$5:$A$304,Config!$A$18,Etapas!$G$5:$G$304,"Atrasada")) | G17: =IF(OR(Config!$A$18="",D17=0),"",AVERAGEIFS(Etapas!$L$5:$L$304,Etapas!$A$5:$A$304,Config!$A$18)) | H17: =IF(Config!$A$18="","",Config!$F$18)
A18: =IF(Config!$A$19="","",Config!$A$19) | B18: =IF(Config!$A$19="","",Config!$C$19) | C18: =IF(Config!$A$19="","",Config!$E$19) | D18: =IF(Config!$A$19="","",COUNTIFS(Etapas!$A$5:$A$304,Config!$A$19)) | E18: =IF(Config!$A$19="","",COUNTIFS(Etapas!$A$5:$A$304,Config!$A$19,Etapas!$G$5:$G$304,"Concluída")) | F18: =IF(Config!$A$19="","",COUNTIFS(Etapas!$A$5:$A$304,Config!$A$19,Etapas!$G$5:$G$304,"Atrasada")) | G18: =IF(OR(Config!$A$19="",D18=0),"",AVERAGEIFS(Etapas!$L$5:$L$304,Etapas!$A$5:$A$304,Config!$A$19)) | H18: =IF(Config!$A$19="","",Config!$F$19)
A20: O que fazer primeiro
A21: Ordem: atrasadas (mais tempo de atraso primeiro), depois as que vencem em breve, depois em andamento.
A22: # | B22: Projeto | C22: Etapa | D22: Responsável | E22: Fim previsto | F22: Situação | G22: Dias | H22: % feito
A23: 1 | B23: =IFERROR(IF(LARGE(Etapas!$K$5:$K$304,1)>0,INDEX(Etapas!$A$5:$A$304,MATCH(LARGE(Etapas!$K$5:$K$304,1),Etapas!$K$5:$K$304,0)),""),"") -> Identidade visual · Padaria do Sol | C23: =IFERROR(IF(LARGE(Etapas!$K$5:$K$304,1)>0,INDEX(Etapas!$B$5:$B$304,MATCH(LARGE(Etapas!$K$5:$K$304,1),Etapas!$K$5:$K$304,0)),""),"") -> Manual da marca | D23: =IFERROR(IF(LARGE(Etapas!$K$5:$K$304,1)>0,INDEX(Etapas!$C$5:$C$304,MATCH(LARGE(Etapas!$K$5:$K$304,1),Etapas!$K$5:$K$304,0)),""),"") -> Carla | E23: =IFERROR(IF(LARGE(Etapas!$K$5:$K$304,1)>0,INDEX(Etapas!$E$5:$E$304,MATCH(LARGE(Etapas!$K$5:$K$304,1),Etapas!$K$5:$K$304,0)),""),"") -> 46270 | F23: =IFERROR(IF(LARGE(Etapas!$K$5:$K$304,1)>0,INDEX(Etapas!$G$5:$G$304,MATCH(LARGE(Etapas!$K$5:$K$304,1),Etapas!$K$5:$K$304,0)),""),"") -> Atrasada | G23: =IFERROR(IF(LARGE(Etapas!$K$5:$K$304,1)>0,INDEX(Etapas!$H$5:$H$304,MATCH(LARGE(Etapas!$K$5:$K$304,1),Etapas!$K$5:$K$304,0)),""),"") -> -9 | H23: =IFERROR(IF(LARGE(Etapas!$K$5:$K$304,1)>0,INDEX(Etapas!$F$5:$F$304,MATCH(LARGE(Etapas!$K$5:$K$304,1),Etapas!$K$5:$K$304,0)),""),"") -> 0.8
A24: 2 | B24: =IFERROR(IF(LARGE(Etapas!$K$5:$K$304,2)>0,INDEX(Etapas!$A$5:$A$304,MATCH(LARGE(Etapas!$K$5:$K$304,2),Etapas!$K$5:$K$304,0)),""),"") -> Site novo · Loja Verde | C24: =IFERROR(IF(LARGE(Etapas!$K$5:$K$304,2)>0,INDEX(Etapas!$B$5:$B$304,MATCH(LARGE(Etapas!$K$5:$K$304,2),Etapas!$K$5:$K$304,0)),""),"") -> Textos das páginas | D24: =IFERROR(IF(LARGE(Etapas!$K$5:$K$304,2)>0,INDEX(Etapas!$C$5:$C$304,MATCH(LARGE(Etapas!$K$5:$K$304,2),Etapas!$K$5:$K$304,0)),""),"") -> Carla | E24: =IFERROR(IF(LARGE(Etapas!$K$5:$K$304,2)>0,INDEX(Etapas!$E$5:$E$304,MATCH(LARGE(Etapas!$K$5:$K$304,2),Etapas!$K$5:$K$304,0)),""),"") -> 46277 | F24: =IFERROR(IF(LARGE(Etapas!$K$5:$K$304,2)>0,INDEX(Etapas!$G$5:$G$304,MATCH(LARGE(Etapas!$K$5:$K$304,2),Etapas!$K$5:$K$304,0)),""),"") -> Atrasada | G24: =IFERROR(IF(LARGE(Etapas!$K$5:$K$304,2)>0,INDEX(Etapas!$H$5:$H$304,MATCH(LARGE(Etapas!$K$5:$K$304,2),Etapas!$K$5:$K$304,0)),""),"") -> -2 | H24: =IFERROR(IF(LARGE(Etapas!$K$5:$K$304,2)>0,INDEX(Etapas!$F$5:$F$304,MATCH(LARGE(Etapas!$K$5:$K$304,2),Etapas!$K$5:$K$304,0)),""),"") -> 0.7
A25: 3 | B25: =IFERROR(IF(LARGE(Etapas!$K$5:$K$304,3)>0,INDEX(Etapas!$A$5:$A$304,MATCH(LARGE(Etapas!$K$5:$K$304,3),Etapas!$K$5:$K$304,0)),""),"") -> Campanha de fim de ano · Bistrô 42 | C25: =IFERROR(IF(LARGE(Etapas!$K$5:$K$304,3)>0,INDEX(Etapas!$B$5:$B$304,MATCH(LARGE(Etapas!$K$5:$K$304,3),Etapas!$K$5:$K$304,0)),""),"") -> Aprovação do cliente | D25: =IFERROR(IF(LARGE(Etapas!$K$5:$K$304,3)>0,INDEX(Etapas!$C$5:$C$304,MATCH(LARGE(Etapas!$K$5:$K$304,3),Etapas!$K$5:$K$304,0)),""),"") -> Carla | E25: =IFERROR(IF(LARGE(Etapas!$K$5:$K$304,3)>0,INDEX(Etapas!$E$5:$E$304,MATCH(LARGE(Etapas!$K$5:$K$304,3),Etapas!$K$5:$K$304,0)),""),"") -> 46282 | F25: =IFERROR(IF(LARGE(Etapas!$K$5:$K$304,3)>0,INDEX(Etapas!$G$5:$G$304,MATCH(LARGE(Etapas!$K$5:$K$304,3),Etapas!$K$5:$K$304,0)),""),"") -> Vence em breve | G25: =IFERROR(IF(LARGE(Etapas!$K$5:$K$304,3)>0,INDEX(Etapas!$H$5:$H$304,MATCH(LARGE(Etapas!$K$5:$K$304,3),Etapas!$K$5:$K$304,0)),""),"") -> 3 | H25: =IFERROR(IF(LARGE(Etapas!$K$5:$K$304,3)>0,INDEX(Etapas!$F$5:$F$304,MATCH(LARGE(Etapas!$K$5:$K$304,3),Etapas!$K$5:$K$304,0)),""),"") -> 0.5
A26: 4 | B26: =IFERROR(IF(LARGE(Etapas!$K$5:$K$304,4)>0,INDEX(Etapas!$A$5:$A$304,MATCH(LARGE(Etapas!$K$5:$K$304,4),Etapas!$K$5:$K$304,0)),""),"") -> Site novo · Loja Verde | C26: =IFERROR(IF(LARGE(Etapas!$K$5:$K$304,4)>0,INDEX(Etapas!$B$5:$B$304,MATCH(LARGE(Etapas!$K$5:$K$304,4),Etapas!$K$5:$K$304,0)),""),"") -> Layout das páginas internas | D26: =IFERROR(IF(LARGE(Etapas!$K$5:$K$304,4)>0,INDEX(Etapas!$C$5:$C$304,MATCH(LARGE(Etapas!$K$5:$K$304,4),Etapas!$K$5:$K$304,0)),""),"") -> Bruno | E26: =IFERROR(IF(LARGE(Etapas!$K$5:$K$304,4)>0,INDEX(Etapas!$E$5:$E$304,MATCH(LARGE(Etapas!$K$5:$K$304,4),Etapas!$K$5:$K$304,0)),""),"") -> 46284 | F26: =IFERROR(IF(LARGE(Etapas!$K$5:$K$304,4)>0,INDEX(Etapas!$G$5:$G$304,MATCH(LARGE(Etapas!$K$5:$K$304,4),Etapas!$K$5:$K$304,0)),""),"") -> Vence em breve | G26: =IFERROR(IF(LARGE(Etapas!$K$5:$K$304,4)>0,INDEX(Etapas!$H$5:$H$304,MATCH(LARGE(Etapas!$K$5:$K$304,4),Etapas!$K$5:$K$304,0)),""),"") -> 5 | H26: =IFERROR(IF(LARGE(Etapas!$K$5:$K$304,4)>0,INDEX(Etapas!$F$5:$F$304,MATCH(LARGE(Etapas!$K$5:$K$304,4),Etapas!$K$5:$K$304,0)),""),"") -> 0.6
A27: 5 | B27: =IFERROR(IF(LARGE(Etapas!$K$5:$K$304,5)>0,INDEX(Etapas!$A$5:$A$304,MATCH(LARGE(Etapas!$K$5:$K$304,5),Etapas!$K$5:$K$304,0)),""),"") -> Relatório anual · Horizonte | C27: =IFERROR(IF(LARGE(Etapas!$K$5:$K$304,5)>0,INDEX(Etapas!$B$5:$B$304,MATCH(LARGE(Etapas!$K$5:$K$304,5),Etapas!$K$5:$K$304,0)),""),"") -> Redação | D27: =IFERROR(IF(LARGE(Etapas!$K$5:$K$304,5)>0,INDEX(Etapas!$C$5:$C$304,MATCH(LARGE(Etapas!$K$5:$K$304,5),Etapas!$K$5:$K$304,0)),""),"") -> Ana | E27: =IFERROR(IF(LARGE(Etapas!$K$5:$K$304,5)>0,INDEX(Etapas!$E$5:$E$304,MATCH(LARGE(Etapas!$K$5:$K$304,5),Etapas!$K$5:$K$304,0)),""),"") -> 46284 | F27: =IFERROR(IF(LARGE(Etapas!$K$5:$K$304,5)>0,INDEX(Etapas!$G$5:$G$304,MATCH(LARGE(Etapas!$K$5:$K$304,5),Etapas!$K$5:$K$304,0)),""),"") -> Vence em breve | G27: =IFERROR(IF(LARGE(Etapas!$K$5:$K$304,5)>0,INDEX(Etapas!$H$5:$H$304,MATCH(LARGE(Etapas!$K$5:$K$304,5),Etapas!$K$5:$K$304,0)),""),"") -> 5 | H27: =IFERROR(IF(LARGE(Etapas!$K$5:$K$304,5)>0,INDEX(Etapas!$F$5:$F$304,MATCH(LARGE(Etapas!$K$5:$K$304,5),Etapas!$K$5:$K$304,0)),""),"") -> 0.3
A28: 6 | B28: =IFERROR(IF(LARGE(Etapas!$K$5:$K$304,6)>0,INDEX(Etapas!$A$5:$A$304,MATCH(LARGE(Etapas!$K$5:$K$304,6),Etapas!$K$5:$K$304,0)),""),"") -> Site novo · Loja Verde | C28: =IFERROR(IF(LARGE(Etapas!$K$5:$K$304,6)>0,INDEX(Etapas!$B$5:$B$304,MATCH(LARGE(Etapas!$K$5:$K$304,6),Etapas!$K$5:$K$304,0)),""),"") -> Implementação | D28: =IFERROR(IF(LARGE(Etapas!$K$5:$K$304,6)>0,INDEX(Etapas!$C$5:$C$304,MATCH(LARGE(Etapas!$K$5:$K$304,6),Etapas!$K$5:$K$304,0)),""),"") -> Diego | E28: =IFERROR(IF(LARGE(Etapas!$K$5:$K$304,6)>0,INDEX(Etapas!$E$5:$E$304,MATCH(LARGE(Etapas!$K$5:$K$304,6),Etapas!$K$5:$K$304,0)),""),"") -> 46298 | F28: =IFERROR(IF(LARGE(Etapas!$K$5:$K$304,6)>0,INDEX(Etapas!$G$5:$G$304,MATCH(LARGE(Etapas!$K$5:$K$304,6),Etapas!$K$5:$K$304,0)),""),"") -> A iniciar | G28: =IFERROR(IF(LARGE(Etapas!$K$5:$K$304,6)>0,INDEX(Etapas!$H$5:$H$304,MATCH(LARGE(Etapas!$K$5:$K$304,6),Etapas!$K$5:$K$304,0)),""),"") -> 19 | H28: =IFERROR(IF(LARGE(Etapas!$K$5:$K$304,6)>0,INDEX(Etapas!$F$5:$F$304,MATCH(LARGE(Etapas!$K$5:$K$304,6),Etapas!$K$5:$K$304,0)),""),"") -> 0
A29: 7 | B29: =IFERROR(IF(LARGE(Etapas!$K$5:$K$304,7)>0,INDEX(Etapas!$A$5:$A$304,MATCH(LARGE(Etapas!$K$5:$K$304,7),Etapas!$K$5:$K$304,0)),""),"") -> Site novo · Loja Verde | C29: =IFERROR(IF(LARGE(Etapas!$K$5:$K$304,7)>0,INDEX(Etapas!$B$5:$B$304,MATCH(LARGE(Etapas!$K$5:$K$304,7),Etapas!$K$5:$K$304,0)),""),"") -> Revisão e publicação | D29: =IFERROR(IF(LARGE(Etapas!$K$5:$K$304,7)>0,INDEX(Etapas!$C$5:$C$304,MATCH(LARGE(Etapas!$K$5:$K$304,7),Etapas!$K$5:$K$304,0)),""),"") -> Ana | E29: =IFERROR(IF(LARGE(Etapas!$K$5:$K$304,7)>0,INDEX(Etapas!$E$5:$E$304,MATCH(LARGE(Etapas!$K$5:$K$304,7),Etapas!$K$5:$K$304,0)),""),"") -> 46304 | F29: =IFERROR(IF(LARGE(Etapas!$K$5:$K$304,7)>0,INDEX(Etapas!$G$5:$G$304,MATCH(LARGE(Etapas!$K$5:$K$304,7),Etapas!$K$5:$K$304,0)),""),"") -> A iniciar | G29: =IFERROR(IF(LARGE(Etapas!$K$5:$K$304,7)>0,INDEX(Etapas!$H$5:$H$304,MATCH(LARGE(Etapas!$K$5:$K$304,7),Etapas!$K$5:$K$304,0)),""),"") -> 25 | H29: =IFERROR(IF(LARGE(Etapas!$K$5:$K$304,7)>0,INDEX(Etapas!$F$5:$F$304,MATCH(LARGE(Etapas!$K$5:$K$304,7),Etapas!$K$5:$K$304,0)),""),"") -> 0
A30: 8 | B30: =IFERROR(IF(LARGE(Etapas!$K$5:$K$304,8)>0,INDEX(Etapas!$A$5:$A$304,MATCH(LARGE(Etapas!$K$5:$K$304,8),Etapas!$K$5:$K$304,0)),""),"") -> Campanha de fim de ano · Bistrô 42 | C30: =IFERROR(IF(LARGE(Etapas!$K$5:$K$304,8)>0,INDEX(Etapas!$B$5:$B$304,MATCH(LARGE(Etapas!$K$5:$K$304,8),Etapas!$K$5:$K$304,0)),""),"") -> Produção das peças | D30: =IFERROR(IF(LARGE(Etapas!$K$5:$K$304,8)>0,INDEX(Etapas!$C$5:$C$304,MATCH(LARGE(Etapas!$K$5:$K$304,8),Etapas!$K$5:$K$304,0)),""),"") -> Bruno | E30: =IFERROR(IF(LARGE(Etapas!$K$5:$K$304,8)>0,INDEX(Etapas!$E$5:$E$304,MATCH(LARGE(Etapas!$K$5:$K$304,8),Etapas!$K$5:$K$304,0)),""),"") -> 46310 | F30: =IFERROR(IF(LARGE(Etapas!$K$5:$K$304,8)>0,INDEX(Etapas!$G$5:$G$304,MATCH(LARGE(Etapas!$K$5:$K$304,8),Etapas!$K$5:$K$304,0)),""),"") -> A iniciar | G30: =IFERROR(IF(LARGE(Etapas!$K$5:$K$304,8)>0,INDEX(Etapas!$H$5:$H$304,MATCH(LARGE(Etapas!$K$5:$K$304,8),Etapas!$K$5:$K$304,0)),""),"") -> 31 | H30: =IFERROR(IF(LARGE(Etapas!$K$5:$K$304,8)>0,INDEX(Etapas!$F$5:$F$304,MATCH(LARGE(Etapas!$K$5:$K$304,8),Etapas!$K$5:$K$304,0)),""),"") -> 0
A31: 9 | B31: =IFERROR(IF(LARGE(Etapas!$K$5:$K$304,9)>0,INDEX(Etapas!$A$5:$A$304,MATCH(LARGE(Etapas!$K$5:$K$304,9),Etapas!$K$5:$K$304,0)),""),"") -> Campanha de fim de ano · Bistrô 42 | C31: =IFERROR(IF(LARGE(Etapas!$K$5:$K$304,9)>0,INDEX(Etapas!$B$5:$B$304,MATCH(LARGE(Etapas!$K$5:$K$304,9),Etapas!$K$5:$K$304,0)),""),"") -> Plano de mídia | D31: =IFERROR(IF(LARGE(Etapas!$K$5:$K$304,9)>0,INDEX(Etapas!$C$5:$C$304,MATCH(LARGE(Etapas!$K$5:$K$304,9),Etapas!$K$5:$K$304,0)),""),"") -> Ana | E31: =IFERROR(IF(LARGE(Etapas!$K$5:$K$304,9)>0,INDEX(Etapas!$E$5:$E$304,MATCH(LARGE(Etapas!$K$5:$K$304,9),Etapas!$K$5:$K$304,0)),""),"") -> 46315 | F31: =IFERROR(IF(LARGE(Etapas!$K$5:$K$304,9)>0,INDEX(Etapas!$G$5:$G$304,MATCH(LARGE(Etapas!$K$5:$K$304,9),Etapas!$K$5:$K$304,0)),""),"") -> A iniciar | G31: =IFERROR(IF(LARGE(Etapas!$K$5:$K$304,9)>0,INDEX(Etapas!$H$5:$H$304,MATCH(LARGE(Etapas!$K$5:$K$304,9),Etapas!$K$5:$K$304,0)),""),"") -> 36 | H31: =IFERROR(IF(LARGE(Etapas!$K$5:$K$304,9)>0,INDEX(Etapas!$F$5:$F$304,MATCH(LARGE(Etapas!$K$5:$K$304,9),Etapas!$K$5:$K$304,0)),""),"") -> 0
A32: 10 | B32: =IFERROR(IF(LARGE(Etapas!$K$5:$K$304,10)>0,INDEX(Etapas!$A$5:$A$304,MATCH(LARGE(Etapas!$K$5:$K$304,10),Etapas!$K$5:$K$304,0)),""),"") -> Campanha de fim de ano · Bistrô 42 | C32: =IFERROR(IF(LARGE(Etapas!$K$5:$K$304,10)>0,INDEX(Etapas!$B$5:$B$304,MATCH(LARGE(Etapas!$K$5:$K$304,10),Etapas!$K$5:$K$304,0)),""),"") -> Veiculação | D32: =IFERROR(IF(LARGE(Etapas!$K$5:$K$304,10)>0,INDEX(Etapas!$C$5:$C$304,MATCH(LARGE(Etapas!$K$5:$K$304,10),Etapas!$K$5:$K$304,0)),""),"") -> Diego | E32: =IFERROR(IF(LARGE(Etapas!$K$5:$K$304,10)>0,INDEX(Etapas!$E$5:$E$304,MATCH(LARGE(Etapas!$K$5:$K$304,10),Etapas!$K$5:$K$304,0)),""),"") -> 46346 | F32: =IFERROR(IF(LARGE(Etapas!$K$5:$K$304,10)>0,INDEX(Etapas!$G$5:$G$304,MATCH(LARGE(Etapas!$K$5:$K$304,10),Etapas!$K$5:$K$304,0)),""),"") -> A iniciar | G32: =IFERROR(IF(LARGE(Etapas!$K$5:$K$304,10)>0,INDEX(Etapas!$H$5:$H$304,MATCH(LARGE(Etapas!$K$5:$K$304,10),Etapas!$K$5:$K$304,0)),""),"") -> 67 | H32: =IFERROR(IF(LARGE(Etapas!$K$5:$K$304,10)>0,INDEX(Etapas!$F$5:$F$304,MATCH(LARGE(Etapas!$K$5:$K$304,10),Etapas!$K$5:$K$304,0)),""),"") -> 0
A33: 11 | B33: =IFERROR(IF(LARGE(Etapas!$K$5:$K$304,11)>0,INDEX(Etapas!$A$5:$A$304,MATCH(LARGE(Etapas!$K$5:$K$304,11),Etapas!$K$5:$K$304,0)),""),"") -> Relatório anual · Horizonte | C33: =IFERROR(IF(LARGE(Etapas!$K$5:$K$304,11)>0,INDEX(Etapas!$B$5:$B$304,MATCH(LARGE(Etapas!$K$5:$K$304,11),Etapas!$K$5:$K$304,0)),""),"") -> Diagramação | D33: =IFERROR(IF(LARGE(Etapas!$K$5:$K$304,11)>0,INDEX(Etapas!$C$5:$C$304,MATCH(LARGE(Etapas!$K$5:$K$304,11),Etapas!$K$5:$K$304,0)),""),"") -> Bruno | E33: =IFERROR(IF(LARGE(Etapas!$K$5:$K$304,11)>0,INDEX(Etapas!$E$5:$E$304,MATCH(LARGE(Etapas!$K$5:$K$304,11),Etapas!$K$5:$K$304,0)),""),"") -> 46291 | F33: =IFERROR(IF(LARGE(Etapas!$K$5:$K$304,11)>0,INDEX(Etapas!$G$5:$G$304,MATCH(LARGE(Etapas!$K$5:$K$304,11),Etapas!$K$5:$K$304,0)),""),"") -> A iniciar | G33: =IFERROR(IF(LARGE(Etapas!$K$5:$K$304,11)>0,INDEX(Etapas!$H$5:$H$304,MATCH(LARGE(Etapas!$K$5:$K$304,11),Etapas!$K$5:$K$304,0)),""),"") -> 12 | H33: =IFERROR(IF(LARGE(Etapas!$K$5:$K$304,11)>0,INDEX(Etapas!$F$5:$F$304,MATCH(LARGE(Etapas!$K$5:$K$304,11),Etapas!$K$5:$K$304,0)),""),"") -> 0
A34: 12 | B34: =IFERROR(IF(LARGE(Etapas!$K$5:$K$304,12)>0,INDEX(Etapas!$A$5:$A$304,MATCH(LARGE(Etapas!$K$5:$K$304,12),Etapas!$K$5:$K$304,0)),""),"") -> Relatório anual · Horizonte | C34: =IFERROR(IF(LARGE(Etapas!$K$5:$K$304,12)>0,INDEX(Etapas!$B$5:$B$304,MATCH(LARGE(Etapas!$K$5:$K$304,12),Etapas!$K$5:$K$304,0)),""),"") -> Revisão final e entrega | D34: =IFERROR(IF(LARGE(Etapas!$K$5:$K$304,12)>0,INDEX(Etapas!$C$5:$C$304,MATCH(LARGE(Etapas!$K$5:$K$304,12),Etapas!$K$5:$K$304,0)),""),"") -> Ana | E34: =IFERROR(IF(LARGE(Etapas!$K$5:$K$304,12)>0,INDEX(Etapas!$E$5:$E$304,MATCH(LARGE(Etapas!$K$5:$K$304,12),Etapas!$K$5:$K$304,0)),""),"") -> 46295 | F34: =IFERROR(IF(LARGE(Etapas!$K$5:$K$304,12)>0,INDEX(Etapas!$G$5:$G$304,MATCH(LARGE(Etapas!$K$5:$K$304,12),Etapas!$K$5:$K$304,0)),""),"") -> A iniciar | G34: =IFERROR(IF(LARGE(Etapas!$K$5:$K$304,12)>0,INDEX(Etapas!$H$5:$H$304,MATCH(LARGE(Etapas!$K$5:$K$304,12),Etapas!$K$5:$K$304,0)),""),"") -> 16 | H34: =IFERROR(IF(LARGE(Etapas!$K$5:$K$304,12)>0,INDEX(Etapas!$F$5:$F$304,MATCH(LARGE(Etapas!$K$5:$K$304,12),Etapas!$K$5:$K$304,0)),""),"") -> 0
A36: Carga por responsável
A37: Responsável | B37: Etapas abertas | C37: Atrasadas | D37: Vencem em breve | E37: Próximo fim
A38: =IF(Config!$A$22="","",Config!$A$22) -> Ana | B38: =IF(Config!$A$22="","",COUNTIFS(Etapas!$C$5:$C$304,Config!$A$22,Etapas!$B$5:$B$304,"<>")-COUNTIFS(Etapas!$C$5:$C$304,Config!$A$22,Etapas!$G$5:$G$304,"Concluída")) -> 4 | C38: =IF(Config!$A$22="","",COUNTIFS(Etapas!$C$5:$C$304,Config!$A$22,Etapas!$G$5:$G$304,"Atrasada")) -> 0 | D38: =IF(Config!$A$22="","",COUNTIFS(Etapas!$C$5:$C$304,Config!$A$22,Etapas!$G$5:$G$304,"Vence em breve")) -> 1 | E38: =IF(Config!$A$22="","",IFERROR(IF(OR(SUMPRODUCT(MIN((Etapas!$C$5:$C$304=Config!$A$22)*(Etapas!$G$5:$G$304<>"Concluída")*(Etapas!$B$5:$B$304<>"")*(Etapas!$E$5:$E$304<>"")*Etapas!$E$5:$E$304+(1-(Etapas!$C$5:$C$304=Config!$A$22)*(Etapas!$G$5:$G$304<>"Concluída")*(Etapas!$B$5:$B$304<>"")*(Etapas!$E$5:$E$304<>""))*1E+10))=0,SUMPRODUCT(MIN((Etapas!$C$5:$C$304=Config!$A$22)*(Etapas!$G$5:$G$304<>"Concluída")*(Etapas!$B$5:$B$304<>"")*(Etapas!$E$5:$E$304<>"")*Etapas!$E$5:$E$304+(1-(Etapas!$C$5:$C$304=Config!$A$22)*(Etapas!$G$5:$G$304<>"Concluída")*(Etapas!$B$5:$B$304<>"")*(Etapas!$E$5:$E$304<>""))*1E+10))>=1E+10),"",SUMPRODUCT(MIN((Etapas!$C$5:$C$304=Config!$A$22)*(Etapas!$G$5:$G$304<>"Concluída")*(Etapas!$B$5:$B$304<>"")*(Etapas!$E$5:$E$304<>"")*Etapas!$E$5:$E$304+(1-(Etapas!$C$5:$C$304=Config!$A$22)*(Etapas!$G$5:$G$304<>"Concluída")*(Etapas!$B$5:$B$304<>"")*(Etapas!$E$5:$E$304<>""))*1E+10))),"")) -> 46284
A39: =IF(Config!$A$23="","",Config!$A$23) -> Bruno | B39: =IF(Config!$A$23="","",COUNTIFS(Etapas!$C$5:$C$304,Config!$A$23,Etapas!$B$5:$B$304,"<>")-COUNTIFS(Etapas!$C$5:$C$304,Config!$A$23,Etapas!$G$5:$G$304,"Concluída")) -> 3 | C39: =IF(Config!$A$23="","",COUNTIFS(Etapas!$C$5:$C$304,Config!$A$23,Etapas!$G$5:$G$304,"Atrasada")) -> 0 | D39: =IF(Config!$A$23="","",COUNTIFS(Etapas!$C$5:$C$304,Config!$A$23,Etapas!$G$5:$G$304,"Vence em breve")) -> 1 | E39: =IF(Config!$A$23="","",IFERROR(IF(OR(SUMPRODUCT(MIN((Etapas!$C$5:$C$304=Config!$A$23)*(Etapas!$G$5:$G$304<>"Concluída")*(Etapas!$B$5:$B$304<>"")*(Etapas!$E$5:$E$304<>"")*Etapas!$E$5:$E$304+(1-(Etapas!$C$5:$C$304=Config!$A$23)*(Etapas!$G$5:$G$304<>"Concluída")*(Etapas!$B$5:$B$304<>"")*(Etapas!$E$5:$E$304<>""))*1E+10))=0,SUMPRODUCT(MIN((Etapas!$C$5:$C$304=Config!$A$23)*(Etapas!$G$5:$G$304<>"Concluída")*(Etapas!$B$5:$B$304<>"")*(Etapas!$E$5:$E$304<>"")*Etapas!$E$5:$E$304+(1-(Etapas!$C$5:$C$304=Config!$A$23)*(Etapas!$G$5:$G$304<>"Concluída")*(Etapas!$B$5:$B$304<>"")*(Etapas!$E$5:$E$304<>""))*1E+10))>=1E+10),"",SUMPRODUCT(MIN((Etapas!$C$5:$C$304=Config!$A$23)*(Etapas!$G$5:$G$304<>"Concluída")*(Etapas!$B$5:$B$304<>"")*(Etapas!$E$5:$E$304<>"")*Etapas!$E$5:$E$304+(1-(Etapas!$C$5:$C$304=Config!$A$23)*(Etapas!$G$5:$G$304<>"Concluída")*(Etapas!$B$5:$B$304<>"")*(Etapas!$E$5:$E$304<>""))*1E+10))),"")) -> 46284
A40: =IF(Config!$A$24="","",Config!$A$24) -> Carla | B40: =IF(Config!$A$24="","",COUNTIFS(Etapas!$C$5:$C$304,Config!$A$24,Etapas!$B$5:$B$304,"<>")-COUNTIFS(Etapas!$C$5:$C$304,Config!$A$24,Etapas!$G$5:$G$304,"Concluída")) -> 3 | C40: =IF(Config!$A$24="","",COUNTIFS(Etapas!$C$5:$C$304,Config!$A$24,Etapas!$G$5:$G$304,"Atrasada")) -> 2 | D40: =IF(Config!$A$24="","",COUNTIFS(Etapas!$C$5:$C$304,Config!$A$24,Etapas!$G$5:$G$304,"Vence em breve")) -> 1 | E40: =IF(Config!$A$24="","",IFERROR(IF(OR(SUMPRODUCT(MIN((Etapas!$C$5:$C$304=Config!$A$24)*(Etapas!$G$5:$G$304<>"Concluída")*(Etapas!$B$5:$B$304<>"")*(Etapas!$E$5:$E$304<>"")*Etapas!$E$5:$E$304+(1-(Etapas!$C$5:$C$304=Config!$A$24)*(Etapas!$G$5:$G$304<>"Concluída")*(Etapas!$B$5:$B$304<>"")*(Etapas!$E$5:$E$304<>""))*1E+10))=0,SUMPRODUCT(MIN((Etapas!$C$5:$C$304=Config!$A$24)*(Etapas!$G$5:$G$304<>"Concluída")*(Etapas!$B$5:$B$304<>"")*(Etapas!$E$5:$E$304<>"")*Etapas!$E$5:$E$304+(1-(Etapas!$C$5:$C$304=Config!$A$24)*(Etapas!$G$5:$G$304<>"Concluída")*(Etapas!$B$5:$B$304<>"")*(Etapas!$E$5:$E$304<>""))*1E+10))>=1E+10),"",SUMPRODUCT(MIN((Etapas!$C$5:$C$304=Config!$A$24)*(Etapas!$G$5:$G$304<>"Concluída")*(Etapas!$B$5:$B$304<>"")*(Etapas!$E$5:$E$304<>"")*Etapas!$E$5:$E$304+(1-(Etapas!$C$5:$C$304=Config!$A$24)*(Etapas!$G$5:$G$304<>"Concluída")*(Etapas!$B$5:$B$304<>"")*(Etapas!$E$5:$E$304<>""))*1E+10))),"")) -> 46270
A41: =IF(Config!$A$25="","",Config!$A$25) -> Diego | B41: =IF(Config!$A$25="","",COUNTIFS(Etapas!$C$5:$C$304,Config!$A$25,Etapas!$B$5:$B$304,"<>")-COUNTIFS(Etapas!$C$5:$C$304,Config!$A$25,Etapas!$G$5:$G$304,"Concluída")) -> 2 | C41: =IF(Config!$A$25="","",COUNTIFS(Etapas!$C$5:$C$304,Config!$A$25,Etapas!$G$5:$G$304,"Atrasada")) -> 0 | D41: =IF(Config!$A$25="","",COUNTIFS(Etapas!$C$5:$C$304,Config!$A$25,Etapas!$G$5:$G$304,"Vence em breve")) -> 0 | E41: =IF(Config!$A$25="","",IFERROR(IF(OR(SUMPRODUCT(MIN((Etapas!$C$5:$C$304=Config!$A$25)*(Etapas!$G$5:$G$304<>"Concluída")*(Etapas!$B$5:$B$304<>"")*(Etapas!$E$5:$E$304<>"")*Etapas!$E$5:$E$304+(1-(Etapas!$C$5:$C$304=Config!$A$25)*(Etapas!$G$5:$G$304<>"Concluída")*(Etapas!$B$5:$B$304<>"")*(Etapas!$E$5:$E$304<>""))*1E+10))=0,SUMPRODUCT(MIN((Etapas!$C$5:$C$304=Config!$A$25)*(Etapas!$G$5:$G$304<>"Concluída")*(Etapas!$B$5:$B$304<>"")*(Etapas!$E$5:$E$304<>"")*Etapas!$E$5:$E$304+(1-(Etapas!$C$5:$C$304=Config!$A$25)*(Etapas!$G$5:$G$304<>"Concluída")*(Etapas!$B$5:$B$304<>"")*(Etapas!$E$5:$E$304<>""))*1E+10))>=1E+10),"",SUMPRODUCT(MIN((Etapas!$C$5:$C$304=Config!$A$25)*(Etapas!$G$5:$G$304<>"Concluída")*(Etapas!$B$5:$B$304<>"")*(Etapas!$E$5:$E$304<>"")*Etapas!$E$5:$E$304+(1-(Etapas!$C$5:$C$304=Config!$A$25)*(Etapas!$G$5:$G$304<>"Concluída")*(Etapas!$B$5:$B$304<>"")*(Etapas!$E$5:$E$304<>""))*1E+10))),"")) -> 46298
A42: =IF(Config!$A$26="","",Config!$A$26) | B42: =IF(Config!$A$26="","",COUNTIFS(Etapas!$C$5:$C$304,Config!$A$26,Etapas!$B$5:$B$304,"<>")-COUNTIFS(Etapas!$C$5:$C$304,Config!$A$26,Etapas!$G$5:$G$304,"Concluída")) | C42: =IF(Config!$A$26="","",COUNTIFS(Etapas!$C$5:$C$304,Config!$A$26,Etapas!$G$5:$G$304,"Atrasada")) | D42: =IF(Config!$A$26="","",COUNTIFS(Etapas!$C$5:$C$304,Config!$A$26,Etapas!$G$5:$G$304,"Vence em breve")) | E42: =IF(Config!$A$26="","",IFERROR(IF(OR(SUMPRODUCT(MIN((Etapas!$C$5:$C$304=Config!$A$26)*(Etapas!$G$5:$G$304<>"Concluída")*(Etapas!$B$5:$B$304<>"")*(Etapas!$E$5:$E$304<>"")*Etapas!$E$5:$E$304+(1-(Etapas!$C$5:$C$304=Config!$A$26)*(Etapas!$G$5:$G$304<>"Concluída")*(Etapas!$B$5:$B$304<>"")*(Etapas!$E$5:$E$304<>""))*1E+10))=0,SUMPRODUCT(MIN((Etapas!$C$5:$C$304=Config!$A$26)*(Etapas!$G$5:$G$304<>"Concluída")*(Etapas!$B$5:$B$304<>"")*(Etapas!$E$5:$E$304<>"")*Etapas!$E$5:$E$304+(1-(Etapas!$C$5:$C$304=Config!$A$26)*(Etapas!$G$5:$G$304<>"Concluída")*(Etapas!$B$5:$B$304<>"")*(Etapas!$E$5:$E$304<>""))*1E+10))>=1E+10),"",SUMPRODUCT(MIN((Etapas!$C$5:$C$304=Config!$A$26)*(Etapas!$G$5:$G$304<>"Concluída")*(Etapas!$B$5:$B$304<>"")*(Etapas!$E$5:$E$304<>"")*Etapas!$E$5:$E$304+(1-(Etapas!$C$5:$C$304=Config!$A$26)*(Etapas!$G$5:$G$304<>"Concluída")*(Etapas!$B$5:$B$304<>"")*(Etapas!$E$5:$E$304<>""))*1E+10))),""))
A43: =IF(Config!$A$27="","",Config!$A$27) | B43: =IF(Config!$A$27="","",COUNTIFS(Etapas!$C$5:$C$304,Config!$A$27,Etapas!$B$5:$B$304,"<>")-COUNTIFS(Etapas!$C$5:$C$304,Config!$A$27,Etapas!$G$5:$G$304,"Concluída")) | C43: =IF(Config!$A$27="","",COUNTIFS(Etapas!$C$5:$C$304,Config!$A$27,Etapas!$G$5:$G$304,"Atrasada")) | D43: =IF(Config!$A$27="","",COUNTIFS(Etapas!$C$5:$C$304,Config!$A$27,Etapas!$G$5:$G$304,"Vence em breve")) | E43: =IF(Config!$A$27="","",IFERROR(IF(OR(SUMPRODUCT(MIN((Etapas!$C$5:$C$304=Config!$A$27)*(Etapas!$G$5:$G$304<>"Concluída")*(Etapas!$B$5:$B$304<>"")*(Etapas!$E$5:$E$304<>"")*Etapas!$E$5:$E$304+(1-(Etapas!$C$5:$C$304=Config!$A$27)*(Etapas!$G$5:$G$304<>"Concluída")*(Etapas!$B$5:$B$304<>"")*(Etapas!$E$5:$E$304<>""))*1E+10))=0,SUMPRODUCT(MIN((Etapas!$C$5:$C$304=Config!$A$27)*(Etapas!$G$5:$G$304<>"Concluída")*(Etapas!$B$5:$B$304<>"")*(Etapas!$E$5:$E$304<>"")*Etapas!$E$5:$E$304+(1-(Etapas!$C$5:$C$304=Config!$A$27)*(Etapas!$G$5:$G$304<>"Concluída")*(Etapas!$B$5:$B$304<>"")*(Etapas!$E$5:$E$304<>""))*1E+10))>=1E+10),"",SUMPRODUCT(MIN((Etapas!$C$5:$C$304=Config!$A$27)*(Etapas!$G$5:$G$304<>"Concluída")*(Etapas!$B$5:$B$304<>"")*(Etapas!$E$5:$E$304<>"")*Etapas!$E$5:$E$304+(1-(Etapas!$C$5:$C$304=Config!$A$27)*(Etapas!$G$5:$G$304<>"Concluída")*(Etapas!$B$5:$B$304<>"")*(Etapas!$E$5:$E$304<>""))*1E+10))),""))
...

Sheet Linha do tempo
A1: Linha do tempo (semanas)
A2: As 40 primeiras etapas da aba Etapas, semana a semana, a partir da segunda-feira da data de referência. Barra roxa: etapa em curso; cinza: concluída; vermelha: atrasada.
A3: Começar em | B3: =Config!$B$5-WEEKDAY(Config!$B$5,3)-7 -> 46272 | C3: (uma semana antes da data de referência; mude a data em Config para navegar)
A4: Projeto | B4: Etapa | C4: Resp. | D4: Fim | E4: =$B$3+0 -> 46272 | F4: =$B$3+7 -> 46279 | G4: =$B$3+14 -> 46286 | H4: =$B$3+21 -> 46293 | I4: =$B$3+28 -> 46300 | J4: =$B$3+35 -> 46307 | K4: =$B$3+42 -> 46314 | L4: =$B$3+49 -> 46321 | M4: =$B$3+56 -> 46328 | N4: =$B$3+63 -> 46335 | O4: =$B$3+70 -> 46342 | P4: =$B$3+77 -> 46349 | Q4: =$B$3+84 -> 46356 | R4: =$B$3+91 -> 46363
A5: =IF(Etapas!B5="","",Etapas!A5) -> Site novo · Loja Verde | B5: =IF(Etapas!B5="","",Etapas!B5) -> Briefing e mapa do site | C5: =IF(Etapas!B5="","",Etapas!C5) -> Ana | D5: =IF(Etapas!B5="","",Etapas!E5) -> 46249 | E5: =IF(Etapas!$B5="","",IF(AND(E$4<=Etapas!$E5,E$4+6>=Etapas!$D5),IF(Etapas!$G5="Concluída",1,IF(Etapas!$G5="Atrasada",3,2)),"")) | F5: =IF(Etapas!$B5="","",IF(AND(F$4<=Etapas!$E5,F$4+6>=Etapas!$D5),IF(Etapas!$G5="Concluída",1,IF(Etapas!$G5="Atrasada",3,2)),"")) | G5: =IF(Etapas!$B5="","",IF(AND(G$4<=Etapas!$E5,G$4+6>=Etapas!$D5),IF(Etapas!$G5="Concluída",1,IF(Etapas!$G5="Atrasada",3,2)),"")) | H5: =IF(Etapas!$B5="","",IF(AND(H$4<=Etapas!$E5,H$4+6>=Etapas!$D5),IF(Etapas!$G5="Concluída",1,IF(Etapas!$G5="Atrasada",3,2)),"")) | I5: =IF(Etapas!$B5="","",IF(AND(I$4<=Etapas!$E5,I$4+6>=Etapas!$D5),IF(Etapas!$G5="Concluída",1,IF(Etapas!$G5="Atrasada",3,2)),"")) | J5: =IF(Etapas!$B5="","",IF(AND(J$4<=Etapas!$E5,J$4+6>=Etapas!$D5),IF(Etapas!$G5="Concluída",1,IF(Etapas!$G5="Atrasada",3,2)),"")) | K5: =IF(Etapas!$B5="","",IF(AND(K$4<=Etapas!$E5,K$4+6>=Etapas!$D5),IF(Etapas!$G5="Concluída",1,IF(Etapas!$G5="Atrasada",3,2)),"")) | L5: =IF(Etapas!$B5="","",IF(AND(L$4<=Etapas!$E5,L$4+6>=Etapas!$D5),IF(Etapas!$G5="Concluída",1,IF(Etapas!$G5="Atrasada",3,2)),"")) | ... R5: =IF(Etapas!$B5="","",IF(AND(R$4<=Etapas!$E5,R$4+6>=Etapas!$D5),IF(Etapas!$G5="Concluída",1,IF(Etapas!$G5="Atrasada",3,2)),""))
A6: =IF(Etapas!B6="","",Etapas!A6) -> Site novo · Loja Verde | B6: =IF(Etapas!B6="","",Etapas!B6) -> Wireframes das 5 páginas | C6: =IF(Etapas!B6="","",Etapas!C6) -> Ana | D6: =IF(Etapas!B6="","",Etapas!E6) -> 46260 | E6: =IF(Etapas!$B6="","",IF(AND(E$4<=Etapas!$E6,E$4+6>=Etapas!$D6),IF(Etapas!$G6="Concluída",1,IF(Etapas!$G6="Atrasada",3,2)),"")) | F6: =IF(Etapas!$B6="","",IF(AND(F$4<=Etapas!$E6,F$4+6>=Etapas!$D6),IF(Etapas!$G6="Concluída",1,IF(Etapas!$G6="Atrasada",3,2)),"")) | G6: =IF(Etapas!$B6="","",IF(AND(G$4<=Etapas!$E6,G$4+6>=Etapas!$D6),IF(Etapas!$G6="Concluída",1,IF(Etapas!$G6="Atrasada",3,2)),"")) | H6: =IF(Etapas!$B6="","",IF(AND(H$4<=Etapas!$E6,H$4+6>=Etapas!$D6),IF(Etapas!$G6="Concluída",1,IF(Etapas!$G6="Atrasada",3,2)),"")) | I6: =IF(Etapas!$B6="","",IF(AND(I$4<=Etapas!$E6,I$4+6>=Etapas!$D6),IF(Etapas!$G6="Concluída",1,IF(Etapas!$G6="Atrasada",3,2)),"")) | J6: =IF(Etapas!$B6="","",IF(AND(J$4<=Etapas!$E6,J$4+6>=Etapas!$D6),IF(Etapas!$G6="Concluída",1,IF(Etapas!$G6="Atrasada",3,2)),"")) | K6: =IF(Etapas!$B6="","",IF(AND(K$4<=Etapas!$E6,K$4+6>=Etapas!$D6),IF(Etapas!$G6="Concluída",1,IF(Etapas!$G6="Atrasada",3,2)),"")) | L6: =IF(Etapas!$B6="","",IF(AND(L$4<=Etapas!$E6,L$4+6>=Etapas!$D6),IF(Etapas!$G6="Concluída",1,IF(Etapas!$G6="Atrasada",3,2)),"")) | ... R6: =IF(Etapas!$B6="","",IF(AND(R$4<=Etapas!$E6,R$4+6>=Etapas!$D6),IF(Etapas!$G6="Concluída",1,IF(Etapas!$G6="Atrasada",3,2)),""))
A7: =IF(Etapas!B7="","",Etapas!A7) -> Site novo · Loja Verde | B7: =IF(Etapas!B7="","",Etapas!B7) -> Layout da home | C7: =IF(Etapas!B7="","",Etapas!C7) -> Bruno | D7: =IF(Etapas!B7="","",Etapas!E7) -> 46273 | E7: =IF(Etapas!$B7="","",IF(AND(E$4<=Etapas!$E7,E$4+6>=Etapas!$D7),IF(Etapas!$G7="Concluída",1,IF(Etapas!$G7="Atrasada",3,2)),"")) -> 1 | F7: =IF(Etapas!$B7="","",IF(AND(F$4<=Etapas!$E7,F$4+6>=Etapas!$D7),IF(Etapas!$G7="Concluída",1,IF(Etapas!$G7="Atrasada",3,2)),"")) | G7: =IF(Etapas!$B7="","",IF(AND(G$4<=Etapas!$E7,G$4+6>=Etapas!$D7),IF(Etapas!$G7="Concluída",1,IF(Etapas!$G7="Atrasada",3,2)),"")) | H7: =IF(Etapas!$B7="","",IF(AND(H$4<=Etapas!$E7,H$4+6>=Etapas!$D7),IF(Etapas!$G7="Concluída",1,IF(Etapas!$G7="Atrasada",3,2)),"")) | I7: =IF(Etapas!$B7="","",IF(AND(I$4<=Etapas!$E7,I$4+6>=Etapas!$D7),IF(Etapas!$G7="Concluída",1,IF(Etapas!$G7="Atrasada",3,2)),"")) | J7: =IF(Etapas!$B7="","",IF(AND(J$4<=Etapas!$E7,J$4+6>=Etapas!$D7),IF(Etapas!$G7="Concluída",1,IF(Etapas!$G7="Atrasada",3,2)),"")) | K7: =IF(Etapas!$B7="","",IF(AND(K$4<=Etapas!$E7,K$4+6>=Etapas!$D7),IF(Etapas!$G7="Concluída",1,IF(Etapas!$G7="Atrasada",3,2)),"")) | L7: =IF(Etapas!$B7="","",IF(AND(L$4<=Etapas!$E7,L$4+6>=Etapas!$D7),IF(Etapas!$G7="Concluída",1,IF(Etapas!$G7="Atrasada",3,2)),"")) | ... R7: =IF(Etapas!$B7="","",IF(AND(R$4<=Etapas!$E7,R$4+6>=Etapas!$D7),IF(Etapas!$G7="Concluída",1,IF(Etapas!$G7="Atrasada",3,2)),""))
A8: =IF(Etapas!B8="","",Etapas!A8) -> Site novo · Loja Verde | B8: =IF(Etapas!B8="","",Etapas!B8) -> Layout das páginas internas | C8: =IF(Etapas!B8="","",Etapas!C8) -> Bruno | D8: =IF(Etapas!B8="","",Etapas!E8) -> 46284 | E8: =IF(Etapas!$B8="","",IF(AND(E$4<=Etapas!$E8,E$4+6>=Etapas!$D8),IF(Etapas!$G8="Concluída",1,IF(Etapas!$G8="Atrasada",3,2)),"")) -> 2 | F8: =IF(Etapas!$B8="","",IF(AND(F$4<=Etapas!$E8,F$4+6>=Etapas!$D8),IF(Etapas!$G8="Concluída",1,IF(Etapas!$G8="Atrasada",3,2)),"")) -> 2 | G8: =IF(Etapas!$B8="","",IF(AND(G$4<=Etapas!$E8,G$4+6>=Etapas!$D8),IF(Etapas!$G8="Concluída",1,IF(Etapas!$G8="Atrasada",3,2)),"")) | H8: =IF(Etapas!$B8="","",IF(AND(H$4<=Etapas!$E8,H$4+6>=Etapas!$D8),IF(Etapas!$G8="Concluída",1,IF(Etapas!$G8="Atrasada",3,2)),"")) | I8: =IF(Etapas!$B8="","",IF(AND(I$4<=Etapas!$E8,I$4+6>=Etapas!$D8),IF(Etapas!$G8="Concluída",1,IF(Etapas!$G8="Atrasada",3,2)),"")) | J8: =IF(Etapas!$B8="","",IF(AND(J$4<=Etapas!$E8,J$4+6>=Etapas!$D8),IF(Etapas!$G8="Concluída",1,IF(Etapas!$G8="Atrasada",3,2)),"")) | K8: =IF(Etapas!$B8="","",IF(AND(K$4<=Etapas!$E8,K$4+6>=Etapas!$D8),IF(Etapas!$G8="Concluída",1,IF(Etapas!$G8="Atrasada",3,2)),"")) | L8: =IF(Etapas!$B8="","",IF(AND(L$4<=Etapas!$E8,L$4+6>=Etapas!$D8),IF(Etapas!$G8="Concluída",1,IF(Etapas!$G8="Atrasada",3,2)),"")) | ... R8: =IF(Etapas!$B8="","",IF(AND(R$4<=Etapas!$E8,R$4+6>=Etapas!$D8),IF(Etapas!$G8="Concluída",1,IF(Etapas!$G8="Atrasada",3,2)),""))
A9: =IF(Etapas!B9="","",Etapas!A9) -> Site novo · Loja Verde | B9: =IF(Etapas!B9="","",Etapas!B9) -> Textos das páginas | C9: =IF(Etapas!B9="","",Etapas!C9) -> Carla | D9: =IF(Etapas!B9="","",Etapas!E9) -> 46277 | E9: =IF(Etapas!$B9="","",IF(AND(E$4<=Etapas!$E9,E$4+6>=Etapas!$D9),IF(Etapas!$G9="Concluída",1,IF(Etapas!$G9="Atrasada",3,2)),"")) -> 3 | F9: =IF(Etapas!$B9="","",IF(AND(F$4<=Etapas!$E9,F$4+6>=Etapas!$D9),IF(Etapas!$G9="Concluída",1,IF(Etapas!$G9="Atrasada",3,2)),"")) | G9: =IF(Etapas!$B9="","",IF(AND(G$4<=Etapas!$E9,G$4+6>=Etapas!$D9),IF(Etapas!$G9="Concluída",1,IF(Etapas!$G9="Atrasada",3,2)),"")) | H9: =IF(Etapas!$B9="","",IF(AND(H$4<=Etapas!$E9,H$4+6>=Etapas!$D9),IF(Etapas!$G9="Concluída",1,IF(Etapas!$G9="Atrasada",3,2)),"")) | I9: =IF(Etapas!$B9="","",IF(AND(I$4<=Etapas!$E9,I$4+6>=Etapas!$D9),IF(Etapas!$G9="Concluída",1,IF(Etapas!$G9="Atrasada",3,2)),"")) | J9: =IF(Etapas!$B9="","",IF(AND(J$4<=Etapas!$E9,J$4+6>=Etapas!$D9),IF(Etapas!$G9="Concluída",1,IF(Etapas!$G9="Atrasada",3,2)),"")) | K9: =IF(Etapas!$B9="","",IF(AND(K$4<=Etapas!$E9,K$4+6>=Etapas!$D9),IF(Etapas!$G9="Concluída",1,IF(Etapas!$G9="Atrasada",3,2)),"")) | L9: =IF(Etapas!$B9="","",IF(AND(L$4<=Etapas!$E9,L$4+6>=Etapas!$D9),IF(Etapas!$G9="Concluída",1,IF(Etapas!$G9="Atrasada",3,2)),"")) | ... R9: =IF(Etapas!$B9="","",IF(AND(R$4<=Etapas!$E9,R$4+6>=Etapas!$D9),IF(Etapas!$G9="Concluída",1,IF(Etapas!$G9="Atrasada",3,2)),""))
A10: =IF(Etapas!B10="","",Etapas!A10) -> Site novo · Loja Verde | B10: =IF(Etapas!B10="","",Etapas!B10) -> Implementação | C10: =IF(Etapas!B10="","",Etapas!C10) -> Diego | D10: =IF(Etapas!B10="","",Etapas!E10) -> 46298 | E10: =IF(Etapas!$B10="","",IF(AND(E$4<=Etapas!$E10,E$4+6>=Etapas!$D10),IF(Etapas!$G10="Concluída",1,IF(Etapas!$G10="Atrasada",3,2)),"")) | F10: =IF(Etapas!$B10="","",IF(AND(F$4<=Etapas!$E10,F$4+6>=Etapas!$D10),IF(Etapas!$G10="Concluída",1,IF(Etapas!$G10="Atrasada",3,2)),"")) -> 2 | G10: =IF(Etapas!$B10="","",IF(AND(G$4<=Etapas!$E10,G$4+6>=Etapas!$D10),IF(Etapas!$G10="Concluída",1,IF(Etapas!$G10="Atrasada",3,2)),"")) -> 2 | H10: =IF(Etapas!$B10="","",IF(AND(H$4<=Etapas!$E10,H$4+6>=Etapas!$D10),IF(Etapas!$G10="Concluída",1,IF(Etapas!$G10="Atrasada",3,2)),"")) -> 2 | I10: =IF(Etapas!$B10="","",IF(AND(I$4<=Etapas!$E10,I$4+6>=Etapas!$D10),IF(Etapas!$G10="Concluída",1,IF(Etapas!$G10="Atrasada",3,2)),"")) | J10: =IF(Etapas!$B10="","",IF(AND(J$4<=Etapas!$E10,J$4+6>=Etapas!$D10),IF(Etapas!$G10="Concluída",1,IF(Etapas!$G10="Atrasada",3,2)),"")) | K10: =IF(Etapas!$B10="","",IF(AND(K$4<=Etapas!$E10,K$4+6>=Etapas!$D10),IF(Etapas!$G10="Concluída",1,IF(Etapas!$G10="Atrasada",3,2)),"")) | L10: =IF(Etapas!$B10="","",IF(AND(L$4<=Etapas!$E10,L$4+6>=Etapas!$D10),IF(Etapas!$G10="Concluída",1,IF(Etapas!$G10="Atrasada",3,2)),"")) | ... R10: =IF(Etapas!$B10="","",IF(AND(R$4<=Etapas!$E10,R$4+6>=Etapas!$D10),IF(Etapas!$G10="Concluída",1,IF(Etapas!$G10="Atrasada",3,2)),""))
A11: =IF(Etapas!B11="","",Etapas!A11) -> Site novo · Loja Verde | B11: =IF(Etapas!B11="","",Etapas!B11) -> Revisão e publicação | C11: =IF(Etapas!B11="","",Etapas!C11) -> Ana | D11: =IF(Etapas!B11="","",Etapas!E11) -> 46304 | E11: =IF(Etapas!$B11="","",IF(AND(E$4<=Etapas!$E11,E$4+6>=Etapas!$D11),IF(Etapas!$G11="Concluída",1,IF(Etapas!$G11="Atrasada",3,2)),"")) | F11: =IF(Etapas!$B11="","",IF(AND(F$4<=Etapas!$E11,F$4+6>=Etapas!$D11),IF(Etapas!$G11="Concluída",1,IF(Etapas!$G11="Atrasada",3,2)),"")) | G11: =IF(Etapas!$B11="","",IF(AND(G$4<=Etapas!$E11,G$4+6>=Etapas!$D11),IF(Etapas!$G11="Concluída",1,IF(Etapas!$G11="Atrasada",3,2)),"")) | H11: =IF(Etapas!$B11="","",IF(AND(H$4<=Etapas!$E11,H$4+6>=Etapas!$D11),IF(Etapas!$G11="Concluída",1,IF(Etapas!$G11="Atrasada",3,2)),"")) -> 2 | I11: =IF(Etapas!$B11="","",IF(AND(I$4<=Etapas!$E11,I$4+6>=Etapas!$D11),IF(Etapas!$G11="Concluída",1,IF(Etapas!$G11="Atrasada",3,2)),"")) -> 2 | J11: =IF(Etapas!$B11="","",IF(AND(J$4<=Etapas!$E11,J$4+6>=Etapas!$D11),IF(Etapas!$G11="Concluída",1,IF(Etapas!$G11="Atrasada",3,2)),"")) | K11: =IF(Etapas!$B11="","",IF(AND(K$4<=Etapas!$E11,K$4+6>=Etapas!$D11),IF(Etapas!$G11="Concluída",1,IF(Etapas!$G11="Atrasada",3,2)),"")) | L11: =IF(Etapas!$B11="","",IF(AND(L$4<=Etapas!$E11,L$4+6>=Etapas!$D11),IF(Etapas!$G11="Concluída",1,IF(Etapas!$G11="Atrasada",3,2)),"")) | ... R11: =IF(Etapas!$B11="","",IF(AND(R$4<=Etapas!$E11,R$4+6>=Etapas!$D11),IF(Etapas!$G11="Concluída",1,IF(Etapas!$G11="Atrasada",3,2)),""))
A12: =IF(Etapas!B12="","",Etapas!A12) -> Campanha de fim de ano · Bistrô 42 | B12: =IF(Etapas!B12="","",Etapas!B12) -> Conceito criativo | C12: =IF(Etapas!B12="","",Etapas!C12) -> Carla | D12: =IF(Etapas!B12="","",Etapas!E12) -> 46277 | E12: =IF(Etapas!$B12="","",IF(AND(E$4<=Etapas!$E12,E$4+6>=Etapas!$D12),IF(Etapas!$G12="Concluída",1,IF(Etapas!$G12="Atrasada",3,2)),"")) -> 1 | F12: =IF(Etapas!$B12="","",IF(AND(F$4<=Etapas!$E12,F$4+6>=Etapas!$D12),IF(Etapas!$G12="Concluída",1,IF(Etapas!$G12="Atrasada",3,2)),"")) | G12: =IF(Etapas!$B12="","",IF(AND(G$4<=Etapas!$E12,G$4+6>=Etapas!$D12),IF(Etapas!$G12="Concluída",1,IF(Etapas!$G12="Atrasada",3,2)),"")) | H12: =IF(Etapas!$B12="","",IF(AND(H$4<=Etapas!$E12,H$4+6>=Etapas!$D12),IF(Etapas!$G12="Concluída",1,IF(Etapas!$G12="Atrasada",3,2)),"")) | I12: =IF(Etapas!$B12="","",IF(AND(I$4<=Etapas!$E12,I$4+6>=Etapas!$D12),IF(Etapas!$G12="Concluída",1,IF(Etapas!$G12="Atrasada",3,2)),"")) | J12: =IF(Etapas!$B12="","",IF(AND(J$4<=Etapas!$E12,J$4+6>=Etapas!$D12),IF(Etapas!$G12="Concluída",1,IF(Etapas!$G12="Atrasada",3,2)),"")) | K12: =IF(Etapas!$B12="","",IF(AND(K$4<=Etapas!$E12,K$4+6>=Etapas!$D12),IF(Etapas!$G12="Concluída",1,IF(Etapas!$G12="Atrasada",3,2)),"")) | L12: =IF(Etapas!$B12="","",IF(AND(L$4<=Etapas!$E12,L$4+6>=Etapas!$D12),IF(Etapas!$G12="Concluída",1,IF(Etapas!$G12="Atrasada",3,2)),"")) | ... R12: =IF(Etapas!$B12="","",IF(AND(R$4<=Etapas!$E12,R$4+6>=Etapas!$D12),IF(Etapas!$G12="Concluída",1,IF(Etapas!$G12="Atrasada",3,2)),""))
A13: =IF(Etapas!B13="","",Etapas!A13) -> Campanha de fim de ano · Bistrô 42 | B13: =IF(Etapas!B13="","",Etapas!B13) -> Aprovação do cliente | C13: =IF(Etapas!B13="","",Etapas!C13) -> Carla | D13: =IF(Etapas!B13="","",Etapas!E13) -> 46282 | E13: =IF(Etapas!$B13="","",IF(AND(E$4<=Etapas!$E13,E$4+6>=Etapas!$D13),IF(Etapas!$G13="Concluída",1,IF(Etapas!$G13="Atrasada",3,2)),"")) -> 2 | F13: =IF(Etapas!$B13="","",IF(AND(F$4<=Etapas!$E13,F$4+6>=Etapas!$D13),IF(Etapas!$G13="Concluída",1,IF(Etapas!$G13="Atrasada",3,2)),"")) -> 2 | G13: =IF(Etapas!$B13="","",IF(AND(G$4<=Etapas!$E13,G$4+6>=Etapas!$D13),IF(Etapas!$G13="Concluída",1,IF(Etapas!$G13="Atrasada",3,2)),"")) | H13: =IF(Etapas!$B13="","",IF(AND(H$4<=Etapas!$E13,H$4+6>=Etapas!$D13),IF(Etapas!$G13="Concluída",1,IF(Etapas!$G13="Atrasada",3,2)),"")) | I13: =IF(Etapas!$B13="","",IF(AND(I$4<=Etapas!$E13,I$4+6>=Etapas!$D13),IF(Etapas!$G13="Concluída",1,IF(Etapas!$G13="Atrasada",3,2)),"")) | J13: =IF(Etapas!$B13="","",IF(AND(J$4<=Etapas!$E13,J$4+6>=Etapas!$D13),IF(Etapas!$G13="Concluída",1,IF(Etapas!$G13="Atrasada",3,2)),"")) | K13: =IF(Etapas!$B13="","",IF(AND(K$4<=Etapas!$E13,K$4+6>=Etapas!$D13),IF(Etapas!$G13="Concluída",1,IF(Etapas!$G13="Atrasada",3,2)),"")) | L13: =IF(Etapas!$B13="","",IF(AND(L$4<=Etapas!$E13,L$4+6>=Etapas!$D13),IF(Etapas!$G13="Concluída",1,IF(Etapas!$G13="Atrasada",3,2)),"")) | ... R13: =IF(Etapas!$B13="","",IF(AND(R$4<=Etapas!$E13,R$4+6>=Etapas!$D13),IF(Etapas!$G13="Concluída",1,IF(Etapas!$G13="Atrasada",3,2)),""))
A14: =IF(Etapas!B14="","",Etapas!A14) -> Campanha de fim de ano · Bistrô 42 | B14: =IF(Etapas!B14="","",Etapas!B14) -> Produção das peças | C14: =IF(Etapas!B14="","",Etapas!C14) -> Bruno | D14: =IF(Etapas!B14="","",Etapas!E14) -> 46310 | E14: =IF(Etapas!$B14="","",IF(AND(E$4<=Etapas!$E14,E$4+6>=Etapas!$D14),IF(Etapas!$G14="Concluída",1,IF(Etapas!$G14="Atrasada",3,2)),"")) | F14: =IF(Etapas!$B14="","",IF(AND(F$4<=Etapas!$E14,F$4+6>=Etapas!$D14),IF(Etapas!$G14="Concluída",1,IF(Etapas!$G14="Atrasada",3,2)),"")) -> 2 | G14: =IF(Etapas!$B14="","",IF(AND(G$4<=Etapas!$E14,G$4+6>=Etapas!$D14),IF(Etapas!$G14="Concluída",1,IF(Etapas!$G14="Atrasada",3,2)),"")) -> 2 | H14: =IF(Etapas!$B14="","",IF(AND(H$4<=Etapas!$E14,H$4+6>=Etapas!$D14),IF(Etapas!$G14="Concluída",1,IF(Etapas!$G14="Atrasada",3,2)),"")) -> 2 | I14: =IF(Etapas!$B14="","",IF(AND(I$4<=Etapas!$E14,I$4+6>=Etapas!$D14),IF(Etapas!$G14="Concluída",1,IF(Etapas!$G14="Atrasada",3,2)),"")) -> 2 | J14: =IF(Etapas!$B14="","",IF(AND(J$4<=Etapas!$E14,J$4+6>=Etapas!$D14),IF(Etapas!$G14="Concluída",1,IF(Etapas!$G14="Atrasada",3,2)),"")) -> 2 | K14: =IF(Etapas!$B14="","",IF(AND(K$4<=Etapas!$E14,K$4+6>=Etapas!$D14),IF(Etapas!$G14="Concluída",1,IF(Etapas!$G14="Atrasada",3,2)),"")) | L14: =IF(Etapas!$B14="","",IF(AND(L$4<=Etapas!$E14,L$4+6>=Etapas!$D14),IF(Etapas!$G14="Concluída",1,IF(Etapas!$G14="Atrasada",3,2)),"")) | ... R14: =IF(Etapas!$B14="","",IF(AND(R$4<=Etapas!$E14,R$4+6>=Etapas!$D14),IF(Etapas!$G14="Concluída",1,IF(Etapas!$G14="Atrasada",3,2)),""))
A15: =IF(Etapas!B15="","",Etapas!A15) -> Campanha de fim de ano · Bistrô 42 | B15: =IF(Etapas!B15="","",Etapas!B15) -> Plano de mídia | C15: =IF(Etapas!B15="","",Etapas!C15) -> Ana | D15: =IF(Etapas!B15="","",Etapas!E15) -> 46315 | E15: =IF(Etapas!$B15="","",IF(AND(E$4<=Etapas!$E15,E$4+6>=Etapas!$D15),IF(Etapas!$G15="Concluída",1,IF(Etapas!$G15="Atrasada",3,2)),"")) | F15: =IF(Etapas!$B15="","",IF(AND(F$4<=Etapas!$E15,F$4+6>=Etapas!$D15),IF(Etapas!$G15="Concluída",1,IF(Etapas!$G15="Atrasada",3,2)),"")) | G15: =IF(Etapas!$B15="","",IF(AND(G$4<=Etapas!$E15,G$4+6>=Etapas!$D15),IF(Etapas!$G15="Concluída",1,IF(Etapas!$G15="Atrasada",3,2)),"")) | H15: =IF(Etapas!$B15="","",IF(AND(H$4<=Etapas!$E15,H$4+6>=Etapas!$D15),IF(Etapas!$G15="Concluída",1,IF(Etapas!$G15="Atrasada",3,2)),"")) -> 2 | I15: =IF(Etapas!$B15="","",IF(AND(I$4<=Etapas!$E15,I$4+6>=Etapas!$D15),IF(Etapas!$G15="Concluída",1,IF(Etapas!$G15="Atrasada",3,2)),"")) -> 2 | J15: =IF(Etapas!$B15="","",IF(AND(J$4<=Etapas!$E15,J$4+6>=Etapas!$D15),IF(Etapas!$G15="Concluída",1,IF(Etapas!$G15="Atrasada",3,2)),"")) -> 2 | K15: =IF(Etapas!$B15="","",IF(AND(K$4<=Etapas!$E15,K$4+6>=Etapas!$D15),IF(Etapas!$G15="Concluída",1,IF(Etapas!$G15="Atrasada",3,2)),"")) -> 2 | L15: =IF(Etapas!$B15="","",IF(AND(L$4<=Etapas!$E15,L$4+6>=Etapas!$D15),IF(Etapas!$G15="Concluída",1,IF(Etapas!$G15="Atrasada",3,2)),"")) | ... R15: =IF(Etapas!$B15="","",IF(AND(R$4<=Etapas!$E15,R$4+6>=Etapas!$D15),IF(Etapas!$G15="Concluída",1,IF(Etapas!$G15="Atrasada",3,2)),""))
A16: =IF(Etapas!B16="","",Etapas!A16) -> Campanha de fim de ano · Bistrô 42 | B16: =IF(Etapas!B16="","",Etapas!B16) -> Veiculação | C16: =IF(Etapas!B16="","",Etapas!C16) -> Diego | D16: =IF(Etapas!B16="","",Etapas!E16) -> 46346 | E16: =IF(Etapas!$B16="","",IF(AND(E$4<=Etapas!$E16,E$4+6>=Etapas!$D16),IF(Etapas!$G16="Concluída",1,IF(Etapas!$G16="Atrasada",3,2)),"")) | F16: =IF(Etapas!$B16="","",IF(AND(F$4<=Etapas!$E16,F$4+6>=Etapas!$D16),IF(Etapas!$G16="Concluída",1,IF(Etapas!$G16="Atrasada",3,2)),"")) | G16: =IF(Etapas!$B16="","",IF(AND(G$4<=Etapas!$E16,G$4+6>=Etapas!$D16),IF(Etapas!$G16="Concluída",1,IF(Etapas!$G16="Atrasada",3,2)),"")) | H16: =IF(Etapas!$B16="","",IF(AND(H$4<=Etapas!$E16,H$4+6>=Etapas!$D16),IF(Etapas!$G16="Concluída",1,IF(Etapas!$G16="Atrasada",3,2)),"")) | I16: =IF(Etapas!$B16="","",IF(AND(I$4<=Etapas!$E16,I$4+6>=Etapas!$D16),IF(Etapas!$G16="Concluída",1,IF(Etapas!$G16="Atrasada",3,2)),"")) | J16: =IF(Etapas!$B16="","",IF(AND(J$4<=Etapas!$E16,J$4+6>=Etapas!$D16),IF(Etapas!$G16="Concluída",1,IF(Etapas!$G16="Atrasada",3,2)),"")) | K16: =IF(Etapas!$B16="","",IF(AND(K$4<=Etapas!$E16,K$4+6>=Etapas!$D16),IF(Etapas!$G16="Concluída",1,IF(Etapas!$G16="Atrasada",3,2)),"")) | L16: =IF(Etapas!$B16="","",IF(AND(L$4<=Etapas!$E16,L$4+6>=Etapas!$D16),IF(Etapas!$G16="Concluída",1,IF(Etapas!$G16="Atrasada",3,2)),"")) -> 2 | ... R16: =IF(Etapas!$B16="","",IF(AND(R$4<=Etapas!$E16,R$4+6>=Etapas!$D16),IF(Etapas!$G16="Concluída",1,IF(Etapas!$G16="Atrasada",3,2)),""))
... A44: =IF(Etapas!B44="","",Etapas!A44) | B44: =IF(Etapas!B44="","",Etapas!B44) | C44: =IF(Etapas!B44="","",Etapas!C44) | D44: =IF(Etapas!B44="","",Etapas!E44) | E44: =IF(Etapas!$B44="","",IF(AND(E$4<=Etapas!$E44,E$4+6>=Etapas!$D44),IF(Etapas!$G44="Concluída",1,IF(Etapas!$G44="Atrasada",3,2)),"")) | F44: =IF(Etapas!$B44="","",IF(AND(F$4<=Etapas!$E44,F$4+6>=Etapas!$D44),IF(Etapas!$G44="Concluída",1,IF(Etapas!$G44="Atrasada",3,2)),"")) | G44: =IF(Etapas!$B44="","",IF(AND(G$4<=Etapas!$E44,G$4+6>=Etapas!$D44),IF(Etapas!$G44="Concluída",1,IF(Etapas!$G44="Atrasada",3,2)),"")) | H44: =IF(Etapas!$B44="","",IF(AND(H$4<=Etapas!$E44,H$4+6>=Etapas!$D44),IF(Etapas!$G44="Concluída",1,IF(Etapas!$G44="Atrasada",3,2)),"")) | I44: =IF(Etapas!$B44="","",IF(AND(I$4<=Etapas!$E44,I$4+6>=Etapas!$D44),IF(Etapas!$G44="Concluída",1,IF(Etapas!$G44="Atrasada",3,2)),"")) | J44: =IF(Etapas!$B44="","",IF(AND(J$4<=Etapas!$E44,J$4+6>=Etapas!$D44),IF(Etapas!$G44="Concluída",1,IF(Etapas!$G44="Atrasada",3,2)),"")) | K44: =IF(Etapas!$B44="","",IF(AND(K$4<=Etapas!$E44,K$4+6>=Etapas!$D44),IF(Etapas!$G44="Concluída",1,IF(Etapas!$G44="Atrasada",3,2)),"")) | L44: =IF(Etapas!$B44="","",IF(AND(L$4<=Etapas!$E44,L$4+6>=Etapas!$D44),IF(Etapas!$G44="Concluída",1,IF(Etapas!$G44="Atrasada",3,2)),"")) | ... R44: =IF(Etapas!$B44="","",IF(AND(R$4<=Etapas!$E44,R$4+6>=Etapas!$D44),IF(Etapas!$G44="Concluída",1,IF(Etapas!$G44="Atrasada",3,2)),""))

Sheet Config
A1: Configurações
A2: Células amarelas: você preenche. Os projetos cadastrados aqui aparecem nas listas da aba Etapas.
A4: Equipe ou empresa | B4: Prisma Comunicação (exemplo fictício)
A5: Data de referência (hoje) | B5: 46279 | C5: O exemplo está congelado em 14/09/2026, para os arquivos do kit mostrarem a mesma foto. Ao usar com os seus dados, troque por =HOJE().
A6: Avisar entregas nos próximos (dias) | B6: 7
A8: Projetos (até 10)
A9: Projeto | B9: Cliente ou área | C9: Responsável | D9: Início | E9: Prazo final | F9: Situação
A10: Site novo · Loja Verde | B10: Loja Verde | C10: Ana | D10: 46244 | E10: 46304 | F10: =IF(A10="","",IF(COUNTIFS(Etapas!$A$5:$A$304,A10)=0,"Sem etapas",IF(COUNTIFS(Etapas!$A$5:$A$304,A10,Etapas!$G$5:$G$304,"Atrasada")>0,"Com atraso",IF(COUNTIFS(Etapas!$A$5:$A$304,A10,Etapas!$G$5:$G$304,"Concluída")=COUNTIFS(Etapas!$A$5:$A$304,A10),"Concluído","No prazo")))) -> Com atraso
A11: Campanha de fim de ano · Bistrô 42 | B11: Bistrô 42 | C11: Carla | D11: 46266 | E11: 46346 | F11: =IF(A11="","",IF(COUNTIFS(Etapas!$A$5:$A$304,A11)=0,"Sem etapas",IF(COUNTIFS(Etapas!$A$5:$A$304,A11,Etapas!$G$5:$G$304,"Atrasada")>0,"Com atraso",IF(COUNTIFS(Etapas!$A$5:$A$304,A11,Etapas!$G$5:$G$304,"Concluída")=COUNTIFS(Etapas!$A$5:$A$304,A11),"Concluído","No prazo")))) -> No prazo
A12: Relatório anual · Horizonte | B12: Horizonte | C12: Ana | D12: 46273 | E12: 46295 | F12: =IF(A12="","",IF(COUNTIFS(Etapas!$A$5:$A$304,A12)=0,"Sem etapas",IF(COUNTIFS(Etapas!$A$5:$A$304,A12,Etapas!$G$5:$G$304,"Atrasada")>0,"Com atraso",IF(COUNTIFS(Etapas!$A$5:$A$304,A12,Etapas!$G$5:$G$304,"Concluída")=COUNTIFS(Etapas!$A$5:$A$304,A12),"Concluído","No prazo")))) -> No prazo
A13: Identidade visual · Padaria do Sol | B13: Padaria do Sol | C13: Bruno | D13: 46218 | E13: 46270 | F13: =IF(A13="","",IF(COUNTIFS(Etapas!$A$5:$A$304,A13)=0,"Sem etapas",IF(COUNTIFS(Etapas!$A$5:$A$304,A13,Etapas!$G$5:$G$304,"Atrasada")>0,"Com atraso",IF(COUNTIFS(Etapas!$A$5:$A$304,A13,Etapas!$G$5:$G$304,"Concluída")=COUNTIFS(Etapas!$A$5:$A$304,A13),"Concluído","No prazo")))) -> Com atraso
F14: =IF(A14="","",IF(COUNTIFS(Etapas!$A$5:$A$304,A14)=0,"Sem etapas",IF(COUNTIFS(Etapas!$A$5:$A$304,A14,Etapas!$G$5:$G$304,"Atrasada")>0,"Com atraso",IF(COUNTIFS(Etapas!$A$5:$A$304,A14,Etapas!$G$5:$G$304,"Concluída")=COUNTIFS(Etapas!$A$5:$A$304,A14),"Concluído","No prazo"))))
F15: =IF(A15="","",IF(COUNTIFS(Etapas!$A$5:$A$304,A15)=0,"Sem etapas",IF(COUNTIFS(Etapas!$A$5:$A$304,A15,Etapas!$G$5:$G$304,"Atrasada")>0,"Com atraso",IF(COUNTIFS(Etapas!$A$5:$A$304,A15,Etapas!$G$5:$G$304,"Concluída")=COUNTIFS(Etapas!$A$5:$A$304,A15),"Concluído","No prazo"))))
F16: =IF(A16="","",IF(COUNTIFS(Etapas!$A$5:$A$304,A16)=0,"Sem etapas",IF(COUNTIFS(Etapas!$A$5:$A$304,A16,Etapas!$G$5:$G$304,"Atrasada")>0,"Com atraso",IF(COUNTIFS(Etapas!$A$5:$A$304,A16,Etapas!$G$5:$G$304,"Concluída")=COUNTIFS(Etapas!$A$5:$A$304,A16),"Concluído","No prazo"))))
F17: =IF(A17="","",IF(COUNTIFS(Etapas!$A$5:$A$304,A17)=0,"Sem etapas",IF(COUNTIFS(Etapas!$A$5:$A$304,A17,Etapas!$G$5:$G$304,"Atrasada")>0,"Com atraso",IF(COUNTIFS(Etapas!$A$5:$A$304,A17,Etapas!$G$5:$G$304,"Concluída")=COUNTIFS(Etapas!$A$5:$A$304,A17),"Concluído","No prazo"))))
F18: =IF(A18="","",IF(COUNTIFS(Etapas!$A$5:$A$304,A18)=0,"Sem etapas",IF(COUNTIFS(Etapas!$A$5:$A$304,A18,Etapas!$G$5:$G$304,"Atrasada")>0,"Com atraso",IF(COUNTIFS(Etapas!$A$5:$A$304,A18,Etapas!$G$5:$G$304,"Concluída")=COUNTIFS(Etapas!$A$5:$A$304,A18),"Concluído","No prazo"))))
F19: =IF(A19="","",IF(COUNTIFS(Etapas!$A$5:$A$304,A19)=0,"Sem etapas",IF(COUNTIFS(Etapas!$A$5:$A$304,A19,Etapas!$G$5:$G$304,"Atrasada")>0,"Com atraso",IF(COUNTIFS(Etapas!$A$5:$A$304,A19,Etapas!$G$5:$G$304,"Concluída")=COUNTIFS(Etapas!$A$5:$A$304,A19),"Concluído","No prazo"))))
A21: Responsáveis (até 10)
A22: Ana
A23: Bruno
A24: Carla
A25: Diego

Sheet Etapas
A1: Etapas
A2: Uma linha por etapa. Preencha as colunas amarelas; situação e dias são calculados. Apague os exemplos e comece o seu.
A4: Projeto | B4: Etapa | C4: Responsável | D4: Início | E4: Fim previsto | F4: % concluído | G4: Situação | H4: Dias para o fim | I4: Fim real | J4: Observação | K4: Chave
A5: Site novo · Loja Verde | B5: Briefing e mapa do site | C5: Ana | D5: 46244 | E5: 46249 | F5: 1 | G5: =IF(B5="","",IF(OR(F5>=1,I5<>""),"Concluída",IF(E5="","Falta o prazo",IF(E5<Config!$B$5,"Atrasada",IF(E5-Config!$B$5<=Config!$B$6,"Vence em breve",IF(D5<=Config!$B$5,"Em andamento","A iniciar")))))) -> Concluída | H5: =IF(OR(B5="",G5="Concluída",E5=""),"",E5-Config!$B$5) | I5: 46248 | K5: =IF(OR(B5="",G5="Concluída"),0,IF(G5="Atrasada",3000+MIN(Config!$B$5-E5,60),IF(G5="Vence em breve",2000-(E5-Config!$B$5),IF(G5="Em andamento",1000-MIN(E5-Config!$B$5,900),100)))-ROW()/100000) -> 0 | L5: =IF(B5="","",IF(I5<>"",1,N(F5))) -> 1
A6: Site novo · Loja Verde | B6: Wireframes das 5 páginas | C6: Ana | D6: 46250 | E6: 46260 | F6: 1 | G6: =IF(B6="","",IF(OR(F6>=1,I6<>""),"Concluída",IF(E6="","Falta o prazo",IF(E6<Config!$B$5,"Atrasada",IF(E6-Config!$B$5<=Config!$B$6,"Vence em breve",IF(D6<=Config!$B$5,"Em andamento","A iniciar")))))) -> Concluída | H6: =IF(OR(B6="",G6="Concluída",E6=""),"",E6-Config!$B$5) | I6: 46261 | K6: =IF(OR(B6="",G6="Concluída"),0,IF(G6="Atrasada",3000+MIN(Config!$B$5-E6,60),IF(G6="Vence em breve",2000-(E6-Config!$B$5),IF(G6="Em andamento",1000-MIN(E6-Config!$B$5,900),100)))-ROW()/100000) -> 0 | L6: =IF(B6="","",IF(I6<>"",1,N(F6))) -> 1
A7: Site novo · Loja Verde | B7: Layout da home | C7: Bruno | D7: 46261 | E7: 46273 | F7: 1 | G7: =IF(B7="","",IF(OR(F7>=1,I7<>""),"Concluída",IF(E7="","Falta o prazo",IF(E7<Config!$B$5,"Atrasada",IF(E7-Config!$B$5<=Config!$B$6,"Vence em breve",IF(D7<=Config!$B$5,"Em andamento","A iniciar")))))) -> Concluída | H7: =IF(OR(B7="",G7="Concluída",E7=""),"",E7-Config!$B$5) | I7: 46273 | K7: =IF(OR(B7="",G7="Concluída"),0,IF(G7="Atrasada",3000+MIN(Config!$B$5-E7,60),IF(G7="Vence em breve",2000-(E7-Config!$B$5),IF(G7="Em andamento",1000-MIN(E7-Config!$B$5,900),100)))-ROW()/100000) -> 0 | L7: =IF(B7="","",IF(I7<>"",1,N(F7))) -> 1
A8: Site novo · Loja Verde | B8: Layout das páginas internas | C8: Bruno | D8: 46274 | E8: 46284 | F8: 0.6 | G8: =IF(B8="","",IF(OR(F8>=1,I8<>""),"Concluída",IF(E8="","Falta o prazo",IF(E8<Config!$B$5,"Atrasada",IF(E8-Config!$B$5<=Config!$B$6,"Vence em breve",IF(D8<=Config!$B$5,"Em andamento","A iniciar")))))) -> Vence em breve | H8: =IF(OR(B8="",G8="Concluída",E8=""),"",E8-Config!$B$5) -> 5 | K8: =IF(OR(B8="",G8="Concluída"),0,IF(G8="Atrasada",3000+MIN(Config!$B$5-E8,60),IF(G8="Vence em breve",2000-(E8-Config!$B$5),IF(G8="Em andamento",1000-MIN(E8-Config!$B$5,900),100)))-ROW()/100000) -> 1994.9999 | L8: =IF(B8="","",IF(I8<>"",1,N(F8))) -> 0.6
A9: Site novo · Loja Verde | B9: Textos das páginas | C9: Carla | D9: 46267 | E9: 46277 | F9: 0.7 | G9: =IF(B9="","",IF(OR(F9>=1,I9<>""),"Concluída",IF(E9="","Falta o prazo",IF(E9<Config!$B$5,"Atrasada",IF(E9-Config!$B$5<=Config!$B$6,"Vence em breve",IF(D9<=Config!$B$5,"Em andamento","A iniciar")))))) -> Atrasada | H9: =IF(OR(B9="",G9="Concluída",E9=""),"",E9-Config!$B$5) -> -2 | K9: =IF(OR(B9="",G9="Concluída"),0,IF(G9="Atrasada",3000+MIN(Config!$B$5-E9,60),IF(G9="Vence em breve",2000-(E9-Config!$B$5),IF(G9="Em andamento",1000-MIN(E9-Config!$B$5,900),100)))-ROW()/100000) -> 3001.9999 | L9: =IF(B9="","",IF(I9<>"",1,N(F9))) -> 0.7
A10: Site novo · Loja Verde | B10: Implementação | C10: Diego | D10: 46285 | E10: 46298 | F10: 0 | G10: =IF(B10="","",IF(OR(F10>=1,I10<>""),"Concluída",IF(E10="","Falta o prazo",IF(E10<Config!$B$5,"Atrasada",IF(E10-Config!$B$5<=Config!$B$6,"Vence em breve",IF(D10<=Config!$B$5,"Em andamento","A iniciar")))))) -> A iniciar | H10: =IF(OR(B10="",G10="Concluída",E10=""),"",E10-Config!$B$5) -> 19 | K10: =IF(OR(B10="",G10="Concluída"),0,IF(G10="Atrasada",3000+MIN(Config!$B$5-E10,60),IF(G10="Vence em breve",2000-(E10-Config!$B$5),IF(G10="Em andamento",1000-MIN(E10-Config!$B$5,900),100)))-ROW()/100000) -> 99.9999 | L10: =IF(B10="","",IF(I10<>"",1,N(F10))) -> 0
A11: Site novo · Loja Verde | B11: Revisão e publicação | C11: Ana | D11: 46299 | E11: 46304 | F11: 0 | G11: =IF(B11="","",IF(OR(F11>=1,I11<>""),"Concluída",IF(E11="","Falta o prazo",IF(E11<Config!$B$5,"Atrasada",IF(E11-Config!$B$5<=Config!$B$6,"Vence em breve",IF(D11<=Config!$B$5,"Em andamento","A iniciar")))))) -> A iniciar | H11: =IF(OR(B11="",G11="Concluída",E11=""),"",E11-Config!$B$5) -> 25 | K11: =IF(OR(B11="",G11="Concluída"),0,IF(G11="Atrasada",3000+MIN(Config!$B$5-E11,60),IF(G11="Vence em breve",2000-(E11-Config!$B$5),IF(G11="Em andamento",1000-MIN(E11-Config!$B$5,900),100)))-ROW()/100000) -> 99.99989 | L11: =IF(B11="","",IF(I11<>"",1,N(F11))) -> 0
