Workbook

Sheet Como usar
A1: Ata e Pendências
A2: Kit IA no Trabalho · Completo · Seu Sócio Gestor · versão 1.0 (setembro de 2026)
A4: O que esta planilha faz | B4: Registra cada reunião (data, assunto, participantes, decisões) e cada pendência com dono e prazo. Mostra o que cobrar primeiro, a carga por pessoa e monta o resumo pronto para a IA transformar em e-mail ou ata.
A5: Passo 1 | B5: Em Config, preencha o nome da equipe e as pessoas. Troque a data de referência por =HOJE() (no exemplo ela está congelada em 14/09/2026).
A6: Passo 2 | B6: Em Reuniões, uma linha por reunião. Escreva as decisões em frases curtas separadas por ponto e vírgula. O código (R-001, R-002...) é automático.
A7: Passo 3 | B7: Em Pendências, uma linha por tarefa que saiu da reunião: reunião (lista), pendência, dono (lista), prazo, prioridade e status. Ao concluir, mude o status para Feito.
A8: Passo 4 | B8: Em Em aberto, veja o que cobrar primeiro e a carga por pessoa. Em Resumo, escolha a reunião em Config e copie o bloco único.
A9: Rotina | B9: Logo depois da reunião, 5 minutos para registrar. Segunda de manhã, olhe Em aberto e cobre por e-mail com o prompt "Escrever 02".
A10: Com a IA | B10: Bloco único da aba Resumo + prompt "Escrever 07: resumo de reunião para quem não foi". Para cobrar uma pendência atrasada: "Escrever 10: mensagem de cobrança educada".
A11: Legenda | B11: Células amarelas: você preenche. Brancas: calculadas. Não é preciso mexer em nada fora do amarelo.
A12: Proteção | B12: Fórmulas protegidas sem senha. Para editar: Revisar > Desproteger planilha (Excel) ou Dados > Proteger intervalos (Google Sheets).
A13: Requisitos | B13: Excel 2016 ou mais novo, Microsoft 365 ou Google Sheets (só funções do Excel 2007+; nada de MÍNIMOSES, MÁXIMOSES ou UNIRTEXTO). No celular abre nos aplicativos; para preencher, use o computador.
A14: Google Sheets | B14: Faça upload no Google Drive e abra com o Google Sheets. Fórmulas, listas, cores e semáforos funcionam: as regras de cor que dependem do mês escolhido em Config usam INDIRECT, que é a forma que o Sheets aceita para regra condicional apontar para outra aba.
A15: Data de referência | B15: O exemplo está congelado em 14/09/2026, para todos os arquivos do kit mostrarem a mesma foto e os números fecharem entre eles. Ao começar a usar com os SEUS dados, troque em Config: a data de referência por =HOJE(), o ano, o mês do painel, o trimestre (onde houver) e a lista de feriados. Trocar só a data de referência deixa o resto apontando para 2026.
... A17: Suporte | B17: suporte@seusociogestor.com.br · resposta em até 5 dias úteis · reembolso em até 7 dias pelo mesmo canal.

Sheet Em aberto
A1: =Config!B4&" · pendências em "&TEXT(DAY(Config!B5),"00")&"/"&TEXT(MONTH(Config!B5),"00")&"/"&YEAR(Config!B5) -> Prisma Comunicação (exemplo fictício) · pendências em 14/09/2026
A2: Nada para preencher aqui: tudo vem de Reuniões e Pendências.
A4: Abertas | C4: Atrasadas | E4: Para hoje | G4: Feitas no total
A5: =COUNTIFS(Pendências!$B$5:$B$304,"<>",Pendências!$F$5:$F$304,"<>Feito") -> 7 | C5: =COUNTIFS(Pendências!$H$5:$H$304,"Atrasada") -> 3 | E5: =COUNTIFS(Pendências!$H$5:$H$304,"Hoje") -> 0 | G5: =COUNTIFS(Pendências!$F$5:$F$304,"Feito") -> 5
A7: O que cobrar primeiro
A8: Ordem: atrasadas, hoje, esta semana; dentro de cada grupo, prioridade alta primeiro.
A9: # | B9: Pendência | C9: Dono | D9: Prazo | E9: Situação | F9: Prioridade | G9: Reunião | H9: Dias
A10: 1 | B10: =IFERROR(IF(LARGE(Pendências!$J$5:$J$304,1)>0,IF(INDEX(Pendências!$B$5:$B$304,MATCH(LARGE(Pendências!$J$5:$J$304,1),Pendências!$J$5:$J$304,0))="","",INDEX(Pendências!$B$5:$B$304,MATCH(LARGE(Pendências!$J$5:$J$304,1),Pendências!$J$5:$J$304,0))),""),"") -> Escrever os textos das 5 páginas do site | C10: =IFERROR(IF(LARGE(Pendências!$J$5:$J$304,1)>0,IF(INDEX(Pendências!$C$5:$C$304,MATCH(LARGE(Pendências!$J$5:$J$304,1),Pendências!$J$5:$J$304,0))="","",INDEX(Pendências!$C$5:$C$304,MATCH(LARGE(Pendências!$J$5:$J$304,1),Pendências!$J$5:$J$304,0))),""),"") -> Carla | D10: =IFERROR(IF(LARGE(Pendências!$J$5:$J$304,1)>0,IF(INDEX(Pendências!$D$5:$D$304,MATCH(LARGE(Pendências!$J$5:$J$304,1),Pendências!$J$5:$J$304,0))="","",INDEX(Pendências!$D$5:$D$304,MATCH(LARGE(Pendências!$J$5:$J$304,1),Pendências!$J$5:$J$304,0))),""),"") -> 46277 | E10: =IFERROR(IF(LARGE(Pendências!$J$5:$J$304,1)>0,IF(INDEX(Pendências!$H$5:$H$304,MATCH(LARGE(Pendências!$J$5:$J$304,1),Pendências!$J$5:$J$304,0))="","",INDEX(Pendências!$H$5:$H$304,MATCH(LARGE(Pendências!$J$5:$J$304,1),Pendências!$J$5:$J$304,0))),""),"") -> Atrasada | F10: =IFERROR(IF(LARGE(Pendências!$J$5:$J$304,1)>0,IF(INDEX(Pendências!$E$5:$E$304,MATCH(LARGE(Pendências!$J$5:$J$304,1),Pendências!$J$5:$J$304,0))="","",INDEX(Pendências!$E$5:$E$304,MATCH(LARGE(Pendências!$J$5:$J$304,1),Pendências!$J$5:$J$304,0))),""),"") -> Alta | G10: =IFERROR(IF(LARGE(Pendências!$J$5:$J$304,1)>0,IF(INDEX(Pendências!$A$5:$A$304,MATCH(LARGE(Pendências!$J$5:$J$304,1),Pendências!$J$5:$J$304,0))="","",INDEX(Pendências!$A$5:$A$304,MATCH(LARGE(Pendências!$J$5:$J$304,1),Pendências!$J$5:$J$304,0))),""),"") -> R-002 | H10: =IFERROR(IF(LARGE(Pendências!$J$5:$J$304,1)>0,IF(INDEX(Pendências!$I$5:$I$304,MATCH(LARGE(Pendências!$J$5:$J$304,1),Pendências!$J$5:$J$304,0))="","",INDEX(Pendências!$I$5:$I$304,MATCH(LARGE(Pendências!$J$5:$J$304,1),Pendências!$J$5:$J$304,0))),""),"") -> -2
A11: 2 | B11: =IFERROR(IF(LARGE(Pendências!$J$5:$J$304,2)>0,IF(INDEX(Pendências!$B$5:$B$304,MATCH(LARGE(Pendências!$J$5:$J$304,2),Pendências!$J$5:$J$304,0))="","",INDEX(Pendências!$B$5:$B$304,MATCH(LARGE(Pendências!$J$5:$J$304,2),Pendências!$J$5:$J$304,0))),""),"") -> Confirmar a reunião de quarta com o Bistrô | C11: =IFERROR(IF(LARGE(Pendências!$J$5:$J$304,2)>0,IF(INDEX(Pendências!$C$5:$C$304,MATCH(LARGE(Pendências!$J$5:$J$304,2),Pendências!$J$5:$J$304,0))="","",INDEX(Pendências!$C$5:$C$304,MATCH(LARGE(Pendências!$J$5:$J$304,2),Pendências!$J$5:$J$304,0))),""),"") -> Ana | D11: =IFERROR(IF(LARGE(Pendências!$J$5:$J$304,2)>0,IF(INDEX(Pendências!$D$5:$D$304,MATCH(LARGE(Pendências!$J$5:$J$304,2),Pendências!$J$5:$J$304,0))="","",INDEX(Pendências!$D$5:$D$304,MATCH(LARGE(Pendências!$J$5:$J$304,2),Pendências!$J$5:$J$304,0))),""),"") -> 46276 | E11: =IFERROR(IF(LARGE(Pendências!$J$5:$J$304,2)>0,IF(INDEX(Pendências!$H$5:$H$304,MATCH(LARGE(Pendências!$J$5:$J$304,2),Pendências!$J$5:$J$304,0))="","",INDEX(Pendências!$H$5:$H$304,MATCH(LARGE(Pendências!$J$5:$J$304,2),Pendências!$J$5:$J$304,0))),""),"") -> Atrasada | F11: =IFERROR(IF(LARGE(Pendências!$J$5:$J$304,2)>0,IF(INDEX(Pendências!$E$5:$E$304,MATCH(LARGE(Pendências!$J$5:$J$304,2),Pendências!$J$5:$J$304,0))="","",INDEX(Pendências!$E$5:$E$304,MATCH(LARGE(Pendências!$J$5:$J$304,2),Pendências!$J$5:$J$304,0))),""),"") -> Média | G11: =IFERROR(IF(LARGE(Pendências!$J$5:$J$304,2)>0,IF(INDEX(Pendências!$A$5:$A$304,MATCH(LARGE(Pendências!$J$5:$J$304,2),Pendências!$J$5:$J$304,0))="","",INDEX(Pendências!$A$5:$A$304,MATCH(LARGE(Pendências!$J$5:$J$304,2),Pendências!$J$5:$J$304,0))),""),"") -> R-004 | H11: =IFERROR(IF(LARGE(Pendências!$J$5:$J$304,2)>0,IF(INDEX(Pendências!$I$5:$I$304,MATCH(LARGE(Pendências!$J$5:$J$304,2),Pendências!$J$5:$J$304,0))="","",INDEX(Pendências!$I$5:$I$304,MATCH(LARGE(Pendências!$J$5:$J$304,2),Pendências!$J$5:$J$304,0))),""),"") -> -3
A12: 3 | B12: =IFERROR(IF(LARGE(Pendências!$J$5:$J$304,3)>0,IF(INDEX(Pendências!$B$5:$B$304,MATCH(LARGE(Pendências!$J$5:$J$304,3),Pendências!$J$5:$J$304,0))="","",INDEX(Pendências!$B$5:$B$304,MATCH(LARGE(Pendências!$J$5:$J$304,3),Pendências!$J$5:$J$304,0))),""),"") -> Levantar custo do freela de motion | C12: =IFERROR(IF(LARGE(Pendências!$J$5:$J$304,3)>0,IF(INDEX(Pendências!$C$5:$C$304,MATCH(LARGE(Pendências!$J$5:$J$304,3),Pendências!$J$5:$J$304,0))="","",INDEX(Pendências!$C$5:$C$304,MATCH(LARGE(Pendências!$J$5:$J$304,3),Pendências!$J$5:$J$304,0))),""),"") -> Ana | D12: =IFERROR(IF(LARGE(Pendências!$J$5:$J$304,3)>0,IF(INDEX(Pendências!$D$5:$D$304,MATCH(LARGE(Pendências!$J$5:$J$304,3),Pendências!$J$5:$J$304,0))="","",INDEX(Pendências!$D$5:$D$304,MATCH(LARGE(Pendências!$J$5:$J$304,3),Pendências!$J$5:$J$304,0))),""),"") -> 46278 | E12: =IFERROR(IF(LARGE(Pendências!$J$5:$J$304,3)>0,IF(INDEX(Pendências!$H$5:$H$304,MATCH(LARGE(Pendências!$J$5:$J$304,3),Pendências!$J$5:$J$304,0))="","",INDEX(Pendências!$H$5:$H$304,MATCH(LARGE(Pendências!$J$5:$J$304,3),Pendências!$J$5:$J$304,0))),""),"") -> Atrasada | F12: =IFERROR(IF(LARGE(Pendências!$J$5:$J$304,3)>0,IF(INDEX(Pendências!$E$5:$E$304,MATCH(LARGE(Pendências!$J$5:$J$304,3),Pendências!$J$5:$J$304,0))="","",INDEX(Pendências!$E$5:$E$304,MATCH(LARGE(Pendências!$J$5:$J$304,3),Pendências!$J$5:$J$304,0))),""),"") -> Baixa | G12: =IFERROR(IF(LARGE(Pendências!$J$5:$J$304,3)>0,IF(INDEX(Pendências!$A$5:$A$304,MATCH(LARGE(Pendências!$J$5:$J$304,3),Pendências!$J$5:$J$304,0))="","",INDEX(Pendências!$A$5:$A$304,MATCH(LARGE(Pendências!$J$5:$J$304,3),Pendências!$J$5:$J$304,0))),""),"") -> R-004 | H12: =IFERROR(IF(LARGE(Pendências!$J$5:$J$304,3)>0,IF(INDEX(Pendências!$I$5:$I$304,MATCH(LARGE(Pendências!$J$5:$J$304,3),Pendências!$J$5:$J$304,0))="","",INDEX(Pendências!$I$5:$I$304,MATCH(LARGE(Pendências!$J$5:$J$304,3),Pendências!$J$5:$J$304,0))),""),"") -> -1
A13: 4 | B13: =IFERROR(IF(LARGE(Pendências!$J$5:$J$304,4)>0,IF(INDEX(Pendências!$B$5:$B$304,MATCH(LARGE(Pendências!$J$5:$J$304,4),Pendências!$J$5:$J$304,0))="","",INDEX(Pendências!$B$5:$B$304,MATCH(LARGE(Pendências!$J$5:$J$304,4),Pendências!$J$5:$J$304,0))),""),"") -> Fechar o manual da marca da Padaria | C13: =IFERROR(IF(LARGE(Pendências!$J$5:$J$304,4)>0,IF(INDEX(Pendências!$C$5:$C$304,MATCH(LARGE(Pendências!$J$5:$J$304,4),Pendências!$J$5:$J$304,0))="","",INDEX(Pendências!$C$5:$C$304,MATCH(LARGE(Pendências!$J$5:$J$304,4),Pendências!$J$5:$J$304,0))),""),"") -> Carla | D13: =IFERROR(IF(LARGE(Pendências!$J$5:$J$304,4)>0,IF(INDEX(Pendências!$D$5:$D$304,MATCH(LARGE(Pendências!$J$5:$J$304,4),Pendências!$J$5:$J$304,0))="","",INDEX(Pendências!$D$5:$D$304,MATCH(LARGE(Pendências!$J$5:$J$304,4),Pendências!$J$5:$J$304,0))),""),"") -> 46280 | E13: =IFERROR(IF(LARGE(Pendências!$J$5:$J$304,4)>0,IF(INDEX(Pendências!$H$5:$H$304,MATCH(LARGE(Pendências!$J$5:$J$304,4),Pendências!$J$5:$J$304,0))="","",INDEX(Pendências!$H$5:$H$304,MATCH(LARGE(Pendências!$J$5:$J$304,4),Pendências!$J$5:$J$304,0))),""),"") -> Esta semana | F13: =IFERROR(IF(LARGE(Pendências!$J$5:$J$304,4)>0,IF(INDEX(Pendências!$E$5:$E$304,MATCH(LARGE(Pendências!$J$5:$J$304,4),Pendências!$J$5:$J$304,0))="","",INDEX(Pendências!$E$5:$E$304,MATCH(LARGE(Pendências!$J$5:$J$304,4),Pendências!$J$5:$J$304,0))),""),"") -> Alta | G13: =IFERROR(IF(LARGE(Pendências!$J$5:$J$304,4)>0,IF(INDEX(Pendências!$A$5:$A$304,MATCH(LARGE(Pendências!$J$5:$J$304,4),Pendências!$J$5:$J$304,0))="","",INDEX(Pendências!$A$5:$A$304,MATCH(LARGE(Pendências!$J$5:$J$304,4),Pendências!$J$5:$J$304,0))),""),"") -> R-004 | H13: =IFERROR(IF(LARGE(Pendências!$J$5:$J$304,4)>0,IF(INDEX(Pendências!$I$5:$I$304,MATCH(LARGE(Pendências!$J$5:$J$304,4),Pendências!$J$5:$J$304,0))="","",INDEX(Pendências!$I$5:$I$304,MATCH(LARGE(Pendências!$J$5:$J$304,4),Pendências!$J$5:$J$304,0))),""),"") -> 1
A14: 5 | B14: =IFERROR(IF(LARGE(Pendências!$J$5:$J$304,5)>0,IF(INDEX(Pendências!$B$5:$B$304,MATCH(LARGE(Pendências!$J$5:$J$304,5),Pendências!$J$5:$J$304,0))="","",INDEX(Pendências!$B$5:$B$304,MATCH(LARGE(Pendências!$J$5:$J$304,5),Pendências!$J$5:$J$304,0))),""),"") -> Enviar 3 referências de diagramação | C14: =IFERROR(IF(LARGE(Pendências!$J$5:$J$304,5)>0,IF(INDEX(Pendências!$C$5:$C$304,MATCH(LARGE(Pendências!$J$5:$J$304,5),Pendências!$J$5:$J$304,0))="","",INDEX(Pendências!$C$5:$C$304,MATCH(LARGE(Pendências!$J$5:$J$304,5),Pendências!$J$5:$J$304,0))),""),"") -> Bruno | D14: =IFERROR(IF(LARGE(Pendências!$J$5:$J$304,5)>0,IF(INDEX(Pendências!$D$5:$D$304,MATCH(LARGE(Pendências!$J$5:$J$304,5),Pendências!$J$5:$J$304,0))="","",INDEX(Pendências!$D$5:$D$304,MATCH(LARGE(Pendências!$J$5:$J$304,5),Pendências!$J$5:$J$304,0))),""),"") -> 46281 | E14: =IFERROR(IF(LARGE(Pendências!$J$5:$J$304,5)>0,IF(INDEX(Pendências!$H$5:$H$304,MATCH(LARGE(Pendências!$J$5:$J$304,5),Pendências!$J$5:$J$304,0))="","",INDEX(Pendências!$H$5:$H$304,MATCH(LARGE(Pendências!$J$5:$J$304,5),Pendências!$J$5:$J$304,0))),""),"") -> Esta semana | F14: =IFERROR(IF(LARGE(Pendências!$J$5:$J$304,5)>0,IF(INDEX(Pendências!$E$5:$E$304,MATCH(LARGE(Pendências!$J$5:$J$304,5),Pendências!$J$5:$J$304,0))="","",INDEX(Pendências!$E$5:$E$304,MATCH(LARGE(Pendências!$J$5:$J$304,5),Pendências!$J$5:$J$304,0))),""),"") -> Média | G14: =IFERROR(IF(LARGE(Pendências!$J$5:$J$304,5)>0,IF(INDEX(Pendências!$A$5:$A$304,MATCH(LARGE(Pendências!$J$5:$J$304,5),Pendências!$J$5:$J$304,0))="","",INDEX(Pendências!$A$5:$A$304,MATCH(LARGE(Pendências!$J$5:$J$304,5),Pendências!$J$5:$J$304,0))),""),"") -> R-003 | H14: =IFERROR(IF(LARGE(Pendências!$J$5:$J$304,5)>0,IF(INDEX(Pendências!$I$5:$I$304,MATCH(LARGE(Pendências!$J$5:$J$304,5),Pendências!$J$5:$J$304,0))="","",INDEX(Pendências!$I$5:$I$304,MATCH(LARGE(Pendências!$J$5:$J$304,5),Pendências!$J$5:$J$304,0))),""),"") -> 2
A15: 6 | B15: =IFERROR(IF(LARGE(Pendências!$J$5:$J$304,6)>0,IF(INDEX(Pendências!$B$5:$B$304,MATCH(LARGE(Pendências!$J$5:$J$304,6),Pendências!$J$5:$J$304,0))="","",INDEX(Pendências!$B$5:$B$304,MATCH(LARGE(Pendências!$J$5:$J$304,6),Pendências!$J$5:$J$304,0))),""),"") -> Preparar o servidor e o domínio do site | C15: =IFERROR(IF(LARGE(Pendências!$J$5:$J$304,6)>0,IF(INDEX(Pendências!$C$5:$C$304,MATCH(LARGE(Pendências!$J$5:$J$304,6),Pendências!$J$5:$J$304,0))="","",INDEX(Pendências!$C$5:$C$304,MATCH(LARGE(Pendências!$J$5:$J$304,6),Pendências!$J$5:$J$304,0))),""),"") -> Diego | D15: =IFERROR(IF(LARGE(Pendências!$J$5:$J$304,6)>0,IF(INDEX(Pendências!$D$5:$D$304,MATCH(LARGE(Pendências!$J$5:$J$304,6),Pendências!$J$5:$J$304,0))="","",INDEX(Pendências!$D$5:$D$304,MATCH(LARGE(Pendências!$J$5:$J$304,6),Pendências!$J$5:$J$304,0))),""),"") -> 46283 | E15: =IFERROR(IF(LARGE(Pendências!$J$5:$J$304,6)>0,IF(INDEX(Pendências!$H$5:$H$304,MATCH(LARGE(Pendências!$J$5:$J$304,6),Pendências!$J$5:$J$304,0))="","",INDEX(Pendências!$H$5:$H$304,MATCH(LARGE(Pendências!$J$5:$J$304,6),Pendências!$J$5:$J$304,0))),""),"") -> Esta semana | F15: =IFERROR(IF(LARGE(Pendências!$J$5:$J$304,6)>0,IF(INDEX(Pendências!$E$5:$E$304,MATCH(LARGE(Pendências!$J$5:$J$304,6),Pendências!$J$5:$J$304,0))="","",INDEX(Pendências!$E$5:$E$304,MATCH(LARGE(Pendências!$J$5:$J$304,6),Pendências!$J$5:$J$304,0))),""),"") -> Média | G15: =IFERROR(IF(LARGE(Pendências!$J$5:$J$304,6)>0,IF(INDEX(Pendências!$A$5:$A$304,MATCH(LARGE(Pendências!$J$5:$J$304,6),Pendências!$J$5:$J$304,0))="","",INDEX(Pendências!$A$5:$A$304,MATCH(LARGE(Pendências!$J$5:$J$304,6),Pendências!$J$5:$J$304,0))),""),"") -> R-004 | H15: =IFERROR(IF(LARGE(Pendências!$J$5:$J$304,6)>0,IF(INDEX(Pendências!$I$5:$I$304,MATCH(LARGE(Pendências!$J$5:$J$304,6),Pendências!$J$5:$J$304,0))="","",INDEX(Pendências!$I$5:$I$304,MATCH(LARGE(Pendências!$J$5:$J$304,6),Pendências!$J$5:$J$304,0))),""),"") -> 4
A16: 7 | B16: =IFERROR(IF(LARGE(Pendências!$J$5:$J$304,7)>0,IF(INDEX(Pendências!$B$5:$B$304,MATCH(LARGE(Pendências!$J$5:$J$304,7),Pendências!$J$5:$J$304,0))="","",INDEX(Pendências!$B$5:$B$304,MATCH(LARGE(Pendências!$J$5:$J$304,7),Pendências!$J$5:$J$304,0))),""),"") -> Revisar a proposta comercial da Aurora | C16: =IFERROR(IF(LARGE(Pendências!$J$5:$J$304,7)>0,IF(INDEX(Pendências!$C$5:$C$304,MATCH(LARGE(Pendências!$J$5:$J$304,7),Pendências!$J$5:$J$304,0))="","",INDEX(Pendências!$C$5:$C$304,MATCH(LARGE(Pendências!$J$5:$J$304,7),Pendências!$J$5:$J$304,0))),""),"") -> Ana | D16: =IFERROR(IF(LARGE(Pendências!$J$5:$J$304,7)>0,IF(INDEX(Pendências!$D$5:$D$304,MATCH(LARGE(Pendências!$J$5:$J$304,7),Pendências!$J$5:$J$304,0))="","",INDEX(Pendências!$D$5:$D$304,MATCH(LARGE(Pendências!$J$5:$J$304,7),Pendências!$J$5:$J$304,0))),""),"") | E16: =IFERROR(IF(LARGE(Pendências!$J$5:$J$304,7)>0,IF(INDEX(Pendências!$H$5:$H$304,MATCH(LARGE(Pendências!$J$5:$J$304,7),Pendências!$J$5:$J$304,0))="","",INDEX(Pendências!$H$5:$H$304,MATCH(LARGE(Pendências!$J$5:$J$304,7),Pendências!$J$5:$J$304,0))),""),"") -> Sem prazo | F16: =IFERROR(IF(LARGE(Pendências!$J$5:$J$304,7)>0,IF(INDEX(Pendências!$E$5:$E$304,MATCH(LARGE(Pendências!$J$5:$J$304,7),Pendências!$J$5:$J$304,0))="","",INDEX(Pendências!$E$5:$E$304,MATCH(LARGE(Pendências!$J$5:$J$304,7),Pendências!$J$5:$J$304,0))),""),"") -> Média | G16: =IFERROR(IF(LARGE(Pendências!$J$5:$J$304,7)>0,IF(INDEX(Pendências!$A$5:$A$304,MATCH(LARGE(Pendências!$J$5:$J$304,7),Pendências!$J$5:$J$304,0))="","",INDEX(Pendências!$A$5:$A$304,MATCH(LARGE(Pendências!$J$5:$J$304,7),Pendências!$J$5:$J$304,0))),""),"") -> R-004 | H16: =IFERROR(IF(LARGE(Pendências!$J$5:$J$304,7)>0,IF(INDEX(Pendências!$I$5:$I$304,MATCH(LARGE(Pendências!$J$5:$J$304,7),Pendências!$J$5:$J$304,0))="","",INDEX(Pendências!$I$5:$I$304,MATCH(LARGE(Pendências!$J$5:$J$304,7),Pendências!$J$5:$J$304,0))),""),"")
A17: 8 | B17: =IFERROR(IF(LARGE(Pendências!$J$5:$J$304,8)>0,IF(INDEX(Pendências!$B$5:$B$304,MATCH(LARGE(Pendências!$J$5:$J$304,8),Pendências!$J$5:$J$304,0))="","",INDEX(Pendências!$B$5:$B$304,MATCH(LARGE(Pendências!$J$5:$J$304,8),Pendências!$J$5:$J$304,0))),""),"") | C17: =IFERROR(IF(LARGE(Pendências!$J$5:$J$304,8)>0,IF(INDEX(Pendências!$C$5:$C$304,MATCH(LARGE(Pendências!$J$5:$J$304,8),Pendências!$J$5:$J$304,0))="","",INDEX(Pendências!$C$5:$C$304,MATCH(LARGE(Pendências!$J$5:$J$304,8),Pendências!$J$5:$J$304,0))),""),"") | D17: =IFERROR(IF(LARGE(Pendências!$J$5:$J$304,8)>0,IF(INDEX(Pendências!$D$5:$D$304,MATCH(LARGE(Pendências!$J$5:$J$304,8),Pendências!$J$5:$J$304,0))="","",INDEX(Pendências!$D$5:$D$304,MATCH(LARGE(Pendências!$J$5:$J$304,8),Pendências!$J$5:$J$304,0))),""),"") | E17: =IFERROR(IF(LARGE(Pendências!$J$5:$J$304,8)>0,IF(INDEX(Pendências!$H$5:$H$304,MATCH(LARGE(Pendências!$J$5:$J$304,8),Pendências!$J$5:$J$304,0))="","",INDEX(Pendências!$H$5:$H$304,MATCH(LARGE(Pendências!$J$5:$J$304,8),Pendências!$J$5:$J$304,0))),""),"") | F17: =IFERROR(IF(LARGE(Pendências!$J$5:$J$304,8)>0,IF(INDEX(Pendências!$E$5:$E$304,MATCH(LARGE(Pendências!$J$5:$J$304,8),Pendências!$J$5:$J$304,0))="","",INDEX(Pendências!$E$5:$E$304,MATCH(LARGE(Pendências!$J$5:$J$304,8),Pendências!$J$5:$J$304,0))),""),"") | G17: =IFERROR(IF(LARGE(Pendências!$J$5:$J$304,8)>0,IF(INDEX(Pendências!$A$5:$A$304,MATCH(LARGE(Pendências!$J$5:$J$304,8),Pendências!$J$5:$J$304,0))="","",INDEX(Pendências!$A$5:$A$304,MATCH(LARGE(Pendências!$J$5:$J$304,8),Pendências!$J$5:$J$304,0))),""),"") | H17: =IFERROR(IF(LARGE(Pendências!$J$5:$J$304,8)>0,IF(INDEX(Pendências!$I$5:$I$304,MATCH(LARGE(Pendências!$J$5:$J$304,8),Pendências!$J$5:$J$304,0))="","",INDEX(Pendências!$I$5:$I$304,MATCH(LARGE(Pendências!$J$5:$J$304,8),Pendências!$J$5:$J$304,0))),""),"")
A18: 9 | B18: =IFERROR(IF(LARGE(Pendências!$J$5:$J$304,9)>0,IF(INDEX(Pendências!$B$5:$B$304,MATCH(LARGE(Pendências!$J$5:$J$304,9),Pendências!$J$5:$J$304,0))="","",INDEX(Pendências!$B$5:$B$304,MATCH(LARGE(Pendências!$J$5:$J$304,9),Pendências!$J$5:$J$304,0))),""),"") | C18: =IFERROR(IF(LARGE(Pendências!$J$5:$J$304,9)>0,IF(INDEX(Pendências!$C$5:$C$304,MATCH(LARGE(Pendências!$J$5:$J$304,9),Pendências!$J$5:$J$304,0))="","",INDEX(Pendências!$C$5:$C$304,MATCH(LARGE(Pendências!$J$5:$J$304,9),Pendências!$J$5:$J$304,0))),""),"") | D18: =IFERROR(IF(LARGE(Pendências!$J$5:$J$304,9)>0,IF(INDEX(Pendências!$D$5:$D$304,MATCH(LARGE(Pendências!$J$5:$J$304,9),Pendências!$J$5:$J$304,0))="","",INDEX(Pendências!$D$5:$D$304,MATCH(LARGE(Pendências!$J$5:$J$304,9),Pendências!$J$5:$J$304,0))),""),"") | E18: =IFERROR(IF(LARGE(Pendências!$J$5:$J$304,9)>0,IF(INDEX(Pendências!$H$5:$H$304,MATCH(LARGE(Pendências!$J$5:$J$304,9),Pendências!$J$5:$J$304,0))="","",INDEX(Pendências!$H$5:$H$304,MATCH(LARGE(Pendências!$J$5:$J$304,9),Pendências!$J$5:$J$304,0))),""),"") | F18: =IFERROR(IF(LARGE(Pendências!$J$5:$J$304,9)>0,IF(INDEX(Pendências!$E$5:$E$304,MATCH(LARGE(Pendências!$J$5:$J$304,9),Pendências!$J$5:$J$304,0))="","",INDEX(Pendências!$E$5:$E$304,MATCH(LARGE(Pendências!$J$5:$J$304,9),Pendências!$J$5:$J$304,0))),""),"") | G18: =IFERROR(IF(LARGE(Pendências!$J$5:$J$304,9)>0,IF(INDEX(Pendências!$A$5:$A$304,MATCH(LARGE(Pendências!$J$5:$J$304,9),Pendências!$J$5:$J$304,0))="","",INDEX(Pendências!$A$5:$A$304,MATCH(LARGE(Pendências!$J$5:$J$304,9),Pendências!$J$5:$J$304,0))),""),"") | H18: =IFERROR(IF(LARGE(Pendências!$J$5:$J$304,9)>0,IF(INDEX(Pendências!$I$5:$I$304,MATCH(LARGE(Pendências!$J$5:$J$304,9),Pendências!$J$5:$J$304,0))="","",INDEX(Pendências!$I$5:$I$304,MATCH(LARGE(Pendências!$J$5:$J$304,9),Pendências!$J$5:$J$304,0))),""),"")
A19: 10 | B19: =IFERROR(IF(LARGE(Pendências!$J$5:$J$304,10)>0,IF(INDEX(Pendências!$B$5:$B$304,MATCH(LARGE(Pendências!$J$5:$J$304,10),Pendências!$J$5:$J$304,0))="","",INDEX(Pendências!$B$5:$B$304,MATCH(LARGE(Pendências!$J$5:$J$304,10),Pendências!$J$5:$J$304,0))),""),"") | C19: =IFERROR(IF(LARGE(Pendências!$J$5:$J$304,10)>0,IF(INDEX(Pendências!$C$5:$C$304,MATCH(LARGE(Pendências!$J$5:$J$304,10),Pendências!$J$5:$J$304,0))="","",INDEX(Pendências!$C$5:$C$304,MATCH(LARGE(Pendências!$J$5:$J$304,10),Pendências!$J$5:$J$304,0))),""),"") | D19: =IFERROR(IF(LARGE(Pendências!$J$5:$J$304,10)>0,IF(INDEX(Pendências!$D$5:$D$304,MATCH(LARGE(Pendências!$J$5:$J$304,10),Pendências!$J$5:$J$304,0))="","",INDEX(Pendências!$D$5:$D$304,MATCH(LARGE(Pendências!$J$5:$J$304,10),Pendências!$J$5:$J$304,0))),""),"") | E19: =IFERROR(IF(LARGE(Pendências!$J$5:$J$304,10)>0,IF(INDEX(Pendências!$H$5:$H$304,MATCH(LARGE(Pendências!$J$5:$J$304,10),Pendências!$J$5:$J$304,0))="","",INDEX(Pendências!$H$5:$H$304,MATCH(LARGE(Pendências!$J$5:$J$304,10),Pendências!$J$5:$J$304,0))),""),"") | F19: =IFERROR(IF(LARGE(Pendências!$J$5:$J$304,10)>0,IF(INDEX(Pendências!$E$5:$E$304,MATCH(LARGE(Pendências!$J$5:$J$304,10),Pendências!$J$5:$J$304,0))="","",INDEX(Pendências!$E$5:$E$304,MATCH(LARGE(Pendências!$J$5:$J$304,10),Pendências!$J$5:$J$304,0))),""),"") | G19: =IFERROR(IF(LARGE(Pendências!$J$5:$J$304,10)>0,IF(INDEX(Pendências!$A$5:$A$304,MATCH(LARGE(Pendências!$J$5:$J$304,10),Pendências!$J$5:$J$304,0))="","",INDEX(Pendências!$A$5:$A$304,MATCH(LARGE(Pendências!$J$5:$J$304,10),Pendências!$J$5:$J$304,0))),""),"") | H19: =IFERROR(IF(LARGE(Pendências!$J$5:$J$304,10)>0,IF(INDEX(Pendências!$I$5:$I$304,MATCH(LARGE(Pendências!$J$5:$J$304,10),Pendências!$J$5:$J$304,0))="","",INDEX(Pendências!$I$5:$I$304,MATCH(LARGE(Pendências!$J$5:$J$304,10),Pendências!$J$5:$J$304,0))),""),"")
A20: 11 | B20: =IFERROR(IF(LARGE(Pendências!$J$5:$J$304,11)>0,IF(INDEX(Pendências!$B$5:$B$304,MATCH(LARGE(Pendências!$J$5:$J$304,11),Pendências!$J$5:$J$304,0))="","",INDEX(Pendências!$B$5:$B$304,MATCH(LARGE(Pendências!$J$5:$J$304,11),Pendências!$J$5:$J$304,0))),""),"") | C20: =IFERROR(IF(LARGE(Pendências!$J$5:$J$304,11)>0,IF(INDEX(Pendências!$C$5:$C$304,MATCH(LARGE(Pendências!$J$5:$J$304,11),Pendências!$J$5:$J$304,0))="","",INDEX(Pendências!$C$5:$C$304,MATCH(LARGE(Pendências!$J$5:$J$304,11),Pendências!$J$5:$J$304,0))),""),"") | D20: =IFERROR(IF(LARGE(Pendências!$J$5:$J$304,11)>0,IF(INDEX(Pendências!$D$5:$D$304,MATCH(LARGE(Pendências!$J$5:$J$304,11),Pendências!$J$5:$J$304,0))="","",INDEX(Pendências!$D$5:$D$304,MATCH(LARGE(Pendências!$J$5:$J$304,11),Pendências!$J$5:$J$304,0))),""),"") | E20: =IFERROR(IF(LARGE(Pendências!$J$5:$J$304,11)>0,IF(INDEX(Pendências!$H$5:$H$304,MATCH(LARGE(Pendências!$J$5:$J$304,11),Pendências!$J$5:$J$304,0))="","",INDEX(Pendências!$H$5:$H$304,MATCH(LARGE(Pendências!$J$5:$J$304,11),Pendências!$J$5:$J$304,0))),""),"") | F20: =IFERROR(IF(LARGE(Pendências!$J$5:$J$304,11)>0,IF(INDEX(Pendências!$E$5:$E$304,MATCH(LARGE(Pendências!$J$5:$J$304,11),Pendências!$J$5:$J$304,0))="","",INDEX(Pendências!$E$5:$E$304,MATCH(LARGE(Pendências!$J$5:$J$304,11),Pendências!$J$5:$J$304,0))),""),"") | G20: =IFERROR(IF(LARGE(Pendências!$J$5:$J$304,11)>0,IF(INDEX(Pendências!$A$5:$A$304,MATCH(LARGE(Pendências!$J$5:$J$304,11),Pendências!$J$5:$J$304,0))="","",INDEX(Pendências!$A$5:$A$304,MATCH(LARGE(Pendências!$J$5:$J$304,11),Pendências!$J$5:$J$304,0))),""),"") | H20: =IFERROR(IF(LARGE(Pendências!$J$5:$J$304,11)>0,IF(INDEX(Pendências!$I$5:$I$304,MATCH(LARGE(Pendências!$J$5:$J$304,11),Pendências!$J$5:$J$304,0))="","",INDEX(Pendências!$I$5:$I$304,MATCH(LARGE(Pendências!$J$5:$J$304,11),Pendências!$J$5:$J$304,0))),""),"")
A21: 12 | B21: =IFERROR(IF(LARGE(Pendências!$J$5:$J$304,12)>0,IF(INDEX(Pendências!$B$5:$B$304,MATCH(LARGE(Pendências!$J$5:$J$304,12),Pendências!$J$5:$J$304,0))="","",INDEX(Pendências!$B$5:$B$304,MATCH(LARGE(Pendências!$J$5:$J$304,12),Pendências!$J$5:$J$304,0))),""),"") | C21: =IFERROR(IF(LARGE(Pendências!$J$5:$J$304,12)>0,IF(INDEX(Pendências!$C$5:$C$304,MATCH(LARGE(Pendências!$J$5:$J$304,12),Pendências!$J$5:$J$304,0))="","",INDEX(Pendências!$C$5:$C$304,MATCH(LARGE(Pendências!$J$5:$J$304,12),Pendências!$J$5:$J$304,0))),""),"") | D21: =IFERROR(IF(LARGE(Pendências!$J$5:$J$304,12)>0,IF(INDEX(Pendências!$D$5:$D$304,MATCH(LARGE(Pendências!$J$5:$J$304,12),Pendências!$J$5:$J$304,0))="","",INDEX(Pendências!$D$5:$D$304,MATCH(LARGE(Pendências!$J$5:$J$304,12),Pendências!$J$5:$J$304,0))),""),"") | E21: =IFERROR(IF(LARGE(Pendências!$J$5:$J$304,12)>0,IF(INDEX(Pendências!$H$5:$H$304,MATCH(LARGE(Pendências!$J$5:$J$304,12),Pendências!$J$5:$J$304,0))="","",INDEX(Pendências!$H$5:$H$304,MATCH(LARGE(Pendências!$J$5:$J$304,12),Pendências!$J$5:$J$304,0))),""),"") | F21: =IFERROR(IF(LARGE(Pendências!$J$5:$J$304,12)>0,IF(INDEX(Pendências!$E$5:$E$304,MATCH(LARGE(Pendências!$J$5:$J$304,12),Pendências!$J$5:$J$304,0))="","",INDEX(Pendências!$E$5:$E$304,MATCH(LARGE(Pendências!$J$5:$J$304,12),Pendências!$J$5:$J$304,0))),""),"") | G21: =IFERROR(IF(LARGE(Pendências!$J$5:$J$304,12)>0,IF(INDEX(Pendências!$A$5:$A$304,MATCH(LARGE(Pendências!$J$5:$J$304,12),Pendências!$J$5:$J$304,0))="","",INDEX(Pendências!$A$5:$A$304,MATCH(LARGE(Pendências!$J$5:$J$304,12),Pendências!$J$5:$J$304,0))),""),"") | H21: =IFERROR(IF(LARGE(Pendências!$J$5:$J$304,12)>0,IF(INDEX(Pendências!$I$5:$I$304,MATCH(LARGE(Pendências!$J$5:$J$304,12),Pendências!$J$5:$J$304,0))="","",INDEX(Pendências!$I$5:$I$304,MATCH(LARGE(Pendências!$J$5:$J$304,12),Pendências!$J$5:$J$304,0))),""),"")
A22: 13 | B22: =IFERROR(IF(LARGE(Pendências!$J$5:$J$304,13)>0,IF(INDEX(Pendências!$B$5:$B$304,MATCH(LARGE(Pendências!$J$5:$J$304,13),Pendências!$J$5:$J$304,0))="","",INDEX(Pendências!$B$5:$B$304,MATCH(LARGE(Pendências!$J$5:$J$304,13),Pendências!$J$5:$J$304,0))),""),"") | C22: =IFERROR(IF(LARGE(Pendências!$J$5:$J$304,13)>0,IF(INDEX(Pendências!$C$5:$C$304,MATCH(LARGE(Pendências!$J$5:$J$304,13),Pendências!$J$5:$J$304,0))="","",INDEX(Pendências!$C$5:$C$304,MATCH(LARGE(Pendências!$J$5:$J$304,13),Pendências!$J$5:$J$304,0))),""),"") | D22: =IFERROR(IF(LARGE(Pendências!$J$5:$J$304,13)>0,IF(INDEX(Pendências!$D$5:$D$304,MATCH(LARGE(Pendências!$J$5:$J$304,13),Pendências!$J$5:$J$304,0))="","",INDEX(Pendências!$D$5:$D$304,MATCH(LARGE(Pendências!$J$5:$J$304,13),Pendências!$J$5:$J$304,0))),""),"") | E22: =IFERROR(IF(LARGE(Pendências!$J$5:$J$304,13)>0,IF(INDEX(Pendências!$H$5:$H$304,MATCH(LARGE(Pendências!$J$5:$J$304,13),Pendências!$J$5:$J$304,0))="","",INDEX(Pendências!$H$5:$H$304,MATCH(LARGE(Pendências!$J$5:$J$304,13),Pendências!$J$5:$J$304,0))),""),"") | F22: =IFERROR(IF(LARGE(Pendências!$J$5:$J$304,13)>0,IF(INDEX(Pendências!$E$5:$E$304,MATCH(LARGE(Pendências!$J$5:$J$304,13),Pendências!$J$5:$J$304,0))="","",INDEX(Pendências!$E$5:$E$304,MATCH(LARGE(Pendências!$J$5:$J$304,13),Pendências!$J$5:$J$304,0))),""),"") | G22: =IFERROR(IF(LARGE(Pendências!$J$5:$J$304,13)>0,IF(INDEX(Pendências!$A$5:$A$304,MATCH(LARGE(Pendências!$J$5:$J$304,13),Pendências!$J$5:$J$304,0))="","",INDEX(Pendências!$A$5:$A$304,MATCH(LARGE(Pendências!$J$5:$J$304,13),Pendências!$J$5:$J$304,0))),""),"") | H22: =IFERROR(IF(LARGE(Pendências!$J$5:$J$304,13)>0,IF(INDEX(Pendências!$I$5:$I$304,MATCH(LARGE(Pendências!$J$5:$J$304,13),Pendências!$J$5:$J$304,0))="","",INDEX(Pendências!$I$5:$I$304,MATCH(LARGE(Pendências!$J$5:$J$304,13),Pendências!$J$5:$J$304,0))),""),"")
A23: 14 | B23: =IFERROR(IF(LARGE(Pendências!$J$5:$J$304,14)>0,IF(INDEX(Pendências!$B$5:$B$304,MATCH(LARGE(Pendências!$J$5:$J$304,14),Pendências!$J$5:$J$304,0))="","",INDEX(Pendências!$B$5:$B$304,MATCH(LARGE(Pendências!$J$5:$J$304,14),Pendências!$J$5:$J$304,0))),""),"") | C23: =IFERROR(IF(LARGE(Pendências!$J$5:$J$304,14)>0,IF(INDEX(Pendências!$C$5:$C$304,MATCH(LARGE(Pendências!$J$5:$J$304,14),Pendências!$J$5:$J$304,0))="","",INDEX(Pendências!$C$5:$C$304,MATCH(LARGE(Pendências!$J$5:$J$304,14),Pendências!$J$5:$J$304,0))),""),"") | D23: =IFERROR(IF(LARGE(Pendências!$J$5:$J$304,14)>0,IF(INDEX(Pendências!$D$5:$D$304,MATCH(LARGE(Pendências!$J$5:$J$304,14),Pendências!$J$5:$J$304,0))="","",INDEX(Pendências!$D$5:$D$304,MATCH(LARGE(Pendências!$J$5:$J$304,14),Pendências!$J$5:$J$304,0))),""),"") | E23: =IFERROR(IF(LARGE(Pendências!$J$5:$J$304,14)>0,IF(INDEX(Pendências!$H$5:$H$304,MATCH(LARGE(Pendências!$J$5:$J$304,14),Pendências!$J$5:$J$304,0))="","",INDEX(Pendências!$H$5:$H$304,MATCH(LARGE(Pendências!$J$5:$J$304,14),Pendências!$J$5:$J$304,0))),""),"") | F23: =IFERROR(IF(LARGE(Pendências!$J$5:$J$304,14)>0,IF(INDEX(Pendências!$E$5:$E$304,MATCH(LARGE(Pendências!$J$5:$J$304,14),Pendências!$J$5:$J$304,0))="","",INDEX(Pendências!$E$5:$E$304,MATCH(LARGE(Pendências!$J$5:$J$304,14),Pendências!$J$5:$J$304,0))),""),"") | G23: =IFERROR(IF(LARGE(Pendências!$J$5:$J$304,14)>0,IF(INDEX(Pendências!$A$5:$A$304,MATCH(LARGE(Pendências!$J$5:$J$304,14),Pendências!$J$5:$J$304,0))="","",INDEX(Pendências!$A$5:$A$304,MATCH(LARGE(Pendências!$J$5:$J$304,14),Pendências!$J$5:$J$304,0))),""),"") | H23: =IFERROR(IF(LARGE(Pendências!$J$5:$J$304,14)>0,IF(INDEX(Pendências!$I$5:$I$304,MATCH(LARGE(Pendências!$J$5:$J$304,14),Pendências!$J$5:$J$304,0))="","",INDEX(Pendências!$I$5:$I$304,MATCH(LARGE(Pendências!$J$5:$J$304,14),Pendências!$J$5:$J$304,0))),""),"")
A24: 15 | B24: =IFERROR(IF(LARGE(Pendências!$J$5:$J$304,15)>0,IF(INDEX(Pendências!$B$5:$B$304,MATCH(LARGE(Pendências!$J$5:$J$304,15),Pendências!$J$5:$J$304,0))="","",INDEX(Pendências!$B$5:$B$304,MATCH(LARGE(Pendências!$J$5:$J$304,15),Pendências!$J$5:$J$304,0))),""),"") | C24: =IFERROR(IF(LARGE(Pendências!$J$5:$J$304,15)>0,IF(INDEX(Pendências!$C$5:$C$304,MATCH(LARGE(Pendências!$J$5:$J$304,15),Pendências!$J$5:$J$304,0))="","",INDEX(Pendências!$C$5:$C$304,MATCH(LARGE(Pendências!$J$5:$J$304,15),Pendências!$J$5:$J$304,0))),""),"") | D24: =IFERROR(IF(LARGE(Pendências!$J$5:$J$304,15)>0,IF(INDEX(Pendências!$D$5:$D$304,MATCH(LARGE(Pendências!$J$5:$J$304,15),Pendências!$J$5:$J$304,0))="","",INDEX(Pendências!$D$5:$D$304,MATCH(LARGE(Pendências!$J$5:$J$304,15),Pendências!$J$5:$J$304,0))),""),"") | E24: =IFERROR(IF(LARGE(Pendências!$J$5:$J$304,15)>0,IF(INDEX(Pendências!$H$5:$H$304,MATCH(LARGE(Pendências!$J$5:$J$304,15),Pendências!$J$5:$J$304,0))="","",INDEX(Pendências!$H$5:$H$304,MATCH(LARGE(Pendências!$J$5:$J$304,15),Pendências!$J$5:$J$304,0))),""),"") | F24: =IFERROR(IF(LARGE(Pendências!$J$5:$J$304,15)>0,IF(INDEX(Pendências!$E$5:$E$304,MATCH(LARGE(Pendências!$J$5:$J$304,15),Pendências!$J$5:$J$304,0))="","",INDEX(Pendências!$E$5:$E$304,MATCH(LARGE(Pendências!$J$5:$J$304,15),Pendências!$J$5:$J$304,0))),""),"") | G24: =IFERROR(IF(LARGE(Pendências!$J$5:$J$304,15)>0,IF(INDEX(Pendências!$A$5:$A$304,MATCH(LARGE(Pendências!$J$5:$J$304,15),Pendências!$J$5:$J$304,0))="","",INDEX(Pendências!$A$5:$A$304,MATCH(LARGE(Pendências!$J$5:$J$304,15),Pendências!$J$5:$J$304,0))),""),"") | H24: =IFERROR(IF(LARGE(Pendências!$J$5:$J$304,15)>0,IF(INDEX(Pendências!$I$5:$I$304,MATCH(LARGE(Pendências!$J$5:$J$304,15),Pendências!$J$5:$J$304,0))="","",INDEX(Pendências!$I$5:$I$304,MATCH(LARGE(Pendências!$J$5:$J$304,15),Pendências!$J$5:$J$304,0))),""),"")
A26: Por pessoa
A27: Pessoa | B27: Abertas | C27: Atrasadas | D27: Esta semana | E27: Feitas | F27: Próximo prazo
A28: =IF(Config!$A$9="","",Config!$A$9) -> Ana | B28: =IF(Config!$A$9="","",COUNTIFS(Pendências!$C$5:$C$304,Config!$A$9,Pendências!$B$5:$B$304,"<>",Pendências!$F$5:$F$304,"<>Feito")) -> 3 | C28: =IF(Config!$A$9="","",COUNTIFS(Pendências!$C$5:$C$304,Config!$A$9,Pendências!$H$5:$H$304,"Atrasada")) -> 2 | D28: =IF(Config!$A$9="","",COUNTIFS(Pendências!$C$5:$C$304,Config!$A$9,Pendências!$H$5:$H$304,"Esta semana")+COUNTIFS(Pendências!$C$5:$C$304,Config!$A$9,Pendências!$H$5:$H$304,"Hoje")) -> 0 | E28: =IF(Config!$A$9="","",COUNTIFS(Pendências!$C$5:$C$304,Config!$A$9,Pendências!$F$5:$F$304,"Feito")) -> 3 | F28: =IF(Config!$A$9="","",IFERROR(IF(OR(SUMPRODUCT(MIN((Pendências!$C$5:$C$304=Config!$A$9)*(Pendências!$F$5:$F$304<>"Feito")*(Pendências!$B$5:$B$304<>"")*(Pendências!$D$5:$D$304<>"")*Pendências!$D$5:$D$304+(1-(Pendências!$C$5:$C$304=Config!$A$9)*(Pendências!$F$5:$F$304<>"Feito")*(Pendências!$B$5:$B$304<>"")*(Pendências!$D$5:$D$304<>""))*1E+10))=0,SUMPRODUCT(MIN((Pendências!$C$5:$C$304=Config!$A$9)*(Pendências!$F$5:$F$304<>"Feito")*(Pendências!$B$5:$B$304<>"")*(Pendências!$D$5:$D$304<>"")*Pendências!$D$5:$D$304+(1-(Pendências!$C$5:$C$304=Config!$A$9)*(Pendências!$F$5:$F$304<>"Feito")*(Pendências!$B$5:$B$304<>"")*(Pendências!$D$5:$D$304<>""))*1E+10))>=1E+10),"",SUMPRODUCT(MIN((Pendências!$C$5:$C$304=Config!$A$9)*(Pendências!$F$5:$F$304<>"Feito")*(Pendências!$B$5:$B$304<>"")*(Pendências!$D$5:$D$304<>"")*Pendências!$D$5:$D$304+(1-(Pendências!$C$5:$C$304=Config!$A$9)*(Pendências!$F$5:$F$304<>"Feito")*(Pendências!$B$5:$B$304<>"")*(Pendências!$D$5:$D$304<>""))*1E+10))),"")) -> 46276
A29: =IF(Config!$A$10="","",Config!$A$10) -> Bruno | B29: =IF(Config!$A$10="","",COUNTIFS(Pendências!$C$5:$C$304,Config!$A$10,Pendências!$B$5:$B$304,"<>",Pendências!$F$5:$F$304,"<>Feito")) -> 1 | C29: =IF(Config!$A$10="","",COUNTIFS(Pendências!$C$5:$C$304,Config!$A$10,Pendências!$H$5:$H$304,"Atrasada")) -> 0 | D29: =IF(Config!$A$10="","",COUNTIFS(Pendências!$C$5:$C$304,Config!$A$10,Pendências!$H$5:$H$304,"Esta semana")+COUNTIFS(Pendências!$C$5:$C$304,Config!$A$10,Pendências!$H$5:$H$304,"Hoje")) -> 1 | E29: =IF(Config!$A$10="","",COUNTIFS(Pendências!$C$5:$C$304,Config!$A$10,Pendências!$F$5:$F$304,"Feito")) -> 1 | F29: =IF(Config!$A$10="","",IFERROR(IF(OR(SUMPRODUCT(MIN((Pendências!$C$5:$C$304=Config!$A$10)*(Pendências!$F$5:$F$304<>"Feito")*(Pendências!$B$5:$B$304<>"")*(Pendências!$D$5:$D$304<>"")*Pendências!$D$5:$D$304+(1-(Pendências!$C$5:$C$304=Config!$A$10)*(Pendências!$F$5:$F$304<>"Feito")*(Pendências!$B$5:$B$304<>"")*(Pendências!$D$5:$D$304<>""))*1E+10))=0,SUMPRODUCT(MIN((Pendências!$C$5:$C$304=Config!$A$10)*(Pendências!$F$5:$F$304<>"Feito")*(Pendências!$B$5:$B$304<>"")*(Pendências!$D$5:$D$304<>"")*Pendências!$D$5:$D$304+(1-(Pendências!$C$5:$C$304=Config!$A$10)*(Pendências!$F$5:$F$304<>"Feito")*(Pendências!$B$5:$B$304<>"")*(Pendências!$D$5:$D$304<>""))*1E+10))>=1E+10),"",SUMPRODUCT(MIN((Pendências!$C$5:$C$304=Config!$A$10)*(Pendências!$F$5:$F$304<>"Feito")*(Pendências!$B$5:$B$304<>"")*(Pendências!$D$5:$D$304<>"")*Pendências!$D$5:$D$304+(1-(Pendências!$C$5:$C$304=Config!$A$10)*(Pendências!$F$5:$F$304<>"Feito")*(Pendências!$B$5:$B$304<>"")*(Pendências!$D$5:$D$304<>""))*1E+10))),"")) -> 46281
A30: =IF(Config!$A$11="","",Config!$A$11) -> Carla | B30: =IF(Config!$A$11="","",COUNTIFS(Pendências!$C$5:$C$304,Config!$A$11,Pendências!$B$5:$B$304,"<>",Pendências!$F$5:$F$304,"<>Feito")) -> 2 | C30: =IF(Config!$A$11="","",COUNTIFS(Pendências!$C$5:$C$304,Config!$A$11,Pendências!$H$5:$H$304,"Atrasada")) -> 1 | D30: =IF(Config!$A$11="","",COUNTIFS(Pendências!$C$5:$C$304,Config!$A$11,Pendências!$H$5:$H$304,"Esta semana")+COUNTIFS(Pendências!$C$5:$C$304,Config!$A$11,Pendências!$H$5:$H$304,"Hoje")) -> 1 | E30: =IF(Config!$A$11="","",COUNTIFS(Pendências!$C$5:$C$304,Config!$A$11,Pendências!$F$5:$F$304,"Feito")) -> 0 | F30: =IF(Config!$A$11="","",IFERROR(IF(OR(SUMPRODUCT(MIN((Pendências!$C$5:$C$304=Config!$A$11)*(Pendências!$F$5:$F$304<>"Feito")*(Pendências!$B$5:$B$304<>"")*(Pendências!$D$5:$D$304<>"")*Pendências!$D$5:$D$304+(1-(Pendências!$C$5:$C$304=Config!$A$11)*(Pendências!$F$5:$F$304<>"Feito")*(Pendências!$B$5:$B$304<>"")*(Pendências!$D$5:$D$304<>""))*1E+10))=0,SUMPRODUCT(MIN((Pendências!$C$5:$C$304=Config!$A$11)*(Pendências!$F$5:$F$304<>"Feito")*(Pendências!$B$5:$B$304<>"")*(Pendências!$D$5:$D$304<>"")*Pendências!$D$5:$D$304+(1-(Pendências!$C$5:$C$304=Config!$A$11)*(Pendências!$F$5:$F$304<>"Feito")*(Pendências!$B$5:$B$304<>"")*(Pendências!$D$5:$D$304<>""))*1E+10))>=1E+10),"",SUMPRODUCT(MIN((Pendências!$C$5:$C$304=Config!$A$11)*(Pendências!$F$5:$F$304<>"Feito")*(Pendências!$B$5:$B$304<>"")*(Pendências!$D$5:$D$304<>"")*Pendências!$D$5:$D$304+(1-(Pendências!$C$5:$C$304=Config!$A$11)*(Pendências!$F$5:$F$304<>"Feito")*(Pendências!$B$5:$B$304<>"")*(Pendências!$D$5:$D$304<>""))*1E+10))),"")) -> 46277
A31: =IF(Config!$A$12="","",Config!$A$12) -> Diego | B31: =IF(Config!$A$12="","",COUNTIFS(Pendências!$C$5:$C$304,Config!$A$12,Pendências!$B$5:$B$304,"<>",Pendências!$F$5:$F$304,"<>Feito")) -> 1 | C31: =IF(Config!$A$12="","",COUNTIFS(Pendências!$C$5:$C$304,Config!$A$12,Pendências!$H$5:$H$304,"Atrasada")) -> 0 | D31: =IF(Config!$A$12="","",COUNTIFS(Pendências!$C$5:$C$304,Config!$A$12,Pendências!$H$5:$H$304,"Esta semana")+COUNTIFS(Pendências!$C$5:$C$304,Config!$A$12,Pendências!$H$5:$H$304,"Hoje")) -> 1 | E31: =IF(Config!$A$12="","",COUNTIFS(Pendências!$C$5:$C$304,Config!$A$12,Pendências!$F$5:$F$304,"Feito")) -> 0 | F31: =IF(Config!$A$12="","",IFERROR(IF(OR(SUMPRODUCT(MIN((Pendências!$C$5:$C$304=Config!$A$12)*(Pendências!$F$5:$F$304<>"Feito")*(Pendências!$B$5:$B$304<>"")*(Pendências!$D$5:$D$304<>"")*Pendências!$D$5:$D$304+(1-(Pendências!$C$5:$C$304=Config!$A$12)*(Pendências!$F$5:$F$304<>"Feito")*(Pendências!$B$5:$B$304<>"")*(Pendências!$D$5:$D$304<>""))*1E+10))=0,SUMPRODUCT(MIN((Pendências!$C$5:$C$304=Config!$A$12)*(Pendências!$F$5:$F$304<>"Feito")*(Pendências!$B$5:$B$304<>"")*(Pendências!$D$5:$D$304<>"")*Pendências!$D$5:$D$304+(1-(Pendências!$C$5:$C$304=Config!$A$12)*(Pendências!$F$5:$F$304<>"Feito")*(Pendências!$B$5:$B$304<>"")*(Pendências!$D$5:$D$304<>""))*1E+10))>=1E+10),"",SUMPRODUCT(MIN((Pendências!$C$5:$C$304=Config!$A$12)*(Pendências!$F$5:$F$304<>"Feito")*(Pendências!$B$5:$B$304<>"")*(Pendências!$D$5:$D$304<>"")*Pendências!$D$5:$D$304+(1-(Pendências!$C$5:$C$304=Config!$A$12)*(Pendências!$F$5:$F$304<>"Feito")*(Pendências!$B$5:$B$304<>"")*(Pendências!$D$5:$D$304<>""))*1E+10))),"")) -> 46283
A32: =IF(Config!$A$13="","",Config!$A$13) -> Marina (cliente) | B32: =IF(Config!$A$13="","",COUNTIFS(Pendências!$C$5:$C$304,Config!$A$13,Pendências!$B$5:$B$304,"<>",Pendências!$F$5:$F$304,"<>Feito")) -> 0 | C32: =IF(Config!$A$13="","",COUNTIFS(Pendências!$C$5:$C$304,Config!$A$13,Pendências!$H$5:$H$304,"Atrasada")) -> 0 | D32: =IF(Config!$A$13="","",COUNTIFS(Pendências!$C$5:$C$304,Config!$A$13,Pendências!$H$5:$H$304,"Esta semana")+COUNTIFS(Pendências!$C$5:$C$304,Config!$A$13,Pendências!$H$5:$H$304,"Hoje")) -> 0 | E32: =IF(Config!$A$13="","",COUNTIFS(Pendências!$C$5:$C$304,Config!$A$13,Pendências!$F$5:$F$304,"Feito")) -> 1 | F32: =IF(Config!$A$13="","",IFERROR(IF(OR(SUMPRODUCT(MIN((Pendências!$C$5:$C$304=Config!$A$13)*(Pendências!$F$5:$F$304<>"Feito")*(Pendências!$B$5:$B$304<>"")*(Pendências!$D$5:$D$304<>"")*Pendências!$D$5:$D$304+(1-(Pendências!$C$5:$C$304=Config!$A$13)*(Pendências!$F$5:$F$304<>"Feito")*(Pendências!$B$5:$B$304<>"")*(Pendências!$D$5:$D$304<>""))*1E+10))=0,SUMPRODUCT(MIN((Pendências!$C$5:$C$304=Config!$A$13)*(Pendências!$F$5:$F$304<>"Feito")*(Pendências!$B$5:$B$304<>"")*(Pendências!$D$5:$D$304<>"")*Pendências!$D$5:$D$304+(1-(Pendências!$C$5:$C$304=Config!$A$13)*(Pendências!$F$5:$F$304<>"Feito")*(Pendências!$B$5:$B$304<>"")*(Pendências!$D$5:$D$304<>""))*1E+10))>=1E+10),"",SUMPRODUCT(MIN((Pendências!$C$5:$C$304=Config!$A$13)*(Pendências!$F$5:$F$304<>"Feito")*(Pendências!$B$5:$B$304<>"")*(Pendências!$D$5:$D$304<>"")*Pendências!$D$5:$D$304+(1-(Pendências!$C$5:$C$304=Config!$A$13)*(Pendências!$F$5:$F$304<>"Feito")*(Pendências!$B$5:$B$304<>"")*(Pendências!$D$5:$D$304<>""))*1E+10))),""))
A33: =IF(Config!$A$14="","",Config!$A$14) | B33: =IF(Config!$A$14="","",COUNTIFS(Pendências!$C$5:$C$304,Config!$A$14,Pendências!$B$5:$B$304,"<>",Pendências!$F$5:$F$304,"<>Feito")) | C33: =IF(Config!$A$14="","",COUNTIFS(Pendências!$C$5:$C$304,Config!$A$14,Pendências!$H$5:$H$304,"Atrasada")) | D33: =IF(Config!$A$14="","",COUNTIFS(Pendências!$C$5:$C$304,Config!$A$14,Pendências!$H$5:$H$304,"Esta semana")+COUNTIFS(Pendências!$C$5:$C$304,Config!$A$14,Pendências!$H$5:$H$304,"Hoje")) | E33: =IF(Config!$A$14="","",COUNTIFS(Pendências!$C$5:$C$304,Config!$A$14,Pendências!$F$5:$F$304,"Feito")) | F33: =IF(Config!$A$14="","",IFERROR(IF(OR(SUMPRODUCT(MIN((Pendências!$C$5:$C$304=Config!$A$14)*(Pendências!$F$5:$F$304<>"Feito")*(Pendências!$B$5:$B$304<>"")*(Pendências!$D$5:$D$304<>"")*Pendências!$D$5:$D$304+(1-(Pendências!$C$5:$C$304=Config!$A$14)*(Pendências!$F$5:$F$304<>"Feito")*(Pendências!$B$5:$B$304<>"")*(Pendências!$D$5:$D$304<>""))*1E+10))=0,SUMPRODUCT(MIN((Pendências!$C$5:$C$304=Config!$A$14)*(Pendências!$F$5:$F$304<>"Feito")*(Pendências!$B$5:$B$304<>"")*(Pendências!$D$5:$D$304<>"")*Pendências!$D$5:$D$304+(1-(Pendências!$C$5:$C$304=Config!$A$14)*(Pendências!$F$5:$F$304<>"Feito")*(Pendências!$B$5:$B$304<>"")*(Pendências!$D$5:$D$304<>""))*1E+10))>=1E+10),"",SUMPRODUCT(MIN((Pendências!$C$5:$C$304=Config!$A$14)*(Pendências!$F$5:$F$304<>"Feito")*(Pendências!$B$5:$B$304<>"")*(Pendências!$D$5:$D$304<>"")*Pendências!$D$5:$D$304+(1-(Pendências!$C$5:$C$304=Config!$A$14)*(Pendências!$F$5:$F$304<>"Feito")*(Pendências!$B$5:$B$304<>"")*(Pendências!$D$5:$D$304<>""))*1E+10))),""))
A34: =IF(Config!$A$15="","",Config!$A$15) | B34: =IF(Config!$A$15="","",COUNTIFS(Pendências!$C$5:$C$304,Config!$A$15,Pendências!$B$5:$B$304,"<>",Pendências!$F$5:$F$304,"<>Feito")) | C34: =IF(Config!$A$15="","",COUNTIFS(Pendências!$C$5:$C$304,Config!$A$15,Pendências!$H$5:$H$304,"Atrasada")) | D34: =IF(Config!$A$15="","",COUNTIFS(Pendências!$C$5:$C$304,Config!$A$15,Pendências!$H$5:$H$304,"Esta semana")+COUNTIFS(Pendências!$C$5:$C$304,Config!$A$15,Pendências!$H$5:$H$304,"Hoje")) | E34: =IF(Config!$A$15="","",COUNTIFS(Pendências!$C$5:$C$304,Config!$A$15,Pendências!$F$5:$F$304,"Feito")) | F34: =IF(Config!$A$15="","",IFERROR(IF(OR(SUMPRODUCT(MIN((Pendências!$C$5:$C$304=Config!$A$15)*(Pendências!$F$5:$F$304<>"Feito")*(Pendências!$B$5:$B$304<>"")*(Pendências!$D$5:$D$304<>"")*Pendências!$D$5:$D$304+(1-(Pendências!$C$5:$C$304=Config!$A$15)*(Pendências!$F$5:$F$304<>"Feito")*(Pendências!$B$5:$B$304<>"")*(Pendências!$D$5:$D$304<>""))*1E+10))=0,SUMPRODUCT(MIN((Pendências!$C$5:$C$304=Config!$A$15)*(Pendências!$F$5:$F$304<>"Feito")*(Pendências!$B$5:$B$304<>"")*(Pendências!$D$5:$D$304<>"")*Pendências!$D$5:$D$304+(1-(Pendências!$C$5:$C$304=Config!$A$15)*(Pendências!$F$5:$F$304<>"Feito")*(Pendências!$B$5:$B$304<>"")*(Pendências!$D$5:$D$304<>""))*1E+10))>=1E+10),"",SUMPRODUCT(MIN((Pendências!$C$5:$C$304=Config!$A$15)*(Pendências!$F$5:$F$304<>"Feito")*(Pendências!$B$5:$B$304<>"")*(Pendências!$D$5:$D$304<>"")*Pendências!$D$5:$D$304+(1-(Pendências!$C$5:$C$304=Config!$A$15)*(Pendências!$F$5:$F$304<>"Feito")*(Pendências!$B$5:$B$304<>"")*(Pendências!$D$5:$D$304<>""))*1E+10))),""))
A35: =IF(Config!$A$16="","",Config!$A$16) | B35: =IF(Config!$A$16="","",COUNTIFS(Pendências!$C$5:$C$304,Config!$A$16,Pendências!$B$5:$B$304,"<>",Pendências!$F$5:$F$304,"<>Feito")) | C35: =IF(Config!$A$16="","",COUNTIFS(Pendências!$C$5:$C$304,Config!$A$16,Pendências!$H$5:$H$304,"Atrasada")) | D35: =IF(Config!$A$16="","",COUNTIFS(Pendências!$C$5:$C$304,Config!$A$16,Pendências!$H$5:$H$304,"Esta semana")+COUNTIFS(Pendências!$C$5:$C$304,Config!$A$16,Pendências!$H$5:$H$304,"Hoje")) | E35: =IF(Config!$A$16="","",COUNTIFS(Pendências!$C$5:$C$304,Config!$A$16,Pendências!$F$5:$F$304,"Feito")) | F35: =IF(Config!$A$16="","",IFERROR(IF(OR(SUMPRODUCT(MIN((Pendências!$C$5:$C$304=Config!$A$16)*(Pendências!$F$5:$F$304<>"Feito")*(Pendências!$B$5:$B$304<>"")*(Pendências!$D$5:$D$304<>"")*Pendências!$D$5:$D$304+(1-(Pendências!$C$5:$C$304=Config!$A$16)*(Pendências!$F$5:$F$304<>"Feito")*(Pendências!$B$5:$B$304<>"")*(Pendências!$D$5:$D$304<>""))*1E+10))=0,SUMPRODUCT(MIN((Pendências!$C$5:$C$304=Config!$A$16)*(Pendências!$F$5:$F$304<>"Feito")*(Pendências!$B$5:$B$304<>"")*(Pendências!$D$5:$D$304<>"")*Pendências!$D$5:$D$304+(1-(Pendências!$C$5:$C$304=Config!$A$16)*(Pendências!$F$5:$F$304<>"Feito")*(Pendências!$B$5:$B$304<>"")*(Pendências!$D$5:$D$304<>""))*1E+10))>=1E+10),"",SUMPRODUCT(MIN((Pendências!$C$5:$C$304=Config!$A$16)*(Pendências!$F$5:$F$304<>"Feito")*(Pendências!$B$5:$B$304<>"")*(Pendências!$D$5:$D$304<>"")*Pendências!$D$5:$D$304+(1-(Pendências!$C$5:$C$304=Config!$A$16)*(Pendências!$F$5:$F$304<>"Feito")*(Pendências!$B$5:$B$304<>"")*(Pendências!$D$5:$D$304<>""))*1E+10))),""))
A36: =IF(Config!$A$17="","",Config!$A$17) | B36: =IF(Config!$A$17="","",COUNTIFS(Pendências!$C$5:$C$304,Config!$A$17,Pendências!$B$5:$B$304,"<>",Pendências!$F$5:$F$304,"<>Feito")) | C36: =IF(Config!$A$17="","",COUNTIFS(Pendências!$C$5:$C$304,Config!$A$17,Pendências!$H$5:$H$304,"Atrasada")) | D36: =IF(Config!$A$17="","",COUNTIFS(Pendências!$C$5:$C$304,Config!$A$17,Pendências!$H$5:$H$304,"Esta semana")+COUNTIFS(Pendências!$C$5:$C$304,Config!$A$17,Pendências!$H$5:$H$304,"Hoje")) | E36: =IF(Config!$A$17="","",COUNTIFS(Pendências!$C$5:$C$304,Config!$A$17,Pendências!$F$5:$F$304,"Feito")) | F36: =IF(Config!$A$17="","",IFERROR(IF(OR(SUMPRODUCT(MIN((Pendências!$C$5:$C$304=Config!$A$17)*(Pendências!$F$5:$F$304<>"Feito")*(Pendências!$B$5:$B$304<>"")*(Pendências!$D$5:$D$304<>"")*Pendências!$D$5:$D$304+(1-(Pendências!$C$5:$C$304=Config!$A$17)*(Pendências!$F$5:$F$304<>"Feito")*(Pendências!$B$5:$B$304<>"")*(Pendências!$D$5:$D$304<>""))*1E+10))=0,SUMPRODUCT(MIN((Pendências!$C$5:$C$304=Config!$A$17)*(Pendências!$F$5:$F$304<>"Feito")*(Pendências!$B$5:$B$304<>"")*(Pendências!$D$5:$D$304<>"")*Pendências!$D$5:$D$304+(1-(Pendências!$C$5:$C$304=Config!$A$17)*(Pendências!$F$5:$F$304<>"Feito")*(Pendências!$B$5:$B$304<>"")*(Pendências!$D$5:$D$304<>""))*1E+10))>=1E+10),"",SUMPRODUCT(MIN((Pendências!$C$5:$C$304=Config!$A$17)*(Pendências!$F$5:$F$304<>"Feito")*(Pendências!$B$5:$B$304<>"")*(Pendências!$D$5:$D$304<>"")*Pendências!$D$5:$D$304+(1-(Pendências!$C$5:$C$304=Config!$A$17)*(Pendências!$F$5:$F$304<>"Feito")*(Pendências!$B$5:$B$304<>"")*(Pendências!$D$5:$D$304<>""))*1E+10))),""))
A37: =IF(Config!$A$18="","",Config!$A$18) | B37: =IF(Config!$A$18="","",COUNTIFS(Pendências!$C$5:$C$304,Config!$A$18,Pendências!$B$5:$B$304,"<>",Pendências!$F$5:$F$304,"<>Feito")) | C37: =IF(Config!$A$18="","",COUNTIFS(Pendências!$C$5:$C$304,Config!$A$18,Pendências!$H$5:$H$304,"Atrasada")) | D37: =IF(Config!$A$18="","",COUNTIFS(Pendências!$C$5:$C$304,Config!$A$18,Pendências!$H$5:$H$304,"Esta semana")+COUNTIFS(Pendências!$C$5:$C$304,Config!$A$18,Pendências!$H$5:$H$304,"Hoje")) | E37: =IF(Config!$A$18="","",COUNTIFS(Pendências!$C$5:$C$304,Config!$A$18,Pendências!$F$5:$F$304,"Feito")) | F37: =IF(Config!$A$18="","",IFERROR(IF(OR(SUMPRODUCT(MIN((Pendências!$C$5:$C$304=Config!$A$18)*(Pendências!$F$5:$F$304<>"Feito")*(Pendências!$B$5:$B$304<>"")*(Pendências!$D$5:$D$304<>"")*Pendências!$D$5:$D$304+(1-(Pendências!$C$5:$C$304=Config!$A$18)*(Pendências!$F$5:$F$304<>"Feito")*(Pendências!$B$5:$B$304<>"")*(Pendências!$D$5:$D$304<>""))*1E+10))=0,SUMPRODUCT(MIN((Pendências!$C$5:$C$304=Config!$A$18)*(Pendências!$F$5:$F$304<>"Feito")*(Pendências!$B$5:$B$304<>"")*(Pendências!$D$5:$D$304<>"")*Pendências!$D$5:$D$304+(1-(Pendências!$C$5:$C$304=Config!$A$18)*(Pendências!$F$5:$F$304<>"Feito")*(Pendências!$B$5:$B$304<>"")*(Pendências!$D$5:$D$304<>""))*1E+10))>=1E+10),"",SUMPRODUCT(MIN((Pendências!$C$5:$C$304=Config!$A$18)*(Pendências!$F$5:$F$304<>"Feito")*(Pendências!$B$5:$B$304<>"")*(Pendências!$D$5:$D$304<>"")*Pendências!$D$5:$D$304+(1-(Pendências!$C$5:$C$304=Config!$A$18)*(Pendências!$F$5:$F$304<>"Feito")*(Pendências!$B$5:$B$304<>"")*(Pendências!$D$5:$D$304<>""))*1E+10))),""))
A38: =IF(Config!$A$19="","",Config!$A$19) | B38: =IF(Config!$A$19="","",COUNTIFS(Pendências!$C$5:$C$304,Config!$A$19,Pendências!$B$5:$B$304,"<>",Pendências!$F$5:$F$304,"<>Feito")) | C38: =IF(Config!$A$19="","",COUNTIFS(Pendências!$C$5:$C$304,Config!$A$19,Pendências!$H$5:$H$304,"Atrasada")) | D38: =IF(Config!$A$19="","",COUNTIFS(Pendências!$C$5:$C$304,Config!$A$19,Pendências!$H$5:$H$304,"Esta semana")+COUNTIFS(Pendências!$C$5:$C$304,Config!$A$19,Pendências!$H$5:$H$304,"Hoje")) | E38: =IF(Config!$A$19="","",COUNTIFS(Pendências!$C$5:$C$304,Config!$A$19,Pendências!$F$5:$F$304,"Feito")) | F38: =IF(Config!$A$19="","",IFERROR(IF(OR(SUMPRODUCT(MIN((Pendências!$C$5:$C$304=Config!$A$19)*(Pendências!$F$5:$F$304<>"Feito")*(Pendências!$B$5:$B$304<>"")*(Pendências!$D$5:$D$304<>"")*Pendências!$D$5:$D$304+(1-(Pendências!$C$5:$C$304=Config!$A$19)*(Pendências!$F$5:$F$304<>"Feito")*(Pendências!$B$5:$B$304<>"")*(Pendências!$D$5:$D$304<>""))*1E+10))=0,SUMPRODUCT(MIN((Pendências!$C$5:$C$304=Config!$A$19)*(Pendências!$F$5:$F$304<>"Feito")*(Pendências!$B$5:$B$304<>"")*(Pendências!$D$5:$D$304<>"")*Pendências!$D$5:$D$304+(1-(Pendências!$C$5:$C$304=Config!$A$19)*(Pendências!$F$5:$F$304<>"Feito")*(Pendências!$B$5:$B$304<>"")*(Pendências!$D$5:$D$304<>""))*1E+10))>=1E+10),"",SUMPRODUCT(MIN((Pendências!$C$5:$C$304=Config!$A$19)*(Pendências!$F$5:$F$304<>"Feito")*(Pendências!$B$5:$B$304<>"")*(Pendências!$D$5:$D$304<>"")*Pendências!$D$5:$D$304+(1-(Pendências!$C$5:$C$304=Config!$A$19)*(Pendências!$F$5:$F$304<>"Feito")*(Pendências!$B$5:$B$304<>"")*(Pendências!$D$5:$D$304<>""))*1E+10))),""))
A39: =IF(Config!$A$20="","",Config!$A$20) | B39: =IF(Config!$A$20="","",COUNTIFS(Pendências!$C$5:$C$304,Config!$A$20,Pendências!$B$5:$B$304,"<>",Pendências!$F$5:$F$304,"<>Feito")) | C39: =IF(Config!$A$20="","",COUNTIFS(Pendências!$C$5:$C$304,Config!$A$20,Pendências!$H$5:$H$304,"Atrasada")) | D39: =IF(Config!$A$20="","",COUNTIFS(Pendências!$C$5:$C$304,Config!$A$20,Pendências!$H$5:$H$304,"Esta semana")+COUNTIFS(Pendências!$C$5:$C$304,Config!$A$20,Pendências!$H$5:$H$304,"Hoje")) | E39: =IF(Config!$A$20="","",COUNTIFS(Pendências!$C$5:$C$304,Config!$A$20,Pendências!$F$5:$F$304,"Feito")) | F39: =IF(Config!$A$20="","",IFERROR(IF(OR(SUMPRODUCT(MIN((Pendências!$C$5:$C$304=Config!$A$20)*(Pendências!$F$5:$F$304<>"Feito")*(Pendências!$B$5:$B$304<>"")*(Pendências!$D$5:$D$304<>"")*Pendências!$D$5:$D$304+(1-(Pendências!$C$5:$C$304=Config!$A$20)*(Pendências!$F$5:$F$304<>"Feito")*(Pendências!$B$5:$B$304<>"")*(Pendências!$D$5:$D$304<>""))*1E+10))=0,SUMPRODUCT(MIN((Pendências!$C$5:$C$304=Config!$A$20)*(Pendências!$F$5:$F$304<>"Feito")*(Pendências!$B$5:$B$304<>"")*(Pendências!$D$5:$D$304<>"")*Pendências!$D$5:$D$304+(1-(Pendências!$C$5:$C$304=Config!$A$20)*(Pendências!$F$5:$F$304<>"Feito")*(Pendências!$B$5:$B$304<>"")*(Pendências!$D$5:$D$304<>""))*1E+10))>=1E+10),"",SUMPRODUCT(MIN((Pendências!$C$5:$C$304=Config!$A$20)*(Pendências!$F$5:$F$304<>"Feito")*(Pendências!$B$5:$B$304<>"")*(Pendências!$D$5:$D$304<>"")*Pendências!$D$5:$D$304+(1-(Pendências!$C$5:$C$304=Config!$A$20)*(Pendências!$F$5:$F$304<>"Feito")*(Pendências!$B$5:$B$304<>"")*(Pendências!$D$5:$D$304<>""))*1E+10))),""))

Sheet Resumo
A1: ="Resumo da reunião "&Config!B6&" · "&IFERROR(INDEX(Reuniões!$C$5:$C$104,MATCH(Config!B6,Reuniões!$A$5:$A$104,0)),"") -> Resumo da reunião R-004 · Semanal da equipe
A2: Escolha a reunião em Config. Copie o bloco abaixo e cole no prompt "Escrever 07: resumo de reunião para quem não foi" ou "Escrever 02: e-mail curto que pede algo".
A4: Data | B4: =IFERROR(INDEX(Reuniões!$B$5:$B$104,MATCH(Config!$B$6,Reuniões!$A$5:$A$104,0)),"") -> 46275
A5: Assunto | B5: =IFERROR(INDEX(Reuniões!$C$5:$C$104,MATCH(Config!$B$6,Reuniões!$A$5:$A$104,0)),"") -> Semanal da equipe
A6: Participantes | B6: =IFERROR(INDEX(Reuniões!$D$5:$D$104,MATCH(Config!$B$6,Reuniões!$A$5:$A$104,0)),"") -> Ana; Bruno; Carla; Diego
A7: Decisões | B7: =IFERROR(INDEX(Reuniões!$E$5:$E$104,MATCH(Config!$B$6,Reuniões!$A$5:$A$104,0)),"") -> Manual da Padaria atrasou: Carla fecha até 15/09; Diego prepara o servidor do site; reunião com o Bistrô na quarta
A9: Pendências desta reunião
A10: # | B10: Pendência | C10: Dono | D10: Prazo | E10: Status | F10: Situação
A11: 1 | B11: =IFERROR(IF(INDEX(Pendências!$B$5:$B$304,MATCH(1,Pendências!$K$5:$K$304,0))="","",INDEX(Pendências!$B$5:$B$304,MATCH(1,Pendências!$K$5:$K$304,0))),"") -> Fechar o manual da marca da Padaria | C11: =IFERROR(IF(INDEX(Pendências!$C$5:$C$304,MATCH(1,Pendências!$K$5:$K$304,0))="","",INDEX(Pendências!$C$5:$C$304,MATCH(1,Pendências!$K$5:$K$304,0))),"") -> Carla | D11: =IFERROR(IF(INDEX(Pendências!$D$5:$D$304,MATCH(1,Pendências!$K$5:$K$304,0))="","",INDEX(Pendências!$D$5:$D$304,MATCH(1,Pendências!$K$5:$K$304,0))),"") -> 46280 | E11: =IFERROR(IF(INDEX(Pendências!$F$5:$F$304,MATCH(1,Pendências!$K$5:$K$304,0))="","",INDEX(Pendências!$F$5:$F$304,MATCH(1,Pendências!$K$5:$K$304,0))),"") -> Fazendo | F11: =IFERROR(IF(INDEX(Pendências!$H$5:$H$304,MATCH(1,Pendências!$K$5:$K$304,0))="","",INDEX(Pendências!$H$5:$H$304,MATCH(1,Pendências!$K$5:$K$304,0))),"") -> Esta semana | H11: =""&IF(B11="","",B11&" (dono: "&C11&"; prazo: "&IF(D11="","sem prazo",TEXT(DAY(D11),"00")&"/"&TEXT(MONTH(D11),"00"))&IF(F11="Sem prazo","","; "&LOWER(F11))&") | ") -> Fechar o manual da marca da Padaria (dono: Carla; prazo: 15/09; esta semana) |
A12: 2 | B12: =IFERROR(IF(INDEX(Pendências!$B$5:$B$304,MATCH(2,Pendências!$K$5:$K$304,0))="","",INDEX(Pendências!$B$5:$B$304,MATCH(2,Pendências!$K$5:$K$304,0))),"") -> Preparar o servidor e o domínio do site | C12: =IFERROR(IF(INDEX(Pendências!$C$5:$C$304,MATCH(2,Pendências!$K$5:$K$304,0))="","",INDEX(Pendências!$C$5:$C$304,MATCH(2,Pendências!$K$5:$K$304,0))),"") -> Diego | D12: =IFERROR(IF(INDEX(Pendências!$D$5:$D$304,MATCH(2,Pendências!$K$5:$K$304,0))="","",INDEX(Pendências!$D$5:$D$304,MATCH(2,Pendências!$K$5:$K$304,0))),"") -> 46283 | E12: =IFERROR(IF(INDEX(Pendências!$F$5:$F$304,MATCH(2,Pendências!$K$5:$K$304,0))="","",INDEX(Pendências!$F$5:$F$304,MATCH(2,Pendências!$K$5:$K$304,0))),"") -> A fazer | F12: =IFERROR(IF(INDEX(Pendências!$H$5:$H$304,MATCH(2,Pendências!$K$5:$K$304,0))="","",INDEX(Pendências!$H$5:$H$304,MATCH(2,Pendências!$K$5:$K$304,0))),"") -> Esta semana | H12: =H11&IF(B12="","",B12&" (dono: "&C12&"; prazo: "&IF(D12="","sem prazo",TEXT(DAY(D12),"00")&"/"&TEXT(MONTH(D12),"00"))&IF(F12="Sem prazo","","; "&LOWER(F12))&") | ") -> Fechar o manual da marca da Padaria (dono: Carla; prazo: 15/09; esta semana) | Preparar o servidor e o domínio do site (dono: Diego; prazo: 18/09; esta semana) |
A13: 3 | B13: =IFERROR(IF(INDEX(Pendências!$B$5:$B$304,MATCH(3,Pendências!$K$5:$K$304,0))="","",INDEX(Pendências!$B$5:$B$304,MATCH(3,Pendências!$K$5:$K$304,0))),"") -> Confirmar a reunião de quarta com o Bistrô | C13: =IFERROR(IF(INDEX(Pendências!$C$5:$C$304,MATCH(3,Pendências!$K$5:$K$304,0))="","",INDEX(Pendências!$C$5:$C$304,MATCH(3,Pendências!$K$5:$K$304,0))),"") -> Ana | D13: =IFERROR(IF(INDEX(Pendências!$D$5:$D$304,MATCH(3,Pendências!$K$5:$K$304,0))="","",INDEX(Pendências!$D$5:$D$304,MATCH(3,Pendências!$K$5:$K$304,0))),"") -> 46276 | E13: =IFERROR(IF(INDEX(Pendências!$F$5:$F$304,MATCH(3,Pendências!$K$5:$K$304,0))="","",INDEX(Pendências!$F$5:$F$304,MATCH(3,Pendências!$K$5:$K$304,0))),"") -> A fazer | F13: =IFERROR(IF(INDEX(Pendências!$H$5:$H$304,MATCH(3,Pendências!$K$5:$K$304,0))="","",INDEX(Pendências!$H$5:$H$304,MATCH(3,Pendências!$K$5:$K$304,0))),"") -> Atrasada | H13: =H12&IF(B13="","",B13&" (dono: "&C13&"; prazo: "&IF(D13="","sem prazo",TEXT(DAY(D13),"00")&"/"&TEXT(MONTH(D13),"00"))&IF(F13="Sem prazo","","; "&LOWER(F13))&") | ") -> Fechar o manual da marca da Padaria (dono: Carla; prazo: 15/09; esta semana) | Preparar o servidor e o domínio do site (dono: Diego; prazo: 18/09; esta semana) | Confirmar a reunião de quarta com o Bistrô (dono: Ana; prazo: 11/09; atrasada) |
A14: 4 | B14: =IFERROR(IF(INDEX(Pendências!$B$5:$B$304,MATCH(4,Pendências!$K$5:$K$304,0))="","",INDEX(Pendências!$B$5:$B$304,MATCH(4,Pendências!$K$5:$K$304,0))),"") -> Levantar custo do freela de motion | C14: =IFERROR(IF(INDEX(Pendências!$C$5:$C$304,MATCH(4,Pendências!$K$5:$K$304,0))="","",INDEX(Pendências!$C$5:$C$304,MATCH(4,Pendências!$K$5:$K$304,0))),"") -> Ana | D14: =IFERROR(IF(INDEX(Pendências!$D$5:$D$304,MATCH(4,Pendências!$K$5:$K$304,0))="","",INDEX(Pendências!$D$5:$D$304,MATCH(4,Pendências!$K$5:$K$304,0))),"") -> 46278 | E14: =IFERROR(IF(INDEX(Pendências!$F$5:$F$304,MATCH(4,Pendências!$K$5:$K$304,0))="","",INDEX(Pendências!$F$5:$F$304,MATCH(4,Pendências!$K$5:$K$304,0))),"") -> A fazer | F14: =IFERROR(IF(INDEX(Pendências!$H$5:$H$304,MATCH(4,Pendências!$K$5:$K$304,0))="","",INDEX(Pendências!$H$5:$H$304,MATCH(4,Pendências!$K$5:$K$304,0))),"") -> Atrasada | H14: =H13&IF(B14="","",B14&" (dono: "&C14&"; prazo: "&IF(D14="","sem prazo",TEXT(DAY(D14),"00")&"/"&TEXT(MONTH(D14),"00"))&IF(F14="Sem prazo","","; "&LOWER(F14))&") | ") -> Fechar o manual da marca da Padaria (dono: Carla; prazo: 15/09; esta semana) | Preparar o servidor e o domínio do site (dono: Diego; prazo: 18/09; esta semana) | Confirmar a reunião de quarta com o Bistrô (dono: Ana; prazo: 11/09; atrasada) | Levantar custo do freela de motion (dono: Ana; prazo: 13/09; atrasada) |
A15: 5 | B15: =IFERROR(IF(INDEX(Pendências!$B$5:$B$304,MATCH(5,Pendências!$K$5:$K$304,0))="","",INDEX(Pendências!$B$5:$B$304,MATCH(5,Pendências!$K$5:$K$304,0))),"") -> Revisar a proposta comercial da Aurora | C15: =IFERROR(IF(INDEX(Pendências!$C$5:$C$304,MATCH(5,Pendências!$K$5:$K$304,0))="","",INDEX(Pendências!$C$5:$C$304,MATCH(5,Pendências!$K$5:$K$304,0))),"") -> Ana | D15: =IFERROR(IF(INDEX(Pendências!$D$5:$D$304,MATCH(5,Pendências!$K$5:$K$304,0))="","",INDEX(Pendências!$D$5:$D$304,MATCH(5,Pendências!$K$5:$K$304,0))),"") | E15: =IFERROR(IF(INDEX(Pendências!$F$5:$F$304,MATCH(5,Pendências!$K$5:$K$304,0))="","",INDEX(Pendências!$F$5:$F$304,MATCH(5,Pendências!$K$5:$K$304,0))),"") -> A fazer | F15: =IFERROR(IF(INDEX(Pendências!$H$5:$H$304,MATCH(5,Pendências!$K$5:$K$304,0))="","",INDEX(Pendências!$H$5:$H$304,MATCH(5,Pendências!$K$5:$K$304,0))),"") -> Sem prazo | H15: =H14&IF(B15="","",B15&" (dono: "&C15&"; prazo: "&IF(D15="","sem prazo",TEXT(DAY(D15),"00")&"/"&TEXT(MONTH(D15),"00"))&IF(F15="Sem prazo","","; "&LOWER(F15))&") | ") -> Fechar o manual da marca da Padaria (dono: Carla; prazo: 15/09; esta semana) | Preparar o servidor e o domínio do site (dono: Diego; prazo: 18/09; esta semana) | Confirmar a reunião de quarta com o Bistrô (dono: Ana; prazo: 11/09; atrasada) | Levantar custo do freela de motion (dono: Ana; prazo: 13/09; atrasada) | Revisar a proposta comercial da Aurora (dono: Ana; prazo: sem prazo) |
A16: 6 | B16: =IFERROR(IF(INDEX(Pendências!$B$5:$B$304,MATCH(6,Pendências!$K$5:$K$304,0))="","",INDEX(Pendências!$B$5:$B$304,MATCH(6,Pendências!$K$5:$K$304,0))),"") | C16: =IFERROR(IF(INDEX(Pendências!$C$5:$C$304,MATCH(6,Pendências!$K$5:$K$304,0))="","",INDEX(Pendências!$C$5:$C$304,MATCH(6,Pendências!$K$5:$K$304,0))),"") | D16: =IFERROR(IF(INDEX(Pendências!$D$5:$D$304,MATCH(6,Pendências!$K$5:$K$304,0))="","",INDEX(Pendências!$D$5:$D$304,MATCH(6,Pendências!$K$5:$K$304,0))),"") | E16: =IFERROR(IF(INDEX(Pendências!$F$5:$F$304,MATCH(6,Pendências!$K$5:$K$304,0))="","",INDEX(Pendências!$F$5:$F$304,MATCH(6,Pendências!$K$5:$K$304,0))),"") | F16: =IFERROR(IF(INDEX(Pendências!$H$5:$H$304,MATCH(6,Pendências!$K$5:$K$304,0))="","",INDEX(Pendências!$H$5:$H$304,MATCH(6,Pendências!$K$5:$K$304,0))),"") | H16: =H15&IF(B16="","",B16&" (dono: "&C16&"; prazo: "&IF(D16="","sem prazo",TEXT(DAY(D16),"00")&"/"&TEXT(MONTH(D16),"00"))&IF(F16="Sem prazo","","; "&LOWER(F16))&") | ") -> Fechar o manual da marca da Padaria (dono: Carla; prazo: 15/09; esta semana) | Preparar o servidor e o domínio do site (dono: Diego; prazo: 18/09; esta semana) | Confirmar a reunião de quarta com o Bistrô (dono: Ana; prazo: 11/09; atrasada) | Levantar custo do freela de motion (dono: Ana; prazo: 13/09; atrasada) | Revisar a proposta comercial da Aurora (dono: Ana; prazo: sem prazo) |
