Workbook

Sheet Como usar
A1: Orçamento Previsto × Realizado
A2: Kit IA no Trabalho · Completo · Seu Sócio Gestor · versão 1.0 (setembro de 2026)
A4: O que esta planilha faz | B4: Você planeja o ano por categoria (previsto) e lança o que aconteceu (realizado). Ela mostra, mês a mês, o desvio em reais e em %, o que estourou, o acumulado do ano e o resultado previsto contra o real.
A5: Passo 1 | B5: Em Config, preencha o ano, o mês do painel, o limite de alerta (10% é um bom padrão) e as categorias com tipo (receita ou despesa).
A6: Passo 2 | B6: Em Previsto, digite o valor planejado de cada categoria em cada mês. Pode ser o mesmo número o ano inteiro.
A7: Passo 3 | B7: Em Realizado, uma linha por lançamento, ou uma linha por categoria com o total do mês. A categoria vem da lista.
A8: Passo 4 | B8: Em Painel, escolha o mês em Config: por categoria com situação (dentro, acima, estourou) e o ano completo com gráfico.
A9: Rotina | B9: Uma vez por semana, 10 minutos de lançamentos. Dia 5 de cada mês: fechar o mês anterior e olhar o painel antes de decidir gasto novo.
A10: Com a IA | B10: Copie "Por categoria no mês" e use "Analisar 03: onde cortar gastos" ou "Escrever 05: explicar o mês financeiro". Para a reunião com o sócio, "Apresentar 01: roteiro de 8 slides".
A11: Legenda | B11: Células amarelas: você preenche. Brancas: calculadas. Não é preciso mexer em nada fora do amarelo.
A12: Proteção | B12: Fórmulas protegidas sem senha. Para editar: Revisar > Desproteger planilha (Excel) ou Dados > Proteger intervalos (Google Sheets).
A13: Google Sheets | B13: Faça upload no Google Drive e abra com o Google Sheets. Fórmulas, listas, cores e gráficos funcionam.
A14: Exemplos | B14: Prisma Comunicação é uma empresa fictícia. Nomes e valores são inventados. Apague-os antes de começar.
A15: Suporte | B15: suporte@seusociogestor.com.br · resposta em até 5 dias úteis · reembolso em até 7 dias pelo mesmo canal.

Sheet Painel
A1: =Config!B4&" · "&Config!B6&" de "&Config!B5 -> Prisma Comunicação (exemplo fictício) · Setembro de 2026
A2: Nada para preencher aqui. Escolha o mês em Config; previsto vem da aba Previsto, realizado da aba Realizado.
A4: Receita prevista | C4: Receita realizada | E4: Despesa prevista | G4: Despesa realizada | I4: Resultado do mês
A5: =SUMIFS(INDEX(Previsto!$B$5:$M$24,0,Config!$B$7),Config!$B$12:$B$31,"Receita") -> 95000 | C5: =SUMIFS(Realizado!$D$5:$D$604,Realizado!$H$5:$H$604,"Receita",Realizado!$F$5:$F$604,Config!$B$7,Realizado!$G$5:$G$604,Config!$B$5) -> 95559.34 | E5: =SUMIFS(INDEX(Previsto!$B$5:$M$24,0,Config!$B$7),Config!$B$12:$B$31,"Despesa") -> 77800 | G5: =SUMIFS(Realizado!$D$5:$D$604,Realizado!$H$5:$H$604,"Despesa",Realizado!$F$5:$F$604,Config!$B$7,Realizado!$G$5:$G$604,Config!$B$5) -> 81387.49 | I5: =C5-G5 -> 14171.85
A7: Por categoria no mês
A8: Categoria | B8: Tipo | C8: Previsto | D8: Realizado | E8: Desvio (R$) | F8: Desvio (%) | G8: Situação | H8: Acumulado previsto | I8: Acumulado realizado
A9: =IF(Config!$A$12="","",Config!$A$12) -> Serviços · projetos | B9: =IF(Config!$A$12="","",Config!$B$12) -> Receita | C9: =IF(Config!$A$12="","",INDEX(Previsto!$B$5:$M$5,1,Config!$B$7)) -> 66000 | D9: =IF(Config!$A$12="","",SUMIFS(Realizado!$D$5:$D$604,Realizado!$B$5:$B$604,Config!$A$12,Realizado!$F$5:$F$604,Config!$B$7,Realizado!$G$5:$G$604,Config!$B$5)) -> 65593.42 | E9: =IF(Config!$A$12="","",D9-C9) -> -406.58 | F9: =IF(OR(Config!$A$12="",C9=0),"",E9/C9) -> -0.006160303 | G9: =IF(Config!$A$12="","",IF(B9="Despesa",IF(AND(C9>0,F9>Config!$B$8),"Estourou",IF(D9>C9,"Acima","Dentro")),IF(AND(C9>0,F9<-Config!$B$8),"Abaixo da meta",IF(D9>=C9,"Meta batida","Perto da meta")))) -> Perto da meta | H9: =IF(Config!$A$12="","",SUM(INDEX(Previsto!$B$5:$M$5,1,1):INDEX(Previsto!$B$5:$M$5,1,Config!$B$7))) -> 541000 | I9: =IF(Config!$A$12="","",SUMIFS(Realizado!$D$5:$D$604,Realizado!$B$5:$B$604,Config!$A$12,Realizado!$F$5:$F$604,"<="&Config!$B$7,Realizado!$G$5:$G$604,Config!$B$5)) -> 519718.65
A10: =IF(Config!$A$13="","",Config!$A$13) -> Serviços · mensalidades | B10: =IF(Config!$A$13="","",Config!$B$13) -> Receita | C10: =IF(Config!$A$13="","",INDEX(Previsto!$B$6:$M$6,1,Config!$B$7)) -> 26000 | D10: =IF(Config!$A$13="","",SUMIFS(Realizado!$D$5:$D$604,Realizado!$B$5:$B$604,Config!$A$13,Realizado!$F$5:$F$604,Config!$B$7,Realizado!$G$5:$G$604,Config!$B$5)) -> 26534.91 | E10: =IF(Config!$A$13="","",D10-C10) -> 534.91 | F10: =IF(OR(Config!$A$13="",C10=0),"",E10/C10) -> 0.020573462 | G10: =IF(Config!$A$13="","",IF(B10="Despesa",IF(AND(C10>0,F10>Config!$B$8),"Estourou",IF(D10>C10,"Acima","Dentro")),IF(AND(C10>0,F10<-Config!$B$8),"Abaixo da meta",IF(D10>=C10,"Meta batida","Perto da meta")))) -> Meta batida | H10: =IF(Config!$A$13="","",SUM(INDEX(Previsto!$B$6:$M$6,1,1):INDEX(Previsto!$B$6:$M$6,1,Config!$B$7))) -> 194000 | I10: =IF(Config!$A$13="","",SUMIFS(Realizado!$D$5:$D$604,Realizado!$B$5:$B$604,Config!$A$13,Realizado!$F$5:$F$604,"<="&Config!$B$7,Realizado!$G$5:$G$604,Config!$B$5)) -> 199168.99
A11: =IF(Config!$A$14="","",Config!$A$14) -> Produtos digitais | B11: =IF(Config!$A$14="","",Config!$B$14) -> Receita | C11: =IF(Config!$A$14="","",INDEX(Previsto!$B$7:$M$7,1,Config!$B$7)) -> 3000 | D11: =IF(Config!$A$14="","",SUMIFS(Realizado!$D$5:$D$604,Realizado!$B$5:$B$604,Config!$A$14,Realizado!$F$5:$F$604,Config!$B$7,Realizado!$G$5:$G$604,Config!$B$5)) -> 3431.01 | E11: =IF(Config!$A$14="","",D11-C11) -> 431.01 | F11: =IF(OR(Config!$A$14="",C11=0),"",E11/C11) -> 0.14367 | G11: =IF(Config!$A$14="","",IF(B11="Despesa",IF(AND(C11>0,F11>Config!$B$8),"Estourou",IF(D11>C11,"Acima","Dentro")),IF(AND(C11>0,F11<-Config!$B$8),"Abaixo da meta",IF(D11>=C11,"Meta batida","Perto da meta")))) -> Meta batida | H11: =IF(Config!$A$14="","",SUM(INDEX(Previsto!$B$7:$M$7,1,1):INDEX(Previsto!$B$7:$M$7,1,Config!$B$7))) -> 17000 | I11: =IF(Config!$A$14="","",SUMIFS(Realizado!$D$5:$D$604,Realizado!$B$5:$B$604,Config!$A$14,Realizado!$F$5:$F$604,"<="&Config!$B$7,Realizado!$G$5:$G$604,Config!$B$5)) -> 19802.13
A12: =IF(Config!$A$15="","",Config!$A$15) -> Salários e pró-labore | B12: =IF(Config!$A$15="","",Config!$B$15) -> Despesa | C12: =IF(Config!$A$15="","",INDEX(Previsto!$B$8:$M$8,1,Config!$B$7)) -> 41000 | D12: =IF(Config!$A$15="","",SUMIFS(Realizado!$D$5:$D$604,Realizado!$B$5:$B$604,Config!$A$15,Realizado!$F$5:$F$604,Config!$B$7,Realizado!$G$5:$G$604,Config!$B$5)) -> 41722.62 | E12: =IF(Config!$A$15="","",D12-C12) -> 722.62 | F12: =IF(OR(Config!$A$15="",C12=0),"",E12/C12) -> 0.017624878 | G12: =IF(Config!$A$15="","",IF(B12="Despesa",IF(AND(C12>0,F12>Config!$B$8),"Estourou",IF(D12>C12,"Acima","Dentro")),IF(AND(C12>0,F12<-Config!$B$8),"Abaixo da meta",IF(D12>=C12,"Meta batida","Perto da meta")))) -> Acima | H12: =IF(Config!$A$15="","",SUM(INDEX(Previsto!$B$8:$M$8,1,1):INDEX(Previsto!$B$8:$M$8,1,Config!$B$7))) -> 351000 | I12: =IF(Config!$A$15="","",SUMIFS(Realizado!$D$5:$D$604,Realizado!$B$5:$B$604,Config!$A$15,Realizado!$F$5:$F$604,"<="&Config!$B$7,Realizado!$G$5:$G$604,Config!$B$5)) -> 352675.89
A13: =IF(Config!$A$16="","",Config!$A$16) -> Freelancers | B13: =IF(Config!$A$16="","",Config!$B$16) -> Despesa | C13: =IF(Config!$A$16="","",INDEX(Previsto!$B$9:$M$9,1,Config!$B$7)) -> 9000 | D13: =IF(Config!$A$16="","",SUMIFS(Realizado!$D$5:$D$604,Realizado!$B$5:$B$604,Config!$A$16,Realizado!$F$5:$F$604,Config!$B$7,Realizado!$G$5:$G$604,Config!$B$5)) -> 10749.54 | E13: =IF(Config!$A$16="","",D13-C13) -> 1749.54 | F13: =IF(OR(Config!$A$16="",C13=0),"",E13/C13) -> 0.19439333 | G13: =IF(Config!$A$16="","",IF(B13="Despesa",IF(AND(C13>0,F13>Config!$B$8),"Estourou",IF(D13>C13,"Acima","Dentro")),IF(AND(C13>0,F13<-Config!$B$8),"Abaixo da meta",IF(D13>=C13,"Meta batida","Perto da meta")))) -> Estourou | H13: =IF(Config!$A$16="","",SUM(INDEX(Previsto!$B$9:$M$9,1,1):INDEX(Previsto!$B$9:$M$9,1,Config!$B$7))) -> 68000 | I13: =IF(Config!$A$16="","",SUMIFS(Realizado!$D$5:$D$604,Realizado!$B$5:$B$604,Config!$A$16,Realizado!$F$5:$F$604,"<="&Config!$B$7,Realizado!$G$5:$G$604,Config!$B$5)) -> 83952.45
A14: =IF(Config!$A$17="","",Config!$A$17) -> Escritório e contas | B14: =IF(Config!$A$17="","",Config!$B$17) -> Despesa | C14: =IF(Config!$A$17="","",INDEX(Previsto!$B$10:$M$10,1,Config!$B$7)) -> 4200 | D14: =IF(Config!$A$17="","",SUMIFS(Realizado!$D$5:$D$604,Realizado!$B$5:$B$604,Config!$A$17,Realizado!$F$5:$F$604,Config!$B$7,Realizado!$G$5:$G$604,Config!$B$5)) -> 4257.16 | E14: =IF(Config!$A$17="","",D14-C14) -> 57.16 | F14: =IF(OR(Config!$A$17="",C14=0),"",E14/C14) -> 0.013609524 | G14: =IF(Config!$A$17="","",IF(B14="Despesa",IF(AND(C14>0,F14>Config!$B$8),"Estourou",IF(D14>C14,"Acima","Dentro")),IF(AND(C14>0,F14<-Config!$B$8),"Abaixo da meta",IF(D14>=C14,"Meta batida","Perto da meta")))) -> Acima | H14: =IF(Config!$A$17="","",SUM(INDEX(Previsto!$B$10:$M$10,1,1):INDEX(Previsto!$B$10:$M$10,1,Config!$B$7))) -> 37800 | I14: =IF(Config!$A$17="","",SUMIFS(Realizado!$D$5:$D$604,Realizado!$B$5:$B$604,Config!$A$17,Realizado!$F$5:$F$604,"<="&Config!$B$7,Realizado!$G$5:$G$604,Config!$B$5)) -> 39310.67
A15: =IF(Config!$A$18="","",Config!$A$18) -> Softwares e assinaturas | B15: =IF(Config!$A$18="","",Config!$B$18) -> Despesa | C15: =IF(Config!$A$18="","",INDEX(Previsto!$B$11:$M$11,1,Config!$B$7)) -> 1900 | D15: =IF(Config!$A$18="","",SUMIFS(Realizado!$D$5:$D$604,Realizado!$B$5:$B$604,Config!$A$18,Realizado!$F$5:$F$604,Config!$B$7,Realizado!$G$5:$G$604,Config!$B$5)) -> 2209.34 | E15: =IF(Config!$A$18="","",D15-C15) -> 309.34 | F15: =IF(OR(Config!$A$18="",C15=0),"",E15/C15) -> 0.16281053 | G15: =IF(Config!$A$18="","",IF(B15="Despesa",IF(AND(C15>0,F15>Config!$B$8),"Estourou",IF(D15>C15,"Acima","Dentro")),IF(AND(C15>0,F15<-Config!$B$8),"Abaixo da meta",IF(D15>=C15,"Meta batida","Perto da meta")))) -> Estourou | H15: =IF(Config!$A$18="","",SUM(INDEX(Previsto!$B$11:$M$11,1,1):INDEX(Previsto!$B$11:$M$11,1,Config!$B$7))) -> 17100 | I15: =IF(Config!$A$18="","",SUMIFS(Realizado!$D$5:$D$604,Realizado!$B$5:$B$604,Config!$A$18,Realizado!$F$5:$F$604,"<="&Config!$B$7,Realizado!$G$5:$G$604,Config!$B$5)) -> 19110.46
A16: =IF(Config!$A$19="","",Config!$A$19) -> Marketing e mídia | B16: =IF(Config!$A$19="","",Config!$B$19) -> Despesa | C16: =IF(Config!$A$19="","",INDEX(Previsto!$B$12:$M$12,1,Config!$B$7)) -> 5000 | D16: =IF(Config!$A$19="","",SUMIFS(Realizado!$D$5:$D$604,Realizado!$B$5:$B$604,Config!$A$19,Realizado!$F$5:$F$604,Config!$B$7,Realizado!$G$5:$G$604,Config!$B$5)) -> 6510.99 | E16: =IF(Config!$A$19="","",D16-C16) -> 1510.99 | F16: =IF(OR(Config!$A$19="",C16=0),"",E16/C16) -> 0.302198 | G16: =IF(Config!$A$19="","",IF(B16="Despesa",IF(AND(C16>0,F16>Config!$B$8),"Estourou",IF(D16>C16,"Acima","Dentro")),IF(AND(C16>0,F16<-Config!$B$8),"Abaixo da meta",IF(D16>=C16,"Meta batida","Perto da meta")))) -> Estourou | H16: =IF(Config!$A$19="","",SUM(INDEX(Previsto!$B$12:$M$12,1,1):INDEX(Previsto!$B$12:$M$12,1,Config!$B$7))) -> 35000 | I16: =IF(Config!$A$19="","",SUMIFS(Realizado!$D$5:$D$604,Realizado!$B$5:$B$604,Config!$A$19,Realizado!$F$5:$F$604,"<="&Config!$B$7,Realizado!$G$5:$G$604,Config!$B$5)) -> 45451.52
A17: =IF(Config!$A$20="","",Config!$A$20) -> Impostos | B17: =IF(Config!$A$20="","",Config!$B$20) -> Despesa | C17: =IF(Config!$A$20="","",INDEX(Previsto!$B$13:$M$13,1,Config!$B$7)) -> 10200 | D17: =IF(Config!$A$20="","",SUMIFS(Realizado!$D$5:$D$604,Realizado!$B$5:$B$604,Config!$A$20,Realizado!$F$5:$F$604,Config!$B$7,Realizado!$G$5:$G$604,Config!$B$5)) -> 10137.12 | E17: =IF(Config!$A$20="","",D17-C17) -> -62.88 | F17: =IF(OR(Config!$A$20="",C17=0),"",E17/C17) -> -0.0061647059 | G17: =IF(Config!$A$20="","",IF(B17="Despesa",IF(AND(C17>0,F17>Config!$B$8),"Estourou",IF(D17>C17,"Acima","Dentro")),IF(AND(C17>0,F17<-Config!$B$8),"Abaixo da meta",IF(D17>=C17,"Meta batida","Perto da meta")))) -> Dentro | H17: =IF(Config!$A$20="","",SUM(INDEX(Previsto!$B$13:$M$13,1,1):INDEX(Previsto!$B$13:$M$13,1,Config!$B$7))) -> 84400 | I17: =IF(Config!$A$20="","",SUMIFS(Realizado!$D$5:$D$604,Realizado!$B$5:$B$604,Config!$A$20,Realizado!$F$5:$F$604,"<="&Config!$B$7,Realizado!$G$5:$G$604,Config!$B$5)) -> 83612.75
A18: =IF(Config!$A$21="","",Config!$A$21) -> Equipamentos | B18: =IF(Config!$A$21="","",Config!$B$21) -> Despesa | C18: =IF(Config!$A$21="","",INDEX(Previsto!$B$14:$M$14,1,Config!$B$7)) -> 0 | D18: =IF(Config!$A$21="","",SUMIFS(Realizado!$D$5:$D$604,Realizado!$B$5:$B$604,Config!$A$21,Realizado!$F$5:$F$604,Config!$B$7,Realizado!$G$5:$G$604,Config!$B$5)) -> 0 | E18: =IF(Config!$A$21="","",D18-C18) -> 0 | F18: =IF(OR(Config!$A$21="",C18=0),"",E18/C18) | G18: =IF(Config!$A$21="","",IF(B18="Despesa",IF(AND(C18>0,F18>Config!$B$8),"Estourou",IF(D18>C18,"Acima","Dentro")),IF(AND(C18>0,F18<-Config!$B$8),"Abaixo da meta",IF(D18>=C18,"Meta batida","Perto da meta")))) -> Dentro | H18: =IF(Config!$A$21="","",SUM(INDEX(Previsto!$B$14:$M$14,1,1):INDEX(Previsto!$B$14:$M$14,1,Config!$B$7))) -> 7000 | I18: =IF(Config!$A$21="","",SUMIFS(Realizado!$D$5:$D$604,Realizado!$B$5:$B$604,Config!$A$21,Realizado!$F$5:$F$604,"<="&Config!$B$7,Realizado!$G$5:$G$604,Config!$B$5)) -> 7026.92
A19: =IF(Config!$A$22="","",Config!$A$22) -> Treinamento | B19: =IF(Config!$A$22="","",Config!$B$22) -> Despesa | C19: =IF(Config!$A$22="","",INDEX(Previsto!$B$15:$M$15,1,Config!$B$7)) -> 500 | D19: =IF(Config!$A$22="","",SUMIFS(Realizado!$D$5:$D$604,Realizado!$B$5:$B$604,Config!$A$22,Realizado!$F$5:$F$604,Config!$B$7,Realizado!$G$5:$G$604,Config!$B$5)) -> 198.64 | E19: =IF(Config!$A$22="","",D19-C19) -> -301.36 | F19: =IF(OR(Config!$A$22="",C19=0),"",E19/C19) -> -0.60272 | G19: =IF(Config!$A$22="","",IF(B19="Despesa",IF(AND(C19>0,F19>Config!$B$8),"Estourou",IF(D19>C19,"Acima","Dentro")),IF(AND(C19>0,F19<-Config!$B$8),"Abaixo da meta",IF(D19>=C19,"Meta batida","Perto da meta")))) -> Dentro | H19: =IF(Config!$A$22="","",SUM(INDEX(Previsto!$B$15:$M$15,1,1):INDEX(Previsto!$B$15:$M$15,1,Config!$B$7))) -> 4500 | I19: =IF(Config!$A$22="","",SUMIFS(Realizado!$D$5:$D$604,Realizado!$B$5:$B$604,Config!$A$22,Realizado!$F$5:$F$604,"<="&Config!$B$7,Realizado!$G$5:$G$604,Config!$B$5)) -> 1815.27
A20: =IF(Config!$A$23="","",Config!$A$23) -> Viagens e eventos | B20: =IF(Config!$A$23="","",Config!$B$23) -> Despesa | C20: =IF(Config!$A$23="","",INDEX(Previsto!$B$16:$M$16,1,Config!$B$7)) -> 3000 | D20: =IF(Config!$A$23="","",SUMIFS(Realizado!$D$5:$D$604,Realizado!$B$5:$B$604,Config!$A$23,Realizado!$F$5:$F$604,Config!$B$7,Realizado!$G$5:$G$604,Config!$B$5)) -> 2717.27 | E20: =IF(Config!$A$23="","",D20-C20) -> -282.73 | F20: =IF(OR(Config!$A$23="",C20=0),"",E20/C20) -> -0.094243333 | G20: =IF(Config!$A$23="","",IF(B20="Despesa",IF(AND(C20>0,F20>Config!$B$8),"Estourou",IF(D20>C20,"Acima","Dentro")),IF(AND(C20>0,F20<-Config!$B$8),"Abaixo da meta",IF(D20>=C20,"Meta batida","Perto da meta")))) -> Dentro | H20: =IF(Config!$A$23="","",SUM(INDEX(Previsto!$B$16:$M$16,1,1):INDEX(Previsto!$B$16:$M$16,1,Config!$B$7))) -> 11100 | I20: =IF(Config!$A$23="","",SUMIFS(Realizado!$D$5:$D$604,Realizado!$B$5:$B$604,Config!$A$23,Realizado!$F$5:$F$604,"<="&Config!$B$7,Realizado!$G$5:$G$604,Config!$B$5)) -> 10012.63
A21: =IF(Config!$A$24="","",Config!$A$24) -> Reserva | B21: =IF(Config!$A$24="","",Config!$B$24) -> Despesa | C21: =IF(Config!$A$24="","",INDEX(Previsto!$B$17:$M$17,1,Config!$B$7)) -> 3000 | D21: =IF(Config!$A$24="","",SUMIFS(Realizado!$D$5:$D$604,Realizado!$B$5:$B$604,Config!$A$24,Realizado!$F$5:$F$604,Config!$B$7,Realizado!$G$5:$G$604,Config!$B$5)) -> 2884.81 | E21: =IF(Config!$A$24="","",D21-C21) -> -115.19 | F21: =IF(OR(Config!$A$24="",C21=0),"",E21/C21) -> -0.038396667 | G21: =IF(Config!$A$24="","",IF(B21="Despesa",IF(AND(C21>0,F21>Config!$B$8),"Estourou",IF(D21>C21,"Acima","Dentro")),IF(AND(C21>0,F21<-Config!$B$8),"Abaixo da meta",IF(D21>=C21,"Meta batida","Perto da meta")))) -> Dentro | H21: =IF(Config!$A$24="","",SUM(INDEX(Previsto!$B$17:$M$17,1,1):INDEX(Previsto!$B$17:$M$17,1,Config!$B$7))) -> 27000 | I21: =IF(Config!$A$24="","",SUMIFS(Realizado!$D$5:$D$604,Realizado!$B$5:$B$604,Config!$A$24,Realizado!$F$5:$F$604,"<="&Config!$B$7,Realizado!$G$5:$G$604,Config!$B$5)) -> 26763.1
A22: =IF(Config!$A$25="","",Config!$A$25) | B22: =IF(Config!$A$25="","",Config!$B$25) | C22: =IF(Config!$A$25="","",INDEX(Previsto!$B$18:$M$18,1,Config!$B$7)) | D22: =IF(Config!$A$25="","",SUMIFS(Realizado!$D$5:$D$604,Realizado!$B$5:$B$604,Config!$A$25,Realizado!$F$5:$F$604,Config!$B$7,Realizado!$G$5:$G$604,Config!$B$5)) | E22: =IF(Config!$A$25="","",D22-C22) | F22: =IF(OR(Config!$A$25="",C22=0),"",E22/C22) | G22: =IF(Config!$A$25="","",IF(B22="Despesa",IF(AND(C22>0,F22>Config!$B$8),"Estourou",IF(D22>C22,"Acima","Dentro")),IF(AND(C22>0,F22<-Config!$B$8),"Abaixo da meta",IF(D22>=C22,"Meta batida","Perto da meta")))) | H22: =IF(Config!$A$25="","",SUM(INDEX(Previsto!$B$18:$M$18,1,1):INDEX(Previsto!$B$18:$M$18,1,Config!$B$7))) | I22: =IF(Config!$A$25="","",SUMIFS(Realizado!$D$5:$D$604,Realizado!$B$5:$B$604,Config!$A$25,Realizado!$F$5:$F$604,"<="&Config!$B$7,Realizado!$G$5:$G$604,Config!$B$5))
A23: =IF(Config!$A$26="","",Config!$A$26) | B23: =IF(Config!$A$26="","",Config!$B$26) | C23: =IF(Config!$A$26="","",INDEX(Previsto!$B$19:$M$19,1,Config!$B$7)) | D23: =IF(Config!$A$26="","",SUMIFS(Realizado!$D$5:$D$604,Realizado!$B$5:$B$604,Config!$A$26,Realizado!$F$5:$F$604,Config!$B$7,Realizado!$G$5:$G$604,Config!$B$5)) | E23: =IF(Config!$A$26="","",D23-C23) | F23: =IF(OR(Config!$A$26="",C23=0),"",E23/C23) | G23: =IF(Config!$A$26="","",IF(B23="Despesa",IF(AND(C23>0,F23>Config!$B$8),"Estourou",IF(D23>C23,"Acima","Dentro")),IF(AND(C23>0,F23<-Config!$B$8),"Abaixo da meta",IF(D23>=C23,"Meta batida","Perto da meta")))) | H23: =IF(Config!$A$26="","",SUM(INDEX(Previsto!$B$19:$M$19,1,1):INDEX(Previsto!$B$19:$M$19,1,Config!$B$7))) | I23: =IF(Config!$A$26="","",SUMIFS(Realizado!$D$5:$D$604,Realizado!$B$5:$B$604,Config!$A$26,Realizado!$F$5:$F$604,"<="&Config!$B$7,Realizado!$G$5:$G$604,Config!$B$5))
A24: =IF(Config!$A$27="","",Config!$A$27) | B24: =IF(Config!$A$27="","",Config!$B$27) | C24: =IF(Config!$A$27="","",INDEX(Previsto!$B$20:$M$20,1,Config!$B$7)) | D24: =IF(Config!$A$27="","",SUMIFS(Realizado!$D$5:$D$604,Realizado!$B$5:$B$604,Config!$A$27,Realizado!$F$5:$F$604,Config!$B$7,Realizado!$G$5:$G$604,Config!$B$5)) | E24: =IF(Config!$A$27="","",D24-C24) | F24: =IF(OR(Config!$A$27="",C24=0),"",E24/C24) | G24: =IF(Config!$A$27="","",IF(B24="Despesa",IF(AND(C24>0,F24>Config!$B$8),"Estourou",IF(D24>C24,"Acima","Dentro")),IF(AND(C24>0,F24<-Config!$B$8),"Abaixo da meta",IF(D24>=C24,"Meta batida","Perto da meta")))) | H24: =IF(Config!$A$27="","",SUM(INDEX(Previsto!$B$20:$M$20,1,1):INDEX(Previsto!$B$20:$M$20,1,Config!$B$7))) | I24: =IF(Config!$A$27="","",SUMIFS(Realizado!$D$5:$D$604,Realizado!$B$5:$B$604,Config!$A$27,Realizado!$F$5:$F$604,"<="&Config!$B$7,Realizado!$G$5:$G$604,Config!$B$5))
A25: =IF(Config!$A$28="","",Config!$A$28) | B25: =IF(Config!$A$28="","",Config!$B$28) | C25: =IF(Config!$A$28="","",INDEX(Previsto!$B$21:$M$21,1,Config!$B$7)) | D25: =IF(Config!$A$28="","",SUMIFS(Realizado!$D$5:$D$604,Realizado!$B$5:$B$604,Config!$A$28,Realizado!$F$5:$F$604,Config!$B$7,Realizado!$G$5:$G$604,Config!$B$5)) | E25: =IF(Config!$A$28="","",D25-C25) | F25: =IF(OR(Config!$A$28="",C25=0),"",E25/C25) | G25: =IF(Config!$A$28="","",IF(B25="Despesa",IF(AND(C25>0,F25>Config!$B$8),"Estourou",IF(D25>C25,"Acima","Dentro")),IF(AND(C25>0,F25<-Config!$B$8),"Abaixo da meta",IF(D25>=C25,"Meta batida","Perto da meta")))) | H25: =IF(Config!$A$28="","",SUM(INDEX(Previsto!$B$21:$M$21,1,1):INDEX(Previsto!$B$21:$M$21,1,Config!$B$7))) | I25: =IF(Config!$A$28="","",SUMIFS(Realizado!$D$5:$D$604,Realizado!$B$5:$B$604,Config!$A$28,Realizado!$F$5:$F$604,"<="&Config!$B$7,Realizado!$G$5:$G$604,Config!$B$5))
A26: =IF(Config!$A$29="","",Config!$A$29) | B26: =IF(Config!$A$29="","",Config!$B$29) | C26: =IF(Config!$A$29="","",INDEX(Previsto!$B$22:$M$22,1,Config!$B$7)) | D26: =IF(Config!$A$29="","",SUMIFS(Realizado!$D$5:$D$604,Realizado!$B$5:$B$604,Config!$A$29,Realizado!$F$5:$F$604,Config!$B$7,Realizado!$G$5:$G$604,Config!$B$5)) | E26: =IF(Config!$A$29="","",D26-C26) | F26: =IF(OR(Config!$A$29="",C26=0),"",E26/C26) | G26: =IF(Config!$A$29="","",IF(B26="Despesa",IF(AND(C26>0,F26>Config!$B$8),"Estourou",IF(D26>C26,"Acima","Dentro")),IF(AND(C26>0,F26<-Config!$B$8),"Abaixo da meta",IF(D26>=C26,"Meta batida","Perto da meta")))) | H26: =IF(Config!$A$29="","",SUM(INDEX(Previsto!$B$22:$M$22,1,1):INDEX(Previsto!$B$22:$M$22,1,Config!$B$7))) | I26: =IF(Config!$A$29="","",SUMIFS(Realizado!$D$5:$D$604,Realizado!$B$5:$B$604,Config!$A$29,Realizado!$F$5:$F$604,"<="&Config!$B$7,Realizado!$G$5:$G$604,Config!$B$5))
A27: =IF(Config!$A$30="","",Config!$A$30) | B27: =IF(Config!$A$30="","",Config!$B$30) | C27: =IF(Config!$A$30="","",INDEX(Previsto!$B$23:$M$23,1,Config!$B$7)) | D27: =IF(Config!$A$30="","",SUMIFS(Realizado!$D$5:$D$604,Realizado!$B$5:$B$604,Config!$A$30,Realizado!$F$5:$F$604,Config!$B$7,Realizado!$G$5:$G$604,Config!$B$5)) | E27: =IF(Config!$A$30="","",D27-C27) | F27: =IF(OR(Config!$A$30="",C27=0),"",E27/C27) | G27: =IF(Config!$A$30="","",IF(B27="Despesa",IF(AND(C27>0,F27>Config!$B$8),"Estourou",IF(D27>C27,"Acima","Dentro")),IF(AND(C27>0,F27<-Config!$B$8),"Abaixo da meta",IF(D27>=C27,"Meta batida","Perto da meta")))) | H27: =IF(Config!$A$30="","",SUM(INDEX(Previsto!$B$23:$M$23,1,1):INDEX(Previsto!$B$23:$M$23,1,Config!$B$7))) | I27: =IF(Config!$A$30="","",SUMIFS(Realizado!$D$5:$D$604,Realizado!$B$5:$B$604,Config!$A$30,Realizado!$F$5:$F$604,"<="&Config!$B$7,Realizado!$G$5:$G$604,Config!$B$5))
A28: =IF(Config!$A$31="","",Config!$A$31) | B28: =IF(Config!$A$31="","",Config!$B$31) | C28: =IF(Config!$A$31="","",INDEX(Previsto!$B$24:$M$24,1,Config!$B$7)) | D28: =IF(Config!$A$31="","",SUMIFS(Realizado!$D$5:$D$604,Realizado!$B$5:$B$604,Config!$A$31,Realizado!$F$5:$F$604,Config!$B$7,Realizado!$G$5:$G$604,Config!$B$5)) | E28: =IF(Config!$A$31="","",D28-C28) | F28: =IF(OR(Config!$A$31="",C28=0),"",E28/C28) | G28: =IF(Config!$A$31="","",IF(B28="Despesa",IF(AND(C28>0,F28>Config!$B$8),"Estourou",IF(D28>C28,"Acima","Dentro")),IF(AND(C28>0,F28<-Config!$B$8),"Abaixo da meta",IF(D28>=C28,"Meta batida","Perto da meta")))) | H28: =IF(Config!$A$31="","",SUM(INDEX(Previsto!$B$24:$M$24,1,1):INDEX(Previsto!$B$24:$M$24,1,Config!$B$7))) | I28: =IF(Config!$A$31="","",SUMIFS(Realizado!$D$5:$D$604,Realizado!$B$5:$B$604,Config!$A$31,Realizado!$F$5:$F$604,"<="&Config!$B$7,Realizado!$G$5:$G$604,Config!$B$5))
A30: O ano, mês a mês
A31: Mês | B31: Receita prevista | C31: Receita realizada | D31: Despesa prevista | E31: Despesa realizada | F31: Resultado previsto | G31: Resultado realizado
A32: Janeiro | B32: =SUMIFS(INDEX(Previsto!$B$5:$M$24,0,1),Config!$B$12:$B$31,"Receita") -> 71000 | C32: =SUMIFS(Realizado!$D$5:$D$604,Realizado!$H$5:$H$604,"Receita",Realizado!$F$5:$F$604,1,Realizado!$G$5:$G$604,Config!$B$5) -> 68436.54 | D32: =SUMIFS(INDEX(Previsto!$B$5:$M$24,0,1),Config!$B$12:$B$31,"Despesa") -> 65900 | E32: =SUMIFS(Realizado!$D$5:$D$604,Realizado!$H$5:$H$604,"Despesa",Realizado!$F$5:$F$604,1,Realizado!$G$5:$G$604,Config!$B$5) -> 68195.56 | F32: =B32-D32 -> 5100 | G32: =C32-E32 -> 240.98
A33: Fevereiro | B33: =SUMIFS(INDEX(Previsto!$B$5:$M$24,0,2),Config!$B$12:$B$31,"Receita") -> 74000 | C33: =SUMIFS(Realizado!$D$5:$D$604,Realizado!$H$5:$H$604,"Receita",Realizado!$F$5:$F$604,2,Realizado!$G$5:$G$604,Config!$B$5) -> 72382.24 | D33: =SUMIFS(INDEX(Previsto!$B$5:$M$24,0,2),Config!$B$12:$B$31,"Despesa") -> 66100 | E33: =SUMIFS(Realizado!$D$5:$D$604,Realizado!$H$5:$H$604,"Despesa",Realizado!$F$5:$F$604,2,Realizado!$G$5:$G$604,Config!$B$5) -> 68512.13 | F33: =B33-D33 -> 7900 | G33: =C33-E33 -> 3870.11
A34: Março | B34: =SUMIFS(INDEX(Previsto!$B$5:$M$24,0,3),Config!$B$12:$B$31,"Receita") -> 79500 | C34: =SUMIFS(Realizado!$D$5:$D$604,Realizado!$H$5:$H$604,"Receita",Realizado!$F$5:$F$604,3,Realizado!$G$5:$G$604,Config!$B$5) -> 79418.93 | D34: =SUMIFS(INDEX(Previsto!$B$5:$M$24,0,3),Config!$B$12:$B$31,"Despesa") -> 71900 | E34: =SUMIFS(Realizado!$D$5:$D$604,Realizado!$H$5:$H$604,"Despesa",Realizado!$F$5:$F$604,3,Realizado!$G$5:$G$604,Config!$B$5) -> 75904.68 | F34: =B34-D34 -> 7600 | G34: =C34-E34 -> 3514.25
A35: Abril | B35: =SUMIFS(INDEX(Previsto!$B$5:$M$24,0,4),Config!$B$12:$B$31,"Receita") -> 81500 | C35: =SUMIFS(Realizado!$D$5:$D$604,Realizado!$H$5:$H$604,"Receita",Realizado!$F$5:$F$604,4,Realizado!$G$5:$G$604,Config!$B$5) -> 79171.73 | D35: =SUMIFS(INDEX(Previsto!$B$5:$M$24,0,4),Config!$B$12:$B$31,"Despesa") -> 69800 | E35: =SUMIFS(Realizado!$D$5:$D$604,Realizado!$H$5:$H$604,"Despesa",Realizado!$F$5:$F$604,4,Realizado!$G$5:$G$604,Config!$B$5) -> 72484.05 | F35: =B35-D35 -> 11700 | G35: =C35-E35 -> 6687.68
A36: Maio | B36: =SUMIFS(INDEX(Previsto!$B$5:$M$24,0,5),Config!$B$12:$B$31,"Receita") -> 84000 | C36: =SUMIFS(Realizado!$D$5:$D$604,Realizado!$H$5:$H$604,"Receita",Realizado!$F$5:$F$604,5,Realizado!$G$5:$G$604,Config!$B$5) -> 84895.22 | D36: =SUMIFS(INDEX(Previsto!$B$5:$M$24,0,5),Config!$B$12:$B$31,"Despesa") -> 69800 | E36: =SUMIFS(Realizado!$D$5:$D$604,Realizado!$H$5:$H$604,"Despesa",Realizado!$F$5:$F$604,5,Realizado!$G$5:$G$604,Config!$B$5) -> 72272.98 | F36: =B36-D36 -> 14200 | G36: =C36-E36 -> 12622.24
A37: Junho | B37: =SUMIFS(INDEX(Previsto!$B$5:$M$24,0,6),Config!$B$12:$B$31,"Receita") -> 86000 | C37: =SUMIFS(Realizado!$D$5:$D$604,Realizado!$H$5:$H$604,"Receita",Realizado!$F$5:$F$604,6,Realizado!$G$5:$G$604,Config!$B$5) -> 82906.89 | D37: =SUMIFS(INDEX(Previsto!$B$5:$M$24,0,6),Config!$B$12:$B$31,"Despesa") -> 70000 | E37: =SUMIFS(Realizado!$D$5:$D$604,Realizado!$H$5:$H$604,"Despesa",Realizado!$F$5:$F$604,6,Realizado!$G$5:$G$604,Config!$B$5) -> 71740.09 | F37: =B37-D37 -> 16000 | G37: =C37-E37 -> 11166.8
A38: Julho | B38: =SUMIFS(INDEX(Previsto!$B$5:$M$24,0,7),Config!$B$12:$B$31,"Receita") -> 90500 | C38: =SUMIFS(Realizado!$D$5:$D$604,Realizado!$H$5:$H$604,"Receita",Realizado!$F$5:$F$604,7,Realizado!$G$5:$G$604,Config!$B$5) -> 89625.23 | D38: =SUMIFS(INDEX(Previsto!$B$5:$M$24,0,7),Config!$B$12:$B$31,"Despesa") -> 76800 | E38: =SUMIFS(Realizado!$D$5:$D$604,Realizado!$H$5:$H$604,"Despesa",Realizado!$F$5:$F$604,7,Realizado!$G$5:$G$604,Config!$B$5) -> 81289.98 | F38: =B38-D38 -> 13700 | G38: =C38-E38 -> 8335.25
A39: Agosto | B39: =SUMIFS(INDEX(Previsto!$B$5:$M$24,0,8),Config!$B$12:$B$31,"Receita") -> 90500 | C39: =SUMIFS(Realizado!$D$5:$D$604,Realizado!$H$5:$H$604,"Receita",Realizado!$F$5:$F$604,8,Realizado!$G$5:$G$604,Config!$B$5) -> 86293.65 | D39: =SUMIFS(INDEX(Previsto!$B$5:$M$24,0,8),Config!$B$12:$B$31,"Despesa") -> 74800 | E39: =SUMIFS(Realizado!$D$5:$D$604,Realizado!$H$5:$H$604,"Despesa",Realizado!$F$5:$F$604,8,Realizado!$G$5:$G$604,Config!$B$5) -> 77944.7 | F39: =B39-D39 -> 15700 | G39: =C39-E39 -> 8348.95
A40: Setembro | B40: =SUMIFS(INDEX(Previsto!$B$5:$M$24,0,9),Config!$B$12:$B$31,"Receita") -> 95000 | C40: =SUMIFS(Realizado!$D$5:$D$604,Realizado!$H$5:$H$604,"Receita",Realizado!$F$5:$F$604,9,Realizado!$G$5:$G$604,Config!$B$5) -> 95559.34 | D40: =SUMIFS(INDEX(Previsto!$B$5:$M$24,0,9),Config!$B$12:$B$31,"Despesa") -> 77800 | E40: =SUMIFS(Realizado!$D$5:$D$604,Realizado!$H$5:$H$604,"Despesa",Realizado!$F$5:$F$604,9,Realizado!$G$5:$G$604,Config!$B$5) -> 81387.49 | F40: =B40-D40 -> 17200 | G40: =C40-E40 -> 14171.85
A41: Outubro | B41: =SUMIFS(INDEX(Previsto!$B$5:$M$24,0,10),Config!$B$12:$B$31,"Receita") -> 99000 | C41: =SUMIFS(Realizado!$D$5:$D$604,Realizado!$H$5:$H$604,"Receita",Realizado!$F$5:$F$604,10,Realizado!$G$5:$G$604,Config!$B$5) -> 0 | D41: =SUMIFS(INDEX(Previsto!$B$5:$M$24,0,10),Config!$B$12:$B$31,"Despesa") -> 78100 | E41: =SUMIFS(Realizado!$D$5:$D$604,Realizado!$H$5:$H$604,"Despesa",Realizado!$F$5:$F$604,10,Realizado!$G$5:$G$604,Config!$B$5) -> 0 | F41: =B41-D41 -> 20900 | G41: =C41-E41 -> 0
A42: Novembro | B42: =SUMIFS(INDEX(Previsto!$B$5:$M$24,0,11),Config!$B$12:$B$31,"Receita") -> 103500 | C42: =SUMIFS(Realizado!$D$5:$D$604,Realizado!$H$5:$H$604,"Receita",Realizado!$F$5:$F$604,11,Realizado!$G$5:$G$604,Config!$B$5) -> 0 | D42: =SUMIFS(INDEX(Previsto!$B$5:$M$24,0,11),Config!$B$12:$B$31,"Despesa") -> 78400 | E42: =SUMIFS(Realizado!$D$5:$D$604,Realizado!$H$5:$H$604,"Despesa",Realizado!$F$5:$F$604,11,Realizado!$G$5:$G$604,Config!$B$5) -> 0 | F42: =B42-D42 -> 25100 | G42: =C42-E42 -> 0
A43: Dezembro | B43: =SUMIFS(INDEX(Previsto!$B$5:$M$24,0,12),Config!$B$12:$B$31,"Receita") -> 92000 | C43: =SUMIFS(Realizado!$D$5:$D$604,Realizado!$H$5:$H$604,"Receita",Realizado!$F$5:$F$604,12,Realizado!$G$5:$G$604,Config!$B$5) -> 0 | D43: =SUMIFS(INDEX(Previsto!$B$5:$M$24,0,12),Config!$B$12:$B$31,"Despesa") -> 70400 | E43: =SUMIFS(Realizado!$D$5:$D$604,Realizado!$H$5:$H$604,"Despesa",Realizado!$F$5:$F$604,12,Realizado!$G$5:$G$604,Config!$B$5) -> 0 | F43: =B43-D43 -> 21600 | G43: =C43-E43 -> 0
...

Sheet Config
A1: Configurações
A2: Células amarelas: você preenche. As categorias aqui alimentam a aba Previsto e a lista de Realizado.
A4: Empresa ou área | B4: Prisma Comunicação (exemplo fictício) | E4: Meses
A5: Ano | B5: 2026 | E5: Janeiro
A6: Mês do painel | B6: Setembro | E6: Fevereiro
A7: Número do mês | B7: =MATCH(B6,$E$5:$E$16,0) -> 9 | E7: Março
A8: Alerta de estouro acima de (%) | B8: 0.1 | E8: Abril
E9: Maio
A10: Categorias (até 20) | E10: Junho
A11: Categoria | B11: Tipo | C11: Responsável | E11: Julho
A12: Serviços · projetos | B12: Receita | C12: Ana | E12: Agosto
A13: Serviços · mensalidades | B13: Receita | C13: Ana | E13: Setembro
A14: Produtos digitais | B14: Receita | C14: Carla | E14: Outubro
A15: Salários e pró-labore | B15: Despesa | C15: Ana | E15: Novembro
A16: Freelancers | B16: Despesa | C16: Bruno | E16: Dezembro
A17: Escritório e contas | B17: Despesa | C17: Ana
A18: Softwares e assinaturas | B18: Despesa | C18: Diego
A19: Marketing e mídia | B19: Despesa | C19: Carla
A20: Impostos | B20: Despesa | C20: Ana
A21: Equipamentos | B21: Despesa | C21: Diego
A22: Treinamento | B22: Despesa | C22: Ana
A23: Viagens e eventos | B23: Despesa | C23: Carla
A24: Reserva | B24: Despesa | C24: Ana

Sheet Previsto
A1: Orçamento previsto
A2: Quanto você planeja receber ou gastar em cada categoria, mês a mês. Preencha o amarelo; total é calculado.
A4: Categoria | B4: Jan | C4: Fev | D4: Mar | E4: Abr | F4: Mai | G4: Jun | H4: Jul | I4: Ago | J4: Set | K4: Out | L4: Nov | M4: Dez | N4: Total
A5: =IF(Config!$A$12="","",Config!$A$12) -> Serviços · projetos | B5: 52000 | C5: 55000 | D5: 58000 | E5: 60000 | F5: 60000 | G5: 62000 | H5: 64000 | I5: 64000 | J5: 66000 | K5: 70000 | L5: 72000 | M5: 60000 | N5: =IF(A5="","",SUM(B5:M5)) -> 743000
A6: =IF(Config!$A$13="","",Config!$A$13) -> Serviços · mensalidades | B6: 18000 | C6: 18000 | D6: 20000 | E6: 20000 | F6: 22000 | G6: 22000 | H6: 24000 | I6: 24000 | J6: 26000 | K6: 26000 | L6: 28000 | M6: 28000 | N6: =IF(A6="","",SUM(B6:M6)) -> 276000
A7: =IF(Config!$A$14="","",Config!$A$14) -> Produtos digitais | B7: 1000 | C7: 1000 | D7: 1500 | E7: 1500 | F7: 2000 | G7: 2000 | H7: 2500 | I7: 2500 | J7: 3000 | K7: 3000 | L7: 3500 | M7: 4000 | N7: =IF(A7="","",SUM(B7:M7)) -> 27500
A8: =IF(Config!$A$15="","",Config!$A$15) -> Salários e pró-labore | B8: 38000 | C8: 38000 | D8: 38000 | E8: 38000 | F8: 38000 | G8: 38000 | H8: 41000 | I8: 41000 | J8: 41000 | K8: 41000 | L8: 41000 | M8: 41000 | N8: =IF(A8="","",SUM(B8:M8)) -> 474000
A9: =IF(Config!$A$16="","",Config!$A$16) -> Freelancers | B9: 6000 | C9: 6000 | D9: 7000 | E9: 7000 | F9: 8000 | G9: 8000 | H9: 8000 | I9: 9000 | J9: 9000 | K9: 10000 | L9: 10000 | M9: 6000 | N9: =IF(A9="","",SUM(B9:M9)) -> 94000
A10: =IF(Config!$A$17="","",Config!$A$17) -> Escritório e contas | B10: 4200 | C10: 4200 | D10: 4200 | E10: 4200 | F10: 4200 | G10: 4200 | H10: 4200 | I10: 4200 | J10: 4200 | K10: 4200 | L10: 4200 | M10: 4200 | N10: =IF(A10="","",SUM(B10:M10)) -> 50400
A11: =IF(Config!$A$18="","",Config!$A$18) -> Softwares e assinaturas | B11: 1900 | C11: 1900 | D11: 1900 | E11: 1900 | F11: 1900 | G11: 1900 | H11: 1900 | I11: 1900 | J11: 1900 | K11: 1900 | L11: 1900 | M11: 1900 | N11: =IF(A11="","",SUM(B11:M11)) -> 22800
A12: =IF(Config!$A$19="","",Config!$A$19) -> Marketing e mídia | B12: 3000 | C12: 3000 | D12: 3500 | E12: 3500 | F12: 4000 | G12: 4000 | H12: 4500 | I12: 4500 | J12: 5000 | K12: 6000 | L12: 6000 | M12: 3000 | N12: =IF(A12="","",SUM(B12:M12)) -> 50000
A13: =IF(Config!$A$20="","",Config!$A$20) -> Impostos | B13: 8500 | C13: 8700 | D13: 9000 | E13: 9200 | F13: 9400 | G13: 9600 | H13: 9900 | I13: 9900 | J13: 10200 | K13: 10700 | L13: 11000 | M13: 10000 | N13: =IF(A13="","",SUM(B13:M13)) -> 116100
A14: =IF(Config!$A$21="","",Config!$A$21) -> Equipamentos | B14: 0 | C14: 0 | D14: 4000 | E14: 0 | F14: 0 | G14: 0 | H14: 3000 | I14: 0 | J14: 0 | K14: 0 | L14: 0 | M14: 0 | N14: =IF(A14="","",SUM(B14:M14)) -> 7000
A15: =IF(Config!$A$22="","",Config!$A$22) -> Treinamento | B15: 500 | C15: 500 | D15: 500 | E15: 500 | F15: 500 | G15: 500 | H15: 500 | I15: 500 | J15: 500 | K15: 500 | L15: 500 | M15: 500 | N15: =IF(A15="","",SUM(B15:M15)) -> 6000
A16: =IF(Config!$A$23="","",Config!$A$23) -> Viagens e eventos | B16: 800 | C16: 800 | D16: 800 | E16: 2500 | F16: 800 | G16: 800 | H16: 800 | I16: 800 | J16: 3000 | K16: 800 | L16: 800 | M16: 800 | N16: =IF(A16="","",SUM(B16:M16)) -> 13500
A17: =IF(Config!$A$24="","",Config!$A$24) -> Reserva | B17: 3000 | C17: 3000 | D17: 3000 | E17: 3000 | F17: 3000 | G17: 3000 | H17: 3000 | I17: 3000 | J17: 3000 | K17: 3000 | L17: 3000 | M17: 3000 | N17: =IF(A17="","",SUM(B17:M17)) -> 36000
A18: =IF(Config!$A$25="","",Config!$A$25) | N18: =IF(A18="","",SUM(B18:M18))
A19: =IF(Config!$A$26="","",Config!$A$26) | N19: =IF(A19="","",SUM(B19:M19))
A20: =IF(Config!$A$27="","",Config!$A$27) | N20: =IF(A20="","",SUM(B20:M20))
A21: =IF(Config!$A$28="","",Config!$A$28) | N21: =IF(A21="","",SUM(B21:M21))
A22: =IF(Config!$A$29="","",Config!$A$29) | N22: =IF(A22="","",SUM(B22:M22))
A23: =IF(Config!$A$30="","",Config!$A$30) | N23: =IF(A23="","",SUM(B23:M23))
A24: =IF(Config!$A$31="","",Config!$A$31) | N24: =IF(A24="","",SUM(B24:M24))
A25: Receitas previstas | B25: =SUMIFS(B5:B24,Config!$B$12:$B$31,"Receita") -> 71000 | C25: =SUMIFS(C5:C24,Config!$B$12:$B$31,"Receita") -> 74000 | D25: =SUMIFS(D5:D24,Config!$B$12:$B$31,"Receita") -> 79500 | E25: =SUMIFS(E5:E24,Config!$B$12:$B$31,"Receita") -> 81500 | F25: =SUMIFS(F5:F24,Config!$B$12:$B$31,"Receita") -> 84000 | G25: =SUMIFS(G5:G24,Config!$B$12:$B$31,"Receita") -> 86000 | H25: =SUMIFS(H5:H24,Config!$B$12:$B$31,"Receita") -> 90500 | I25: =SUMIFS(I5:I24,Config!$B$12:$B$31,"Receita") -> 90500 | ... N25: =SUMIFS(N5:N24,Config!$B$12:$B$31,"Receita") -> 1046500
A26: Despesas previstas | B26: =SUMIFS(B5:B24,Config!$B$12:$B$31,"Despesa") -> 65900 | C26: =SUMIFS(C5:C24,Config!$B$12:$B$31,"Despesa") -> 66100 | D26: =SUMIFS(D5:D24,Config!$B$12:$B$31,"Despesa") -> 71900 | E26: =SUMIFS(E5:E24,Config!$B$12:$B$31,"Despesa") -> 69800 | F26: =SUMIFS(F5:F24,Config!$B$12:$B$31,"Despesa") -> 69800 | G26: =SUMIFS(G5:G24,Config!$B$12:$B$31,"Despesa") -> 70000 | H26: =SUMIFS(H5:H24,Config!$B$12:$B$31,"Despesa") -> 76800 | I26: =SUMIFS(I5:I24,Config!$B$12:$B$31,"Despesa") -> 74800 | ... N26: =SUMIFS(N5:N24,Config!$B$12:$B$31,"Despesa") -> 869800
A27: Resultado previsto | B27: =B25-B26 -> 5100 | C27: =C25-C26 -> 7900 | D27: =D25-D26 -> 7600 | E27: =E25-E26 -> 11700 | F27: =F25-F26 -> 14200 | G27: =G25-G26 -> 16000 | H27: =H25-H26 -> 13700 | I27: =I25-I26 -> 15700 | ... N27: =N25-N26 -> 176700

Sheet Realizado
A1: Realizado
A2: Uma linha por lançamento real (ou o total do mês por categoria, se preferir). Mês e ano são calculados.
A4: Data | B4: Categoria | C4: Descrição | D4: Valor | E4: Observação | F4: Mês | G4: Ano | H4: Tipo
A5: 46027 | B5: Serviços · projetos | C5: Projetos faturados no mês | D5: 48873.54 | F5: =IF(A5="","",MONTH(A5)) -> 1 | G5: =IF(A5="","",YEAR(A5)) -> 2026 | H5: =IF(B5="","",IFERROR(INDEX(Config!$B$12:$B$31,MATCH(B5,Config!$A$12:$A$31,0)),"?")) -> Receita
A6: 46029 | B6: Serviços · mensalidades | C6: Contratos mensais | D6: 18424.96 | F6: =IF(A6="","",MONTH(A6)) -> 1 | G6: =IF(A6="","",YEAR(A6)) -> 2026 | H6: =IF(B6="","",IFERROR(INDEX(Config!$B$12:$B$31,MATCH(B6,Config!$A$12:$A$31,0)),"?")) -> Receita
A7: 46031 | B7: Produtos digitais | C7: Vendas de templates | D7: 1138.04 | F7: =IF(A7="","",MONTH(A7)) -> 1 | G7: =IF(A7="","",YEAR(A7)) -> 2026 | H7: =IF(B7="","",IFERROR(INDEX(Config!$B$12:$B$31,MATCH(B7,Config!$A$12:$A$31,0)),"?")) -> Receita
A8: 46033 | B8: Salários e pró-labore | C8: Folha do mês | D8: 38315.92 | F8: =IF(A8="","",MONTH(A8)) -> 1 | G8: =IF(A8="","",YEAR(A8)) -> 2026 | H8: =IF(B8="","",IFERROR(INDEX(Config!$B$12:$B$31,MATCH(B8,Config!$A$12:$A$31,0)),"?")) -> Despesa
A9: 46035 | B9: Freelancers | C9: Freelas de motion e redação | D9: 7393.62 | F9: =IF(A9="","",MONTH(A9)) -> 1 | G9: =IF(A9="","",YEAR(A9)) -> 2026 | H9: =IF(B9="","",IFERROR(INDEX(Config!$B$12:$B$31,MATCH(B9,Config!$A$12:$A$31,0)),"?")) -> Despesa
A10: 46037 | B10: Escritório e contas | C10: Aluguel, luz, internet | D10: 4175.64 | F10: =IF(A10="","",MONTH(A10)) -> 1 | G10: =IF(A10="","",YEAR(A10)) -> 2026 | H10: =IF(B10="","",IFERROR(INDEX(Config!$B$12:$B$31,MATCH(B10,Config!$A$12:$A$31,0)),"?")) -> Despesa
A11: 46039 | B11: Softwares e assinaturas | C11: Adobe, Google, Notion, hospedagem | D11: 2045.12 | F11: =IF(A11="","",MONTH(A11)) -> 1 | G11: =IF(A11="","",YEAR(A11)) -> 2026 | H11: =IF(B11="","",IFERROR(INDEX(Config!$B$12:$B$31,MATCH(B11,Config!$A$12:$A$31,0)),"?")) -> Despesa
A12: 46041 | B12: Marketing e mídia | C12: Impulsionamento e mídia paga | D12: 4005.29 | F12: =IF(A12="","",MONTH(A12)) -> 1 | G12: =IF(A12="","",YEAR(A12)) -> 2026 | H12: =IF(B12="","",IFERROR(INDEX(Config!$B$12:$B$31,MATCH(B12,Config!$A$12:$A$31,0)),"?")) -> Despesa
A13: 46043 | B13: Impostos | C13: DAS e retenções | D13: 8253 | F13: =IF(A13="","",MONTH(A13)) -> 1 | G13: =IF(A13="","",YEAR(A13)) -> 2026 | H13: =IF(B13="","",IFERROR(INDEX(Config!$B$12:$B$31,MATCH(B13,Config!$A$12:$A$31,0)),"?")) -> Despesa
A14: 46047 | B14: Treinamento | C14: Curso online | D14: 207.93 | F14: =IF(A14="","",MONTH(A14)) -> 1 | G14: =IF(A14="","",YEAR(A14)) -> 2026 | H14: =IF(B14="","",IFERROR(INDEX(Config!$B$12:$B$31,MATCH(B14,Config!$A$12:$A$31,0)),"?")) -> Despesa
A15: 46049 | B15: Viagens e eventos | C15: Deslocamentos a clientes | D15: 718.29 | F15: =IF(A15="","",MONTH(A15)) -> 1 | G15: =IF(A15="","",YEAR(A15)) -> 2026 | H15: =IF(B15="","",IFERROR(INDEX(Config!$B$12:$B$31,MATCH(B15,Config!$A$12:$A$31,0)),"?")) -> Despesa
A16: 46050 | B16: Reserva | C16: Transferência para a reserva | D16: 3080.75 | F16: =IF(A16="","",MONTH(A16)) -> 1 | G16: =IF(A16="","",YEAR(A16)) -> 2026 | H16: =IF(B16="","",IFERROR(INDEX(Config!$B$12:$B$31,MATCH(B16,Config!$A$12:$A$31,0)),"?")) -> Despesa
... A114: 46293 | B114: Reserva | C114: Transferência para a reserva | D114: 2884.81 | F114: =IF(A114="","",MONTH(A114)) -> 9 | G114: =IF(A114="","",YEAR(A114)) -> 2026 | H114: =IF(B114="","",IFERROR(INDEX(Config!$B$12:$B$31,MATCH(B114,Config!$A$12:$A$31,0)),"?")) -> Despesa
F115: =IF(A115="","",MONTH(A115)) | G115: =IF(A115="","",YEAR(A115)) | H115: =IF(B115="","",IFERROR(INDEX(Config!$B$12:$B$31,MATCH(B115,Config!$A$12:$A$31,0)),"?"))
F116: =IF(A116="","",MONTH(A116)) | G116: =IF(A116="","",YEAR(A116)) | H116: =IF(B116="","",IFERROR(INDEX(Config!$B$12:$B$31,MATCH(B116,Config!$A$12:$A$31,0)),"?"))
F117: =IF(A117="","",MONTH(A117)) | G117: =IF(A117="","",YEAR(A117)) | H117: =IF(B117="","",IFERROR(INDEX(Config!$B$12:$B$31,MATCH(B117,Config!$A$12:$A$31,0)),"?"))
F118: =IF(A118="","",MONTH(A118)) | G118: =IF(A118="","",YEAR(A118)) | H118: =IF(B118="","",IFERROR(INDEX(Config!$B$12:$B$31,MATCH(B118,Config!$A$12:$A$31,0)),"?"))
F119: =IF(A119="","",MONTH(A119)) | G119: =IF(A119="","",YEAR(A119)) | H119: =IF(B119="","",IFERROR(INDEX(Config!$B$12:$B$31,MATCH(B119,Config!$A$12:$A$31,0)),"?"))
F120: =IF(A120="","",MONTH(A120)) | G120: =IF(A120="","",YEAR(A120)) | H120: =IF(B120="","",IFERROR(INDEX(Config!$B$12:$B$31,MATCH(B120,Config!$A$12:$A$31,0)),"?"))
F121: =IF(A121="","",MONTH(A121)) | G121: =IF(A121="","",YEAR(A121)) | H121: =IF(B121="","",IFERROR(INDEX(Config!$B$12:$B$31,MATCH(B121,Config!$A$12:$A$31,0)),"?"))
F122: =IF(A122="","",MONTH(A122)) | G122: =IF(A122="","",YEAR(A122)) | H122: =IF(B122="","",IFERROR(INDEX(Config!$B$12:$B$31,MATCH(B122,Config!$A$12:$A$31,0)),"?"))
F123: =IF(A123="","",MONTH(A123)) | G123: =IF(A123="","",YEAR(A123)) | H123: =IF(B123="","",IFERROR(INDEX(Config!$B$12:$B$31,MATCH(B123,Config!$A$12:$A$31,0)),"?"))
F124: =IF(A124="","",MONTH(A124)) | G124: =IF(A124="","",YEAR(A124)) | H124: =IF(B124="","",IFERROR(INDEX(Config!$B$12:$B$31,MATCH(B124,Config!$A$12:$A$31,0)),"?"))
F125: =IF(A125="","",MONTH(A125)) | G125: =IF(A125="","",YEAR(A125)) | H125: =IF(B125="","",IFERROR(INDEX(Config!$B$12:$B$31,MATCH(B125,Config!$A$12:$A$31,0)),"?"))
F126: =IF(A126="","",MONTH(A126)) | G126: =IF(A126="","",YEAR(A126)) | H126: =IF(B126="","",IFERROR(INDEX(Config!$B$12:$B$31,MATCH(B126,Config!$A$12:$A$31,0)),"?"))
... F604: =IF(A604="","",MONTH(A604)) | G604: =IF(A604="","",YEAR(A604)) | H604: =IF(B604="","",IFERROR(INDEX(Config!$B$12:$B$31,MATCH(B604,Config!$A$12:$A$31,0)),"?"))
