Workbook

Sheet Como usar
A1: Tabela de referência de honorários
A2: Kit de Gestão para Advogados · Seu Sócio Gestor · versão 1.0 (setembro de 2026)
A4: O que esta planilha faz | B4: Cria a tabela interna de honorários do escritório: para cada área e tipo de serviço, uma faixa mínima e máxima calculada do custo-hora, com horas típicas e modalidade recomendada. Depois compara o que já está contratado com essa referência e aponta os casos abaixo do mínimo.
A5: Passo 1 | B5: Em Config, o custo-hora (da planilha 05), impostos, as margens mínima e alvo e a folga para horas não previstas. Isso vira a hora mínima com folga e a hora alvo com folga: a hora mínima da 05 (R$ 110 no exemplo) acrescida de 20 % de horas não previstas (R$ 127,88).
A6: Passo 2 | B6: Em Referência, ajuste as horas típicas (de e até) e a modalidade de cada linha. Adicione linhas para os serviços que o escritório faz. A faixa em reais é calculada.
A7: Passo 3 | B7: Em Nossos casos, uma linha por caso com valor contratado e horas estimadas. A situação mostra se está abaixo do mínimo, na faixa ou acima do alvo.
A8: Passo 4 | B8: No topo de Referência: quantos casos estão abaixo do mínimo, quanto falta e o valor por hora médio por área. Use a faixa ao montar a proposta (planilha 07).
A9: Rotina | B9: Revise a tabela a cada trimestre, junto com o custo-hora. Antes de aceitar caso novo, confira a faixa.
A10: Com a IA | B10: Copie "O que cobramos hoje, por área" e use o prompt "Honorários 06 · Montar a tabela de referência interna" da biblioteca do kit para apontar onde o escritório está cobrando abaixo do custo e sugerir uma conversa de reajuste. Os valores da tabela são do seu escritório, não uma tabela oficial.
A11: Legenda | B11: Células amarelas: você preenche. Brancas: calculadas. Não é preciso mexer em nada fora do amarelo.
A12: Proteção | B12: Fórmulas protegidas sem senha. Para editar: Revisar > Desproteger planilha (Excel) ou Dados > Proteger intervalos (Google Sheets).
A13: Requisitos | B13: Excel 2016 ou mais novo, Microsoft 365 ou Google Sheets (só funções do Excel 2007+; nada de MÍNIMOSES, MÁXIMOSES ou UNIRTEXTO). No celular abre nos aplicativos; para preencher, use o computador.
A14: Google Sheets | B14: Faça upload no Google Drive e abra com o Google Sheets. Fórmulas, listas, cores, semáforos e gráficos funcionam: as regras de cor que dependem do mês escolhido em Config usam INDIRECT, que é a forma que o Sheets aceita para regra condicional apontar para outra aba.
A15: Exemplos | B15: Ferraz & Lima Advocacia é um escritório fictício. Clientes, processos, nomes e valores são inventados. Apague-os antes de começar.
... A17: Suporte | B17: suporte@seusociogestor.com.br · resposta em até 5 dias úteis · reembolso em até 7 dias pelo mesmo canal.

Sheet Referência
A1: =Config!$B$4&" · Tabela de referência de honorários · "&Config!$B$5 -> Ferraz & Lima Advocacia (exemplo fictício) · Tabela de referência de honorários · Setembro de 2026
A2: Tabela interna: faixa de valor por área e tipo de serviço, calculada do custo-hora. Amarelo: horas típicas e modalidade. Abaixo, o que cobramos hoje contra a referência.
A4: Hora mínima com folga | C4: Hora alvo com folga | E4: Casos abaixo do mínimo | G4: Falta até o mínimo | I4: Valor por hora médio
A5: =Config!$B$12 -> 127.88013 | C5: =Config!$B$13 -> 168.69294 | E5: =IF(NOT(ISNUMBER(Config!$B$12)),Config!$B$12,IF(SUMPRODUCT(((('Nossos casos'!$A$5:$A$204<>"")+('Nossos casos'!$C$5:$C$204<>"")+('Nossos casos'!$F$5:$F$204<>"")+('Nossos casos'!$G$5:$G$204<>"")>0)*((('Nossos casos'!$A$5:$A$204="")+(ISNUMBER(MATCH('Nossos casos'!$C$5:$C$204,Config!$E$16:$E$35,0))=FALSE)+(ISNUMBER('Nossos casos'!$F$5:$F$204)=FALSE)+ISNUMBER('Nossos casos'!$F$5:$F$204)*('Nossos casos'!$F$5:$F$204<0)+(ISNUMBER('Nossos casos'!$G$5:$G$204)=FALSE)+ISNUMBER('Nossos casos'!$G$5:$G$204)*('Nossos casos'!$G$5:$G$204<0))>0)))>0,SUMPRODUCT(((('Nossos casos'!$A$5:$A$204<>"")+('Nossos casos'!$C$5:$C$204<>"")+('Nossos casos'!$F$5:$F$204<>"")+('Nossos casos'!$G$5:$G$204<>"")>0)*((('Nossos casos'!$A$5:$A$204="")+(ISNUMBER(MATCH('Nossos casos'!$C$5:$C$204,Config!$E$16:$E$35,0))=FALSE)+(ISNUMBER('Nossos casos'!$F$5:$F$204)=FALSE)+ISNUMBER('Nossos casos'!$F$5:$F$204)*('Nossos casos'!$F$5:$F$204<0)+(ISNUMBER('Nossos casos'!$G$5:$G$204)=FALSE)+ISNUMBER('Nossos casos'!$G$5:$G$204)*('Nossos casos'!$G$5:$G$204<0))>0)))&" caso(s) incompletos (nº, área, valor ou horas)",COUNTIF('Nossos casos'!$J$5:$J$204,"Abaixo do mínimo")&" de "&(COUNTIF('Nossos casos'!$J$5:$J$204,"Abaixo do mínimo")+COUNTIF('Nossos casos'!$J$5:$J$204,"Na faixa")+COUNTIF('Nossos casos'!$J$5:$J$204,"Acima do alvo")))) -> 10 de 38 | G5: =IF(NOT(ISNUMBER(Config!$B$12)),Config!$B$12,IF(SUMPRODUCT(((('Nossos casos'!$A$5:$A$204<>"")+('Nossos casos'!$C$5:$C$204<>"")+('Nossos casos'!$F$5:$F$204<>"")+('Nossos casos'!$G$5:$G$204<>"")>0)*((('Nossos casos'!$A$5:$A$204="")+(ISNUMBER(MATCH('Nossos casos'!$C$5:$C$204,Config!$E$16:$E$35,0))=FALSE)+(ISNUMBER('Nossos casos'!$F$5:$F$204)=FALSE)+ISNUMBER('Nossos casos'!$F$5:$F$204)*('Nossos casos'!$F$5:$F$204<0)+(ISNUMBER('Nossos casos'!$G$5:$G$204)=FALSE)+ISNUMBER('Nossos casos'!$G$5:$G$204)*('Nossos casos'!$G$5:$G$204<0))>0)))>0,SUMPRODUCT(((('Nossos casos'!$A$5:$A$204<>"")+('Nossos casos'!$C$5:$C$204<>"")+('Nossos casos'!$F$5:$F$204<>"")+('Nossos casos'!$G$5:$G$204<>"")>0)*((('Nossos casos'!$A$5:$A$204="")+(ISNUMBER(MATCH('Nossos casos'!$C$5:$C$204,Config!$E$16:$E$35,0))=FALSE)+(ISNUMBER('Nossos casos'!$F$5:$F$204)=FALSE)+ISNUMBER('Nossos casos'!$F$5:$F$204)*('Nossos casos'!$F$5:$F$204<0)+(ISNUMBER('Nossos casos'!$G$5:$G$204)=FALSE)+ISNUMBER('Nossos casos'!$G$5:$G$204)*('Nossos casos'!$G$5:$G$204<0))>0)))&" caso(s) incompletos (nº, área, valor ou horas)",SUM('Nossos casos'!$K$5:$K$204))) -> 11876.69 | I5: =IF(SUMPRODUCT(((('Nossos casos'!$A$5:$A$204<>"")+('Nossos casos'!$C$5:$C$204<>"")+('Nossos casos'!$F$5:$F$204<>"")+('Nossos casos'!$G$5:$G$204<>"")>0)*((('Nossos casos'!$A$5:$A$204="")+(ISNUMBER(MATCH('Nossos casos'!$C$5:$C$204,Config!$E$16:$E$35,0))=FALSE)+(ISNUMBER('Nossos casos'!$F$5:$F$204)=FALSE)+ISNUMBER('Nossos casos'!$F$5:$F$204)*('Nossos casos'!$F$5:$F$204<0)+(ISNUMBER('Nossos casos'!$G$5:$G$204)=FALSE)+ISNUMBER('Nossos casos'!$G$5:$G$204)*('Nossos casos'!$G$5:$G$204<0))>0)))>0,SUMPRODUCT(((('Nossos casos'!$A$5:$A$204<>"")+('Nossos casos'!$C$5:$C$204<>"")+('Nossos casos'!$F$5:$F$204<>"")+('Nossos casos'!$G$5:$G$204<>"")>0)*((('Nossos casos'!$A$5:$A$204="")+(ISNUMBER(MATCH('Nossos casos'!$C$5:$C$204,Config!$E$16:$E$35,0))=FALSE)+(ISNUMBER('Nossos casos'!$F$5:$F$204)=FALSE)+ISNUMBER('Nossos casos'!$F$5:$F$204)*('Nossos casos'!$F$5:$F$204<0)+(ISNUMBER('Nossos casos'!$G$5:$G$204)=FALSE)+ISNUMBER('Nossos casos'!$G$5:$G$204)*('Nossos casos'!$G$5:$G$204<0))>0)))&" caso(s) incompletos (nº, área, valor ou horas)",IFERROR(SUM('Nossos casos'!$F$5:$F$204)/SUM('Nossos casos'!$G$5:$G$204),"")) -> 153.3147
A7: Faixa de referência por área e tipo de serviço
A8: Área | B8: Tipo de serviço | C8: Horas típicas · de | D8: Horas típicas · até | E8: Modalidade recomendada | F8: Mínimo (R$) | G8: Máximo (R$) | H8: Ponto médio (R$) | I8: Como usar a faixa
A9: Cível | B9: Consultoria pontual | C9: 3 | D9: 8 | E9: Fixo | F9: =IF(OR(A9="",C9=""),"",IF(NOT(IF(ISNUMBER(C9),C9>=0,FALSE)),"horas inválidas",IF(ISNUMBER(Config!$B$12),C9*Config!$B$12,Config!$B$12))) -> 383.64039 | G9: =IF(OR(A9="",D9=""),"",IF(NOT(IF(ISNUMBER(D9),D9>=0,FALSE)),"horas inválidas",IF(ISNUMBER(Config!$B$13),D9*Config!$B$13,Config!$B$13))) -> 1349.5435 | H9: =IF(OR(NOT(ISNUMBER(F9)),NOT(ISNUMBER(G9))),"",(F9+G9)/2) -> 866.59194 | I9: =IF(A9="","",IF(E9="Hora","Cobre a hora entre a mínima e a alvo; a faixa é o total esperado",IF(E9="Êxito","Percentual que, na chance esperada, fique dentro da faixa",IF(E9="Misto","Entrada perto do mínimo; o êxito leva ao máximo","Caso simples perto do mínimo; complexo perto do máximo")))) -> Caso simples perto do mínimo; complexo perto do máximo
A10: Cível | B10: Contrato ou documento | C10: 6 | D10: 15 | E10: Fixo | F10: =IF(OR(A10="",C10=""),"",IF(NOT(IF(ISNUMBER(C10),C10>=0,FALSE)),"horas inválidas",IF(ISNUMBER(Config!$B$12),C10*Config!$B$12,Config!$B$12))) -> 767.28077 | G10: =IF(OR(A10="",D10=""),"",IF(NOT(IF(ISNUMBER(D10),D10>=0,FALSE)),"horas inválidas",IF(ISNUMBER(Config!$B$13),D10*Config!$B$13,Config!$B$13))) -> 2530.394 | H10: =IF(OR(NOT(ISNUMBER(F10)),NOT(ISNUMBER(G10))),"",(F10+G10)/2) -> 1648.8374 | I10: =IF(A10="","",IF(E10="Hora","Cobre a hora entre a mínima e a alvo; a faixa é o total esperado",IF(E10="Êxito","Percentual que, na chance esperada, fique dentro da faixa",IF(E10="Misto","Entrada perto do mínimo; o êxito leva ao máximo","Caso simples perto do mínimo; complexo perto do máximo")))) -> Caso simples perto do mínimo; complexo perto do máximo
A11: Cível | B11: Processo completo | C11: 50 | D11: 100 | E11: Misto | F11: =IF(OR(A11="",C11=""),"",IF(NOT(IF(ISNUMBER(C11),C11>=0,FALSE)),"horas inválidas",IF(ISNUMBER(Config!$B$12),C11*Config!$B$12,Config!$B$12))) -> 6394.0065 | G11: =IF(OR(A11="",D11=""),"",IF(NOT(IF(ISNUMBER(D11),D11>=0,FALSE)),"horas inválidas",IF(ISNUMBER(Config!$B$13),D11*Config!$B$13,Config!$B$13))) -> 16869.294 | H11: =IF(OR(NOT(ISNUMBER(F11)),NOT(ISNUMBER(G11))),"",(F11+G11)/2) -> 11631.65 | I11: =IF(A11="","",IF(E11="Hora","Cobre a hora entre a mínima e a alvo; a faixa é o total esperado",IF(E11="Êxito","Percentual que, na chance esperada, fique dentro da faixa",IF(E11="Misto","Entrada perto do mínimo; o êxito leva ao máximo","Caso simples perto do mínimo; complexo perto do máximo")))) -> Entrada perto do mínimo; o êxito leva ao máximo
A12: Cível | B12: Recurso | C12: 15 | D12: 35 | E12: Fixo | F12: =IF(OR(A12="",C12=""),"",IF(NOT(IF(ISNUMBER(C12),C12>=0,FALSE)),"horas inválidas",IF(ISNUMBER(Config!$B$12),C12*Config!$B$12,Config!$B$12))) -> 1918.2019 | G12: =IF(OR(A12="",D12=""),"",IF(NOT(IF(ISNUMBER(D12),D12>=0,FALSE)),"horas inválidas",IF(ISNUMBER(Config!$B$13),D12*Config!$B$13,Config!$B$13))) -> 5904.2528 | H12: =IF(OR(NOT(ISNUMBER(F12)),NOT(ISNUMBER(G12))),"",(F12+G12)/2) -> 3911.2274 | I12: =IF(A12="","",IF(E12="Hora","Cobre a hora entre a mínima e a alvo; a faixa é o total esperado",IF(E12="Êxito","Percentual que, na chance esperada, fique dentro da faixa",IF(E12="Misto","Entrada perto do mínimo; o êxito leva ao máximo","Caso simples perto do mínimo; complexo perto do máximo")))) -> Caso simples perto do mínimo; complexo perto do máximo
A13: Cível | B13: Acordo e negociação | C13: 8 | D13: 25 | E13: Misto | F13: =IF(OR(A13="",C13=""),"",IF(NOT(IF(ISNUMBER(C13),C13>=0,FALSE)),"horas inválidas",IF(ISNUMBER(Config!$B$12),C13*Config!$B$12,Config!$B$12))) -> 1023.041 | G13: =IF(OR(A13="",D13=""),"",IF(NOT(IF(ISNUMBER(D13),D13>=0,FALSE)),"horas inválidas",IF(ISNUMBER(Config!$B$13),D13*Config!$B$13,Config!$B$13))) -> 4217.3234 | H13: =IF(OR(NOT(ISNUMBER(F13)),NOT(ISNUMBER(G13))),"",(F13+G13)/2) -> 2620.1822 | I13: =IF(A13="","",IF(E13="Hora","Cobre a hora entre a mínima e a alvo; a faixa é o total esperado",IF(E13="Êxito","Percentual que, na chance esperada, fique dentro da faixa",IF(E13="Misto","Entrada perto do mínimo; o êxito leva ao máximo","Caso simples perto do mínimo; complexo perto do máximo")))) -> Entrada perto do mínimo; o êxito leva ao máximo
A14: Trabalhista | B14: Consultoria pontual | C14: 3 | D14: 8 | E14: Fixo | F14: =IF(OR(A14="",C14=""),"",IF(NOT(IF(ISNUMBER(C14),C14>=0,FALSE)),"horas inválidas",IF(ISNUMBER(Config!$B$12),C14*Config!$B$12,Config!$B$12))) -> 383.64039 | G14: =IF(OR(A14="",D14=""),"",IF(NOT(IF(ISNUMBER(D14),D14>=0,FALSE)),"horas inválidas",IF(ISNUMBER(Config!$B$13),D14*Config!$B$13,Config!$B$13))) -> 1349.5435 | H14: =IF(OR(NOT(ISNUMBER(F14)),NOT(ISNUMBER(G14))),"",(F14+G14)/2) -> 866.59194 | I14: =IF(A14="","",IF(E14="Hora","Cobre a hora entre a mínima e a alvo; a faixa é o total esperado",IF(E14="Êxito","Percentual que, na chance esperada, fique dentro da faixa",IF(E14="Misto","Entrada perto do mínimo; o êxito leva ao máximo","Caso simples perto do mínimo; complexo perto do máximo")))) -> Caso simples perto do mínimo; complexo perto do máximo
A15: Trabalhista | B15: Contrato ou documento | C15: 6 | D15: 15 | E15: Fixo | F15: =IF(OR(A15="",C15=""),"",IF(NOT(IF(ISNUMBER(C15),C15>=0,FALSE)),"horas inválidas",IF(ISNUMBER(Config!$B$12),C15*Config!$B$12,Config!$B$12))) -> 767.28077 | G15: =IF(OR(A15="",D15=""),"",IF(NOT(IF(ISNUMBER(D15),D15>=0,FALSE)),"horas inválidas",IF(ISNUMBER(Config!$B$13),D15*Config!$B$13,Config!$B$13))) -> 2530.394 | H15: =IF(OR(NOT(ISNUMBER(F15)),NOT(ISNUMBER(G15))),"",(F15+G15)/2) -> 1648.8374 | I15: =IF(A15="","",IF(E15="Hora","Cobre a hora entre a mínima e a alvo; a faixa é o total esperado",IF(E15="Êxito","Percentual que, na chance esperada, fique dentro da faixa",IF(E15="Misto","Entrada perto do mínimo; o êxito leva ao máximo","Caso simples perto do mínimo; complexo perto do máximo")))) -> Caso simples perto do mínimo; complexo perto do máximo
A16: Trabalhista | B16: Processo completo | C16: 35 | D16: 70 | E16: Êxito | F16: =IF(OR(A16="",C16=""),"",IF(NOT(IF(ISNUMBER(C16),C16>=0,FALSE)),"horas inválidas",IF(ISNUMBER(Config!$B$12),C16*Config!$B$12,Config!$B$12))) -> 4475.8045 | G16: =IF(OR(A16="",D16=""),"",IF(NOT(IF(ISNUMBER(D16),D16>=0,FALSE)),"horas inválidas",IF(ISNUMBER(Config!$B$13),D16*Config!$B$13,Config!$B$13))) -> 11808.506 | H16: =IF(OR(NOT(ISNUMBER(F16)),NOT(ISNUMBER(G16))),"",(F16+G16)/2) -> 8142.155 | I16: =IF(A16="","",IF(E16="Hora","Cobre a hora entre a mínima e a alvo; a faixa é o total esperado",IF(E16="Êxito","Percentual que, na chance esperada, fique dentro da faixa",IF(E16="Misto","Entrada perto do mínimo; o êxito leva ao máximo","Caso simples perto do mínimo; complexo perto do máximo")))) -> Percentual que, na chance esperada, fique dentro da faixa
A17: Trabalhista | B17: Recurso | C17: 15 | D17: 35 | E17: Fixo | F17: =IF(OR(A17="",C17=""),"",IF(NOT(IF(ISNUMBER(C17),C17>=0,FALSE)),"horas inválidas",IF(ISNUMBER(Config!$B$12),C17*Config!$B$12,Config!$B$12))) -> 1918.2019 | G17: =IF(OR(A17="",D17=""),"",IF(NOT(IF(ISNUMBER(D17),D17>=0,FALSE)),"horas inválidas",IF(ISNUMBER(Config!$B$13),D17*Config!$B$13,Config!$B$13))) -> 5904.2528 | H17: =IF(OR(NOT(ISNUMBER(F17)),NOT(ISNUMBER(G17))),"",(F17+G17)/2) -> 3911.2274 | I17: =IF(A17="","",IF(E17="Hora","Cobre a hora entre a mínima e a alvo; a faixa é o total esperado",IF(E17="Êxito","Percentual que, na chance esperada, fique dentro da faixa",IF(E17="Misto","Entrada perto do mínimo; o êxito leva ao máximo","Caso simples perto do mínimo; complexo perto do máximo")))) -> Caso simples perto do mínimo; complexo perto do máximo
A18: Trabalhista | B18: Acordo e negociação | C18: 8 | D18: 25 | E18: Misto | F18: =IF(OR(A18="",C18=""),"",IF(NOT(IF(ISNUMBER(C18),C18>=0,FALSE)),"horas inválidas",IF(ISNUMBER(Config!$B$12),C18*Config!$B$12,Config!$B$12))) -> 1023.041 | G18: =IF(OR(A18="",D18=""),"",IF(NOT(IF(ISNUMBER(D18),D18>=0,FALSE)),"horas inválidas",IF(ISNUMBER(Config!$B$13),D18*Config!$B$13,Config!$B$13))) -> 4217.3234 | H18: =IF(OR(NOT(ISNUMBER(F18)),NOT(ISNUMBER(G18))),"",(F18+G18)/2) -> 2620.1822 | I18: =IF(A18="","",IF(E18="Hora","Cobre a hora entre a mínima e a alvo; a faixa é o total esperado",IF(E18="Êxito","Percentual que, na chance esperada, fique dentro da faixa",IF(E18="Misto","Entrada perto do mínimo; o êxito leva ao máximo","Caso simples perto do mínimo; complexo perto do máximo")))) -> Entrada perto do mínimo; o êxito leva ao máximo
A19: Previdenciário | B19: Consultoria pontual | C19: 3 | D19: 8 | E19: Fixo | F19: =IF(OR(A19="",C19=""),"",IF(NOT(IF(ISNUMBER(C19),C19>=0,FALSE)),"horas inválidas",IF(ISNUMBER(Config!$B$12),C19*Config!$B$12,Config!$B$12))) -> 383.64039 | G19: =IF(OR(A19="",D19=""),"",IF(NOT(IF(ISNUMBER(D19),D19>=0,FALSE)),"horas inválidas",IF(ISNUMBER(Config!$B$13),D19*Config!$B$13,Config!$B$13))) -> 1349.5435 | H19: =IF(OR(NOT(ISNUMBER(F19)),NOT(ISNUMBER(G19))),"",(F19+G19)/2) -> 866.59194 | I19: =IF(A19="","",IF(E19="Hora","Cobre a hora entre a mínima e a alvo; a faixa é o total esperado",IF(E19="Êxito","Percentual que, na chance esperada, fique dentro da faixa",IF(E19="Misto","Entrada perto do mínimo; o êxito leva ao máximo","Caso simples perto do mínimo; complexo perto do máximo")))) -> Caso simples perto do mínimo; complexo perto do máximo
A20: Previdenciário | B20: Contrato ou documento | C20: 6 | D20: 15 | E20: Fixo | F20: =IF(OR(A20="",C20=""),"",IF(NOT(IF(ISNUMBER(C20),C20>=0,FALSE)),"horas inválidas",IF(ISNUMBER(Config!$B$12),C20*Config!$B$12,Config!$B$12))) -> 767.28077 | G20: =IF(OR(A20="",D20=""),"",IF(NOT(IF(ISNUMBER(D20),D20>=0,FALSE)),"horas inválidas",IF(ISNUMBER(Config!$B$13),D20*Config!$B$13,Config!$B$13))) -> 2530.394 | H20: =IF(OR(NOT(ISNUMBER(F20)),NOT(ISNUMBER(G20))),"",(F20+G20)/2) -> 1648.8374 | I20: =IF(A20="","",IF(E20="Hora","Cobre a hora entre a mínima e a alvo; a faixa é o total esperado",IF(E20="Êxito","Percentual que, na chance esperada, fique dentro da faixa",IF(E20="Misto","Entrada perto do mínimo; o êxito leva ao máximo","Caso simples perto do mínimo; complexo perto do máximo")))) -> Caso simples perto do mínimo; complexo perto do máximo
... A33: Família | B33: Acordo e negociação | C33: 8 | D33: 25 | E33: Misto | F33: =IF(OR(A33="",C33=""),"",IF(NOT(IF(ISNUMBER(C33),C33>=0,FALSE)),"horas inválidas",IF(ISNUMBER(Config!$B$12),C33*Config!$B$12,Config!$B$12))) -> 1023.041 | G33: =IF(OR(A33="",D33=""),"",IF(NOT(IF(ISNUMBER(D33),D33>=0,FALSE)),"horas inválidas",IF(ISNUMBER(Config!$B$13),D33*Config!$B$13,Config!$B$13))) -> 4217.3234 | H33: =IF(OR(NOT(ISNUMBER(F33)),NOT(ISNUMBER(G33))),"",(F33+G33)/2) -> 2620.1822 | I33: =IF(A33="","",IF(E33="Hora","Cobre a hora entre a mínima e a alvo; a faixa é o total esperado",IF(E33="Êxito","Percentual que, na chance esperada, fique dentro da faixa",IF(E33="Misto","Entrada perto do mínimo; o êxito leva ao máximo","Caso simples perto do mínimo; complexo perto do máximo")))) -> Entrada perto do mínimo; o êxito leva ao máximo
F34: =IF(OR(A34="",C34=""),"",IF(NOT(IF(ISNUMBER(C34),C34>=0,FALSE)),"horas inválidas",IF(ISNUMBER(Config!$B$12),C34*Config!$B$12,Config!$B$12))) | G34: =IF(OR(A34="",D34=""),"",IF(NOT(IF(ISNUMBER(D34),D34>=0,FALSE)),"horas inválidas",IF(ISNUMBER(Config!$B$13),D34*Config!$B$13,Config!$B$13))) | H34: =IF(OR(NOT(ISNUMBER(F34)),NOT(ISNUMBER(G34))),"",(F34+G34)/2) | I34: =IF(A34="","",IF(E34="Hora","Cobre a hora entre a mínima e a alvo; a faixa é o total esperado",IF(E34="Êxito","Percentual que, na chance esperada, fique dentro da faixa",IF(E34="Misto","Entrada perto do mínimo; o êxito leva ao máximo","Caso simples perto do mínimo; complexo perto do máximo"))))
F35: =IF(OR(A35="",C35=""),"",IF(NOT(IF(ISNUMBER(C35),C35>=0,FALSE)),"horas inválidas",IF(ISNUMBER(Config!$B$12),C35*Config!$B$12,Config!$B$12))) | G35: =IF(OR(A35="",D35=""),"",IF(NOT(IF(ISNUMBER(D35),D35>=0,FALSE)),"horas inválidas",IF(ISNUMBER(Config!$B$13),D35*Config!$B$13,Config!$B$13))) | H35: =IF(OR(NOT(ISNUMBER(F35)),NOT(ISNUMBER(G35))),"",(F35+G35)/2) | I35: =IF(A35="","",IF(E35="Hora","Cobre a hora entre a mínima e a alvo; a faixa é o total esperado",IF(E35="Êxito","Percentual que, na chance esperada, fique dentro da faixa",IF(E35="Misto","Entrada perto do mínimo; o êxito leva ao máximo","Caso simples perto do mínimo; complexo perto do máximo"))))
F36: =IF(OR(A36="",C36=""),"",IF(NOT(IF(ISNUMBER(C36),C36>=0,FALSE)),"horas inválidas",IF(ISNUMBER(Config!$B$12),C36*Config!$B$12,Config!$B$12))) | G36: =IF(OR(A36="",D36=""),"",IF(NOT(IF(ISNUMBER(D36),D36>=0,FALSE)),"horas inválidas",IF(ISNUMBER(Config!$B$13),D36*Config!$B$13,Config!$B$13))) | H36: =IF(OR(NOT(ISNUMBER(F36)),NOT(ISNUMBER(G36))),"",(F36+G36)/2) | I36: =IF(A36="","",IF(E36="Hora","Cobre a hora entre a mínima e a alvo; a faixa é o total esperado",IF(E36="Êxito","Percentual que, na chance esperada, fique dentro da faixa",IF(E36="Misto","Entrada perto do mínimo; o êxito leva ao máximo","Caso simples perto do mínimo; complexo perto do máximo"))))
F37: =IF(OR(A37="",C37=""),"",IF(NOT(IF(ISNUMBER(C37),C37>=0,FALSE)),"horas inválidas",IF(ISNUMBER(Config!$B$12),C37*Config!$B$12,Config!$B$12))) | G37: =IF(OR(A37="",D37=""),"",IF(NOT(IF(ISNUMBER(D37),D37>=0,FALSE)),"horas inválidas",IF(ISNUMBER(Config!$B$13),D37*Config!$B$13,Config!$B$13))) | H37: =IF(OR(NOT(ISNUMBER(F37)),NOT(ISNUMBER(G37))),"",(F37+G37)/2) | I37: =IF(A37="","",IF(E37="Hora","Cobre a hora entre a mínima e a alvo; a faixa é o total esperado",IF(E37="Êxito","Percentual que, na chance esperada, fique dentro da faixa",IF(E37="Misto","Entrada perto do mínimo; o êxito leva ao máximo","Caso simples perto do mínimo; complexo perto do máximo"))))
F38: =IF(OR(A38="",C38=""),"",IF(NOT(IF(ISNUMBER(C38),C38>=0,FALSE)),"horas inválidas",IF(ISNUMBER(Config!$B$12),C38*Config!$B$12,Config!$B$12))) | G38: =IF(OR(A38="",D38=""),"",IF(NOT(IF(ISNUMBER(D38),D38>=0,FALSE)),"horas inválidas",IF(ISNUMBER(Config!$B$13),D38*Config!$B$13,Config!$B$13))) | H38: =IF(OR(NOT(ISNUMBER(F38)),NOT(ISNUMBER(G38))),"",(F38+G38)/2) | I38: =IF(A38="","",IF(E38="Hora","Cobre a hora entre a mínima e a alvo; a faixa é o total esperado",IF(E38="Êxito","Percentual que, na chance esperada, fique dentro da faixa",IF(E38="Misto","Entrada perto do mínimo; o êxito leva ao máximo","Caso simples perto do mínimo; complexo perto do máximo"))))
F39: =IF(OR(A39="",C39=""),"",IF(NOT(IF(ISNUMBER(C39),C39>=0,FALSE)),"horas inválidas",IF(ISNUMBER(Config!$B$12),C39*Config!$B$12,Config!$B$12))) | G39: =IF(OR(A39="",D39=""),"",IF(NOT(IF(ISNUMBER(D39),D39>=0,FALSE)),"horas inválidas",IF(ISNUMBER(Config!$B$13),D39*Config!$B$13,Config!$B$13))) | H39: =IF(OR(NOT(ISNUMBER(F39)),NOT(ISNUMBER(G39))),"",(F39+G39)/2) | I39: =IF(A39="","",IF(E39="Hora","Cobre a hora entre a mínima e a alvo; a faixa é o total esperado",IF(E39="Êxito","Percentual que, na chance esperada, fique dentro da faixa",IF(E39="Misto","Entrada perto do mínimo; o êxito leva ao máximo","Caso simples perto do mínimo; complexo perto do máximo"))))
F40: =IF(OR(A40="",C40=""),"",IF(NOT(IF(ISNUMBER(C40),C40>=0,FALSE)),"horas inválidas",IF(ISNUMBER(Config!$B$12),C40*Config!$B$12,Config!$B$12))) | G40: =IF(OR(A40="",D40=""),"",IF(NOT(IF(ISNUMBER(D40),D40>=0,FALSE)),"horas inválidas",IF(ISNUMBER(Config!$B$13),D40*Config!$B$13,Config!$B$13))) | H40: =IF(OR(NOT(ISNUMBER(F40)),NOT(ISNUMBER(G40))),"",(F40+G40)/2) | I40: =IF(A40="","",IF(E40="Hora","Cobre a hora entre a mínima e a alvo; a faixa é o total esperado",IF(E40="Êxito","Percentual que, na chance esperada, fique dentro da faixa",IF(E40="Misto","Entrada perto do mínimo; o êxito leva ao máximo","Caso simples perto do mínimo; complexo perto do máximo"))))
F41: =IF(OR(A41="",C41=""),"",IF(NOT(IF(ISNUMBER(C41),C41>=0,FALSE)),"horas inválidas",IF(ISNUMBER(Config!$B$12),C41*Config!$B$12,Config!$B$12))) | G41: =IF(OR(A41="",D41=""),"",IF(NOT(IF(ISNUMBER(D41),D41>=0,FALSE)),"horas inválidas",IF(ISNUMBER(Config!$B$13),D41*Config!$B$13,Config!$B$13))) | H41: =IF(OR(NOT(ISNUMBER(F41)),NOT(ISNUMBER(G41))),"",(F41+G41)/2) | I41: =IF(A41="","",IF(E41="Hora","Cobre a hora entre a mínima e a alvo; a faixa é o total esperado",IF(E41="Êxito","Percentual que, na chance esperada, fique dentro da faixa",IF(E41="Misto","Entrada perto do mínimo; o êxito leva ao máximo","Caso simples perto do mínimo; complexo perto do máximo"))))
F42: =IF(OR(A42="",C42=""),"",IF(NOT(IF(ISNUMBER(C42),C42>=0,FALSE)),"horas inválidas",IF(ISNUMBER(Config!$B$12),C42*Config!$B$12,Config!$B$12))) | G42: =IF(OR(A42="",D42=""),"",IF(NOT(IF(ISNUMBER(D42),D42>=0,FALSE)),"horas inválidas",IF(ISNUMBER(Config!$B$13),D42*Config!$B$13,Config!$B$13))) | H42: =IF(OR(NOT(ISNUMBER(F42)),NOT(ISNUMBER(G42))),"",(F42+G42)/2) | I42: =IF(A42="","",IF(E42="Hora","Cobre a hora entre a mínima e a alvo; a faixa é o total esperado",IF(E42="Êxito","Percentual que, na chance esperada, fique dentro da faixa",IF(E42="Misto","Entrada perto do mínimo; o êxito leva ao máximo","Caso simples perto do mínimo; complexo perto do máximo"))))
F43: =IF(OR(A43="",C43=""),"",IF(NOT(IF(ISNUMBER(C43),C43>=0,FALSE)),"horas inválidas",IF(ISNUMBER(Config!$B$12),C43*Config!$B$12,Config!$B$12))) | G43: =IF(OR(A43="",D43=""),"",IF(NOT(IF(ISNUMBER(D43),D43>=0,FALSE)),"horas inválidas",IF(ISNUMBER(Config!$B$13),D43*Config!$B$13,Config!$B$13))) | H43: =IF(OR(NOT(ISNUMBER(F43)),NOT(ISNUMBER(G43))),"",(F43+G43)/2) | I43: =IF(A43="","",IF(E43="Hora","Cobre a hora entre a mínima e a alvo; a faixa é o total esperado",IF(E43="Êxito","Percentual que, na chance esperada, fique dentro da faixa",IF(E43="Misto","Entrada perto do mínimo; o êxito leva ao máximo","Caso simples perto do mínimo; complexo perto do máximo"))))
F44: =IF(OR(A44="",C44=""),"",IF(NOT(IF(ISNUMBER(C44),C44>=0,FALSE)),"horas inválidas",IF(ISNUMBER(Config!$B$12),C44*Config!$B$12,Config!$B$12))) | G44: =IF(OR(A44="",D44=""),"",IF(NOT(IF(ISNUMBER(D44),D44>=0,FALSE)),"horas inválidas",IF(ISNUMBER(Config!$B$13),D44*Config!$B$13,Config!$B$13))) | H44: =IF(OR(NOT(ISNUMBER(F44)),NOT(ISNUMBER(G44))),"",(F44+G44)/2) | I44: =IF(A44="","",IF(E44="Hora","Cobre a hora entre a mínima e a alvo; a faixa é o total esperado",IF(E44="Êxito","Percentual que, na chance esperada, fique dentro da faixa",IF(E44="Misto","Entrada perto do mínimo; o êxito leva ao máximo","Caso simples perto do mínimo; complexo perto do máximo"))))
F45: =IF(OR(A45="",C45=""),"",IF(NOT(IF(ISNUMBER(C45),C45>=0,FALSE)),"horas inválidas",IF(ISNUMBER(Config!$B$12),C45*Config!$B$12,Config!$B$12))) | G45: =IF(OR(A45="",D45=""),"",IF(NOT(IF(ISNUMBER(D45),D45>=0,FALSE)),"horas inválidas",IF(ISNUMBER(Config!$B$13),D45*Config!$B$13,Config!$B$13))) | H45: =IF(OR(NOT(ISNUMBER(F45)),NOT(ISNUMBER(G45))),"",(F45+G45)/2) | I45: =IF(A45="","",IF(E45="Hora","Cobre a hora entre a mínima e a alvo; a faixa é o total esperado",IF(E45="Êxito","Percentual que, na chance esperada, fique dentro da faixa",IF(E45="Misto","Entrada perto do mínimo; o êxito leva ao máximo","Caso simples perto do mínimo; complexo perto do máximo"))))
... F48: =IF(OR(A48="",C48=""),"",IF(NOT(IF(ISNUMBER(C48),C48>=0,FALSE)),"horas inválidas",IF(ISNUMBER(Config!$B$12),C48*Config!$B$12,Config!$B$12))) | G48: =IF(OR(A48="",D48=""),"",IF(NOT(IF(ISNUMBER(D48),D48>=0,FALSE)),"horas inválidas",IF(ISNUMBER(Config!$B$13),D48*Config!$B$13,Config!$B$13))) | H48: =IF(OR(NOT(ISNUMBER(F48)),NOT(ISNUMBER(G48))),"",(F48+G48)/2) | I48: =IF(A48="","",IF(E48="Hora","Cobre a hora entre a mínima e a alvo; a faixa é o total esperado",IF(E48="Êxito","Percentual que, na chance esperada, fique dentro da faixa",IF(E48="Misto","Entrada perto do mínimo; o êxito leva ao máximo","Caso simples perto do mínimo; complexo perto do máximo"))))
A49: Mínimo = horas de × hora mínima com folga. Máximo = horas até × hora alvo com folga (as duas incluem os 20 % de horas não previstas de Config; por isso a hora mínima daqui é maior que a da planilha 05). Abaixo do mínimo, o caso paga o custo mas não a margem que o escritório precisa.
A52: O que cobramos hoje, por área
A53: Área | B53: Casos | C53: Valor contratado (R$) | D53: Horas estimadas | E53: Valor por hora (R$) | F53: Contra a hora mínima | G53: Abaixo do mínimo | H53: Falta até o mínimo (R$)
A54: =IF(Config!$E$16="","",Config!$E$16) -> Cível | B54: =IF(Config!$E$16="","",COUNTIFS('Nossos casos'!$C$5:$C$204,Config!$E$16,'Nossos casos'!$J$5:$J$204,"<>")) -> 8 | C54: =IF(Config!$E$16="","",IF(SUMPRODUCT(('Nossos casos'!$C$5:$C$204=Config!$E$16)*((('Nossos casos'!$A$5:$A$204<>"")+('Nossos casos'!$C$5:$C$204<>"")+('Nossos casos'!$F$5:$F$204<>"")+('Nossos casos'!$G$5:$G$204<>"")>0)*((('Nossos casos'!$A$5:$A$204="")+(ISNUMBER(MATCH('Nossos casos'!$C$5:$C$204,Config!$E$16:$E$35,0))=FALSE)+(ISNUMBER('Nossos casos'!$F$5:$F$204)=FALSE)+ISNUMBER('Nossos casos'!$F$5:$F$204)*('Nossos casos'!$F$5:$F$204<0)+(ISNUMBER('Nossos casos'!$G$5:$G$204)=FALSE)+ISNUMBER('Nossos casos'!$G$5:$G$204)*('Nossos casos'!$G$5:$G$204<0))>0)))>0,"caso incompleto",SUMIFS('Nossos casos'!$F$5:$F$204,'Nossos casos'!$C$5:$C$204,Config!$E$16))) -> 101500 | D54: =IF(OR(Config!$E$16="",SUMPRODUCT(('Nossos casos'!$C$5:$C$204=Config!$E$16)*((('Nossos casos'!$A$5:$A$204<>"")+('Nossos casos'!$C$5:$C$204<>"")+('Nossos casos'!$F$5:$F$204<>"")+('Nossos casos'!$G$5:$G$204<>"")>0)*((('Nossos casos'!$A$5:$A$204="")+(ISNUMBER(MATCH('Nossos casos'!$C$5:$C$204,Config!$E$16:$E$35,0))=FALSE)+(ISNUMBER('Nossos casos'!$F$5:$F$204)=FALSE)+ISNUMBER('Nossos casos'!$F$5:$F$204)*('Nossos casos'!$F$5:$F$204<0)+(ISNUMBER('Nossos casos'!$G$5:$G$204)=FALSE)+ISNUMBER('Nossos casos'!$G$5:$G$204)*('Nossos casos'!$G$5:$G$204<0))>0)))>0),"",SUMIFS('Nossos casos'!$G$5:$G$204,'Nossos casos'!$C$5:$C$204,Config!$E$16)) -> 632 | E54: =IF(OR(Config!$E$16="",NOT(ISNUMBER(C54)),NOT(ISNUMBER(D54)),N(D54)=0),"",C54/D54) -> 160.60127 | F54: =IF(OR(NOT(ISNUMBER(E54)),NOT(ISNUMBER(Config!$B$12))),"",IF(Config!$B$12=0,"sem base (mínimo zero)",E54/Config!$B$12-1)) -> 0.2558735 | G54: =IF(OR(Config!$E$16="",NOT(ISNUMBER(Config!$B$12)),SUMPRODUCT(('Nossos casos'!$C$5:$C$204=Config!$E$16)*((('Nossos casos'!$A$5:$A$204<>"")+('Nossos casos'!$C$5:$C$204<>"")+('Nossos casos'!$F$5:$F$204<>"")+('Nossos casos'!$G$5:$G$204<>"")>0)*((('Nossos casos'!$A$5:$A$204="")+(ISNUMBER(MATCH('Nossos casos'!$C$5:$C$204,Config!$E$16:$E$35,0))=FALSE)+(ISNUMBER('Nossos casos'!$F$5:$F$204)=FALSE)+ISNUMBER('Nossos casos'!$F$5:$F$204)*('Nossos casos'!$F$5:$F$204<0)+(ISNUMBER('Nossos casos'!$G$5:$G$204)=FALSE)+ISNUMBER('Nossos casos'!$G$5:$G$204)*('Nossos casos'!$G$5:$G$204<0))>0)))>0),"",COUNTIFS('Nossos casos'!$C$5:$C$204,Config!$E$16,'Nossos casos'!$J$5:$J$204,"Abaixo do mínimo")) -> 1 | H54: =IF(OR(Config!$E$16="",NOT(ISNUMBER(Config!$B$12)),SUMPRODUCT(('Nossos casos'!$C$5:$C$204=Config!$E$16)*((('Nossos casos'!$A$5:$A$204<>"")+('Nossos casos'!$C$5:$C$204<>"")+('Nossos casos'!$F$5:$F$204<>"")+('Nossos casos'!$G$5:$G$204<>"")>0)*((('Nossos casos'!$A$5:$A$204="")+(ISNUMBER(MATCH('Nossos casos'!$C$5:$C$204,Config!$E$16:$E$35,0))=FALSE)+(ISNUMBER('Nossos casos'!$F$5:$F$204)=FALSE)+ISNUMBER('Nossos casos'!$F$5:$F$204)*('Nossos casos'!$F$5:$F$204<0)+(ISNUMBER('Nossos casos'!$G$5:$G$204)=FALSE)+ISNUMBER('Nossos casos'!$G$5:$G$204)*('Nossos casos'!$G$5:$G$204<0))>0)))>0),"",SUMIFS('Nossos casos'!$K$5:$K$204,'Nossos casos'!$C$5:$C$204,Config!$E$16)) -> 1509.2116
A55: =IF(Config!$E$17="","",Config!$E$17) -> Trabalhista | B55: =IF(Config!$E$17="","",COUNTIFS('Nossos casos'!$C$5:$C$204,Config!$E$17,'Nossos casos'!$J$5:$J$204,"<>")) -> 12 | C55: =IF(Config!$E$17="","",IF(SUMPRODUCT(('Nossos casos'!$C$5:$C$204=Config!$E$17)*((('Nossos casos'!$A$5:$A$204<>"")+('Nossos casos'!$C$5:$C$204<>"")+('Nossos casos'!$F$5:$F$204<>"")+('Nossos casos'!$G$5:$G$204<>"")>0)*((('Nossos casos'!$A$5:$A$204="")+(ISNUMBER(MATCH('Nossos casos'!$C$5:$C$204,Config!$E$16:$E$35,0))=FALSE)+(ISNUMBER('Nossos casos'!$F$5:$F$204)=FALSE)+ISNUMBER('Nossos casos'!$F$5:$F$204)*('Nossos casos'!$F$5:$F$204<0)+(ISNUMBER('Nossos casos'!$G$5:$G$204)=FALSE)+ISNUMBER('Nossos casos'!$G$5:$G$204)*('Nossos casos'!$G$5:$G$204<0))>0)))>0,"caso incompleto",SUMIFS('Nossos casos'!$F$5:$F$204,'Nossos casos'!$C$5:$C$204,Config!$E$17))) -> 105400 | D55: =IF(OR(Config!$E$17="",SUMPRODUCT(('Nossos casos'!$C$5:$C$204=Config!$E$17)*((('Nossos casos'!$A$5:$A$204<>"")+('Nossos casos'!$C$5:$C$204<>"")+('Nossos casos'!$F$5:$F$204<>"")+('Nossos casos'!$G$5:$G$204<>"")>0)*((('Nossos casos'!$A$5:$A$204="")+(ISNUMBER(MATCH('Nossos casos'!$C$5:$C$204,Config!$E$16:$E$35,0))=FALSE)+(ISNUMBER('Nossos casos'!$F$5:$F$204)=FALSE)+ISNUMBER('Nossos casos'!$F$5:$F$204)*('Nossos casos'!$F$5:$F$204<0)+(ISNUMBER('Nossos casos'!$G$5:$G$204)=FALSE)+ISNUMBER('Nossos casos'!$G$5:$G$204)*('Nossos casos'!$G$5:$G$204<0))>0)))>0),"",SUMIFS('Nossos casos'!$G$5:$G$204,'Nossos casos'!$C$5:$C$204,Config!$E$17)) -> 838 | E55: =IF(OR(Config!$E$17="",NOT(ISNUMBER(C55)),NOT(ISNUMBER(D55)),N(D55)=0),"",C55/D55) -> 125.77566 | F55: =IF(OR(NOT(ISNUMBER(E55)),NOT(ISNUMBER(Config!$B$12))),"",IF(Config!$B$12=0,"sem base (mínimo zero)",E55/Config!$B$12-1)) -> -0.016456605 | G55: =IF(OR(Config!$E$17="",NOT(ISNUMBER(Config!$B$12)),SUMPRODUCT(('Nossos casos'!$C$5:$C$204=Config!$E$17)*((('Nossos casos'!$A$5:$A$204<>"")+('Nossos casos'!$C$5:$C$204<>"")+('Nossos casos'!$F$5:$F$204<>"")+('Nossos casos'!$G$5:$G$204<>"")>0)*((('Nossos casos'!$A$5:$A$204="")+(ISNUMBER(MATCH('Nossos casos'!$C$5:$C$204,Config!$E$16:$E$35,0))=FALSE)+(ISNUMBER('Nossos casos'!$F$5:$F$204)=FALSE)+ISNUMBER('Nossos casos'!$F$5:$F$204)*('Nossos casos'!$F$5:$F$204<0)+(ISNUMBER('Nossos casos'!$G$5:$G$204)=FALSE)+ISNUMBER('Nossos casos'!$G$5:$G$204)*('Nossos casos'!$G$5:$G$204<0))>0)))>0),"",COUNTIFS('Nossos casos'!$C$5:$C$204,Config!$E$17,'Nossos casos'!$J$5:$J$204,"Abaixo do mínimo")) -> 7 | H55: =IF(OR(Config!$E$17="",NOT(ISNUMBER(Config!$B$12)),SUMPRODUCT(('Nossos casos'!$C$5:$C$204=Config!$E$17)*((('Nossos casos'!$A$5:$A$204<>"")+('Nossos casos'!$C$5:$C$204<>"")+('Nossos casos'!$F$5:$F$204<>"")+('Nossos casos'!$G$5:$G$204<>"")>0)*((('Nossos casos'!$A$5:$A$204="")+(ISNUMBER(MATCH('Nossos casos'!$C$5:$C$204,Config!$E$16:$E$35,0))=FALSE)+(ISNUMBER('Nossos casos'!$F$5:$F$204)=FALSE)+ISNUMBER('Nossos casos'!$F$5:$F$204)*('Nossos casos'!$F$5:$F$204<0)+(ISNUMBER('Nossos casos'!$G$5:$G$204)=FALSE)+ISNUMBER('Nossos casos'!$G$5:$G$204)*('Nossos casos'!$G$5:$G$204<0))>0)))>0),"",SUMIFS('Nossos casos'!$K$5:$K$204,'Nossos casos'!$C$5:$C$204,Config!$E$17)) -> 9218.8658
A56: =IF(Config!$E$18="","",Config!$E$18) -> Previdenciário | B56: =IF(Config!$E$18="","",COUNTIFS('Nossos casos'!$C$5:$C$204,Config!$E$18,'Nossos casos'!$J$5:$J$204,"<>")) -> 7 | C56: =IF(Config!$E$18="","",IF(SUMPRODUCT(('Nossos casos'!$C$5:$C$204=Config!$E$18)*((('Nossos casos'!$A$5:$A$204<>"")+('Nossos casos'!$C$5:$C$204<>"")+('Nossos casos'!$F$5:$F$204<>"")+('Nossos casos'!$G$5:$G$204<>"")>0)*((('Nossos casos'!$A$5:$A$204="")+(ISNUMBER(MATCH('Nossos casos'!$C$5:$C$204,Config!$E$16:$E$35,0))=FALSE)+(ISNUMBER('Nossos casos'!$F$5:$F$204)=FALSE)+ISNUMBER('Nossos casos'!$F$5:$F$204)*('Nossos casos'!$F$5:$F$204<0)+(ISNUMBER('Nossos casos'!$G$5:$G$204)=FALSE)+ISNUMBER('Nossos casos'!$G$5:$G$204)*('Nossos casos'!$G$5:$G$204<0))>0)))>0,"caso incompleto",SUMIFS('Nossos casos'!$F$5:$F$204,'Nossos casos'!$C$5:$C$204,Config!$E$18))) -> 39400 | D56: =IF(OR(Config!$E$18="",SUMPRODUCT(('Nossos casos'!$C$5:$C$204=Config!$E$18)*((('Nossos casos'!$A$5:$A$204<>"")+('Nossos casos'!$C$5:$C$204<>"")+('Nossos casos'!$F$5:$F$204<>"")+('Nossos casos'!$G$5:$G$204<>"")>0)*((('Nossos casos'!$A$5:$A$204="")+(ISNUMBER(MATCH('Nossos casos'!$C$5:$C$204,Config!$E$16:$E$35,0))=FALSE)+(ISNUMBER('Nossos casos'!$F$5:$F$204)=FALSE)+ISNUMBER('Nossos casos'!$F$5:$F$204)*('Nossos casos'!$F$5:$F$204<0)+(ISNUMBER('Nossos casos'!$G$5:$G$204)=FALSE)+ISNUMBER('Nossos casos'!$G$5:$G$204)*('Nossos casos'!$G$5:$G$204<0))>0)))>0),"",SUMIFS('Nossos casos'!$G$5:$G$204,'Nossos casos'!$C$5:$C$204,Config!$E$18)) -> 264 | E56: =IF(OR(Config!$E$18="",NOT(ISNUMBER(C56)),NOT(ISNUMBER(D56)),N(D56)=0),"",C56/D56) -> 149.24242 | F56: =IF(OR(NOT(ISNUMBER(E56)),NOT(ISNUMBER(Config!$B$12))),"",IF(Config!$B$12=0,"sem base (mínimo zero)",E56/Config!$B$12-1)) -> 0.16704937 | G56: =IF(OR(Config!$E$18="",NOT(ISNUMBER(Config!$B$12)),SUMPRODUCT(('Nossos casos'!$C$5:$C$204=Config!$E$18)*((('Nossos casos'!$A$5:$A$204<>"")+('Nossos casos'!$C$5:$C$204<>"")+('Nossos casos'!$F$5:$F$204<>"")+('Nossos casos'!$G$5:$G$204<>"")>0)*((('Nossos casos'!$A$5:$A$204="")+(ISNUMBER(MATCH('Nossos casos'!$C$5:$C$204,Config!$E$16:$E$35,0))=FALSE)+(ISNUMBER('Nossos casos'!$F$5:$F$204)=FALSE)+ISNUMBER('Nossos casos'!$F$5:$F$204)*('Nossos casos'!$F$5:$F$204<0)+(ISNUMBER('Nossos casos'!$G$5:$G$204)=FALSE)+ISNUMBER('Nossos casos'!$G$5:$G$204)*('Nossos casos'!$G$5:$G$204<0))>0)))>0),"",COUNTIFS('Nossos casos'!$C$5:$C$204,Config!$E$18,'Nossos casos'!$J$5:$J$204,"Abaixo do mínimo")) -> 1 | H56: =IF(OR(Config!$E$18="",NOT(ISNUMBER(Config!$B$12)),SUMPRODUCT(('Nossos casos'!$C$5:$C$204=Config!$E$18)*((('Nossos casos'!$A$5:$A$204<>"")+('Nossos casos'!$C$5:$C$204<>"")+('Nossos casos'!$F$5:$F$204<>"")+('Nossos casos'!$G$5:$G$204<>"")>0)*((('Nossos casos'!$A$5:$A$204="")+(ISNUMBER(MATCH('Nossos casos'!$C$5:$C$204,Config!$E$16:$E$35,0))=FALSE)+(ISNUMBER('Nossos casos'!$F$5:$F$204)=FALSE)+ISNUMBER('Nossos casos'!$F$5:$F$204)*('Nossos casos'!$F$5:$F$204<0)+(ISNUMBER('Nossos casos'!$G$5:$G$204)=FALSE)+ISNUMBER('Nossos casos'!$G$5:$G$204)*('Nossos casos'!$G$5:$G$204<0))>0)))>0),"",SUMIFS('Nossos casos'!$K$5:$K$204,'Nossos casos'!$C$5:$C$204,Config!$E$18)) -> 1115.2052
A57: =IF(Config!$E$19="","",Config!$E$19) -> Empresarial | B57: =IF(Config!$E$19="","",COUNTIFS('Nossos casos'!$C$5:$C$204,Config!$E$19,'Nossos casos'!$J$5:$J$204,"<>")) -> 8 | C57: =IF(Config!$E$19="","",IF(SUMPRODUCT(('Nossos casos'!$C$5:$C$204=Config!$E$19)*((('Nossos casos'!$A$5:$A$204<>"")+('Nossos casos'!$C$5:$C$204<>"")+('Nossos casos'!$F$5:$F$204<>"")+('Nossos casos'!$G$5:$G$204<>"")>0)*((('Nossos casos'!$A$5:$A$204="")+(ISNUMBER(MATCH('Nossos casos'!$C$5:$C$204,Config!$E$16:$E$35,0))=FALSE)+(ISNUMBER('Nossos casos'!$F$5:$F$204)=FALSE)+ISNUMBER('Nossos casos'!$F$5:$F$204)*('Nossos casos'!$F$5:$F$204<0)+(ISNUMBER('Nossos casos'!$G$5:$G$204)=FALSE)+ISNUMBER('Nossos casos'!$G$5:$G$204)*('Nossos casos'!$G$5:$G$204<0))>0)))>0,"caso incompleto",SUMIFS('Nossos casos'!$F$5:$F$204,'Nossos casos'!$C$5:$C$204,Config!$E$19))) -> 115000 | D57: =IF(OR(Config!$E$19="",SUMPRODUCT(('Nossos casos'!$C$5:$C$204=Config!$E$19)*((('Nossos casos'!$A$5:$A$204<>"")+('Nossos casos'!$C$5:$C$204<>"")+('Nossos casos'!$F$5:$F$204<>"")+('Nossos casos'!$G$5:$G$204<>"")>0)*((('Nossos casos'!$A$5:$A$204="")+(ISNUMBER(MATCH('Nossos casos'!$C$5:$C$204,Config!$E$16:$E$35,0))=FALSE)+(ISNUMBER('Nossos casos'!$F$5:$F$204)=FALSE)+ISNUMBER('Nossos casos'!$F$5:$F$204)*('Nossos casos'!$F$5:$F$204<0)+(ISNUMBER('Nossos casos'!$G$5:$G$204)=FALSE)+ISNUMBER('Nossos casos'!$G$5:$G$204)*('Nossos casos'!$G$5:$G$204<0))>0)))>0),"",SUMIFS('Nossos casos'!$G$5:$G$204,'Nossos casos'!$C$5:$C$204,Config!$E$19)) -> 615 | E57: =IF(OR(Config!$E$19="",NOT(ISNUMBER(C57)),NOT(ISNUMBER(D57)),N(D57)=0),"",C57/D57) -> 186.99187 | F57: =IF(OR(NOT(ISNUMBER(E57)),NOT(ISNUMBER(Config!$B$12))),"",IF(Config!$B$12=0,"sem base (mínimo zero)",E57/Config!$B$12-1)) -> 0.46224336 | G57: =IF(OR(Config!$E$19="",NOT(ISNUMBER(Config!$B$12)),SUMPRODUCT(('Nossos casos'!$C$5:$C$204=Config!$E$19)*((('Nossos casos'!$A$5:$A$204<>"")+('Nossos casos'!$C$5:$C$204<>"")+('Nossos casos'!$F$5:$F$204<>"")+('Nossos casos'!$G$5:$G$204<>"")>0)*((('Nossos casos'!$A$5:$A$204="")+(ISNUMBER(MATCH('Nossos casos'!$C$5:$C$204,Config!$E$16:$E$35,0))=FALSE)+(ISNUMBER('Nossos casos'!$F$5:$F$204)=FALSE)+ISNUMBER('Nossos casos'!$F$5:$F$204)*('Nossos casos'!$F$5:$F$204<0)+(ISNUMBER('Nossos casos'!$G$5:$G$204)=FALSE)+ISNUMBER('Nossos casos'!$G$5:$G$204)*('Nossos casos'!$G$5:$G$204<0))>0)))>0),"",COUNTIFS('Nossos casos'!$C$5:$C$204,Config!$E$19,'Nossos casos'!$J$5:$J$204,"Abaixo do mínimo")) -> 0 | H57: =IF(OR(Config!$E$19="",NOT(ISNUMBER(Config!$B$12)),SUMPRODUCT(('Nossos casos'!$C$5:$C$204=Config!$E$19)*((('Nossos casos'!$A$5:$A$204<>"")+('Nossos casos'!$C$5:$C$204<>"")+('Nossos casos'!$F$5:$F$204<>"")+('Nossos casos'!$G$5:$G$204<>"")>0)*((('Nossos casos'!$A$5:$A$204="")+(ISNUMBER(MATCH('Nossos casos'!$C$5:$C$204,Config!$E$16:$E$35,0))=FALSE)+(ISNUMBER('Nossos casos'!$F$5:$F$204)=FALSE)+ISNUMBER('Nossos casos'!$F$5:$F$204)*('Nossos casos'!$F$5:$F$204<0)+(ISNUMBER('Nossos casos'!$G$5:$G$204)=FALSE)+ISNUMBER('Nossos casos'!$G$5:$G$204)*('Nossos casos'!$G$5:$G$204<0))>0)))>0),"",SUMIFS('Nossos casos'!$K$5:$K$204,'Nossos casos'!$C$5:$C$204,Config!$E$19)) -> 0
A58: =IF(Config!$E$20="","",Config!$E$20) -> Família | B58: =IF(Config!$E$20="","",COUNTIFS('Nossos casos'!$C$5:$C$204,Config!$E$20,'Nossos casos'!$J$5:$J$204,"<>")) -> 3 | C58: =IF(Config!$E$20="","",IF(SUMPRODUCT(('Nossos casos'!$C$5:$C$204=Config!$E$20)*((('Nossos casos'!$A$5:$A$204<>"")+('Nossos casos'!$C$5:$C$204<>"")+('Nossos casos'!$F$5:$F$204<>"")+('Nossos casos'!$G$5:$G$204<>"")>0)*((('Nossos casos'!$A$5:$A$204="")+(ISNUMBER(MATCH('Nossos casos'!$C$5:$C$204,Config!$E$16:$E$35,0))=FALSE)+(ISNUMBER('Nossos casos'!$F$5:$F$204)=FALSE)+ISNUMBER('Nossos casos'!$F$5:$F$204)*('Nossos casos'!$F$5:$F$204<0)+(ISNUMBER('Nossos casos'!$G$5:$G$204)=FALSE)+ISNUMBER('Nossos casos'!$G$5:$G$204)*('Nossos casos'!$G$5:$G$204<0))>0)))>0,"caso incompleto",SUMIFS('Nossos casos'!$F$5:$F$204,'Nossos casos'!$C$5:$C$204,Config!$E$20))) -> 22600 | D58: =IF(OR(Config!$E$20="",SUMPRODUCT(('Nossos casos'!$C$5:$C$204=Config!$E$20)*((('Nossos casos'!$A$5:$A$204<>"")+('Nossos casos'!$C$5:$C$204<>"")+('Nossos casos'!$F$5:$F$204<>"")+('Nossos casos'!$G$5:$G$204<>"")>0)*((('Nossos casos'!$A$5:$A$204="")+(ISNUMBER(MATCH('Nossos casos'!$C$5:$C$204,Config!$E$16:$E$35,0))=FALSE)+(ISNUMBER('Nossos casos'!$F$5:$F$204)=FALSE)+ISNUMBER('Nossos casos'!$F$5:$F$204)*('Nossos casos'!$F$5:$F$204<0)+(ISNUMBER('Nossos casos'!$G$5:$G$204)=FALSE)+ISNUMBER('Nossos casos'!$G$5:$G$204)*('Nossos casos'!$G$5:$G$204<0))>0)))>0),"",SUMIFS('Nossos casos'!$G$5:$G$204,'Nossos casos'!$C$5:$C$204,Config!$E$20)) -> 155 | E58: =IF(OR(Config!$E$20="",NOT(ISNUMBER(C58)),NOT(ISNUMBER(D58)),N(D58)=0),"",C58/D58) -> 145.80645 | F58: =IF(OR(NOT(ISNUMBER(E58)),NOT(ISNUMBER(Config!$B$12))),"",IF(Config!$B$12=0,"sem base (mínimo zero)",E58/Config!$B$12-1)) -> 0.14018067 | G58: =IF(OR(Config!$E$20="",NOT(ISNUMBER(Config!$B$12)),SUMPRODUCT(('Nossos casos'!$C$5:$C$204=Config!$E$20)*((('Nossos casos'!$A$5:$A$204<>"")+('Nossos casos'!$C$5:$C$204<>"")+('Nossos casos'!$F$5:$F$204<>"")+('Nossos casos'!$G$5:$G$204<>"")>0)*((('Nossos casos'!$A$5:$A$204="")+(ISNUMBER(MATCH('Nossos casos'!$C$5:$C$204,Config!$E$16:$E$35,0))=FALSE)+(ISNUMBER('Nossos casos'!$F$5:$F$204)=FALSE)+ISNUMBER('Nossos casos'!$F$5:$F$204)*('Nossos casos'!$F$5:$F$204<0)+(ISNUMBER('Nossos casos'!$G$5:$G$204)=FALSE)+ISNUMBER('Nossos casos'!$G$5:$G$204)*('Nossos casos'!$G$5:$G$204<0))>0)))>0),"",COUNTIFS('Nossos casos'!$C$5:$C$204,Config!$E$20,'Nossos casos'!$J$5:$J$204,"Abaixo do mínimo")) -> 1 | H58: =IF(OR(Config!$E$20="",NOT(ISNUMBER(Config!$B$12)),SUMPRODUCT(('Nossos casos'!$C$5:$C$204=Config!$E$20)*((('Nossos casos'!$A$5:$A$204<>"")+('Nossos casos'!$C$5:$C$204<>"")+('Nossos casos'!$F$5:$F$204<>"")+('Nossos casos'!$G$5:$G$204<>"")>0)*((('Nossos casos'!$A$5:$A$204="")+(ISNUMBER(MATCH('Nossos casos'!$C$5:$C$204,Config!$E$16:$E$35,0))=FALSE)+(ISNUMBER('Nossos casos'!$F$5:$F$204)=FALSE)+ISNUMBER('Nossos casos'!$F$5:$F$204)*('Nossos casos'!$F$5:$F$204<0)+(ISNUMBER('Nossos casos'!$G$5:$G$204)=FALSE)+ISNUMBER('Nossos casos'!$G$5:$G$204)*('Nossos casos'!$G$5:$G$204<0))>0)))>0),"",SUMIFS('Nossos casos'!$K$5:$K$204,'Nossos casos'!$C$5:$C$204,Config!$E$20)) -> 33.407097
...

Sheet Config
A1: Configurações
A2: Células amarelas: você preenche. O custo-hora vem da planilha 05; margens mínima e alvo definem a faixa de cada serviço.
A4: Nome do escritório | B4: Ferraz & Lima Advocacia (exemplo fictício)
A5: Mês de referência | B5: Setembro de 2026
A6: Data de referência | B6: 46279
A7: Custo-hora do escritório (R$) | B7: 66.0714 | C7: Copie do Painel da planilha 05 ("Custo-hora do escritório").
A8: Impostos e taxas sobre o que entra (%) | B8: 0.08 | C8: Exemplo; confira com o contador.
A9: Margem mínima sobre o preço (%) | B9: 0.3 | C9: Abaixo disso o caso não vale a pena. Define o piso da faixa. A mesma margem desejada da planilha 05.
A10: Margem alvo sobre o preço (%) | B10: 0.45 | C10: A margem que você quer de verdade. Define o teto da faixa.
A11: Folga para horas não previstas (%) | B11: 0.2 | C11: Caso costuma consumir mais horas que o estimado; a folga protege a faixa. Igual à folga de horas da planilha 06.
A12: Hora mínima com folga (20 % de horas não previstas) (R$) | B12: =IF(NOT(ISNUMBER(B7)),"falta o custo-hora",IF(IF(AND(ISNUMBER(B8),ISNUMBER(B9),ISNUMBER(B10),ISNUMBER(B11)),AND(B8>=0,B8<1,B9>=0,B9<=B10,B10<1,B8+B10<1,B11>=0),FALSE),B7*(1+B11)/(1-B8-B9),"margens inválidas (Config)")) -> 127.88013 | C12: Custo-hora × (1 + folga) ÷ (1 − impostos − margem mínima). É a hora mínima da planilha 05 (R$ 106,57 → R$ 110) com 20 % de folga para horas não previstas: por isso é maior. A tabela usa esta, mais protegida, porque a faixa é fixada antes de conhecer o caso.
A13: Hora alvo com folga (R$) | B13: =IF(NOT(ISNUMBER(B7)),"falta o custo-hora",IF(IF(AND(ISNUMBER(B8),ISNUMBER(B9),ISNUMBER(B10),ISNUMBER(B11)),AND(B8>=0,B8<1,B9>=0,B9<=B10,B10<1,B8+B10<1,B11>=0),FALSE),B7*(1+B11)/(1-B8-B10),"margens inválidas (Config)")) -> 168.69294 | C13: Custo-hora × (1 + folga) ÷ (1 − impostos − margem alvo).
A14: Listas (preencha de cima para baixo, sem pular linha)
E15: Áreas | G15: Tipos de serviço | I15: Modalidades
E16: Cível | G16: Consultoria pontual | I16: Fixo
E17: Trabalhista | G17: Contrato ou documento | I17: Hora
E18: Previdenciário | G18: Processo completo | I18: Êxito
E19: Empresarial | G19: Recurso | I19: Misto
E20: Família | G20: Acordo e negociação

Sheet Nossos casos
A1: O que cobramos hoje
A2: Uma linha por caso (copie da planilha 13 · Carteira, aba Casos: a 13 é a fonte; horas estimadas da 16). O valor por hora é comparado com a hora mínima com folga e a hora alvo de Config.
A4: Nº do processo ou caso | B4: Cliente | C4: Área | D4: Modalidade | E4: Fase | F4: Valor contratado (R$) | G4: Horas estimadas | H4: Valor por hora (R$) | I4: Contra a hora mínima com folga | J4: Situação | K4: Falta até o mínimo (R$) | L4: Ordem
A5: CONS-2026-01 | B5: Padaria do Sol Ltda | C5: Empresarial | D5: Fixo | E5: Consultivo | F5: 18000 | G5: 72 | H5: =IF(OR(A5="",G5="",F5=""),"",IF(OR(NOT(IF(ISNUMBER(F5),F5>=0,FALSE)),NOT(IF(ISNUMBER(G5),G5>=0,FALSE))),"valor ou horas inválidos",IF(G5=0,"",F5/G5))) -> 250 | I5: =IF(OR(NOT(ISNUMBER(H5)),NOT(ISNUMBER(Config!$B$12))),"",IF(Config!$B$12=0,"sem base (mínimo zero)",H5/Config!$B$12-1)) -> 0.9549558 | J5: =IF(H5="","",IF(NOT(ISNUMBER(H5)),H5,IF(NOT(ISNUMBER(Config!$B$12)),Config!$B$12,IF(NOT(ISNUMBER(Config!$B$13)),Config!$B$13,IF(H5<Config!$B$12,"Abaixo do mínimo",IF(H5<Config!$B$13,"Na faixa","Acima do alvo")))))) -> Acima do alvo | K5: =IF(OR(NOT(ISNUMBER(H5)),NOT(ISNUMBER(Config!$B$12))),"",MAX(0,Config!$B$12*G5-F5)) -> 0 | L5: =IF(K5="","",K5+ROW()/1000000) -> 5e-06
A6: 2998500-50.2026.8.26.0515 | B6: Ana Beatriz Moreira | C6: Trabalhista | D6: Êxito | E6: Inicial | F6: 6000 | G6: 70 | H6: =IF(OR(A6="",G6="",F6=""),"",IF(OR(NOT(IF(ISNUMBER(F6),F6>=0,FALSE)),NOT(IF(ISNUMBER(G6),G6>=0,FALSE))),"valor ou horas inválidos",IF(G6=0,"",F6/G6))) -> 85.714286 | I6: =IF(OR(NOT(ISNUMBER(H6)),NOT(ISNUMBER(Config!$B$12))),"",IF(Config!$B$12=0,"sem base (mínimo zero)",H6/Config!$B$12-1)) -> -0.32972944 | J6: =IF(H6="","",IF(NOT(ISNUMBER(H6)),H6,IF(NOT(ISNUMBER(Config!$B$12)),Config!$B$12,IF(NOT(ISNUMBER(Config!$B$13)),Config!$B$13,IF(H6<Config!$B$12,"Abaixo do mínimo",IF(H6<Config!$B$13,"Na faixa","Acima do alvo")))))) -> Abaixo do mínimo | K6: =IF(OR(NOT(ISNUMBER(H6)),NOT(ISNUMBER(Config!$B$12))),"",MAX(0,Config!$B$12*G6-F6)) -> 2951.609 | L6: =IF(K6="","",K6+ROW()/1000000) -> 2951.609
A7: 9586960-92.2026.8.26.0106 | B7: Construtora Horizonte | C7: Cível | D7: Misto | E7: Inicial | F7: 15500 | G7: 90 | H7: =IF(OR(A7="",G7="",F7=""),"",IF(OR(NOT(IF(ISNUMBER(F7),F7>=0,FALSE)),NOT(IF(ISNUMBER(G7),G7>=0,FALSE))),"valor ou horas inválidos",IF(G7=0,"",F7/G7))) -> 172.22222 | I7: =IF(OR(NOT(ISNUMBER(H7)),NOT(ISNUMBER(Config!$B$12))),"",IF(Config!$B$12=0,"sem base (mínimo zero)",H7/Config!$B$12-1)) -> 0.34674733 | J7: =IF(H7="","",IF(NOT(ISNUMBER(H7)),H7,IF(NOT(ISNUMBER(Config!$B$12)),Config!$B$12,IF(NOT(ISNUMBER(Config!$B$13)),Config!$B$13,IF(H7<Config!$B$12,"Abaixo do mínimo",IF(H7<Config!$B$13,"Na faixa","Acima do alvo")))))) -> Acima do alvo | K7: =IF(OR(NOT(ISNUMBER(H7)),NOT(ISNUMBER(Config!$B$12))),"",MAX(0,Config!$B$12*G7-F7)) -> 0 | L7: =IF(K7="","",K7+ROW()/1000000) -> 7e-06
A8: 4746093-86.2026.8.26.0637 | B8: Carlos Eduardo Nunes | C8: Previdenciário | D8: Fixo | E8: Inicial | F8: 5400 | G8: 40 | H8: =IF(OR(A8="",G8="",F8=""),"",IF(OR(NOT(IF(ISNUMBER(F8),F8>=0,FALSE)),NOT(IF(ISNUMBER(G8),G8>=0,FALSE))),"valor ou horas inválidos",IF(G8=0,"",F8/G8))) -> 135 | I8: =IF(OR(NOT(ISNUMBER(H8)),NOT(ISNUMBER(Config!$B$12))),"",IF(Config!$B$12=0,"sem base (mínimo zero)",H8/Config!$B$12-1)) -> 0.055676132 | J8: =IF(H8="","",IF(NOT(ISNUMBER(H8)),H8,IF(NOT(ISNUMBER(Config!$B$12)),Config!$B$12,IF(NOT(ISNUMBER(Config!$B$13)),Config!$B$13,IF(H8<Config!$B$12,"Abaixo do mínimo",IF(H8<Config!$B$13,"Na faixa","Acima do alvo")))))) -> Na faixa | K8: =IF(OR(NOT(ISNUMBER(H8)),NOT(ISNUMBER(Config!$B$12))),"",MAX(0,Config!$B$12*G8-F8)) -> 0 | L8: =IF(K8="","",K8+ROW()/1000000) -> 8e-06
A9: CONS-2026-02 | B9: Loja Verde Comércio | C9: Empresarial | D9: Fixo | E9: Consultivo | F9: 8400 | G9: 45 | H9: =IF(OR(A9="",G9="",F9=""),"",IF(OR(NOT(IF(ISNUMBER(F9),F9>=0,FALSE)),NOT(IF(ISNUMBER(G9),G9>=0,FALSE))),"valor ou horas inválidos",IF(G9=0,"",F9/G9))) -> 186.66667 | I9: =IF(OR(NOT(ISNUMBER(H9)),NOT(ISNUMBER(Config!$B$12))),"",IF(Config!$B$12=0,"sem base (mínimo zero)",H9/Config!$B$12-1)) -> 0.45970033 | J9: =IF(H9="","",IF(NOT(ISNUMBER(H9)),H9,IF(NOT(ISNUMBER(Config!$B$12)),Config!$B$12,IF(NOT(ISNUMBER(Config!$B$13)),Config!$B$13,IF(H9<Config!$B$12,"Abaixo do mínimo",IF(H9<Config!$B$13,"Na faixa","Acima do alvo")))))) -> Acima do alvo | K9: =IF(OR(NOT(ISNUMBER(H9)),NOT(ISNUMBER(Config!$B$12))),"",MAX(0,Config!$B$12*G9-F9)) -> 0 | L9: =IF(K9="","",K9+ROW()/1000000) -> 9e-06
A10: CONS-2026-03 | B10: Marcos Vinícius Teles | C10: Previdenciário | D10: Fixo | E10: Consultivo | F10: 4500 | G10: 24 | H10: =IF(OR(A10="",G10="",F10=""),"",IF(OR(NOT(IF(ISNUMBER(F10),F10>=0,FALSE)),NOT(IF(ISNUMBER(G10),G10>=0,FALSE))),"valor ou horas inválidos",IF(G10=0,"",F10/G10))) -> 187.5 | I10: =IF(OR(NOT(ISNUMBER(H10)),NOT(ISNUMBER(Config!$B$12))),"",IF(Config!$B$12=0,"sem base (mínimo zero)",H10/Config!$B$12-1)) -> 0.46621685 | J10: =IF(H10="","",IF(NOT(ISNUMBER(H10)),H10,IF(NOT(ISNUMBER(Config!$B$12)),Config!$B$12,IF(NOT(ISNUMBER(Config!$B$13)),Config!$B$13,IF(H10<Config!$B$12,"Abaixo do mínimo",IF(H10<Config!$B$13,"Na faixa","Acima do alvo")))))) -> Acima do alvo | K10: =IF(OR(NOT(ISNUMBER(H10)),NOT(ISNUMBER(Config!$B$12))),"",MAX(0,Config!$B$12*G10-F10)) -> 0 | L10: =IF(K10="","",K10+ROW()/1000000) -> 1e-05
A11: CONS-2026-04 | B11: Escola Aurora | C11: Cível | D11: Fixo | E11: Consultivo | F11: 13200 | G11: 72 | H11: =IF(OR(A11="",G11="",F11=""),"",IF(OR(NOT(IF(ISNUMBER(F11),F11>=0,FALSE)),NOT(IF(ISNUMBER(G11),G11>=0,FALSE))),"valor ou horas inválidos",IF(G11=0,"",F11/G11))) -> 183.33333 | I11: =IF(OR(NOT(ISNUMBER(H11)),NOT(ISNUMBER(Config!$B$12))),"",IF(Config!$B$12=0,"sem base (mínimo zero)",H11/Config!$B$12-1)) -> 0.43363425 | J11: =IF(H11="","",IF(NOT(ISNUMBER(H11)),H11,IF(NOT(ISNUMBER(Config!$B$12)),Config!$B$12,IF(NOT(ISNUMBER(Config!$B$13)),Config!$B$13,IF(H11<Config!$B$12,"Abaixo do mínimo",IF(H11<Config!$B$13,"Na faixa","Acima do alvo")))))) -> Acima do alvo | K11: =IF(OR(NOT(ISNUMBER(H11)),NOT(ISNUMBER(Config!$B$12))),"",MAX(0,Config!$B$12*G11-F11)) -> 0 | L11: =IF(K11="","",K11+ROW()/1000000) -> 1.1e-05
A12: 8056747-83.2026.8.26.0561 | B12: Bistrô 42 | C12: Trabalhista | D12: Fixo | E12: Instrução | F12: 9500 | G12: 80 | H12: =IF(OR(A12="",G12="",F12=""),"",IF(OR(NOT(IF(ISNUMBER(F12),F12>=0,FALSE)),NOT(IF(ISNUMBER(G12),G12>=0,FALSE))),"valor ou horas inválidos",IF(G12=0,"",F12/G12))) -> 118.75 | I12: =IF(OR(NOT(ISNUMBER(H12)),NOT(ISNUMBER(Config!$B$12))),"",IF(Config!$B$12=0,"sem base (mínimo zero)",H12/Config!$B$12-1)) -> -0.071395995 | J12: =IF(H12="","",IF(NOT(ISNUMBER(H12)),H12,IF(NOT(ISNUMBER(Config!$B$12)),Config!$B$12,IF(NOT(ISNUMBER(Config!$B$13)),Config!$B$13,IF(H12<Config!$B$12,"Abaixo do mínimo",IF(H12<Config!$B$13,"Na faixa","Acima do alvo")))))) -> Abaixo do mínimo | K12: =IF(OR(NOT(ISNUMBER(H12)),NOT(ISNUMBER(Config!$B$12))),"",MAX(0,Config!$B$12*G12-F12)) -> 730.41032 | L12: =IF(K12="","",K12+ROW()/1000000) -> 730.41033
A13: 9236009-85.2025.8.26.0452 | B13: Bistrô 42 | C13: Trabalhista | D13: Êxito | E13: Execução | F13: 4000 | G13: 45 | H13: =IF(OR(A13="",G13="",F13=""),"",IF(OR(NOT(IF(ISNUMBER(F13),F13>=0,FALSE)),NOT(IF(ISNUMBER(G13),G13>=0,FALSE))),"valor ou horas inválidos",IF(G13=0,"",F13/G13))) -> 88.888889 | I13: =IF(OR(NOT(ISNUMBER(H13)),NOT(ISNUMBER(Config!$B$12))),"",IF(Config!$B$12=0,"sem base (mínimo zero)",H13/Config!$B$12-1)) -> -0.3049046 | J13: =IF(H13="","",IF(NOT(ISNUMBER(H13)),H13,IF(NOT(ISNUMBER(Config!$B$12)),Config!$B$12,IF(NOT(ISNUMBER(Config!$B$13)),Config!$B$13,IF(H13<Config!$B$12,"Abaixo do mínimo",IF(H13<Config!$B$13,"Na faixa","Acima do alvo")))))) -> Abaixo do mínimo | K13: =IF(OR(NOT(ISNUMBER(H13)),NOT(ISNUMBER(Config!$B$12))),"",MAX(0,Config!$B$12*G13-F13)) -> 1754.6058 | L13: =IF(K13="","",K13+ROW()/1000000) -> 1754.6058
A14: 5025425-10.2025.8.26.0629 | B14: Roberto Almeida | C14: Cível | D14: Fixo | E14: Sentença | F14: 15000 | G14: 95 | H14: =IF(OR(A14="",G14="",F14=""),"",IF(OR(NOT(IF(ISNUMBER(F14),F14>=0,FALSE)),NOT(IF(ISNUMBER(G14),G14>=0,FALSE))),"valor ou horas inválidos",IF(G14=0,"",F14/G14))) -> 157.89474 | I14: =IF(OR(NOT(ISNUMBER(H14)),NOT(ISNUMBER(Config!$B$12))),"",IF(Config!$B$12=0,"sem base (mínimo zero)",H14/Config!$B$12-1)) -> 0.23470893 | J14: =IF(H14="","",IF(NOT(ISNUMBER(H14)),H14,IF(NOT(ISNUMBER(Config!$B$12)),Config!$B$12,IF(NOT(ISNUMBER(Config!$B$13)),Config!$B$13,IF(H14<Config!$B$12,"Abaixo do mínimo",IF(H14<Config!$B$13,"Na faixa","Acima do alvo")))))) -> Na faixa | K14: =IF(OR(NOT(ISNUMBER(H14)),NOT(ISNUMBER(Config!$B$12))),"",MAX(0,Config!$B$12*G14-F14)) -> 0 | L14: =IF(K14="","",K14+ROW()/1000000) -> 1.4e-05
A15: 2354318-24.2026.8.26.0295 | B15: Roberto Almeida | C15: Cível | D15: Misto | E15: Recurso | F15: 10200 | G15: 60 | H15: =IF(OR(A15="",G15="",F15=""),"",IF(OR(NOT(IF(ISNUMBER(F15),F15>=0,FALSE)),NOT(IF(ISNUMBER(G15),G15>=0,FALSE))),"valor ou horas inválidos",IF(G15=0,"",F15/G15))) -> 170 | I15: =IF(OR(NOT(ISNUMBER(H15)),NOT(ISNUMBER(Config!$B$12))),"",IF(Config!$B$12=0,"sem base (mínimo zero)",H15/Config!$B$12-1)) -> 0.32936994 | J15: =IF(H15="","",IF(NOT(ISNUMBER(H15)),H15,IF(NOT(ISNUMBER(Config!$B$12)),Config!$B$12,IF(NOT(ISNUMBER(Config!$B$13)),Config!$B$13,IF(H15<Config!$B$12,"Abaixo do mínimo",IF(H15<Config!$B$13,"Na faixa","Acima do alvo")))))) -> Acima do alvo | K15: =IF(OR(NOT(ISNUMBER(H15)),NOT(ISNUMBER(Config!$B$12))),"",MAX(0,Config!$B$12*G15-F15)) -> 0 | L15: =IF(K15="","",K15+ROW()/1000000) -> 1.5e-05
A16: CONS-2025-05 | B16: Clínica Bem-Estar | C16: Empresarial | D16: Hora | E16: Consultivo | F16: 21600 | G16: 120 | H16: =IF(OR(A16="",G16="",F16=""),"",IF(OR(NOT(IF(ISNUMBER(F16),F16>=0,FALSE)),NOT(IF(ISNUMBER(G16),G16>=0,FALSE))),"valor ou horas inválidos",IF(G16=0,"",F16/G16))) -> 180 | I16: =IF(OR(NOT(ISNUMBER(H16)),NOT(ISNUMBER(Config!$B$12))),"",IF(Config!$B$12=0,"sem base (mínimo zero)",H16/Config!$B$12-1)) -> 0.40756818 | J16: =IF(H16="","",IF(NOT(ISNUMBER(H16)),H16,IF(NOT(ISNUMBER(Config!$B$12)),Config!$B$12,IF(NOT(ISNUMBER(Config!$B$13)),Config!$B$13,IF(H16<Config!$B$12,"Abaixo do mínimo",IF(H16<Config!$B$13,"Na faixa","Acima do alvo")))))) -> Acima do alvo | K16: =IF(OR(NOT(ISNUMBER(H16)),NOT(ISNUMBER(Config!$B$12))),"",MAX(0,Config!$B$12*G16-F16)) -> 0 | L16: =IF(K16="","",K16+ROW()/1000000) -> 1.6e-05
... A42: 9420478-99.2025.8.26.0491 | B42: Ana Beatriz Moreira | C42: Trabalhista | D42: Misto | E42: Encerrado | F42: 8500 | G42: 70 | H42: =IF(OR(A42="",G42="",F42=""),"",IF(OR(NOT(IF(ISNUMBER(F42),F42>=0,FALSE)),NOT(IF(ISNUMBER(G42),G42>=0,FALSE))),"valor ou horas inválidos",IF(G42=0,"",F42/G42))) -> 121.42857 | I42: =IF(OR(NOT(ISNUMBER(H42)),NOT(ISNUMBER(Config!$B$12))),"",IF(Config!$B$12=0,"sem base (mínimo zero)",H42/Config!$B$12-1)) -> -0.05045004 | J42: =IF(H42="","",IF(NOT(ISNUMBER(H42)),H42,IF(NOT(ISNUMBER(Config!$B$12)),Config!$B$12,IF(NOT(ISNUMBER(Config!$B$13)),Config!$B$13,IF(H42<Config!$B$12,"Abaixo do mínimo",IF(H42<Config!$B$13,"Na faixa","Acima do alvo")))))) -> Abaixo do mínimo | K42: =IF(OR(NOT(ISNUMBER(H42)),NOT(ISNUMBER(Config!$B$12))),"",MAX(0,Config!$B$12*G42-F42)) -> 451.60903 | L42: =IF(K42="","",K42+ROW()/1000000) -> 451.60907
H43: =IF(OR(A43="",G43="",F43=""),"",IF(OR(NOT(IF(ISNUMBER(F43),F43>=0,FALSE)),NOT(IF(ISNUMBER(G43),G43>=0,FALSE))),"valor ou horas inválidos",IF(G43=0,"",F43/G43))) | I43: =IF(OR(NOT(ISNUMBER(H43)),NOT(ISNUMBER(Config!$B$12))),"",IF(Config!$B$12=0,"sem base (mínimo zero)",H43/Config!$B$12-1)) | J43: =IF(H43="","",IF(NOT(ISNUMBER(H43)),H43,IF(NOT(ISNUMBER(Config!$B$12)),Config!$B$12,IF(NOT(ISNUMBER(Config!$B$13)),Config!$B$13,IF(H43<Config!$B$12,"Abaixo do mínimo",IF(H43<Config!$B$13,"Na faixa","Acima do alvo")))))) | K43: =IF(OR(NOT(ISNUMBER(H43)),NOT(ISNUMBER(Config!$B$12))),"",MAX(0,Config!$B$12*G43-F43)) | L43: =IF(K43="","",K43+ROW()/1000000)
H44: =IF(OR(A44="",G44="",F44=""),"",IF(OR(NOT(IF(ISNUMBER(F44),F44>=0,FALSE)),NOT(IF(ISNUMBER(G44),G44>=0,FALSE))),"valor ou horas inválidos",IF(G44=0,"",F44/G44))) | I44: =IF(OR(NOT(ISNUMBER(H44)),NOT(ISNUMBER(Config!$B$12))),"",IF(Config!$B$12=0,"sem base (mínimo zero)",H44/Config!$B$12-1)) | J44: =IF(H44="","",IF(NOT(ISNUMBER(H44)),H44,IF(NOT(ISNUMBER(Config!$B$12)),Config!$B$12,IF(NOT(ISNUMBER(Config!$B$13)),Config!$B$13,IF(H44<Config!$B$12,"Abaixo do mínimo",IF(H44<Config!$B$13,"Na faixa","Acima do alvo")))))) | K44: =IF(OR(NOT(ISNUMBER(H44)),NOT(ISNUMBER(Config!$B$12))),"",MAX(0,Config!$B$12*G44-F44)) | L44: =IF(K44="","",K44+ROW()/1000000)
H45: =IF(OR(A45="",G45="",F45=""),"",IF(OR(NOT(IF(ISNUMBER(F45),F45>=0,FALSE)),NOT(IF(ISNUMBER(G45),G45>=0,FALSE))),"valor ou horas inválidos",IF(G45=0,"",F45/G45))) | I45: =IF(OR(NOT(ISNUMBER(H45)),NOT(ISNUMBER(Config!$B$12))),"",IF(Config!$B$12=0,"sem base (mínimo zero)",H45/Config!$B$12-1)) | J45: =IF(H45="","",IF(NOT(ISNUMBER(H45)),H45,IF(NOT(ISNUMBER(Config!$B$12)),Config!$B$12,IF(NOT(ISNUMBER(Config!$B$13)),Config!$B$13,IF(H45<Config!$B$12,"Abaixo do mínimo",IF(H45<Config!$B$13,"Na faixa","Acima do alvo")))))) | K45: =IF(OR(NOT(ISNUMBER(H45)),NOT(ISNUMBER(Config!$B$12))),"",MAX(0,Config!$B$12*G45-F45)) | L45: =IF(K45="","",K45+ROW()/1000000)
H46: =IF(OR(A46="",G46="",F46=""),"",IF(OR(NOT(IF(ISNUMBER(F46),F46>=0,FALSE)),NOT(IF(ISNUMBER(G46),G46>=0,FALSE))),"valor ou horas inválidos",IF(G46=0,"",F46/G46))) | I46: =IF(OR(NOT(ISNUMBER(H46)),NOT(ISNUMBER(Config!$B$12))),"",IF(Config!$B$12=0,"sem base (mínimo zero)",H46/Config!$B$12-1)) | J46: =IF(H46="","",IF(NOT(ISNUMBER(H46)),H46,IF(NOT(ISNUMBER(Config!$B$12)),Config!$B$12,IF(NOT(ISNUMBER(Config!$B$13)),Config!$B$13,IF(H46<Config!$B$12,"Abaixo do mínimo",IF(H46<Config!$B$13,"Na faixa","Acima do alvo")))))) | K46: =IF(OR(NOT(ISNUMBER(H46)),NOT(ISNUMBER(Config!$B$12))),"",MAX(0,Config!$B$12*G46-F46)) | L46: =IF(K46="","",K46+ROW()/1000000)
H47: =IF(OR(A47="",G47="",F47=""),"",IF(OR(NOT(IF(ISNUMBER(F47),F47>=0,FALSE)),NOT(IF(ISNUMBER(G47),G47>=0,FALSE))),"valor ou horas inválidos",IF(G47=0,"",F47/G47))) | I47: =IF(OR(NOT(ISNUMBER(H47)),NOT(ISNUMBER(Config!$B$12))),"",IF(Config!$B$12=0,"sem base (mínimo zero)",H47/Config!$B$12-1)) | J47: =IF(H47="","",IF(NOT(ISNUMBER(H47)),H47,IF(NOT(ISNUMBER(Config!$B$12)),Config!$B$12,IF(NOT(ISNUMBER(Config!$B$13)),Config!$B$13,IF(H47<Config!$B$12,"Abaixo do mínimo",IF(H47<Config!$B$13,"Na faixa","Acima do alvo")))))) | K47: =IF(OR(NOT(ISNUMBER(H47)),NOT(ISNUMBER(Config!$B$12))),"",MAX(0,Config!$B$12*G47-F47)) | L47: =IF(K47="","",K47+ROW()/1000000)
