Workbook

Sheet Como usar
A1: Parcelas e Inadimplência
A2: Kit de Gestão para Advogados · Seu Sócio Gestor · versão 1.0 (setembro de 2026)
A4: O que esta planilha faz | B4: Você lança as parcelas combinadas com cada cliente e marca as pagas; ela mostra o que vence nos próximos dias, o que já venceu por faixa de atraso, a inadimplência e a lista de quem cobrar primeiro, com a ação sugerida da régua de cobrança.
A5: Passo 1 | B5: Em Config, ajuste as janelas (7 e 30 dias) e a régua: a partir de quantos dias de atraso fazer o quê. Escreva as ações do seu jeito, educadas e diretas.
A6: Passo 2 | B6: Em Casos, cole a lista de casos da planilha 13 · Carteira (número, cliente, modalidade, valor contratado); a 13 é a fonte do cadastro. É a lista que alimenta a escolha do caso em Parcelas.
A7: Passo 3 | B7: Em Parcelas, uma linha por parcela: caso, número da parcela, vencimento e valor. Quando receber, marque Pago? = Sim e a data do pagamento, e lance a mesma entrada no caixa (planilha 09). Honorário por hora entra como fatura mensal; êxito, só no fim do caso.
A8: Passo 4 | B8: Em Painel, veja o que vence em 7 e 30 dias, o vencido por faixa, a inadimplência (vencido ÷ (pago + vencido), a mesma conta das planilhas 17, 19 e 20) e a lista "Cobrar primeiro" com o texto da régua para cada parcela.
A9: Rotina | B9: Segunda-feira, 10 minutos: conferir o extrato, marcar as pagas, mandar as mensagens da lista "Cobrar primeiro". Sexta: confirmar as que vencem na semana seguinte.
A10: Com a IA | B10: Copie uma linha de "Cobrar primeiro" (cliente, parcela, valor, dias, ação) e use o prompt "Clientes 03 · Cobrança educada em três versões" da biblioteca (ou "Clientes 02 · Quem cobrar primeiro" para a lista inteira) ou os 15 modelos de mensagem do bônus. Nunca cole dados que o cliente não autorizou compartilhar.
A11: Legenda | B11: Células amarelas: você preenche. Brancas: calculadas. Não é preciso mexer em nada fora do amarelo.
A12: Proteção | B12: Fórmulas protegidas sem senha. Para editar: Revisar > Desproteger planilha (Excel) ou Dados > Proteger intervalos (Google Sheets).
A13: Requisitos | B13: Excel 2016 ou mais novo, Microsoft 365 ou Google Sheets (só funções do Excel 2007+; nada de MÍNIMOSES, MÁXIMOSES ou UNIRTEXTO). No celular abre nos aplicativos; para preencher, use o computador.
A14: Google Sheets | B14: Faça upload no Google Drive e abra com o Google Sheets. Fórmulas, listas, cores, semáforos e gráficos funcionam: as regras de cor que dependem do mês escolhido em Config usam INDIRECT, que é a forma que o Sheets aceita para regra condicional apontar para outra aba.
A15: Exemplos | B15: Ferraz & Lima Advocacia é um escritório fictício. Clientes, processos, nomes e valores são inventados. Apague-os antes de começar.
... A17: Suporte | B17: suporte@seusociogestor.com.br · resposta em até 5 dias úteis · reembolso em até 7 dias pelo mesmo canal.

Sheet Painel
A1: =Config!$B$4&" · Parcelas e inadimplência · "&TEXT(DAY(Config!$B$5),"00")&"/"&TEXT(MONTH(Config!$B$5),"00")&"/"&YEAR(Config!$B$5) -> Ferraz & Lima Advocacia (exemplo fictício) · Parcelas e inadimplência · 14/09/2026
A2: Nada para digitar aqui: tudo vem de Parcelas e da régua em Config.
A4: ="Vence em até "&Config!$B$6&" dias" -> Vence em até 7 dias | C4: ="Vence em até "&Config!$B$7&" dias" -> Vence em até 30 dias | E4: Em aberto (total) | G4: Vencido (R$) | I4: Parcelas vencidas | K4: Inadimplência (vencido ÷ (pago + vencido))
A5: =SUMIFS(Parcelas!$E$5:$E$404,Parcelas!$H$5:$H$404,"A vencer",Parcelas!$J$5:$J$404,"<="&Config!$B$6) -> 2800 | C5: =SUMIFS(Parcelas!$E$5:$E$404,Parcelas!$H$5:$H$404,"A vencer",Parcelas!$J$5:$J$404,"<="&Config!$B$7) -> 15450 | E5: =SUMIFS(Parcelas!$E$5:$E$404,Parcelas!$H$5:$H$404,"A vencer")+SUMIFS(Parcelas!$E$5:$E$404,Parcelas!$H$5:$H$404,"Vencida") -> 55330 | G5: =SUMIFS(Parcelas!$E$5:$E$404,Parcelas!$H$5:$H$404,"Vencida") -> 13080 | I5: =COUNTIFS(Parcelas!$H$5:$H$404,"Vencida") -> 7 | K5: =IFERROR(G5/(G5+SUMIFS(Parcelas!$E$5:$E$404,Parcelas!$H$5:$H$404,"Paga")),0) -> 0.045896347
A7: Inadimplência = vencido ÷ (pago + vencido): de tudo o que já venceu, quanto ainda não entrou. É a definição usada em todo o kit (17, 19, 20). Outra conta possível, vencido ÷ em aberto (vencido + a vencer), mede a carteira futura e dá um número maior; não a use para comparar com estas planilhas.
A9: Vencidas por faixa de atraso
A10: Faixa | B10: Parcelas | C10: Valor (R$) | D10: % do vencido | E10: Ação da régua
A11: =IF(Config!$C$10="","",Config!$C$10) -> 1 a 6 dias | B11: =IF(Config!$C$10="","",COUNTIFS(Parcelas!$K$5:$K$404,Config!$C$10)) -> 1 | C11: =IF(Config!$C$10="","",SUMIFS(Parcelas!$E$5:$E$404,Parcelas!$K$5:$K$404,Config!$C$10)) -> 1980 | D11: =IF(Config!$C$10="","",IFERROR(C11/$G$5,0)) -> 0.15137615 | E11: =IF(Config!$C$10="","",Config!$B$10) -> Lembrete gentil por WhatsApp ou e-mail: confirmar se o boleto ou o link de pagamento chegou e reenviar, se preciso.
A12: =IF(Config!$C$11="","",Config!$C$11) -> 7 a 14 dias | B12: =IF(Config!$C$11="","",COUNTIFS(Parcelas!$K$5:$K$404,Config!$C$11)) -> 0 | C12: =IF(Config!$C$11="","",SUMIFS(Parcelas!$E$5:$E$404,Parcelas!$K$5:$K$404,Config!$C$11)) -> 0 | D12: =IF(Config!$C$11="","",IFERROR(C12/$G$5,0)) -> 0 | E12: =IF(Config!$C$11="","",Config!$B$11) -> Mensagem do responsável pelo caso perguntando se houve algum imprevisto e oferecendo uma nova data para o pagamento.
A13: =IF(Config!$C$12="","",Config!$C$12) -> 15 a 29 dias | B13: =IF(Config!$C$12="","",COUNTIFS(Parcelas!$K$5:$K$404,Config!$C$12)) -> 1 | C13: =IF(Config!$C$12="","",SUMIFS(Parcelas!$E$5:$E$404,Parcelas!$K$5:$K$404,Config!$C$12)) -> 1500 | D13: =IF(Config!$C$12="","",IFERROR(C13/$G$5,0)) -> 0.1146789 | E13: =IF(Config!$C$12="","",Config!$B$12) -> E-mail com o demonstrativo das parcelas em aberto e proposta de renegociação (nova data ou divisão do valor).
A14: =IF(Config!$C$13="","",Config!$C$13) -> 30 dias ou mais | B14: =IF(Config!$C$13="","",COUNTIFS(Parcelas!$K$5:$K$404,Config!$C$13)) -> 5 | C14: =IF(Config!$C$13="","",SUMIFS(Parcelas!$E$5:$E$404,Parcelas!$K$5:$K$404,Config!$C$13)) -> 9600 | D14: =IF(Config!$C$13="","",IFERROR(C14/$G$5,0)) -> 0.73394495 | E14: =IF(Config!$C$13="","",Config!$B$13) -> Ligação ou reunião para combinar um plano de pagamento; registrar por escrito o que foi combinado e a nova data.
A15: Antes da régua | B15: =COUNTIFS(Parcelas!$K$5:$K$404,"Antes da régua") -> 0 | C15: =SUMIFS(Parcelas!$E$5:$E$404,Parcelas!$K$5:$K$404,"Antes da régua") -> 0 | D15: =IFERROR(C15/$G$5,0) -> 0 | E15: Vencidas há menos dias que o primeiro passo da régua.
A17: Cobrar primeiro
A18: Parcelas vencidas em ordem de valor × dias de atraso: as que mais pesam no caixa vêm no topo. O texto da última coluna é a ação da régua para a faixa de cada uma.
A19: # | B19: Cliente | C19: Caso | D19: Parcela | E19: Vencimento | F19: Valor (R$) | G19: Dias de atraso | H19: Faixa | I19: Ação sugerida
A20: 1 | B20: =IFERROR(IF(LARGE(Parcelas!$M$5:$M$404,1)>0,INDEX(Parcelas!$B$5:$B$404,MATCH(LARGE(Parcelas!$M$5:$M$404,1),Parcelas!$M$5:$M$404,0)),""),"") -> Bistrô 42 | C20: =IFERROR(IF(LARGE(Parcelas!$M$5:$M$404,1)>0,INDEX(Parcelas!$A$5:$A$404,MATCH(LARGE(Parcelas!$M$5:$M$404,1),Parcelas!$M$5:$M$404,0)),""),"") -> 8056747-83.2026.8.26.0561 | D20: =IFERROR(IF(LARGE(Parcelas!$M$5:$M$404,1)>0,INDEX(Parcelas!$C$5:$C$404,MATCH(LARGE(Parcelas!$M$5:$M$404,1),Parcelas!$M$5:$M$404,0)),""),"") -> 3 | E20: =IFERROR(IF(LARGE(Parcelas!$M$5:$M$404,1)>0,INDEX(Parcelas!$D$5:$D$404,MATCH(LARGE(Parcelas!$M$5:$M$404,1),Parcelas!$M$5:$M$404,0)),""),"") -> 46099 | F20: =IFERROR(IF(LARGE(Parcelas!$M$5:$M$404,1)>0,INDEX(Parcelas!$E$5:$E$404,MATCH(LARGE(Parcelas!$M$5:$M$404,1),Parcelas!$M$5:$M$404,0)),""),"") -> 2100 | G20: =IFERROR(IF(LARGE(Parcelas!$M$5:$M$404,1)>0,INDEX(Parcelas!$I$5:$I$404,MATCH(LARGE(Parcelas!$M$5:$M$404,1),Parcelas!$M$5:$M$404,0)),""),"") -> 180 | H20: =IFERROR(IF(LARGE(Parcelas!$M$5:$M$404,1)>0,INDEX(Parcelas!$K$5:$K$404,MATCH(LARGE(Parcelas!$M$5:$M$404,1),Parcelas!$M$5:$M$404,0)),""),"") -> 30 dias ou mais | I20: =IFERROR(IF(LARGE(Parcelas!$M$5:$M$404,1)>0,INDEX(Parcelas!$L$5:$L$404,MATCH(LARGE(Parcelas!$M$5:$M$404,1),Parcelas!$M$5:$M$404,0)),""),"") -> Ligação ou reunião para combinar um plano de pagamento; registrar por escrito o que foi combinado e a nova data.
A21: 2 | B21: =IFERROR(IF(LARGE(Parcelas!$M$5:$M$404,2)>0,INDEX(Parcelas!$B$5:$B$404,MATCH(LARGE(Parcelas!$M$5:$M$404,2),Parcelas!$M$5:$M$404,0)),""),"") -> Bistrô 42 | C21: =IFERROR(IF(LARGE(Parcelas!$M$5:$M$404,2)>0,INDEX(Parcelas!$A$5:$A$404,MATCH(LARGE(Parcelas!$M$5:$M$404,2),Parcelas!$M$5:$M$404,0)),""),"") -> 8056747-83.2026.8.26.0561 | D21: =IFERROR(IF(LARGE(Parcelas!$M$5:$M$404,2)>0,INDEX(Parcelas!$C$5:$C$404,MATCH(LARGE(Parcelas!$M$5:$M$404,2),Parcelas!$M$5:$M$404,0)),""),"") -> 4 | E21: =IFERROR(IF(LARGE(Parcelas!$M$5:$M$404,2)>0,INDEX(Parcelas!$D$5:$D$404,MATCH(LARGE(Parcelas!$M$5:$M$404,2),Parcelas!$M$5:$M$404,0)),""),"") -> 46129 | F21: =IFERROR(IF(LARGE(Parcelas!$M$5:$M$404,2)>0,INDEX(Parcelas!$E$5:$E$404,MATCH(LARGE(Parcelas!$M$5:$M$404,2),Parcelas!$M$5:$M$404,0)),""),"") -> 2100 | G21: =IFERROR(IF(LARGE(Parcelas!$M$5:$M$404,2)>0,INDEX(Parcelas!$I$5:$I$404,MATCH(LARGE(Parcelas!$M$5:$M$404,2),Parcelas!$M$5:$M$404,0)),""),"") -> 150 | H21: =IFERROR(IF(LARGE(Parcelas!$M$5:$M$404,2)>0,INDEX(Parcelas!$K$5:$K$404,MATCH(LARGE(Parcelas!$M$5:$M$404,2),Parcelas!$M$5:$M$404,0)),""),"") -> 30 dias ou mais | I21: =IFERROR(IF(LARGE(Parcelas!$M$5:$M$404,2)>0,INDEX(Parcelas!$L$5:$L$404,MATCH(LARGE(Parcelas!$M$5:$M$404,2),Parcelas!$M$5:$M$404,0)),""),"") -> Ligação ou reunião para combinar um plano de pagamento; registrar por escrito o que foi combinado e a nova data.
A22: 3 | B22: =IFERROR(IF(LARGE(Parcelas!$M$5:$M$404,3)>0,INDEX(Parcelas!$B$5:$B$404,MATCH(LARGE(Parcelas!$M$5:$M$404,3),Parcelas!$M$5:$M$404,0)),""),"") -> Oficina Mecânica Central | C22: =IFERROR(IF(LARGE(Parcelas!$M$5:$M$404,3)>0,INDEX(Parcelas!$A$5:$A$404,MATCH(LARGE(Parcelas!$M$5:$M$404,3),Parcelas!$M$5:$M$404,0)),""),"") -> 6184138-13.2026.8.26.0378 | D22: =IFERROR(IF(LARGE(Parcelas!$M$5:$M$404,3)>0,INDEX(Parcelas!$C$5:$C$404,MATCH(LARGE(Parcelas!$M$5:$M$404,3),Parcelas!$M$5:$M$404,0)),""),"") -> 3 | E22: =IFERROR(IF(LARGE(Parcelas!$M$5:$M$404,3)>0,INDEX(Parcelas!$D$5:$D$404,MATCH(LARGE(Parcelas!$M$5:$M$404,3),Parcelas!$M$5:$M$404,0)),""),"") -> 46192 | F22: =IFERROR(IF(LARGE(Parcelas!$M$5:$M$404,3)>0,INDEX(Parcelas!$E$5:$E$404,MATCH(LARGE(Parcelas!$M$5:$M$404,3),Parcelas!$M$5:$M$404,0)),""),"") -> 1500 | G22: =IFERROR(IF(LARGE(Parcelas!$M$5:$M$404,3)>0,INDEX(Parcelas!$I$5:$I$404,MATCH(LARGE(Parcelas!$M$5:$M$404,3),Parcelas!$M$5:$M$404,0)),""),"") -> 87 | H22: =IFERROR(IF(LARGE(Parcelas!$M$5:$M$404,3)>0,INDEX(Parcelas!$K$5:$K$404,MATCH(LARGE(Parcelas!$M$5:$M$404,3),Parcelas!$M$5:$M$404,0)),""),"") -> 30 dias ou mais | I22: =IFERROR(IF(LARGE(Parcelas!$M$5:$M$404,3)>0,INDEX(Parcelas!$L$5:$L$404,MATCH(LARGE(Parcelas!$M$5:$M$404,3),Parcelas!$M$5:$M$404,0)),""),"") -> Ligação ou reunião para combinar um plano de pagamento; registrar por escrito o que foi combinado e a nova data.
A23: 4 | B23: =IFERROR(IF(LARGE(Parcelas!$M$5:$M$404,4)>0,INDEX(Parcelas!$B$5:$B$404,MATCH(LARGE(Parcelas!$M$5:$M$404,4),Parcelas!$M$5:$M$404,0)),""),"") -> Patrícia Gomes | C23: =IFERROR(IF(LARGE(Parcelas!$M$5:$M$404,4)>0,INDEX(Parcelas!$A$5:$A$404,MATCH(LARGE(Parcelas!$M$5:$M$404,4),Parcelas!$M$5:$M$404,0)),""),"") -> 9616569-91.2026.8.26.0079 | D23: =IFERROR(IF(LARGE(Parcelas!$M$5:$M$404,4)>0,INDEX(Parcelas!$C$5:$C$404,MATCH(LARGE(Parcelas!$M$5:$M$404,4),Parcelas!$M$5:$M$404,0)),""),"") -> 3 | E23: =IFERROR(IF(LARGE(Parcelas!$M$5:$M$404,4)>0,INDEX(Parcelas!$D$5:$D$404,MATCH(LARGE(Parcelas!$M$5:$M$404,4),Parcelas!$M$5:$M$404,0)),""),"") -> 46248 | F23: =IFERROR(IF(LARGE(Parcelas!$M$5:$M$404,4)>0,INDEX(Parcelas!$E$5:$E$404,MATCH(LARGE(Parcelas!$M$5:$M$404,4),Parcelas!$M$5:$M$404,0)),""),"") -> 2100 | G23: =IFERROR(IF(LARGE(Parcelas!$M$5:$M$404,4)>0,INDEX(Parcelas!$I$5:$I$404,MATCH(LARGE(Parcelas!$M$5:$M$404,4),Parcelas!$M$5:$M$404,0)),""),"") -> 31 | H23: =IFERROR(IF(LARGE(Parcelas!$M$5:$M$404,4)>0,INDEX(Parcelas!$K$5:$K$404,MATCH(LARGE(Parcelas!$M$5:$M$404,4),Parcelas!$M$5:$M$404,0)),""),"") -> 30 dias ou mais | I23: =IFERROR(IF(LARGE(Parcelas!$M$5:$M$404,4)>0,INDEX(Parcelas!$L$5:$L$404,MATCH(LARGE(Parcelas!$M$5:$M$404,4),Parcelas!$M$5:$M$404,0)),""),"") -> Ligação ou reunião para combinar um plano de pagamento; registrar por escrito o que foi combinado e a nova data.
A24: 5 | B24: =IFERROR(IF(LARGE(Parcelas!$M$5:$M$404,5)>0,INDEX(Parcelas!$B$5:$B$404,MATCH(LARGE(Parcelas!$M$5:$M$404,5),Parcelas!$M$5:$M$404,0)),""),"") -> Agência Prisma | C24: =IFERROR(IF(LARGE(Parcelas!$M$5:$M$404,5)>0,INDEX(Parcelas!$A$5:$A$404,MATCH(LARGE(Parcelas!$M$5:$M$404,5),Parcelas!$M$5:$M$404,0)),""),"") -> 9362688-24.2025.8.26.0436 | D24: =IFERROR(IF(LARGE(Parcelas!$M$5:$M$404,5)>0,INDEX(Parcelas!$C$5:$C$404,MATCH(LARGE(Parcelas!$M$5:$M$404,5),Parcelas!$M$5:$M$404,0)),""),"") -> 8 | E24: =IFERROR(IF(LARGE(Parcelas!$M$5:$M$404,5)>0,INDEX(Parcelas!$D$5:$D$404,MATCH(LARGE(Parcelas!$M$5:$M$404,5),Parcelas!$M$5:$M$404,0)),""),"") -> 46244 | F24: =IFERROR(IF(LARGE(Parcelas!$M$5:$M$404,5)>0,INDEX(Parcelas!$E$5:$E$404,MATCH(LARGE(Parcelas!$M$5:$M$404,5),Parcelas!$M$5:$M$404,0)),""),"") -> 1800 | G24: =IFERROR(IF(LARGE(Parcelas!$M$5:$M$404,5)>0,INDEX(Parcelas!$I$5:$I$404,MATCH(LARGE(Parcelas!$M$5:$M$404,5),Parcelas!$M$5:$M$404,0)),""),"") -> 35 | H24: =IFERROR(IF(LARGE(Parcelas!$M$5:$M$404,5)>0,INDEX(Parcelas!$K$5:$K$404,MATCH(LARGE(Parcelas!$M$5:$M$404,5),Parcelas!$M$5:$M$404,0)),""),"") -> 30 dias ou mais | I24: =IFERROR(IF(LARGE(Parcelas!$M$5:$M$404,5)>0,INDEX(Parcelas!$L$5:$L$404,MATCH(LARGE(Parcelas!$M$5:$M$404,5),Parcelas!$M$5:$M$404,0)),""),"") -> Ligação ou reunião para combinar um plano de pagamento; registrar por escrito o que foi combinado e a nova data.
A25: 6 | B25: =IFERROR(IF(LARGE(Parcelas!$M$5:$M$404,6)>0,INDEX(Parcelas!$B$5:$B$404,MATCH(LARGE(Parcelas!$M$5:$M$404,6),Parcelas!$M$5:$M$404,0)),""),"") -> Helena Duarte | C25: =IFERROR(IF(LARGE(Parcelas!$M$5:$M$404,6)>0,INDEX(Parcelas!$A$5:$A$404,MATCH(LARGE(Parcelas!$M$5:$M$404,6),Parcelas!$M$5:$M$404,0)),""),"") -> 7679821-77.2026.8.26.0265 | D25: =IFERROR(IF(LARGE(Parcelas!$M$5:$M$404,6)>0,INDEX(Parcelas!$C$5:$C$404,MATCH(LARGE(Parcelas!$M$5:$M$404,6),Parcelas!$M$5:$M$404,0)),""),"") -> 3 | E25: =IFERROR(IF(LARGE(Parcelas!$M$5:$M$404,6)>0,INDEX(Parcelas!$D$5:$D$404,MATCH(LARGE(Parcelas!$M$5:$M$404,6),Parcelas!$M$5:$M$404,0)),""),"") -> 46262 | F25: =IFERROR(IF(LARGE(Parcelas!$M$5:$M$404,6)>0,INDEX(Parcelas!$E$5:$E$404,MATCH(LARGE(Parcelas!$M$5:$M$404,6),Parcelas!$M$5:$M$404,0)),""),"") -> 1500 | G25: =IFERROR(IF(LARGE(Parcelas!$M$5:$M$404,6)>0,INDEX(Parcelas!$I$5:$I$404,MATCH(LARGE(Parcelas!$M$5:$M$404,6),Parcelas!$M$5:$M$404,0)),""),"") -> 17 | H25: =IFERROR(IF(LARGE(Parcelas!$M$5:$M$404,6)>0,INDEX(Parcelas!$K$5:$K$404,MATCH(LARGE(Parcelas!$M$5:$M$404,6),Parcelas!$M$5:$M$404,0)),""),"") -> 15 a 29 dias | I25: =IFERROR(IF(LARGE(Parcelas!$M$5:$M$404,6)>0,INDEX(Parcelas!$L$5:$L$404,MATCH(LARGE(Parcelas!$M$5:$M$404,6),Parcelas!$M$5:$M$404,0)),""),"") -> E-mail com o demonstrativo das parcelas em aberto e proposta de renegociação (nova data ou divisão do valor).
A26: 7 | B26: =IFERROR(IF(LARGE(Parcelas!$M$5:$M$404,7)>0,INDEX(Parcelas!$B$5:$B$404,MATCH(LARGE(Parcelas!$M$5:$M$404,7),Parcelas!$M$5:$M$404,0)),""),"") -> Agência Prisma | C26: =IFERROR(IF(LARGE(Parcelas!$M$5:$M$404,7)>0,INDEX(Parcelas!$A$5:$A$404,MATCH(LARGE(Parcelas!$M$5:$M$404,7),Parcelas!$M$5:$M$404,0)),""),"") -> 9362688-24.2025.8.26.0436 | D26: =IFERROR(IF(LARGE(Parcelas!$M$5:$M$404,7)>0,INDEX(Parcelas!$C$5:$C$404,MATCH(LARGE(Parcelas!$M$5:$M$404,7),Parcelas!$M$5:$M$404,0)),""),"") -> 9 | E26: =IFERROR(IF(LARGE(Parcelas!$M$5:$M$404,7)>0,INDEX(Parcelas!$D$5:$D$404,MATCH(LARGE(Parcelas!$M$5:$M$404,7),Parcelas!$M$5:$M$404,0)),""),"") -> 46275 | F26: =IFERROR(IF(LARGE(Parcelas!$M$5:$M$404,7)>0,INDEX(Parcelas!$E$5:$E$404,MATCH(LARGE(Parcelas!$M$5:$M$404,7),Parcelas!$M$5:$M$404,0)),""),"") -> 1980 | G26: =IFERROR(IF(LARGE(Parcelas!$M$5:$M$404,7)>0,INDEX(Parcelas!$I$5:$I$404,MATCH(LARGE(Parcelas!$M$5:$M$404,7),Parcelas!$M$5:$M$404,0)),""),"") -> 4 | H26: =IFERROR(IF(LARGE(Parcelas!$M$5:$M$404,7)>0,INDEX(Parcelas!$K$5:$K$404,MATCH(LARGE(Parcelas!$M$5:$M$404,7),Parcelas!$M$5:$M$404,0)),""),"") -> 1 a 6 dias | I26: =IFERROR(IF(LARGE(Parcelas!$M$5:$M$404,7)>0,INDEX(Parcelas!$L$5:$L$404,MATCH(LARGE(Parcelas!$M$5:$M$404,7),Parcelas!$M$5:$M$404,0)),""),"") -> Lembrete gentil por WhatsApp ou e-mail: confirmar se o boleto ou o link de pagamento chegou e reenviar, se preciso.
A27: 8 | B27: =IFERROR(IF(LARGE(Parcelas!$M$5:$M$404,8)>0,INDEX(Parcelas!$B$5:$B$404,MATCH(LARGE(Parcelas!$M$5:$M$404,8),Parcelas!$M$5:$M$404,0)),""),"") | C27: =IFERROR(IF(LARGE(Parcelas!$M$5:$M$404,8)>0,INDEX(Parcelas!$A$5:$A$404,MATCH(LARGE(Parcelas!$M$5:$M$404,8),Parcelas!$M$5:$M$404,0)),""),"") | D27: =IFERROR(IF(LARGE(Parcelas!$M$5:$M$404,8)>0,INDEX(Parcelas!$C$5:$C$404,MATCH(LARGE(Parcelas!$M$5:$M$404,8),Parcelas!$M$5:$M$404,0)),""),"") | E27: =IFERROR(IF(LARGE(Parcelas!$M$5:$M$404,8)>0,INDEX(Parcelas!$D$5:$D$404,MATCH(LARGE(Parcelas!$M$5:$M$404,8),Parcelas!$M$5:$M$404,0)),""),"") | F27: =IFERROR(IF(LARGE(Parcelas!$M$5:$M$404,8)>0,INDEX(Parcelas!$E$5:$E$404,MATCH(LARGE(Parcelas!$M$5:$M$404,8),Parcelas!$M$5:$M$404,0)),""),"") | G27: =IFERROR(IF(LARGE(Parcelas!$M$5:$M$404,8)>0,INDEX(Parcelas!$I$5:$I$404,MATCH(LARGE(Parcelas!$M$5:$M$404,8),Parcelas!$M$5:$M$404,0)),""),"") | H27: =IFERROR(IF(LARGE(Parcelas!$M$5:$M$404,8)>0,INDEX(Parcelas!$K$5:$K$404,MATCH(LARGE(Parcelas!$M$5:$M$404,8),Parcelas!$M$5:$M$404,0)),""),"") | I27: =IFERROR(IF(LARGE(Parcelas!$M$5:$M$404,8)>0,INDEX(Parcelas!$L$5:$L$404,MATCH(LARGE(Parcelas!$M$5:$M$404,8),Parcelas!$M$5:$M$404,0)),""),"")
A28: 9 | B28: =IFERROR(IF(LARGE(Parcelas!$M$5:$M$404,9)>0,INDEX(Parcelas!$B$5:$B$404,MATCH(LARGE(Parcelas!$M$5:$M$404,9),Parcelas!$M$5:$M$404,0)),""),"") | C28: =IFERROR(IF(LARGE(Parcelas!$M$5:$M$404,9)>0,INDEX(Parcelas!$A$5:$A$404,MATCH(LARGE(Parcelas!$M$5:$M$404,9),Parcelas!$M$5:$M$404,0)),""),"") | D28: =IFERROR(IF(LARGE(Parcelas!$M$5:$M$404,9)>0,INDEX(Parcelas!$C$5:$C$404,MATCH(LARGE(Parcelas!$M$5:$M$404,9),Parcelas!$M$5:$M$404,0)),""),"") | E28: =IFERROR(IF(LARGE(Parcelas!$M$5:$M$404,9)>0,INDEX(Parcelas!$D$5:$D$404,MATCH(LARGE(Parcelas!$M$5:$M$404,9),Parcelas!$M$5:$M$404,0)),""),"") | F28: =IFERROR(IF(LARGE(Parcelas!$M$5:$M$404,9)>0,INDEX(Parcelas!$E$5:$E$404,MATCH(LARGE(Parcelas!$M$5:$M$404,9),Parcelas!$M$5:$M$404,0)),""),"") | G28: =IFERROR(IF(LARGE(Parcelas!$M$5:$M$404,9)>0,INDEX(Parcelas!$I$5:$I$404,MATCH(LARGE(Parcelas!$M$5:$M$404,9),Parcelas!$M$5:$M$404,0)),""),"") | H28: =IFERROR(IF(LARGE(Parcelas!$M$5:$M$404,9)>0,INDEX(Parcelas!$K$5:$K$404,MATCH(LARGE(Parcelas!$M$5:$M$404,9),Parcelas!$M$5:$M$404,0)),""),"") | I28: =IFERROR(IF(LARGE(Parcelas!$M$5:$M$404,9)>0,INDEX(Parcelas!$L$5:$L$404,MATCH(LARGE(Parcelas!$M$5:$M$404,9),Parcelas!$M$5:$M$404,0)),""),"")
A29: 10 | B29: =IFERROR(IF(LARGE(Parcelas!$M$5:$M$404,10)>0,INDEX(Parcelas!$B$5:$B$404,MATCH(LARGE(Parcelas!$M$5:$M$404,10),Parcelas!$M$5:$M$404,0)),""),"") | C29: =IFERROR(IF(LARGE(Parcelas!$M$5:$M$404,10)>0,INDEX(Parcelas!$A$5:$A$404,MATCH(LARGE(Parcelas!$M$5:$M$404,10),Parcelas!$M$5:$M$404,0)),""),"") | D29: =IFERROR(IF(LARGE(Parcelas!$M$5:$M$404,10)>0,INDEX(Parcelas!$C$5:$C$404,MATCH(LARGE(Parcelas!$M$5:$M$404,10),Parcelas!$M$5:$M$404,0)),""),"") | E29: =IFERROR(IF(LARGE(Parcelas!$M$5:$M$404,10)>0,INDEX(Parcelas!$D$5:$D$404,MATCH(LARGE(Parcelas!$M$5:$M$404,10),Parcelas!$M$5:$M$404,0)),""),"") | F29: =IFERROR(IF(LARGE(Parcelas!$M$5:$M$404,10)>0,INDEX(Parcelas!$E$5:$E$404,MATCH(LARGE(Parcelas!$M$5:$M$404,10),Parcelas!$M$5:$M$404,0)),""),"") | G29: =IFERROR(IF(LARGE(Parcelas!$M$5:$M$404,10)>0,INDEX(Parcelas!$I$5:$I$404,MATCH(LARGE(Parcelas!$M$5:$M$404,10),Parcelas!$M$5:$M$404,0)),""),"") | H29: =IFERROR(IF(LARGE(Parcelas!$M$5:$M$404,10)>0,INDEX(Parcelas!$K$5:$K$404,MATCH(LARGE(Parcelas!$M$5:$M$404,10),Parcelas!$M$5:$M$404,0)),""),"") | I29: =IFERROR(IF(LARGE(Parcelas!$M$5:$M$404,10)>0,INDEX(Parcelas!$L$5:$L$404,MATCH(LARGE(Parcelas!$M$5:$M$404,10),Parcelas!$M$5:$M$404,0)),""),"")
A31: Vencem nos próximos dias
A32: ="Parcelas a vencer em até "&Config!$B$7&" dias, a mais próxima primeiro. Bom momento para confirmar o pagamento antes do vencimento." -> Parcelas a vencer em até 30 dias, a mais próxima primeiro. Bom momento para confirmar o pagamento antes do vencimento.
A33: # | B33: Cliente | C33: Caso | D33: Parcela | E33: Vencimento | F33: Valor (R$) | G33: Dias para vencer
A34: 1 | B34: =IFERROR(IF(LARGE(Parcelas!$N$5:$N$404,1)>0,INDEX(Parcelas!$B$5:$B$404,MATCH(LARGE(Parcelas!$N$5:$N$404,1),Parcelas!$N$5:$N$404,0)),""),"") -> Loja Verde Comércio | C34: =IFERROR(IF(LARGE(Parcelas!$N$5:$N$404,1)>0,INDEX(Parcelas!$A$5:$A$404,MATCH(LARGE(Parcelas!$N$5:$N$404,1),Parcelas!$N$5:$N$404,0)),""),"") -> CONS-2026-02 | D34: =IFERROR(IF(LARGE(Parcelas!$N$5:$N$404,1)>0,INDEX(Parcelas!$C$5:$C$404,MATCH(LARGE(Parcelas!$N$5:$N$404,1),Parcelas!$N$5:$N$404,0)),""),"") -> 2 | E34: =IFERROR(IF(LARGE(Parcelas!$N$5:$N$404,1)>0,INDEX(Parcelas!$D$5:$D$404,MATCH(LARGE(Parcelas!$N$5:$N$404,1),Parcelas!$N$5:$N$404,0)),""),"") -> 46282 | F34: =IFERROR(IF(LARGE(Parcelas!$N$5:$N$404,1)>0,INDEX(Parcelas!$E$5:$E$404,MATCH(LARGE(Parcelas!$N$5:$N$404,1),Parcelas!$N$5:$N$404,0)),""),"") -> 2800 | G34: =IFERROR(IF(LARGE(Parcelas!$N$5:$N$404,1)>0,INDEX(Parcelas!$J$5:$J$404,MATCH(LARGE(Parcelas!$N$5:$N$404,1),Parcelas!$N$5:$N$404,0)),""),"") -> 3
A35: 2 | B35: =IFERROR(IF(LARGE(Parcelas!$N$5:$N$404,2)>0,INDEX(Parcelas!$B$5:$B$404,MATCH(LARGE(Parcelas!$N$5:$N$404,2),Parcelas!$N$5:$N$404,0)),""),"") -> Clínica Bem-Estar | C35: =IFERROR(IF(LARGE(Parcelas!$N$5:$N$404,2)>0,INDEX(Parcelas!$A$5:$A$404,MATCH(LARGE(Parcelas!$N$5:$N$404,2),Parcelas!$N$5:$N$404,0)),""),"") -> 2645033-67.2026.8.26.0012 | D35: =IFERROR(IF(LARGE(Parcelas!$N$5:$N$404,2)>0,INDEX(Parcelas!$C$5:$C$404,MATCH(LARGE(Parcelas!$N$5:$N$404,2),Parcelas!$N$5:$N$404,0)),""),"") -> 5 | E35: =IFERROR(IF(LARGE(Parcelas!$N$5:$N$404,2)>0,INDEX(Parcelas!$D$5:$D$404,MATCH(LARGE(Parcelas!$N$5:$N$404,2),Parcelas!$N$5:$N$404,0)),""),"") -> 46289 | F35: =IFERROR(IF(LARGE(Parcelas!$N$5:$N$404,2)>0,INDEX(Parcelas!$E$5:$E$404,MATCH(LARGE(Parcelas!$N$5:$N$404,2),Parcelas!$N$5:$N$404,0)),""),"") -> 2700 | G35: =IFERROR(IF(LARGE(Parcelas!$N$5:$N$404,2)>0,INDEX(Parcelas!$J$5:$J$404,MATCH(LARGE(Parcelas!$N$5:$N$404,2),Parcelas!$N$5:$N$404,0)),""),"") -> 10
A36: 3 | B36: =IFERROR(IF(LARGE(Parcelas!$N$5:$N$404,3)>0,INDEX(Parcelas!$B$5:$B$404,MATCH(LARGE(Parcelas!$N$5:$N$404,3),Parcelas!$N$5:$N$404,0)),""),"") -> Marcos Vinícius Teles | C36: =IFERROR(IF(LARGE(Parcelas!$N$5:$N$404,3)>0,INDEX(Parcelas!$A$5:$A$404,MATCH(LARGE(Parcelas!$N$5:$N$404,3),Parcelas!$N$5:$N$404,0)),""),"") -> CONS-2026-03 | D36: =IFERROR(IF(LARGE(Parcelas!$N$5:$N$404,3)>0,INDEX(Parcelas!$C$5:$C$404,MATCH(LARGE(Parcelas!$N$5:$N$404,3),Parcelas!$N$5:$N$404,0)),""),"") -> 2 | E36: =IFERROR(IF(LARGE(Parcelas!$N$5:$N$404,3)>0,INDEX(Parcelas!$D$5:$D$404,MATCH(LARGE(Parcelas!$N$5:$N$404,3),Parcelas!$N$5:$N$404,0)),""),"") -> 46290 | F36: =IFERROR(IF(LARGE(Parcelas!$N$5:$N$404,3)>0,INDEX(Parcelas!$E$5:$E$404,MATCH(LARGE(Parcelas!$N$5:$N$404,3),Parcelas!$N$5:$N$404,0)),""),"") -> 2250 | G36: =IFERROR(IF(LARGE(Parcelas!$N$5:$N$404,3)>0,INDEX(Parcelas!$J$5:$J$404,MATCH(LARGE(Parcelas!$N$5:$N$404,3),Parcelas!$N$5:$N$404,0)),""),"") -> 11
A37: 4 | B37: =IFERROR(IF(LARGE(Parcelas!$N$5:$N$404,4)>0,INDEX(Parcelas!$B$5:$B$404,MATCH(LARGE(Parcelas!$N$5:$N$404,4),Parcelas!$N$5:$N$404,0)),""),"") -> Construtora Horizonte | C37: =IFERROR(IF(LARGE(Parcelas!$N$5:$N$404,4)>0,INDEX(Parcelas!$A$5:$A$404,MATCH(LARGE(Parcelas!$N$5:$N$404,4),Parcelas!$N$5:$N$404,0)),""),"") -> 9586960-92.2026.8.26.0106 | D37: =IFERROR(IF(LARGE(Parcelas!$N$5:$N$404,4)>0,INDEX(Parcelas!$C$5:$C$404,MATCH(LARGE(Parcelas!$N$5:$N$404,4),Parcelas!$N$5:$N$404,0)),""),"") -> 3 | E37: =IFERROR(IF(LARGE(Parcelas!$N$5:$N$404,4)>0,INDEX(Parcelas!$D$5:$D$404,MATCH(LARGE(Parcelas!$N$5:$N$404,4),Parcelas!$N$5:$N$404,0)),""),"") -> 46293 | F37: =IFERROR(IF(LARGE(Parcelas!$N$5:$N$404,4)>0,INDEX(Parcelas!$E$5:$E$404,MATCH(LARGE(Parcelas!$N$5:$N$404,4),Parcelas!$N$5:$N$404,0)),""),"") -> 2100 | G37: =IFERROR(IF(LARGE(Parcelas!$N$5:$N$404,4)>0,INDEX(Parcelas!$J$5:$J$404,MATCH(LARGE(Parcelas!$N$5:$N$404,4),Parcelas!$N$5:$N$404,0)),""),"") -> 14
A38: 5 | B38: =IFERROR(IF(LARGE(Parcelas!$N$5:$N$404,5)>0,INDEX(Parcelas!$B$5:$B$404,MATCH(LARGE(Parcelas!$N$5:$N$404,5),Parcelas!$N$5:$N$404,0)),""),"") -> Helena Duarte | C38: =IFERROR(IF(LARGE(Parcelas!$N$5:$N$404,5)>0,INDEX(Parcelas!$A$5:$A$404,MATCH(LARGE(Parcelas!$N$5:$N$404,5),Parcelas!$N$5:$N$404,0)),""),"") -> 7679821-77.2026.8.26.0265 | D38: =IFERROR(IF(LARGE(Parcelas!$N$5:$N$404,5)>0,INDEX(Parcelas!$C$5:$C$404,MATCH(LARGE(Parcelas!$N$5:$N$404,5),Parcelas!$N$5:$N$404,0)),""),"") -> 4 | E38: =IFERROR(IF(LARGE(Parcelas!$N$5:$N$404,5)>0,INDEX(Parcelas!$D$5:$D$404,MATCH(LARGE(Parcelas!$N$5:$N$404,5),Parcelas!$N$5:$N$404,0)),""),"") -> 46293 | F38: =IFERROR(IF(LARGE(Parcelas!$N$5:$N$404,5)>0,INDEX(Parcelas!$E$5:$E$404,MATCH(LARGE(Parcelas!$N$5:$N$404,5),Parcelas!$N$5:$N$404,0)),""),"") -> 1500 | G38: =IFERROR(IF(LARGE(Parcelas!$N$5:$N$404,5)>0,INDEX(Parcelas!$J$5:$J$404,MATCH(LARGE(Parcelas!$N$5:$N$404,5),Parcelas!$N$5:$N$404,0)),""),"") -> 14
A39: 6 | B39: =IFERROR(IF(LARGE(Parcelas!$N$5:$N$404,6)>0,INDEX(Parcelas!$B$5:$B$404,MATCH(LARGE(Parcelas!$N$5:$N$404,6),Parcelas!$N$5:$N$404,0)),""),"") -> Carlos Eduardo Nunes | C39: =IFERROR(IF(LARGE(Parcelas!$N$5:$N$404,6)>0,INDEX(Parcelas!$A$5:$A$404,MATCH(LARGE(Parcelas!$N$5:$N$404,6),Parcelas!$N$5:$N$404,0)),""),"") -> 4746093-86.2026.8.26.0637 | D39: =IFERROR(IF(LARGE(Parcelas!$N$5:$N$404,6)>0,INDEX(Parcelas!$C$5:$C$404,MATCH(LARGE(Parcelas!$N$5:$N$404,6),Parcelas!$N$5:$N$404,0)),""),"") -> 3 | E39: =IFERROR(IF(LARGE(Parcelas!$N$5:$N$404,6)>0,INDEX(Parcelas!$D$5:$D$404,MATCH(LARGE(Parcelas!$N$5:$N$404,6),Parcelas!$N$5:$N$404,0)),""),"") -> 46295 | F39: =IFERROR(IF(LARGE(Parcelas!$N$5:$N$404,6)>0,INDEX(Parcelas!$E$5:$E$404,MATCH(LARGE(Parcelas!$N$5:$N$404,6),Parcelas!$N$5:$N$404,0)),""),"") -> 1500 | G39: =IFERROR(IF(LARGE(Parcelas!$N$5:$N$404,6)>0,INDEX(Parcelas!$J$5:$J$404,MATCH(LARGE(Parcelas!$N$5:$N$404,6),Parcelas!$N$5:$N$404,0)),""),"") -> 16
A40: 7 | B40: =IFERROR(IF(LARGE(Parcelas!$N$5:$N$404,7)>0,INDEX(Parcelas!$B$5:$B$404,MATCH(LARGE(Parcelas!$N$5:$N$404,7),Parcelas!$N$5:$N$404,0)),""),"") -> Padaria do Sol Ltda | C40: =IFERROR(IF(LARGE(Parcelas!$N$5:$N$404,7)>0,INDEX(Parcelas!$A$5:$A$404,MATCH(LARGE(Parcelas!$N$5:$N$404,7),Parcelas!$N$5:$N$404,0)),""),"") -> CONS-2026-01 | D40: =IFERROR(IF(LARGE(Parcelas!$N$5:$N$404,7)>0,INDEX(Parcelas!$C$5:$C$404,MATCH(LARGE(Parcelas!$N$5:$N$404,7),Parcelas!$N$5:$N$404,0)),""),"") -> 4 | E40: =IFERROR(IF(LARGE(Parcelas!$N$5:$N$404,7)>0,INDEX(Parcelas!$D$5:$D$404,MATCH(LARGE(Parcelas!$N$5:$N$404,7),Parcelas!$N$5:$N$404,0)),""),"") -> 46300 | F40: =IFERROR(IF(LARGE(Parcelas!$N$5:$N$404,7)>0,INDEX(Parcelas!$E$5:$E$404,MATCH(LARGE(Parcelas!$N$5:$N$404,7),Parcelas!$N$5:$N$404,0)),""),"") -> 1500 | G40: =IFERROR(IF(LARGE(Parcelas!$N$5:$N$404,7)>0,INDEX(Parcelas!$J$5:$J$404,MATCH(LARGE(Parcelas!$N$5:$N$404,7),Parcelas!$N$5:$N$404,0)),""),"") -> 21
A41: 8 | B41: =IFERROR(IF(LARGE(Parcelas!$N$5:$N$404,8)>0,INDEX(Parcelas!$B$5:$B$404,MATCH(LARGE(Parcelas!$N$5:$N$404,8),Parcelas!$N$5:$N$404,0)),""),"") -> Escola Aurora | C41: =IFERROR(IF(LARGE(Parcelas!$N$5:$N$404,8)>0,INDEX(Parcelas!$A$5:$A$404,MATCH(LARGE(Parcelas!$N$5:$N$404,8),Parcelas!$N$5:$N$404,0)),""),"") -> CONS-2026-04 | D41: =IFERROR(IF(LARGE(Parcelas!$N$5:$N$404,8)>0,INDEX(Parcelas!$C$5:$C$404,MATCH(LARGE(Parcelas!$N$5:$N$404,8),Parcelas!$N$5:$N$404,0)),""),"") -> 3 | E41: =IFERROR(IF(LARGE(Parcelas!$N$5:$N$404,8)>0,INDEX(Parcelas!$D$5:$D$404,MATCH(LARGE(Parcelas!$N$5:$N$404,8),Parcelas!$N$5:$N$404,0)),""),"") -> 46305 | F41: =IFERROR(IF(LARGE(Parcelas!$N$5:$N$404,8)>0,INDEX(Parcelas!$E$5:$E$404,MATCH(LARGE(Parcelas!$N$5:$N$404,8),Parcelas!$N$5:$N$404,0)),""),"") -> 1100 | G41: =IFERROR(IF(LARGE(Parcelas!$N$5:$N$404,8)>0,INDEX(Parcelas!$J$5:$J$404,MATCH(LARGE(Parcelas!$N$5:$N$404,8),Parcelas!$N$5:$N$404,0)),""),"") -> 26
A43: Fonte: aba Parcelas. A planilha avisa e sugere; a conversa com o cliente é sua.

Sheet Config
A1: Configurações e régua de cobrança
A2: Células amarelas: você preenche. A régua diz o que fazer em cada faixa de atraso; o texto aparece no Painel, parcela por parcela.
A4: Escritório | B4: Ferraz & Lima Advocacia (exemplo fictício)
A5: Data de referência (hoje) | B5: 46279
A6: Janela curta: vence em até (dias) | B6: 7
A7: Janela longa: vence em até (dias) | B7: 30
A9: A partir de (dias de atraso) | B9: Ação sugerida | C9: Faixa (calculada)
A10: 1 | B10: Lembrete gentil por WhatsApp ou e-mail: confirmar se o boleto ou o link de pagamento chegou e reenviar, se preciso. | C10: =IF(A10="","",IF(A11-1=A10,A10&" dia"&IF(A10>1,"s",""),A10&" a "&(A11-1)&" dias")) -> 1 a 6 dias
A11: 7 | B11: Mensagem do responsável pelo caso perguntando se houve algum imprevisto e oferecendo uma nova data para o pagamento. | C11: =IF(A11="","",IF(A12-1=A11,A11&" dia"&IF(A11>1,"s",""),A11&" a "&(A12-1)&" dias")) -> 7 a 14 dias
A12: 15 | B12: E-mail com o demonstrativo das parcelas em aberto e proposta de renegociação (nova data ou divisão do valor). | C12: =IF(A12="","",IF(A13-1=A12,A12&" dia"&IF(A12>1,"s",""),A12&" a "&(A13-1)&" dias")) -> 15 a 29 dias
A13: 30 | B13: Ligação ou reunião para combinar um plano de pagamento; registrar por escrito o que foi combinado e a nova data. | C13: =IF(A13="","",A13&" dias ou mais") -> 30 dias ou mais
A15: Os dias precisam estar em ordem crescente (ex.: 1, 7, 15, 30). Cada parcela vencida recebe a ação da maior faixa que ela já alcançou. Escreva as ações como você fala com o cliente: educado, direto e sem ameaça.
A16: Os modelos de mensagem do bônus "15 modelos de cobrança e confirmação" seguem esta mesma régua.

Sheet Casos
A1: Casos (entrada)
A2: Copie da planilha 13 · Carteira (aba Casos; a 13 é a fonte): número, cliente, modalidade e valor. As colunas brancas somam as parcelas de cada caso.
A4: Número do processo ou referência | B4: Cliente | C4: Modalidade | D4: Valor contratado (R$) | E4: Parcelas | F4: Valor em parcelas (R$) | G4: Pago (R$) | H4: Em aberto (R$) | I4: Vencido (R$) | J4: Diferença contratado − parcelas
A5: CONS-2026-01 | B5: Padaria do Sol Ltda | C5: Fixo | D5: 18000 | E5: =IF(A5="","",COUNTIFS(Parcelas!$A$5:$A$404,A5)) -> 12 | F5: =IF(A5="","",SUMIFS(Parcelas!$E$5:$E$404,Parcelas!$A$5:$A$404,A5)) -> 18000 | G5: =IF(A5="","",SUMIFS(Parcelas!$E$5:$E$404,Parcelas!$A$5:$A$404,A5,Parcelas!$H$5:$H$404,"Paga")) -> 4500 | H5: =IF(A5="","",F5-G5) -> 13500 | I5: =IF(A5="","",SUMIFS(Parcelas!$E$5:$E$404,Parcelas!$A$5:$A$404,A5,Parcelas!$H$5:$H$404,"Vencida")) -> 0 | J5: =IF(OR(A5="",E5=0),"",D5-F5) -> 0
A6: 2998500-50.2026.8.26.0515 | B6: Ana Beatriz Moreira | C6: Êxito | D6: 6000 | E6: =IF(A6="","",COUNTIFS(Parcelas!$A$5:$A$404,A6)) -> 0 | F6: =IF(A6="","",SUMIFS(Parcelas!$E$5:$E$404,Parcelas!$A$5:$A$404,A6)) -> 0 | G6: =IF(A6="","",SUMIFS(Parcelas!$E$5:$E$404,Parcelas!$A$5:$A$404,A6,Parcelas!$H$5:$H$404,"Paga")) -> 0 | H6: =IF(A6="","",F6-G6) -> 0 | I6: =IF(A6="","",SUMIFS(Parcelas!$E$5:$E$404,Parcelas!$A$5:$A$404,A6,Parcelas!$H$5:$H$404,"Vencida")) -> 0 | J6: =IF(OR(A6="",E6=0),"",D6-F6)
A7: 9586960-92.2026.8.26.0106 | B7: Construtora Horizonte | C7: Misto | D7: 15500 | E7: =IF(A7="","",COUNTIFS(Parcelas!$A$5:$A$404,A7)) -> 4 | F7: =IF(A7="","",SUMIFS(Parcelas!$E$5:$E$404,Parcelas!$A$5:$A$404,A7)) -> 10500 | G7: =IF(A7="","",SUMIFS(Parcelas!$E$5:$E$404,Parcelas!$A$5:$A$404,A7,Parcelas!$H$5:$H$404,"Paga")) -> 6300 | H7: =IF(A7="","",F7-G7) -> 4200 | I7: =IF(A7="","",SUMIFS(Parcelas!$E$5:$E$404,Parcelas!$A$5:$A$404,A7,Parcelas!$H$5:$H$404,"Vencida")) -> 0 | J7: =IF(OR(A7="",E7=0),"",D7-F7) -> 5000
A8: 4746093-86.2026.8.26.0637 | B8: Carlos Eduardo Nunes | C8: Fixo | D8: 5400 | E8: =IF(A8="","",COUNTIFS(Parcelas!$A$5:$A$404,A8)) -> 3 | F8: =IF(A8="","",SUMIFS(Parcelas!$E$5:$E$404,Parcelas!$A$5:$A$404,A8)) -> 5400 | G8: =IF(A8="","",SUMIFS(Parcelas!$E$5:$E$404,Parcelas!$A$5:$A$404,A8,Parcelas!$H$5:$H$404,"Paga")) -> 3900 | H8: =IF(A8="","",F8-G8) -> 1500 | I8: =IF(A8="","",SUMIFS(Parcelas!$E$5:$E$404,Parcelas!$A$5:$A$404,A8,Parcelas!$H$5:$H$404,"Vencida")) -> 0 | J8: =IF(OR(A8="",E8=0),"",D8-F8) -> 0
A9: CONS-2026-02 | B9: Loja Verde Comércio | C9: Fixo | D9: 8400 | E9: =IF(A9="","",COUNTIFS(Parcelas!$A$5:$A$404,A9)) -> 3 | F9: =IF(A9="","",SUMIFS(Parcelas!$E$5:$E$404,Parcelas!$A$5:$A$404,A9)) -> 8400 | G9: =IF(A9="","",SUMIFS(Parcelas!$E$5:$E$404,Parcelas!$A$5:$A$404,A9,Parcelas!$H$5:$H$404,"Paga")) -> 2800 | H9: =IF(A9="","",F9-G9) -> 5600 | I9: =IF(A9="","",SUMIFS(Parcelas!$E$5:$E$404,Parcelas!$A$5:$A$404,A9,Parcelas!$H$5:$H$404,"Vencida")) -> 0 | J9: =IF(OR(A9="",E9=0),"",D9-F9) -> 0
A10: CONS-2026-03 | B10: Marcos Vinícius Teles | C10: Fixo | D10: 4500 | E10: =IF(A10="","",COUNTIFS(Parcelas!$A$5:$A$404,A10)) -> 2 | F10: =IF(A10="","",SUMIFS(Parcelas!$E$5:$E$404,Parcelas!$A$5:$A$404,A10)) -> 4500 | G10: =IF(A10="","",SUMIFS(Parcelas!$E$5:$E$404,Parcelas!$A$5:$A$404,A10,Parcelas!$H$5:$H$404,"Paga")) -> 2250 | H10: =IF(A10="","",F10-G10) -> 2250 | I10: =IF(A10="","",SUMIFS(Parcelas!$E$5:$E$404,Parcelas!$A$5:$A$404,A10,Parcelas!$H$5:$H$404,"Vencida")) -> 0 | J10: =IF(OR(A10="",E10=0),"",D10-F10) -> 0
A11: CONS-2026-04 | B11: Escola Aurora | C11: Fixo | D11: 13200 | E11: =IF(A11="","",COUNTIFS(Parcelas!$A$5:$A$404,A11)) -> 12 | F11: =IF(A11="","",SUMIFS(Parcelas!$E$5:$E$404,Parcelas!$A$5:$A$404,A11)) -> 13200 | G11: =IF(A11="","",SUMIFS(Parcelas!$E$5:$E$404,Parcelas!$A$5:$A$404,A11,Parcelas!$H$5:$H$404,"Paga")) -> 2200 | H11: =IF(A11="","",F11-G11) -> 11000 | I11: =IF(A11="","",SUMIFS(Parcelas!$E$5:$E$404,Parcelas!$A$5:$A$404,A11,Parcelas!$H$5:$H$404,"Vencida")) -> 0 | J11: =IF(OR(A11="",E11=0),"",D11-F11) -> 0
A12: 8056747-83.2026.8.26.0561 | B12: Bistrô 42 | C12: Fixo | D12: 9500 | E12: =IF(A12="","",COUNTIFS(Parcelas!$A$5:$A$404,A12)) -> 4 | F12: =IF(A12="","",SUMIFS(Parcelas!$E$5:$E$404,Parcelas!$A$5:$A$404,A12)) -> 9500 | G12: =IF(A12="","",SUMIFS(Parcelas!$E$5:$E$404,Parcelas!$A$5:$A$404,A12,Parcelas!$H$5:$H$404,"Paga")) -> 5300 | H12: =IF(A12="","",F12-G12) -> 4200 | I12: =IF(A12="","",SUMIFS(Parcelas!$E$5:$E$404,Parcelas!$A$5:$A$404,A12,Parcelas!$H$5:$H$404,"Vencida")) -> 4200 | J12: =IF(OR(A12="",E12=0),"",D12-F12) -> 0
A13: 9236009-85.2025.8.26.0452 | B13: Bistrô 42 | C13: Êxito | D13: 4000 | E13: =IF(A13="","",COUNTIFS(Parcelas!$A$5:$A$404,A13)) -> 0 | F13: =IF(A13="","",SUMIFS(Parcelas!$E$5:$E$404,Parcelas!$A$5:$A$404,A13)) -> 0 | G13: =IF(A13="","",SUMIFS(Parcelas!$E$5:$E$404,Parcelas!$A$5:$A$404,A13,Parcelas!$H$5:$H$404,"Paga")) -> 0 | H13: =IF(A13="","",F13-G13) -> 0 | I13: =IF(A13="","",SUMIFS(Parcelas!$E$5:$E$404,Parcelas!$A$5:$A$404,A13,Parcelas!$H$5:$H$404,"Vencida")) -> 0 | J13: =IF(OR(A13="",E13=0),"",D13-F13)
A14: 5025425-10.2025.8.26.0629 | B14: Roberto Almeida | C14: Fixo | D14: 15000 | E14: =IF(A14="","",COUNTIFS(Parcelas!$A$5:$A$404,A14)) -> 4 | F14: =IF(A14="","",SUMIFS(Parcelas!$E$5:$E$404,Parcelas!$A$5:$A$404,A14)) -> 15000 | G14: =IF(A14="","",SUMIFS(Parcelas!$E$5:$E$404,Parcelas!$A$5:$A$404,A14,Parcelas!$H$5:$H$404,"Paga")) -> 15000 | H14: =IF(A14="","",F14-G14) -> 0 | I14: =IF(A14="","",SUMIFS(Parcelas!$E$5:$E$404,Parcelas!$A$5:$A$404,A14,Parcelas!$H$5:$H$404,"Vencida")) -> 0 | J14: =IF(OR(A14="",E14=0),"",D14-F14) -> 0
A15: 2354318-24.2026.8.26.0295 | B15: Roberto Almeida | C15: Misto | D15: 10200 | E15: =IF(A15="","",COUNTIFS(Parcelas!$A$5:$A$404,A15)) -> 3 | F15: =IF(A15="","",SUMIFS(Parcelas!$E$5:$E$404,Parcelas!$A$5:$A$404,A15)) -> 7200 | G15: =IF(A15="","",SUMIFS(Parcelas!$E$5:$E$404,Parcelas!$A$5:$A$404,A15,Parcelas!$H$5:$H$404,"Paga")) -> 7200 | H15: =IF(A15="","",F15-G15) -> 0 | I15: =IF(A15="","",SUMIFS(Parcelas!$E$5:$E$404,Parcelas!$A$5:$A$404,A15,Parcelas!$H$5:$H$404,"Vencida")) -> 0 | J15: =IF(OR(A15="",E15=0),"",D15-F15) -> 3000
A16: CONS-2025-05 | B16: Clínica Bem-Estar | C16: Hora | D16: 21600 | E16: =IF(A16="","",COUNTIFS(Parcelas!$A$5:$A$404,A16)) -> 10 | F16: =IF(A16="","",SUMIFS(Parcelas!$E$5:$E$404,Parcelas!$A$5:$A$404,A16)) -> 19260 | G16: =IF(A16="","",SUMIFS(Parcelas!$E$5:$E$404,Parcelas!$A$5:$A$404,A16,Parcelas!$H$5:$H$404,"Paga")) -> 19260 | H16: =IF(A16="","",F16-G16) -> 0 | I16: =IF(A16="","",SUMIFS(Parcelas!$E$5:$E$404,Parcelas!$A$5:$A$404,A16,Parcelas!$H$5:$H$404,"Vencida")) -> 0 | J16: =IF(OR(A16="",E16=0),"",D16-F16) -> 2340
... A42: 9420478-99.2025.8.26.0491 | B42: Ana Beatriz Moreira | C42: Misto | D42: 8500 | E42: =IF(A42="","",COUNTIFS(Parcelas!$A$5:$A$404,A42)) -> 2 | F42: =IF(A42="","",SUMIFS(Parcelas!$E$5:$E$404,Parcelas!$A$5:$A$404,A42)) -> 8500 | G42: =IF(A42="","",SUMIFS(Parcelas!$E$5:$E$404,Parcelas!$A$5:$A$404,A42,Parcelas!$H$5:$H$404,"Paga")) -> 8500 | H42: =IF(A42="","",F42-G42) -> 0 | I42: =IF(A42="","",SUMIFS(Parcelas!$E$5:$E$404,Parcelas!$A$5:$A$404,A42,Parcelas!$H$5:$H$404,"Vencida")) -> 0 | J42: =IF(OR(A42="",E42=0),"",D42-F42) -> 0
E43: =IF(A43="","",COUNTIFS(Parcelas!$A$5:$A$404,A43)) | F43: =IF(A43="","",SUMIFS(Parcelas!$E$5:$E$404,Parcelas!$A$5:$A$404,A43)) | G43: =IF(A43="","",SUMIFS(Parcelas!$E$5:$E$404,Parcelas!$A$5:$A$404,A43,Parcelas!$H$5:$H$404,"Paga")) | H43: =IF(A43="","",F43-G43) | I43: =IF(A43="","",SUMIFS(Parcelas!$E$5:$E$404,Parcelas!$A$5:$A$404,A43,Parcelas!$H$5:$H$404,"Vencida")) | J43: =IF(OR(A43="",E43=0),"",D43-F43)
E44: =IF(A44="","",COUNTIFS(Parcelas!$A$5:$A$404,A44)) | F44: =IF(A44="","",SUMIFS(Parcelas!$E$5:$E$404,Parcelas!$A$5:$A$404,A44)) | G44: =IF(A44="","",SUMIFS(Parcelas!$E$5:$E$404,Parcelas!$A$5:$A$404,A44,Parcelas!$H$5:$H$404,"Paga")) | H44: =IF(A44="","",F44-G44) | I44: =IF(A44="","",SUMIFS(Parcelas!$E$5:$E$404,Parcelas!$A$5:$A$404,A44,Parcelas!$H$5:$H$404,"Vencida")) | J44: =IF(OR(A44="",E44=0),"",D44-F44)
E45: =IF(A45="","",COUNTIFS(Parcelas!$A$5:$A$404,A45)) | F45: =IF(A45="","",SUMIFS(Parcelas!$E$5:$E$404,Parcelas!$A$5:$A$404,A45)) | G45: =IF(A45="","",SUMIFS(Parcelas!$E$5:$E$404,Parcelas!$A$5:$A$404,A45,Parcelas!$H$5:$H$404,"Paga")) | H45: =IF(A45="","",F45-G45) | I45: =IF(A45="","",SUMIFS(Parcelas!$E$5:$E$404,Parcelas!$A$5:$A$404,A45,Parcelas!$H$5:$H$404,"Vencida")) | J45: =IF(OR(A45="",E45=0),"",D45-F45)
E46: =IF(A46="","",COUNTIFS(Parcelas!$A$5:$A$404,A46)) | F46: =IF(A46="","",SUMIFS(Parcelas!$E$5:$E$404,Parcelas!$A$5:$A$404,A46)) | G46: =IF(A46="","",SUMIFS(Parcelas!$E$5:$E$404,Parcelas!$A$5:$A$404,A46,Parcelas!$H$5:$H$404,"Paga")) | H46: =IF(A46="","",F46-G46) | I46: =IF(A46="","",SUMIFS(Parcelas!$E$5:$E$404,Parcelas!$A$5:$A$404,A46,Parcelas!$H$5:$H$404,"Vencida")) | J46: =IF(OR(A46="",E46=0),"",D46-F46)
E47: =IF(A47="","",COUNTIFS(Parcelas!$A$5:$A$404,A47)) | F47: =IF(A47="","",SUMIFS(Parcelas!$E$5:$E$404,Parcelas!$A$5:$A$404,A47)) | G47: =IF(A47="","",SUMIFS(Parcelas!$E$5:$E$404,Parcelas!$A$5:$A$404,A47,Parcelas!$H$5:$H$404,"Paga")) | H47: =IF(A47="","",F47-G47) | I47: =IF(A47="","",SUMIFS(Parcelas!$E$5:$E$404,Parcelas!$A$5:$A$404,A47,Parcelas!$H$5:$H$404,"Vencida")) | J47: =IF(OR(A47="",E47=0),"",D47-F47)
E48: =IF(A48="","",COUNTIFS(Parcelas!$A$5:$A$404,A48)) | F48: =IF(A48="","",SUMIFS(Parcelas!$E$5:$E$404,Parcelas!$A$5:$A$404,A48)) | G48: =IF(A48="","",SUMIFS(Parcelas!$E$5:$E$404,Parcelas!$A$5:$A$404,A48,Parcelas!$H$5:$H$404,"Paga")) | H48: =IF(A48="","",F48-G48) | I48: =IF(A48="","",SUMIFS(Parcelas!$E$5:$E$404,Parcelas!$A$5:$A$404,A48,Parcelas!$H$5:$H$404,"Vencida")) | J48: =IF(OR(A48="",E48=0),"",D48-F48)
E49: =IF(A49="","",COUNTIFS(Parcelas!$A$5:$A$404,A49)) | F49: =IF(A49="","",SUMIFS(Parcelas!$E$5:$E$404,Parcelas!$A$5:$A$404,A49)) | G49: =IF(A49="","",SUMIFS(Parcelas!$E$5:$E$404,Parcelas!$A$5:$A$404,A49,Parcelas!$H$5:$H$404,"Paga")) | H49: =IF(A49="","",F49-G49) | I49: =IF(A49="","",SUMIFS(Parcelas!$E$5:$E$404,Parcelas!$A$5:$A$404,A49,Parcelas!$H$5:$H$404,"Vencida")) | J49: =IF(OR(A49="",E49=0),"",D49-F49)
E50: =IF(A50="","",COUNTIFS(Parcelas!$A$5:$A$404,A50)) | F50: =IF(A50="","",SUMIFS(Parcelas!$E$5:$E$404,Parcelas!$A$5:$A$404,A50)) | G50: =IF(A50="","",SUMIFS(Parcelas!$E$5:$E$404,Parcelas!$A$5:$A$404,A50,Parcelas!$H$5:$H$404,"Paga")) | H50: =IF(A50="","",F50-G50) | I50: =IF(A50="","",SUMIFS(Parcelas!$E$5:$E$404,Parcelas!$A$5:$A$404,A50,Parcelas!$H$5:$H$404,"Vencida")) | J50: =IF(OR(A50="",E50=0),"",D50-F50)
E51: =IF(A51="","",COUNTIFS(Parcelas!$A$5:$A$404,A51)) | F51: =IF(A51="","",SUMIFS(Parcelas!$E$5:$E$404,Parcelas!$A$5:$A$404,A51)) | G51: =IF(A51="","",SUMIFS(Parcelas!$E$5:$E$404,Parcelas!$A$5:$A$404,A51,Parcelas!$H$5:$H$404,"Paga")) | H51: =IF(A51="","",F51-G51) | I51: =IF(A51="","",SUMIFS(Parcelas!$E$5:$E$404,Parcelas!$A$5:$A$404,A51,Parcelas!$H$5:$H$404,"Vencida")) | J51: =IF(OR(A51="",E51=0),"",D51-F51)
E52: =IF(A52="","",COUNTIFS(Parcelas!$A$5:$A$404,A52)) | F52: =IF(A52="","",SUMIFS(Parcelas!$E$5:$E$404,Parcelas!$A$5:$A$404,A52)) | G52: =IF(A52="","",SUMIFS(Parcelas!$E$5:$E$404,Parcelas!$A$5:$A$404,A52,Parcelas!$H$5:$H$404,"Paga")) | H52: =IF(A52="","",F52-G52) | I52: =IF(A52="","",SUMIFS(Parcelas!$E$5:$E$404,Parcelas!$A$5:$A$404,A52,Parcelas!$H$5:$H$404,"Vencida")) | J52: =IF(OR(A52="",E52=0),"",D52-F52)
E53: =IF(A53="","",COUNTIFS(Parcelas!$A$5:$A$404,A53)) | F53: =IF(A53="","",SUMIFS(Parcelas!$E$5:$E$404,Parcelas!$A$5:$A$404,A53)) | G53: =IF(A53="","",SUMIFS(Parcelas!$E$5:$E$404,Parcelas!$A$5:$A$404,A53,Parcelas!$H$5:$H$404,"Paga")) | H53: =IF(A53="","",F53-G53) | I53: =IF(A53="","",SUMIFS(Parcelas!$E$5:$E$404,Parcelas!$A$5:$A$404,A53,Parcelas!$H$5:$H$404,"Vencida")) | J53: =IF(OR(A53="",E53=0),"",D53-F53)
E54: =IF(A54="","",COUNTIFS(Parcelas!$A$5:$A$404,A54)) | F54: =IF(A54="","",SUMIFS(Parcelas!$E$5:$E$404,Parcelas!$A$5:$A$404,A54)) | G54: =IF(A54="","",SUMIFS(Parcelas!$E$5:$E$404,Parcelas!$A$5:$A$404,A54,Parcelas!$H$5:$H$404,"Paga")) | H54: =IF(A54="","",F54-G54) | I54: =IF(A54="","",SUMIFS(Parcelas!$E$5:$E$404,Parcelas!$A$5:$A$404,A54,Parcelas!$H$5:$H$404,"Vencida")) | J54: =IF(OR(A54="",E54=0),"",D54-F54)
... E204: =IF(A204="","",COUNTIFS(Parcelas!$A$5:$A$404,A204)) | F204: =IF(A204="","",SUMIFS(Parcelas!$E$5:$E$404,Parcelas!$A$5:$A$404,A204)) | G204: =IF(A204="","",SUMIFS(Parcelas!$E$5:$E$404,Parcelas!$A$5:$A$404,A204,Parcelas!$H$5:$H$404,"Paga")) | H204: =IF(A204="","",F204-G204) | I204: =IF(A204="","",SUMIFS(Parcelas!$E$5:$E$404,Parcelas!$A$5:$A$404,A204,Parcelas!$H$5:$H$404,"Vencida")) | J204: =IF(OR(A204="",E204=0),"",D204-F204)
A206: Casos por hora: lance uma parcela por fatura mensal (a diferença em amarelo é o que ainda não foi faturado). Êxito e a parte de êxito do misto só viram parcela no fim do caso: até lá a diferença é o êxito esperado. Cadastre todos os casos, mesmo sem parcela, para a lista ficar completa.

Sheet Parcelas
A1: Parcelas
A2: Uma linha por parcela. Escolha o caso na lista; cliente, situação, dias e ação da régua são calculados.
A4: Caso | B4: Cliente | C4: Nº da parcela | D4: Vencimento | E4: Valor (R$) | F4: Pago? | G4: Data do pagamento | H4: Situação | I4: Dias de atraso | J4: Dias para vencer | K4: Faixa de atraso | L4: Ação sugerida (régua)
A5: CONS-2026-01 | B5: =IF(A5="","",IFERROR(INDEX(Casos!$B$5:$B$204,MATCH(A5,Casos!$A$5:$A$204,0)),"")) -> Padaria do Sol Ltda | C5: 1 | D5: 46208 | E5: 1500 | F5: Sim | G5: 46209 | H5: =IF(A5="","",IF(F5="Sim","Paga",IF(D5="","Sem vencimento",IF(D5<Config!$B$5,"Vencida","A vencer")))) -> Paga | I5: =IF(H5="Vencida",Config!$B$5-D5,"") | J5: =IF(H5="A vencer",D5-Config!$B$5,"") | K5: =IF(H5<>"Vencida","",IF(COUNTIF(Config!$A$10:$A$13,"<="&I5)=0,"Antes da régua",INDEX(Config!$C$10:$C$13,COUNTIF(Config!$A$10:$A$13,"<="&I5)))) | L5: =IF(H5<>"Vencida","",IF(COUNTIF(Config!$A$10:$A$13,"<="&I5)=0,"Aguardar: ainda não chegou ao primeiro passo da régua.",INDEX(Config!$B$10:$B$13,COUNTIF(Config!$A$10:$A$13,"<="&I5)))) | M5: =IF(H5="Vencida",E5*I5+ROW()/100000,0) -> 0 | N5: =IF(AND(H5="A vencer",J5<=Config!$B$7),100000-J5-ROW()/100000,0) -> 0
A6: CONS-2026-01 | B6: =IF(A6="","",IFERROR(INDEX(Casos!$B$5:$B$204,MATCH(A6,Casos!$A$5:$A$204,0)),"")) -> Padaria do Sol Ltda | C6: 2 | D6: 46239 | E6: 1500 | F6: Sim | G6: 46239 | H6: =IF(A6="","",IF(F6="Sim","Paga",IF(D6="","Sem vencimento",IF(D6<Config!$B$5,"Vencida","A vencer")))) -> Paga | I6: =IF(H6="Vencida",Config!$B$5-D6,"") | J6: =IF(H6="A vencer",D6-Config!$B$5,"") | K6: =IF(H6<>"Vencida","",IF(COUNTIF(Config!$A$10:$A$13,"<="&I6)=0,"Antes da régua",INDEX(Config!$C$10:$C$13,COUNTIF(Config!$A$10:$A$13,"<="&I6)))) | L6: =IF(H6<>"Vencida","",IF(COUNTIF(Config!$A$10:$A$13,"<="&I6)=0,"Aguardar: ainda não chegou ao primeiro passo da régua.",INDEX(Config!$B$10:$B$13,COUNTIF(Config!$A$10:$A$13,"<="&I6)))) | M6: =IF(H6="Vencida",E6*I6+ROW()/100000,0) -> 0 | N6: =IF(AND(H6="A vencer",J6<=Config!$B$7),100000-J6-ROW()/100000,0) -> 0
A7: CONS-2026-01 | B7: =IF(A7="","",IFERROR(INDEX(Casos!$B$5:$B$204,MATCH(A7,Casos!$A$5:$A$204,0)),"")) -> Padaria do Sol Ltda | C7: 3 | D7: 46270 | E7: 1500 | F7: Sim | G7: 46273 | H7: =IF(A7="","",IF(F7="Sim","Paga",IF(D7="","Sem vencimento",IF(D7<Config!$B$5,"Vencida","A vencer")))) -> Paga | I7: =IF(H7="Vencida",Config!$B$5-D7,"") | J7: =IF(H7="A vencer",D7-Config!$B$5,"") | K7: =IF(H7<>"Vencida","",IF(COUNTIF(Config!$A$10:$A$13,"<="&I7)=0,"Antes da régua",INDEX(Config!$C$10:$C$13,COUNTIF(Config!$A$10:$A$13,"<="&I7)))) | L7: =IF(H7<>"Vencida","",IF(COUNTIF(Config!$A$10:$A$13,"<="&I7)=0,"Aguardar: ainda não chegou ao primeiro passo da régua.",INDEX(Config!$B$10:$B$13,COUNTIF(Config!$A$10:$A$13,"<="&I7)))) | M7: =IF(H7="Vencida",E7*I7+ROW()/100000,0) -> 0 | N7: =IF(AND(H7="A vencer",J7<=Config!$B$7),100000-J7-ROW()/100000,0) -> 0
A8: CONS-2026-01 | B8: =IF(A8="","",IFERROR(INDEX(Casos!$B$5:$B$204,MATCH(A8,Casos!$A$5:$A$204,0)),"")) -> Padaria do Sol Ltda | C8: 4 | D8: 46300 | E8: 1500 | F8: Não | H8: =IF(A8="","",IF(F8="Sim","Paga",IF(D8="","Sem vencimento",IF(D8<Config!$B$5,"Vencida","A vencer")))) -> A vencer | I8: =IF(H8="Vencida",Config!$B$5-D8,"") | J8: =IF(H8="A vencer",D8-Config!$B$5,"") -> 21 | K8: =IF(H8<>"Vencida","",IF(COUNTIF(Config!$A$10:$A$13,"<="&I8)=0,"Antes da régua",INDEX(Config!$C$10:$C$13,COUNTIF(Config!$A$10:$A$13,"<="&I8)))) | L8: =IF(H8<>"Vencida","",IF(COUNTIF(Config!$A$10:$A$13,"<="&I8)=0,"Aguardar: ainda não chegou ao primeiro passo da régua.",INDEX(Config!$B$10:$B$13,COUNTIF(Config!$A$10:$A$13,"<="&I8)))) | M8: =IF(H8="Vencida",E8*I8+ROW()/100000,0) -> 0 | N8: =IF(AND(H8="A vencer",J8<=Config!$B$7),100000-J8-ROW()/100000,0) -> 99979
A9: CONS-2026-01 | B9: =IF(A9="","",IFERROR(INDEX(Casos!$B$5:$B$204,MATCH(A9,Casos!$A$5:$A$204,0)),"")) -> Padaria do Sol Ltda | C9: 5 | D9: 46331 | E9: 1500 | F9: Não | H9: =IF(A9="","",IF(F9="Sim","Paga",IF(D9="","Sem vencimento",IF(D9<Config!$B$5,"Vencida","A vencer")))) -> A vencer | I9: =IF(H9="Vencida",Config!$B$5-D9,"") | J9: =IF(H9="A vencer",D9-Config!$B$5,"") -> 52 | K9: =IF(H9<>"Vencida","",IF(COUNTIF(Config!$A$10:$A$13,"<="&I9)=0,"Antes da régua",INDEX(Config!$C$10:$C$13,COUNTIF(Config!$A$10:$A$13,"<="&I9)))) | L9: =IF(H9<>"Vencida","",IF(COUNTIF(Config!$A$10:$A$13,"<="&I9)=0,"Aguardar: ainda não chegou ao primeiro passo da régua.",INDEX(Config!$B$10:$B$13,COUNTIF(Config!$A$10:$A$13,"<="&I9)))) | M9: =IF(H9="Vencida",E9*I9+ROW()/100000,0) -> 0 | N9: =IF(AND(H9="A vencer",J9<=Config!$B$7),100000-J9-ROW()/100000,0) -> 0
A10: CONS-2026-01 | B10: =IF(A10="","",IFERROR(INDEX(Casos!$B$5:$B$204,MATCH(A10,Casos!$A$5:$A$204,0)),"")) -> Padaria do Sol Ltda | C10: 6 | D10: 46361 | E10: 1500 | F10: Não | H10: =IF(A10="","",IF(F10="Sim","Paga",IF(D10="","Sem vencimento",IF(D10<Config!$B$5,"Vencida","A vencer")))) -> A vencer | I10: =IF(H10="Vencida",Config!$B$5-D10,"") | J10: =IF(H10="A vencer",D10-Config!$B$5,"") -> 82 | K10: =IF(H10<>"Vencida","",IF(COUNTIF(Config!$A$10:$A$13,"<="&I10)=0,"Antes da régua",INDEX(Config!$C$10:$C$13,COUNTIF(Config!$A$10:$A$13,"<="&I10)))) | L10: =IF(H10<>"Vencida","",IF(COUNTIF(Config!$A$10:$A$13,"<="&I10)=0,"Aguardar: ainda não chegou ao primeiro passo da régua.",INDEX(Config!$B$10:$B$13,COUNTIF(Config!$A$10:$A$13,"<="&I10)))) | M10: =IF(H10="Vencida",E10*I10+ROW()/100000,0) -> 0 | N10: =IF(AND(H10="A vencer",J10<=Config!$B$7),100000-J10-ROW()/100000,0) -> 0
A11: CONS-2026-01 | B11: =IF(A11="","",IFERROR(INDEX(Casos!$B$5:$B$204,MATCH(A11,Casos!$A$5:$A$204,0)),"")) -> Padaria do Sol Ltda | C11: 7 | D11: 46392 | E11: 1500 | F11: Não | H11: =IF(A11="","",IF(F11="Sim","Paga",IF(D11="","Sem vencimento",IF(D11<Config!$B$5,"Vencida","A vencer")))) -> A vencer | I11: =IF(H11="Vencida",Config!$B$5-D11,"") | J11: =IF(H11="A vencer",D11-Config!$B$5,"") -> 113 | K11: =IF(H11<>"Vencida","",IF(COUNTIF(Config!$A$10:$A$13,"<="&I11)=0,"Antes da régua",INDEX(Config!$C$10:$C$13,COUNTIF(Config!$A$10:$A$13,"<="&I11)))) | L11: =IF(H11<>"Vencida","",IF(COUNTIF(Config!$A$10:$A$13,"<="&I11)=0,"Aguardar: ainda não chegou ao primeiro passo da régua.",INDEX(Config!$B$10:$B$13,COUNTIF(Config!$A$10:$A$13,"<="&I11)))) | M11: =IF(H11="Vencida",E11*I11+ROW()/100000,0) -> 0 | N11: =IF(AND(H11="A vencer",J11<=Config!$B$7),100000-J11-ROW()/100000,0) -> 0
A12: CONS-2026-01 | B12: =IF(A12="","",IFERROR(INDEX(Casos!$B$5:$B$204,MATCH(A12,Casos!$A$5:$A$204,0)),"")) -> Padaria do Sol Ltda | C12: 8 | D12: 46423 | E12: 1500 | F12: Não | H12: =IF(A12="","",IF(F12="Sim","Paga",IF(D12="","Sem vencimento",IF(D12<Config!$B$5,"Vencida","A vencer")))) -> A vencer | I12: =IF(H12="Vencida",Config!$B$5-D12,"") | J12: =IF(H12="A vencer",D12-Config!$B$5,"") -> 144 | K12: =IF(H12<>"Vencida","",IF(COUNTIF(Config!$A$10:$A$13,"<="&I12)=0,"Antes da régua",INDEX(Config!$C$10:$C$13,COUNTIF(Config!$A$10:$A$13,"<="&I12)))) | L12: =IF(H12<>"Vencida","",IF(COUNTIF(Config!$A$10:$A$13,"<="&I12)=0,"Aguardar: ainda não chegou ao primeiro passo da régua.",INDEX(Config!$B$10:$B$13,COUNTIF(Config!$A$10:$A$13,"<="&I12)))) | M12: =IF(H12="Vencida",E12*I12+ROW()/100000,0) -> 0 | N12: =IF(AND(H12="A vencer",J12<=Config!$B$7),100000-J12-ROW()/100000,0) -> 0
A13: CONS-2026-01 | B13: =IF(A13="","",IFERROR(INDEX(Casos!$B$5:$B$204,MATCH(A13,Casos!$A$5:$A$204,0)),"")) -> Padaria do Sol Ltda | C13: 9 | D13: 46451 | E13: 1500 | F13: Não | H13: =IF(A13="","",IF(F13="Sim","Paga",IF(D13="","Sem vencimento",IF(D13<Config!$B$5,"Vencida","A vencer")))) -> A vencer | I13: =IF(H13="Vencida",Config!$B$5-D13,"") | J13: =IF(H13="A vencer",D13-Config!$B$5,"") -> 172 | K13: =IF(H13<>"Vencida","",IF(COUNTIF(Config!$A$10:$A$13,"<="&I13)=0,"Antes da régua",INDEX(Config!$C$10:$C$13,COUNTIF(Config!$A$10:$A$13,"<="&I13)))) | L13: =IF(H13<>"Vencida","",IF(COUNTIF(Config!$A$10:$A$13,"<="&I13)=0,"Aguardar: ainda não chegou ao primeiro passo da régua.",INDEX(Config!$B$10:$B$13,COUNTIF(Config!$A$10:$A$13,"<="&I13)))) | M13: =IF(H13="Vencida",E13*I13+ROW()/100000,0) -> 0 | N13: =IF(AND(H13="A vencer",J13<=Config!$B$7),100000-J13-ROW()/100000,0) -> 0
A14: CONS-2026-01 | B14: =IF(A14="","",IFERROR(INDEX(Casos!$B$5:$B$204,MATCH(A14,Casos!$A$5:$A$204,0)),"")) -> Padaria do Sol Ltda | C14: 10 | D14: 46482 | E14: 1500 | F14: Não | H14: =IF(A14="","",IF(F14="Sim","Paga",IF(D14="","Sem vencimento",IF(D14<Config!$B$5,"Vencida","A vencer")))) -> A vencer | I14: =IF(H14="Vencida",Config!$B$5-D14,"") | J14: =IF(H14="A vencer",D14-Config!$B$5,"") -> 203 | K14: =IF(H14<>"Vencida","",IF(COUNTIF(Config!$A$10:$A$13,"<="&I14)=0,"Antes da régua",INDEX(Config!$C$10:$C$13,COUNTIF(Config!$A$10:$A$13,"<="&I14)))) | L14: =IF(H14<>"Vencida","",IF(COUNTIF(Config!$A$10:$A$13,"<="&I14)=0,"Aguardar: ainda não chegou ao primeiro passo da régua.",INDEX(Config!$B$10:$B$13,COUNTIF(Config!$A$10:$A$13,"<="&I14)))) | M14: =IF(H14="Vencida",E14*I14+ROW()/100000,0) -> 0 | N14: =IF(AND(H14="A vencer",J14<=Config!$B$7),100000-J14-ROW()/100000,0) -> 0
A15: CONS-2026-01 | B15: =IF(A15="","",IFERROR(INDEX(Casos!$B$5:$B$204,MATCH(A15,Casos!$A$5:$A$204,0)),"")) -> Padaria do Sol Ltda | C15: 11 | D15: 46512 | E15: 1500 | F15: Não | H15: =IF(A15="","",IF(F15="Sim","Paga",IF(D15="","Sem vencimento",IF(D15<Config!$B$5,"Vencida","A vencer")))) -> A vencer | I15: =IF(H15="Vencida",Config!$B$5-D15,"") | J15: =IF(H15="A vencer",D15-Config!$B$5,"") -> 233 | K15: =IF(H15<>"Vencida","",IF(COUNTIF(Config!$A$10:$A$13,"<="&I15)=0,"Antes da régua",INDEX(Config!$C$10:$C$13,COUNTIF(Config!$A$10:$A$13,"<="&I15)))) | L15: =IF(H15<>"Vencida","",IF(COUNTIF(Config!$A$10:$A$13,"<="&I15)=0,"Aguardar: ainda não chegou ao primeiro passo da régua.",INDEX(Config!$B$10:$B$13,COUNTIF(Config!$A$10:$A$13,"<="&I15)))) | M15: =IF(H15="Vencida",E15*I15+ROW()/100000,0) -> 0 | N15: =IF(AND(H15="A vencer",J15<=Config!$B$7),100000-J15-ROW()/100000,0) -> 0
A16: CONS-2026-01 | B16: =IF(A16="","",IFERROR(INDEX(Casos!$B$5:$B$204,MATCH(A16,Casos!$A$5:$A$204,0)),"")) -> Padaria do Sol Ltda | C16: 12 | D16: 46543 | E16: 1500 | F16: Não | H16: =IF(A16="","",IF(F16="Sim","Paga",IF(D16="","Sem vencimento",IF(D16<Config!$B$5,"Vencida","A vencer")))) -> A vencer | I16: =IF(H16="Vencida",Config!$B$5-D16,"") | J16: =IF(H16="A vencer",D16-Config!$B$5,"") -> 264 | K16: =IF(H16<>"Vencida","",IF(COUNTIF(Config!$A$10:$A$13,"<="&I16)=0,"Antes da régua",INDEX(Config!$C$10:$C$13,COUNTIF(Config!$A$10:$A$13,"<="&I16)))) | L16: =IF(H16<>"Vencida","",IF(COUNTIF(Config!$A$10:$A$13,"<="&I16)=0,"Aguardar: ainda não chegou ao primeiro passo da régua.",INDEX(Config!$B$10:$B$13,COUNTIF(Config!$A$10:$A$13,"<="&I16)))) | M16: =IF(H16="Vencida",E16*I16+ROW()/100000,0) -> 0 | N16: =IF(AND(H16="A vencer",J16<=Config!$B$7),100000-J16-ROW()/100000,0) -> 0
A17: 9586960-92.2026.8.26.0106 | B17: =IF(A17="","",IFERROR(INDEX(Casos!$B$5:$B$204,MATCH(A17,Casos!$A$5:$A$204,0)),"")) -> Construtora Horizonte | C17: 1 | D17: 46232 | E17: 4200 | F17: Sim | G17: 46232 | H17: =IF(A17="","",IF(F17="Sim","Paga",IF(D17="","Sem vencimento",IF(D17<Config!$B$5,"Vencida","A vencer")))) -> Paga | I17: =IF(H17="Vencida",Config!$B$5-D17,"") | J17: =IF(H17="A vencer",D17-Config!$B$5,"") | K17: =IF(H17<>"Vencida","",IF(COUNTIF(Config!$A$10:$A$13,"<="&I17)=0,"Antes da régua",INDEX(Config!$C$10:$C$13,COUNTIF(Config!$A$10:$A$13,"<="&I17)))) | L17: =IF(H17<>"Vencida","",IF(COUNTIF(Config!$A$10:$A$13,"<="&I17)=0,"Aguardar: ainda não chegou ao primeiro passo da régua.",INDEX(Config!$B$10:$B$13,COUNTIF(Config!$A$10:$A$13,"<="&I17)))) | M17: =IF(H17="Vencida",E17*I17+ROW()/100000,0) -> 0 | N17: =IF(AND(H17="A vencer",J17<=Config!$B$7),100000-J17-ROW()/100000,0) -> 0
A18: 9586960-92.2026.8.26.0106 | B18: =IF(A18="","",IFERROR(INDEX(Casos!$B$5:$B$204,MATCH(A18,Casos!$A$5:$A$204,0)),"")) -> Construtora Horizonte | C18: 2 | D18: 46262 | E18: 2100 | F18: Sim | G18: 46262 | H18: =IF(A18="","",IF(F18="Sim","Paga",IF(D18="","Sem vencimento",IF(D18<Config!$B$5,"Vencida","A vencer")))) -> Paga | I18: =IF(H18="Vencida",Config!$B$5-D18,"") | J18: =IF(H18="A vencer",D18-Config!$B$5,"") | K18: =IF(H18<>"Vencida","",IF(COUNTIF(Config!$A$10:$A$13,"<="&I18)=0,"Antes da régua",INDEX(Config!$C$10:$C$13,COUNTIF(Config!$A$10:$A$13,"<="&I18)))) | L18: =IF(H18<>"Vencida","",IF(COUNTIF(Config!$A$10:$A$13,"<="&I18)=0,"Aguardar: ainda não chegou ao primeiro passo da régua.",INDEX(Config!$B$10:$B$13,COUNTIF(Config!$A$10:$A$13,"<="&I18)))) | M18: =IF(H18="Vencida",E18*I18+ROW()/100000,0) -> 0 | N18: =IF(AND(H18="A vencer",J18<=Config!$B$7),100000-J18-ROW()/100000,0) -> 0
A19: 9586960-92.2026.8.26.0106 | B19: =IF(A19="","",IFERROR(INDEX(Casos!$B$5:$B$204,MATCH(A19,Casos!$A$5:$A$204,0)),"")) -> Construtora Horizonte | C19: 3 | D19: 46293 | E19: 2100 | F19: Não | H19: =IF(A19="","",IF(F19="Sim","Paga",IF(D19="","Sem vencimento",IF(D19<Config!$B$5,"Vencida","A vencer")))) -> A vencer | I19: =IF(H19="Vencida",Config!$B$5-D19,"") | J19: =IF(H19="A vencer",D19-Config!$B$5,"") -> 14 | K19: =IF(H19<>"Vencida","",IF(COUNTIF(Config!$A$10:$A$13,"<="&I19)=0,"Antes da régua",INDEX(Config!$C$10:$C$13,COUNTIF(Config!$A$10:$A$13,"<="&I19)))) | L19: =IF(H19<>"Vencida","",IF(COUNTIF(Config!$A$10:$A$13,"<="&I19)=0,"Aguardar: ainda não chegou ao primeiro passo da régua.",INDEX(Config!$B$10:$B$13,COUNTIF(Config!$A$10:$A$13,"<="&I19)))) | M19: =IF(H19="Vencida",E19*I19+ROW()/100000,0) -> 0 | N19: =IF(AND(H19="A vencer",J19<=Config!$B$7),100000-J19-ROW()/100000,0) -> 99986
A20: 9586960-92.2026.8.26.0106 | B20: =IF(A20="","",IFERROR(INDEX(Casos!$B$5:$B$204,MATCH(A20,Casos!$A$5:$A$204,0)),"")) -> Construtora Horizonte | C20: 4 | D20: 46323 | E20: 2100 | F20: Não | H20: =IF(A20="","",IF(F20="Sim","Paga",IF(D20="","Sem vencimento",IF(D20<Config!$B$5,"Vencida","A vencer")))) -> A vencer | I20: =IF(H20="Vencida",Config!$B$5-D20,"") | J20: =IF(H20="A vencer",D20-Config!$B$5,"") -> 44 | K20: =IF(H20<>"Vencida","",IF(COUNTIF(Config!$A$10:$A$13,"<="&I20)=0,"Antes da régua",INDEX(Config!$C$10:$C$13,COUNTIF(Config!$A$10:$A$13,"<="&I20)))) | L20: =IF(H20<>"Vencida","",IF(COUNTIF(Config!$A$10:$A$13,"<="&I20)=0,"Aguardar: ainda não chegou ao primeiro passo da régua.",INDEX(Config!$B$10:$B$13,COUNTIF(Config!$A$10:$A$13,"<="&I20)))) | M20: =IF(H20="Vencida",E20*I20+ROW()/100000,0) -> 0 | N20: =IF(AND(H20="A vencer",J20<=Config!$B$7),100000-J20-ROW()/100000,0) -> 0
A21: 4746093-86.2026.8.26.0637 | B21: =IF(A21="","",IFERROR(INDEX(Casos!$B$5:$B$204,MATCH(A21,Casos!$A$5:$A$204,0)),"")) -> Carlos Eduardo Nunes | C21: 1 | D21: 46238 | E21: 2400 | F21: Sim | G21: 46234 | H21: =IF(A21="","",IF(F21="Sim","Paga",IF(D21="","Sem vencimento",IF(D21<Config!$B$5,"Vencida","A vencer")))) -> Paga | I21: =IF(H21="Vencida",Config!$B$5-D21,"") | J21: =IF(H21="A vencer",D21-Config!$B$5,"") | K21: =IF(H21<>"Vencida","",IF(COUNTIF(Config!$A$10:$A$13,"<="&I21)=0,"Antes da régua",INDEX(Config!$C$10:$C$13,COUNTIF(Config!$A$10:$A$13,"<="&I21)))) | L21: =IF(H21<>"Vencida","",IF(COUNTIF(Config!$A$10:$A$13,"<="&I21)=0,"Aguardar: ainda não chegou ao primeiro passo da régua.",INDEX(Config!$B$10:$B$13,COUNTIF(Config!$A$10:$A$13,"<="&I21)))) | M21: =IF(H21="Vencida",E21*I21+ROW()/100000,0) -> 0 | N21: =IF(AND(H21="A vencer",J21<=Config!$B$7),100000-J21-ROW()/100000,0) -> 0
A22: 4746093-86.2026.8.26.0637 | B22: =IF(A22="","",IFERROR(INDEX(Casos!$B$5:$B$204,MATCH(A22,Casos!$A$5:$A$204,0)),"")) -> Carlos Eduardo Nunes | C22: 2 | D22: 46265 | E22: 1500 | F22: Sim | G22: 46265 | H22: =IF(A22="","",IF(F22="Sim","Paga",IF(D22="","Sem vencimento",IF(D22<Config!$B$5,"Vencida","A vencer")))) -> Paga | I22: =IF(H22="Vencida",Config!$B$5-D22,"") | J22: =IF(H22="A vencer",D22-Config!$B$5,"") | K22: =IF(H22<>"Vencida","",IF(COUNTIF(Config!$A$10:$A$13,"<="&I22)=0,"Antes da régua",INDEX(Config!$C$10:$C$13,COUNTIF(Config!$A$10:$A$13,"<="&I22)))) | L22: =IF(H22<>"Vencida","",IF(COUNTIF(Config!$A$10:$A$13,"<="&I22)=0,"Aguardar: ainda não chegou ao primeiro passo da régua.",INDEX(Config!$B$10:$B$13,COUNTIF(Config!$A$10:$A$13,"<="&I22)))) | M22: =IF(H22="Vencida",E22*I22+ROW()/100000,0) -> 0 | N22: =IF(AND(H22="A vencer",J22<=Config!$B$7),100000-J22-ROW()/100000,0) -> 0
A23: 4746093-86.2026.8.26.0637 | B23: =IF(A23="","",IFERROR(INDEX(Casos!$B$5:$B$204,MATCH(A23,Casos!$A$5:$A$204,0)),"")) -> Carlos Eduardo Nunes | C23: 3 | D23: 46295 | E23: 1500 | F23: Não | H23: =IF(A23="","",IF(F23="Sim","Paga",IF(D23="","Sem vencimento",IF(D23<Config!$B$5,"Vencida","A vencer")))) -> A vencer | I23: =IF(H23="Vencida",Config!$B$5-D23,"") | J23: =IF(H23="A vencer",D23-Config!$B$5,"") -> 16 | K23: =IF(H23<>"Vencida","",IF(COUNTIF(Config!$A$10:$A$13,"<="&I23)=0,"Antes da régua",INDEX(Config!$C$10:$C$13,COUNTIF(Config!$A$10:$A$13,"<="&I23)))) | L23: =IF(H23<>"Vencida","",IF(COUNTIF(Config!$A$10:$A$13,"<="&I23)=0,"Aguardar: ainda não chegou ao primeiro passo da régua.",INDEX(Config!$B$10:$B$13,COUNTIF(Config!$A$10:$A$13,"<="&I23)))) | M23: =IF(H23="Vencida",E23*I23+ROW()/100000,0) -> 0 | N23: =IF(AND(H23="A vencer",J23<=Config!$B$7),100000-J23-ROW()/100000,0) -> 99984
