Workbook

Sheet Como usar
A1: Funil de Propostas
A2: Kit de Gestão para Advogados · Seu Sócio Gestor · versão 1.0 (setembro de 2026)
A4: O que esta planilha faz | B4: Você registra cada proposta de honorários com valor e etapa; ela calcula a previsão ponderada, mostra o funil por etapa, o que está parado ou com previsão vencida, a taxa de fechamento por área e origem e por que o escritório perde propostas.
A5: Passo 1 | B5: Em Config, preencha a meta de honorários fechados no trimestre, o limite de "parada" (14 dias é um bom padrão), as áreas, origens, motivos de perda, responsáveis e serviços. Ajuste as probabilidades por etapa se a sua experiência for diferente.
A6: Passo 2 | B6: Em Propostas, uma linha por proposta: cliente, área, serviço, origem, responsável, valor, etapa e datas. Sempre que falar com o cliente, atualize a última movimentação.
A7: Passo 3 | B7: Ao fechar, mude a etapa para Fechada ou Perdida e preencha a data. Se perdida, anote o motivo: é a parte mais valiosa da planilha.
A8: Passo 4 | B8: Em Painel, veja o funil, a previsão ponderada, a lista "O que mexer primeiro", a taxa de fechamento por área e origem e os motivos de perda.
A9: Rotina | B9: Sexta-feira, 10 minutos: atualizar etapas e datas, retomar as paradas. Dia 1 do mês: comparar o fechado com a meta e olhar os motivos de perda.
A10: Com a IA | B10: Copie "Motivos de perda" e use o prompt "Clientes 06 · Por que as propostas não fecham" da biblioteca; para uma proposta parada, "Honorários 02 · Revisar a proposta pela margem" antes de retomar o contato. A proposta fechada vira caso na planilha 13 (Carteira).
A11: Exemplo | B11: O funil traz 20 propostas de junho a setembro de 2026: as 7 fechadas viraram casos na planilha 13 (abertura no mês do fechamento) e as 10 mais recentes já enviadas são as mesmas do Registro da planilha 07.
A12: Legenda | B12: Células amarelas: você preenche. Brancas: calculadas. Não é preciso mexer em nada fora do amarelo.
A13: Proteção | B13: Fórmulas protegidas sem senha. Para editar: Revisar > Desproteger planilha (Excel) ou Dados > Proteger intervalos (Google Sheets).
A14: Requisitos | B14: Excel 2016 ou mais novo, Microsoft 365 ou Google Sheets (só funções do Excel 2007+; nada de MÍNIMOSES, MÁXIMOSES ou UNIRTEXTO). No celular abre nos aplicativos; para preencher, use o computador.
A15: Google Sheets | B15: Faça upload no Google Drive e abra com o Google Sheets. Fórmulas, listas, cores, semáforos e gráficos funcionam: as regras de cor que dependem do mês escolhido em Config usam INDIRECT, que é a forma que o Sheets aceita para regra condicional apontar para outra aba.
... A18: Suporte | B18: suporte@seusociogestor.com.br · resposta em até 5 dias úteis · reembolso em até 7 dias pelo mesmo canal.

Sheet Painel
A1: =Config!$B$4&" · Funil de propostas · "&TEXT(DAY(Config!$B$5),"00")&"/"&TEXT(MONTH(Config!$B$5),"00")&"/"&YEAR(Config!$B$5) -> Ferraz & Lima Advocacia (exemplo fictício) · Funil de propostas · 14/09/2026
A2: Nada para digitar aqui: tudo vem de Propostas e Config.
A4: Em aberto (R$) | C4: Previsão ponderada | E4: Fechado no trimestre | G4: % da meta | I4: Taxa de fechamento | K4: Dias até fechar (média)
A5: =SUMIFS(Propostas!$F$5:$F$304,Propostas!$G$5:$G$304,"<>Fechada",Propostas!$G$5:$G$304,"<>Perdida",Propostas!$G$5:$G$304,"<>") -> 72900 | C5: =SUMIFS(Propostas!$N$5:$N$304,Propostas!$G$5:$G$304,"<>Fechada",Propostas!$G$5:$G$304,"<>Perdida",Propostas!$G$5:$G$304,"<>") -> 30805 | E5: =SUMIFS(Propostas!$F$5:$F$304,Propostas!$G$5:$G$304,"Fechada",Propostas!$K$5:$K$304,">="&DATE(YEAR(Config!$B$5),3*INT((MONTH(Config!$B$5)-1)/3)+1,1),Propostas!$K$5:$K$304,"<"&DATE(YEAR(Config!$B$5)+(3*INT((MONTH(Config!$B$5)-1)/3)+4>12),IF(3*INT((MONTH(Config!$B$5)-1)/3)+4>12,1,3*INT((MONTH(Config!$B$5)-1)/3)+4),1)) -> 53000 | G5: =IFERROR(E5/Config!$B$6,0) -> 0.88333333 | I5: =IFERROR(COUNTIFS(Propostas!$G$5:$G$304,"Fechada")/(COUNTIFS(Propostas!$G$5:$G$304,"Fechada")+COUNTIFS(Propostas!$G$5:$G$304,"Perdida")),0) -> 0.63636364 | K5: =IFERROR(AVERAGEIFS(Propostas!$P$5:$P$304,Propostas!$G$5:$G$304,"Fechada"),0) -> 19.571429
A7: Taxa de fechamento = fechadas ÷ (fechadas + perdidas). Dias até fechar = da data de entrada à data de fechamento, média das fechadas.
A9: Funil por etapa
A10: Etapa | B10: Propostas | C10: Valor (R$) | D10: Ponderado (R$) | E10: Taxa de passagem | F10: Barra
A11: =Config!$A$10 -> Contato | B11: =COUNTIFS(Propostas!$G$5:$G$304,A11) -> 2 | C11: =SUMIFS(Propostas!$F$5:$F$304,Propostas!$G$5:$G$304,A11) -> 18800 | D11: =SUMIFS(Propostas!$N$5:$N$304,Propostas!$G$5:$G$304,A11) -> 1880 | E11: =IFERROR((COUNTIFS(Propostas!$G$5:$G$304,Config!$A$11)+COUNTIFS(Propostas!$G$5:$G$304,Config!$A$12)+COUNTIFS(Propostas!$G$5:$G$304,Config!$A$13)+COUNTIFS(Propostas!$G$5:$G$304,Config!$A$14)+COUNTIFS(Propostas!$G$5:$G$304,Config!$A$15))/(B11+COUNTIFS(Propostas!$G$5:$G$304,Config!$A$11)+COUNTIFS(Propostas!$G$5:$G$304,Config!$A$12)+COUNTIFS(Propostas!$G$5:$G$304,Config!$A$13)+COUNTIFS(Propostas!$G$5:$G$304,Config!$A$14)+COUNTIFS(Propostas!$G$5:$G$304,Config!$A$15)),0) -> 0.9 | F11: =REPT("█",ROUND(IFERROR(C11/MAX($C$11:$C$14),0)*30,0)) -> ███████████████████████████
A12: =Config!$A$11 -> Reunião feita | B12: =COUNTIFS(Propostas!$G$5:$G$304,A12) -> 2 | C12: =SUMIFS(Propostas!$F$5:$F$304,Propostas!$G$5:$G$304,A12) -> 13700 | D12: =SUMIFS(Propostas!$N$5:$N$304,Propostas!$G$5:$G$304,A12) -> 3425 | E12: =IFERROR((COUNTIFS(Propostas!$G$5:$G$304,Config!$A$12)+COUNTIFS(Propostas!$G$5:$G$304,Config!$A$13)+COUNTIFS(Propostas!$G$5:$G$304,Config!$A$14)+COUNTIFS(Propostas!$G$5:$G$304,Config!$A$15))/(B12+COUNTIFS(Propostas!$G$5:$G$304,Config!$A$12)+COUNTIFS(Propostas!$G$5:$G$304,Config!$A$13)+COUNTIFS(Propostas!$G$5:$G$304,Config!$A$14)+COUNTIFS(Propostas!$G$5:$G$304,Config!$A$15)),0) -> 0.88888889 | F12: =REPT("█",ROUND(IFERROR(C12/MAX($C$11:$C$14),0)*30,0)) -> ███████████████████
A13: =Config!$A$12 -> Proposta enviada | B13: =COUNTIFS(Propostas!$G$5:$G$304,A13) -> 3 | C13: =SUMIFS(Propostas!$F$5:$F$304,Propostas!$G$5:$G$304,A13) -> 19200 | D13: =SUMIFS(Propostas!$N$5:$N$304,Propostas!$G$5:$G$304,A13) -> 9600 | E13: =IFERROR((COUNTIFS(Propostas!$G$5:$G$304,Config!$A$13)+COUNTIFS(Propostas!$G$5:$G$304,Config!$A$14)+COUNTIFS(Propostas!$G$5:$G$304,Config!$A$15))/(B13+COUNTIFS(Propostas!$G$5:$G$304,Config!$A$13)+COUNTIFS(Propostas!$G$5:$G$304,Config!$A$14)+COUNTIFS(Propostas!$G$5:$G$304,Config!$A$15)),0) -> 0.8125 | F13: =REPT("█",ROUND(IFERROR(C13/MAX($C$11:$C$14),0)*30,0)) -> ███████████████████████████
A14: =Config!$A$13 -> Negociação | B14: =COUNTIFS(Propostas!$G$5:$G$304,A14) -> 2 | C14: =SUMIFS(Propostas!$F$5:$F$304,Propostas!$G$5:$G$304,A14) -> 21200 | D14: =SUMIFS(Propostas!$N$5:$N$304,Propostas!$G$5:$G$304,A14) -> 15900 | E14: =IFERROR((COUNTIFS(Propostas!$G$5:$G$304,Config!$A$14)+COUNTIFS(Propostas!$G$5:$G$304,Config!$A$15))/(B14+COUNTIFS(Propostas!$G$5:$G$304,Config!$A$14)+COUNTIFS(Propostas!$G$5:$G$304,Config!$A$15)),0) -> 0.84615385 | F14: =REPT("█",ROUND(IFERROR(C14/MAX($C$11:$C$14),0)*30,0)) -> ██████████████████████████████
A15: Fechadas (total) | B15: =COUNTIFS(Propostas!$G$5:$G$304,"Fechada") -> 7 | C15: =SUMIFS(Propostas!$F$5:$F$304,Propostas!$G$5:$G$304,"Fechada") -> 71000
A16: Perdidas (total) | B16: =COUNTIFS(Propostas!$G$5:$G$304,"Perdida") -> 4 | C16: =SUMIFS(Propostas!$F$5:$F$304,Propostas!$G$5:$G$304,"Perdida") -> 27100
A17: Honorário médio das fechadas | B17: =IFERROR(C15/B15,0) -> 10142.857
A18: Taxa de passagem: de tudo o que chegou a uma etapa, quanto já seguiu adiante (inclui fechadas e perdidas).
A20: O que mexer primeiro
A21: Propostas abertas com previsão vencida ou paradas há mais tempo; as de maior valor primeiro.
A22: # | B22: Cliente | C22: Serviço | D22: Etapa | E22: Valor (R$) | F22: Dias parada | G22: Situação | H22: Responsável
A23: 1 | B23: =IFERROR(IF(LARGE(Propostas!$R$5:$R$304,1)>0,INDEX(Propostas!$A$5:$A$304,MATCH(LARGE(Propostas!$R$5:$R$304,1),Propostas!$R$5:$R$304,0)),""),"") -> Clínica Bem-Estar | C23: =IFERROR(IF(LARGE(Propostas!$R$5:$R$304,1)>0,INDEX(Propostas!$C$5:$C$304,MATCH(LARGE(Propostas!$R$5:$R$304,1),Propostas!$R$5:$R$304,0)),""),"") -> Contratos com convênios | D23: =IFERROR(IF(LARGE(Propostas!$R$5:$R$304,1)>0,INDEX(Propostas!$G$5:$G$304,MATCH(LARGE(Propostas!$R$5:$R$304,1),Propostas!$R$5:$R$304,0)),""),"") -> Negociação | E23: =IFERROR(IF(LARGE(Propostas!$R$5:$R$304,1)>0,INDEX(Propostas!$F$5:$F$304,MATCH(LARGE(Propostas!$R$5:$R$304,1),Propostas!$R$5:$R$304,0)),""),"") -> 6800 | F23: =IFERROR(IF(LARGE(Propostas!$R$5:$R$304,1)>0,INDEX(Propostas!$O$5:$O$304,MATCH(LARGE(Propostas!$R$5:$R$304,1),Propostas!$R$5:$R$304,0)),""),"") -> 17 | G23: =IFERROR(IF(LARGE(Propostas!$R$5:$R$304,1)>0,INDEX(Propostas!$Q$5:$Q$304,MATCH(LARGE(Propostas!$R$5:$R$304,1),Propostas!$R$5:$R$304,0)),""),"") -> Previsão vencida | H23: =IFERROR(IF(LARGE(Propostas!$R$5:$R$304,1)>0,INDEX(Propostas!$E$5:$E$304,MATCH(LARGE(Propostas!$R$5:$R$304,1),Propostas!$R$5:$R$304,0)),""),"") -> Marina Ferraz
A24: 2 | B24: =IFERROR(IF(LARGE(Propostas!$R$5:$R$304,2)>0,INDEX(Propostas!$A$5:$A$304,MATCH(LARGE(Propostas!$R$5:$R$304,2),Propostas!$R$5:$R$304,0)),""),"") -> José Antônio Ribeiro | C24: =IFERROR(IF(LARGE(Propostas!$R$5:$R$304,2)>0,INDEX(Propostas!$C$5:$C$304,MATCH(LARGE(Propostas!$R$5:$R$304,2),Propostas!$R$5:$R$304,0)),""),"") -> Revisão de benefício | D24: =IFERROR(IF(LARGE(Propostas!$R$5:$R$304,2)>0,INDEX(Propostas!$G$5:$G$304,MATCH(LARGE(Propostas!$R$5:$R$304,2),Propostas!$R$5:$R$304,0)),""),"") -> Proposta enviada | E24: =IFERROR(IF(LARGE(Propostas!$R$5:$R$304,2)>0,INDEX(Propostas!$F$5:$F$304,MATCH(LARGE(Propostas!$R$5:$R$304,2),Propostas!$R$5:$R$304,0)),""),"") -> 4200 | F24: =IFERROR(IF(LARGE(Propostas!$R$5:$R$304,2)>0,INDEX(Propostas!$O$5:$O$304,MATCH(LARGE(Propostas!$R$5:$R$304,2),Propostas!$R$5:$R$304,0)),""),"") -> 14 | G24: =IFERROR(IF(LARGE(Propostas!$R$5:$R$304,2)>0,INDEX(Propostas!$Q$5:$Q$304,MATCH(LARGE(Propostas!$R$5:$R$304,2),Propostas!$R$5:$R$304,0)),""),"") -> Previsão vencida | H24: =IFERROR(IF(LARGE(Propostas!$R$5:$R$304,2)>0,INDEX(Propostas!$E$5:$E$304,MATCH(LARGE(Propostas!$R$5:$R$304,2),Propostas!$R$5:$R$304,0)),""),"") -> Rafael Lima
A25: 3 | B25: =IFERROR(IF(LARGE(Propostas!$R$5:$R$304,3)>0,INDEX(Propostas!$A$5:$A$304,MATCH(LARGE(Propostas!$R$5:$R$304,3),Propostas!$R$5:$R$304,0)),""),"") -> Patrícia Gomes | C25: =IFERROR(IF(LARGE(Propostas!$R$5:$R$304,3)>0,INDEX(Propostas!$C$5:$C$304,MATCH(LARGE(Propostas!$R$5:$R$304,3),Propostas!$R$5:$R$304,0)),""),"") -> Inventário | D25: =IFERROR(IF(LARGE(Propostas!$R$5:$R$304,3)>0,INDEX(Propostas!$G$5:$G$304,MATCH(LARGE(Propostas!$R$5:$R$304,3),Propostas!$R$5:$R$304,0)),""),"") -> Proposta enviada | E25: =IFERROR(IF(LARGE(Propostas!$R$5:$R$304,3)>0,INDEX(Propostas!$F$5:$F$304,MATCH(LARGE(Propostas!$R$5:$R$304,3),Propostas!$R$5:$R$304,0)),""),"") -> 10500 | F25: =IFERROR(IF(LARGE(Propostas!$R$5:$R$304,3)>0,INDEX(Propostas!$O$5:$O$304,MATCH(LARGE(Propostas!$R$5:$R$304,3),Propostas!$R$5:$R$304,0)),""),"") -> 16 | G25: =IFERROR(IF(LARGE(Propostas!$R$5:$R$304,3)>0,INDEX(Propostas!$Q$5:$Q$304,MATCH(LARGE(Propostas!$R$5:$R$304,3),Propostas!$R$5:$R$304,0)),""),"") -> Parada | H25: =IFERROR(IF(LARGE(Propostas!$R$5:$R$304,3)>0,INDEX(Propostas!$E$5:$E$304,MATCH(LARGE(Propostas!$R$5:$R$304,3),Propostas!$R$5:$R$304,0)),""),"") -> Marina Ferraz
A26: 4 | B26: =IFERROR(IF(LARGE(Propostas!$R$5:$R$304,4)>0,INDEX(Propostas!$A$5:$A$304,MATCH(LARGE(Propostas!$R$5:$R$304,4),Propostas!$R$5:$R$304,0)),""),"") -> Transportadora Rota Sul | C26: =IFERROR(IF(LARGE(Propostas!$R$5:$R$304,4)>0,INDEX(Propostas!$C$5:$C$304,MATCH(LARGE(Propostas!$R$5:$R$304,4),Propostas!$R$5:$R$304,0)),""),"") -> Assessoria mensal (12 meses) | D26: =IFERROR(IF(LARGE(Propostas!$R$5:$R$304,4)>0,INDEX(Propostas!$G$5:$G$304,MATCH(LARGE(Propostas!$R$5:$R$304,4),Propostas!$R$5:$R$304,0)),""),"") -> Negociação | E26: =IFERROR(IF(LARGE(Propostas!$R$5:$R$304,4)>0,INDEX(Propostas!$F$5:$F$304,MATCH(LARGE(Propostas!$R$5:$R$304,4),Propostas!$R$5:$R$304,0)),""),"") -> 14400 | F26: =IFERROR(IF(LARGE(Propostas!$R$5:$R$304,4)>0,INDEX(Propostas!$O$5:$O$304,MATCH(LARGE(Propostas!$R$5:$R$304,4),Propostas!$R$5:$R$304,0)),""),"") -> 4 | G26: =IFERROR(IF(LARGE(Propostas!$R$5:$R$304,4)>0,INDEX(Propostas!$Q$5:$Q$304,MATCH(LARGE(Propostas!$R$5:$R$304,4),Propostas!$R$5:$R$304,0)),""),"") -> Ativa | H26: =IFERROR(IF(LARGE(Propostas!$R$5:$R$304,4)>0,INDEX(Propostas!$E$5:$E$304,MATCH(LARGE(Propostas!$R$5:$R$304,4),Propostas!$R$5:$R$304,0)),""),"") -> Rafael Lima
A27: 5 | B27: =IFERROR(IF(LARGE(Propostas!$R$5:$R$304,5)>0,INDEX(Propostas!$A$5:$A$304,MATCH(LARGE(Propostas!$R$5:$R$304,5),Propostas!$R$5:$R$304,0)),""),"") -> Helena Duarte | C27: =IFERROR(IF(LARGE(Propostas!$R$5:$R$304,5)>0,INDEX(Propostas!$C$5:$C$304,MATCH(LARGE(Propostas!$R$5:$R$304,5),Propostas!$R$5:$R$304,0)),""),"") -> Ação trabalhista | D27: =IFERROR(IF(LARGE(Propostas!$R$5:$R$304,5)>0,INDEX(Propostas!$G$5:$G$304,MATCH(LARGE(Propostas!$R$5:$R$304,5),Propostas!$R$5:$R$304,0)),""),"") -> Reunião feita | E27: =IFERROR(IF(LARGE(Propostas!$R$5:$R$304,5)>0,INDEX(Propostas!$F$5:$F$304,MATCH(LARGE(Propostas!$R$5:$R$304,5),Propostas!$R$5:$R$304,0)),""),"") -> 5800 | F27: =IFERROR(IF(LARGE(Propostas!$R$5:$R$304,5)>0,INDEX(Propostas!$O$5:$O$304,MATCH(LARGE(Propostas!$R$5:$R$304,5),Propostas!$R$5:$R$304,0)),""),"") -> 3 | G27: =IFERROR(IF(LARGE(Propostas!$R$5:$R$304,5)>0,INDEX(Propostas!$Q$5:$Q$304,MATCH(LARGE(Propostas!$R$5:$R$304,5),Propostas!$R$5:$R$304,0)),""),"") -> Ativa | H27: =IFERROR(IF(LARGE(Propostas!$R$5:$R$304,5)>0,INDEX(Propostas!$E$5:$E$304,MATCH(LARGE(Propostas!$R$5:$R$304,5),Propostas!$R$5:$R$304,0)),""),"") -> Rafael Lima
A28: 6 | B28: =IFERROR(IF(LARGE(Propostas!$R$5:$R$304,6)>0,INDEX(Propostas!$A$5:$A$304,MATCH(LARGE(Propostas!$R$5:$R$304,6),Propostas!$R$5:$R$304,0)),""),"") -> Marcos Vinícius Teles | C28: =IFERROR(IF(LARGE(Propostas!$R$5:$R$304,6)>0,INDEX(Propostas!$C$5:$C$304,MATCH(LARGE(Propostas!$R$5:$R$304,6),Propostas!$R$5:$R$304,0)),""),"") -> Divórcio e partilha | D28: =IFERROR(IF(LARGE(Propostas!$R$5:$R$304,6)>0,INDEX(Propostas!$G$5:$G$304,MATCH(LARGE(Propostas!$R$5:$R$304,6),Propostas!$R$5:$R$304,0)),""),"") -> Contato | E28: =IFERROR(IF(LARGE(Propostas!$R$5:$R$304,6)>0,INDEX(Propostas!$F$5:$F$304,MATCH(LARGE(Propostas!$R$5:$R$304,6),Propostas!$R$5:$R$304,0)),""),"") -> 5600 | F28: =IFERROR(IF(LARGE(Propostas!$R$5:$R$304,6)>0,INDEX(Propostas!$O$5:$O$304,MATCH(LARGE(Propostas!$R$5:$R$304,6),Propostas!$R$5:$R$304,0)),""),"") -> 3 | G28: =IFERROR(IF(LARGE(Propostas!$R$5:$R$304,6)>0,INDEX(Propostas!$Q$5:$Q$304,MATCH(LARGE(Propostas!$R$5:$R$304,6),Propostas!$R$5:$R$304,0)),""),"") -> Ativa | H28: =IFERROR(IF(LARGE(Propostas!$R$5:$R$304,6)>0,INDEX(Propostas!$E$5:$E$304,MATCH(LARGE(Propostas!$R$5:$R$304,6),Propostas!$R$5:$R$304,0)),""),"") -> Marina Ferraz
A29: 7 | B29: =IFERROR(IF(LARGE(Propostas!$R$5:$R$304,7)>0,INDEX(Propostas!$A$5:$A$304,MATCH(LARGE(Propostas!$R$5:$R$304,7),Propostas!$R$5:$R$304,0)),""),"") -> Luciana Farias | C29: =IFERROR(IF(LARGE(Propostas!$R$5:$R$304,7)>0,INDEX(Propostas!$C$5:$C$304,MATCH(LARGE(Propostas!$R$5:$R$304,7),Propostas!$R$5:$R$304,0)),""),"") -> Cobrança judicial | D29: =IFERROR(IF(LARGE(Propostas!$R$5:$R$304,7)>0,INDEX(Propostas!$G$5:$G$304,MATCH(LARGE(Propostas!$R$5:$R$304,7),Propostas!$R$5:$R$304,0)),""),"") -> Reunião feita | E29: =IFERROR(IF(LARGE(Propostas!$R$5:$R$304,7)>0,INDEX(Propostas!$F$5:$F$304,MATCH(LARGE(Propostas!$R$5:$R$304,7),Propostas!$R$5:$R$304,0)),""),"") -> 7900 | F29: =IFERROR(IF(LARGE(Propostas!$R$5:$R$304,7)>0,INDEX(Propostas!$O$5:$O$304,MATCH(LARGE(Propostas!$R$5:$R$304,7),Propostas!$R$5:$R$304,0)),""),"") -> 2 | G29: =IFERROR(IF(LARGE(Propostas!$R$5:$R$304,7)>0,INDEX(Propostas!$Q$5:$Q$304,MATCH(LARGE(Propostas!$R$5:$R$304,7),Propostas!$R$5:$R$304,0)),""),"") -> Ativa | H29: =IFERROR(IF(LARGE(Propostas!$R$5:$R$304,7)>0,INDEX(Propostas!$E$5:$E$304,MATCH(LARGE(Propostas!$R$5:$R$304,7),Propostas!$R$5:$R$304,0)),""),"") -> Marina Ferraz
A30: 8 | B30: =IFERROR(IF(LARGE(Propostas!$R$5:$R$304,8)>0,INDEX(Propostas!$A$5:$A$304,MATCH(LARGE(Propostas!$R$5:$R$304,8),Propostas!$R$5:$R$304,0)),""),"") -> Construtora Horizonte | C30: =IFERROR(IF(LARGE(Propostas!$R$5:$R$304,8)>0,INDEX(Propostas!$C$5:$C$304,MATCH(LARGE(Propostas!$R$5:$R$304,8),Propostas!$R$5:$R$304,0)),""),"") -> Assessoria mensal (12 meses) | D30: =IFERROR(IF(LARGE(Propostas!$R$5:$R$304,8)>0,INDEX(Propostas!$G$5:$G$304,MATCH(LARGE(Propostas!$R$5:$R$304,8),Propostas!$R$5:$R$304,0)),""),"") -> Contato | E30: =IFERROR(IF(LARGE(Propostas!$R$5:$R$304,8)>0,INDEX(Propostas!$F$5:$F$304,MATCH(LARGE(Propostas!$R$5:$R$304,8),Propostas!$R$5:$R$304,0)),""),"") -> 13200 | F30: =IFERROR(IF(LARGE(Propostas!$R$5:$R$304,8)>0,INDEX(Propostas!$O$5:$O$304,MATCH(LARGE(Propostas!$R$5:$R$304,8),Propostas!$R$5:$R$304,0)),""),"") -> 1 | G30: =IFERROR(IF(LARGE(Propostas!$R$5:$R$304,8)>0,INDEX(Propostas!$Q$5:$Q$304,MATCH(LARGE(Propostas!$R$5:$R$304,8),Propostas!$R$5:$R$304,0)),""),"") -> Ativa | H30: =IFERROR(IF(LARGE(Propostas!$R$5:$R$304,8)>0,INDEX(Propostas!$E$5:$E$304,MATCH(LARGE(Propostas!$R$5:$R$304,8),Propostas!$R$5:$R$304,0)),""),"") -> Marina Ferraz
A32: Por área
A33: Área | B33: Propostas | C33: Fechadas | D33: Perdidas | E33: Taxa de fechamento | F33: Valor fechado (R$) | G33: Em aberto (R$)
A34: =IF(Config!$A$18="","",Config!$A$18) -> Cível | B34: =IF(Config!$A$18="","",COUNTIFS(Propostas!$B$5:$B$304,Config!$A$18)) -> 4 | C34: =IF(Config!$A$18="","",COUNTIFS(Propostas!$B$5:$B$304,Config!$A$18,Propostas!$G$5:$G$304,"Fechada")) -> 2 | D34: =IF(Config!$A$18="","",COUNTIFS(Propostas!$B$5:$B$304,Config!$A$18,Propostas!$G$5:$G$304,"Perdida")) -> 0 | E34: =IF(Config!$A$18="","",IFERROR(C34/(C34+D34),0)) -> 1 | F34: =IF(Config!$A$18="","",SUMIFS(Propostas!$F$5:$F$304,Propostas!$B$5:$B$304,Config!$A$18,Propostas!$G$5:$G$304,"Fechada")) -> 28700 | G34: =IF(Config!$A$18="","",SUMIFS(Propostas!$F$5:$F$304,Propostas!$B$5:$B$304,Config!$A$18,Propostas!$G$5:$G$304,"<>Fechada",Propostas!$G$5:$G$304,"<>Perdida",Propostas!$G$5:$G$304,"<>")) -> 12400
A35: =IF(Config!$A$19="","",Config!$A$19) -> Trabalhista | B35: =IF(Config!$A$19="","",COUNTIFS(Propostas!$B$5:$B$304,Config!$A$19)) -> 5 | C35: =IF(Config!$A$19="","",COUNTIFS(Propostas!$B$5:$B$304,Config!$A$19,Propostas!$G$5:$G$304,"Fechada")) -> 1 | D35: =IF(Config!$A$19="","",COUNTIFS(Propostas!$B$5:$B$304,Config!$A$19,Propostas!$G$5:$G$304,"Perdida")) -> 2 | E35: =IF(Config!$A$19="","",IFERROR(C35/(C35+D35),0)) -> 0.33333333 | F35: =IF(Config!$A$19="","",SUMIFS(Propostas!$F$5:$F$304,Propostas!$B$5:$B$304,Config!$A$19,Propostas!$G$5:$G$304,"Fechada")) -> 6000 | G35: =IF(Config!$A$19="","",SUMIFS(Propostas!$F$5:$F$304,Propostas!$B$5:$B$304,Config!$A$19,Propostas!$G$5:$G$304,"<>Fechada",Propostas!$G$5:$G$304,"<>Perdida",Propostas!$G$5:$G$304,"<>")) -> 20200
A36: =IF(Config!$A$20="","",Config!$A$20) -> Previdenciário | B36: =IF(Config!$A$20="","",COUNTIFS(Propostas!$B$5:$B$304,Config!$A$20)) -> 3 | C36: =IF(Config!$A$20="","",COUNTIFS(Propostas!$B$5:$B$304,Config!$A$20,Propostas!$G$5:$G$304,"Fechada")) -> 2 | D36: =IF(Config!$A$20="","",COUNTIFS(Propostas!$B$5:$B$304,Config!$A$20,Propostas!$G$5:$G$304,"Perdida")) -> 0 | E36: =IF(Config!$A$20="","",IFERROR(C36/(C36+D36),0)) -> 1 | F36: =IF(Config!$A$20="","",SUMIFS(Propostas!$F$5:$F$304,Propostas!$B$5:$B$304,Config!$A$20,Propostas!$G$5:$G$304,"Fechada")) -> 9900 | G36: =IF(Config!$A$20="","",SUMIFS(Propostas!$F$5:$F$304,Propostas!$B$5:$B$304,Config!$A$20,Propostas!$G$5:$G$304,"<>Fechada",Propostas!$G$5:$G$304,"<>Perdida",Propostas!$G$5:$G$304,"<>")) -> 4200
A37: =IF(Config!$A$21="","",Config!$A$21) -> Empresarial | B37: =IF(Config!$A$21="","",COUNTIFS(Propostas!$B$5:$B$304,Config!$A$21)) -> 5 | C37: =IF(Config!$A$21="","",COUNTIFS(Propostas!$B$5:$B$304,Config!$A$21,Propostas!$G$5:$G$304,"Fechada")) -> 2 | D37: =IF(Config!$A$21="","",COUNTIFS(Propostas!$B$5:$B$304,Config!$A$21,Propostas!$G$5:$G$304,"Perdida")) -> 1 | E37: =IF(Config!$A$21="","",IFERROR(C37/(C37+D37),0)) -> 0.66666667 | F37: =IF(Config!$A$21="","",SUMIFS(Propostas!$F$5:$F$304,Propostas!$B$5:$B$304,Config!$A$21,Propostas!$G$5:$G$304,"Fechada")) -> 26400 | G37: =IF(Config!$A$21="","",SUMIFS(Propostas!$F$5:$F$304,Propostas!$B$5:$B$304,Config!$A$21,Propostas!$G$5:$G$304,"<>Fechada",Propostas!$G$5:$G$304,"<>Perdida",Propostas!$G$5:$G$304,"<>")) -> 20000
A38: =IF(Config!$A$22="","",Config!$A$22) -> Família | B38: =IF(Config!$A$22="","",COUNTIFS(Propostas!$B$5:$B$304,Config!$A$22)) -> 3 | C38: =IF(Config!$A$22="","",COUNTIFS(Propostas!$B$5:$B$304,Config!$A$22,Propostas!$G$5:$G$304,"Fechada")) -> 0 | D38: =IF(Config!$A$22="","",COUNTIFS(Propostas!$B$5:$B$304,Config!$A$22,Propostas!$G$5:$G$304,"Perdida")) -> 1 | E38: =IF(Config!$A$22="","",IFERROR(C38/(C38+D38),0)) -> 0 | F38: =IF(Config!$A$22="","",SUMIFS(Propostas!$F$5:$F$304,Propostas!$B$5:$B$304,Config!$A$22,Propostas!$G$5:$G$304,"Fechada")) -> 0 | G38: =IF(Config!$A$22="","",SUMIFS(Propostas!$F$5:$F$304,Propostas!$B$5:$B$304,Config!$A$22,Propostas!$G$5:$G$304,"<>Fechada",Propostas!$G$5:$G$304,"<>Perdida",Propostas!$G$5:$G$304,"<>")) -> 16100
A39: =IF(Config!$A$23="","",Config!$A$23) | B39: =IF(Config!$A$23="","",COUNTIFS(Propostas!$B$5:$B$304,Config!$A$23)) | C39: =IF(Config!$A$23="","",COUNTIFS(Propostas!$B$5:$B$304,Config!$A$23,Propostas!$G$5:$G$304,"Fechada")) | D39: =IF(Config!$A$23="","",COUNTIFS(Propostas!$B$5:$B$304,Config!$A$23,Propostas!$G$5:$G$304,"Perdida")) | E39: =IF(Config!$A$23="","",IFERROR(C39/(C39+D39),0)) | F39: =IF(Config!$A$23="","",SUMIFS(Propostas!$F$5:$F$304,Propostas!$B$5:$B$304,Config!$A$23,Propostas!$G$5:$G$304,"Fechada")) | G39: =IF(Config!$A$23="","",SUMIFS(Propostas!$F$5:$F$304,Propostas!$B$5:$B$304,Config!$A$23,Propostas!$G$5:$G$304,"<>Fechada",Propostas!$G$5:$G$304,"<>Perdida",Propostas!$G$5:$G$304,"<>"))
A40: =IF(Config!$A$24="","",Config!$A$24) | B40: =IF(Config!$A$24="","",COUNTIFS(Propostas!$B$5:$B$304,Config!$A$24)) | C40: =IF(Config!$A$24="","",COUNTIFS(Propostas!$B$5:$B$304,Config!$A$24,Propostas!$G$5:$G$304,"Fechada")) | D40: =IF(Config!$A$24="","",COUNTIFS(Propostas!$B$5:$B$304,Config!$A$24,Propostas!$G$5:$G$304,"Perdida")) | E40: =IF(Config!$A$24="","",IFERROR(C40/(C40+D40),0)) | F40: =IF(Config!$A$24="","",SUMIFS(Propostas!$F$5:$F$304,Propostas!$B$5:$B$304,Config!$A$24,Propostas!$G$5:$G$304,"Fechada")) | G40: =IF(Config!$A$24="","",SUMIFS(Propostas!$F$5:$F$304,Propostas!$B$5:$B$304,Config!$A$24,Propostas!$G$5:$G$304,"<>Fechada",Propostas!$G$5:$G$304,"<>Perdida",Propostas!$G$5:$G$304,"<>"))
A41: =IF(Config!$A$25="","",Config!$A$25) | B41: =IF(Config!$A$25="","",COUNTIFS(Propostas!$B$5:$B$304,Config!$A$25)) | C41: =IF(Config!$A$25="","",COUNTIFS(Propostas!$B$5:$B$304,Config!$A$25,Propostas!$G$5:$G$304,"Fechada")) | D41: =IF(Config!$A$25="","",COUNTIFS(Propostas!$B$5:$B$304,Config!$A$25,Propostas!$G$5:$G$304,"Perdida")) | E41: =IF(Config!$A$25="","",IFERROR(C41/(C41+D41),0)) | F41: =IF(Config!$A$25="","",SUMIFS(Propostas!$F$5:$F$304,Propostas!$B$5:$B$304,Config!$A$25,Propostas!$G$5:$G$304,"Fechada")) | G41: =IF(Config!$A$25="","",SUMIFS(Propostas!$F$5:$F$304,Propostas!$B$5:$B$304,Config!$A$25,Propostas!$G$5:$G$304,"<>Fechada",Propostas!$G$5:$G$304,"<>Perdida",Propostas!$G$5:$G$304,"<>"))
A42: =IF(Config!$A$26="","",Config!$A$26) | B42: =IF(Config!$A$26="","",COUNTIFS(Propostas!$B$5:$B$304,Config!$A$26)) | C42: =IF(Config!$A$26="","",COUNTIFS(Propostas!$B$5:$B$304,Config!$A$26,Propostas!$G$5:$G$304,"Fechada")) | D42: =IF(Config!$A$26="","",COUNTIFS(Propostas!$B$5:$B$304,Config!$A$26,Propostas!$G$5:$G$304,"Perdida")) | E42: =IF(Config!$A$26="","",IFERROR(C42/(C42+D42),0)) | F42: =IF(Config!$A$26="","",SUMIFS(Propostas!$F$5:$F$304,Propostas!$B$5:$B$304,Config!$A$26,Propostas!$G$5:$G$304,"Fechada")) | G42: =IF(Config!$A$26="","",SUMIFS(Propostas!$F$5:$F$304,Propostas!$B$5:$B$304,Config!$A$26,Propostas!$G$5:$G$304,"<>Fechada",Propostas!$G$5:$G$304,"<>Perdida",Propostas!$G$5:$G$304,"<>"))
A43: =IF(Config!$A$27="","",Config!$A$27) | B43: =IF(Config!$A$27="","",COUNTIFS(Propostas!$B$5:$B$304,Config!$A$27)) | C43: =IF(Config!$A$27="","",COUNTIFS(Propostas!$B$5:$B$304,Config!$A$27,Propostas!$G$5:$G$304,"Fechada")) | D43: =IF(Config!$A$27="","",COUNTIFS(Propostas!$B$5:$B$304,Config!$A$27,Propostas!$G$5:$G$304,"Perdida")) | E43: =IF(Config!$A$27="","",IFERROR(C43/(C43+D43),0)) | F43: =IF(Config!$A$27="","",SUMIFS(Propostas!$F$5:$F$304,Propostas!$B$5:$B$304,Config!$A$27,Propostas!$G$5:$G$304,"Fechada")) | G43: =IF(Config!$A$27="","",SUMIFS(Propostas!$F$5:$F$304,Propostas!$B$5:$B$304,Config!$A$27,Propostas!$G$5:$G$304,"<>Fechada",Propostas!$G$5:$G$304,"<>Perdida",Propostas!$G$5:$G$304,"<>"))
A44: =IF(Config!$A$28="","",Config!$A$28) | B44: =IF(Config!$A$28="","",COUNTIFS(Propostas!$B$5:$B$304,Config!$A$28)) | C44: =IF(Config!$A$28="","",COUNTIFS(Propostas!$B$5:$B$304,Config!$A$28,Propostas!$G$5:$G$304,"Fechada")) | D44: =IF(Config!$A$28="","",COUNTIFS(Propostas!$B$5:$B$304,Config!$A$28,Propostas!$G$5:$G$304,"Perdida")) | E44: =IF(Config!$A$28="","",IFERROR(C44/(C44+D44),0)) | F44: =IF(Config!$A$28="","",SUMIFS(Propostas!$F$5:$F$304,Propostas!$B$5:$B$304,Config!$A$28,Propostas!$G$5:$G$304,"Fechada")) | G44: =IF(Config!$A$28="","",SUMIFS(Propostas!$F$5:$F$304,Propostas!$B$5:$B$304,Config!$A$28,Propostas!$G$5:$G$304,"<>Fechada",Propostas!$G$5:$G$304,"<>Perdida",Propostas!$G$5:$G$304,"<>"))
A45: =IF(Config!$A$29="","",Config!$A$29) | B45: =IF(Config!$A$29="","",COUNTIFS(Propostas!$B$5:$B$304,Config!$A$29)) | C45: =IF(Config!$A$29="","",COUNTIFS(Propostas!$B$5:$B$304,Config!$A$29,Propostas!$G$5:$G$304,"Fechada")) | D45: =IF(Config!$A$29="","",COUNTIFS(Propostas!$B$5:$B$304,Config!$A$29,Propostas!$G$5:$G$304,"Perdida")) | E45: =IF(Config!$A$29="","",IFERROR(C45/(C45+D45),0)) | F45: =IF(Config!$A$29="","",SUMIFS(Propostas!$F$5:$F$304,Propostas!$B$5:$B$304,Config!$A$29,Propostas!$G$5:$G$304,"Fechada")) | G45: =IF(Config!$A$29="","",SUMIFS(Propostas!$F$5:$F$304,Propostas!$B$5:$B$304,Config!$A$29,Propostas!$G$5:$G$304,"<>Fechada",Propostas!$G$5:$G$304,"<>Perdida",Propostas!$G$5:$G$304,"<>"))
...

Sheet Config
A1: Configurações
A2: Células amarelas: você preenche. As probabilidades por etapa alimentam a previsão ponderada.
A4: Escritório | B4: Ferraz & Lima Advocacia (exemplo fictício)
A5: Data de referência (hoje) | B5: 46279
A6: Meta de honorários fechados no trimestre (R$) | B6: 60000
A7: Proposta parada há mais de (dias) | B7: 14
A9: Etapa | B9: Probabilidade de fechar
A10: Contato | B10: 0.1
A11: Reunião feita | B11: 0.25
A12: Proposta enviada | B12: 0.5
A13: Negociação | B13: 0.75
A14: Fechada | B14: 1
A15: Perdida | B15: 0
A16: Etapas fixas: contato → reunião → proposta enviada → negociação → fechada ou perdida. Ajuste só as probabilidades, pela sua experiência.
A17: Áreas de atuação | C17: Origens do contato | E17: Motivos de perda | G17: Responsáveis | I17: Serviços mais comuns
A18: Cível | C18: Indicação de cliente | E18: Preço | G18: Marina Ferraz | I18: Assessoria mensal (12 meses)
A19: Trabalhista | C19: Site e Google | E19: Fechou com outro escritório | G19: Rafael Lima | I19: Ação trabalhista
A20: Previdenciário | C20: Instagram | E20: Desistiu da demanda | I20: Defesa em reclamação trabalhista
A21: Empresarial | C21: Cliente antigo | E21: Sem resposta | I21: Revisão de benefício
A22: Família | C22: Parceria (contador, imobiliária) | E22: Fora da área de atuação | I22: Planejamento previdenciário
C23: Evento ou palestra | E23: Prazo de atendimento | I23: Cobrança judicial
I24: Contratos e consultoria
I25: Contratos com convênios
I26: Divórcio e partilha
I27: Inventário
I28: Discussão de contrato de prestação de serviços
A39: Preencha cada lista de cima para baixo, sem pular linha: as listas suspensas de Propostas param na primeira célula vazia. Até 20 itens por lista. Serviço é texto livre; a lista só sugere.

Sheet Propostas
A1: Propostas
A2: Uma linha por proposta de honorários. Atualize a etapa conforme avança; ao fechar, marque Fechada ou Perdida, a data e, se perdida, o motivo.
A4: Cliente | B4: Área | C4: Serviço | D4: Origem | E4: Responsável | F4: Valor (R$) | G4: Etapa | H4: Data de entrada | I4: Última movimentação | J4: Fechamento previsto | K4: Data de fechamento | L4: Motivo (se perdida) | M4: Probabilidade | N4: Valor ponderado | O4: Dias parada | P4: Dias até fechar | Q4: Situação
A5: Padaria do Sol Ltda | B5: Empresarial | C5: Assessoria mensal (12 meses) | D5: Cliente antigo | E5: Marina Ferraz | F5: 18000 | G5: Fechada | H5: 46181 | I5: 46202 | J5: 46206 | K5: 46202 | M5: =IF(G5="","",IFERROR(INDEX(Config!$B$10:$B$15,MATCH(G5,Config!$A$10:$A$15,0)),0)) -> 1 | N5: =IF(OR(G5="",F5=""),"",F5*M5) -> 18000 | O5: =IF(OR(G5="",G5="Fechada",G5="Perdida",AND(H5="",I5="")),"",Config!$B$5-IF(I5="",H5,I5)) | P5: =IF(AND(G5="Fechada",K5<>"",H5<>""),K5-H5,"") -> 21 | Q5: =IF(G5="","",IF(G5="Fechada","Fechada",IF(G5="Perdida","Perdida",IF(AND(J5<>"",J5<Config!$B$5),"Previsão vencida",IF(AND(O5<>"",O5>Config!$B$7),"Parada","Ativa"))))) -> Fechada | R5: =IF(OR(G5="",Q5="Fechada",Q5="Perdida"),0,IF(Q5="Previsão vencida",3,IF(Q5="Parada",2,1))*1E+15+MIN(N(O5),500)*1E+12+MIN(ROUND(N(F5)*100,0),99999999)*1E+4+(304+1-ROW())) -> 0
A6: Ana Beatriz Moreira | B6: Trabalhista | C6: Ação trabalhista | D6: Indicação de cliente | E6: Rafael Lima | F6: 6000 | G6: Fechada | H6: 46188 | I6: 46210 | J6: 46213 | K6: 46210 | M6: =IF(G6="","",IFERROR(INDEX(Config!$B$10:$B$15,MATCH(G6,Config!$A$10:$A$15,0)),0)) -> 1 | N6: =IF(OR(G6="",F6=""),"",F6*M6) -> 6000 | O6: =IF(OR(G6="",G6="Fechada",G6="Perdida",AND(H6="",I6="")),"",Config!$B$5-IF(I6="",H6,I6)) | P6: =IF(AND(G6="Fechada",K6<>"",H6<>""),K6-H6,"") -> 22 | Q6: =IF(G6="","",IF(G6="Fechada","Fechada",IF(G6="Perdida","Perdida",IF(AND(J6<>"",J6<Config!$B$5),"Previsão vencida",IF(AND(O6<>"",O6>Config!$B$7),"Parada","Ativa"))))) -> Fechada | R6: =IF(OR(G6="",Q6="Fechada",Q6="Perdida"),0,IF(Q6="Previsão vencida",3,IF(Q6="Parada",2,1))*1E+15+MIN(N(O6),500)*1E+12+MIN(ROUND(N(F6)*100,0),99999999)*1E+4+(304+1-ROW())) -> 0
A7: Construtora Horizonte | B7: Cível | C7: Cobrança judicial | D7: Cliente antigo | E7: Marina Ferraz | F7: 15500 | G7: Fechada | H7: 46204 | I7: 46225 | J7: 46234 | K7: 46225 | M7: =IF(G7="","",IFERROR(INDEX(Config!$B$10:$B$15,MATCH(G7,Config!$A$10:$A$15,0)),0)) -> 1 | N7: =IF(OR(G7="",F7=""),"",F7*M7) -> 15500 | O7: =IF(OR(G7="",G7="Fechada",G7="Perdida",AND(H7="",I7="")),"",Config!$B$5-IF(I7="",H7,I7)) | P7: =IF(AND(G7="Fechada",K7<>"",H7<>""),K7-H7,"") -> 21 | Q7: =IF(G7="","",IF(G7="Fechada","Fechada",IF(G7="Perdida","Perdida",IF(AND(J7<>"",J7<Config!$B$5),"Previsão vencida",IF(AND(O7<>"",O7>Config!$B$7),"Parada","Ativa"))))) -> Fechada | R7: =IF(OR(G7="",Q7="Fechada",Q7="Perdida"),0,IF(Q7="Previsão vencida",3,IF(Q7="Parada",2,1))*1E+15+MIN(N(O7),500)*1E+12+MIN(ROUND(N(F7)*100,0),99999999)*1E+4+(304+1-ROW())) -> 0
A8: Carlos Eduardo Nunes | B8: Previdenciário | C8: Revisão de benefício | D8: Site e Google | E8: Rafael Lima | F8: 5400 | G8: Fechada | H8: 46216 | I8: 46231 | J8: 46239 | K8: 46231 | M8: =IF(G8="","",IFERROR(INDEX(Config!$B$10:$B$15,MATCH(G8,Config!$A$10:$A$15,0)),0)) -> 1 | N8: =IF(OR(G8="",F8=""),"",F8*M8) -> 5400 | O8: =IF(OR(G8="",G8="Fechada",G8="Perdida",AND(H8="",I8="")),"",Config!$B$5-IF(I8="",H8,I8)) | P8: =IF(AND(G8="Fechada",K8<>"",H8<>""),K8-H8,"") -> 15 | Q8: =IF(G8="","",IF(G8="Fechada","Fechada",IF(G8="Perdida","Perdida",IF(AND(J8<>"",J8<Config!$B$5),"Previsão vencida",IF(AND(O8<>"",O8>Config!$B$7),"Parada","Ativa"))))) -> Fechada | R8: =IF(OR(G8="",Q8="Fechada",Q8="Perdida"),0,IF(Q8="Previsão vencida",3,IF(Q8="Parada",2,1))*1E+15+MIN(N(O8),500)*1E+12+MIN(ROUND(N(F8)*100,0),99999999)*1E+4+(304+1-ROW())) -> 0
A9: Escola Aurora | B9: Cível | C9: Assessoria mensal (12 meses) | D9: Cliente antigo | E9: Marina Ferraz | F9: 13200 | G9: Fechada | H9: 46217 | I9: 46237 | J9: 46241 | K9: 46237 | M9: =IF(G9="","",IFERROR(INDEX(Config!$B$10:$B$15,MATCH(G9,Config!$A$10:$A$15,0)),0)) -> 1 | N9: =IF(OR(G9="",F9=""),"",F9*M9) -> 13200 | O9: =IF(OR(G9="",G9="Fechada",G9="Perdida",AND(H9="",I9="")),"",Config!$B$5-IF(I9="",H9,I9)) | P9: =IF(AND(G9="Fechada",K9<>"",H9<>""),K9-H9,"") -> 20 | Q9: =IF(G9="","",IF(G9="Fechada","Fechada",IF(G9="Perdida","Perdida",IF(AND(J9<>"",J9<Config!$B$5),"Previsão vencida",IF(AND(O9<>"",O9>Config!$B$7),"Parada","Ativa"))))) -> Fechada | R9: =IF(OR(G9="",Q9="Fechada",Q9="Perdida"),0,IF(Q9="Previsão vencida",3,IF(Q9="Parada",2,1))*1E+15+MIN(N(O9),500)*1E+12+MIN(ROUND(N(F9)*100,0),99999999)*1E+4+(304+1-ROW())) -> 0
A10: Bistrô 42 | B10: Trabalhista | C10: Defesa em reclamação trabalhista | D10: Indicação de cliente | E10: Rafael Lima | F10: 5200 | G10: Perdida | H10: 46195 | I10: 46217 | J10: 46220 | K10: 46217 | L10: Preço | M10: =IF(G10="","",IFERROR(INDEX(Config!$B$10:$B$15,MATCH(G10,Config!$A$10:$A$15,0)),0)) -> 0 | N10: =IF(OR(G10="",F10=""),"",F10*M10) -> 0 | O10: =IF(OR(G10="",G10="Fechada",G10="Perdida",AND(H10="",I10="")),"",Config!$B$5-IF(I10="",H10,I10)) | P10: =IF(AND(G10="Fechada",K10<>"",H10<>""),K10-H10,"") | Q10: =IF(G10="","",IF(G10="Fechada","Fechada",IF(G10="Perdida","Perdida",IF(AND(J10<>"",J10<Config!$B$5),"Previsão vencida",IF(AND(O10<>"",O10>Config!$B$7),"Parada","Ativa"))))) -> Perdida | R10: =IF(OR(G10="",Q10="Fechada",Q10="Perdida"),0,IF(Q10="Previsão vencida",3,IF(Q10="Parada",2,1))*1E+15+MIN(N(O10),500)*1E+12+MIN(ROUND(N(F10)*100,0),99999999)*1E+4+(304+1-ROW())) -> 0
A11: Fernanda Castro | B11: Família | C11: Divórcio e partilha | D11: Site e Google | E11: Marina Ferraz | F11: 6500 | G11: Perdida | H11: 46209 | I11: 46230 | J11: 46234 | K11: 46230 | L11: Fechou com outro escritório | M11: =IF(G11="","",IFERROR(INDEX(Config!$B$10:$B$15,MATCH(G11,Config!$A$10:$A$15,0)),0)) -> 0 | N11: =IF(OR(G11="",F11=""),"",F11*M11) -> 0 | O11: =IF(OR(G11="",G11="Fechada",G11="Perdida",AND(H11="",I11="")),"",Config!$B$5-IF(I11="",H11,I11)) | P11: =IF(AND(G11="Fechada",K11<>"",H11<>""),K11-H11,"") | Q11: =IF(G11="","",IF(G11="Fechada","Fechada",IF(G11="Perdida","Perdida",IF(AND(J11<>"",J11<Config!$B$5),"Previsão vencida",IF(AND(O11<>"",O11>Config!$B$7),"Parada","Ativa"))))) -> Perdida | R11: =IF(OR(G11="",Q11="Fechada",Q11="Perdida"),0,IF(Q11="Previsão vencida",3,IF(Q11="Parada",2,1))*1E+15+MIN(N(O11),500)*1E+12+MIN(ROUND(N(F11)*100,0),99999999)*1E+4+(304+1-ROW())) -> 0
A12: Loja Verde Comércio | B12: Empresarial | C12: Contratos e consultoria | D12: Parceria (contador, imobiliária) | E12: Marina Ferraz | F12: 8400 | G12: Fechada | H12: 46223 | I12: 46245 | J12: 46248 | K12: 46245 | M12: =IF(G12="","",IFERROR(INDEX(Config!$B$10:$B$15,MATCH(G12,Config!$A$10:$A$15,0)),0)) -> 1 | N12: =IF(OR(G12="",F12=""),"",F12*M12) -> 8400 | O12: =IF(OR(G12="",G12="Fechada",G12="Perdida",AND(H12="",I12="")),"",Config!$B$5-IF(I12="",H12,I12)) | P12: =IF(AND(G12="Fechada",K12<>"",H12<>""),K12-H12,"") -> 22 | Q12: =IF(G12="","",IF(G12="Fechada","Fechada",IF(G12="Perdida","Perdida",IF(AND(J12<>"",J12<Config!$B$5),"Previsão vencida",IF(AND(O12<>"",O12>Config!$B$7),"Parada","Ativa"))))) -> Fechada | R12: =IF(OR(G12="",Q12="Fechada",Q12="Perdida"),0,IF(Q12="Previsão vencida",3,IF(Q12="Parada",2,1))*1E+15+MIN(N(O12),500)*1E+12+MIN(ROUND(N(F12)*100,0),99999999)*1E+4+(304+1-ROW())) -> 0
A13: Marcos Vinícius Teles | B13: Previdenciário | C13: Planejamento previdenciário | D13: Instagram | E13: Rafael Lima | F13: 4500 | G13: Fechada | H13: 46237 | I13: 46253 | J13: 46262 | K13: 46253 | M13: =IF(G13="","",IFERROR(INDEX(Config!$B$10:$B$15,MATCH(G13,Config!$A$10:$A$15,0)),0)) -> 1 | N13: =IF(OR(G13="",F13=""),"",F13*M13) -> 4500 | O13: =IF(OR(G13="",G13="Fechada",G13="Perdida",AND(H13="",I13="")),"",Config!$B$5-IF(I13="",H13,I13)) | P13: =IF(AND(G13="Fechada",K13<>"",H13<>""),K13-H13,"") -> 16 | Q13: =IF(G13="","",IF(G13="Fechada","Fechada",IF(G13="Perdida","Perdida",IF(AND(J13<>"",J13<Config!$B$5),"Previsão vencida",IF(AND(O13<>"",O13>Config!$B$7),"Parada","Ativa"))))) -> Fechada | R13: =IF(OR(G13="",Q13="Fechada",Q13="Perdida"),0,IF(Q13="Previsão vencida",3,IF(Q13="Parada",2,1))*1E+15+MIN(N(O13),500)*1E+12+MIN(ROUND(N(F13)*100,0),99999999)*1E+4+(304+1-ROW())) -> 0
A14: Oficina Mecânica Central | B14: Trabalhista | C14: Ação trabalhista | D14: Evento ou palestra | E14: Rafael Lima | F14: 4400 | G14: Perdida | H14: 46238 | I14: 46259 | J14: 46262 | K14: 46259 | L14: Sem resposta | M14: =IF(G14="","",IFERROR(INDEX(Config!$B$10:$B$15,MATCH(G14,Config!$A$10:$A$15,0)),0)) -> 0 | N14: =IF(OR(G14="",F14=""),"",F14*M14) -> 0 | O14: =IF(OR(G14="",G14="Fechada",G14="Perdida",AND(H14="",I14="")),"",Config!$B$5-IF(I14="",H14,I14)) | P14: =IF(AND(G14="Fechada",K14<>"",H14<>""),K14-H14,"") | Q14: =IF(G14="","",IF(G14="Fechada","Fechada",IF(G14="Perdida","Perdida",IF(AND(J14<>"",J14<Config!$B$5),"Previsão vencida",IF(AND(O14<>"",O14>Config!$B$7),"Parada","Ativa"))))) -> Perdida | R14: =IF(OR(G14="",Q14="Fechada",Q14="Perdida"),0,IF(Q14="Previsão vencida",3,IF(Q14="Parada",2,1))*1E+15+MIN(N(O14),500)*1E+12+MIN(ROUND(N(F14)*100,0),99999999)*1E+4+(304+1-ROW())) -> 0
A15: Agência Prisma | B15: Empresarial | C15: Contratos e consultoria | D15: Instagram | E15: Marina Ferraz | F15: 11000 | G15: Perdida | H15: 46246 | I15: 46267 | J15: 46269 | K15: 46267 | L15: Preço | M15: =IF(G15="","",IFERROR(INDEX(Config!$B$10:$B$15,MATCH(G15,Config!$A$10:$A$15,0)),0)) -> 0 | N15: =IF(OR(G15="",F15=""),"",F15*M15) -> 0 | O15: =IF(OR(G15="",G15="Fechada",G15="Perdida",AND(H15="",I15="")),"",Config!$B$5-IF(I15="",H15,I15)) | P15: =IF(AND(G15="Fechada",K15<>"",H15<>""),K15-H15,"") | Q15: =IF(G15="","",IF(G15="Fechada","Fechada",IF(G15="Perdida","Perdida",IF(AND(J15<>"",J15<Config!$B$5),"Previsão vencida",IF(AND(O15<>"",O15>Config!$B$7),"Parada","Ativa"))))) -> Perdida | R15: =IF(OR(G15="",Q15="Fechada",Q15="Perdida"),0,IF(Q15="Previsão vencida",3,IF(Q15="Parada",2,1))*1E+15+MIN(N(O15),500)*1E+12+MIN(ROUND(N(F15)*100,0),99999999)*1E+4+(304+1-ROW())) -> 0
A16: Transportadora Rota Sul | B16: Trabalhista | C16: Assessoria mensal (12 meses) | D16: Cliente antigo | E16: Rafael Lima | F16: 14400 | G16: Negociação | H16: 46251 | I16: 46275 | J16: 46285 | M16: =IF(G16="","",IFERROR(INDEX(Config!$B$10:$B$15,MATCH(G16,Config!$A$10:$A$15,0)),0)) -> 0.75 | N16: =IF(OR(G16="",F16=""),"",F16*M16) -> 10800 | O16: =IF(OR(G16="",G16="Fechada",G16="Perdida",AND(H16="",I16="")),"",Config!$B$5-IF(I16="",H16,I16)) -> 4 | P16: =IF(AND(G16="Fechada",K16<>"",H16<>""),K16-H16,"") | Q16: =IF(G16="","",IF(G16="Fechada","Fechada",IF(G16="Perdida","Perdida",IF(AND(J16<>"",J16<Config!$B$5),"Previsão vencida",IF(AND(O16<>"",O16>Config!$B$7),"Parada","Ativa"))))) -> Ativa | R16: =IF(OR(G16="",Q16="Fechada",Q16="Perdida"),0,IF(Q16="Previsão vencida",3,IF(Q16="Parada",2,1))*1E+15+MIN(N(O16),500)*1E+12+MIN(ROUND(N(F16)*100,0),99999999)*1E+4+(304+1-ROW())) -> 1.0040144e+15
A17: Clínica Bem-Estar | B17: Empresarial | C17: Contratos com convênios | D17: Cliente antigo | E17: Marina Ferraz | F17: 6800 | G17: Negociação | H17: 46258 | I17: 46262 | J17: 46277 | M17: =IF(G17="","",IFERROR(INDEX(Config!$B$10:$B$15,MATCH(G17,Config!$A$10:$A$15,0)),0)) -> 0.75 | N17: =IF(OR(G17="",F17=""),"",F17*M17) -> 5100 | O17: =IF(OR(G17="",G17="Fechada",G17="Perdida",AND(H17="",I17="")),"",Config!$B$5-IF(I17="",H17,I17)) -> 17 | P17: =IF(AND(G17="Fechada",K17<>"",H17<>""),K17-H17,"") | Q17: =IF(G17="","",IF(G17="Fechada","Fechada",IF(G17="Perdida","Perdida",IF(AND(J17<>"",J17<Config!$B$5),"Previsão vencida",IF(AND(O17<>"",O17>Config!$B$7),"Parada","Ativa"))))) -> Previsão vencida | R17: =IF(OR(G17="",Q17="Fechada",Q17="Perdida"),0,IF(Q17="Previsão vencida",3,IF(Q17="Parada",2,1))*1E+15+MIN(N(O17),500)*1E+12+MIN(ROUND(N(F17)*100,0),99999999)*1E+4+(304+1-ROW())) -> 3.0170068e+15
A18: Patrícia Gomes | B18: Família | C18: Inventário | D18: Indicação de cliente | E18: Marina Ferraz | F18: 10500 | G18: Proposta enviada | H18: 46260 | I18: 46263 | J18: 46291 | M18: =IF(G18="","",IFERROR(INDEX(Config!$B$10:$B$15,MATCH(G18,Config!$A$10:$A$15,0)),0)) -> 0.5 | N18: =IF(OR(G18="",F18=""),"",F18*M18) -> 5250 | O18: =IF(OR(G18="",G18="Fechada",G18="Perdida",AND(H18="",I18="")),"",Config!$B$5-IF(I18="",H18,I18)) -> 16 | P18: =IF(AND(G18="Fechada",K18<>"",H18<>""),K18-H18,"") | Q18: =IF(G18="","",IF(G18="Fechada","Fechada",IF(G18="Perdida","Perdida",IF(AND(J18<>"",J18<Config!$B$5),"Previsão vencida",IF(AND(O18<>"",O18>Config!$B$7),"Parada","Ativa"))))) -> Parada | R18: =IF(OR(G18="",Q18="Fechada",Q18="Perdida"),0,IF(Q18="Previsão vencida",3,IF(Q18="Parada",2,1))*1E+15+MIN(N(O18),500)*1E+12+MIN(ROUND(N(F18)*100,0),99999999)*1E+4+(304+1-ROW())) -> 2.0160105e+15
A19: José Antônio Ribeiro | B19: Previdenciário | C19: Revisão de benefício | D19: Site e Google | E19: Rafael Lima | F19: 4200 | G19: Proposta enviada | H19: 46262 | I19: 46265 | J19: 46273 | M19: =IF(G19="","",IFERROR(INDEX(Config!$B$10:$B$15,MATCH(G19,Config!$A$10:$A$15,0)),0)) -> 0.5 | N19: =IF(OR(G19="",F19=""),"",F19*M19) -> 2100 | O19: =IF(OR(G19="",G19="Fechada",G19="Perdida",AND(H19="",I19="")),"",Config!$B$5-IF(I19="",H19,I19)) -> 14 | P19: =IF(AND(G19="Fechada",K19<>"",H19<>""),K19-H19,"") | Q19: =IF(G19="","",IF(G19="Fechada","Fechada",IF(G19="Perdida","Perdida",IF(AND(J19<>"",J19<Config!$B$5),"Previsão vencida",IF(AND(O19<>"",O19>Config!$B$7),"Parada","Ativa"))))) -> Previsão vencida | R19: =IF(OR(G19="",Q19="Fechada",Q19="Perdida"),0,IF(Q19="Previsão vencida",3,IF(Q19="Parada",2,1))*1E+15+MIN(N(O19),500)*1E+12+MIN(ROUND(N(F19)*100,0),99999999)*1E+4+(304+1-ROW())) -> 3.0140042e+15
A20: Helena Duarte | B20: Trabalhista | C20: Ação trabalhista | D20: Indicação de cliente | E20: Rafael Lima | F20: 5800 | G20: Reunião feita | H20: 46267 | I20: 46276 | J20: 46299 | M20: =IF(G20="","",IFERROR(INDEX(Config!$B$10:$B$15,MATCH(G20,Config!$A$10:$A$15,0)),0)) -> 0.25 | N20: =IF(OR(G20="",F20=""),"",F20*M20) -> 1450 | O20: =IF(OR(G20="",G20="Fechada",G20="Perdida",AND(H20="",I20="")),"",Config!$B$5-IF(I20="",H20,I20)) -> 3 | P20: =IF(AND(G20="Fechada",K20<>"",H20<>""),K20-H20,"") | Q20: =IF(G20="","",IF(G20="Fechada","Fechada",IF(G20="Perdida","Perdida",IF(AND(J20<>"",J20<Config!$B$5),"Previsão vencida",IF(AND(O20<>"",O20>Config!$B$7),"Parada","Ativa"))))) -> Ativa | R20: =IF(OR(G20="",Q20="Fechada",Q20="Perdida"),0,IF(Q20="Previsão vencida",3,IF(Q20="Parada",2,1))*1E+15+MIN(N(O20),500)*1E+12+MIN(ROUND(N(F20)*100,0),99999999)*1E+4+(304+1-ROW())) -> 1.0030058e+15
A21: Luciana Farias | B21: Cível | C21: Cobrança judicial | D21: Parceria (contador, imobiliária) | E21: Marina Ferraz | F21: 7900 | G21: Reunião feita | H21: 46269 | I21: 46277 | J21: 46304 | M21: =IF(G21="","",IFERROR(INDEX(Config!$B$10:$B$15,MATCH(G21,Config!$A$10:$A$15,0)),0)) -> 0.25 | N21: =IF(OR(G21="",F21=""),"",F21*M21) -> 1975 | O21: =IF(OR(G21="",G21="Fechada",G21="Perdida",AND(H21="",I21="")),"",Config!$B$5-IF(I21="",H21,I21)) -> 2 | P21: =IF(AND(G21="Fechada",K21<>"",H21<>""),K21-H21,"") | Q21: =IF(G21="","",IF(G21="Fechada","Fechada",IF(G21="Perdida","Perdida",IF(AND(J21<>"",J21<Config!$B$5),"Previsão vencida",IF(AND(O21<>"",O21>Config!$B$7),"Parada","Ativa"))))) -> Ativa | R21: =IF(OR(G21="",Q21="Fechada",Q21="Perdida"),0,IF(Q21="Previsão vencida",3,IF(Q21="Parada",2,1))*1E+15+MIN(N(O21),500)*1E+12+MIN(ROUND(N(F21)*100,0),99999999)*1E+4+(304+1-ROW())) -> 1.0020079e+15
A22: Construtora Horizonte | B22: Empresarial | C22: Assessoria mensal (12 meses) | D22: Cliente antigo | E22: Marina Ferraz | F22: 13200 | G22: Contato | H22: 46274 | I22: 46278 | J22: 46309 | M22: =IF(G22="","",IFERROR(INDEX(Config!$B$10:$B$15,MATCH(G22,Config!$A$10:$A$15,0)),0)) -> 0.1 | N22: =IF(OR(G22="",F22=""),"",F22*M22) -> 1320 | O22: =IF(OR(G22="",G22="Fechada",G22="Perdida",AND(H22="",I22="")),"",Config!$B$5-IF(I22="",H22,I22)) -> 1 | P22: =IF(AND(G22="Fechada",K22<>"",H22<>""),K22-H22,"") | Q22: =IF(G22="","",IF(G22="Fechada","Fechada",IF(G22="Perdida","Perdida",IF(AND(J22<>"",J22<Config!$B$5),"Previsão vencida",IF(AND(O22<>"",O22>Config!$B$7),"Parada","Ativa"))))) -> Ativa | R22: =IF(OR(G22="",Q22="Fechada",Q22="Perdida"),0,IF(Q22="Previsão vencida",3,IF(Q22="Parada",2,1))*1E+15+MIN(N(O22),500)*1E+12+MIN(ROUND(N(F22)*100,0),99999999)*1E+4+(304+1-ROW())) -> 1.0010132e+15
A23: Roberto Almeida | B23: Cível | C23: Discussão de contrato de prestação de serviços | D23: Cliente antigo | E23: Marina Ferraz | F23: 4500 | G23: Proposta enviada | H23: 46274 | I23: 46279 | J23: 46294 | M23: =IF(G23="","",IFERROR(INDEX(Config!$B$10:$B$15,MATCH(G23,Config!$A$10:$A$15,0)),0)) -> 0.5 | N23: =IF(OR(G23="",F23=""),"",F23*M23) -> 2250 | O23: =IF(OR(G23="",G23="Fechada",G23="Perdida",AND(H23="",I23="")),"",Config!$B$5-IF(I23="",H23,I23)) -> 0 | P23: =IF(AND(G23="Fechada",K23<>"",H23<>""),K23-H23,"") | Q23: =IF(G23="","",IF(G23="Fechada","Fechada",IF(G23="Perdida","Perdida",IF(AND(J23<>"",J23<Config!$B$5),"Previsão vencida",IF(AND(O23<>"",O23>Config!$B$7),"Parada","Ativa"))))) -> Ativa | R23: =IF(OR(G23="",Q23="Fechada",Q23="Perdida"),0,IF(Q23="Previsão vencida",3,IF(Q23="Parada",2,1))*1E+15+MIN(N(O23),500)*1E+12+MIN(ROUND(N(F23)*100,0),99999999)*1E+4+(304+1-ROW())) -> 1.0000045e+15
A24: Marcos Vinícius Teles | B24: Família | C24: Divórcio e partilha | D24: Cliente antigo | E24: Marina Ferraz | F24: 5600 | G24: Contato | H24: 46276 | I24: 46276 | J24: 46314 | M24: =IF(G24="","",IFERROR(INDEX(Config!$B$10:$B$15,MATCH(G24,Config!$A$10:$A$15,0)),0)) -> 0.1 | N24: =IF(OR(G24="",F24=""),"",F24*M24) -> 560 | O24: =IF(OR(G24="",G24="Fechada",G24="Perdida",AND(H24="",I24="")),"",Config!$B$5-IF(I24="",H24,I24)) -> 3 | P24: =IF(AND(G24="Fechada",K24<>"",H24<>""),K24-H24,"") | Q24: =IF(G24="","",IF(G24="Fechada","Fechada",IF(G24="Perdida","Perdida",IF(AND(J24<>"",J24<Config!$B$5),"Previsão vencida",IF(AND(O24<>"",O24>Config!$B$7),"Parada","Ativa"))))) -> Ativa | R24: =IF(OR(G24="",Q24="Fechada",Q24="Perdida"),0,IF(Q24="Previsão vencida",3,IF(Q24="Parada",2,1))*1E+15+MIN(N(O24),500)*1E+12+MIN(ROUND(N(F24)*100,0),99999999)*1E+4+(304+1-ROW())) -> 1.0030056e+15
M25: =IF(G25="","",IFERROR(INDEX(Config!$B$10:$B$15,MATCH(G25,Config!$A$10:$A$15,0)),0)) | N25: =IF(OR(G25="",F25=""),"",F25*M25) | O25: =IF(OR(G25="",G25="Fechada",G25="Perdida",AND(H25="",I25="")),"",Config!$B$5-IF(I25="",H25,I25)) | P25: =IF(AND(G25="Fechada",K25<>"",H25<>""),K25-H25,"") | Q25: =IF(G25="","",IF(G25="Fechada","Fechada",IF(G25="Perdida","Perdida",IF(AND(J25<>"",J25<Config!$B$5),"Previsão vencida",IF(AND(O25<>"",O25>Config!$B$7),"Parada","Ativa"))))) | R25: =IF(OR(G25="",Q25="Fechada",Q25="Perdida"),0,IF(Q25="Previsão vencida",3,IF(Q25="Parada",2,1))*1E+15+MIN(N(O25),500)*1E+12+MIN(ROUND(N(F25)*100,0),99999999)*1E+4+(304+1-ROW())) -> 0
M26: =IF(G26="","",IFERROR(INDEX(Config!$B$10:$B$15,MATCH(G26,Config!$A$10:$A$15,0)),0)) | N26: =IF(OR(G26="",F26=""),"",F26*M26) | O26: =IF(OR(G26="",G26="Fechada",G26="Perdida",AND(H26="",I26="")),"",Config!$B$5-IF(I26="",H26,I26)) | P26: =IF(AND(G26="Fechada",K26<>"",H26<>""),K26-H26,"") | Q26: =IF(G26="","",IF(G26="Fechada","Fechada",IF(G26="Perdida","Perdida",IF(AND(J26<>"",J26<Config!$B$5),"Previsão vencida",IF(AND(O26<>"",O26>Config!$B$7),"Parada","Ativa"))))) | R26: =IF(OR(G26="",Q26="Fechada",Q26="Perdida"),0,IF(Q26="Previsão vencida",3,IF(Q26="Parada",2,1))*1E+15+MIN(N(O26),500)*1E+12+MIN(ROUND(N(F26)*100,0),99999999)*1E+4+(304+1-ROW())) -> 0
M27: =IF(G27="","",IFERROR(INDEX(Config!$B$10:$B$15,MATCH(G27,Config!$A$10:$A$15,0)),0)) | N27: =IF(OR(G27="",F27=""),"",F27*M27) | O27: =IF(OR(G27="",G27="Fechada",G27="Perdida",AND(H27="",I27="")),"",Config!$B$5-IF(I27="",H27,I27)) | P27: =IF(AND(G27="Fechada",K27<>"",H27<>""),K27-H27,"") | Q27: =IF(G27="","",IF(G27="Fechada","Fechada",IF(G27="Perdida","Perdida",IF(AND(J27<>"",J27<Config!$B$5),"Previsão vencida",IF(AND(O27<>"",O27>Config!$B$7),"Parada","Ativa"))))) | R27: =IF(OR(G27="",Q27="Fechada",Q27="Perdida"),0,IF(Q27="Previsão vencida",3,IF(Q27="Parada",2,1))*1E+15+MIN(N(O27),500)*1E+12+MIN(ROUND(N(F27)*100,0),99999999)*1E+4+(304+1-ROW())) -> 0
M28: =IF(G28="","",IFERROR(INDEX(Config!$B$10:$B$15,MATCH(G28,Config!$A$10:$A$15,0)),0)) | N28: =IF(OR(G28="",F28=""),"",F28*M28) | O28: =IF(OR(G28="",G28="Fechada",G28="Perdida",AND(H28="",I28="")),"",Config!$B$5-IF(I28="",H28,I28)) | P28: =IF(AND(G28="Fechada",K28<>"",H28<>""),K28-H28,"") | Q28: =IF(G28="","",IF(G28="Fechada","Fechada",IF(G28="Perdida","Perdida",IF(AND(J28<>"",J28<Config!$B$5),"Previsão vencida",IF(AND(O28<>"",O28>Config!$B$7),"Parada","Ativa"))))) | R28: =IF(OR(G28="",Q28="Fechada",Q28="Perdida"),0,IF(Q28="Previsão vencida",3,IF(Q28="Parada",2,1))*1E+15+MIN(N(O28),500)*1E+12+MIN(ROUND(N(F28)*100,0),99999999)*1E+4+(304+1-ROW())) -> 0
M29: =IF(G29="","",IFERROR(INDEX(Config!$B$10:$B$15,MATCH(G29,Config!$A$10:$A$15,0)),0)) | N29: =IF(OR(G29="",F29=""),"",F29*M29) | O29: =IF(OR(G29="",G29="Fechada",G29="Perdida",AND(H29="",I29="")),"",Config!$B$5-IF(I29="",H29,I29)) | P29: =IF(AND(G29="Fechada",K29<>"",H29<>""),K29-H29,"") | Q29: =IF(G29="","",IF(G29="Fechada","Fechada",IF(G29="Perdida","Perdida",IF(AND(J29<>"",J29<Config!$B$5),"Previsão vencida",IF(AND(O29<>"",O29>Config!$B$7),"Parada","Ativa"))))) | R29: =IF(OR(G29="",Q29="Fechada",Q29="Perdida"),0,IF(Q29="Previsão vencida",3,IF(Q29="Parada",2,1))*1E+15+MIN(N(O29),500)*1E+12+MIN(ROUND(N(F29)*100,0),99999999)*1E+4+(304+1-ROW())) -> 0
M30: =IF(G30="","",IFERROR(INDEX(Config!$B$10:$B$15,MATCH(G30,Config!$A$10:$A$15,0)),0)) | N30: =IF(OR(G30="",F30=""),"",F30*M30) | O30: =IF(OR(G30="",G30="Fechada",G30="Perdida",AND(H30="",I30="")),"",Config!$B$5-IF(I30="",H30,I30)) | P30: =IF(AND(G30="Fechada",K30<>"",H30<>""),K30-H30,"") | Q30: =IF(G30="","",IF(G30="Fechada","Fechada",IF(G30="Perdida","Perdida",IF(AND(J30<>"",J30<Config!$B$5),"Previsão vencida",IF(AND(O30<>"",O30>Config!$B$7),"Parada","Ativa"))))) | R30: =IF(OR(G30="",Q30="Fechada",Q30="Perdida"),0,IF(Q30="Previsão vencida",3,IF(Q30="Parada",2,1))*1E+15+MIN(N(O30),500)*1E+12+MIN(ROUND(N(F30)*100,0),99999999)*1E+4+(304+1-ROW())) -> 0
M31: =IF(G31="","",IFERROR(INDEX(Config!$B$10:$B$15,MATCH(G31,Config!$A$10:$A$15,0)),0)) | N31: =IF(OR(G31="",F31=""),"",F31*M31) | O31: =IF(OR(G31="",G31="Fechada",G31="Perdida",AND(H31="",I31="")),"",Config!$B$5-IF(I31="",H31,I31)) | P31: =IF(AND(G31="Fechada",K31<>"",H31<>""),K31-H31,"") | Q31: =IF(G31="","",IF(G31="Fechada","Fechada",IF(G31="Perdida","Perdida",IF(AND(J31<>"",J31<Config!$B$5),"Previsão vencida",IF(AND(O31<>"",O31>Config!$B$7),"Parada","Ativa"))))) | R31: =IF(OR(G31="",Q31="Fechada",Q31="Perdida"),0,IF(Q31="Previsão vencida",3,IF(Q31="Parada",2,1))*1E+15+MIN(N(O31),500)*1E+12+MIN(ROUND(N(F31)*100,0),99999999)*1E+4+(304+1-ROW())) -> 0
M32: =IF(G32="","",IFERROR(INDEX(Config!$B$10:$B$15,MATCH(G32,Config!$A$10:$A$15,0)),0)) | N32: =IF(OR(G32="",F32=""),"",F32*M32) | O32: =IF(OR(G32="",G32="Fechada",G32="Perdida",AND(H32="",I32="")),"",Config!$B$5-IF(I32="",H32,I32)) | P32: =IF(AND(G32="Fechada",K32<>"",H32<>""),K32-H32,"") | Q32: =IF(G32="","",IF(G32="Fechada","Fechada",IF(G32="Perdida","Perdida",IF(AND(J32<>"",J32<Config!$B$5),"Previsão vencida",IF(AND(O32<>"",O32>Config!$B$7),"Parada","Ativa"))))) | R32: =IF(OR(G32="",Q32="Fechada",Q32="Perdida"),0,IF(Q32="Previsão vencida",3,IF(Q32="Parada",2,1))*1E+15+MIN(N(O32),500)*1E+12+MIN(ROUND(N(F32)*100,0),99999999)*1E+4+(304+1-ROW())) -> 0
M33: =IF(G33="","",IFERROR(INDEX(Config!$B$10:$B$15,MATCH(G33,Config!$A$10:$A$15,0)),0)) | N33: =IF(OR(G33="",F33=""),"",F33*M33) | O33: =IF(OR(G33="",G33="Fechada",G33="Perdida",AND(H33="",I33="")),"",Config!$B$5-IF(I33="",H33,I33)) | P33: =IF(AND(G33="Fechada",K33<>"",H33<>""),K33-H33,"") | Q33: =IF(G33="","",IF(G33="Fechada","Fechada",IF(G33="Perdida","Perdida",IF(AND(J33<>"",J33<Config!$B$5),"Previsão vencida",IF(AND(O33<>"",O33>Config!$B$7),"Parada","Ativa"))))) | R33: =IF(OR(G33="",Q33="Fechada",Q33="Perdida"),0,IF(Q33="Previsão vencida",3,IF(Q33="Parada",2,1))*1E+15+MIN(N(O33),500)*1E+12+MIN(ROUND(N(F33)*100,0),99999999)*1E+4+(304+1-ROW())) -> 0
M34: =IF(G34="","",IFERROR(INDEX(Config!$B$10:$B$15,MATCH(G34,Config!$A$10:$A$15,0)),0)) | N34: =IF(OR(G34="",F34=""),"",F34*M34) | O34: =IF(OR(G34="",G34="Fechada",G34="Perdida",AND(H34="",I34="")),"",Config!$B$5-IF(I34="",H34,I34)) | P34: =IF(AND(G34="Fechada",K34<>"",H34<>""),K34-H34,"") | Q34: =IF(G34="","",IF(G34="Fechada","Fechada",IF(G34="Perdida","Perdida",IF(AND(J34<>"",J34<Config!$B$5),"Previsão vencida",IF(AND(O34<>"",O34>Config!$B$7),"Parada","Ativa"))))) | R34: =IF(OR(G34="",Q34="Fechada",Q34="Perdida"),0,IF(Q34="Previsão vencida",3,IF(Q34="Parada",2,1))*1E+15+MIN(N(O34),500)*1E+12+MIN(ROUND(N(F34)*100,0),99999999)*1E+4+(304+1-ROW())) -> 0
M35: =IF(G35="","",IFERROR(INDEX(Config!$B$10:$B$15,MATCH(G35,Config!$A$10:$A$15,0)),0)) | N35: =IF(OR(G35="",F35=""),"",F35*M35) | O35: =IF(OR(G35="",G35="Fechada",G35="Perdida",AND(H35="",I35="")),"",Config!$B$5-IF(I35="",H35,I35)) | P35: =IF(AND(G35="Fechada",K35<>"",H35<>""),K35-H35,"") | Q35: =IF(G35="","",IF(G35="Fechada","Fechada",IF(G35="Perdida","Perdida",IF(AND(J35<>"",J35<Config!$B$5),"Previsão vencida",IF(AND(O35<>"",O35>Config!$B$7),"Parada","Ativa"))))) | R35: =IF(OR(G35="",Q35="Fechada",Q35="Perdida"),0,IF(Q35="Previsão vencida",3,IF(Q35="Parada",2,1))*1E+15+MIN(N(O35),500)*1E+12+MIN(ROUND(N(F35)*100,0),99999999)*1E+4+(304+1-ROW())) -> 0
M36: =IF(G36="","",IFERROR(INDEX(Config!$B$10:$B$15,MATCH(G36,Config!$A$10:$A$15,0)),0)) | N36: =IF(OR(G36="",F36=""),"",F36*M36) | O36: =IF(OR(G36="",G36="Fechada",G36="Perdida",AND(H36="",I36="")),"",Config!$B$5-IF(I36="",H36,I36)) | P36: =IF(AND(G36="Fechada",K36<>"",H36<>""),K36-H36,"") | Q36: =IF(G36="","",IF(G36="Fechada","Fechada",IF(G36="Perdida","Perdida",IF(AND(J36<>"",J36<Config!$B$5),"Previsão vencida",IF(AND(O36<>"",O36>Config!$B$7),"Parada","Ativa"))))) | R36: =IF(OR(G36="",Q36="Fechada",Q36="Perdida"),0,IF(Q36="Previsão vencida",3,IF(Q36="Parada",2,1))*1E+15+MIN(N(O36),500)*1E+12+MIN(ROUND(N(F36)*100,0),99999999)*1E+4+(304+1-ROW())) -> 0
... M304: =IF(G304="","",IFERROR(INDEX(Config!$B$10:$B$15,MATCH(G304,Config!$A$10:$A$15,0)),0)) | N304: =IF(OR(G304="",F304=""),"",F304*M304) | O304: =IF(OR(G304="",G304="Fechada",G304="Perdida",AND(H304="",I304="")),"",Config!$B$5-IF(I304="",H304,I304)) | P304: =IF(AND(G304="Fechada",K304<>"",H304<>""),K304-H304,"") | Q304: =IF(G304="","",IF(G304="Fechada","Fechada",IF(G304="Perdida","Perdida",IF(AND(J304<>"",J304<Config!$B$5),"Previsão vencida",IF(AND(O304<>"",O304>Config!$B$7),"Parada","Ativa"))))) | R304: =IF(OR(G304="",Q304="Fechada",Q304="Perdida"),0,IF(Q304="Previsão vencida",3,IF(Q304="Parada",2,1))*1E+15+MIN(N(O304),500)*1E+12+MIN(ROUND(N(F304)*100,0),99999999)*1E+4+(304+1-ROW())) -> 0
A306: Amarelo: parada há mais dias que o limite da Config. Vermelho: fechamento previsto já passou. Verde: fechada. Cinza: perdida. Motivo em vermelho: perdida sem motivo (preencha, é o que ensina).
