Workbook

Sheet Como usar
A1: Agenda e ocupação por profissional e sala
A2: Kit de Gestão para Médicos · Seu Sócio Gestor · versão 1.0 (setembro de 2026)
A4: O que esta planilha faz | B4: Registra cada horário da agenda (quem atende, em que sala, qual paciente, pagador e procedimento, e o que aconteceu) e mede o que ninguém mede: quantas horas a clínica tinha disponíveis, quantas foram atendidas, a ocupação por profissional, por sala e por dia da semana, as faltas e a produção do mês.
A5: Passo 1 | B5: Em Config, cadastre profissionais, salas, pagadores (particular e convênios), procedimentos com duração e a tabela de preços por pagador. Depois os turnos da semana (quem atende em que dia, período e sala) e os feriados. Preencha as listas de cima para baixo, sem pular linha.
A6: Passo 2 | B6: Em Pacientes, uma linha por paciente: nome, pagador, profissional principal e contato. Só o necessário para agendar e cobrar; nada clínico. Esta aba é a fonte do cadastro de pacientes (a 14 copia daqui).
A7: Passo 3 | B7: Em Agenda, uma linha por horário: data, hora, profissional, sala, paciente, pagador, procedimento e situação. No fim do dia, a recepção marca Realizado, Falta, Cancelado ou Remarcado e a forma de pagamento (a planilha 04 tem esse passo no fechamento do dia).
A8: Passo 4 | B8: Em Painel, escolha o mês em Config: horas disponíveis (só dias já passados), atendidas, ocupação, horas vazias, faltas e produção; por profissional, por sala, por dia da semana e período, por procedimento e por pagador; e os próximos 7 dias com as vagas.
A9: Rotina de segunda | B9: 4 minutos: olhar as vagas dos próximos 7 dias e a ocupação da semana. Confirmar os agendados da semana é a rotina seguinte (mais 4 minutos). As duas estão na planilha 03 · Rotina da semana, que soma 12 minutos na segunda e 18 na sexta.
A10: Limite e como estender | B10: A aba Agenda tem 3.000 linhas (5 a 3004): com cerca de 300 atendimentos por mês, dá 10 meses. Quando chegar perto do fim, copie a última linha preenchida para baixo (a aba precisa ser desprotegida em Revisar > Desproteger planilha) e ajuste o número final nas fórmulas do Painel, ou comece um arquivo por ano — é o mais simples e mantém o histórico separado. A aba Pacientes tem 400 linhas.
A11: Ligação com as outras planilhas | B11: A produção por profissional alimenta o repasse (11); os atendimentos de convênio viram guias (13); os a prazo, parcelas (14); os no cartão, a conciliação (16). O Painel da clínica (17) copia horas atendidas, ocupação e faltas daqui. A planilha 02 copia esta Agenda para medir faltas e montar a lista de retorno.
A12: Com a IA | B12: Copie "Por dia da semana e período" e "Por profissional" e use o prompt "Agenda 01 · Onde a agenda esvazia" da biblioteca do kit. Nunca cole a aba Pacientes ou a Agenda com nomes na IA: use só as tabelas do Painel.
A13: Legenda | B13: Células amarelas: você preenche. Brancas: calculadas. Não é preciso mexer em nada fora do amarelo.
A14: Proteção | B14: Fórmulas protegidas sem senha. Para editar: Revisar > Desproteger planilha (Excel) ou Dados > Proteger intervalos (Google Sheets).
A15: Requisitos | B15: Excel 2016 ou mais novo, Microsoft 365 ou Google Sheets (só funções do Excel 2007+; nada de MÍNIMOSES, MÁXIMOSES ou UNIRTEXTO). No celular abre nos aplicativos; para preencher, use o computador.
... A20: Suporte | B20: suporte@seusociogestor.com.br · resposta em até 5 dias úteis · reembolso em até 7 dias pelo mesmo canal.

Sheet Painel
A1: =Config!$B$4&" · Agenda e ocupação · "&Config!$B$6&" de "&Config!$B$5 -> Clínica Vida Plena (exemplo fictício) · Agenda e ocupação · Setembro de 2026
A2: Nada para digitar aqui. Escolha o mês em Config; tudo vem de Agenda e dos turnos. Ocupação = horas atendidas ÷ horas disponíveis (só dias já passados).
A4: Horas disponíveis (até ontem) | C4: Horas atendidas | E4: Ocupação | G4: Horas vazias | I4: Faltas no mês | K4: Produção (R$)
A5: =SUM(Config!$G$20:$G$43) -> 64 | C5: =SUMIFS(Agenda!$R$5:$R$3004,Agenda!$N$5:$N$3004,Config!$B$7,Agenda!$O$5:$O$3004,Config!$B$5) -> 51.833333 | E5: =IF(A5=0,"",C5/A5) -> 0.80989583 | G5: =IF(A5=0,"",MAX(0,A5-C5)) -> 12.166667 | I5: =COUNTIFS(Agenda!$H$5:$H$3004,"Falta",Agenda!$N$5:$N$3004,Config!$B$7,Agenda!$O$5:$O$3004,Config!$B$5) -> 6 | K5: =SUMIFS(Agenda!$M$5:$M$3004,Agenda!$H$5:$H$3004,"Realizado",Agenda!$N$5:$N$3004,Config!$B$7,Agenda!$O$5:$O$3004,Config!$B$5) -> 20045
A7: Horas vazias = disponíveis − atendidas: inclui faltas, cancelamentos e horários que ninguém marcou. Produção = valor de tabela dos atendimentos realizados (particular e convênio), antes de glosa e taxas; o que entrou de fato está no caixa (09).
A8: =IF(SUM(Agenda!$V$5:$V$3004)=0,"","Atenção: "&SUM(Agenda!$V$5:$V$3004)&" atendimento(s) realizado(s) sem minutos ou sem valor na Agenda (em vermelho lá). Eles não entram nas horas atendidas, na ocupação nem na produção: os números deste Painel estão MENORES do que a realidade até você completar. Valor 0 digitado é válido (retorno incluído na consulta).")
A9: Por profissional
A10: Profissional | B10: Horas disponíveis | C10: Horas atendidas | D10: Ocupação | E10: Realizados | F10: Faltas | G10: Taxa de falta | H10: Produção (R$) | I10: Barra
A11: =IF(Config!$D$5="","",Config!$D$5) -> Dra. Carolina Mendes | B11: =IF(Config!$D$5="","",SUMIFS(Config!$G$20:$G$43,Config!$A$20:$A$43,Config!$D$5)) -> 24 | C11: =IF(Config!$D$5="","",SUMIFS(Agenda!$R$5:$R$3004,Agenda!$C$5:$C$3004,Config!$D$5,Agenda!$N$5:$N$3004,Config!$B$7,Agenda!$O$5:$O$3004,Config!$B$5)) -> 22 | D11: =IF(OR(Config!$D$5="",B11=0),"",C11/B11) -> 0.91666667 | E11: =IF(Config!$D$5="","",COUNTIFS(Agenda!$C$5:$C$3004,Config!$D$5,Agenda!$H$5:$H$3004,"Realizado",Agenda!$N$5:$N$3004,Config!$B$7,Agenda!$O$5:$O$3004,Config!$B$5)) -> 47 | F11: =IF(Config!$D$5="","",COUNTIFS(Agenda!$C$5:$C$3004,Config!$D$5,Agenda!$H$5:$H$3004,"Falta",Agenda!$N$5:$N$3004,Config!$B$7,Agenda!$O$5:$O$3004,Config!$B$5)) -> 1 | G11: =IF(Config!$D$5="","",IF(E11+F11=0,"",F11/(E11+F11))) -> 0.020833333 | H11: =IF(Config!$D$5="","",SUMIFS(Agenda!$M$5:$M$3004,Agenda!$C$5:$C$3004,Config!$D$5,Agenda!$H$5:$H$3004,"Realizado",Agenda!$N$5:$N$3004,Config!$B$7,Agenda!$O$5:$O$3004,Config!$B$5)) -> 10050 | I11: =IF(D11="","",REPT("█",ROUND(MIN(1,D11)*30,0))) -> ████████████████████████████
A12: =IF(Config!$D$6="","",Config!$D$6) -> Dr. Paulo Andrade | B12: =IF(Config!$D$6="","",SUMIFS(Config!$G$20:$G$43,Config!$A$20:$A$43,Config!$D$6)) -> 24 | C12: =IF(Config!$D$6="","",SUMIFS(Agenda!$R$5:$R$3004,Agenda!$C$5:$C$3004,Config!$D$6,Agenda!$N$5:$N$3004,Config!$B$7,Agenda!$O$5:$O$3004,Config!$B$5)) -> 15.833333 | D12: =IF(OR(Config!$D$6="",B12=0),"",C12/B12) -> 0.65972222 | E12: =IF(Config!$D$6="","",COUNTIFS(Agenda!$C$5:$C$3004,Config!$D$6,Agenda!$H$5:$H$3004,"Realizado",Agenda!$N$5:$N$3004,Config!$B$7,Agenda!$O$5:$O$3004,Config!$B$5)) -> 36 | F12: =IF(Config!$D$6="","",COUNTIFS(Agenda!$C$5:$C$3004,Config!$D$6,Agenda!$H$5:$H$3004,"Falta",Agenda!$N$5:$N$3004,Config!$B$7,Agenda!$O$5:$O$3004,Config!$B$5)) -> 4 | G12: =IF(Config!$D$6="","",IF(E12+F12=0,"",F12/(E12+F12))) -> 0.1 | H12: =IF(Config!$D$6="","",SUMIFS(Agenda!$M$5:$M$3004,Agenda!$C$5:$C$3004,Config!$D$6,Agenda!$H$5:$H$3004,"Realizado",Agenda!$N$5:$N$3004,Config!$B$7,Agenda!$O$5:$O$3004,Config!$B$5)) -> 4145 | I12: =IF(D12="","",REPT("█",ROUND(MIN(1,D12)*30,0))) -> ████████████████████
A13: =IF(Config!$D$7="","",Config!$D$7) -> Dra. Renata Sousa | B13: =IF(Config!$D$7="","",SUMIFS(Config!$G$20:$G$43,Config!$A$20:$A$43,Config!$D$7)) -> 16 | C13: =IF(Config!$D$7="","",SUMIFS(Agenda!$R$5:$R$3004,Agenda!$C$5:$C$3004,Config!$D$7,Agenda!$N$5:$N$3004,Config!$B$7,Agenda!$O$5:$O$3004,Config!$B$5)) -> 14 | D13: =IF(OR(Config!$D$7="",B13=0),"",C13/B13) -> 0.875 | E13: =IF(Config!$D$7="","",COUNTIFS(Agenda!$C$5:$C$3004,Config!$D$7,Agenda!$H$5:$H$3004,"Realizado",Agenda!$N$5:$N$3004,Config!$B$7,Agenda!$O$5:$O$3004,Config!$B$5)) -> 24 | F13: =IF(Config!$D$7="","",COUNTIFS(Agenda!$C$5:$C$3004,Config!$D$7,Agenda!$H$5:$H$3004,"Falta",Agenda!$N$5:$N$3004,Config!$B$7,Agenda!$O$5:$O$3004,Config!$B$5)) -> 1 | G13: =IF(Config!$D$7="","",IF(E13+F13=0,"",F13/(E13+F13))) -> 0.04 | H13: =IF(Config!$D$7="","",SUMIFS(Agenda!$M$5:$M$3004,Agenda!$C$5:$C$3004,Config!$D$7,Agenda!$H$5:$H$3004,"Realizado",Agenda!$N$5:$N$3004,Config!$B$7,Agenda!$O$5:$O$3004,Config!$B$5)) -> 5850 | I13: =IF(D13="","",REPT("█",ROUND(MIN(1,D13)*30,0))) -> ██████████████████████████
A14: =IF(Config!$D$8="","",Config!$D$8) | B14: =IF(Config!$D$8="","",SUMIFS(Config!$G$20:$G$43,Config!$A$20:$A$43,Config!$D$8)) | C14: =IF(Config!$D$8="","",SUMIFS(Agenda!$R$5:$R$3004,Agenda!$C$5:$C$3004,Config!$D$8,Agenda!$N$5:$N$3004,Config!$B$7,Agenda!$O$5:$O$3004,Config!$B$5)) | D14: =IF(OR(Config!$D$8="",B14=0),"",C14/B14) | E14: =IF(Config!$D$8="","",COUNTIFS(Agenda!$C$5:$C$3004,Config!$D$8,Agenda!$H$5:$H$3004,"Realizado",Agenda!$N$5:$N$3004,Config!$B$7,Agenda!$O$5:$O$3004,Config!$B$5)) | F14: =IF(Config!$D$8="","",COUNTIFS(Agenda!$C$5:$C$3004,Config!$D$8,Agenda!$H$5:$H$3004,"Falta",Agenda!$N$5:$N$3004,Config!$B$7,Agenda!$O$5:$O$3004,Config!$B$5)) | G14: =IF(Config!$D$8="","",IF(E14+F14=0,"",F14/(E14+F14))) | H14: =IF(Config!$D$8="","",SUMIFS(Agenda!$M$5:$M$3004,Agenda!$C$5:$C$3004,Config!$D$8,Agenda!$H$5:$H$3004,"Realizado",Agenda!$N$5:$N$3004,Config!$B$7,Agenda!$O$5:$O$3004,Config!$B$5)) | I14: =IF(D14="","",REPT("█",ROUND(MIN(1,D14)*30,0)))
A15: =IF(Config!$D$9="","",Config!$D$9) | B15: =IF(Config!$D$9="","",SUMIFS(Config!$G$20:$G$43,Config!$A$20:$A$43,Config!$D$9)) | C15: =IF(Config!$D$9="","",SUMIFS(Agenda!$R$5:$R$3004,Agenda!$C$5:$C$3004,Config!$D$9,Agenda!$N$5:$N$3004,Config!$B$7,Agenda!$O$5:$O$3004,Config!$B$5)) | D15: =IF(OR(Config!$D$9="",B15=0),"",C15/B15) | E15: =IF(Config!$D$9="","",COUNTIFS(Agenda!$C$5:$C$3004,Config!$D$9,Agenda!$H$5:$H$3004,"Realizado",Agenda!$N$5:$N$3004,Config!$B$7,Agenda!$O$5:$O$3004,Config!$B$5)) | F15: =IF(Config!$D$9="","",COUNTIFS(Agenda!$C$5:$C$3004,Config!$D$9,Agenda!$H$5:$H$3004,"Falta",Agenda!$N$5:$N$3004,Config!$B$7,Agenda!$O$5:$O$3004,Config!$B$5)) | G15: =IF(Config!$D$9="","",IF(E15+F15=0,"",F15/(E15+F15))) | H15: =IF(Config!$D$9="","",SUMIFS(Agenda!$M$5:$M$3004,Agenda!$C$5:$C$3004,Config!$D$9,Agenda!$H$5:$H$3004,"Realizado",Agenda!$N$5:$N$3004,Config!$B$7,Agenda!$O$5:$O$3004,Config!$B$5)) | I15: =IF(D15="","",REPT("█",ROUND(MIN(1,D15)*30,0)))
A16: =IF(Config!$D$10="","",Config!$D$10) | B16: =IF(Config!$D$10="","",SUMIFS(Config!$G$20:$G$43,Config!$A$20:$A$43,Config!$D$10)) | C16: =IF(Config!$D$10="","",SUMIFS(Agenda!$R$5:$R$3004,Agenda!$C$5:$C$3004,Config!$D$10,Agenda!$N$5:$N$3004,Config!$B$7,Agenda!$O$5:$O$3004,Config!$B$5)) | D16: =IF(OR(Config!$D$10="",B16=0),"",C16/B16) | E16: =IF(Config!$D$10="","",COUNTIFS(Agenda!$C$5:$C$3004,Config!$D$10,Agenda!$H$5:$H$3004,"Realizado",Agenda!$N$5:$N$3004,Config!$B$7,Agenda!$O$5:$O$3004,Config!$B$5)) | F16: =IF(Config!$D$10="","",COUNTIFS(Agenda!$C$5:$C$3004,Config!$D$10,Agenda!$H$5:$H$3004,"Falta",Agenda!$N$5:$N$3004,Config!$B$7,Agenda!$O$5:$O$3004,Config!$B$5)) | G16: =IF(Config!$D$10="","",IF(E16+F16=0,"",F16/(E16+F16))) | H16: =IF(Config!$D$10="","",SUMIFS(Agenda!$M$5:$M$3004,Agenda!$C$5:$C$3004,Config!$D$10,Agenda!$H$5:$H$3004,"Realizado",Agenda!$N$5:$N$3004,Config!$B$7,Agenda!$O$5:$O$3004,Config!$B$5)) | I16: =IF(D16="","",REPT("█",ROUND(MIN(1,D16)*30,0)))
A17: =IF(Config!$D$11="","",Config!$D$11) | B17: =IF(Config!$D$11="","",SUMIFS(Config!$G$20:$G$43,Config!$A$20:$A$43,Config!$D$11)) | C17: =IF(Config!$D$11="","",SUMIFS(Agenda!$R$5:$R$3004,Agenda!$C$5:$C$3004,Config!$D$11,Agenda!$N$5:$N$3004,Config!$B$7,Agenda!$O$5:$O$3004,Config!$B$5)) | D17: =IF(OR(Config!$D$11="",B17=0),"",C17/B17) | E17: =IF(Config!$D$11="","",COUNTIFS(Agenda!$C$5:$C$3004,Config!$D$11,Agenda!$H$5:$H$3004,"Realizado",Agenda!$N$5:$N$3004,Config!$B$7,Agenda!$O$5:$O$3004,Config!$B$5)) | F17: =IF(Config!$D$11="","",COUNTIFS(Agenda!$C$5:$C$3004,Config!$D$11,Agenda!$H$5:$H$3004,"Falta",Agenda!$N$5:$N$3004,Config!$B$7,Agenda!$O$5:$O$3004,Config!$B$5)) | G17: =IF(Config!$D$11="","",IF(E17+F17=0,"",F17/(E17+F17))) | H17: =IF(Config!$D$11="","",SUMIFS(Agenda!$M$5:$M$3004,Agenda!$C$5:$C$3004,Config!$D$11,Agenda!$H$5:$H$3004,"Realizado",Agenda!$N$5:$N$3004,Config!$B$7,Agenda!$O$5:$O$3004,Config!$B$5)) | I17: =IF(D17="","",REPT("█",ROUND(MIN(1,D17)*30,0)))
A18: =IF(Config!$D$12="","",Config!$D$12) | B18: =IF(Config!$D$12="","",SUMIFS(Config!$G$20:$G$43,Config!$A$20:$A$43,Config!$D$12)) | C18: =IF(Config!$D$12="","",SUMIFS(Agenda!$R$5:$R$3004,Agenda!$C$5:$C$3004,Config!$D$12,Agenda!$N$5:$N$3004,Config!$B$7,Agenda!$O$5:$O$3004,Config!$B$5)) | D18: =IF(OR(Config!$D$12="",B18=0),"",C18/B18) | E18: =IF(Config!$D$12="","",COUNTIFS(Agenda!$C$5:$C$3004,Config!$D$12,Agenda!$H$5:$H$3004,"Realizado",Agenda!$N$5:$N$3004,Config!$B$7,Agenda!$O$5:$O$3004,Config!$B$5)) | F18: =IF(Config!$D$12="","",COUNTIFS(Agenda!$C$5:$C$3004,Config!$D$12,Agenda!$H$5:$H$3004,"Falta",Agenda!$N$5:$N$3004,Config!$B$7,Agenda!$O$5:$O$3004,Config!$B$5)) | G18: =IF(Config!$D$12="","",IF(E18+F18=0,"",F18/(E18+F18))) | H18: =IF(Config!$D$12="","",SUMIFS(Agenda!$M$5:$M$3004,Agenda!$C$5:$C$3004,Config!$D$12,Agenda!$H$5:$H$3004,"Realizado",Agenda!$N$5:$N$3004,Config!$B$7,Agenda!$O$5:$O$3004,Config!$B$5)) | I18: =IF(D18="","",REPT("█",ROUND(MIN(1,D18)*30,0)))
A19: Ocupação abaixo de 60 % fica em amarelo; taxa de falta acima de 10 % em vermelho. Taxa de falta = faltas ÷ (faltas + realizados), a mesma conta da planilha 02.
A21: Por sala
A22: Sala | B22: Horas disponíveis | C22: Horas atendidas | D22: Ocupação | E22: Horas vazias | F22: Turnos por semana
A23: =IF(Config!$F$5="","",Config!$F$5) -> Sala 1 | B23: =IF(Config!$F$5="","",SUMIFS(Config!$G$20:$G$43,Config!$D$20:$D$43,Config!$F$5)) -> 40 | C23: =IF(Config!$F$5="","",SUMIFS(Agenda!$R$5:$R$3004,Agenda!$D$5:$D$3004,Config!$F$5,Agenda!$N$5:$N$3004,Config!$B$7,Agenda!$O$5:$O$3004,Config!$B$5)) -> 36 | D23: =IF(OR(Config!$F$5="",B23=0),"",C23/B23) -> 0.9 | E23: =IF(B23="","",MAX(0,B23-C23)) -> 4 | F23: =IF(Config!$F$5="","",COUNTIFS(Config!$D$20:$D$43,Config!$F$5,Config!$A$20:$A$43,"<>")) -> 6
A24: =IF(Config!$F$6="","",Config!$F$6) -> Sala 2 | B24: =IF(Config!$F$6="","",SUMIFS(Config!$G$20:$G$43,Config!$D$20:$D$43,Config!$F$6)) -> 24 | C24: =IF(Config!$F$6="","",SUMIFS(Agenda!$R$5:$R$3004,Agenda!$D$5:$D$3004,Config!$F$6,Agenda!$N$5:$N$3004,Config!$B$7,Agenda!$O$5:$O$3004,Config!$B$5)) -> 15.833333 | D24: =IF(OR(Config!$F$6="",B24=0),"",C24/B24) -> 0.65972222 | E24: =IF(B24="","",MAX(0,B24-C24)) -> 8.1666667 | F24: =IF(Config!$F$6="","",COUNTIFS(Config!$D$20:$D$43,Config!$F$6,Config!$A$20:$A$43,"<>")) -> 4
A25: =IF(Config!$F$7="","",Config!$F$7) | B25: =IF(Config!$F$7="","",SUMIFS(Config!$G$20:$G$43,Config!$D$20:$D$43,Config!$F$7)) | C25: =IF(Config!$F$7="","",SUMIFS(Agenda!$R$5:$R$3004,Agenda!$D$5:$D$3004,Config!$F$7,Agenda!$N$5:$N$3004,Config!$B$7,Agenda!$O$5:$O$3004,Config!$B$5)) | D25: =IF(OR(Config!$F$7="",B25=0),"",C25/B25) | E25: =IF(B25="","",MAX(0,B25-C25)) | F25: =IF(Config!$F$7="","",COUNTIFS(Config!$D$20:$D$43,Config!$F$7,Config!$A$20:$A$43,"<>"))
A26: =IF(Config!$F$8="","",Config!$F$8) | B26: =IF(Config!$F$8="","",SUMIFS(Config!$G$20:$G$43,Config!$D$20:$D$43,Config!$F$8)) | C26: =IF(Config!$F$8="","",SUMIFS(Agenda!$R$5:$R$3004,Agenda!$D$5:$D$3004,Config!$F$8,Agenda!$N$5:$N$3004,Config!$B$7,Agenda!$O$5:$O$3004,Config!$B$5)) | D26: =IF(OR(Config!$F$8="",B26=0),"",C26/B26) | E26: =IF(B26="","",MAX(0,B26-C26)) | F26: =IF(Config!$F$8="","",COUNTIFS(Config!$D$20:$D$43,Config!$F$8,Config!$A$20:$A$43,"<>"))
A27: =IF(Config!$F$9="","",Config!$F$9) | B27: =IF(Config!$F$9="","",SUMIFS(Config!$G$20:$G$43,Config!$D$20:$D$43,Config!$F$9)) | C27: =IF(Config!$F$9="","",SUMIFS(Agenda!$R$5:$R$3004,Agenda!$D$5:$D$3004,Config!$F$9,Agenda!$N$5:$N$3004,Config!$B$7,Agenda!$O$5:$O$3004,Config!$B$5)) | D27: =IF(OR(Config!$F$9="",B27=0),"",C27/B27) | E27: =IF(B27="","",MAX(0,B27-C27)) | F27: =IF(Config!$F$9="","",COUNTIFS(Config!$D$20:$D$43,Config!$F$9,Config!$A$20:$A$43,"<>"))
A28: =IF(Config!$F$10="","",Config!$F$10) | B28: =IF(Config!$F$10="","",SUMIFS(Config!$G$20:$G$43,Config!$D$20:$D$43,Config!$F$10)) | C28: =IF(Config!$F$10="","",SUMIFS(Agenda!$R$5:$R$3004,Agenda!$D$5:$D$3004,Config!$F$10,Agenda!$N$5:$N$3004,Config!$B$7,Agenda!$O$5:$O$3004,Config!$B$5)) | D28: =IF(OR(Config!$F$10="",B28=0),"",C28/B28) | E28: =IF(B28="","",MAX(0,B28-C28)) | F28: =IF(Config!$F$10="","",COUNTIFS(Config!$D$20:$D$43,Config!$F$10,Config!$A$20:$A$43,"<>"))
A29: Sala com poucos turnos por semana é capacidade parada: cabe outro profissional por repasse (planilha 11) sem aumentar o aluguel.
A32: Por dia da semana e período (onde a agenda esvazia)
A33: Dia | B33: Manhã · disponíveis | C33: Manhã · atendidas | D33: Manhã · ocupação | E33: Tarde · disponíveis | F33: Tarde · atendidas | G33: Tarde · ocupação | H33: Faltas no dia
A34: Segunda | B34: =SUMIFS(Config!$G$20:$G$43,Config!$B$20:$B$43,A34,Config!$C$20:$C$43,"Manhã") -> 0 | C34: =SUMIFS(Agenda!$R$5:$R$3004,Agenda!$P$5:$P$3004,A34,Agenda!$Q$5:$Q$3004,"Manhã",Agenda!$N$5:$N$3004,Config!$B$7,Agenda!$O$5:$O$3004,Config!$B$5) -> 0 | D34: =IF(B34=0,"",C34/B34) | E34: =SUMIFS(Config!$G$20:$G$43,Config!$B$20:$B$43,A34,Config!$C$20:$C$43,"Tarde") -> 0 | F34: =SUMIFS(Agenda!$R$5:$R$3004,Agenda!$P$5:$P$3004,A34,Agenda!$Q$5:$Q$3004,"Tarde",Agenda!$N$5:$N$3004,Config!$B$7,Agenda!$O$5:$O$3004,Config!$B$5) -> 0 | G34: =IF(E34=0,"",F34/E34) | H34: =COUNTIFS(Agenda!$P$5:$P$3004,A34,Agenda!$H$5:$H$3004,"Falta",Agenda!$N$5:$N$3004,Config!$B$7,Agenda!$O$5:$O$3004,Config!$B$5) -> 0
A35: Terça | B35: =SUMIFS(Config!$G$20:$G$43,Config!$B$20:$B$43,A35,Config!$C$20:$C$43,"Manhã") -> 8 | C35: =SUMIFS(Agenda!$R$5:$R$3004,Agenda!$P$5:$P$3004,A35,Agenda!$Q$5:$Q$3004,"Manhã",Agenda!$N$5:$N$3004,Config!$B$7,Agenda!$O$5:$O$3004,Config!$B$5) -> 6.8333333 | D35: =IF(B35=0,"",C35/B35) -> 0.85416667 | E35: =SUMIFS(Config!$G$20:$G$43,Config!$B$20:$B$43,A35,Config!$C$20:$C$43,"Tarde") -> 16 | F35: =SUMIFS(Agenda!$R$5:$R$3004,Agenda!$P$5:$P$3004,A35,Agenda!$Q$5:$Q$3004,"Tarde",Agenda!$N$5:$N$3004,Config!$B$7,Agenda!$O$5:$O$3004,Config!$B$5) -> 13 | G35: =IF(E35=0,"",F35/E35) -> 0.8125 | H35: =COUNTIFS(Agenda!$P$5:$P$3004,A35,Agenda!$H$5:$H$3004,"Falta",Agenda!$N$5:$N$3004,Config!$B$7,Agenda!$O$5:$O$3004,Config!$B$5) -> 2
A36: Quarta | B36: =SUMIFS(Config!$G$20:$G$43,Config!$B$20:$B$43,A36,Config!$C$20:$C$43,"Manhã") -> 0 | C36: =SUMIFS(Agenda!$R$5:$R$3004,Agenda!$P$5:$P$3004,A36,Agenda!$Q$5:$Q$3004,"Manhã",Agenda!$N$5:$N$3004,Config!$B$7,Agenda!$O$5:$O$3004,Config!$B$5) -> 0 | D36: =IF(B36=0,"",C36/B36) | E36: =SUMIFS(Config!$G$20:$G$43,Config!$B$20:$B$43,A36,Config!$C$20:$C$43,"Tarde") -> 8 | F36: =SUMIFS(Agenda!$R$5:$R$3004,Agenda!$P$5:$P$3004,A36,Agenda!$Q$5:$Q$3004,"Tarde",Agenda!$N$5:$N$3004,Config!$B$7,Agenda!$O$5:$O$3004,Config!$B$5) -> 7.8333333 | G36: =IF(E36=0,"",F36/E36) -> 0.97916667 | H36: =COUNTIFS(Agenda!$P$5:$P$3004,A36,Agenda!$H$5:$H$3004,"Falta",Agenda!$N$5:$N$3004,Config!$B$7,Agenda!$O$5:$O$3004,Config!$B$5) -> 0
A37: Quinta | B37: =SUMIFS(Config!$G$20:$G$43,Config!$B$20:$B$43,A37,Config!$C$20:$C$43,"Manhã") -> 8 | C37: =SUMIFS(Agenda!$R$5:$R$3004,Agenda!$P$5:$P$3004,A37,Agenda!$Q$5:$Q$3004,"Manhã",Agenda!$N$5:$N$3004,Config!$B$7,Agenda!$O$5:$O$3004,Config!$B$5) -> 7.3333333 | D37: =IF(B37=0,"",C37/B37) -> 0.91666667 | E37: =SUMIFS(Config!$G$20:$G$43,Config!$B$20:$B$43,A37,Config!$C$20:$C$43,"Tarde") -> 16 | F37: =SUMIFS(Agenda!$R$5:$R$3004,Agenda!$P$5:$P$3004,A37,Agenda!$Q$5:$Q$3004,"Tarde",Agenda!$N$5:$N$3004,Config!$B$7,Agenda!$O$5:$O$3004,Config!$B$5) -> 11.666667 | G37: =IF(E37=0,"",F37/E37) -> 0.72916667 | H37: =COUNTIFS(Agenda!$P$5:$P$3004,A37,Agenda!$H$5:$H$3004,"Falta",Agenda!$N$5:$N$3004,Config!$B$7,Agenda!$O$5:$O$3004,Config!$B$5) -> 2
A38: Sexta | B38: =SUMIFS(Config!$G$20:$G$43,Config!$B$20:$B$43,A38,Config!$C$20:$C$43,"Manhã") -> 8 | C38: =SUMIFS(Agenda!$R$5:$R$3004,Agenda!$P$5:$P$3004,A38,Agenda!$Q$5:$Q$3004,"Manhã",Agenda!$N$5:$N$3004,Config!$B$7,Agenda!$O$5:$O$3004,Config!$B$5) -> 5.1666667 | D38: =IF(B38=0,"",C38/B38) -> 0.64583333 | E38: =SUMIFS(Config!$G$20:$G$43,Config!$B$20:$B$43,A38,Config!$C$20:$C$43,"Tarde") -> 0 | F38: =SUMIFS(Agenda!$R$5:$R$3004,Agenda!$P$5:$P$3004,A38,Agenda!$Q$5:$Q$3004,"Tarde",Agenda!$N$5:$N$3004,Config!$B$7,Agenda!$O$5:$O$3004,Config!$B$5) -> 0 | G38: =IF(E38=0,"",F38/E38) | H38: =COUNTIFS(Agenda!$P$5:$P$3004,A38,Agenda!$H$5:$H$3004,"Falta",Agenda!$N$5:$N$3004,Config!$B$7,Agenda!$O$5:$O$3004,Config!$B$5) -> 2
A39: Sábado | B39: =SUMIFS(Config!$G$20:$G$43,Config!$B$20:$B$43,A39,Config!$C$20:$C$43,"Manhã") -> 0 | C39: =SUMIFS(Agenda!$R$5:$R$3004,Agenda!$P$5:$P$3004,A39,Agenda!$Q$5:$Q$3004,"Manhã",Agenda!$N$5:$N$3004,Config!$B$7,Agenda!$O$5:$O$3004,Config!$B$5) -> 0 | D39: =IF(B39=0,"",C39/B39) | E39: =SUMIFS(Config!$G$20:$G$43,Config!$B$20:$B$43,A39,Config!$C$20:$C$43,"Tarde") -> 0 | F39: =SUMIFS(Agenda!$R$5:$R$3004,Agenda!$P$5:$P$3004,A39,Agenda!$Q$5:$Q$3004,"Tarde",Agenda!$N$5:$N$3004,Config!$B$7,Agenda!$O$5:$O$3004,Config!$B$5) -> 0 | G39: =IF(E39=0,"",F39/E39) | H39: =COUNTIFS(Agenda!$P$5:$P$3004,A39,Agenda!$H$5:$H$3004,"Falta",Agenda!$N$5:$N$3004,Config!$B$7,Agenda!$O$5:$O$3004,Config!$B$5) -> 0
A40: Dia em cinza: nenhum turno disponível no período contado. As horas disponíveis só contam dias já passados e pulam os feriados de Config, então num mês em andamento um dia da semana pode aparecer zerado sem que a clínica tenha fechado. No exemplo (setembro), a segunda aparece assim: 07/09 é feriado e 14/09 é hoje, e as duas segundas anteriores ao mês não contam — Dra. Carolina e Dr. Paulo atendem normalmente às segundas.
A42: Por procedimento
A43: Procedimento | B43: Realizados | C43: Horas | D43: Produção (R$) | E43: Valor médio (R$) | G43: Pagador | H43: Realizados | I43: Horas | J43: Faltas | K43: Taxa de falta | L43: Produção (R$) | M43: Valor médio (R$) | N43: % da produção
A44: =IF(Config!$J$5="","",Config!$J$5) -> Consulta | B44: =IF(Config!$J$5="","",COUNTIFS(Agenda!$G$5:$G$3004,Config!$J$5,Agenda!$H$5:$H$3004,"Realizado",Agenda!$N$5:$N$3004,Config!$B$7,Agenda!$O$5:$O$3004,Config!$B$5)) -> 49 | C44: =IF(Config!$J$5="","",SUMIFS(Agenda!$U$5:$U$3004,Agenda!$G$5:$G$3004,Config!$J$5,Agenda!$N$5:$N$3004,Config!$B$7,Agenda!$O$5:$O$3004,Config!$B$5)) -> 24.5 | D44: =IF(Config!$J$5="","",SUMIFS(Agenda!$M$5:$M$3004,Agenda!$G$5:$G$3004,Config!$J$5,Agenda!$H$5:$H$3004,"Realizado",Agenda!$N$5:$N$3004,Config!$B$7,Agenda!$O$5:$O$3004,Config!$B$5)) -> 11240 | E44: =IF(OR(Config!$J$5="",B44=0),"",D44/B44) -> 229.38776 | G44: =IF(Config!$H$5="","",Config!$H$5) -> Particular | H44: =IF(Config!$H$5="","",COUNTIFS(Agenda!$F$5:$F$3004,Config!$H$5,Agenda!$H$5:$H$3004,"Realizado",Agenda!$N$5:$N$3004,Config!$B$7,Agenda!$O$5:$O$3004,Config!$B$5)) -> 55 | I44: =IF(Config!$H$5="","",SUMIFS(Agenda!$U$5:$U$3004,Agenda!$F$5:$F$3004,Config!$H$5,Agenda!$N$5:$N$3004,Config!$B$7,Agenda!$O$5:$O$3004,Config!$B$5)) -> 27 | J44: =IF(Config!$H$5="","",COUNTIFS(Agenda!$F$5:$F$3004,Config!$H$5,Agenda!$H$5:$H$3004,"Falta",Agenda!$N$5:$N$3004,Config!$B$7,Agenda!$O$5:$O$3004,Config!$B$5)) -> 2 | K44: =IF(Config!$H$5="","",IF(H44+J44=0,"",J44/(H44+J44))) -> 0.035087719 | L44: =IF(Config!$H$5="","",SUMIFS(Agenda!$M$5:$M$3004,Agenda!$F$5:$F$3004,Config!$H$5,Agenda!$H$5:$H$3004,"Realizado",Agenda!$N$5:$N$3004,Config!$B$7,Agenda!$O$5:$O$3004,Config!$B$5)) -> 15620 | M44: =IF(OR(Config!$H$5="",H44=0),"",L44/H44) -> 284 | N44: =IF(OR(Config!$H$5="",$K$5=0),"",L44/$K$5) -> 0.77924669
A45: =IF(Config!$J$6="","",Config!$J$6) -> Retorno | B45: =IF(Config!$J$6="","",COUNTIFS(Agenda!$G$5:$G$3004,Config!$J$6,Agenda!$H$5:$H$3004,"Realizado",Agenda!$N$5:$N$3004,Config!$B$7,Agenda!$O$5:$O$3004,Config!$B$5)) -> 23 | C45: =IF(Config!$J$6="","",SUMIFS(Agenda!$U$5:$U$3004,Agenda!$G$5:$G$3004,Config!$J$6,Agenda!$N$5:$N$3004,Config!$B$7,Agenda!$O$5:$O$3004,Config!$B$5)) -> 7.6666667 | D45: =IF(Config!$J$6="","",SUMIFS(Agenda!$M$5:$M$3004,Agenda!$G$5:$G$3004,Config!$J$6,Agenda!$H$5:$H$3004,"Realizado",Agenda!$N$5:$N$3004,Config!$B$7,Agenda!$O$5:$O$3004,Config!$B$5)) -> 0 | E45: =IF(OR(Config!$J$6="",B45=0),"",D45/B45) -> 0 | G45: =IF(Config!$H$6="","",Config!$H$6) -> Saúde Total | H45: =IF(Config!$H$6="","",COUNTIFS(Agenda!$F$5:$F$3004,Config!$H$6,Agenda!$H$5:$H$3004,"Realizado",Agenda!$N$5:$N$3004,Config!$B$7,Agenda!$O$5:$O$3004,Config!$B$5)) -> 26 | I45: =IF(Config!$H$6="","",SUMIFS(Agenda!$U$5:$U$3004,Agenda!$F$5:$F$3004,Config!$H$6,Agenda!$N$5:$N$3004,Config!$B$7,Agenda!$O$5:$O$3004,Config!$B$5)) -> 12.833333 | J45: =IF(Config!$H$6="","",COUNTIFS(Agenda!$F$5:$F$3004,Config!$H$6,Agenda!$H$5:$H$3004,"Falta",Agenda!$N$5:$N$3004,Config!$B$7,Agenda!$O$5:$O$3004,Config!$B$5)) -> 2 | K45: =IF(Config!$H$6="","",IF(H45+J45=0,"",J45/(H45+J45))) -> 0.071428571 | L45: =IF(Config!$H$6="","",SUMIFS(Agenda!$M$5:$M$3004,Agenda!$F$5:$F$3004,Config!$H$6,Agenda!$H$5:$H$3004,"Realizado",Agenda!$N$5:$N$3004,Config!$B$7,Agenda!$O$5:$O$3004,Config!$B$5)) -> 2435 | M45: =IF(OR(Config!$H$6="",H45=0),"",L45/H45) -> 93.653846 | N45: =IF(OR(Config!$H$6="",$K$5=0),"",L45/$K$5) -> 0.12147668
A46: =IF(Config!$J$7="","",Config!$J$7) -> ECG | B46: =IF(Config!$J$7="","",COUNTIFS(Agenda!$G$5:$G$3004,Config!$J$7,Agenda!$H$5:$H$3004,"Realizado",Agenda!$N$5:$N$3004,Config!$B$7,Agenda!$O$5:$O$3004,Config!$B$5)) -> 5 | C46: =IF(Config!$J$7="","",SUMIFS(Agenda!$U$5:$U$3004,Agenda!$G$5:$G$3004,Config!$J$7,Agenda!$N$5:$N$3004,Config!$B$7,Agenda!$O$5:$O$3004,Config!$B$5)) -> 1.6666667 | D46: =IF(Config!$J$7="","",SUMIFS(Agenda!$M$5:$M$3004,Agenda!$G$5:$G$3004,Config!$J$7,Agenda!$H$5:$H$3004,"Realizado",Agenda!$N$5:$N$3004,Config!$B$7,Agenda!$O$5:$O$3004,Config!$B$5)) -> 375 | E46: =IF(OR(Config!$J$7="",B46=0),"",D46/B46) -> 75 | G46: =IF(Config!$H$7="","",Config!$H$7) -> MediPlan | H46: =IF(Config!$H$7="","",COUNTIFS(Agenda!$F$5:$F$3004,Config!$H$7,Agenda!$H$5:$H$3004,"Realizado",Agenda!$N$5:$N$3004,Config!$B$7,Agenda!$O$5:$O$3004,Config!$B$5)) -> 19 | I46: =IF(Config!$H$7="","",SUMIFS(Agenda!$U$5:$U$3004,Agenda!$F$5:$F$3004,Config!$H$7,Agenda!$N$5:$N$3004,Config!$B$7,Agenda!$O$5:$O$3004,Config!$B$5)) -> 8.6666667 | J46: =IF(Config!$H$7="","",COUNTIFS(Agenda!$F$5:$F$3004,Config!$H$7,Agenda!$H$5:$H$3004,"Falta",Agenda!$N$5:$N$3004,Config!$B$7,Agenda!$O$5:$O$3004,Config!$B$5)) -> 1 | K46: =IF(Config!$H$7="","",IF(H46+J46=0,"",J46/(H46+J46))) -> 0.05 | L46: =IF(Config!$H$7="","",SUMIFS(Agenda!$M$5:$M$3004,Agenda!$F$5:$F$3004,Config!$H$7,Agenda!$H$5:$H$3004,"Realizado",Agenda!$N$5:$N$3004,Config!$B$7,Agenda!$O$5:$O$3004,Config!$B$5)) -> 1445 | M46: =IF(OR(Config!$H$7="",H46=0),"",L46/H46) -> 76.052632 | N46: =IF(OR(Config!$H$7="",$K$5=0),"",L46/$K$5) -> 0.072087802
...

Sheet Config
A1: Configurações
A2: Células amarelas: você preenche. Profissionais, salas, pagadores, procedimentos, tabela de preços e turnos alimentam a Agenda e o Painel.
M3: Tabela de preços por pagador (R$)
A4: Clínica | B4: Clínica Vida Plena (exemplo fictício) | D4: Profissionais (até 8) | E4: Especialidade | F4: Salas (até 6) | H4: Pagadores (até 6) | J4: Procedimentos (até 12) | K4: Minutos | L4: Retorno em (dias) | M4: =IF($H$5="","",$H$5) -> Particular | N4: =IF($H$6="","",$H$6) -> Saúde Total | O4: =IF($H$7="","",$H$7) -> MediPlan | P4: =IF($H$8="","",$H$8) -> Vida Care | Q4: =IF($H$9="","",$H$9) | R4: =IF($H$10="","",$H$10) | T4: Meses
A5: Ano do painel | B5: 2026 | D5: Dra. Carolina Mendes | E5: Clínica médica | F5: Sala 1 | H5: Particular | J5: Consulta | K5: 30 | L5: 30 | M5: 380 | N5: 120 | O5: 100 | P5: 90 | T5: Janeiro
A6: Mês do painel | B6: Setembro | D6: Dr. Paulo Andrade | E6: Cardiologia | F6: Sala 2 | H6: Saúde Total | J6: Retorno | K6: 20 | L6: 0 | M6: 0 | N6: 0 | O6: 0 | P6: 0 | T6: Fevereiro
A7: Número do mês | B7: =MATCH(B6,$T$5:$T$16,0) -> 9 | D7: Dra. Renata Sousa | E7: Endocrinologia | H7: MediPlan | J7: ECG | K7: 20 | L7: 0 | M7: 130 | N7: 40 | O7: 35 | P7: 32 | T7: Março
A8: Data de referência (hoje) | B8: 46279 | C8: O exemplo está congelado em 14/09/2026, para os arquivos do kit mostrarem a mesma foto. Ao usar com os seus dados, troque por =HOJE(). | H8: Vida Care | J8: MAPA | K8: 20 | L8: 0 | M8: 300 | N8: 95 | O8: 85 | P8: 75 | T8: Abril
A9: Painel conta horas disponíveis até | B9: =MIN(DATE(B5,B7+1,0),B8-1) -> 46278 | C9: Ontem, ou o fim do mês do painel se ele já passou: as horas disponíveis só contam dias que já aconteceram. | J9: Holter | K9: 20 | L9: 0 | M9: 350 | N9: 105 | O9: 95 | P9: 85 | T9: Maio
A10: Horas por turno (padrão) | B10: 4 | J10: Teste ergométrico | K10: 40 | L10: 0 | M10: 450 | N10: 140 | O10: 125 | P10: 110 | T10: Junho
J11: Avaliação endócrina | K11: 40 | L11: 45 | M11: 400 | N11: 130 | T11: Julho
T12: Agosto
T13: Setembro
D14: Preencha as listas de cima para baixo, sem pular linha: as listas suspensas da Agenda param na última linha preenchida. Retorno em (dias) = prazo em que se espera o paciente de volta (0 = não se aplica); a planilha 02 usa isso na lista de retorno. | T14: Outubro
D15: Tabela de preços: valor de cada procedimento para cada pagador. Célula vazia = não credenciado. A Agenda SUGERE o valor daqui nas duas últimas colunas, mas grava na linha o valor que você lançar: reajustar esta tabela não mexe no que já aconteceu. COPIE DA PLANILHA 08 (Tabela de preços): ela é a fonte única da tabela no kit; 06 e 07 também copiam de lá. Mudou um preço? Atualize a 08 primeiro e depois 06, 07 e esta Config. | T15: Novembro
T16: Dezembro
A18: Turnos da semana (até 24): quem atende, em que dia, período e sala | I18: Feriados e dias sem atendimento (até 20)
A19: Profissional | B19: Dia da semana | C19: Período | D19: Sala | E19: Início | F19: Horas | G19: Horas disponíveis no mês (até o limite) | I19: 46023
A20: Dra. Carolina Mendes | B20: Segunda | C20: Manhã | D20: Sala 1 | E20: 0.33333333 | F20: 4 | G20: =IF(A20="","",IF(F20="",$B$10,F20)*IFERROR(INDEX($J$45:$J$50,MATCH(B20,$I$45:$I$50,0)),0)) -> 0 | I20: 46069
A21: Dra. Carolina Mendes | B21: Terça | C21: Manhã | D21: Sala 1 | E21: 0.33333333 | F21: 4 | G21: =IF(A21="","",IF(F21="",$B$10,F21)*IFERROR(INDEX($J$45:$J$50,MATCH(B21,$I$45:$I$50,0)),0)) -> 8 | I21: 46070
A22: Dra. Carolina Mendes | B22: Quarta | C22: Tarde | D22: Sala 1 | E22: 0.58333333 | F22: 4 | G22: =IF(A22="","",IF(F22="",$B$10,F22)*IFERROR(INDEX($J$45:$J$50,MATCH(B22,$I$45:$I$50,0)),0)) -> 8 | I22: 46115
A23: Dra. Carolina Mendes | B23: Quinta | C23: Manhã | D23: Sala 1 | E23: 0.33333333 | F23: 4 | G23: =IF(A23="","",IF(F23="",$B$10,F23)*IFERROR(INDEX($J$45:$J$50,MATCH(B23,$I$45:$I$50,0)),0)) -> 8 | I23: 46133
A24: Dr. Paulo Andrade | B24: Segunda | C24: Tarde | D24: Sala 2 | E24: 0.58333333 | F24: 4 | G24: =IF(A24="","",IF(F24="",$B$10,F24)*IFERROR(INDEX($J$45:$J$50,MATCH(B24,$I$45:$I$50,0)),0)) -> 0 | I24: 46143
A25: Dr. Paulo Andrade | B25: Terça | C25: Tarde | D25: Sala 2 | E25: 0.58333333 | F25: 4 | G25: =IF(A25="","",IF(F25="",$B$10,F25)*IFERROR(INDEX($J$45:$J$50,MATCH(B25,$I$45:$I$50,0)),0)) -> 8 | I25: 46177
A26: Dr. Paulo Andrade | B26: Quinta | C26: Tarde | D26: Sala 2 | E26: 0.58333333 | F26: 4 | G26: =IF(A26="","",IF(F26="",$B$10,F26)*IFERROR(INDEX($J$45:$J$50,MATCH(B26,$I$45:$I$50,0)),0)) -> 8 | I26: 46272
A27: Dr. Paulo Andrade | B27: Sexta | C27: Manhã | D27: Sala 2 | E27: 0.33333333 | F27: 4 | G27: =IF(A27="","",IF(F27="",$B$10,F27)*IFERROR(INDEX($J$45:$J$50,MATCH(B27,$I$45:$I$50,0)),0)) -> 8 | I27: 46307
A28: Dra. Renata Sousa | B28: Terça | C28: Tarde | D28: Sala 1 | E28: 0.58333333 | F28: 4 | G28: =IF(A28="","",IF(F28="",$B$10,F28)*IFERROR(INDEX($J$45:$J$50,MATCH(B28,$I$45:$I$50,0)),0)) -> 8 | I28: 46328
A29: Dra. Renata Sousa | B29: Quinta | C29: Tarde | D29: Sala 1 | E29: 0.58333333 | F29: 4 | G29: =IF(A29="","",IF(F29="",$B$10,F29)*IFERROR(INDEX($J$45:$J$50,MATCH(B29,$I$45:$I$50,0)),0)) -> 8 | I29: 46341
G30: =IF(A30="","",IF(F30="",$B$10,F30)*IFERROR(INDEX($J$45:$J$50,MATCH(B30,$I$45:$I$50,0)),0)) | I30: 46346
G31: =IF(A31="","",IF(F31="",$B$10,F31)*IFERROR(INDEX($J$45:$J$50,MATCH(B31,$I$45:$I$50,0)),0)) | I31: 46381
G32: =IF(A32="","",IF(F32="",$B$10,F32)*IFERROR(INDEX($J$45:$J$50,MATCH(B32,$I$45:$I$50,0)),0))
G33: =IF(A33="","",IF(F33="",$B$10,F33)*IFERROR(INDEX($J$45:$J$50,MATCH(B33,$I$45:$I$50,0)),0))
G34: =IF(A34="","",IF(F34="",$B$10,F34)*IFERROR(INDEX($J$45:$J$50,MATCH(B34,$I$45:$I$50,0)),0))
G35: =IF(A35="","",IF(F35="",$B$10,F35)*IFERROR(INDEX($J$45:$J$50,MATCH(B35,$I$45:$I$50,0)),0))
G36: =IF(A36="","",IF(F36="",$B$10,F36)*IFERROR(INDEX($J$45:$J$50,MATCH(B36,$I$45:$I$50,0)),0))
G37: =IF(A37="","",IF(F37="",$B$10,F37)*IFERROR(INDEX($J$45:$J$50,MATCH(B37,$I$45:$I$50,0)),0))
G38: =IF(A38="","",IF(F38="",$B$10,F38)*IFERROR(INDEX($J$45:$J$50,MATCH(B38,$I$45:$I$50,0)),0))
G39: =IF(A39="","",IF(F39="",$B$10,F39)*IFERROR(INDEX($J$45:$J$50,MATCH(B39,$I$45:$I$50,0)),0))
G40: =IF(A40="","",IF(F40="",$B$10,F40)*IFERROR(INDEX($J$45:$J$50,MATCH(B40,$I$45:$I$50,0)),0))
G41: =IF(A41="","",IF(F41="",$B$10,F41)*IFERROR(INDEX($J$45:$J$50,MATCH(B41,$I$45:$I$50,0)),0))
...

Sheet Pacientes
A1: Pacientes
A2: Uma linha por paciente: nome, pagador (particular ou convênio), profissional principal e contato. Só dados de gestão; nada clínico. As colunas brancas vêm da Agenda.
A4: Paciente | B4: Pagador | C4: Profissional principal | D4: Contato | E4: Observação | F4: Atendimentos realizados | G4: Faltas | H4: Último atendimento | I4: Próximo agendado
A5: Ana Costa | B5: Particular | C5: Dra. Carolina Mendes | D5: (11) 90000-0147 | F5: =IF(A5="","",COUNTIFS(Agenda!$E$5:$E$3004,A5,Agenda!$H$5:$H$3004,"Realizado")) -> 12 | G5: =IF(A5="","",COUNTIFS(Agenda!$E$5:$E$3004,A5,Agenda!$H$5:$H$3004,"Falta")) -> 0 | H5: =IF(A5="","",IF(SUMPRODUCT(MAX((Agenda!$E$5:$E$3004=A5)*(Agenda!$H$5:$H$3004="Realizado")*Agenda!$A$5:$A$3004))=0,"",SUMPRODUCT(MAX((Agenda!$E$5:$E$3004=A5)*(Agenda!$H$5:$H$3004="Realizado")*Agenda!$A$5:$A$3004)))) -> 46274 | I5: =IF(A5="","",IF(SUMPRODUCT(MIN(((Agenda!$E$5:$E$3004=A5)*((Agenda!$H$5:$H$3004="Agendado")+(Agenda!$H$5:$H$3004="Confirmado")))*Agenda!$A$5:$A$3004+(1-((Agenda!$E$5:$E$3004=A5)*((Agenda!$H$5:$H$3004="Agendado")+(Agenda!$H$5:$H$3004="Confirmado"))))*1E+10))>=1E+10,"",SUMPRODUCT(MIN(((Agenda!$E$5:$E$3004=A5)*((Agenda!$H$5:$H$3004="Agendado")+(Agenda!$H$5:$H$3004="Confirmado")))*Agenda!$A$5:$A$3004+(1-((Agenda!$E$5:$E$3004=A5)*((Agenda!$H$5:$H$3004="Agendado")+(Agenda!$H$5:$H$3004="Confirmado"))))*1E+10)))) -> 46281
A6: Beatriz Gomes | B6: Particular | C6: Dra. Renata Sousa | D6: (11) 90000-0254 | F6: =IF(A6="","",COUNTIFS(Agenda!$E$5:$E$3004,A6,Agenda!$H$5:$H$3004,"Realizado")) -> 1 | G6: =IF(A6="","",COUNTIFS(Agenda!$E$5:$E$3004,A6,Agenda!$H$5:$H$3004,"Falta")) -> 0 | H6: =IF(A6="","",IF(SUMPRODUCT(MAX((Agenda!$E$5:$E$3004=A6)*(Agenda!$H$5:$H$3004="Realizado")*Agenda!$A$5:$A$3004))=0,"",SUMPRODUCT(MAX((Agenda!$E$5:$E$3004=A6)*(Agenda!$H$5:$H$3004="Realizado")*Agenda!$A$5:$A$3004)))) -> 46273 | I6: =IF(A6="","",IF(SUMPRODUCT(MIN(((Agenda!$E$5:$E$3004=A6)*((Agenda!$H$5:$H$3004="Agendado")+(Agenda!$H$5:$H$3004="Confirmado")))*Agenda!$A$5:$A$3004+(1-((Agenda!$E$5:$E$3004=A6)*((Agenda!$H$5:$H$3004="Agendado")+(Agenda!$H$5:$H$3004="Confirmado"))))*1E+10))>=1E+10,"",SUMPRODUCT(MIN(((Agenda!$E$5:$E$3004=A6)*((Agenda!$H$5:$H$3004="Agendado")+(Agenda!$H$5:$H$3004="Confirmado")))*Agenda!$A$5:$A$3004+(1-((Agenda!$E$5:$E$3004=A6)*((Agenda!$H$5:$H$3004="Agendado")+(Agenda!$H$5:$H$3004="Confirmado"))))*1E+10)))) -> 46280
A7: Beatriz Gonçalves | B7: Saúde Total | C7: Dr. Paulo Andrade | D7: (11) 90000-0177 | F7: =IF(A7="","",COUNTIFS(Agenda!$E$5:$E$3004,A7,Agenda!$H$5:$H$3004,"Realizado")) -> 4 | G7: =IF(A7="","",COUNTIFS(Agenda!$E$5:$E$3004,A7,Agenda!$H$5:$H$3004,"Falta")) -> 0 | H7: =IF(A7="","",IF(SUMPRODUCT(MAX((Agenda!$E$5:$E$3004=A7)*(Agenda!$H$5:$H$3004="Realizado")*Agenda!$A$5:$A$3004))=0,"",SUMPRODUCT(MAX((Agenda!$E$5:$E$3004=A7)*(Agenda!$H$5:$H$3004="Realizado")*Agenda!$A$5:$A$3004)))) -> 46273 | I7: =IF(A7="","",IF(SUMPRODUCT(MIN(((Agenda!$E$5:$E$3004=A7)*((Agenda!$H$5:$H$3004="Agendado")+(Agenda!$H$5:$H$3004="Confirmado")))*Agenda!$A$5:$A$3004+(1-((Agenda!$E$5:$E$3004=A7)*((Agenda!$H$5:$H$3004="Agendado")+(Agenda!$H$5:$H$3004="Confirmado"))))*1E+10))>=1E+10,"",SUMPRODUCT(MIN(((Agenda!$E$5:$E$3004=A7)*((Agenda!$H$5:$H$3004="Agendado")+(Agenda!$H$5:$H$3004="Confirmado")))*Agenda!$A$5:$A$3004+(1-((Agenda!$E$5:$E$3004=A7)*((Agenda!$H$5:$H$3004="Agendado")+(Agenda!$H$5:$H$3004="Confirmado"))))*1E+10)))) -> 46287
A8: Beatriz Monteiro | B8: Particular | C8: Dra. Renata Sousa | D8: (11) 90000-0233 | F8: =IF(A8="","",COUNTIFS(Agenda!$E$5:$E$3004,A8,Agenda!$H$5:$H$3004,"Realizado")) -> 7 | G8: =IF(A8="","",COUNTIFS(Agenda!$E$5:$E$3004,A8,Agenda!$H$5:$H$3004,"Falta")) -> 0 | H8: =IF(A8="","",IF(SUMPRODUCT(MAX((Agenda!$E$5:$E$3004=A8)*(Agenda!$H$5:$H$3004="Realizado")*Agenda!$A$5:$A$3004))=0,"",SUMPRODUCT(MAX((Agenda!$E$5:$E$3004=A8)*(Agenda!$H$5:$H$3004="Realizado")*Agenda!$A$5:$A$3004)))) -> 46259 | I8: =IF(A8="","",IF(SUMPRODUCT(MIN(((Agenda!$E$5:$E$3004=A8)*((Agenda!$H$5:$H$3004="Agendado")+(Agenda!$H$5:$H$3004="Confirmado")))*Agenda!$A$5:$A$3004+(1-((Agenda!$E$5:$E$3004=A8)*((Agenda!$H$5:$H$3004="Agendado")+(Agenda!$H$5:$H$3004="Confirmado"))))*1E+10))>=1E+10,"",SUMPRODUCT(MIN(((Agenda!$E$5:$E$3004=A8)*((Agenda!$H$5:$H$3004="Agendado")+(Agenda!$H$5:$H$3004="Confirmado")))*Agenda!$A$5:$A$3004+(1-((Agenda!$E$5:$E$3004=A8)*((Agenda!$H$5:$H$3004="Agendado")+(Agenda!$H$5:$H$3004="Confirmado"))))*1E+10))))
A9: Beatriz Reis | B9: Particular | C9: Dra. Renata Sousa | D9: (11) 90000-0255 | F9: =IF(A9="","",COUNTIFS(Agenda!$E$5:$E$3004,A9,Agenda!$H$5:$H$3004,"Realizado")) -> 2 | G9: =IF(A9="","",COUNTIFS(Agenda!$E$5:$E$3004,A9,Agenda!$H$5:$H$3004,"Falta")) -> 0 | H9: =IF(A9="","",IF(SUMPRODUCT(MAX((Agenda!$E$5:$E$3004=A9)*(Agenda!$H$5:$H$3004="Realizado")*Agenda!$A$5:$A$3004))=0,"",SUMPRODUCT(MAX((Agenda!$E$5:$E$3004=A9)*(Agenda!$H$5:$H$3004="Realizado")*Agenda!$A$5:$A$3004)))) -> 46224 | I9: =IF(A9="","",IF(SUMPRODUCT(MIN(((Agenda!$E$5:$E$3004=A9)*((Agenda!$H$5:$H$3004="Agendado")+(Agenda!$H$5:$H$3004="Confirmado")))*Agenda!$A$5:$A$3004+(1-((Agenda!$E$5:$E$3004=A9)*((Agenda!$H$5:$H$3004="Agendado")+(Agenda!$H$5:$H$3004="Confirmado"))))*1E+10))>=1E+10,"",SUMPRODUCT(MIN(((Agenda!$E$5:$E$3004=A9)*((Agenda!$H$5:$H$3004="Agendado")+(Agenda!$H$5:$H$3004="Confirmado")))*Agenda!$A$5:$A$3004+(1-((Agenda!$E$5:$E$3004=A9)*((Agenda!$H$5:$H$3004="Agendado")+(Agenda!$H$5:$H$3004="Confirmado"))))*1E+10))))
A10: Bruno Carvalho | B10: Saúde Total | C10: Dr. Paulo Andrade | D10: (11) 90000-0213 | F10: =IF(A10="","",COUNTIFS(Agenda!$E$5:$E$3004,A10,Agenda!$H$5:$H$3004,"Realizado")) -> 3 | G10: =IF(A10="","",COUNTIFS(Agenda!$E$5:$E$3004,A10,Agenda!$H$5:$H$3004,"Falta")) -> 0 | H10: =IF(A10="","",IF(SUMPRODUCT(MAX((Agenda!$E$5:$E$3004=A10)*(Agenda!$H$5:$H$3004="Realizado")*Agenda!$A$5:$A$3004))=0,"",SUMPRODUCT(MAX((Agenda!$E$5:$E$3004=A10)*(Agenda!$H$5:$H$3004="Realizado")*Agenda!$A$5:$A$3004)))) -> 46261 | I10: =IF(A10="","",IF(SUMPRODUCT(MIN(((Agenda!$E$5:$E$3004=A10)*((Agenda!$H$5:$H$3004="Agendado")+(Agenda!$H$5:$H$3004="Confirmado")))*Agenda!$A$5:$A$3004+(1-((Agenda!$E$5:$E$3004=A10)*((Agenda!$H$5:$H$3004="Agendado")+(Agenda!$H$5:$H$3004="Confirmado"))))*1E+10))>=1E+10,"",SUMPRODUCT(MIN(((Agenda!$E$5:$E$3004=A10)*((Agenda!$H$5:$H$3004="Agendado")+(Agenda!$H$5:$H$3004="Confirmado")))*Agenda!$A$5:$A$3004+(1-((Agenda!$E$5:$E$3004=A10)*((Agenda!$H$5:$H$3004="Agendado")+(Agenda!$H$5:$H$3004="Confirmado"))))*1E+10)))) -> 46279
A11: Camila Batista | B11: MediPlan | C11: Dra. Carolina Mendes | D11: (11) 90000-0102 | F11: =IF(A11="","",COUNTIFS(Agenda!$E$5:$E$3004,A11,Agenda!$H$5:$H$3004,"Realizado")) -> 11 | G11: =IF(A11="","",COUNTIFS(Agenda!$E$5:$E$3004,A11,Agenda!$H$5:$H$3004,"Falta")) -> 2 | H11: =IF(A11="","",IF(SUMPRODUCT(MAX((Agenda!$E$5:$E$3004=A11)*(Agenda!$H$5:$H$3004="Realizado")*Agenda!$A$5:$A$3004))=0,"",SUMPRODUCT(MAX((Agenda!$E$5:$E$3004=A11)*(Agenda!$H$5:$H$3004="Realizado")*Agenda!$A$5:$A$3004)))) -> 46269 | I11: =IF(A11="","",IF(SUMPRODUCT(MIN(((Agenda!$E$5:$E$3004=A11)*((Agenda!$H$5:$H$3004="Agendado")+(Agenda!$H$5:$H$3004="Confirmado")))*Agenda!$A$5:$A$3004+(1-((Agenda!$E$5:$E$3004=A11)*((Agenda!$H$5:$H$3004="Agendado")+(Agenda!$H$5:$H$3004="Confirmado"))))*1E+10))>=1E+10,"",SUMPRODUCT(MIN(((Agenda!$E$5:$E$3004=A11)*((Agenda!$H$5:$H$3004="Agendado")+(Agenda!$H$5:$H$3004="Confirmado")))*Agenda!$A$5:$A$3004+(1-((Agenda!$E$5:$E$3004=A11)*((Agenda!$H$5:$H$3004="Agendado")+(Agenda!$H$5:$H$3004="Confirmado"))))*1E+10)))) -> 46279
A12: Camila Dias | B12: Particular | C12: Dra. Renata Sousa | D12: (11) 90000-0241 | F12: =IF(A12="","",COUNTIFS(Agenda!$E$5:$E$3004,A12,Agenda!$H$5:$H$3004,"Realizado")) -> 3 | G12: =IF(A12="","",COUNTIFS(Agenda!$E$5:$E$3004,A12,Agenda!$H$5:$H$3004,"Falta")) -> 0 | H12: =IF(A12="","",IF(SUMPRODUCT(MAX((Agenda!$E$5:$E$3004=A12)*(Agenda!$H$5:$H$3004="Realizado")*Agenda!$A$5:$A$3004))=0,"",SUMPRODUCT(MAX((Agenda!$E$5:$E$3004=A12)*(Agenda!$H$5:$H$3004="Realizado")*Agenda!$A$5:$A$3004)))) -> 46205 | I12: =IF(A12="","",IF(SUMPRODUCT(MIN(((Agenda!$E$5:$E$3004=A12)*((Agenda!$H$5:$H$3004="Agendado")+(Agenda!$H$5:$H$3004="Confirmado")))*Agenda!$A$5:$A$3004+(1-((Agenda!$E$5:$E$3004=A12)*((Agenda!$H$5:$H$3004="Agendado")+(Agenda!$H$5:$H$3004="Confirmado"))))*1E+10))>=1E+10,"",SUMPRODUCT(MIN(((Agenda!$E$5:$E$3004=A12)*((Agenda!$H$5:$H$3004="Agendado")+(Agenda!$H$5:$H$3004="Confirmado")))*Agenda!$A$5:$A$3004+(1-((Agenda!$E$5:$E$3004=A12)*((Agenda!$H$5:$H$3004="Agendado")+(Agenda!$H$5:$H$3004="Confirmado"))))*1E+10))))
A13: Camila Freitas | B13: Particular | C13: Dr. Paulo Andrade | D13: (11) 90000-0212 | F13: =IF(A13="","",COUNTIFS(Agenda!$E$5:$E$3004,A13,Agenda!$H$5:$H$3004,"Realizado")) -> 2 | G13: =IF(A13="","",COUNTIFS(Agenda!$E$5:$E$3004,A13,Agenda!$H$5:$H$3004,"Falta")) -> 0 | H13: =IF(A13="","",IF(SUMPRODUCT(MAX((Agenda!$E$5:$E$3004=A13)*(Agenda!$H$5:$H$3004="Realizado")*Agenda!$A$5:$A$3004))=0,"",SUMPRODUCT(MAX((Agenda!$E$5:$E$3004=A13)*(Agenda!$H$5:$H$3004="Realizado")*Agenda!$A$5:$A$3004)))) -> 46258 | I13: =IF(A13="","",IF(SUMPRODUCT(MIN(((Agenda!$E$5:$E$3004=A13)*((Agenda!$H$5:$H$3004="Agendado")+(Agenda!$H$5:$H$3004="Confirmado")))*Agenda!$A$5:$A$3004+(1-((Agenda!$E$5:$E$3004=A13)*((Agenda!$H$5:$H$3004="Agendado")+(Agenda!$H$5:$H$3004="Confirmado"))))*1E+10))>=1E+10,"",SUMPRODUCT(MIN(((Agenda!$E$5:$E$3004=A13)*((Agenda!$H$5:$H$3004="Agendado")+(Agenda!$H$5:$H$3004="Confirmado")))*Agenda!$A$5:$A$3004+(1-((Agenda!$E$5:$E$3004=A13)*((Agenda!$H$5:$H$3004="Agendado")+(Agenda!$H$5:$H$3004="Confirmado"))))*1E+10)))) -> 46289
A14: Camila Martins | B14: Vida Care | C14: Dr. Paulo Andrade | D14: (11) 90000-0201 | F14: =IF(A14="","",COUNTIFS(Agenda!$E$5:$E$3004,A14,Agenda!$H$5:$H$3004,"Realizado")) -> 7 | G14: =IF(A14="","",COUNTIFS(Agenda!$E$5:$E$3004,A14,Agenda!$H$5:$H$3004,"Falta")) -> 1 | H14: =IF(A14="","",IF(SUMPRODUCT(MAX((Agenda!$E$5:$E$3004=A14)*(Agenda!$H$5:$H$3004="Realizado")*Agenda!$A$5:$A$3004))=0,"",SUMPRODUCT(MAX((Agenda!$E$5:$E$3004=A14)*(Agenda!$H$5:$H$3004="Realizado")*Agenda!$A$5:$A$3004)))) -> 46269 | I14: =IF(A14="","",IF(SUMPRODUCT(MIN(((Agenda!$E$5:$E$3004=A14)*((Agenda!$H$5:$H$3004="Agendado")+(Agenda!$H$5:$H$3004="Confirmado")))*Agenda!$A$5:$A$3004+(1-((Agenda!$E$5:$E$3004=A14)*((Agenda!$H$5:$H$3004="Agendado")+(Agenda!$H$5:$H$3004="Confirmado"))))*1E+10))>=1E+10,"",SUMPRODUCT(MIN(((Agenda!$E$5:$E$3004=A14)*((Agenda!$H$5:$H$3004="Agendado")+(Agenda!$H$5:$H$3004="Confirmado")))*Agenda!$A$5:$A$3004+(1-((Agenda!$E$5:$E$3004=A14)*((Agenda!$H$5:$H$3004="Agendado")+(Agenda!$H$5:$H$3004="Confirmado"))))*1E+10)))) -> 46289
A15: Carlos Barros | B15: MediPlan | C15: Dra. Carolina Mendes | D15: (11) 90000-0131 | F15: =IF(A15="","",COUNTIFS(Agenda!$E$5:$E$3004,A15,Agenda!$H$5:$H$3004,"Realizado")) -> 5 | G15: =IF(A15="","",COUNTIFS(Agenda!$E$5:$E$3004,A15,Agenda!$H$5:$H$3004,"Falta")) -> 0 | H15: =IF(A15="","",IF(SUMPRODUCT(MAX((Agenda!$E$5:$E$3004=A15)*(Agenda!$H$5:$H$3004="Realizado")*Agenda!$A$5:$A$3004))=0,"",SUMPRODUCT(MAX((Agenda!$E$5:$E$3004=A15)*(Agenda!$H$5:$H$3004="Realizado")*Agenda!$A$5:$A$3004)))) -> 46273 | I15: =IF(A15="","",IF(SUMPRODUCT(MIN(((Agenda!$E$5:$E$3004=A15)*((Agenda!$H$5:$H$3004="Agendado")+(Agenda!$H$5:$H$3004="Confirmado")))*Agenda!$A$5:$A$3004+(1-((Agenda!$E$5:$E$3004=A15)*((Agenda!$H$5:$H$3004="Agendado")+(Agenda!$H$5:$H$3004="Confirmado"))))*1E+10))>=1E+10,"",SUMPRODUCT(MIN(((Agenda!$E$5:$E$3004=A15)*((Agenda!$H$5:$H$3004="Agendado")+(Agenda!$H$5:$H$3004="Confirmado")))*Agenda!$A$5:$A$3004+(1-((Agenda!$E$5:$E$3004=A15)*((Agenda!$H$5:$H$3004="Agendado")+(Agenda!$H$5:$H$3004="Confirmado"))))*1E+10)))) -> 46280
A16: Carlos Castro | B16: Saúde Total | C16: Dra. Carolina Mendes | D16: (11) 90000-0123 | F16: =IF(A16="","",COUNTIFS(Agenda!$E$5:$E$3004,A16,Agenda!$H$5:$H$3004,"Realizado")) -> 7 | G16: =IF(A16="","",COUNTIFS(Agenda!$E$5:$E$3004,A16,Agenda!$H$5:$H$3004,"Falta")) -> 1 | H16: =IF(A16="","",IF(SUMPRODUCT(MAX((Agenda!$E$5:$E$3004=A16)*(Agenda!$H$5:$H$3004="Realizado")*Agenda!$A$5:$A$3004))=0,"",SUMPRODUCT(MAX((Agenda!$E$5:$E$3004=A16)*(Agenda!$H$5:$H$3004="Realizado")*Agenda!$A$5:$A$3004)))) -> 46274 | I16: =IF(A16="","",IF(SUMPRODUCT(MIN(((Agenda!$E$5:$E$3004=A16)*((Agenda!$H$5:$H$3004="Agendado")+(Agenda!$H$5:$H$3004="Confirmado")))*Agenda!$A$5:$A$3004+(1-((Agenda!$E$5:$E$3004=A16)*((Agenda!$H$5:$H$3004="Agendado")+(Agenda!$H$5:$H$3004="Confirmado"))))*1E+10))>=1E+10,"",SUMPRODUCT(MIN(((Agenda!$E$5:$E$3004=A16)*((Agenda!$H$5:$H$3004="Agendado")+(Agenda!$H$5:$H$3004="Confirmado")))*Agenda!$A$5:$A$3004+(1-((Agenda!$E$5:$E$3004=A16)*((Agenda!$H$5:$H$3004="Agendado")+(Agenda!$H$5:$H$3004="Confirmado"))))*1E+10)))) -> 46289
... A160: Wagner Santos | B160: Particular | C160: Dra. Carolina Mendes | D160: (11) 90000-0151 | F160: =IF(A160="","",COUNTIFS(Agenda!$E$5:$E$3004,A160,Agenda!$H$5:$H$3004,"Realizado")) -> 8 | G160: =IF(A160="","",COUNTIFS(Agenda!$E$5:$E$3004,A160,Agenda!$H$5:$H$3004,"Falta")) -> 0 | H160: =IF(A160="","",IF(SUMPRODUCT(MAX((Agenda!$E$5:$E$3004=A160)*(Agenda!$H$5:$H$3004="Realizado")*Agenda!$A$5:$A$3004))=0,"",SUMPRODUCT(MAX((Agenda!$E$5:$E$3004=A160)*(Agenda!$H$5:$H$3004="Realizado")*Agenda!$A$5:$A$3004)))) -> 46245 | I160: =IF(A160="","",IF(SUMPRODUCT(MIN(((Agenda!$E$5:$E$3004=A160)*((Agenda!$H$5:$H$3004="Agendado")+(Agenda!$H$5:$H$3004="Confirmado")))*Agenda!$A$5:$A$3004+(1-((Agenda!$E$5:$E$3004=A160)*((Agenda!$H$5:$H$3004="Agendado")+(Agenda!$H$5:$H$3004="Confirmado"))))*1E+10))>=1E+10,"",SUMPRODUCT(MIN(((Agenda!$E$5:$E$3004=A160)*((Agenda!$H$5:$H$3004="Agendado")+(Agenda!$H$5:$H$3004="Confirmado")))*Agenda!$A$5:$A$3004+(1-((Agenda!$E$5:$E$3004=A160)*((Agenda!$H$5:$H$3004="Agendado")+(Agenda!$H$5:$H$3004="Confirmado"))))*1E+10)))) -> 46286
F161: =IF(A161="","",COUNTIFS(Agenda!$E$5:$E$3004,A161,Agenda!$H$5:$H$3004,"Realizado")) | G161: =IF(A161="","",COUNTIFS(Agenda!$E$5:$E$3004,A161,Agenda!$H$5:$H$3004,"Falta")) | H161: =IF(A161="","",IF(SUMPRODUCT(MAX((Agenda!$E$5:$E$3004=A161)*(Agenda!$H$5:$H$3004="Realizado")*Agenda!$A$5:$A$3004))=0,"",SUMPRODUCT(MAX((Agenda!$E$5:$E$3004=A161)*(Agenda!$H$5:$H$3004="Realizado")*Agenda!$A$5:$A$3004)))) | I161: =IF(A161="","",IF(SUMPRODUCT(MIN(((Agenda!$E$5:$E$3004=A161)*((Agenda!$H$5:$H$3004="Agendado")+(Agenda!$H$5:$H$3004="Confirmado")))*Agenda!$A$5:$A$3004+(1-((Agenda!$E$5:$E$3004=A161)*((Agenda!$H$5:$H$3004="Agendado")+(Agenda!$H$5:$H$3004="Confirmado"))))*1E+10))>=1E+10,"",SUMPRODUCT(MIN(((Agenda!$E$5:$E$3004=A161)*((Agenda!$H$5:$H$3004="Agendado")+(Agenda!$H$5:$H$3004="Confirmado")))*Agenda!$A$5:$A$3004+(1-((Agenda!$E$5:$E$3004=A161)*((Agenda!$H$5:$H$3004="Agendado")+(Agenda!$H$5:$H$3004="Confirmado"))))*1E+10))))
F162: =IF(A162="","",COUNTIFS(Agenda!$E$5:$E$3004,A162,Agenda!$H$5:$H$3004,"Realizado")) | G162: =IF(A162="","",COUNTIFS(Agenda!$E$5:$E$3004,A162,Agenda!$H$5:$H$3004,"Falta")) | H162: =IF(A162="","",IF(SUMPRODUCT(MAX((Agenda!$E$5:$E$3004=A162)*(Agenda!$H$5:$H$3004="Realizado")*Agenda!$A$5:$A$3004))=0,"",SUMPRODUCT(MAX((Agenda!$E$5:$E$3004=A162)*(Agenda!$H$5:$H$3004="Realizado")*Agenda!$A$5:$A$3004)))) | I162: =IF(A162="","",IF(SUMPRODUCT(MIN(((Agenda!$E$5:$E$3004=A162)*((Agenda!$H$5:$H$3004="Agendado")+(Agenda!$H$5:$H$3004="Confirmado")))*Agenda!$A$5:$A$3004+(1-((Agenda!$E$5:$E$3004=A162)*((Agenda!$H$5:$H$3004="Agendado")+(Agenda!$H$5:$H$3004="Confirmado"))))*1E+10))>=1E+10,"",SUMPRODUCT(MIN(((Agenda!$E$5:$E$3004=A162)*((Agenda!$H$5:$H$3004="Agendado")+(Agenda!$H$5:$H$3004="Confirmado")))*Agenda!$A$5:$A$3004+(1-((Agenda!$E$5:$E$3004=A162)*((Agenda!$H$5:$H$3004="Agendado")+(Agenda!$H$5:$H$3004="Confirmado"))))*1E+10))))
F163: =IF(A163="","",COUNTIFS(Agenda!$E$5:$E$3004,A163,Agenda!$H$5:$H$3004,"Realizado")) | G163: =IF(A163="","",COUNTIFS(Agenda!$E$5:$E$3004,A163,Agenda!$H$5:$H$3004,"Falta")) | H163: =IF(A163="","",IF(SUMPRODUCT(MAX((Agenda!$E$5:$E$3004=A163)*(Agenda!$H$5:$H$3004="Realizado")*Agenda!$A$5:$A$3004))=0,"",SUMPRODUCT(MAX((Agenda!$E$5:$E$3004=A163)*(Agenda!$H$5:$H$3004="Realizado")*Agenda!$A$5:$A$3004)))) | I163: =IF(A163="","",IF(SUMPRODUCT(MIN(((Agenda!$E$5:$E$3004=A163)*((Agenda!$H$5:$H$3004="Agendado")+(Agenda!$H$5:$H$3004="Confirmado")))*Agenda!$A$5:$A$3004+(1-((Agenda!$E$5:$E$3004=A163)*((Agenda!$H$5:$H$3004="Agendado")+(Agenda!$H$5:$H$3004="Confirmado"))))*1E+10))>=1E+10,"",SUMPRODUCT(MIN(((Agenda!$E$5:$E$3004=A163)*((Agenda!$H$5:$H$3004="Agendado")+(Agenda!$H$5:$H$3004="Confirmado")))*Agenda!$A$5:$A$3004+(1-((Agenda!$E$5:$E$3004=A163)*((Agenda!$H$5:$H$3004="Agendado")+(Agenda!$H$5:$H$3004="Confirmado"))))*1E+10))))
F164: =IF(A164="","",COUNTIFS(Agenda!$E$5:$E$3004,A164,Agenda!$H$5:$H$3004,"Realizado")) | G164: =IF(A164="","",COUNTIFS(Agenda!$E$5:$E$3004,A164,Agenda!$H$5:$H$3004,"Falta")) | H164: =IF(A164="","",IF(SUMPRODUCT(MAX((Agenda!$E$5:$E$3004=A164)*(Agenda!$H$5:$H$3004="Realizado")*Agenda!$A$5:$A$3004))=0,"",SUMPRODUCT(MAX((Agenda!$E$5:$E$3004=A164)*(Agenda!$H$5:$H$3004="Realizado")*Agenda!$A$5:$A$3004)))) | I164: =IF(A164="","",IF(SUMPRODUCT(MIN(((Agenda!$E$5:$E$3004=A164)*((Agenda!$H$5:$H$3004="Agendado")+(Agenda!$H$5:$H$3004="Confirmado")))*Agenda!$A$5:$A$3004+(1-((Agenda!$E$5:$E$3004=A164)*((Agenda!$H$5:$H$3004="Agendado")+(Agenda!$H$5:$H$3004="Confirmado"))))*1E+10))>=1E+10,"",SUMPRODUCT(MIN(((Agenda!$E$5:$E$3004=A164)*((Agenda!$H$5:$H$3004="Agendado")+(Agenda!$H$5:$H$3004="Confirmado")))*Agenda!$A$5:$A$3004+(1-((Agenda!$E$5:$E$3004=A164)*((Agenda!$H$5:$H$3004="Agendado")+(Agenda!$H$5:$H$3004="Confirmado"))))*1E+10))))
F165: =IF(A165="","",COUNTIFS(Agenda!$E$5:$E$3004,A165,Agenda!$H$5:$H$3004,"Realizado")) | G165: =IF(A165="","",COUNTIFS(Agenda!$E$5:$E$3004,A165,Agenda!$H$5:$H$3004,"Falta")) | H165: =IF(A165="","",IF(SUMPRODUCT(MAX((Agenda!$E$5:$E$3004=A165)*(Agenda!$H$5:$H$3004="Realizado")*Agenda!$A$5:$A$3004))=0,"",SUMPRODUCT(MAX((Agenda!$E$5:$E$3004=A165)*(Agenda!$H$5:$H$3004="Realizado")*Agenda!$A$5:$A$3004)))) | I165: =IF(A165="","",IF(SUMPRODUCT(MIN(((Agenda!$E$5:$E$3004=A165)*((Agenda!$H$5:$H$3004="Agendado")+(Agenda!$H$5:$H$3004="Confirmado")))*Agenda!$A$5:$A$3004+(1-((Agenda!$E$5:$E$3004=A165)*((Agenda!$H$5:$H$3004="Agendado")+(Agenda!$H$5:$H$3004="Confirmado"))))*1E+10))>=1E+10,"",SUMPRODUCT(MIN(((Agenda!$E$5:$E$3004=A165)*((Agenda!$H$5:$H$3004="Agendado")+(Agenda!$H$5:$H$3004="Confirmado")))*Agenda!$A$5:$A$3004+(1-((Agenda!$E$5:$E$3004=A165)*((Agenda!$H$5:$H$3004="Agendado")+(Agenda!$H$5:$H$3004="Confirmado"))))*1E+10))))
F166: =IF(A166="","",COUNTIFS(Agenda!$E$5:$E$3004,A166,Agenda!$H$5:$H$3004,"Realizado")) | G166: =IF(A166="","",COUNTIFS(Agenda!$E$5:$E$3004,A166,Agenda!$H$5:$H$3004,"Falta")) | H166: =IF(A166="","",IF(SUMPRODUCT(MAX((Agenda!$E$5:$E$3004=A166)*(Agenda!$H$5:$H$3004="Realizado")*Agenda!$A$5:$A$3004))=0,"",SUMPRODUCT(MAX((Agenda!$E$5:$E$3004=A166)*(Agenda!$H$5:$H$3004="Realizado")*Agenda!$A$5:$A$3004)))) | I166: =IF(A166="","",IF(SUMPRODUCT(MIN(((Agenda!$E$5:$E$3004=A166)*((Agenda!$H$5:$H$3004="Agendado")+(Agenda!$H$5:$H$3004="Confirmado")))*Agenda!$A$5:$A$3004+(1-((Agenda!$E$5:$E$3004=A166)*((Agenda!$H$5:$H$3004="Agendado")+(Agenda!$H$5:$H$3004="Confirmado"))))*1E+10))>=1E+10,"",SUMPRODUCT(MIN(((Agenda!$E$5:$E$3004=A166)*((Agenda!$H$5:$H$3004="Agendado")+(Agenda!$H$5:$H$3004="Confirmado")))*Agenda!$A$5:$A$3004+(1-((Agenda!$E$5:$E$3004=A166)*((Agenda!$H$5:$H$3004="Agendado")+(Agenda!$H$5:$H$3004="Confirmado"))))*1E+10))))
F167: =IF(A167="","",COUNTIFS(Agenda!$E$5:$E$3004,A167,Agenda!$H$5:$H$3004,"Realizado")) | G167: =IF(A167="","",COUNTIFS(Agenda!$E$5:$E$3004,A167,Agenda!$H$5:$H$3004,"Falta")) | H167: =IF(A167="","",IF(SUMPRODUCT(MAX((Agenda!$E$5:$E$3004=A167)*(Agenda!$H$5:$H$3004="Realizado")*Agenda!$A$5:$A$3004))=0,"",SUMPRODUCT(MAX((Agenda!$E$5:$E$3004=A167)*(Agenda!$H$5:$H$3004="Realizado")*Agenda!$A$5:$A$3004)))) | I167: =IF(A167="","",IF(SUMPRODUCT(MIN(((Agenda!$E$5:$E$3004=A167)*((Agenda!$H$5:$H$3004="Agendado")+(Agenda!$H$5:$H$3004="Confirmado")))*Agenda!$A$5:$A$3004+(1-((Agenda!$E$5:$E$3004=A167)*((Agenda!$H$5:$H$3004="Agendado")+(Agenda!$H$5:$H$3004="Confirmado"))))*1E+10))>=1E+10,"",SUMPRODUCT(MIN(((Agenda!$E$5:$E$3004=A167)*((Agenda!$H$5:$H$3004="Agendado")+(Agenda!$H$5:$H$3004="Confirmado")))*Agenda!$A$5:$A$3004+(1-((Agenda!$E$5:$E$3004=A167)*((Agenda!$H$5:$H$3004="Agendado")+(Agenda!$H$5:$H$3004="Confirmado"))))*1E+10))))
F168: =IF(A168="","",COUNTIFS(Agenda!$E$5:$E$3004,A168,Agenda!$H$5:$H$3004,"Realizado")) | G168: =IF(A168="","",COUNTIFS(Agenda!$E$5:$E$3004,A168,Agenda!$H$5:$H$3004,"Falta")) | H168: =IF(A168="","",IF(SUMPRODUCT(MAX((Agenda!$E$5:$E$3004=A168)*(Agenda!$H$5:$H$3004="Realizado")*Agenda!$A$5:$A$3004))=0,"",SUMPRODUCT(MAX((Agenda!$E$5:$E$3004=A168)*(Agenda!$H$5:$H$3004="Realizado")*Agenda!$A$5:$A$3004)))) | I168: =IF(A168="","",IF(SUMPRODUCT(MIN(((Agenda!$E$5:$E$3004=A168)*((Agenda!$H$5:$H$3004="Agendado")+(Agenda!$H$5:$H$3004="Confirmado")))*Agenda!$A$5:$A$3004+(1-((Agenda!$E$5:$E$3004=A168)*((Agenda!$H$5:$H$3004="Agendado")+(Agenda!$H$5:$H$3004="Confirmado"))))*1E+10))>=1E+10,"",SUMPRODUCT(MIN(((Agenda!$E$5:$E$3004=A168)*((Agenda!$H$5:$H$3004="Agendado")+(Agenda!$H$5:$H$3004="Confirmado")))*Agenda!$A$5:$A$3004+(1-((Agenda!$E$5:$E$3004=A168)*((Agenda!$H$5:$H$3004="Agendado")+(Agenda!$H$5:$H$3004="Confirmado"))))*1E+10))))
F169: =IF(A169="","",COUNTIFS(Agenda!$E$5:$E$3004,A169,Agenda!$H$5:$H$3004,"Realizado")) | G169: =IF(A169="","",COUNTIFS(Agenda!$E$5:$E$3004,A169,Agenda!$H$5:$H$3004,"Falta")) | H169: =IF(A169="","",IF(SUMPRODUCT(MAX((Agenda!$E$5:$E$3004=A169)*(Agenda!$H$5:$H$3004="Realizado")*Agenda!$A$5:$A$3004))=0,"",SUMPRODUCT(MAX((Agenda!$E$5:$E$3004=A169)*(Agenda!$H$5:$H$3004="Realizado")*Agenda!$A$5:$A$3004)))) | I169: =IF(A169="","",IF(SUMPRODUCT(MIN(((Agenda!$E$5:$E$3004=A169)*((Agenda!$H$5:$H$3004="Agendado")+(Agenda!$H$5:$H$3004="Confirmado")))*Agenda!$A$5:$A$3004+(1-((Agenda!$E$5:$E$3004=A169)*((Agenda!$H$5:$H$3004="Agendado")+(Agenda!$H$5:$H$3004="Confirmado"))))*1E+10))>=1E+10,"",SUMPRODUCT(MIN(((Agenda!$E$5:$E$3004=A169)*((Agenda!$H$5:$H$3004="Agendado")+(Agenda!$H$5:$H$3004="Confirmado")))*Agenda!$A$5:$A$3004+(1-((Agenda!$E$5:$E$3004=A169)*((Agenda!$H$5:$H$3004="Agendado")+(Agenda!$H$5:$H$3004="Confirmado"))))*1E+10))))
F170: =IF(A170="","",COUNTIFS(Agenda!$E$5:$E$3004,A170,Agenda!$H$5:$H$3004,"Realizado")) | G170: =IF(A170="","",COUNTIFS(Agenda!$E$5:$E$3004,A170,Agenda!$H$5:$H$3004,"Falta")) | H170: =IF(A170="","",IF(SUMPRODUCT(MAX((Agenda!$E$5:$E$3004=A170)*(Agenda!$H$5:$H$3004="Realizado")*Agenda!$A$5:$A$3004))=0,"",SUMPRODUCT(MAX((Agenda!$E$5:$E$3004=A170)*(Agenda!$H$5:$H$3004="Realizado")*Agenda!$A$5:$A$3004)))) | I170: =IF(A170="","",IF(SUMPRODUCT(MIN(((Agenda!$E$5:$E$3004=A170)*((Agenda!$H$5:$H$3004="Agendado")+(Agenda!$H$5:$H$3004="Confirmado")))*Agenda!$A$5:$A$3004+(1-((Agenda!$E$5:$E$3004=A170)*((Agenda!$H$5:$H$3004="Agendado")+(Agenda!$H$5:$H$3004="Confirmado"))))*1E+10))>=1E+10,"",SUMPRODUCT(MIN(((Agenda!$E$5:$E$3004=A170)*((Agenda!$H$5:$H$3004="Agendado")+(Agenda!$H$5:$H$3004="Confirmado")))*Agenda!$A$5:$A$3004+(1-((Agenda!$E$5:$E$3004=A170)*((Agenda!$H$5:$H$3004="Agendado")+(Agenda!$H$5:$H$3004="Confirmado"))))*1E+10))))
F171: =IF(A171="","",COUNTIFS(Agenda!$E$5:$E$3004,A171,Agenda!$H$5:$H$3004,"Realizado")) | G171: =IF(A171="","",COUNTIFS(Agenda!$E$5:$E$3004,A171,Agenda!$H$5:$H$3004,"Falta")) | H171: =IF(A171="","",IF(SUMPRODUCT(MAX((Agenda!$E$5:$E$3004=A171)*(Agenda!$H$5:$H$3004="Realizado")*Agenda!$A$5:$A$3004))=0,"",SUMPRODUCT(MAX((Agenda!$E$5:$E$3004=A171)*(Agenda!$H$5:$H$3004="Realizado")*Agenda!$A$5:$A$3004)))) | I171: =IF(A171="","",IF(SUMPRODUCT(MIN(((Agenda!$E$5:$E$3004=A171)*((Agenda!$H$5:$H$3004="Agendado")+(Agenda!$H$5:$H$3004="Confirmado")))*Agenda!$A$5:$A$3004+(1-((Agenda!$E$5:$E$3004=A171)*((Agenda!$H$5:$H$3004="Agendado")+(Agenda!$H$5:$H$3004="Confirmado"))))*1E+10))>=1E+10,"",SUMPRODUCT(MIN(((Agenda!$E$5:$E$3004=A171)*((Agenda!$H$5:$H$3004="Agendado")+(Agenda!$H$5:$H$3004="Confirmado")))*Agenda!$A$5:$A$3004+(1-((Agenda!$E$5:$E$3004=A171)*((Agenda!$H$5:$H$3004="Agendado")+(Agenda!$H$5:$H$3004="Confirmado"))))*1E+10))))
F172: =IF(A172="","",COUNTIFS(Agenda!$E$5:$E$3004,A172,Agenda!$H$5:$H$3004,"Realizado")) | G172: =IF(A172="","",COUNTIFS(Agenda!$E$5:$E$3004,A172,Agenda!$H$5:$H$3004,"Falta")) | H172: =IF(A172="","",IF(SUMPRODUCT(MAX((Agenda!$E$5:$E$3004=A172)*(Agenda!$H$5:$H$3004="Realizado")*Agenda!$A$5:$A$3004))=0,"",SUMPRODUCT(MAX((Agenda!$E$5:$E$3004=A172)*(Agenda!$H$5:$H$3004="Realizado")*Agenda!$A$5:$A$3004)))) | I172: =IF(A172="","",IF(SUMPRODUCT(MIN(((Agenda!$E$5:$E$3004=A172)*((Agenda!$H$5:$H$3004="Agendado")+(Agenda!$H$5:$H$3004="Confirmado")))*Agenda!$A$5:$A$3004+(1-((Agenda!$E$5:$E$3004=A172)*((Agenda!$H$5:$H$3004="Agendado")+(Agenda!$H$5:$H$3004="Confirmado"))))*1E+10))>=1E+10,"",SUMPRODUCT(MIN(((Agenda!$E$5:$E$3004=A172)*((Agenda!$H$5:$H$3004="Agendado")+(Agenda!$H$5:$H$3004="Confirmado")))*Agenda!$A$5:$A$3004+(1-((Agenda!$E$5:$E$3004=A172)*((Agenda!$H$5:$H$3004="Agendado")+(Agenda!$H$5:$H$3004="Confirmado"))))*1E+10))))
... F404: =IF(A404="","",COUNTIFS(Agenda!$E$5:$E$3004,A404,Agenda!$H$5:$H$3004,"Realizado")) | G404: =IF(A404="","",COUNTIFS(Agenda!$E$5:$E$3004,A404,Agenda!$H$5:$H$3004,"Falta")) | H404: =IF(A404="","",IF(SUMPRODUCT(MAX((Agenda!$E$5:$E$3004=A404)*(Agenda!$H$5:$H$3004="Realizado")*Agenda!$A$5:$A$3004))=0,"",SUMPRODUCT(MAX((Agenda!$E$5:$E$3004=A404)*(Agenda!$H$5:$H$3004="Realizado")*Agenda!$A$5:$A$3004)))) | I404: =IF(A404="","",IF(SUMPRODUCT(MIN(((Agenda!$E$5:$E$3004=A404)*((Agenda!$H$5:$H$3004="Agendado")+(Agenda!$H$5:$H$3004="Confirmado")))*Agenda!$A$5:$A$3004+(1-((Agenda!$E$5:$E$3004=A404)*((Agenda!$H$5:$H$3004="Agendado")+(Agenda!$H$5:$H$3004="Confirmado"))))*1E+10))>=1E+10,"",SUMPRODUCT(MIN(((Agenda!$E$5:$E$3004=A404)*((Agenda!$H$5:$H$3004="Agendado")+(Agenda!$H$5:$H$3004="Confirmado")))*Agenda!$A$5:$A$3004+(1-((Agenda!$E$5:$E$3004=A404)*((Agenda!$H$5:$H$3004="Agendado")+(Agenda!$H$5:$H$3004="Confirmado"))))*1E+10))))
A406: Esta aba é a fonte do cadastro de pacientes do kit: a planilha 14 (parcelas) copia os nomes daqui. Contato fictício no exemplo. Não guarde aqui nada além do necessário para agendar e cobrar.

Sheet Agenda
A1: Agenda
A2: Uma linha por horário marcado. Preencha o amarelo, inclusive minutos e valor (as duas últimas colunas sugerem o que a tabela de Config diz hoje); mês, dia da semana e período são calculados. Situação: Agendado, Confirmado, Realizado, Falta, Cancelado ou Remarcado. Esta aba é a fonte da agenda do kit (02 e 16 copiam daqui).
A4: Data | B4: Hora | C4: Profissional | D4: Sala | E4: Paciente | F4: Pagador | G4: Procedimento | H4: Situação | I4: Forma de pagamento | J4: Parcelas (cartão) | K4: Observação | L4: Minutos | M4: Valor (R$) | N4: Mês | O4: Ano | P4: Dia da semana | Q4: Período | R4: Horas atendidas | S4: Minutos pela tabela de hoje | T4: Valor pela tabela de hoje
