Workbook

Sheet Como usar
A1: Checklist de abertura e fechamento do dia
A2: Kit de Gestão para Médicos · Seu Sócio Gestor · versão 1.0 (setembro de 2026)
A4: O que esta planilha faz | B4: Para cada dia de atendimento, marca os itens administrativos que precisam estar em ordem na abertura (agenda confirmada, salas prontas, guias separadas, troco conferido) e no fechamento (caixa fechado e conferido, lançado no Caixa, situação de cada horário marcada, guias guardadas, retornos agendados). Calcula o % concluído por dia e mostra no Painel os dias com pendência e o item mais esquecido.
A5: Passo 1 | B5: Em Config, ajuste os itens de abertura e de fechamento ao jeito da clínica e cadastre os responsáveis. Preencha de cima para baixo, sem pular linha.
A6: Passo 2 | B6: Em Checklist, apague os exemplos e crie uma linha por dia (data e responsável). Em cada item, marque Sim, Não ou N/A. Vazio conta como pendente, de propósito: o dia só fecha quando tudo está marcado.
A7: Passo 3 | B7: Em Painel: aderência dos últimos 20 dias (abertura e fechamento completos), os dias com pendência e "Item mais esquecido": se o mesmo item pende em vários dias, o problema é a rotina, não o dia.
A8: Rotina | B8: É o roteiro diário da recepção, fora dos 30 minutos semanais dos sócios (planilha 03): abertura, 3 minutos antes do primeiro paciente; fechamento, 10 minutos depois do último — são 13 minutos por dia. O fechamento inclui lançar o caixa do dia na planilha 09; na sexta a sócia só confere os cinco fechamentos da semana (rotina de sexta da 03).
A9: Exemplo | B9: Dias úteis de 01/06 a 11/09/2026, preenchidos pela recepção. Sexta-feira 11/09 tem itens de fechamento em branco: é o que o Painel aponta na segunda.
A10: Com a IA | B10: Copie a coluna "O que faltou" de um dia e use o prompt "Agenda 06 · Pendências do dia viram tarefas da recepção" da biblioteca do kit.
A11: Legenda | B11: Células amarelas: você preenche. Brancas: calculadas. Não é preciso mexer em nada fora do amarelo.
A12: Proteção | B12: Fórmulas protegidas sem senha. Para editar: Revisar > Desproteger planilha (Excel) ou Dados > Proteger intervalos (Google Sheets).
A13: Requisitos | B13: Excel 2016 ou mais novo, Microsoft 365 ou Google Sheets (só funções do Excel 2007+; nada de MÍNIMOSES, MÁXIMOSES ou UNIRTEXTO). No celular abre nos aplicativos; para preencher, use o computador.
A14: Dados de pacientes | B14: Guarde só o que a gestão precisa (nome, contato, valor, data). Nada de diagnóstico, prontuário ou exame nestas planilhas: o kit é gestão, não é prontuário. Veja o guia LGPD do kit antes de colar qualquer tabela em uma IA.
A15: Google Sheets | B15: Faça upload no Google Drive e abra com o Google Sheets. Fórmulas, listas, cores, semáforos e gráficos funcionam: as regras de cor que dependem do mês escolhido em Config usam INDIRECT, que é a forma que o Sheets aceita para regra condicional apontar para outra aba.
... A18: Suporte | B18: suporte@seusociogestor.com.br · resposta em até 5 dias úteis · reembolso em até 7 dias pelo mesmo canal.

Sheet Painel
A1: =Config!$B$4&" · Abertura e fechamento do dia · "&TEXT(Config!$B$5,"dd/mm/yyyy") -> Clínica Vida Plena (exemplo fictício) · Abertura e fechamento do dia · 14/09/2026
A2: Nada para digitar aqui: tudo vem de Config e Checklist. Pendência = item de abertura ou de fechamento que não está marcado como Sim ou N/A.
A4: Dias registrados | C4: ="Abertura completa (últimos "&Config!$B$6&" dias)" -> Abertura completa (últimos 20 dias) | E4: ="Fechamento completo (últimos "&Config!$B$6&" dias)" -> Fechamento completo (últimos 20 dias) | G4: Dias com pendência | I4: Itens pendentes no total
A5: =COUNTIFS(Checklist!$A$5:$A$304,"<>") -> 73 | C5: =IFERROR(COUNTIFS(Checklist!$AB$5:$AB$304,"<="&Config!$B$6,Checklist!$AB$5:$AB$304,">0",Checklist!$V$5:$V$304,0)/MIN(Config!$B$6,COUNTIFS(Checklist!$A$5:$A$304,"<>")),"") -> 0.8 | E5: =IFERROR(COUNTIFS(Checklist!$AB$5:$AB$304,"<="&Config!$B$6,Checklist!$AB$5:$AB$304,">0",Checklist!$W$5:$W$304,0)/MIN(Config!$B$6,COUNTIFS(Checklist!$A$5:$A$304,"<>")),"") -> 0.55 | G5: =COUNTIFS(Checklist!$X$5:$X$304,">0") -> 32 | I5: =SUM(Checklist!$X$5:$X$304) -> 46
A7: Dias com pendência (mais itens pendentes primeiro; empate: o mais recente)
A8: Mostra os 12 primeiros; os demais ficam na aba Checklist, que pode ser filtrada pela coluna Pendências.
A9: # | B9: Data | C9: Dia | D9: Responsável | E9: % abertura | F9: % fechamento | G9: Pendências | H9: O que faltou
A10: 1 | B10: =IFERROR(IF(LARGE(Checklist!$Z$5:$Z$304,1)>0,IF(INDEX(Checklist!$A$5:$A$304,MATCH(LARGE(Checklist!$Z$5:$Z$304,1),Checklist!$Z$5:$Z$304,0))="","",INDEX(Checklist!$A$5:$A$304,MATCH(LARGE(Checklist!$Z$5:$Z$304,1),Checklist!$Z$5:$Z$304,0))),""),"") -> 46266 | C10: =IFERROR(IF(LARGE(Checklist!$Z$5:$Z$304,1)>0,IF(INDEX(Checklist!$B$5:$B$304,MATCH(LARGE(Checklist!$Z$5:$Z$304,1),Checklist!$Z$5:$Z$304,0))="","",INDEX(Checklist!$B$5:$B$304,MATCH(LARGE(Checklist!$Z$5:$Z$304,1),Checklist!$Z$5:$Z$304,0))),""),"") -> Terça | D10: =IFERROR(IF(LARGE(Checklist!$Z$5:$Z$304,1)>0,IF(INDEX(Checklist!$C$5:$C$304,MATCH(LARGE(Checklist!$Z$5:$Z$304,1),Checklist!$Z$5:$Z$304,0))="","",INDEX(Checklist!$C$5:$C$304,MATCH(LARGE(Checklist!$Z$5:$Z$304,1),Checklist!$Z$5:$Z$304,0))),""),"") -> Bruna Carvalho | E10: =IFERROR(IF(LARGE(Checklist!$Z$5:$Z$304,1)>0,IF(INDEX(Checklist!$T$5:$T$304,MATCH(LARGE(Checklist!$Z$5:$Z$304,1),Checklist!$Z$5:$Z$304,0))="","",INDEX(Checklist!$T$5:$T$304,MATCH(LARGE(Checklist!$Z$5:$Z$304,1),Checklist!$Z$5:$Z$304,0))),""),"") -> 1 | F10: =IFERROR(IF(LARGE(Checklist!$Z$5:$Z$304,1)>0,IF(INDEX(Checklist!$U$5:$U$304,MATCH(LARGE(Checklist!$Z$5:$Z$304,1),Checklist!$Z$5:$Z$304,0))="","",INDEX(Checklist!$U$5:$U$304,MATCH(LARGE(Checklist!$Z$5:$Z$304,1),Checklist!$Z$5:$Z$304,0))),""),"") -> 0.5 | G10: =IFERROR(IF(LARGE(Checklist!$Z$5:$Z$304,1)>0,IF(INDEX(Checklist!$X$5:$X$304,MATCH(LARGE(Checklist!$Z$5:$Z$304,1),Checklist!$Z$5:$Z$304,0))="","",INDEX(Checklist!$X$5:$X$304,MATCH(LARGE(Checklist!$Z$5:$Z$304,1),Checklist!$Z$5:$Z$304,0))),""),"") -> 3 | H10: =IFERROR(IF(LARGE(Checklist!$Z$5:$Z$304,1)>0,IF(INDEX(Checklist!$Y$5:$Y$304,MATCH(LARGE(Checklist!$Z$5:$Z$304,1),Checklist!$Z$5:$Z$304,0))="","",INDEX(Checklist!$Y$5:$Y$304,MATCH(LARGE(Checklist!$Z$5:$Z$304,1),Checklist!$Z$5:$Z$304,0))),""),"") -> Caixa do dia fechado e conferido (Pix, cartão, dinheiro); Fechamento do dia lançado no Caixa (09); Guias do dia conferidas e guardadas para o lote (13)
A11: 2 | B11: =IFERROR(IF(LARGE(Checklist!$Z$5:$Z$304,2)>0,IF(INDEX(Checklist!$A$5:$A$304,MATCH(LARGE(Checklist!$Z$5:$Z$304,2),Checklist!$Z$5:$Z$304,0))="","",INDEX(Checklist!$A$5:$A$304,MATCH(LARGE(Checklist!$Z$5:$Z$304,2),Checklist!$Z$5:$Z$304,0))),""),"") -> 46231 | C11: =IFERROR(IF(LARGE(Checklist!$Z$5:$Z$304,2)>0,IF(INDEX(Checklist!$B$5:$B$304,MATCH(LARGE(Checklist!$Z$5:$Z$304,2),Checklist!$Z$5:$Z$304,0))="","",INDEX(Checklist!$B$5:$B$304,MATCH(LARGE(Checklist!$Z$5:$Z$304,2),Checklist!$Z$5:$Z$304,0))),""),"") -> Terça | D11: =IFERROR(IF(LARGE(Checklist!$Z$5:$Z$304,2)>0,IF(INDEX(Checklist!$C$5:$C$304,MATCH(LARGE(Checklist!$Z$5:$Z$304,2),Checklist!$Z$5:$Z$304,0))="","",INDEX(Checklist!$C$5:$C$304,MATCH(LARGE(Checklist!$Z$5:$Z$304,2),Checklist!$Z$5:$Z$304,0))),""),"") -> Bruna Carvalho | E11: =IFERROR(IF(LARGE(Checklist!$Z$5:$Z$304,2)>0,IF(INDEX(Checklist!$T$5:$T$304,MATCH(LARGE(Checklist!$Z$5:$Z$304,2),Checklist!$Z$5:$Z$304,0))="","",INDEX(Checklist!$T$5:$T$304,MATCH(LARGE(Checklist!$Z$5:$Z$304,2),Checklist!$Z$5:$Z$304,0))),""),"") -> 0.8 | F11: =IFERROR(IF(LARGE(Checklist!$Z$5:$Z$304,2)>0,IF(INDEX(Checklist!$U$5:$U$304,MATCH(LARGE(Checklist!$Z$5:$Z$304,2),Checklist!$Z$5:$Z$304,0))="","",INDEX(Checklist!$U$5:$U$304,MATCH(LARGE(Checklist!$Z$5:$Z$304,2),Checklist!$Z$5:$Z$304,0))),""),"") -> 0.66666667 | G11: =IFERROR(IF(LARGE(Checklist!$Z$5:$Z$304,2)>0,IF(INDEX(Checklist!$X$5:$X$304,MATCH(LARGE(Checklist!$Z$5:$Z$304,2),Checklist!$Z$5:$Z$304,0))="","",INDEX(Checklist!$X$5:$X$304,MATCH(LARGE(Checklist!$Z$5:$Z$304,2),Checklist!$Z$5:$Z$304,0))),""),"") -> 3 | H11: =IFERROR(IF(LARGE(Checklist!$Z$5:$Z$304,2)>0,IF(INDEX(Checklist!$Y$5:$Y$304,MATCH(LARGE(Checklist!$Z$5:$Z$304,2),Checklist!$Z$5:$Z$304,0))="","",INDEX(Checklist!$Y$5:$Y$304,MATCH(LARGE(Checklist!$Z$5:$Z$304,2),Checklist!$Z$5:$Z$304,0))),""),"") -> Faltas e cancelamentos de ontem registrados na agenda; Caixa do dia fechado e conferido (Pix, cartão, dinheiro); Situação de cada horário marcada (realizado, falta, cancelado)
A12: 3 | B12: =IFERROR(IF(LARGE(Checklist!$Z$5:$Z$304,3)>0,IF(INDEX(Checklist!$A$5:$A$304,MATCH(LARGE(Checklist!$Z$5:$Z$304,3),Checklist!$Z$5:$Z$304,0))="","",INDEX(Checklist!$A$5:$A$304,MATCH(LARGE(Checklist!$Z$5:$Z$304,3),Checklist!$Z$5:$Z$304,0))),""),"") -> 46276 | C12: =IFERROR(IF(LARGE(Checklist!$Z$5:$Z$304,3)>0,IF(INDEX(Checklist!$B$5:$B$304,MATCH(LARGE(Checklist!$Z$5:$Z$304,3),Checklist!$Z$5:$Z$304,0))="","",INDEX(Checklist!$B$5:$B$304,MATCH(LARGE(Checklist!$Z$5:$Z$304,3),Checklist!$Z$5:$Z$304,0))),""),"") -> Sexta | D12: =IFERROR(IF(LARGE(Checklist!$Z$5:$Z$304,3)>0,IF(INDEX(Checklist!$C$5:$C$304,MATCH(LARGE(Checklist!$Z$5:$Z$304,3),Checklist!$Z$5:$Z$304,0))="","",INDEX(Checklist!$C$5:$C$304,MATCH(LARGE(Checklist!$Z$5:$Z$304,3),Checklist!$Z$5:$Z$304,0))),""),"") -> Bruna Carvalho | E12: =IFERROR(IF(LARGE(Checklist!$Z$5:$Z$304,3)>0,IF(INDEX(Checklist!$T$5:$T$304,MATCH(LARGE(Checklist!$Z$5:$Z$304,3),Checklist!$Z$5:$Z$304,0))="","",INDEX(Checklist!$T$5:$T$304,MATCH(LARGE(Checklist!$Z$5:$Z$304,3),Checklist!$Z$5:$Z$304,0))),""),"") -> 0.83333333 | F12: =IFERROR(IF(LARGE(Checklist!$Z$5:$Z$304,3)>0,IF(INDEX(Checklist!$U$5:$U$304,MATCH(LARGE(Checklist!$Z$5:$Z$304,3),Checklist!$Z$5:$Z$304,0))="","",INDEX(Checklist!$U$5:$U$304,MATCH(LARGE(Checklist!$Z$5:$Z$304,3),Checklist!$Z$5:$Z$304,0))),""),"") -> 0.83333333 | G12: =IFERROR(IF(LARGE(Checklist!$Z$5:$Z$304,3)>0,IF(INDEX(Checklist!$X$5:$X$304,MATCH(LARGE(Checklist!$Z$5:$Z$304,3),Checklist!$Z$5:$Z$304,0))="","",INDEX(Checklist!$X$5:$X$304,MATCH(LARGE(Checklist!$Z$5:$Z$304,3),Checklist!$Z$5:$Z$304,0))),""),"") -> 2 | H12: =IFERROR(IF(LARGE(Checklist!$Z$5:$Z$304,3)>0,IF(INDEX(Checklist!$Y$5:$Y$304,MATCH(LARGE(Checklist!$Z$5:$Z$304,3),Checklist!$Z$5:$Z$304,0))="","",INDEX(Checklist!$Y$5:$Y$304,MATCH(LARGE(Checklist!$Z$5:$Z$304,3),Checklist!$Z$5:$Z$304,0))),""),"") -> Troco e maquininha conferidos; Guias do dia conferidas e guardadas para o lote (13)
A13: 4 | B13: =IFERROR(IF(LARGE(Checklist!$Z$5:$Z$304,4)>0,IF(INDEX(Checklist!$A$5:$A$304,MATCH(LARGE(Checklist!$Z$5:$Z$304,4),Checklist!$Z$5:$Z$304,0))="","",INDEX(Checklist!$A$5:$A$304,MATCH(LARGE(Checklist!$Z$5:$Z$304,4),Checklist!$Z$5:$Z$304,0))),""),"") -> 46275 | C13: =IFERROR(IF(LARGE(Checklist!$Z$5:$Z$304,4)>0,IF(INDEX(Checklist!$B$5:$B$304,MATCH(LARGE(Checklist!$Z$5:$Z$304,4),Checklist!$Z$5:$Z$304,0))="","",INDEX(Checklist!$B$5:$B$304,MATCH(LARGE(Checklist!$Z$5:$Z$304,4),Checklist!$Z$5:$Z$304,0))),""),"") -> Quinta | D13: =IFERROR(IF(LARGE(Checklist!$Z$5:$Z$304,4)>0,IF(INDEX(Checklist!$C$5:$C$304,MATCH(LARGE(Checklist!$Z$5:$Z$304,4),Checklist!$Z$5:$Z$304,0))="","",INDEX(Checklist!$C$5:$C$304,MATCH(LARGE(Checklist!$Z$5:$Z$304,4),Checklist!$Z$5:$Z$304,0))),""),"") -> Bruna Carvalho | E13: =IFERROR(IF(LARGE(Checklist!$Z$5:$Z$304,4)>0,IF(INDEX(Checklist!$T$5:$T$304,MATCH(LARGE(Checklist!$Z$5:$Z$304,4),Checklist!$Z$5:$Z$304,0))="","",INDEX(Checklist!$T$5:$T$304,MATCH(LARGE(Checklist!$Z$5:$Z$304,4),Checklist!$Z$5:$Z$304,0))),""),"") -> 0.8 | F13: =IFERROR(IF(LARGE(Checklist!$Z$5:$Z$304,4)>0,IF(INDEX(Checklist!$U$5:$U$304,MATCH(LARGE(Checklist!$Z$5:$Z$304,4),Checklist!$Z$5:$Z$304,0))="","",INDEX(Checklist!$U$5:$U$304,MATCH(LARGE(Checklist!$Z$5:$Z$304,4),Checklist!$Z$5:$Z$304,0))),""),"") -> 0.83333333 | G13: =IFERROR(IF(LARGE(Checklist!$Z$5:$Z$304,4)>0,IF(INDEX(Checklist!$X$5:$X$304,MATCH(LARGE(Checklist!$Z$5:$Z$304,4),Checklist!$Z$5:$Z$304,0))="","",INDEX(Checklist!$X$5:$X$304,MATCH(LARGE(Checklist!$Z$5:$Z$304,4),Checklist!$Z$5:$Z$304,0))),""),"") -> 2 | H13: =IFERROR(IF(LARGE(Checklist!$Z$5:$Z$304,4)>0,IF(INDEX(Checklist!$Y$5:$Y$304,MATCH(LARGE(Checklist!$Z$5:$Z$304,4),Checklist!$Z$5:$Z$304,0))="","",INDEX(Checklist!$Y$5:$Y$304,MATCH(LARGE(Checklist!$Z$5:$Z$304,4),Checklist!$Z$5:$Z$304,0))),""),"") -> Guias e autorizações de convênio do dia separadas; Fechamento do dia lançado no Caixa (09)
A14: 5 | B14: =IFERROR(IF(LARGE(Checklist!$Z$5:$Z$304,5)>0,IF(INDEX(Checklist!$A$5:$A$304,MATCH(LARGE(Checklist!$Z$5:$Z$304,5),Checklist!$Z$5:$Z$304,0))="","",INDEX(Checklist!$A$5:$A$304,MATCH(LARGE(Checklist!$Z$5:$Z$304,5),Checklist!$Z$5:$Z$304,0))),""),"") -> 46268 | C14: =IFERROR(IF(LARGE(Checklist!$Z$5:$Z$304,5)>0,IF(INDEX(Checklist!$B$5:$B$304,MATCH(LARGE(Checklist!$Z$5:$Z$304,5),Checklist!$Z$5:$Z$304,0))="","",INDEX(Checklist!$B$5:$B$304,MATCH(LARGE(Checklist!$Z$5:$Z$304,5),Checklist!$Z$5:$Z$304,0))),""),"") -> Quinta | D14: =IFERROR(IF(LARGE(Checklist!$Z$5:$Z$304,5)>0,IF(INDEX(Checklist!$C$5:$C$304,MATCH(LARGE(Checklist!$Z$5:$Z$304,5),Checklist!$Z$5:$Z$304,0))="","",INDEX(Checklist!$C$5:$C$304,MATCH(LARGE(Checklist!$Z$5:$Z$304,5),Checklist!$Z$5:$Z$304,0))),""),"") -> Bruna Carvalho | E14: =IFERROR(IF(LARGE(Checklist!$Z$5:$Z$304,5)>0,IF(INDEX(Checklist!$T$5:$T$304,MATCH(LARGE(Checklist!$Z$5:$Z$304,5),Checklist!$Z$5:$Z$304,0))="","",INDEX(Checklist!$T$5:$T$304,MATCH(LARGE(Checklist!$Z$5:$Z$304,5),Checklist!$Z$5:$Z$304,0))),""),"") -> 0.8 | F14: =IFERROR(IF(LARGE(Checklist!$Z$5:$Z$304,5)>0,IF(INDEX(Checklist!$U$5:$U$304,MATCH(LARGE(Checklist!$Z$5:$Z$304,5),Checklist!$Z$5:$Z$304,0))="","",INDEX(Checklist!$U$5:$U$304,MATCH(LARGE(Checklist!$Z$5:$Z$304,5),Checklist!$Z$5:$Z$304,0))),""),"") -> 0.83333333 | G14: =IFERROR(IF(LARGE(Checklist!$Z$5:$Z$304,5)>0,IF(INDEX(Checklist!$X$5:$X$304,MATCH(LARGE(Checklist!$Z$5:$Z$304,5),Checklist!$Z$5:$Z$304,0))="","",INDEX(Checklist!$X$5:$X$304,MATCH(LARGE(Checklist!$Z$5:$Z$304,5),Checklist!$Z$5:$Z$304,0))),""),"") -> 2 | H14: =IFERROR(IF(LARGE(Checklist!$Z$5:$Z$304,5)>0,IF(INDEX(Checklist!$Y$5:$Y$304,MATCH(LARGE(Checklist!$Z$5:$Z$304,5),Checklist!$Z$5:$Z$304,0))="","",INDEX(Checklist!$Y$5:$Y$304,MATCH(LARGE(Checklist!$Z$5:$Z$304,5),Checklist!$Z$5:$Z$304,0))),""),"") -> Faltas e cancelamentos de ontem registrados na agenda; Agenda de amanhã revisada e confirmações enviadas
A15: 6 | B15: =IFERROR(IF(LARGE(Checklist!$Z$5:$Z$304,6)>0,IF(INDEX(Checklist!$A$5:$A$304,MATCH(LARGE(Checklist!$Z$5:$Z$304,6),Checklist!$Z$5:$Z$304,0))="","",INDEX(Checklist!$A$5:$A$304,MATCH(LARGE(Checklist!$Z$5:$Z$304,6),Checklist!$Z$5:$Z$304,0))),""),"") -> 46258 | C15: =IFERROR(IF(LARGE(Checklist!$Z$5:$Z$304,6)>0,IF(INDEX(Checklist!$B$5:$B$304,MATCH(LARGE(Checklist!$Z$5:$Z$304,6),Checklist!$Z$5:$Z$304,0))="","",INDEX(Checklist!$B$5:$B$304,MATCH(LARGE(Checklist!$Z$5:$Z$304,6),Checklist!$Z$5:$Z$304,0))),""),"") -> Segunda | D15: =IFERROR(IF(LARGE(Checklist!$Z$5:$Z$304,6)>0,IF(INDEX(Checklist!$C$5:$C$304,MATCH(LARGE(Checklist!$Z$5:$Z$304,6),Checklist!$Z$5:$Z$304,0))="","",INDEX(Checklist!$C$5:$C$304,MATCH(LARGE(Checklist!$Z$5:$Z$304,6),Checklist!$Z$5:$Z$304,0))),""),"") -> Bruna Carvalho | E15: =IFERROR(IF(LARGE(Checklist!$Z$5:$Z$304,6)>0,IF(INDEX(Checklist!$T$5:$T$304,MATCH(LARGE(Checklist!$Z$5:$Z$304,6),Checklist!$Z$5:$Z$304,0))="","",INDEX(Checklist!$T$5:$T$304,MATCH(LARGE(Checklist!$Z$5:$Z$304,6),Checklist!$Z$5:$Z$304,0))),""),"") -> 1 | F15: =IFERROR(IF(LARGE(Checklist!$Z$5:$Z$304,6)>0,IF(INDEX(Checklist!$U$5:$U$304,MATCH(LARGE(Checklist!$Z$5:$Z$304,6),Checklist!$Z$5:$Z$304,0))="","",INDEX(Checklist!$U$5:$U$304,MATCH(LARGE(Checklist!$Z$5:$Z$304,6),Checklist!$Z$5:$Z$304,0))),""),"") -> 0.66666667 | G15: =IFERROR(IF(LARGE(Checklist!$Z$5:$Z$304,6)>0,IF(INDEX(Checklist!$X$5:$X$304,MATCH(LARGE(Checklist!$Z$5:$Z$304,6),Checklist!$Z$5:$Z$304,0))="","",INDEX(Checklist!$X$5:$X$304,MATCH(LARGE(Checklist!$Z$5:$Z$304,6),Checklist!$Z$5:$Z$304,0))),""),"") -> 2 | H15: =IFERROR(IF(LARGE(Checklist!$Z$5:$Z$304,6)>0,IF(INDEX(Checklist!$Y$5:$Y$304,MATCH(LARGE(Checklist!$Z$5:$Z$304,6),Checklist!$Z$5:$Z$304,0))="","",INDEX(Checklist!$Y$5:$Y$304,MATCH(LARGE(Checklist!$Z$5:$Z$304,6),Checklist!$Z$5:$Z$304,0))),""),"") -> Fechamento do dia lançado no Caixa (09); Situação de cada horário marcada (realizado, falta, cancelado)
A16: 7 | B16: =IFERROR(IF(LARGE(Checklist!$Z$5:$Z$304,7)>0,IF(INDEX(Checklist!$A$5:$A$304,MATCH(LARGE(Checklist!$Z$5:$Z$304,7),Checklist!$Z$5:$Z$304,0))="","",INDEX(Checklist!$A$5:$A$304,MATCH(LARGE(Checklist!$Z$5:$Z$304,7),Checklist!$Z$5:$Z$304,0))),""),"") -> 46255 | C16: =IFERROR(IF(LARGE(Checklist!$Z$5:$Z$304,7)>0,IF(INDEX(Checklist!$B$5:$B$304,MATCH(LARGE(Checklist!$Z$5:$Z$304,7),Checklist!$Z$5:$Z$304,0))="","",INDEX(Checklist!$B$5:$B$304,MATCH(LARGE(Checklist!$Z$5:$Z$304,7),Checklist!$Z$5:$Z$304,0))),""),"") -> Sexta | D16: =IFERROR(IF(LARGE(Checklist!$Z$5:$Z$304,7)>0,IF(INDEX(Checklist!$C$5:$C$304,MATCH(LARGE(Checklist!$Z$5:$Z$304,7),Checklist!$Z$5:$Z$304,0))="","",INDEX(Checklist!$C$5:$C$304,MATCH(LARGE(Checklist!$Z$5:$Z$304,7),Checklist!$Z$5:$Z$304,0))),""),"") -> Bruna Carvalho | E16: =IFERROR(IF(LARGE(Checklist!$Z$5:$Z$304,7)>0,IF(INDEX(Checklist!$T$5:$T$304,MATCH(LARGE(Checklist!$Z$5:$Z$304,7),Checklist!$Z$5:$Z$304,0))="","",INDEX(Checklist!$T$5:$T$304,MATCH(LARGE(Checklist!$Z$5:$Z$304,7),Checklist!$Z$5:$Z$304,0))),""),"") -> 0.83333333 | F16: =IFERROR(IF(LARGE(Checklist!$Z$5:$Z$304,7)>0,IF(INDEX(Checklist!$U$5:$U$304,MATCH(LARGE(Checklist!$Z$5:$Z$304,7),Checklist!$Z$5:$Z$304,0))="","",INDEX(Checklist!$U$5:$U$304,MATCH(LARGE(Checklist!$Z$5:$Z$304,7),Checklist!$Z$5:$Z$304,0))),""),"") -> 0.83333333 | G16: =IFERROR(IF(LARGE(Checklist!$Z$5:$Z$304,7)>0,IF(INDEX(Checklist!$X$5:$X$304,MATCH(LARGE(Checklist!$Z$5:$Z$304,7),Checklist!$Z$5:$Z$304,0))="","",INDEX(Checklist!$X$5:$X$304,MATCH(LARGE(Checklist!$Z$5:$Z$304,7),Checklist!$Z$5:$Z$304,0))),""),"") -> 2 | H16: =IFERROR(IF(LARGE(Checklist!$Z$5:$Z$304,7)>0,IF(INDEX(Checklist!$Y$5:$Y$304,MATCH(LARGE(Checklist!$Z$5:$Z$304,7),Checklist!$Z$5:$Z$304,0))="","",INDEX(Checklist!$Y$5:$Y$304,MATCH(LARGE(Checklist!$Z$5:$Z$304,7),Checklist!$Z$5:$Z$304,0))),""),"") -> Faltas e cancelamentos de ontem registrados na agenda; Fechamento do dia lançado no Caixa (09)
A17: 8 | B17: =IFERROR(IF(LARGE(Checklist!$Z$5:$Z$304,8)>0,IF(INDEX(Checklist!$A$5:$A$304,MATCH(LARGE(Checklist!$Z$5:$Z$304,8),Checklist!$Z$5:$Z$304,0))="","",INDEX(Checklist!$A$5:$A$304,MATCH(LARGE(Checklist!$Z$5:$Z$304,8),Checklist!$Z$5:$Z$304,0))),""),"") -> 46239 | C17: =IFERROR(IF(LARGE(Checklist!$Z$5:$Z$304,8)>0,IF(INDEX(Checklist!$B$5:$B$304,MATCH(LARGE(Checklist!$Z$5:$Z$304,8),Checklist!$Z$5:$Z$304,0))="","",INDEX(Checklist!$B$5:$B$304,MATCH(LARGE(Checklist!$Z$5:$Z$304,8),Checklist!$Z$5:$Z$304,0))),""),"") -> Quarta | D17: =IFERROR(IF(LARGE(Checklist!$Z$5:$Z$304,8)>0,IF(INDEX(Checklist!$C$5:$C$304,MATCH(LARGE(Checklist!$Z$5:$Z$304,8),Checklist!$Z$5:$Z$304,0))="","",INDEX(Checklist!$C$5:$C$304,MATCH(LARGE(Checklist!$Z$5:$Z$304,8),Checklist!$Z$5:$Z$304,0))),""),"") -> Bruna Carvalho | E17: =IFERROR(IF(LARGE(Checklist!$Z$5:$Z$304,8)>0,IF(INDEX(Checklist!$T$5:$T$304,MATCH(LARGE(Checklist!$Z$5:$Z$304,8),Checklist!$Z$5:$Z$304,0))="","",INDEX(Checklist!$T$5:$T$304,MATCH(LARGE(Checklist!$Z$5:$Z$304,8),Checklist!$Z$5:$Z$304,0))),""),"") -> 1 | F17: =IFERROR(IF(LARGE(Checklist!$Z$5:$Z$304,8)>0,IF(INDEX(Checklist!$U$5:$U$304,MATCH(LARGE(Checklist!$Z$5:$Z$304,8),Checklist!$Z$5:$Z$304,0))="","",INDEX(Checklist!$U$5:$U$304,MATCH(LARGE(Checklist!$Z$5:$Z$304,8),Checklist!$Z$5:$Z$304,0))),""),"") -> 0.66666667 | G17: =IFERROR(IF(LARGE(Checklist!$Z$5:$Z$304,8)>0,IF(INDEX(Checklist!$X$5:$X$304,MATCH(LARGE(Checklist!$Z$5:$Z$304,8),Checklist!$Z$5:$Z$304,0))="","",INDEX(Checklist!$X$5:$X$304,MATCH(LARGE(Checklist!$Z$5:$Z$304,8),Checklist!$Z$5:$Z$304,0))),""),"") -> 2 | H17: =IFERROR(IF(LARGE(Checklist!$Z$5:$Z$304,8)>0,IF(INDEX(Checklist!$Y$5:$Y$304,MATCH(LARGE(Checklist!$Z$5:$Z$304,8),Checklist!$Z$5:$Z$304,0))="","",INDEX(Checklist!$Y$5:$Y$304,MATCH(LARGE(Checklist!$Z$5:$Z$304,8),Checklist!$Z$5:$Z$304,0))),""),"") -> Caixa do dia fechado e conferido (Pix, cartão, dinheiro); Retornos e exames do dia agendados
A18: 9 | B18: =IFERROR(IF(LARGE(Checklist!$Z$5:$Z$304,9)>0,IF(INDEX(Checklist!$A$5:$A$304,MATCH(LARGE(Checklist!$Z$5:$Z$304,9),Checklist!$Z$5:$Z$304,0))="","",INDEX(Checklist!$A$5:$A$304,MATCH(LARGE(Checklist!$Z$5:$Z$304,9),Checklist!$Z$5:$Z$304,0))),""),"") -> 46223 | C18: =IFERROR(IF(LARGE(Checklist!$Z$5:$Z$304,9)>0,IF(INDEX(Checklist!$B$5:$B$304,MATCH(LARGE(Checklist!$Z$5:$Z$304,9),Checklist!$Z$5:$Z$304,0))="","",INDEX(Checklist!$B$5:$B$304,MATCH(LARGE(Checklist!$Z$5:$Z$304,9),Checklist!$Z$5:$Z$304,0))),""),"") -> Segunda | D18: =IFERROR(IF(LARGE(Checklist!$Z$5:$Z$304,9)>0,IF(INDEX(Checklist!$C$5:$C$304,MATCH(LARGE(Checklist!$Z$5:$Z$304,9),Checklist!$Z$5:$Z$304,0))="","",INDEX(Checklist!$C$5:$C$304,MATCH(LARGE(Checklist!$Z$5:$Z$304,9),Checklist!$Z$5:$Z$304,0))),""),"") -> Bruna Carvalho | E18: =IFERROR(IF(LARGE(Checklist!$Z$5:$Z$304,9)>0,IF(INDEX(Checklist!$T$5:$T$304,MATCH(LARGE(Checklist!$Z$5:$Z$304,9),Checklist!$Z$5:$Z$304,0))="","",INDEX(Checklist!$T$5:$T$304,MATCH(LARGE(Checklist!$Z$5:$Z$304,9),Checklist!$Z$5:$Z$304,0))),""),"") -> 1 | F18: =IFERROR(IF(LARGE(Checklist!$Z$5:$Z$304,9)>0,IF(INDEX(Checklist!$U$5:$U$304,MATCH(LARGE(Checklist!$Z$5:$Z$304,9),Checklist!$Z$5:$Z$304,0))="","",INDEX(Checklist!$U$5:$U$304,MATCH(LARGE(Checklist!$Z$5:$Z$304,9),Checklist!$Z$5:$Z$304,0))),""),"") -> 0.66666667 | G18: =IFERROR(IF(LARGE(Checklist!$Z$5:$Z$304,9)>0,IF(INDEX(Checklist!$X$5:$X$304,MATCH(LARGE(Checklist!$Z$5:$Z$304,9),Checklist!$Z$5:$Z$304,0))="","",INDEX(Checklist!$X$5:$X$304,MATCH(LARGE(Checklist!$Z$5:$Z$304,9),Checklist!$Z$5:$Z$304,0))),""),"") -> 2 | H18: =IFERROR(IF(LARGE(Checklist!$Z$5:$Z$304,9)>0,IF(INDEX(Checklist!$Y$5:$Y$304,MATCH(LARGE(Checklist!$Z$5:$Z$304,9),Checklist!$Z$5:$Z$304,0))="","",INDEX(Checklist!$Y$5:$Y$304,MATCH(LARGE(Checklist!$Z$5:$Z$304,9),Checklist!$Z$5:$Z$304,0))),""),"") -> Caixa do dia fechado e conferido (Pix, cartão, dinheiro); Situação de cada horário marcada (realizado, falta, cancelado)
A19: 10 | B19: =IFERROR(IF(LARGE(Checklist!$Z$5:$Z$304,10)>0,IF(INDEX(Checklist!$A$5:$A$304,MATCH(LARGE(Checklist!$Z$5:$Z$304,10),Checklist!$Z$5:$Z$304,0))="","",INDEX(Checklist!$A$5:$A$304,MATCH(LARGE(Checklist!$Z$5:$Z$304,10),Checklist!$Z$5:$Z$304,0))),""),"") -> 46210 | C19: =IFERROR(IF(LARGE(Checklist!$Z$5:$Z$304,10)>0,IF(INDEX(Checklist!$B$5:$B$304,MATCH(LARGE(Checklist!$Z$5:$Z$304,10),Checklist!$Z$5:$Z$304,0))="","",INDEX(Checklist!$B$5:$B$304,MATCH(LARGE(Checklist!$Z$5:$Z$304,10),Checklist!$Z$5:$Z$304,0))),""),"") -> Terça | D19: =IFERROR(IF(LARGE(Checklist!$Z$5:$Z$304,10)>0,IF(INDEX(Checklist!$C$5:$C$304,MATCH(LARGE(Checklist!$Z$5:$Z$304,10),Checklist!$Z$5:$Z$304,0))="","",INDEX(Checklist!$C$5:$C$304,MATCH(LARGE(Checklist!$Z$5:$Z$304,10),Checklist!$Z$5:$Z$304,0))),""),"") -> Bruna Carvalho | E19: =IFERROR(IF(LARGE(Checklist!$Z$5:$Z$304,10)>0,IF(INDEX(Checklist!$T$5:$T$304,MATCH(LARGE(Checklist!$Z$5:$Z$304,10),Checklist!$Z$5:$Z$304,0))="","",INDEX(Checklist!$T$5:$T$304,MATCH(LARGE(Checklist!$Z$5:$Z$304,10),Checklist!$Z$5:$Z$304,0))),""),"") -> 0.8 | F19: =IFERROR(IF(LARGE(Checklist!$Z$5:$Z$304,10)>0,IF(INDEX(Checklist!$U$5:$U$304,MATCH(LARGE(Checklist!$Z$5:$Z$304,10),Checklist!$Z$5:$Z$304,0))="","",INDEX(Checklist!$U$5:$U$304,MATCH(LARGE(Checklist!$Z$5:$Z$304,10),Checklist!$Z$5:$Z$304,0))),""),"") -> 0.83333333 | G19: =IFERROR(IF(LARGE(Checklist!$Z$5:$Z$304,10)>0,IF(INDEX(Checklist!$X$5:$X$304,MATCH(LARGE(Checklist!$Z$5:$Z$304,10),Checklist!$Z$5:$Z$304,0))="","",INDEX(Checklist!$X$5:$X$304,MATCH(LARGE(Checklist!$Z$5:$Z$304,10),Checklist!$Z$5:$Z$304,0))),""),"") -> 2 | H19: =IFERROR(IF(LARGE(Checklist!$Z$5:$Z$304,10)>0,IF(INDEX(Checklist!$Y$5:$Y$304,MATCH(LARGE(Checklist!$Z$5:$Z$304,10),Checklist!$Z$5:$Z$304,0))="","",INDEX(Checklist!$Y$5:$Y$304,MATCH(LARGE(Checklist!$Z$5:$Z$304,10),Checklist!$Z$5:$Z$304,0))),""),"") -> Troco e maquininha conferidos; Caixa do dia fechado e conferido (Pix, cartão, dinheiro)
A20: 11 | B20: =IFERROR(IF(LARGE(Checklist!$Z$5:$Z$304,11)>0,IF(INDEX(Checklist!$A$5:$A$304,MATCH(LARGE(Checklist!$Z$5:$Z$304,11),Checklist!$Z$5:$Z$304,0))="","",INDEX(Checklist!$A$5:$A$304,MATCH(LARGE(Checklist!$Z$5:$Z$304,11),Checklist!$Z$5:$Z$304,0))),""),"") -> 46198 | C20: =IFERROR(IF(LARGE(Checklist!$Z$5:$Z$304,11)>0,IF(INDEX(Checklist!$B$5:$B$304,MATCH(LARGE(Checklist!$Z$5:$Z$304,11),Checklist!$Z$5:$Z$304,0))="","",INDEX(Checklist!$B$5:$B$304,MATCH(LARGE(Checklist!$Z$5:$Z$304,11),Checklist!$Z$5:$Z$304,0))),""),"") -> Quinta | D20: =IFERROR(IF(LARGE(Checklist!$Z$5:$Z$304,11)>0,IF(INDEX(Checklist!$C$5:$C$304,MATCH(LARGE(Checklist!$Z$5:$Z$304,11),Checklist!$Z$5:$Z$304,0))="","",INDEX(Checklist!$C$5:$C$304,MATCH(LARGE(Checklist!$Z$5:$Z$304,11),Checklist!$Z$5:$Z$304,0))),""),"") -> Bruna Carvalho | E20: =IFERROR(IF(LARGE(Checklist!$Z$5:$Z$304,11)>0,IF(INDEX(Checklist!$T$5:$T$304,MATCH(LARGE(Checklist!$Z$5:$Z$304,11),Checklist!$Z$5:$Z$304,0))="","",INDEX(Checklist!$T$5:$T$304,MATCH(LARGE(Checklist!$Z$5:$Z$304,11),Checklist!$Z$5:$Z$304,0))),""),"") -> 0.8 | F20: =IFERROR(IF(LARGE(Checklist!$Z$5:$Z$304,11)>0,IF(INDEX(Checklist!$U$5:$U$304,MATCH(LARGE(Checklist!$Z$5:$Z$304,11),Checklist!$Z$5:$Z$304,0))="","",INDEX(Checklist!$U$5:$U$304,MATCH(LARGE(Checklist!$Z$5:$Z$304,11),Checklist!$Z$5:$Z$304,0))),""),"") -> 0.83333333 | G20: =IFERROR(IF(LARGE(Checklist!$Z$5:$Z$304,11)>0,IF(INDEX(Checklist!$X$5:$X$304,MATCH(LARGE(Checklist!$Z$5:$Z$304,11),Checklist!$Z$5:$Z$304,0))="","",INDEX(Checklist!$X$5:$X$304,MATCH(LARGE(Checklist!$Z$5:$Z$304,11),Checklist!$Z$5:$Z$304,0))),""),"") -> 2 | H20: =IFERROR(IF(LARGE(Checklist!$Z$5:$Z$304,11)>0,IF(INDEX(Checklist!$Y$5:$Y$304,MATCH(LARGE(Checklist!$Z$5:$Z$304,11),Checklist!$Z$5:$Z$304,0))="","",INDEX(Checklist!$Y$5:$Y$304,MATCH(LARGE(Checklist!$Z$5:$Z$304,11),Checklist!$Z$5:$Z$304,0))),""),"") -> Troco e maquininha conferidos; Caixa do dia fechado e conferido (Pix, cartão, dinheiro)
A21: 12 | B21: =IFERROR(IF(LARGE(Checklist!$Z$5:$Z$304,12)>0,IF(INDEX(Checklist!$A$5:$A$304,MATCH(LARGE(Checklist!$Z$5:$Z$304,12),Checklist!$Z$5:$Z$304,0))="","",INDEX(Checklist!$A$5:$A$304,MATCH(LARGE(Checklist!$Z$5:$Z$304,12),Checklist!$Z$5:$Z$304,0))),""),"") -> 46185 | C21: =IFERROR(IF(LARGE(Checklist!$Z$5:$Z$304,12)>0,IF(INDEX(Checklist!$B$5:$B$304,MATCH(LARGE(Checklist!$Z$5:$Z$304,12),Checklist!$Z$5:$Z$304,0))="","",INDEX(Checklist!$B$5:$B$304,MATCH(LARGE(Checklist!$Z$5:$Z$304,12),Checklist!$Z$5:$Z$304,0))),""),"") -> Sexta | D21: =IFERROR(IF(LARGE(Checklist!$Z$5:$Z$304,12)>0,IF(INDEX(Checklist!$C$5:$C$304,MATCH(LARGE(Checklist!$Z$5:$Z$304,12),Checklist!$Z$5:$Z$304,0))="","",INDEX(Checklist!$C$5:$C$304,MATCH(LARGE(Checklist!$Z$5:$Z$304,12),Checklist!$Z$5:$Z$304,0))),""),"") -> Bruna Carvalho | E21: =IFERROR(IF(LARGE(Checklist!$Z$5:$Z$304,12)>0,IF(INDEX(Checklist!$T$5:$T$304,MATCH(LARGE(Checklist!$Z$5:$Z$304,12),Checklist!$Z$5:$Z$304,0))="","",INDEX(Checklist!$T$5:$T$304,MATCH(LARGE(Checklist!$Z$5:$Z$304,12),Checklist!$Z$5:$Z$304,0))),""),"") -> 1 | F21: =IFERROR(IF(LARGE(Checklist!$Z$5:$Z$304,12)>0,IF(INDEX(Checklist!$U$5:$U$304,MATCH(LARGE(Checklist!$Z$5:$Z$304,12),Checklist!$Z$5:$Z$304,0))="","",INDEX(Checklist!$U$5:$U$304,MATCH(LARGE(Checklist!$Z$5:$Z$304,12),Checklist!$Z$5:$Z$304,0))),""),"") -> 0.66666667 | G21: =IFERROR(IF(LARGE(Checklist!$Z$5:$Z$304,12)>0,IF(INDEX(Checklist!$X$5:$X$304,MATCH(LARGE(Checklist!$Z$5:$Z$304,12),Checklist!$Z$5:$Z$304,0))="","",INDEX(Checklist!$X$5:$X$304,MATCH(LARGE(Checklist!$Z$5:$Z$304,12),Checklist!$Z$5:$Z$304,0))),""),"") -> 2 | H21: =IFERROR(IF(LARGE(Checklist!$Z$5:$Z$304,12)>0,IF(INDEX(Checklist!$Y$5:$Y$304,MATCH(LARGE(Checklist!$Z$5:$Z$304,12),Checklist!$Z$5:$Z$304,0))="","",INDEX(Checklist!$Y$5:$Y$304,MATCH(LARGE(Checklist!$Z$5:$Z$304,12),Checklist!$Z$5:$Z$304,0))),""),"") -> Caixa do dia fechado e conferido (Pix, cartão, dinheiro); Fechamento do dia lançado no Caixa (09)
A23: Item mais esquecido
A24: Conta todos os dias registrados. Item pendente muitas vezes é sinal de que a rotina do dia precisa mudar (horário, responsável ou o próprio item).
A25: Item de abertura | C25: Pendente em | D25: Feito em | E25: N/A | F25: Item de fechamento | H25: Pendente em | I25: Feito em | J25: N/A
A26: =IF(Config!$B$10="","",Config!$B$10) -> Agenda do dia confirmada (mensagens de véspera respondidas) | C26: =IF(Config!$B$10="","",COUNTIFS(Checklist!$A$5:$A$304,"<>",Checklist!$D$5:$D$304,"<>Sim",Checklist!$D$5:$D$304,"<>N/A")) -> 1 | D26: =IF(Config!$B$10="","",COUNTIFS(Checklist!$A$5:$A$304,"<>",Checklist!$D$5:$D$304,"Sim")) -> 72 | E26: =IF(Config!$B$10="","",COUNTIFS(Checklist!$A$5:$A$304,"<>",Checklist!$D$5:$D$304,"N/A")) -> 0 | F26: =IF(Config!$D$10="","",Config!$D$10) -> Caixa do dia fechado e conferido (Pix, cartão, dinheiro) | H26: =IF(Config!$D$10="","",COUNTIFS(Checklist!$A$5:$A$304,"<>",Checklist!$L$5:$L$304,"<>Sim",Checklist!$L$5:$L$304,"<>N/A")) -> 9 | I26: =IF(Config!$D$10="","",COUNTIFS(Checklist!$A$5:$A$304,"<>",Checklist!$L$5:$L$304,"Sim")) -> 64 | J26: =IF(Config!$D$10="","",COUNTIFS(Checklist!$A$5:$A$304,"<>",Checklist!$L$5:$L$304,"N/A")) -> 0
A27: =IF(Config!$B$11="","",Config!$B$11) -> Faltas e cancelamentos de ontem registrados na agenda | C27: =IF(Config!$B$11="","",COUNTIFS(Checklist!$A$5:$A$304,"<>",Checklist!$E$5:$E$304,"<>Sim",Checklist!$E$5:$E$304,"<>N/A")) -> 5 | D27: =IF(Config!$B$11="","",COUNTIFS(Checklist!$A$5:$A$304,"<>",Checklist!$E$5:$E$304,"Sim")) -> 68 | E27: =IF(Config!$B$11="","",COUNTIFS(Checklist!$A$5:$A$304,"<>",Checklist!$E$5:$E$304,"N/A")) -> 0 | F27: =IF(Config!$D$11="","",Config!$D$11) -> Fechamento do dia lançado no Caixa (09) | H27: =IF(Config!$D$11="","",COUNTIFS(Checklist!$A$5:$A$304,"<>",Checklist!$M$5:$M$304,"<>Sim",Checklist!$M$5:$M$304,"<>N/A")) -> 10 | I27: =IF(Config!$D$11="","",COUNTIFS(Checklist!$A$5:$A$304,"<>",Checklist!$M$5:$M$304,"Sim")) -> 63 | J27: =IF(Config!$D$11="","",COUNTIFS(Checklist!$A$5:$A$304,"<>",Checklist!$M$5:$M$304,"N/A")) -> 0
A28: =IF(Config!$B$12="","",Config!$B$12) -> Salas e equipamentos prontos (ECG, MAPA, Holter) | C28: =IF(Config!$B$12="","",COUNTIFS(Checklist!$A$5:$A$304,"<>",Checklist!$F$5:$F$304,"<>Sim",Checklist!$F$5:$F$304,"<>N/A")) -> 1 | D28: =IF(Config!$B$12="","",COUNTIFS(Checklist!$A$5:$A$304,"<>",Checklist!$F$5:$F$304,"Sim")) -> 72 | E28: =IF(Config!$B$12="","",COUNTIFS(Checklist!$A$5:$A$304,"<>",Checklist!$F$5:$F$304,"N/A")) -> 0 | F28: =IF(Config!$D$12="","",Config!$D$12) -> Situação de cada horário marcada (realizado, falta, cancelado) | H28: =IF(Config!$D$12="","",COUNTIFS(Checklist!$A$5:$A$304,"<>",Checklist!$N$5:$N$304,"<>Sim",Checklist!$N$5:$N$304,"<>N/A")) -> 5 | I28: =IF(Config!$D$12="","",COUNTIFS(Checklist!$A$5:$A$304,"<>",Checklist!$N$5:$N$304,"Sim")) -> 68 | J28: =IF(Config!$D$12="","",COUNTIFS(Checklist!$A$5:$A$304,"<>",Checklist!$N$5:$N$304,"N/A")) -> 0
A29: =IF(Config!$B$13="","",Config!$B$13) -> Guias e autorizações de convênio do dia separadas | C29: =IF(Config!$B$13="","",COUNTIFS(Checklist!$A$5:$A$304,"<>",Checklist!$G$5:$G$304,"<>Sim",Checklist!$G$5:$G$304,"<>N/A")) -> 3 | D29: =IF(Config!$B$13="","",COUNTIFS(Checklist!$A$5:$A$304,"<>",Checklist!$G$5:$G$304,"Sim")) -> 70 | E29: =IF(Config!$B$13="","",COUNTIFS(Checklist!$A$5:$A$304,"<>",Checklist!$G$5:$G$304,"N/A")) -> 0 | F29: =IF(Config!$D$13="","",Config!$D$13) -> Guias do dia conferidas e guardadas para o lote (13) | H29: =IF(Config!$D$13="","",COUNTIFS(Checklist!$A$5:$A$304,"<>",Checklist!$O$5:$O$304,"<>Sim",Checklist!$O$5:$O$304,"<>N/A")) -> 3 | I29: =IF(Config!$D$13="","",COUNTIFS(Checklist!$A$5:$A$304,"<>",Checklist!$O$5:$O$304,"Sim")) -> 70 | J29: =IF(Config!$D$13="","",COUNTIFS(Checklist!$A$5:$A$304,"<>",Checklist!$O$5:$O$304,"N/A")) -> 0
A30: =IF(Config!$B$14="","",Config!$B$14) -> Troco e maquininha conferidos | C30: =IF(Config!$B$14="","",COUNTIFS(Checklist!$A$5:$A$304,"<>",Checklist!$H$5:$H$304,"<>Sim",Checklist!$H$5:$H$304,"<>N/A")) -> 4 | D30: =IF(Config!$B$14="","",COUNTIFS(Checklist!$A$5:$A$304,"<>",Checklist!$H$5:$H$304,"Sim")) -> 69 | E30: =IF(Config!$B$14="","",COUNTIFS(Checklist!$A$5:$A$304,"<>",Checklist!$H$5:$H$304,"N/A")) -> 0 | F30: =IF(Config!$D$14="","",Config!$D$14) -> Retornos e exames do dia agendados | H30: =IF(Config!$D$14="","",COUNTIFS(Checklist!$A$5:$A$304,"<>",Checklist!$P$5:$P$304,"<>Sim",Checklist!$P$5:$P$304,"<>N/A")) -> 2 | I30: =IF(Config!$D$14="","",COUNTIFS(Checklist!$A$5:$A$304,"<>",Checklist!$P$5:$P$304,"Sim")) -> 71 | J30: =IF(Config!$D$14="","",COUNTIFS(Checklist!$A$5:$A$304,"<>",Checklist!$P$5:$P$304,"N/A")) -> 0
A31: =IF(Config!$B$15="","",Config!$B$15) -> Orçamentos sem resposta revisados (lista da 15) | C31: =IF(Config!$B$15="","",COUNTIFS(Checklist!$A$5:$A$304,"<>",Checklist!$I$5:$I$304,"<>Sim",Checklist!$I$5:$I$304,"<>N/A")) -> 0 | D31: =IF(Config!$B$15="","",COUNTIFS(Checklist!$A$5:$A$304,"<>",Checklist!$I$5:$I$304,"Sim")) -> 15 | E31: =IF(Config!$B$15="","",COUNTIFS(Checklist!$A$5:$A$304,"<>",Checklist!$I$5:$I$304,"N/A")) -> 58 | F31: =IF(Config!$D$15="","",Config!$D$15) -> Agenda de amanhã revisada e confirmações enviadas | H31: =IF(Config!$D$15="","",COUNTIFS(Checklist!$A$5:$A$304,"<>",Checklist!$Q$5:$Q$304,"<>Sim",Checklist!$Q$5:$Q$304,"<>N/A")) -> 3 | I31: =IF(Config!$D$15="","",COUNTIFS(Checklist!$A$5:$A$304,"<>",Checklist!$Q$5:$Q$304,"Sim")) -> 70 | J31: =IF(Config!$D$15="","",COUNTIFS(Checklist!$A$5:$A$304,"<>",Checklist!$Q$5:$Q$304,"N/A")) -> 0
A32: =IF(Config!$B$16="","",Config!$B$16) | C32: =IF(Config!$B$16="","",COUNTIFS(Checklist!$A$5:$A$304,"<>",Checklist!$J$5:$J$304,"<>Sim",Checklist!$J$5:$J$304,"<>N/A")) | D32: =IF(Config!$B$16="","",COUNTIFS(Checklist!$A$5:$A$304,"<>",Checklist!$J$5:$J$304,"Sim")) | E32: =IF(Config!$B$16="","",COUNTIFS(Checklist!$A$5:$A$304,"<>",Checklist!$J$5:$J$304,"N/A")) | F32: =IF(Config!$D$16="","",Config!$D$16) | H32: =IF(Config!$D$16="","",COUNTIFS(Checklist!$A$5:$A$304,"<>",Checklist!$R$5:$R$304,"<>Sim",Checklist!$R$5:$R$304,"<>N/A")) | I32: =IF(Config!$D$16="","",COUNTIFS(Checklist!$A$5:$A$304,"<>",Checklist!$R$5:$R$304,"Sim")) | J32: =IF(Config!$D$16="","",COUNTIFS(Checklist!$A$5:$A$304,"<>",Checklist!$R$5:$R$304,"N/A"))
A33: =IF(Config!$B$17="","",Config!$B$17) | C33: =IF(Config!$B$17="","",COUNTIFS(Checklist!$A$5:$A$304,"<>",Checklist!$K$5:$K$304,"<>Sim",Checklist!$K$5:$K$304,"<>N/A")) | D33: =IF(Config!$B$17="","",COUNTIFS(Checklist!$A$5:$A$304,"<>",Checklist!$K$5:$K$304,"Sim")) | E33: =IF(Config!$B$17="","",COUNTIFS(Checklist!$A$5:$A$304,"<>",Checklist!$K$5:$K$304,"N/A")) | F33: =IF(Config!$D$17="","",Config!$D$17) | H33: =IF(Config!$D$17="","",COUNTIFS(Checklist!$A$5:$A$304,"<>",Checklist!$S$5:$S$304,"<>Sim",Checklist!$S$5:$S$304,"<>N/A")) | I33: =IF(Config!$D$17="","",COUNTIFS(Checklist!$A$5:$A$304,"<>",Checklist!$S$5:$S$304,"Sim")) | J33: =IF(Config!$D$17="","",COUNTIFS(Checklist!$A$5:$A$304,"<>",Checklist!$S$5:$S$304,"N/A"))
A36: Por dia da semana (todos os dias registrados)
A37: Dia | C37: Dias | D37: Com pendência | E37: Itens pendentes | F37: Abertura completa | G37: Fechamento completo
A38: Segunda | C38: =COUNTIFS(Checklist!$B$5:$B$304,A38) -> 14 | D38: =COUNTIFS(Checklist!$B$5:$B$304,A38,Checklist!$X$5:$X$304,">0") -> 3 | E38: =SUMIFS(Checklist!$X$5:$X$304,Checklist!$B$5:$B$304,A38) -> 5 | F38: =IF(C38=0,"",COUNTIFS(Checklist!$B$5:$B$304,A38,Checklist!$V$5:$V$304,0)/C38) -> 0.92857143 | G38: =IF(C38=0,"",COUNTIFS(Checklist!$B$5:$B$304,A38,Checklist!$W$5:$W$304,0)/C38) -> 0.85714286
A39: Terça | C39: =COUNTIFS(Checklist!$B$5:$B$304,A39) -> 15 | D39: =COUNTIFS(Checklist!$B$5:$B$304,A39,Checklist!$X$5:$X$304,">0") -> 6 | E39: =SUMIFS(Checklist!$X$5:$X$304,Checklist!$B$5:$B$304,A39) -> 11 | F39: =IF(C39=0,"",COUNTIFS(Checklist!$B$5:$B$304,A39,Checklist!$V$5:$V$304,0)/C39) -> 0.86666667 | G39: =IF(C39=0,"",COUNTIFS(Checklist!$B$5:$B$304,A39,Checklist!$W$5:$W$304,0)/C39) -> 0.6
A40: Quarta | C40: =COUNTIFS(Checklist!$B$5:$B$304,A40) -> 15 | D40: =COUNTIFS(Checklist!$B$5:$B$304,A40,Checklist!$X$5:$X$304,">0") -> 7 | E40: =SUMIFS(Checklist!$X$5:$X$304,Checklist!$B$5:$B$304,A40) -> 8 | F40: =IF(C40=0,"",COUNTIFS(Checklist!$B$5:$B$304,A40,Checklist!$V$5:$V$304,0)/C40) -> 0.86666667 | G40: =IF(C40=0,"",COUNTIFS(Checklist!$B$5:$B$304,A40,Checklist!$W$5:$W$304,0)/C40) -> 0.66666667
A41: Quinta | C41: =COUNTIFS(Checklist!$B$5:$B$304,A41) -> 14 | D41: =COUNTIFS(Checklist!$B$5:$B$304,A41,Checklist!$X$5:$X$304,">0") -> 7 | E41: =SUMIFS(Checklist!$X$5:$X$304,Checklist!$B$5:$B$304,A41) -> 10 | F41: =IF(C41=0,"",COUNTIFS(Checklist!$B$5:$B$304,A41,Checklist!$V$5:$V$304,0)/C41) -> 0.57142857 | G41: =IF(C41=0,"",COUNTIFS(Checklist!$B$5:$B$304,A41,Checklist!$W$5:$W$304,0)/C41) -> 0.71428571
A42: Sexta | C42: =COUNTIFS(Checklist!$B$5:$B$304,A42) -> 15 | D42: =COUNTIFS(Checklist!$B$5:$B$304,A42,Checklist!$X$5:$X$304,">0") -> 9 | E42: =SUMIFS(Checklist!$X$5:$X$304,Checklist!$B$5:$B$304,A42) -> 12 | F42: =IF(C42=0,"",COUNTIFS(Checklist!$B$5:$B$304,A42,Checklist!$V$5:$V$304,0)/C42) -> 0.8 | G42: =IF(C42=0,"",COUNTIFS(Checklist!$B$5:$B$304,A42,Checklist!$W$5:$W$304,0)/C42) -> 0.46666667
A43: Sábado | C43: =COUNTIFS(Checklist!$B$5:$B$304,A43) -> 0 | D43: =COUNTIFS(Checklist!$B$5:$B$304,A43,Checklist!$X$5:$X$304,">0") -> 0 | E43: =SUMIFS(Checklist!$X$5:$X$304,Checklist!$B$5:$B$304,A43) -> 0 | F43: =IF(C43=0,"",COUNTIFS(Checklist!$B$5:$B$304,A43,Checklist!$V$5:$V$304,0)/C43) | G43: =IF(C43=0,"",COUNTIFS(Checklist!$B$5:$B$304,A43,Checklist!$W$5:$W$304,0)/C43)
A45: Fechamento do dia sem o caixa conferido é a origem da maior parte das diferenças no extrato. Se um item pende sempre no mesmo dia da semana, mude a rotina desse dia, não a pessoa.

Sheet Config
A1: Configurações
A2: Células amarelas: você preenche. Os itens cadastrados aqui viram as colunas da aba Checklist.
A4: Clínica | B4: Clínica Vida Plena (exemplo fictício)
A5: Data de referência (hoje) | B5: 46279 | C5: O exemplo está congelado em 14/09/2026, para os arquivos do kit mostrarem a mesma foto. Ao usar com os seus dados, troque por =HOJE().
A6: Painel: olhar os últimos (dias registrados) | B6: 20
A9: Itens de abertura (até 8) | D9: Itens de fechamento (até 8) | F9: Responsáveis (até 10)
B10: Agenda do dia confirmada (mensagens de véspera respondidas) | D10: Caixa do dia fechado e conferido (Pix, cartão, dinheiro) | F10: Bruna Carvalho
B11: Faltas e cancelamentos de ontem registrados na agenda | D11: Fechamento do dia lançado no Caixa (09) | F11: Dra. Carolina Mendes
B12: Salas e equipamentos prontos (ECG, MAPA, Holter) | D12: Situação de cada horário marcada (realizado, falta, cancelado) | F12: Dr. Paulo Andrade
B13: Guias e autorizações de convênio do dia separadas | D13: Guias do dia conferidas e guardadas para o lote (13)
B14: Troco e maquininha conferidos | D14: Retornos e exames do dia agendados
B15: Orçamentos sem resposta revisados (lista da 15) | D15: Agenda de amanhã revisada e confirmações enviadas
A19: Itens cadastrados | B19: =COUNTA($B$10:$B$17) -> 6 | D19: =COUNTA($D$10:$D$17) -> 6
A21: Preencha de cima para baixo, sem pular linha: as listas param na última linha preenchida e os itens vazios não contam no percentual.
A22: Os itens são administrativos (o que precisa estar em ordem para o dia começar e terminar sem pendência). Nada clínico aqui. Ajuste ao jeito da clínica.

Sheet Checklist
A1: Checklist por dia
A2: Uma linha por dia de atendimento. Em cada item marque Sim, Não ou N/A (não se aplica). Vazio conta como pendente. Quem fecha o dia é a recepção; quem confere é o sócio da semana.
D3: Abertura | L3: Fechamento
A4: Data | B4: Dia da semana | C4: Responsável | D4: =IF(Config!$B$10="","",Config!$B$10) -> Agenda do dia confirmada (mensagens de véspera respondidas) | E4: =IF(Config!$B$11="","",Config!$B$11) -> Faltas e cancelamentos de ontem registrados na agenda | F4: =IF(Config!$B$12="","",Config!$B$12) -> Salas e equipamentos prontos (ECG, MAPA, Holter) | G4: =IF(Config!$B$13="","",Config!$B$13) -> Guias e autorizações de convênio do dia separadas | H4: =IF(Config!$B$14="","",Config!$B$14) -> Troco e maquininha conferidos | I4: =IF(Config!$B$15="","",Config!$B$15) -> Orçamentos sem resposta revisados (lista da 15) | J4: =IF(Config!$B$16="","",Config!$B$16) | K4: =IF(Config!$B$17="","",Config!$B$17) | L4: =IF(Config!$D$10="","",Config!$D$10) -> Caixa do dia fechado e conferido (Pix, cartão, dinheiro) | M4: =IF(Config!$D$11="","",Config!$D$11) -> Fechamento do dia lançado no Caixa (09) | N4: =IF(Config!$D$12="","",Config!$D$12) -> Situação de cada horário marcada (realizado, falta, cancelado) | O4: =IF(Config!$D$13="","",Config!$D$13) -> Guias do dia conferidas e guardadas para o lote (13) | P4: =IF(Config!$D$14="","",Config!$D$14) -> Retornos e exames do dia agendados | Q4: =IF(Config!$D$15="","",Config!$D$15) -> Agenda de amanhã revisada e confirmações enviadas | R4: =IF(Config!$D$16="","",Config!$D$16) | S4: =IF(Config!$D$17="","",Config!$D$17) | T4: % abertura | U4: % fechamento | V4: Pendências de abertura | W4: Pendências de fechamento | X4: Pendências | Y4: O que faltou | Z4: Chave | AA4: Auxiliar
A5: 46174 | B5: =IF(A5="","",CHOOSE(WEEKDAY(A5,2),"Segunda","Terça","Quarta","Quinta","Sexta","Sábado","Domingo")) -> Segunda | C5: Bruna Carvalho | D5: Sim | E5: Sim | F5: Sim | G5: Sim | H5: Sim | I5: N/A | L5: Sim | M5: Sim | N5: Sim | O5: Sim | P5: Sim | Q5: Sim | T5: =IF(A5="","",IFERROR(COUNTIF(D5:K5,"Sim")/(Config!$B$19-COUNTIF(D5:K5,"N/A")),"")) -> 1 | U5: =IF(A5="","",IFERROR(COUNTIF(L5:S5,"Sim")/(Config!$D$19-COUNTIF(L5:S5,"N/A")),"")) -> 1 | V5: =IF(A5="","",MAX(0,Config!$B$19-COUNTIF(D5:K5,"Sim")-COUNTIF(D5:K5,"N/A"))) -> 0 | W5: =IF(A5="","",MAX(0,Config!$D$19-COUNTIF(L5:S5,"Sim")-COUNTIF(L5:S5,"N/A"))) -> 0 | X5: =IF(A5="","",V5+W5) -> 0 | Y5: =IF(OR(A5="",AA5=""),"",LEFT(AA5,LEN(AA5)-2)) | Z5: =IF(OR(A5="",X5=0),0,X5*100000+A5/100000) -> 0 | AA5: =IF(A5="","",IF(AND(Config!$B$10<>"",D5<>"Sim",D5<>"N/A"),Config!$B$10&"; ","")&IF(AND(Config!$B$11<>"",E5<>"Sim",E5<>"N/A"),Config!$B$11&"; ","")&IF(AND(Config!$B$12<>"",F5<>"Sim",F5<>"N/A"),Config!$B$12&"; ","")&IF(AND(Config!$B$13<>"",G5<>"Sim",G5<>"N/A"),Config!$B$13&"; ","")&IF(AND(Config!$B$14<>"",H5<>"Sim",H5<>"N/A"),Config!$B$14&"; ","")&IF(AND(Config!$B$15<>"",I5<>"Sim",I5<>"N/A"),Config!$B$15&"; ","")&IF(AND(Config!$B$16<>"",J5<>"Sim",J5<>"N/A"),Config!$B$16&"; ","")&IF(AND(Config!$B$17<>"",K5<>"Sim",K5<>"N/A"),Config!$B$17&"; ","")&IF(AND(Config!$D$10<>"",L5<>"Sim",L5<>"N/A"),Config!$D$10&"; ","")&IF(AND(Config!$D$11<>"",M5<>"Sim",M5<>"N/A"),Config!$D$11&"; ","")&IF(AND(Config!$D$12<>"",N5<>"Sim",N5<>"N/A"),Config!$D$12&"; ","")&IF(AND(Config!$D$13<>"",O5<>"Sim",O5<>"N/A"),Config!$D$13&"; ","")&IF(AND(Config!$D$14<>"",P5<>"Sim",P5<>"N/A"),Config!$D$14&"; ","")&IF(AND(Config!$D$15<>"",Q5<>"Sim",Q5<>"N/A"),Config!$D$15&"; ","")&IF(AND(Config!$D$16<>"",R5<>"Sim",R5<>"N/A"),Config!$D$16&"; ","")&IF(AND(Config!$D$17<>"",S5<>"Sim",S5<>"N/A"),Config!$D$17&"; ","")) | AB5: =IF(A5="",0,COUNTIF($A$5:$A$304,">"&A5)+1) -> 73
A6: 46175 | B6: =IF(A6="","",CHOOSE(WEEKDAY(A6,2),"Segunda","Terça","Quarta","Quinta","Sexta","Sábado","Domingo")) -> Terça | C6: Bruna Carvalho | D6: Sim | E6: Sim | F6: Sim | G6: Sim | H6: Sim | I6: N/A | L6: Sim | M6: Sim | N6: Sim | O6: Sim | P6: Sim | Q6: Sim | T6: =IF(A6="","",IFERROR(COUNTIF(D6:K6,"Sim")/(Config!$B$19-COUNTIF(D6:K6,"N/A")),"")) -> 1 | U6: =IF(A6="","",IFERROR(COUNTIF(L6:S6,"Sim")/(Config!$D$19-COUNTIF(L6:S6,"N/A")),"")) -> 1 | V6: =IF(A6="","",MAX(0,Config!$B$19-COUNTIF(D6:K6,"Sim")-COUNTIF(D6:K6,"N/A"))) -> 0 | W6: =IF(A6="","",MAX(0,Config!$D$19-COUNTIF(L6:S6,"Sim")-COUNTIF(L6:S6,"N/A"))) -> 0 | X6: =IF(A6="","",V6+W6) -> 0 | Y6: =IF(OR(A6="",AA6=""),"",LEFT(AA6,LEN(AA6)-2)) | Z6: =IF(OR(A6="",X6=0),0,X6*100000+A6/100000) -> 0 | AA6: =IF(A6="","",IF(AND(Config!$B$10<>"",D6<>"Sim",D6<>"N/A"),Config!$B$10&"; ","")&IF(AND(Config!$B$11<>"",E6<>"Sim",E6<>"N/A"),Config!$B$11&"; ","")&IF(AND(Config!$B$12<>"",F6<>"Sim",F6<>"N/A"),Config!$B$12&"; ","")&IF(AND(Config!$B$13<>"",G6<>"Sim",G6<>"N/A"),Config!$B$13&"; ","")&IF(AND(Config!$B$14<>"",H6<>"Sim",H6<>"N/A"),Config!$B$14&"; ","")&IF(AND(Config!$B$15<>"",I6<>"Sim",I6<>"N/A"),Config!$B$15&"; ","")&IF(AND(Config!$B$16<>"",J6<>"Sim",J6<>"N/A"),Config!$B$16&"; ","")&IF(AND(Config!$B$17<>"",K6<>"Sim",K6<>"N/A"),Config!$B$17&"; ","")&IF(AND(Config!$D$10<>"",L6<>"Sim",L6<>"N/A"),Config!$D$10&"; ","")&IF(AND(Config!$D$11<>"",M6<>"Sim",M6<>"N/A"),Config!$D$11&"; ","")&IF(AND(Config!$D$12<>"",N6<>"Sim",N6<>"N/A"),Config!$D$12&"; ","")&IF(AND(Config!$D$13<>"",O6<>"Sim",O6<>"N/A"),Config!$D$13&"; ","")&IF(AND(Config!$D$14<>"",P6<>"Sim",P6<>"N/A"),Config!$D$14&"; ","")&IF(AND(Config!$D$15<>"",Q6<>"Sim",Q6<>"N/A"),Config!$D$15&"; ","")&IF(AND(Config!$D$16<>"",R6<>"Sim",R6<>"N/A"),Config!$D$16&"; ","")&IF(AND(Config!$D$17<>"",S6<>"Sim",S6<>"N/A"),Config!$D$17&"; ","")) | AB6: =IF(A6="",0,COUNTIF($A$5:$A$304,">"&A6)+1) -> 72
A7: 46176 | B7: =IF(A7="","",CHOOSE(WEEKDAY(A7,2),"Segunda","Terça","Quarta","Quinta","Sexta","Sábado","Domingo")) -> Quarta | C7: Bruna Carvalho | D7: Sim | E7: Sim | F7: Sim | G7: Sim | H7: Sim | I7: N/A | L7: Sim | M7: Sim | N7: Sim | O7: Sim | P7: Sim | Q7: Sim | T7: =IF(A7="","",IFERROR(COUNTIF(D7:K7,"Sim")/(Config!$B$19-COUNTIF(D7:K7,"N/A")),"")) -> 1 | U7: =IF(A7="","",IFERROR(COUNTIF(L7:S7,"Sim")/(Config!$D$19-COUNTIF(L7:S7,"N/A")),"")) -> 1 | V7: =IF(A7="","",MAX(0,Config!$B$19-COUNTIF(D7:K7,"Sim")-COUNTIF(D7:K7,"N/A"))) -> 0 | W7: =IF(A7="","",MAX(0,Config!$D$19-COUNTIF(L7:S7,"Sim")-COUNTIF(L7:S7,"N/A"))) -> 0 | X7: =IF(A7="","",V7+W7) -> 0 | Y7: =IF(OR(A7="",AA7=""),"",LEFT(AA7,LEN(AA7)-2)) | Z7: =IF(OR(A7="",X7=0),0,X7*100000+A7/100000) -> 0 | AA7: =IF(A7="","",IF(AND(Config!$B$10<>"",D7<>"Sim",D7<>"N/A"),Config!$B$10&"; ","")&IF(AND(Config!$B$11<>"",E7<>"Sim",E7<>"N/A"),Config!$B$11&"; ","")&IF(AND(Config!$B$12<>"",F7<>"Sim",F7<>"N/A"),Config!$B$12&"; ","")&IF(AND(Config!$B$13<>"",G7<>"Sim",G7<>"N/A"),Config!$B$13&"; ","")&IF(AND(Config!$B$14<>"",H7<>"Sim",H7<>"N/A"),Config!$B$14&"; ","")&IF(AND(Config!$B$15<>"",I7<>"Sim",I7<>"N/A"),Config!$B$15&"; ","")&IF(AND(Config!$B$16<>"",J7<>"Sim",J7<>"N/A"),Config!$B$16&"; ","")&IF(AND(Config!$B$17<>"",K7<>"Sim",K7<>"N/A"),Config!$B$17&"; ","")&IF(AND(Config!$D$10<>"",L7<>"Sim",L7<>"N/A"),Config!$D$10&"; ","")&IF(AND(Config!$D$11<>"",M7<>"Sim",M7<>"N/A"),Config!$D$11&"; ","")&IF(AND(Config!$D$12<>"",N7<>"Sim",N7<>"N/A"),Config!$D$12&"; ","")&IF(AND(Config!$D$13<>"",O7<>"Sim",O7<>"N/A"),Config!$D$13&"; ","")&IF(AND(Config!$D$14<>"",P7<>"Sim",P7<>"N/A"),Config!$D$14&"; ","")&IF(AND(Config!$D$15<>"",Q7<>"Sim",Q7<>"N/A"),Config!$D$15&"; ","")&IF(AND(Config!$D$16<>"",R7<>"Sim",R7<>"N/A"),Config!$D$16&"; ","")&IF(AND(Config!$D$17<>"",S7<>"Sim",S7<>"N/A"),Config!$D$17&"; ","")) | AB7: =IF(A7="",0,COUNTIF($A$5:$A$304,">"&A7)+1) -> 71
A8: 46178 | B8: =IF(A8="","",CHOOSE(WEEKDAY(A8,2),"Segunda","Terça","Quarta","Quinta","Sexta","Sábado","Domingo")) -> Sexta | C8: Bruna Carvalho | D8: Sim | E8: Sim | F8: Sim | G8: Sim | H8: Sim | I8: Sim | L8: Sim | M8: Sim | N8: Sim | O8: Sim | P8: Sim | Q8: Sim | T8: =IF(A8="","",IFERROR(COUNTIF(D8:K8,"Sim")/(Config!$B$19-COUNTIF(D8:K8,"N/A")),"")) -> 1 | U8: =IF(A8="","",IFERROR(COUNTIF(L8:S8,"Sim")/(Config!$D$19-COUNTIF(L8:S8,"N/A")),"")) -> 1 | V8: =IF(A8="","",MAX(0,Config!$B$19-COUNTIF(D8:K8,"Sim")-COUNTIF(D8:K8,"N/A"))) -> 0 | W8: =IF(A8="","",MAX(0,Config!$D$19-COUNTIF(L8:S8,"Sim")-COUNTIF(L8:S8,"N/A"))) -> 0 | X8: =IF(A8="","",V8+W8) -> 0 | Y8: =IF(OR(A8="",AA8=""),"",LEFT(AA8,LEN(AA8)-2)) | Z8: =IF(OR(A8="",X8=0),0,X8*100000+A8/100000) -> 0 | AA8: =IF(A8="","",IF(AND(Config!$B$10<>"",D8<>"Sim",D8<>"N/A"),Config!$B$10&"; ","")&IF(AND(Config!$B$11<>"",E8<>"Sim",E8<>"N/A"),Config!$B$11&"; ","")&IF(AND(Config!$B$12<>"",F8<>"Sim",F8<>"N/A"),Config!$B$12&"; ","")&IF(AND(Config!$B$13<>"",G8<>"Sim",G8<>"N/A"),Config!$B$13&"; ","")&IF(AND(Config!$B$14<>"",H8<>"Sim",H8<>"N/A"),Config!$B$14&"; ","")&IF(AND(Config!$B$15<>"",I8<>"Sim",I8<>"N/A"),Config!$B$15&"; ","")&IF(AND(Config!$B$16<>"",J8<>"Sim",J8<>"N/A"),Config!$B$16&"; ","")&IF(AND(Config!$B$17<>"",K8<>"Sim",K8<>"N/A"),Config!$B$17&"; ","")&IF(AND(Config!$D$10<>"",L8<>"Sim",L8<>"N/A"),Config!$D$10&"; ","")&IF(AND(Config!$D$11<>"",M8<>"Sim",M8<>"N/A"),Config!$D$11&"; ","")&IF(AND(Config!$D$12<>"",N8<>"Sim",N8<>"N/A"),Config!$D$12&"; ","")&IF(AND(Config!$D$13<>"",O8<>"Sim",O8<>"N/A"),Config!$D$13&"; ","")&IF(AND(Config!$D$14<>"",P8<>"Sim",P8<>"N/A"),Config!$D$14&"; ","")&IF(AND(Config!$D$15<>"",Q8<>"Sim",Q8<>"N/A"),Config!$D$15&"; ","")&IF(AND(Config!$D$16<>"",R8<>"Sim",R8<>"N/A"),Config!$D$16&"; ","")&IF(AND(Config!$D$17<>"",S8<>"Sim",S8<>"N/A"),Config!$D$17&"; ","")) | AB8: =IF(A8="",0,COUNTIF($A$5:$A$304,">"&A8)+1) -> 70
A9: 46181 | B9: =IF(A9="","",CHOOSE(WEEKDAY(A9,2),"Segunda","Terça","Quarta","Quinta","Sexta","Sábado","Domingo")) -> Segunda | C9: Bruna Carvalho | D9: Sim | E9: Sim | F9: Sim | G9: Sim | H9: Sim | I9: N/A | L9: Sim | M9: Sim | N9: Sim | O9: Sim | P9: Sim | Q9: Sim | T9: =IF(A9="","",IFERROR(COUNTIF(D9:K9,"Sim")/(Config!$B$19-COUNTIF(D9:K9,"N/A")),"")) -> 1 | U9: =IF(A9="","",IFERROR(COUNTIF(L9:S9,"Sim")/(Config!$D$19-COUNTIF(L9:S9,"N/A")),"")) -> 1 | V9: =IF(A9="","",MAX(0,Config!$B$19-COUNTIF(D9:K9,"Sim")-COUNTIF(D9:K9,"N/A"))) -> 0 | W9: =IF(A9="","",MAX(0,Config!$D$19-COUNTIF(L9:S9,"Sim")-COUNTIF(L9:S9,"N/A"))) -> 0 | X9: =IF(A9="","",V9+W9) -> 0 | Y9: =IF(OR(A9="",AA9=""),"",LEFT(AA9,LEN(AA9)-2)) | Z9: =IF(OR(A9="",X9=0),0,X9*100000+A9/100000) -> 0 | AA9: =IF(A9="","",IF(AND(Config!$B$10<>"",D9<>"Sim",D9<>"N/A"),Config!$B$10&"; ","")&IF(AND(Config!$B$11<>"",E9<>"Sim",E9<>"N/A"),Config!$B$11&"; ","")&IF(AND(Config!$B$12<>"",F9<>"Sim",F9<>"N/A"),Config!$B$12&"; ","")&IF(AND(Config!$B$13<>"",G9<>"Sim",G9<>"N/A"),Config!$B$13&"; ","")&IF(AND(Config!$B$14<>"",H9<>"Sim",H9<>"N/A"),Config!$B$14&"; ","")&IF(AND(Config!$B$15<>"",I9<>"Sim",I9<>"N/A"),Config!$B$15&"; ","")&IF(AND(Config!$B$16<>"",J9<>"Sim",J9<>"N/A"),Config!$B$16&"; ","")&IF(AND(Config!$B$17<>"",K9<>"Sim",K9<>"N/A"),Config!$B$17&"; ","")&IF(AND(Config!$D$10<>"",L9<>"Sim",L9<>"N/A"),Config!$D$10&"; ","")&IF(AND(Config!$D$11<>"",M9<>"Sim",M9<>"N/A"),Config!$D$11&"; ","")&IF(AND(Config!$D$12<>"",N9<>"Sim",N9<>"N/A"),Config!$D$12&"; ","")&IF(AND(Config!$D$13<>"",O9<>"Sim",O9<>"N/A"),Config!$D$13&"; ","")&IF(AND(Config!$D$14<>"",P9<>"Sim",P9<>"N/A"),Config!$D$14&"; ","")&IF(AND(Config!$D$15<>"",Q9<>"Sim",Q9<>"N/A"),Config!$D$15&"; ","")&IF(AND(Config!$D$16<>"",R9<>"Sim",R9<>"N/A"),Config!$D$16&"; ","")&IF(AND(Config!$D$17<>"",S9<>"Sim",S9<>"N/A"),Config!$D$17&"; ","")) | AB9: =IF(A9="",0,COUNTIF($A$5:$A$304,">"&A9)+1) -> 69
A10: 46182 | B10: =IF(A10="","",CHOOSE(WEEKDAY(A10,2),"Segunda","Terça","Quarta","Quinta","Sexta","Sábado","Domingo")) -> Terça | C10: Bruna Carvalho | D10: Sim | E10: Sim | F10: Sim | G10: Sim | H10: Sim | I10: N/A | L10: Sim | M10: Sim | N10: Sim | O10: Sim | P10: Sim | Q10: Sim | T10: =IF(A10="","",IFERROR(COUNTIF(D10:K10,"Sim")/(Config!$B$19-COUNTIF(D10:K10,"N/A")),"")) -> 1 | U10: =IF(A10="","",IFERROR(COUNTIF(L10:S10,"Sim")/(Config!$D$19-COUNTIF(L10:S10,"N/A")),"")) -> 1 | V10: =IF(A10="","",MAX(0,Config!$B$19-COUNTIF(D10:K10,"Sim")-COUNTIF(D10:K10,"N/A"))) -> 0 | W10: =IF(A10="","",MAX(0,Config!$D$19-COUNTIF(L10:S10,"Sim")-COUNTIF(L10:S10,"N/A"))) -> 0 | X10: =IF(A10="","",V10+W10) -> 0 | Y10: =IF(OR(A10="",AA10=""),"",LEFT(AA10,LEN(AA10)-2)) | Z10: =IF(OR(A10="",X10=0),0,X10*100000+A10/100000) -> 0 | AA10: =IF(A10="","",IF(AND(Config!$B$10<>"",D10<>"Sim",D10<>"N/A"),Config!$B$10&"; ","")&IF(AND(Config!$B$11<>"",E10<>"Sim",E10<>"N/A"),Config!$B$11&"; ","")&IF(AND(Config!$B$12<>"",F10<>"Sim",F10<>"N/A"),Config!$B$12&"; ","")&IF(AND(Config!$B$13<>"",G10<>"Sim",G10<>"N/A"),Config!$B$13&"; ","")&IF(AND(Config!$B$14<>"",H10<>"Sim",H10<>"N/A"),Config!$B$14&"; ","")&IF(AND(Config!$B$15<>"",I10<>"Sim",I10<>"N/A"),Config!$B$15&"; ","")&IF(AND(Config!$B$16<>"",J10<>"Sim",J10<>"N/A"),Config!$B$16&"; ","")&IF(AND(Config!$B$17<>"",K10<>"Sim",K10<>"N/A"),Config!$B$17&"; ","")&IF(AND(Config!$D$10<>"",L10<>"Sim",L10<>"N/A"),Config!$D$10&"; ","")&IF(AND(Config!$D$11<>"",M10<>"Sim",M10<>"N/A"),Config!$D$11&"; ","")&IF(AND(Config!$D$12<>"",N10<>"Sim",N10<>"N/A"),Config!$D$12&"; ","")&IF(AND(Config!$D$13<>"",O10<>"Sim",O10<>"N/A"),Config!$D$13&"; ","")&IF(AND(Config!$D$14<>"",P10<>"Sim",P10<>"N/A"),Config!$D$14&"; ","")&IF(AND(Config!$D$15<>"",Q10<>"Sim",Q10<>"N/A"),Config!$D$15&"; ","")&IF(AND(Config!$D$16<>"",R10<>"Sim",R10<>"N/A"),Config!$D$16&"; ","")&IF(AND(Config!$D$17<>"",S10<>"Sim",S10<>"N/A"),Config!$D$17&"; ","")) | AB10: =IF(A10="",0,COUNTIF($A$5:$A$304,">"&A10)+1) -> 68
A11: 46183 | B11: =IF(A11="","",CHOOSE(WEEKDAY(A11,2),"Segunda","Terça","Quarta","Quinta","Sexta","Sábado","Domingo")) -> Quarta | C11: Bruna Carvalho | D11: Sim | E11: Sim | F11: Sim | G11: Sim | H11: Sim | I11: N/A | L11: Sim | M11: Sim | N11: Sim | O11: Sim | P11: Sim | Q11: Sim | T11: =IF(A11="","",IFERROR(COUNTIF(D11:K11,"Sim")/(Config!$B$19-COUNTIF(D11:K11,"N/A")),"")) -> 1 | U11: =IF(A11="","",IFERROR(COUNTIF(L11:S11,"Sim")/(Config!$D$19-COUNTIF(L11:S11,"N/A")),"")) -> 1 | V11: =IF(A11="","",MAX(0,Config!$B$19-COUNTIF(D11:K11,"Sim")-COUNTIF(D11:K11,"N/A"))) -> 0 | W11: =IF(A11="","",MAX(0,Config!$D$19-COUNTIF(L11:S11,"Sim")-COUNTIF(L11:S11,"N/A"))) -> 0 | X11: =IF(A11="","",V11+W11) -> 0 | Y11: =IF(OR(A11="",AA11=""),"",LEFT(AA11,LEN(AA11)-2)) | Z11: =IF(OR(A11="",X11=0),0,X11*100000+A11/100000) -> 0 | AA11: =IF(A11="","",IF(AND(Config!$B$10<>"",D11<>"Sim",D11<>"N/A"),Config!$B$10&"; ","")&IF(AND(Config!$B$11<>"",E11<>"Sim",E11<>"N/A"),Config!$B$11&"; ","")&IF(AND(Config!$B$12<>"",F11<>"Sim",F11<>"N/A"),Config!$B$12&"; ","")&IF(AND(Config!$B$13<>"",G11<>"Sim",G11<>"N/A"),Config!$B$13&"; ","")&IF(AND(Config!$B$14<>"",H11<>"Sim",H11<>"N/A"),Config!$B$14&"; ","")&IF(AND(Config!$B$15<>"",I11<>"Sim",I11<>"N/A"),Config!$B$15&"; ","")&IF(AND(Config!$B$16<>"",J11<>"Sim",J11<>"N/A"),Config!$B$16&"; ","")&IF(AND(Config!$B$17<>"",K11<>"Sim",K11<>"N/A"),Config!$B$17&"; ","")&IF(AND(Config!$D$10<>"",L11<>"Sim",L11<>"N/A"),Config!$D$10&"; ","")&IF(AND(Config!$D$11<>"",M11<>"Sim",M11<>"N/A"),Config!$D$11&"; ","")&IF(AND(Config!$D$12<>"",N11<>"Sim",N11<>"N/A"),Config!$D$12&"; ","")&IF(AND(Config!$D$13<>"",O11<>"Sim",O11<>"N/A"),Config!$D$13&"; ","")&IF(AND(Config!$D$14<>"",P11<>"Sim",P11<>"N/A"),Config!$D$14&"; ","")&IF(AND(Config!$D$15<>"",Q11<>"Sim",Q11<>"N/A"),Config!$D$15&"; ","")&IF(AND(Config!$D$16<>"",R11<>"Sim",R11<>"N/A"),Config!$D$16&"; ","")&IF(AND(Config!$D$17<>"",S11<>"Sim",S11<>"N/A"),Config!$D$17&"; ","")) | AB11: =IF(A11="",0,COUNTIF($A$5:$A$304,">"&A11)+1) -> 67
A12: 46184 | B12: =IF(A12="","",CHOOSE(WEEKDAY(A12,2),"Segunda","Terça","Quarta","Quinta","Sexta","Sábado","Domingo")) -> Quinta | C12: Bruna Carvalho | D12: Sim | E12: Sim | F12: Não | G12: Sim | H12: Sim | I12: N/A | L12: Sim | M12: Sim | N12: Sim | O12: Sim | P12: Sim | Q12: Sim | T12: =IF(A12="","",IFERROR(COUNTIF(D12:K12,"Sim")/(Config!$B$19-COUNTIF(D12:K12,"N/A")),"")) -> 0.8 | U12: =IF(A12="","",IFERROR(COUNTIF(L12:S12,"Sim")/(Config!$D$19-COUNTIF(L12:S12,"N/A")),"")) -> 1 | V12: =IF(A12="","",MAX(0,Config!$B$19-COUNTIF(D12:K12,"Sim")-COUNTIF(D12:K12,"N/A"))) -> 1 | W12: =IF(A12="","",MAX(0,Config!$D$19-COUNTIF(L12:S12,"Sim")-COUNTIF(L12:S12,"N/A"))) -> 0 | X12: =IF(A12="","",V12+W12) -> 1 | Y12: =IF(OR(A12="",AA12=""),"",LEFT(AA12,LEN(AA12)-2)) -> Salas e equipamentos prontos (ECG, MAPA, Holter) | Z12: =IF(OR(A12="",X12=0),0,X12*100000+A12/100000) -> 100000.46 | AA12: =IF(A12="","",IF(AND(Config!$B$10<>"",D12<>"Sim",D12<>"N/A"),Config!$B$10&"; ","")&IF(AND(Config!$B$11<>"",E12<>"Sim",E12<>"N/A"),Config!$B$11&"; ","")&IF(AND(Config!$B$12<>"",F12<>"Sim",F12<>"N/A"),Config!$B$12&"; ","")&IF(AND(Config!$B$13<>"",G12<>"Sim",G12<>"N/A"),Config!$B$13&"; ","")&IF(AND(Config!$B$14<>"",H12<>"Sim",H12<>"N/A"),Config!$B$14&"; ","")&IF(AND(Config!$B$15<>"",I12<>"Sim",I12<>"N/A"),Config!$B$15&"; ","")&IF(AND(Config!$B$16<>"",J12<>"Sim",J12<>"N/A"),Config!$B$16&"; ","")&IF(AND(Config!$B$17<>"",K12<>"Sim",K12<>"N/A"),Config!$B$17&"; ","")&IF(AND(Config!$D$10<>"",L12<>"Sim",L12<>"N/A"),Config!$D$10&"; ","")&IF(AND(Config!$D$11<>"",M12<>"Sim",M12<>"N/A"),Config!$D$11&"; ","")&IF(AND(Config!$D$12<>"",N12<>"Sim",N12<>"N/A"),Config!$D$12&"; ","")&IF(AND(Config!$D$13<>"",O12<>"Sim",O12<>"N/A"),Config!$D$13&"; ","")&IF(AND(Config!$D$14<>"",P12<>"Sim",P12<>"N/A"),Config!$D$14&"; ","")&IF(AND(Config!$D$15<>"",Q12<>"Sim",Q12<>"N/A"),Config!$D$15&"; ","")&IF(AND(Config!$D$16<>"",R12<>"Sim",R12<>"N/A"),Config!$D$16&"; ","")&IF(AND(Config!$D$17<>"",S12<>"Sim",S12<>"N/A"),Config!$D$17&"; ","")) -> Salas e equipamentos prontos (ECG, MAPA, Holter); | AB12: =IF(A12="",0,COUNTIF($A$5:$A$304,">"&A12)+1) -> 66
A13: 46185 | B13: =IF(A13="","",CHOOSE(WEEKDAY(A13,2),"Segunda","Terça","Quarta","Quinta","Sexta","Sábado","Domingo")) -> Sexta | C13: Bruna Carvalho | D13: Sim | E13: Sim | F13: Sim | G13: Sim | H13: Sim | I13: Sim | L13: Não | M13: Não | N13: Sim | O13: Sim | P13: Sim | Q13: Sim | T13: =IF(A13="","",IFERROR(COUNTIF(D13:K13,"Sim")/(Config!$B$19-COUNTIF(D13:K13,"N/A")),"")) -> 1 | U13: =IF(A13="","",IFERROR(COUNTIF(L13:S13,"Sim")/(Config!$D$19-COUNTIF(L13:S13,"N/A")),"")) -> 0.66666667 | V13: =IF(A13="","",MAX(0,Config!$B$19-COUNTIF(D13:K13,"Sim")-COUNTIF(D13:K13,"N/A"))) -> 0 | W13: =IF(A13="","",MAX(0,Config!$D$19-COUNTIF(L13:S13,"Sim")-COUNTIF(L13:S13,"N/A"))) -> 2 | X13: =IF(A13="","",V13+W13) -> 2 | Y13: =IF(OR(A13="",AA13=""),"",LEFT(AA13,LEN(AA13)-2)) -> Caixa do dia fechado e conferido (Pix, cartão, dinheiro); Fechamento do dia lançado no Caixa (09) | Z13: =IF(OR(A13="",X13=0),0,X13*100000+A13/100000) -> 200000.46 | AA13: =IF(A13="","",IF(AND(Config!$B$10<>"",D13<>"Sim",D13<>"N/A"),Config!$B$10&"; ","")&IF(AND(Config!$B$11<>"",E13<>"Sim",E13<>"N/A"),Config!$B$11&"; ","")&IF(AND(Config!$B$12<>"",F13<>"Sim",F13<>"N/A"),Config!$B$12&"; ","")&IF(AND(Config!$B$13<>"",G13<>"Sim",G13<>"N/A"),Config!$B$13&"; ","")&IF(AND(Config!$B$14<>"",H13<>"Sim",H13<>"N/A"),Config!$B$14&"; ","")&IF(AND(Config!$B$15<>"",I13<>"Sim",I13<>"N/A"),Config!$B$15&"; ","")&IF(AND(Config!$B$16<>"",J13<>"Sim",J13<>"N/A"),Config!$B$16&"; ","")&IF(AND(Config!$B$17<>"",K13<>"Sim",K13<>"N/A"),Config!$B$17&"; ","")&IF(AND(Config!$D$10<>"",L13<>"Sim",L13<>"N/A"),Config!$D$10&"; ","")&IF(AND(Config!$D$11<>"",M13<>"Sim",M13<>"N/A"),Config!$D$11&"; ","")&IF(AND(Config!$D$12<>"",N13<>"Sim",N13<>"N/A"),Config!$D$12&"; ","")&IF(AND(Config!$D$13<>"",O13<>"Sim",O13<>"N/A"),Config!$D$13&"; ","")&IF(AND(Config!$D$14<>"",P13<>"Sim",P13<>"N/A"),Config!$D$14&"; ","")&IF(AND(Config!$D$15<>"",Q13<>"Sim",Q13<>"N/A"),Config!$D$15&"; ","")&IF(AND(Config!$D$16<>"",R13<>"Sim",R13<>"N/A"),Config!$D$16&"; ","")&IF(AND(Config!$D$17<>"",S13<>"Sim",S13<>"N/A"),Config!$D$17&"; ","")) -> Caixa do dia fechado e conferido (Pix, cartão, dinheiro); Fechamento do dia lançado no Caixa (09); | AB13: =IF(A13="",0,COUNTIF($A$5:$A$304,">"&A13)+1) -> 65
