Workbook

Sheet Como usar
A1: Custo da hora de atendimento
A2: Kit de Gestão para Médicos · Seu Sócio Gestor · versão 1.0 (setembro de 2026)
A4: O que esta planilha faz | B4: Responde "quanto custa uma hora da minha agenda?". Soma custos fixos e pró-labore dos sócios, divide pelas horas de atendimento planejadas no mês e mostra o custo-hora, a hora mínima a cobrar (com margem e impostos), o custo de um horário vazio e o que acontece quando faltas tiram horas do mês.
A5: Passo 1 | B5: Em Custos fixos, liste o que a clínica paga todo mês (aluguel, recepção com encargos, contador, sistema, energia, marketing). Uma linha por item, de cima para baixo.
A6: Passo 2 | B6: Em Equipe, cada pessoa: remuneração (pró-labore, salário ou repasse), valor mensal, se já está nos custos fixos, horas de atendimento planejadas no mês e se entra no custo-hora. Sócios entram; médico parceiro por repasse não; recepção já está nos fixos.
A7: Passo 3 | B7: Em Config, a margem mínima sobre o preço e o percentual de impostos e taxas que sai de cada recebimento (a alíquota efetiva que o contador informar).
A8: Passo 4 | B8: Em Painel: custo-hora, hora mínima a cobrar, custo por pessoa, custo de um horário vazio e a sensibilidade. Use o custo-hora nas planilhas 06 (precificação), 07 (simulador de convênio) e 08 (tabela de preços).
A9: Rotina | B9: Revise uma vez por trimestre ou quando mudar aluguel, equipe ou pró-labore. Leva 10 minutos. Na última linha da sensibilidade, digite as horas atendidas do mês fechado (Painel da 01) para ver o custo-hora real.
A10: Com a IA | B10: Copie "Como chegamos ao número" e use o prompt "Preço 01 · Entender o custo da minha hora" da biblioteca do kit para explicar o custo-hora ao sócio em linguagem simples.
A11: Legenda | B11: Células amarelas: você preenche. Brancas: calculadas. Não é preciso mexer em nada fora do amarelo.
A12: Proteção | B12: Fórmulas protegidas sem senha. Para editar: Revisar > Desproteger planilha (Excel) ou Dados > Proteger intervalos (Google Sheets).
A13: Requisitos | B13: Excel 2016 ou mais novo, Microsoft 365 ou Google Sheets (só funções do Excel 2007+; nada de MÍNIMOSES, MÁXIMOSES ou UNIRTEXTO). No celular abre nos aplicativos; para preencher, use o computador.
A14: Dados de pacientes | B14: Guarde só o que a gestão precisa (nome, contato, valor, data). Nada de diagnóstico, prontuário ou exame nestas planilhas: o kit é gestão, não é prontuário. Veja o guia LGPD do kit antes de colar qualquer tabela em uma IA.
A15: Google Sheets | B15: Faça upload no Google Drive e abra com o Google Sheets. Fórmulas, listas, cores, semáforos e gráficos funcionam: as regras de cor que dependem do mês escolhido em Config usam INDIRECT, que é a forma que o Sheets aceita para regra condicional apontar para outra aba.
... A18: Suporte | B18: suporte@seusociogestor.com.br · resposta em até 5 dias úteis · reembolso em até 7 dias pelo mesmo canal.

Sheet Painel
A1: =Config!$B$4&" · Custo da hora de atendimento · "&Config!$B$5 -> Clínica Vida Plena (exemplo fictício) · Custo da hora de atendimento · Setembro de 2026
A2: Nada para digitar aqui, exceto os percentuais da sensibilidade e as horas atendidas de verdade. Custos vêm de Custos fixos, pessoas de Equipe, margem e impostos de Config.
A4: Custo total do mês | C4: Horas de atendimento planejadas no mês | E4: Custo da hora de atendimento | G4: Hora mínima a cobrar | I4: Custo de um horário vazio
A5: =B11 -> 28000 | C5: =B12 -> 140 | E5: =B13 -> 200 | G5: =B17 -> 340 | I5: =B21 -> 100
A6: A base do custo-hora são as horas de atendimento PLANEJADAS do mês (turnos × 4,33 semanas): é o preço que cobre o custo quando a agenda está cheia, e é ele que as planilhas 06, 07 e 08 usam. Como a agenda real nunca fica 100 % cheia, o bloco "Sensibilidade", no fim desta tela, mostra o custo-hora com as horas de fato atendidas (a última linha usa agosto, da planilha 01): é o número da conversa sobre faltas e horários vazios, não o da tabela de preços.
A7: Como chegamos ao número
A8: Passo | B8: Valor | C8: De onde vem
A9: Custos fixos do mês | B9: ='Custos fixos'!B36 -> 10000 | C9: Aba Custos fixos
A10: Pró-labore e salários fora dos custos fixos (de quem entra no custo-hora) | B10: =SUMIFS(Equipe!$D$5:$D$14,Equipe!$E$5:$E$14,"Não",Equipe!$G$5:$G$14,"Sim") -> 18000 | C10: Aba Equipe: marcados "Entra no custo-hora? = Sim" e "Já está nos custos fixos? = Não"
A11: Custo total do mês | B11: =B9+B10 -> 28000 | C11: Soma dos dois acima
A12: Horas de atendimento planejadas no mês (quem entra no custo-hora) | B12: =SUMIFS(Equipe!$F$5:$F$14,Equipe!$G$5:$G$14,"Sim") -> 140 | C12: Aba Equipe: turnos da semana × 4,33 semanas
A13: Custo da hora de atendimento | B13: =IF(B12=0,"",B11/B12) -> 200 | C13: Custo total ÷ horas de atendimento
A14: Margem mínima sobre o preço | B14: =Config!$B$7 -> 0.3 | C14: Config
A15: Impostos sobre o que entra | B15: =Config!$B$8 -> 0.11 | C15: Config
A16: Hora mínima a cobrar (exata) | B16: =IF(B13="","",IFERROR(B13/(1-Config!$B$7-Config!$B$8),"")) -> 338.98305 | C16: Custo-hora ÷ (1 − margem − impostos)
A17: Hora mínima a cobrar (arredondada) | B17: =IF(B16="","",CEILING(B16,Config!$B$9)) -> 340 | C17: Arredondada para cima, no múltiplo de Config
A18: Custo direto médio por hora (pró-labore ÷ horas) | B18: =IF(B12=0,0,B10/B12) -> 128.57143 | C18: O que os sócios custam por hora de agenda
A19: Custos indiretos (custos fixos, com a recepção) | B19: =B9 -> 10000 | C19: Para ratear por hora de atendimento
A20: Custo indireto por hora de atendimento | B20: =IF(B12=0,0,B19/B12) -> 71.428571 | C20: Custos fixos ÷ horas de atendimento (estrutura, recepção, aluguel). Já está dentro do custo-hora acima: na 11 serve só para mostrar quanto vale a hora de sala
A21: Custo de um horário vazio (consulta de Config, em minutos) | B21: =IF(B13="","",B13*Config!$B$10/60) -> 100 | C21: Custo-hora × duração da consulta: o que uma falta custa à clínica
A24: Por pessoa
A25: Pessoa | B25: Papel | C25: Remuneração | D25: Horas planejadas | E25: Custo direto por hora | F25: Custo-hora completo | G25: Hora mínima a cobrar
A26: =IF(Equipe!$A$5="","",Equipe!$A$5) -> Dra. Carolina Mendes | B26: =IF(Equipe!$A$5="","",Equipe!$B$5) -> Sócia · clínica médica | C26: =IF(Equipe!$A$5="","",Equipe!$C$5) -> Pró-labore | D26: =IF(Equipe!$A$5="","",IF(Equipe!$F$5="","",Equipe!$F$5)) -> 70 | E26: =IF(Equipe!$A$5="","",IF(Equipe!$H$5="","—",Equipe!$H$5)) -> 128.57143 | F26: =IF(Equipe!$A$5="","",IF(Equipe!$I$5="","—",Equipe!$I$5)) -> 200 | G26: =IF(Equipe!$A$5="","",IF(Equipe!$J$5="","—",Equipe!$J$5)) -> 338.98305
A27: =IF(Equipe!$A$6="","",Equipe!$A$6) -> Dr. Paulo Andrade | B27: =IF(Equipe!$A$6="","",Equipe!$B$6) -> Sócio · cardiologia | C27: =IF(Equipe!$A$6="","",Equipe!$C$6) -> Pró-labore | D27: =IF(Equipe!$A$6="","",IF(Equipe!$F$6="","",Equipe!$F$6)) -> 70 | E27: =IF(Equipe!$A$6="","",IF(Equipe!$H$6="","—",Equipe!$H$6)) -> 128.57143 | F27: =IF(Equipe!$A$6="","",IF(Equipe!$I$6="","—",Equipe!$I$6)) -> 200 | G27: =IF(Equipe!$A$6="","",IF(Equipe!$J$6="","—",Equipe!$J$6)) -> 338.98305
A28: =IF(Equipe!$A$7="","",Equipe!$A$7) -> Dra. Renata Sousa | B28: =IF(Equipe!$A$7="","",Equipe!$B$7) -> Médica parceira · endocrinologia | C28: =IF(Equipe!$A$7="","",Equipe!$C$7) -> Repasse | D28: =IF(Equipe!$A$7="","",IF(Equipe!$F$7="","",Equipe!$F$7)) -> 35 | E28: =IF(Equipe!$A$7="","",IF(Equipe!$H$7="","—",Equipe!$H$7)) -> — | F28: =IF(Equipe!$A$7="","",IF(Equipe!$I$7="","—",Equipe!$I$7)) -> — | G28: =IF(Equipe!$A$7="","",IF(Equipe!$J$7="","—",Equipe!$J$7)) -> —
A29: =IF(Equipe!$A$8="","",Equipe!$A$8) -> Bruna Carvalho | B29: =IF(Equipe!$A$8="","",Equipe!$B$8) -> Recepcionista (CLT) | C29: =IF(Equipe!$A$8="","",Equipe!$C$8) -> Salário | D29: =IF(Equipe!$A$8="","",IF(Equipe!$F$8="","",Equipe!$F$8)) | E29: =IF(Equipe!$A$8="","",IF(Equipe!$H$8="","—",Equipe!$H$8)) -> — | F29: =IF(Equipe!$A$8="","",IF(Equipe!$I$8="","—",Equipe!$I$8)) -> — | G29: =IF(Equipe!$A$8="","",IF(Equipe!$J$8="","—",Equipe!$J$8)) -> —
A30: =IF(Equipe!$A$9="","",Equipe!$A$9) | B30: =IF(Equipe!$A$9="","",Equipe!$B$9) | C30: =IF(Equipe!$A$9="","",Equipe!$C$9) | D30: =IF(Equipe!$A$9="","",IF(Equipe!$F$9="","",Equipe!$F$9)) | E30: =IF(Equipe!$A$9="","",IF(Equipe!$H$9="","—",Equipe!$H$9)) | F30: =IF(Equipe!$A$9="","",IF(Equipe!$I$9="","—",Equipe!$I$9)) | G30: =IF(Equipe!$A$9="","",IF(Equipe!$J$9="","—",Equipe!$J$9))
A31: =IF(Equipe!$A$10="","",Equipe!$A$10) | B31: =IF(Equipe!$A$10="","",Equipe!$B$10) | C31: =IF(Equipe!$A$10="","",Equipe!$C$10) | D31: =IF(Equipe!$A$10="","",IF(Equipe!$F$10="","",Equipe!$F$10)) | E31: =IF(Equipe!$A$10="","",IF(Equipe!$H$10="","—",Equipe!$H$10)) | F31: =IF(Equipe!$A$10="","",IF(Equipe!$I$10="","—",Equipe!$I$10)) | G31: =IF(Equipe!$A$10="","",IF(Equipe!$J$10="","—",Equipe!$J$10))
A32: =IF(Equipe!$A$11="","",Equipe!$A$11) | B32: =IF(Equipe!$A$11="","",Equipe!$B$11) | C32: =IF(Equipe!$A$11="","",Equipe!$C$11) | D32: =IF(Equipe!$A$11="","",IF(Equipe!$F$11="","",Equipe!$F$11)) | E32: =IF(Equipe!$A$11="","",IF(Equipe!$H$11="","—",Equipe!$H$11)) | F32: =IF(Equipe!$A$11="","",IF(Equipe!$I$11="","—",Equipe!$I$11)) | G32: =IF(Equipe!$A$11="","",IF(Equipe!$J$11="","—",Equipe!$J$11))
A33: =IF(Equipe!$A$12="","",Equipe!$A$12) | B33: =IF(Equipe!$A$12="","",Equipe!$B$12) | C33: =IF(Equipe!$A$12="","",Equipe!$C$12) | D33: =IF(Equipe!$A$12="","",IF(Equipe!$F$12="","",Equipe!$F$12)) | E33: =IF(Equipe!$A$12="","",IF(Equipe!$H$12="","—",Equipe!$H$12)) | F33: =IF(Equipe!$A$12="","",IF(Equipe!$I$12="","—",Equipe!$I$12)) | G33: =IF(Equipe!$A$12="","",IF(Equipe!$J$12="","—",Equipe!$J$12))
A34: =IF(Equipe!$A$13="","",Equipe!$A$13) | B34: =IF(Equipe!$A$13="","",Equipe!$B$13) | C34: =IF(Equipe!$A$13="","",Equipe!$C$13) | D34: =IF(Equipe!$A$13="","",IF(Equipe!$F$13="","",Equipe!$F$13)) | E34: =IF(Equipe!$A$13="","",IF(Equipe!$H$13="","—",Equipe!$H$13)) | F34: =IF(Equipe!$A$13="","",IF(Equipe!$I$13="","—",Equipe!$I$13)) | G34: =IF(Equipe!$A$13="","",IF(Equipe!$J$13="","—",Equipe!$J$13))
A35: =IF(Equipe!$A$14="","",Equipe!$A$14) | B35: =IF(Equipe!$A$14="","",Equipe!$B$14) | C35: =IF(Equipe!$A$14="","",Equipe!$C$14) | D35: =IF(Equipe!$A$14="","",IF(Equipe!$F$14="","",Equipe!$F$14)) | E35: =IF(Equipe!$A$14="","",IF(Equipe!$H$14="","—",Equipe!$H$14)) | F35: =IF(Equipe!$A$14="","",IF(Equipe!$I$14="","—",Equipe!$I$14)) | G35: =IF(Equipe!$A$14="","",IF(Equipe!$J$14="","—",Equipe!$J$14))
A36: Quem é pago por repasse ou já está nos custos fixos aparece com "—": não tem custo-hora próprio. O custo-hora completo de cada sócio = pró-labore ÷ horas + rateio da estrutura.
A38: Sensibilidade: e se faltas e horários vazios tirarem horas do mês?
A39: O custo fixo continua e cada hora atendida fica mais cara. Os percentuais em amarelo podem ser trocados; a última linha usa as horas atendidas de verdade (Painel da planilha 01, mês fechado).
A40: Cenário | B40: Queda nas horas | C40: Horas atendidas | D40: Custo-hora | E40: Hora mínima a cobrar | F40: Diferença por hora
A41: Agenda planejada | B41: 0 | C41: =$B$12*(1-B41) -> 140 | D41: =IF(C41=0,"",$B$11/C41) -> 200 | E41: =IF(D41="","",IFERROR(D41/(1-Config!$B$7-Config!$B$8),"")) -> 338.98305 | F41: =IF(D41="","",D41-$D$41) -> 0
A42: ="Queda de "&ROUND(B42*100,0)&"%" -> Queda de 10% | B42: 0.1 | C42: =$B$12*(1-B42) -> 126 | D42: =IF(C42=0,"",$B$11/C42) -> 222.22222 | E42: =IF(D42="","",IFERROR(D42/(1-Config!$B$7-Config!$B$8),"")) -> 376.64783 | F42: =IF(D42="","",D42-$D$41) -> 22.222222
A43: ="Queda de "&ROUND(B43*100,0)&"%" -> Queda de 20% | B43: 0.2 | C43: =$B$12*(1-B43) -> 112 | D43: =IF(C43=0,"",$B$11/C43) -> 250 | E43: =IF(D43="","",IFERROR(D43/(1-Config!$B$7-Config!$B$8),"")) -> 423.72881 | F43: =IF(D43="","",D43-$D$41) -> 50
A44: ="Queda de "&ROUND(B44*100,0)&"%" -> Queda de 30% | B44: 0.3 | C44: =$B$12*(1-B44) -> 98 | D44: =IF(C44=0,"",$B$11/C44) -> 285.71429 | E44: =IF(D44="","",IFERROR(D44/(1-Config!$B$7-Config!$B$8),"")) -> 484.2615 | F44: =IF(D44="","",D44-$D$41) -> 85.714286
...

Sheet Config
A1: Configurações
A2: Células amarelas: você preenche. Margem e impostos definem a hora mínima a cobrar.
A4: Nome da clínica | B4: Clínica Vida Plena (exemplo fictício)
A5: Mês de referência | B5: Setembro de 2026
A6: Data de referência | B6: 46279
A7: Margem mínima sobre o preço (%) | B7: 0.3 | C7: Quanto do preço deve sobrar depois de pagar o custo da clínica. 30 % é um ponto de partida; ajuste ao seu mercado.
A8: Impostos sobre o que entra (%) | B8: 0.11 | C8: Percentual de imposto que sai de cada real recebido pela PJ médica. No exemplo, 11 %: alíquota efetiva combinada com o contador (Simples, anexo III ou V, simplificado). Confira a sua com o contador. Só imposto: a taxa da maquininha NÃO entra aqui (ela é despesa variável, conciliada na 16 e lançada no caixa 09 e no resultado 18), e o convênio, que não passa na maquininha, pagaria a taxa sem dever.
A9: Arredondar a hora mínima para múltiplos de (R$) | B9: 5 | C9: Só para o número ficar redondo na tabela de preços.
A10: Duração de uma consulta (minutos), para o custo do horário vazio | B10: 30
A12: Custo da hora de atendimento = (custos fixos + pró-labore dos sócios) ÷ horas de atendimento planejadas no mês. Hora mínima = custo-hora ÷ (1 − margem − impostos): a margem é sobre o preço, não sobre o custo.
A13: No exemplo: R$ 28.000 ÷ 140 h = R$ 200,00; hora mínima R$ 338,98 → R$ 340. As planilhas 06, 07 e 08 usam este custo-hora. A médica parceira não entra: o repasse dela é custo variável (planilha 11).

Sheet Custos fixos
A1: Custos fixos do mês
A2: Tudo que a clínica paga todo mês mesmo com a agenda vazia. Preencha de cima para baixo, sem pular linha.
A4: Custo fixo | B4: Valor mensal (R$) | C4: Observação
A5: Aluguel e condomínio | B5: 3900
A6: Recepção (salário e encargos) | B6: 3100 | C6: Bruna Carvalho (CLT): a mesma pessoa da aba Equipe, marcada "Sim" lá
A7: Contador | B7: 600
A8: Sistema de agenda e assinaturas | B8: 300
A9: Energia, água, internet e telefone | B9: 550
A10: Limpeza e material de escritório | B10: 450
A11: Marketing e site | B11: 650
A12: Anuidade CRM, seguro e cursos | B12: 450
A36: Total de custos fixos | B36: =SUM(B5:B34) -> 10000
A38: Pró-labore dos sócios vai na aba Equipe. Salário da recepção com encargos fica aqui (e marcado "Sim" na Equipe, para não contar duas vezes). Materiais de atendimento, taxas de cartão e repasse não são fixos: ficam na precificação (06) e no caixa (09).

Sheet Equipe
A1: Equipe, pró-labore e horas de atendimento
A2: Uma linha por pessoa. Horas de atendimento: as horas de agenda planejadas no mês (turnos × semanas). Quem é pago por repasse não entra no custo-hora.
A4: Pessoa | B4: Papel | C4: Remuneração | D4: Valor mensal (R$) | E4: Já está nos custos fixos? | F4: Horas de atendimento planejadas no mês | G4: Entra no custo-hora? | H4: Custo direto por hora | I4: Custo-hora completo | J4: Hora mínima a cobrar
A5: Dra. Carolina Mendes | B5: Sócia · clínica médica | C5: Pró-labore | D5: 9000 | E5: Não | F5: 70 | G5: Sim | H5: =IF(OR(A5="",G5<>"Sim",F5="",F5=0),"",IF(E5="Sim",0,D5)/F5) -> 128.57143 | I5: =IF(H5="","",H5+Painel!$B$20) -> 200 | J5: =IF(I5="","",IFERROR(I5/(1-Config!$B$7-Config!$B$8),"")) -> 338.98305
A6: Dr. Paulo Andrade | B6: Sócio · cardiologia | C6: Pró-labore | D6: 9000 | E6: Não | F6: 70 | G6: Sim | H6: =IF(OR(A6="",G6<>"Sim",F6="",F6=0),"",IF(E6="Sim",0,D6)/F6) -> 128.57143 | I6: =IF(H6="","",H6+Painel!$B$20) -> 200 | J6: =IF(I6="","",IFERROR(I6/(1-Config!$B$7-Config!$B$8),"")) -> 338.98305
A7: Dra. Renata Sousa | B7: Médica parceira · endocrinologia | C7: Repasse | E7: Não | F7: 35 | G7: Não | H7: =IF(OR(A7="",G7<>"Sim",F7="",F7=0),"",IF(E7="Sim",0,D7)/F7) | I7: =IF(H7="","",H7+Painel!$B$20) | J7: =IF(I7="","",IFERROR(I7/(1-Config!$B$7-Config!$B$8),""))
A8: Bruna Carvalho | B8: Recepcionista (CLT) | C8: Salário | D8: 2200 | E8: Sim | G8: Não | H8: =IF(OR(A8="",G8<>"Sim",F8="",F8=0),"",IF(E8="Sim",0,D8)/F8) | I8: =IF(H8="","",H8+Painel!$B$20) | J8: =IF(I8="","",IFERROR(I8/(1-Config!$B$7-Config!$B$8),""))
H9: =IF(OR(A9="",G9<>"Sim",F9="",F9=0),"",IF(E9="Sim",0,D9)/F9) | I9: =IF(H9="","",H9+Painel!$B$20) | J9: =IF(I9="","",IFERROR(I9/(1-Config!$B$7-Config!$B$8),""))
H10: =IF(OR(A10="",G10<>"Sim",F10="",F10=0),"",IF(E10="Sim",0,D10)/F10) | I10: =IF(H10="","",H10+Painel!$B$20) | J10: =IF(I10="","",IFERROR(I10/(1-Config!$B$7-Config!$B$8),""))
H11: =IF(OR(A11="",G11<>"Sim",F11="",F11=0),"",IF(E11="Sim",0,D11)/F11) | I11: =IF(H11="","",H11+Painel!$B$20) | J11: =IF(I11="","",IFERROR(I11/(1-Config!$B$7-Config!$B$8),""))
H12: =IF(OR(A12="",G12<>"Sim",F12="",F12=0),"",IF(E12="Sim",0,D12)/F12) | I12: =IF(H12="","",H12+Painel!$B$20) | J12: =IF(I12="","",IFERROR(I12/(1-Config!$B$7-Config!$B$8),""))
H13: =IF(OR(A13="",G13<>"Sim",F13="",F13=0),"",IF(E13="Sim",0,D13)/F13) | I13: =IF(H13="","",H13+Painel!$B$20) | J13: =IF(I13="","",IFERROR(I13/(1-Config!$B$7-Config!$B$8),""))
H14: =IF(OR(A14="",G14<>"Sim",F14="",F14=0),"",IF(E14="Sim",0,D14)/F14) | I14: =IF(H14="","",H14+Painel!$B$20) | J14: =IF(I14="","",IFERROR(I14/(1-Config!$B$7-Config!$B$8),""))
A16: Custo direto por hora = pró-labore ÷ horas de atendimento. Custo-hora completo = custo direto + rateio dos custos fixos por hora (calculado no Painel). Hora mínima = custo-hora completo ÷ (1 − margem − impostos).
A17: Horas de atendimento planejadas: turnos da semana × 4,33 semanas (a planilha 01 mostra as disponíveis e as atendidas de verdade). Médico parceiro por repasse: "Entra no custo-hora? = Não". O custo da estrutura já está inteiro dentro do custo-hora dos sócios; por isso, na planilha 11, o custo indireto por hora entra só como informação e a margem da parceria desconta o material, não a estrutura de novo.
