Workbook

Sheet Como usar
A1: Convênios a receber
A2: Kit de Gestão para Médicos · Seu Sócio Gestor · versão 1.0 (setembro de 2026)
A4: O que esta planilha faz | B4: Responde "quanto o convênio deve e quanto ele não pagou?": cada lote enviado (convênio × mês) com previsão de pagamento pelo prazo do contrato, o que foi pago, a glosa, o recurso e o que foi recuperado; por convênio, por mês e a lista de guias glosadas para recorrer.
A5: Passo 1 | B5: Em Config, cadastre cada convênio com o prazo contratual de pagamento (dias após o envio) e o dia de envio do lote. Preencha de cima para baixo, sem pular linha.
A6: Passo 2 | B6: Em Guias, uma linha por atendimento de convênio realizado (copie da Agenda da planilha 01: data, paciente, convênio, procedimento, profissional, valor). É a base do lote do mês.
A7: Passo 3 | B7: Em Lotes, uma linha por convênio e mês: nº de guias, valor enviado e data de envio. Quando o pagamento cair, digite data e valor pago (a glosa é a diferença) e lance a entrada no caixa (09). Se recorrer, marque o recurso; se aceito, o valor recuperado e a data. Volte em Guias e marque as guias glosadas.
A8: Passo 4 | B8: Em Painel: a receber, atrasado, glosa do ano (R$ e %), em recurso; por convênio (com prazo real × contratual), lotes em aberto, mês a mês e as guias glosadas para recorrer.
A9: Rotina | B9: Sexta, 3 minutos (rotina da semana, planilha 03): separar as guias da semana e conferir se todas estão na aba Guias. Dia 5: enviar o lote do mês anterior e registrar. No recebimento: pagamento, glosa e recurso. A planilha avisa o atraso; a cobrança ao convênio é sua.
A10: Ligação com as outras planilhas | B10: A receber e atrasado vão para o Painel da clínica (17); a glosa % por convênio alimenta o simulador (07); os lotes pagos são entradas do caixa (09). As metas do trimestre (19) acompanham glosa, atrasos e recuperado.
A11: Com a IA | B11: Copie "Por convênio" e use o prompt "Recebíveis 01 · Resumir os convênios para o sócio" da biblioteca do kit; para uma guia glosada, "Recebíveis 03 · Recurso de glosa em linguagem administrativa" (sem dados clínicos: só guia, procedimento, data e motivo administrativo).
A12: Legenda | B12: Células amarelas: você preenche. Brancas: calculadas. Não é preciso mexer em nada fora do amarelo.
A13: Proteção | B13: Fórmulas protegidas sem senha. Para editar: Revisar > Desproteger planilha (Excel) ou Dados > Proteger intervalos (Google Sheets).
A14: Requisitos | B14: Excel 2016 ou mais novo, Microsoft 365 ou Google Sheets (só funções do Excel 2007+; nada de MÍNIMOSES, MÁXIMOSES ou UNIRTEXTO). No celular abre nos aplicativos; para preencher, use o computador.
A15: Dados de pacientes | B15: Guarde só o que a gestão precisa (nome, contato, valor, data). Nada de diagnóstico, prontuário ou exame nestas planilhas: o kit é gestão, não é prontuário. Veja o guia LGPD do kit antes de colar qualquer tabela em uma IA.
... A19: Suporte | B19: suporte@seusociogestor.com.br · resposta em até 5 dias úteis · reembolso em até 7 dias pelo mesmo canal.

Sheet Painel
A1: =Config!$B$4&" · Convênios a receber · "&TEXT(DAY(Config!$B$5),"00")&"/"&TEXT(MONTH(Config!$B$5),"00")&"/"&YEAR(Config!$B$5) -> Clínica Vida Plena (exemplo fictício) · Convênios a receber · 14/09/2026
A2: Nada para digitar aqui: tudo vem de Lotes, Guias e Config. A receber = lotes enviados e ainda não pagos (valor enviado).
A4: A receber (lotes enviados) | C4: Atrasado | E4: Recebido no ano | G4: Glosa no ano (R$) | I4: Glosa no ano (%) | K4: Em recurso (R$)
A5: =SUMIFS(Lotes!$D$5:$D$154,Lotes!$N$5:$N$154,"Aguardando")+SUMIFS(Lotes!$D$5:$D$154,Lotes!$N$5:$N$154,"Atrasada") -> 15758 | C5: =SUMIFS(Lotes!$D$5:$D$154,Lotes!$N$5:$N$154,"Atrasada") -> 1727 | E5: =SUMIFS(Lotes!$G$5:$G$154,Lotes!$F$5:$F$154,">="&DATE(Config!$B$6,1,1),Lotes!$F$5:$F$154,"<="&DATE(Config!$B$6,12,31))+SUMIFS(Lotes!$I$5:$I$154,Lotes!$J$5:$J$154,">="&DATE(Config!$B$6,1,1),Lotes!$J$5:$J$154,"<="&DATE(Config!$B$6,12,31)) -> 73702 | G5: =SUMIFS(Lotes!$M$5:$M$154,Lotes!$F$5:$F$154,">="&DATE(Config!$B$6,1,1),Lotes!$F$5:$F$154,"<="&DATE(Config!$B$6,12,31)) -> 4273 | I5: =IFERROR(G5/(SUMIFS(Lotes!$G$5:$G$154,Lotes!$F$5:$F$154,">="&DATE(Config!$B$6,1,1),Lotes!$F$5:$F$154,"<="&DATE(Config!$B$6,12,31))+G5),0) -> 0.055367671 | K5: =SUMIFS(Lotes!$M$5:$M$154,Lotes!$H$5:$H$154,"Em recurso") -> 240
A7: Glosa (%) = glosa ÷ (pago + glosa) dos lotes pagos no ano: de tudo o que o convênio decidiu, quanto ele não pagou. Recebido no ano inclui glosa recuperada por recurso. Em separação (mês corrente) não conta como a receber até o envio.
A9: Por convênio (lotes enviados no ano)
A10: Convênio | B10: Lotes | C10: Enviado (R$) | D10: Pago (R$) | E10: Glosa (R$) | F10: Glosa (%) | G10: Recuperado (R$) | H10: A receber (R$) | I10: Atrasado (R$) | J10: Prazo contratual | K10: Prazo real (média, dias) | L10: Barra da glosa
A11: =IF(Config!$A$10="","",Config!$A$10) -> Saúde Total | B11: =IF(Config!$A$10="","",COUNTIFS(Lotes!$A$5:$A$154,Config!$A$10,Lotes!$E$5:$E$154,">="&DATE(Config!$B$6,1,1),Lotes!$E$5:$E$154,"<="&DATE(Config!$B$6,12,31))) -> 9 | C11: =IF(Config!$A$10="","",SUMIFS(Lotes!$D$5:$D$154,Lotes!$A$5:$A$154,Config!$A$10,Lotes!$E$5:$E$154,">="&DATE(Config!$B$6,1,1),Lotes!$E$5:$E$154,"<="&DATE(Config!$B$6,12,31))) -> 47560 | D11: =IF(Config!$A$10="","",SUMIFS(Lotes!$G$5:$G$154,Lotes!$A$5:$A$154,Config!$A$10,Lotes!$F$5:$F$154,">="&DATE(Config!$B$6,1,1),Lotes!$F$5:$F$154,"<="&DATE(Config!$B$6,12,31))) -> 45565 | E11: =IF(Config!$A$10="","",SUMIFS(Lotes!$M$5:$M$154,Lotes!$A$5:$A$154,Config!$A$10,Lotes!$F$5:$F$154,">="&DATE(Config!$B$6,1,1),Lotes!$F$5:$F$154,"<="&DATE(Config!$B$6,12,31))) -> 1550 | F11: =IF(Config!$A$10="","",IFERROR(E11/(D11+E11),0)) -> 0.032898228 | G11: =IF(Config!$A$10="","",SUMIFS(Lotes!$I$5:$I$154,Lotes!$A$5:$A$154,Config!$A$10,Lotes!$J$5:$J$154,">="&DATE(Config!$B$6,1,1),Lotes!$J$5:$J$154,"<="&DATE(Config!$B$6,12,31))) -> 140 | H11: =IF(Config!$A$10="","",SUMIFS(Lotes!$D$5:$D$154,Lotes!$A$5:$A$154,Config!$A$10,Lotes!$N$5:$N$154,"Aguardando")+SUMIFS(Lotes!$D$5:$D$154,Lotes!$A$5:$A$154,Config!$A$10,Lotes!$N$5:$N$154,"Atrasada")) -> 4555 | I11: =IF(Config!$A$10="","",SUMIFS(Lotes!$D$5:$D$154,Lotes!$A$5:$A$154,Config!$A$10,Lotes!$N$5:$N$154,"Atrasada")) -> 0 | J11: =IF(Config!$A$10="","",Config!$B$10) -> 30 | K11: =IF(Config!$A$10="","",IFERROR(AVERAGEIFS(Lotes!$T$5:$T$154,Lotes!$A$5:$A$154,Config!$A$10,Lotes!$F$5:$F$154,">="&DATE(Config!$B$6,1,1),Lotes!$F$5:$F$154,"<="&DATE(Config!$B$6,12,31)),"—")) -> 32.111111 | L11: =IF(F11="","",REPT("█",ROUND(MIN(1,F11/0.15)*20,0))) -> ████
A12: =IF(Config!$A$11="","",Config!$A$11) -> MediPlan | B12: =IF(Config!$A$11="","",COUNTIFS(Lotes!$A$5:$A$154,Config!$A$11,Lotes!$E$5:$E$154,">="&DATE(Config!$B$6,1,1),Lotes!$E$5:$E$154,"<="&DATE(Config!$B$6,12,31))) -> 9 | C12: =IF(Config!$A$11="","",SUMIFS(Lotes!$D$5:$D$154,Lotes!$A$5:$A$154,Config!$A$11,Lotes!$E$5:$E$154,">="&DATE(Config!$B$6,1,1),Lotes!$E$5:$E$154,"<="&DATE(Config!$B$6,12,31))) -> 20985 | D12: =IF(Config!$A$11="","",SUMIFS(Lotes!$G$5:$G$154,Lotes!$A$5:$A$154,Config!$A$11,Lotes!$F$5:$F$154,">="&DATE(Config!$B$6,1,1),Lotes!$F$5:$F$154,"<="&DATE(Config!$B$6,12,31))) -> 16120 | E12: =IF(Config!$A$11="","",SUMIFS(Lotes!$M$5:$M$154,Lotes!$A$5:$A$154,Config!$A$11,Lotes!$F$5:$F$154,">="&DATE(Config!$B$6,1,1),Lotes!$F$5:$F$154,"<="&DATE(Config!$B$6,12,31))) -> 1300 | F12: =IF(Config!$A$11="","",IFERROR(E12/(D12+E12),0)) -> 0.074626866 | G12: =IF(Config!$A$11="","",SUMIFS(Lotes!$I$5:$I$154,Lotes!$A$5:$A$154,Config!$A$11,Lotes!$J$5:$J$154,">="&DATE(Config!$B$6,1,1),Lotes!$J$5:$J$154,"<="&DATE(Config!$B$6,12,31))) -> 130 | H12: =IF(Config!$A$11="","",SUMIFS(Lotes!$D$5:$D$154,Lotes!$A$5:$A$154,Config!$A$11,Lotes!$N$5:$N$154,"Aguardando")+SUMIFS(Lotes!$D$5:$D$154,Lotes!$A$5:$A$154,Config!$A$11,Lotes!$N$5:$N$154,"Atrasada")) -> 6305 | I12: =IF(Config!$A$11="","",SUMIFS(Lotes!$D$5:$D$154,Lotes!$A$5:$A$154,Config!$A$11,Lotes!$N$5:$N$154,"Atrasada")) -> 0 | J12: =IF(Config!$A$11="","",Config!$B$11) -> 45 | K12: =IF(Config!$A$11="","",IFERROR(AVERAGEIFS(Lotes!$T$5:$T$154,Lotes!$A$5:$A$154,Config!$A$11,Lotes!$F$5:$F$154,">="&DATE(Config!$B$6,1,1),Lotes!$F$5:$F$154,"<="&DATE(Config!$B$6,12,31)),"—")) -> 46.625 | L12: =IF(F12="","",REPT("█",ROUND(MIN(1,F12/0.15)*20,0))) -> ██████████
A13: =IF(Config!$A$12="","",Config!$A$12) -> Vida Care | B13: =IF(Config!$A$12="","",COUNTIFS(Lotes!$A$5:$A$154,Config!$A$12,Lotes!$E$5:$E$154,">="&DATE(Config!$B$6,1,1),Lotes!$E$5:$E$154,"<="&DATE(Config!$B$6,12,31))) -> 9 | C13: =IF(Config!$A$12="","",SUMIFS(Lotes!$D$5:$D$154,Lotes!$A$5:$A$154,Config!$A$12,Lotes!$E$5:$E$154,">="&DATE(Config!$B$6,1,1),Lotes!$E$5:$E$154,"<="&DATE(Config!$B$6,12,31))) -> 14228 | D13: =IF(Config!$A$12="","",SUMIFS(Lotes!$G$5:$G$154,Lotes!$A$5:$A$154,Config!$A$12,Lotes!$F$5:$F$154,">="&DATE(Config!$B$6,1,1),Lotes!$F$5:$F$154,"<="&DATE(Config!$B$6,12,31))) -> 11217 | E13: =IF(Config!$A$12="","",SUMIFS(Lotes!$M$5:$M$154,Lotes!$A$5:$A$154,Config!$A$12,Lotes!$F$5:$F$154,">="&DATE(Config!$B$6,1,1),Lotes!$F$5:$F$154,"<="&DATE(Config!$B$6,12,31))) -> 1423 | F13: =IF(Config!$A$12="","",IFERROR(E13/(D13+E13),0)) -> 0.11257911 | G13: =IF(Config!$A$12="","",SUMIFS(Lotes!$I$5:$I$154,Lotes!$A$5:$A$154,Config!$A$12,Lotes!$J$5:$J$154,">="&DATE(Config!$B$6,1,1),Lotes!$J$5:$J$154,"<="&DATE(Config!$B$6,12,31))) -> 530 | H13: =IF(Config!$A$12="","",SUMIFS(Lotes!$D$5:$D$154,Lotes!$A$5:$A$154,Config!$A$12,Lotes!$N$5:$N$154,"Aguardando")+SUMIFS(Lotes!$D$5:$D$154,Lotes!$A$5:$A$154,Config!$A$12,Lotes!$N$5:$N$154,"Atrasada")) -> 4898 | I13: =IF(Config!$A$12="","",SUMIFS(Lotes!$D$5:$D$154,Lotes!$A$5:$A$154,Config!$A$12,Lotes!$N$5:$N$154,"Atrasada")) -> 1727 | J13: =IF(Config!$A$12="","",Config!$B$12) -> 60 | K13: =IF(Config!$A$12="","",IFERROR(AVERAGEIFS(Lotes!$T$5:$T$154,Lotes!$A$5:$A$154,Config!$A$12,Lotes!$F$5:$F$154,">="&DATE(Config!$B$6,1,1),Lotes!$F$5:$F$154,"<="&DATE(Config!$B$6,12,31)),"—")) -> 60.875 | L13: =IF(F13="","",REPT("█",ROUND(MIN(1,F13/0.15)*20,0))) -> ███████████████
A14: =IF(Config!$A$13="","",Config!$A$13) | B14: =IF(Config!$A$13="","",COUNTIFS(Lotes!$A$5:$A$154,Config!$A$13,Lotes!$E$5:$E$154,">="&DATE(Config!$B$6,1,1),Lotes!$E$5:$E$154,"<="&DATE(Config!$B$6,12,31))) | C14: =IF(Config!$A$13="","",SUMIFS(Lotes!$D$5:$D$154,Lotes!$A$5:$A$154,Config!$A$13,Lotes!$E$5:$E$154,">="&DATE(Config!$B$6,1,1),Lotes!$E$5:$E$154,"<="&DATE(Config!$B$6,12,31))) | D14: =IF(Config!$A$13="","",SUMIFS(Lotes!$G$5:$G$154,Lotes!$A$5:$A$154,Config!$A$13,Lotes!$F$5:$F$154,">="&DATE(Config!$B$6,1,1),Lotes!$F$5:$F$154,"<="&DATE(Config!$B$6,12,31))) | E14: =IF(Config!$A$13="","",SUMIFS(Lotes!$M$5:$M$154,Lotes!$A$5:$A$154,Config!$A$13,Lotes!$F$5:$F$154,">="&DATE(Config!$B$6,1,1),Lotes!$F$5:$F$154,"<="&DATE(Config!$B$6,12,31))) | F14: =IF(Config!$A$13="","",IFERROR(E14/(D14+E14),0)) | G14: =IF(Config!$A$13="","",SUMIFS(Lotes!$I$5:$I$154,Lotes!$A$5:$A$154,Config!$A$13,Lotes!$J$5:$J$154,">="&DATE(Config!$B$6,1,1),Lotes!$J$5:$J$154,"<="&DATE(Config!$B$6,12,31))) | H14: =IF(Config!$A$13="","",SUMIFS(Lotes!$D$5:$D$154,Lotes!$A$5:$A$154,Config!$A$13,Lotes!$N$5:$N$154,"Aguardando")+SUMIFS(Lotes!$D$5:$D$154,Lotes!$A$5:$A$154,Config!$A$13,Lotes!$N$5:$N$154,"Atrasada")) | I14: =IF(Config!$A$13="","",SUMIFS(Lotes!$D$5:$D$154,Lotes!$A$5:$A$154,Config!$A$13,Lotes!$N$5:$N$154,"Atrasada")) | J14: =IF(Config!$A$13="","",Config!$B$13) | K14: =IF(Config!$A$13="","",IFERROR(AVERAGEIFS(Lotes!$T$5:$T$154,Lotes!$A$5:$A$154,Config!$A$13,Lotes!$F$5:$F$154,">="&DATE(Config!$B$6,1,1),Lotes!$F$5:$F$154,"<="&DATE(Config!$B$6,12,31)),"—")) | L14: =IF(F14="","",REPT("█",ROUND(MIN(1,F14/0.15)*20,0)))
A15: =IF(Config!$A$14="","",Config!$A$14) | B15: =IF(Config!$A$14="","",COUNTIFS(Lotes!$A$5:$A$154,Config!$A$14,Lotes!$E$5:$E$154,">="&DATE(Config!$B$6,1,1),Lotes!$E$5:$E$154,"<="&DATE(Config!$B$6,12,31))) | C15: =IF(Config!$A$14="","",SUMIFS(Lotes!$D$5:$D$154,Lotes!$A$5:$A$154,Config!$A$14,Lotes!$E$5:$E$154,">="&DATE(Config!$B$6,1,1),Lotes!$E$5:$E$154,"<="&DATE(Config!$B$6,12,31))) | D15: =IF(Config!$A$14="","",SUMIFS(Lotes!$G$5:$G$154,Lotes!$A$5:$A$154,Config!$A$14,Lotes!$F$5:$F$154,">="&DATE(Config!$B$6,1,1),Lotes!$F$5:$F$154,"<="&DATE(Config!$B$6,12,31))) | E15: =IF(Config!$A$14="","",SUMIFS(Lotes!$M$5:$M$154,Lotes!$A$5:$A$154,Config!$A$14,Lotes!$F$5:$F$154,">="&DATE(Config!$B$6,1,1),Lotes!$F$5:$F$154,"<="&DATE(Config!$B$6,12,31))) | F15: =IF(Config!$A$14="","",IFERROR(E15/(D15+E15),0)) | G15: =IF(Config!$A$14="","",SUMIFS(Lotes!$I$5:$I$154,Lotes!$A$5:$A$154,Config!$A$14,Lotes!$J$5:$J$154,">="&DATE(Config!$B$6,1,1),Lotes!$J$5:$J$154,"<="&DATE(Config!$B$6,12,31))) | H15: =IF(Config!$A$14="","",SUMIFS(Lotes!$D$5:$D$154,Lotes!$A$5:$A$154,Config!$A$14,Lotes!$N$5:$N$154,"Aguardando")+SUMIFS(Lotes!$D$5:$D$154,Lotes!$A$5:$A$154,Config!$A$14,Lotes!$N$5:$N$154,"Atrasada")) | I15: =IF(Config!$A$14="","",SUMIFS(Lotes!$D$5:$D$154,Lotes!$A$5:$A$154,Config!$A$14,Lotes!$N$5:$N$154,"Atrasada")) | J15: =IF(Config!$A$14="","",Config!$B$14) | K15: =IF(Config!$A$14="","",IFERROR(AVERAGEIFS(Lotes!$T$5:$T$154,Lotes!$A$5:$A$154,Config!$A$14,Lotes!$F$5:$F$154,">="&DATE(Config!$B$6,1,1),Lotes!$F$5:$F$154,"<="&DATE(Config!$B$6,12,31)),"—")) | L15: =IF(F15="","",REPT("█",ROUND(MIN(1,F15/0.15)*20,0)))
A16: =IF(Config!$A$15="","",Config!$A$15) | B16: =IF(Config!$A$15="","",COUNTIFS(Lotes!$A$5:$A$154,Config!$A$15,Lotes!$E$5:$E$154,">="&DATE(Config!$B$6,1,1),Lotes!$E$5:$E$154,"<="&DATE(Config!$B$6,12,31))) | C16: =IF(Config!$A$15="","",SUMIFS(Lotes!$D$5:$D$154,Lotes!$A$5:$A$154,Config!$A$15,Lotes!$E$5:$E$154,">="&DATE(Config!$B$6,1,1),Lotes!$E$5:$E$154,"<="&DATE(Config!$B$6,12,31))) | D16: =IF(Config!$A$15="","",SUMIFS(Lotes!$G$5:$G$154,Lotes!$A$5:$A$154,Config!$A$15,Lotes!$F$5:$F$154,">="&DATE(Config!$B$6,1,1),Lotes!$F$5:$F$154,"<="&DATE(Config!$B$6,12,31))) | E16: =IF(Config!$A$15="","",SUMIFS(Lotes!$M$5:$M$154,Lotes!$A$5:$A$154,Config!$A$15,Lotes!$F$5:$F$154,">="&DATE(Config!$B$6,1,1),Lotes!$F$5:$F$154,"<="&DATE(Config!$B$6,12,31))) | F16: =IF(Config!$A$15="","",IFERROR(E16/(D16+E16),0)) | G16: =IF(Config!$A$15="","",SUMIFS(Lotes!$I$5:$I$154,Lotes!$A$5:$A$154,Config!$A$15,Lotes!$J$5:$J$154,">="&DATE(Config!$B$6,1,1),Lotes!$J$5:$J$154,"<="&DATE(Config!$B$6,12,31))) | H16: =IF(Config!$A$15="","",SUMIFS(Lotes!$D$5:$D$154,Lotes!$A$5:$A$154,Config!$A$15,Lotes!$N$5:$N$154,"Aguardando")+SUMIFS(Lotes!$D$5:$D$154,Lotes!$A$5:$A$154,Config!$A$15,Lotes!$N$5:$N$154,"Atrasada")) | I16: =IF(Config!$A$15="","",SUMIFS(Lotes!$D$5:$D$154,Lotes!$A$5:$A$154,Config!$A$15,Lotes!$N$5:$N$154,"Atrasada")) | J16: =IF(Config!$A$15="","",Config!$B$15) | K16: =IF(Config!$A$15="","",IFERROR(AVERAGEIFS(Lotes!$T$5:$T$154,Lotes!$A$5:$A$154,Config!$A$15,Lotes!$F$5:$F$154,">="&DATE(Config!$B$6,1,1),Lotes!$F$5:$F$154,"<="&DATE(Config!$B$6,12,31)),"—")) | L16: =IF(F16="","",REPT("█",ROUND(MIN(1,F16/0.15)*20,0)))
A17: Glosa acima de 5 % e prazo real acima do contratual ficam em vermelho: são os dois argumentos da conversa com o convênio. A barra da glosa vai até 15 %.
A19: Lotes em aberto: atrasados primeiro, depois os maiores
A20: # | B20: Convênio | C20: Competência | D20: Nº de guias | E20: Enviado (R$) | F20: Data de envio | G20: Previsão | H20: Situação | I20: Dias de atraso
A21: 1 | B21: =IFERROR(IF(LARGE(Lotes!$S$5:$S$154,1)>0,INDEX(Lotes!$A$5:$A$154,MATCH(LARGE(Lotes!$S$5:$S$154,1),Lotes!$S$5:$S$154,0)),""),"") -> Vida Care | C21: =IFERROR(IF(LARGE(Lotes!$S$5:$S$154,1)>0,INDEX(Lotes!$B$5:$B$154,MATCH(LARGE(Lotes!$S$5:$S$154,1),Lotes!$S$5:$S$154,0)),""),"") -> 46174 | D21: =IFERROR(IF(LARGE(Lotes!$S$5:$S$154,1)>0,INDEX(Lotes!$C$5:$C$154,MATCH(LARGE(Lotes!$S$5:$S$154,1),Lotes!$S$5:$S$154,0)),""),"") -> 19 | E21: =IFERROR(IF(LARGE(Lotes!$S$5:$S$154,1)>0,INDEX(Lotes!$D$5:$D$154,MATCH(LARGE(Lotes!$S$5:$S$154,1),Lotes!$S$5:$S$154,0)),""),"") -> 1727 | F21: =IFERROR(IF(LARGE(Lotes!$S$5:$S$154,1)>0,INDEX(Lotes!$E$5:$E$154,MATCH(LARGE(Lotes!$S$5:$S$154,1),Lotes!$S$5:$S$154,0)),""),"") -> 46209 | G21: =IFERROR(IF(LARGE(Lotes!$S$5:$S$154,1)>0,INDEX(Lotes!$L$5:$L$154,MATCH(LARGE(Lotes!$S$5:$S$154,1),Lotes!$S$5:$S$154,0)),""),"") -> 46269 | H21: =IFERROR(IF(LARGE(Lotes!$S$5:$S$154,1)>0,INDEX(Lotes!$N$5:$N$154,MATCH(LARGE(Lotes!$S$5:$S$154,1),Lotes!$S$5:$S$154,0)),""),"") -> Atrasada | I21: =IFERROR(IF(LARGE(Lotes!$S$5:$S$154,1)>0,INDEX(Lotes!$O$5:$O$154,MATCH(LARGE(Lotes!$S$5:$S$154,1),Lotes!$S$5:$S$154,0)),""),"") -> 10
A22: 2 | B22: =IFERROR(IF(LARGE(Lotes!$S$5:$S$154,2)>0,INDEX(Lotes!$A$5:$A$154,MATCH(LARGE(Lotes!$S$5:$S$154,2),Lotes!$S$5:$S$154,0)),""),"") -> Saúde Total | C22: =IFERROR(IF(LARGE(Lotes!$S$5:$S$154,2)>0,INDEX(Lotes!$B$5:$B$154,MATCH(LARGE(Lotes!$S$5:$S$154,2),Lotes!$S$5:$S$154,0)),""),"") -> 46235 | D22: =IFERROR(IF(LARGE(Lotes!$S$5:$S$154,2)>0,INDEX(Lotes!$C$5:$C$154,MATCH(LARGE(Lotes!$S$5:$S$154,2),Lotes!$S$5:$S$154,0)),""),"") -> 43 | E22: =IFERROR(IF(LARGE(Lotes!$S$5:$S$154,2)>0,INDEX(Lotes!$D$5:$D$154,MATCH(LARGE(Lotes!$S$5:$S$154,2),Lotes!$S$5:$S$154,0)),""),"") -> 4555 | F22: =IFERROR(IF(LARGE(Lotes!$S$5:$S$154,2)>0,INDEX(Lotes!$E$5:$E$154,MATCH(LARGE(Lotes!$S$5:$S$154,2),Lotes!$S$5:$S$154,0)),""),"") -> 46273 | G22: =IFERROR(IF(LARGE(Lotes!$S$5:$S$154,2)>0,INDEX(Lotes!$L$5:$L$154,MATCH(LARGE(Lotes!$S$5:$S$154,2),Lotes!$S$5:$S$154,0)),""),"") -> 46303 | H22: =IFERROR(IF(LARGE(Lotes!$S$5:$S$154,2)>0,INDEX(Lotes!$N$5:$N$154,MATCH(LARGE(Lotes!$S$5:$S$154,2),Lotes!$S$5:$S$154,0)),""),"") -> Aguardando | I22: =IFERROR(IF(LARGE(Lotes!$S$5:$S$154,2)>0,INDEX(Lotes!$O$5:$O$154,MATCH(LARGE(Lotes!$S$5:$S$154,2),Lotes!$S$5:$S$154,0)),""),"")
A23: 3 | B23: =IFERROR(IF(LARGE(Lotes!$S$5:$S$154,3)>0,INDEX(Lotes!$A$5:$A$154,MATCH(LARGE(Lotes!$S$5:$S$154,3),Lotes!$S$5:$S$154,0)),""),"") -> MediPlan | C23: =IFERROR(IF(LARGE(Lotes!$S$5:$S$154,3)>0,INDEX(Lotes!$B$5:$B$154,MATCH(LARGE(Lotes!$S$5:$S$154,3),Lotes!$S$5:$S$154,0)),""),"") -> 46235 | D23: =IFERROR(IF(LARGE(Lotes!$S$5:$S$154,3)>0,INDEX(Lotes!$C$5:$C$154,MATCH(LARGE(Lotes!$S$5:$S$154,3),Lotes!$S$5:$S$154,0)),""),"") -> 34 | E23: =IFERROR(IF(LARGE(Lotes!$S$5:$S$154,3)>0,INDEX(Lotes!$D$5:$D$154,MATCH(LARGE(Lotes!$S$5:$S$154,3),Lotes!$S$5:$S$154,0)),""),"") -> 3430 | F23: =IFERROR(IF(LARGE(Lotes!$S$5:$S$154,3)>0,INDEX(Lotes!$E$5:$E$154,MATCH(LARGE(Lotes!$S$5:$S$154,3),Lotes!$S$5:$S$154,0)),""),"") -> 46273 | G23: =IFERROR(IF(LARGE(Lotes!$S$5:$S$154,3)>0,INDEX(Lotes!$L$5:$L$154,MATCH(LARGE(Lotes!$S$5:$S$154,3),Lotes!$S$5:$S$154,0)),""),"") -> 46318 | H23: =IFERROR(IF(LARGE(Lotes!$S$5:$S$154,3)>0,INDEX(Lotes!$N$5:$N$154,MATCH(LARGE(Lotes!$S$5:$S$154,3),Lotes!$S$5:$S$154,0)),""),"") -> Aguardando | I23: =IFERROR(IF(LARGE(Lotes!$S$5:$S$154,3)>0,INDEX(Lotes!$O$5:$O$154,MATCH(LARGE(Lotes!$S$5:$S$154,3),Lotes!$S$5:$S$154,0)),""),"")
A24: 4 | B24: =IFERROR(IF(LARGE(Lotes!$S$5:$S$154,4)>0,INDEX(Lotes!$A$5:$A$154,MATCH(LARGE(Lotes!$S$5:$S$154,4),Lotes!$S$5:$S$154,0)),""),"") -> MediPlan | C24: =IFERROR(IF(LARGE(Lotes!$S$5:$S$154,4)>0,INDEX(Lotes!$B$5:$B$154,MATCH(LARGE(Lotes!$S$5:$S$154,4),Lotes!$S$5:$S$154,0)),""),"") -> 46204 | D24: =IFERROR(IF(LARGE(Lotes!$S$5:$S$154,4)>0,INDEX(Lotes!$C$5:$C$154,MATCH(LARGE(Lotes!$S$5:$S$154,4),Lotes!$S$5:$S$154,0)),""),"") -> 31 | E24: =IFERROR(IF(LARGE(Lotes!$S$5:$S$154,4)>0,INDEX(Lotes!$D$5:$D$154,MATCH(LARGE(Lotes!$S$5:$S$154,4),Lotes!$S$5:$S$154,0)),""),"") -> 2875 | F24: =IFERROR(IF(LARGE(Lotes!$S$5:$S$154,4)>0,INDEX(Lotes!$E$5:$E$154,MATCH(LARGE(Lotes!$S$5:$S$154,4),Lotes!$S$5:$S$154,0)),""),"") -> 46239 | G24: =IFERROR(IF(LARGE(Lotes!$S$5:$S$154,4)>0,INDEX(Lotes!$L$5:$L$154,MATCH(LARGE(Lotes!$S$5:$S$154,4),Lotes!$S$5:$S$154,0)),""),"") -> 46284 | H24: =IFERROR(IF(LARGE(Lotes!$S$5:$S$154,4)>0,INDEX(Lotes!$N$5:$N$154,MATCH(LARGE(Lotes!$S$5:$S$154,4),Lotes!$S$5:$S$154,0)),""),"") -> Aguardando | I24: =IFERROR(IF(LARGE(Lotes!$S$5:$S$154,4)>0,INDEX(Lotes!$O$5:$O$154,MATCH(LARGE(Lotes!$S$5:$S$154,4),Lotes!$S$5:$S$154,0)),""),"")
A25: 5 | B25: =IFERROR(IF(LARGE(Lotes!$S$5:$S$154,5)>0,INDEX(Lotes!$A$5:$A$154,MATCH(LARGE(Lotes!$S$5:$S$154,5),Lotes!$S$5:$S$154,0)),""),"") -> Vida Care | C25: =IFERROR(IF(LARGE(Lotes!$S$5:$S$154,5)>0,INDEX(Lotes!$B$5:$B$154,MATCH(LARGE(Lotes!$S$5:$S$154,5),Lotes!$S$5:$S$154,0)),""),"") -> 46235 | D25: =IFERROR(IF(LARGE(Lotes!$S$5:$S$154,5)>0,INDEX(Lotes!$C$5:$C$154,MATCH(LARGE(Lotes!$S$5:$S$154,5),Lotes!$S$5:$S$154,0)),""),"") -> 20 | E25: =IFERROR(IF(LARGE(Lotes!$S$5:$S$154,5)>0,INDEX(Lotes!$D$5:$D$154,MATCH(LARGE(Lotes!$S$5:$S$154,5),Lotes!$S$5:$S$154,0)),""),"") -> 1646 | F25: =IFERROR(IF(LARGE(Lotes!$S$5:$S$154,5)>0,INDEX(Lotes!$E$5:$E$154,MATCH(LARGE(Lotes!$S$5:$S$154,5),Lotes!$S$5:$S$154,0)),""),"") -> 46273 | G25: =IFERROR(IF(LARGE(Lotes!$S$5:$S$154,5)>0,INDEX(Lotes!$L$5:$L$154,MATCH(LARGE(Lotes!$S$5:$S$154,5),Lotes!$S$5:$S$154,0)),""),"") -> 46333 | H25: =IFERROR(IF(LARGE(Lotes!$S$5:$S$154,5)>0,INDEX(Lotes!$N$5:$N$154,MATCH(LARGE(Lotes!$S$5:$S$154,5),Lotes!$S$5:$S$154,0)),""),"") -> Aguardando | I25: =IFERROR(IF(LARGE(Lotes!$S$5:$S$154,5)>0,INDEX(Lotes!$O$5:$O$154,MATCH(LARGE(Lotes!$S$5:$S$154,5),Lotes!$S$5:$S$154,0)),""),"")
A26: 6 | B26: =IFERROR(IF(LARGE(Lotes!$S$5:$S$154,6)>0,INDEX(Lotes!$A$5:$A$154,MATCH(LARGE(Lotes!$S$5:$S$154,6),Lotes!$S$5:$S$154,0)),""),"") -> Vida Care | C26: =IFERROR(IF(LARGE(Lotes!$S$5:$S$154,6)>0,INDEX(Lotes!$B$5:$B$154,MATCH(LARGE(Lotes!$S$5:$S$154,6),Lotes!$S$5:$S$154,0)),""),"") -> 46204 | D26: =IFERROR(IF(LARGE(Lotes!$S$5:$S$154,6)>0,INDEX(Lotes!$C$5:$C$154,MATCH(LARGE(Lotes!$S$5:$S$154,6),Lotes!$S$5:$S$154,0)),""),"") -> 20 | E26: =IFERROR(IF(LARGE(Lotes!$S$5:$S$154,6)>0,INDEX(Lotes!$D$5:$D$154,MATCH(LARGE(Lotes!$S$5:$S$154,6),Lotes!$S$5:$S$154,0)),""),"") -> 1525 | F26: =IFERROR(IF(LARGE(Lotes!$S$5:$S$154,6)>0,INDEX(Lotes!$E$5:$E$154,MATCH(LARGE(Lotes!$S$5:$S$154,6),Lotes!$S$5:$S$154,0)),""),"") -> 46239 | G26: =IFERROR(IF(LARGE(Lotes!$S$5:$S$154,6)>0,INDEX(Lotes!$L$5:$L$154,MATCH(LARGE(Lotes!$S$5:$S$154,6),Lotes!$S$5:$S$154,0)),""),"") -> 46299 | H26: =IFERROR(IF(LARGE(Lotes!$S$5:$S$154,6)>0,INDEX(Lotes!$N$5:$N$154,MATCH(LARGE(Lotes!$S$5:$S$154,6),Lotes!$S$5:$S$154,0)),""),"") -> Aguardando | I26: =IFERROR(IF(LARGE(Lotes!$S$5:$S$154,6)>0,INDEX(Lotes!$O$5:$O$154,MATCH(LARGE(Lotes!$S$5:$S$154,6),Lotes!$S$5:$S$154,0)),""),"")
A27: 7 | B27: =IFERROR(IF(LARGE(Lotes!$S$5:$S$154,7)>0,INDEX(Lotes!$A$5:$A$154,MATCH(LARGE(Lotes!$S$5:$S$154,7),Lotes!$S$5:$S$154,0)),""),"") | C27: =IFERROR(IF(LARGE(Lotes!$S$5:$S$154,7)>0,INDEX(Lotes!$B$5:$B$154,MATCH(LARGE(Lotes!$S$5:$S$154,7),Lotes!$S$5:$S$154,0)),""),"") | D27: =IFERROR(IF(LARGE(Lotes!$S$5:$S$154,7)>0,INDEX(Lotes!$C$5:$C$154,MATCH(LARGE(Lotes!$S$5:$S$154,7),Lotes!$S$5:$S$154,0)),""),"") | E27: =IFERROR(IF(LARGE(Lotes!$S$5:$S$154,7)>0,INDEX(Lotes!$D$5:$D$154,MATCH(LARGE(Lotes!$S$5:$S$154,7),Lotes!$S$5:$S$154,0)),""),"") | F27: =IFERROR(IF(LARGE(Lotes!$S$5:$S$154,7)>0,INDEX(Lotes!$E$5:$E$154,MATCH(LARGE(Lotes!$S$5:$S$154,7),Lotes!$S$5:$S$154,0)),""),"") | G27: =IFERROR(IF(LARGE(Lotes!$S$5:$S$154,7)>0,INDEX(Lotes!$L$5:$L$154,MATCH(LARGE(Lotes!$S$5:$S$154,7),Lotes!$S$5:$S$154,0)),""),"") | H27: =IFERROR(IF(LARGE(Lotes!$S$5:$S$154,7)>0,INDEX(Lotes!$N$5:$N$154,MATCH(LARGE(Lotes!$S$5:$S$154,7),Lotes!$S$5:$S$154,0)),""),"") | I27: =IFERROR(IF(LARGE(Lotes!$S$5:$S$154,7)>0,INDEX(Lotes!$O$5:$O$154,MATCH(LARGE(Lotes!$S$5:$S$154,7),Lotes!$S$5:$S$154,0)),""),"")
A28: 8 | B28: =IFERROR(IF(LARGE(Lotes!$S$5:$S$154,8)>0,INDEX(Lotes!$A$5:$A$154,MATCH(LARGE(Lotes!$S$5:$S$154,8),Lotes!$S$5:$S$154,0)),""),"") | C28: =IFERROR(IF(LARGE(Lotes!$S$5:$S$154,8)>0,INDEX(Lotes!$B$5:$B$154,MATCH(LARGE(Lotes!$S$5:$S$154,8),Lotes!$S$5:$S$154,0)),""),"") | D28: =IFERROR(IF(LARGE(Lotes!$S$5:$S$154,8)>0,INDEX(Lotes!$C$5:$C$154,MATCH(LARGE(Lotes!$S$5:$S$154,8),Lotes!$S$5:$S$154,0)),""),"") | E28: =IFERROR(IF(LARGE(Lotes!$S$5:$S$154,8)>0,INDEX(Lotes!$D$5:$D$154,MATCH(LARGE(Lotes!$S$5:$S$154,8),Lotes!$S$5:$S$154,0)),""),"") | F28: =IFERROR(IF(LARGE(Lotes!$S$5:$S$154,8)>0,INDEX(Lotes!$E$5:$E$154,MATCH(LARGE(Lotes!$S$5:$S$154,8),Lotes!$S$5:$S$154,0)),""),"") | G28: =IFERROR(IF(LARGE(Lotes!$S$5:$S$154,8)>0,INDEX(Lotes!$L$5:$L$154,MATCH(LARGE(Lotes!$S$5:$S$154,8),Lotes!$S$5:$S$154,0)),""),"") | H28: =IFERROR(IF(LARGE(Lotes!$S$5:$S$154,8)>0,INDEX(Lotes!$N$5:$N$154,MATCH(LARGE(Lotes!$S$5:$S$154,8),Lotes!$S$5:$S$154,0)),""),"") | I28: =IFERROR(IF(LARGE(Lotes!$S$5:$S$154,8)>0,INDEX(Lotes!$O$5:$O$154,MATCH(LARGE(Lotes!$S$5:$S$154,8),Lotes!$S$5:$S$154,0)),""),"")
A29: 9 | B29: =IFERROR(IF(LARGE(Lotes!$S$5:$S$154,9)>0,INDEX(Lotes!$A$5:$A$154,MATCH(LARGE(Lotes!$S$5:$S$154,9),Lotes!$S$5:$S$154,0)),""),"") | C29: =IFERROR(IF(LARGE(Lotes!$S$5:$S$154,9)>0,INDEX(Lotes!$B$5:$B$154,MATCH(LARGE(Lotes!$S$5:$S$154,9),Lotes!$S$5:$S$154,0)),""),"") | D29: =IFERROR(IF(LARGE(Lotes!$S$5:$S$154,9)>0,INDEX(Lotes!$C$5:$C$154,MATCH(LARGE(Lotes!$S$5:$S$154,9),Lotes!$S$5:$S$154,0)),""),"") | E29: =IFERROR(IF(LARGE(Lotes!$S$5:$S$154,9)>0,INDEX(Lotes!$D$5:$D$154,MATCH(LARGE(Lotes!$S$5:$S$154,9),Lotes!$S$5:$S$154,0)),""),"") | F29: =IFERROR(IF(LARGE(Lotes!$S$5:$S$154,9)>0,INDEX(Lotes!$E$5:$E$154,MATCH(LARGE(Lotes!$S$5:$S$154,9),Lotes!$S$5:$S$154,0)),""),"") | G29: =IFERROR(IF(LARGE(Lotes!$S$5:$S$154,9)>0,INDEX(Lotes!$L$5:$L$154,MATCH(LARGE(Lotes!$S$5:$S$154,9),Lotes!$S$5:$S$154,0)),""),"") | H29: =IFERROR(IF(LARGE(Lotes!$S$5:$S$154,9)>0,INDEX(Lotes!$N$5:$N$154,MATCH(LARGE(Lotes!$S$5:$S$154,9),Lotes!$S$5:$S$154,0)),""),"") | I29: =IFERROR(IF(LARGE(Lotes!$S$5:$S$154,9)>0,INDEX(Lotes!$O$5:$O$154,MATCH(LARGE(Lotes!$S$5:$S$154,9),Lotes!$S$5:$S$154,0)),""),"")
A30: 10 | B30: =IFERROR(IF(LARGE(Lotes!$S$5:$S$154,10)>0,INDEX(Lotes!$A$5:$A$154,MATCH(LARGE(Lotes!$S$5:$S$154,10),Lotes!$S$5:$S$154,0)),""),"") | C30: =IFERROR(IF(LARGE(Lotes!$S$5:$S$154,10)>0,INDEX(Lotes!$B$5:$B$154,MATCH(LARGE(Lotes!$S$5:$S$154,10),Lotes!$S$5:$S$154,0)),""),"") | D30: =IFERROR(IF(LARGE(Lotes!$S$5:$S$154,10)>0,INDEX(Lotes!$C$5:$C$154,MATCH(LARGE(Lotes!$S$5:$S$154,10),Lotes!$S$5:$S$154,0)),""),"") | E30: =IFERROR(IF(LARGE(Lotes!$S$5:$S$154,10)>0,INDEX(Lotes!$D$5:$D$154,MATCH(LARGE(Lotes!$S$5:$S$154,10),Lotes!$S$5:$S$154,0)),""),"") | F30: =IFERROR(IF(LARGE(Lotes!$S$5:$S$154,10)>0,INDEX(Lotes!$E$5:$E$154,MATCH(LARGE(Lotes!$S$5:$S$154,10),Lotes!$S$5:$S$154,0)),""),"") | G30: =IFERROR(IF(LARGE(Lotes!$S$5:$S$154,10)>0,INDEX(Lotes!$L$5:$L$154,MATCH(LARGE(Lotes!$S$5:$S$154,10),Lotes!$S$5:$S$154,0)),""),"") | H30: =IFERROR(IF(LARGE(Lotes!$S$5:$S$154,10)>0,INDEX(Lotes!$N$5:$N$154,MATCH(LARGE(Lotes!$S$5:$S$154,10),Lotes!$S$5:$S$154,0)),""),"") | I30: =IFERROR(IF(LARGE(Lotes!$S$5:$S$154,10)>0,INDEX(Lotes!$O$5:$O$154,MATCH(LARGE(Lotes!$S$5:$S$154,10),Lotes!$S$5:$S$154,0)),""),"")
A31: 11 | B31: =IFERROR(IF(LARGE(Lotes!$S$5:$S$154,11)>0,INDEX(Lotes!$A$5:$A$154,MATCH(LARGE(Lotes!$S$5:$S$154,11),Lotes!$S$5:$S$154,0)),""),"") | C31: =IFERROR(IF(LARGE(Lotes!$S$5:$S$154,11)>0,INDEX(Lotes!$B$5:$B$154,MATCH(LARGE(Lotes!$S$5:$S$154,11),Lotes!$S$5:$S$154,0)),""),"") | D31: =IFERROR(IF(LARGE(Lotes!$S$5:$S$154,11)>0,INDEX(Lotes!$C$5:$C$154,MATCH(LARGE(Lotes!$S$5:$S$154,11),Lotes!$S$5:$S$154,0)),""),"") | E31: =IFERROR(IF(LARGE(Lotes!$S$5:$S$154,11)>0,INDEX(Lotes!$D$5:$D$154,MATCH(LARGE(Lotes!$S$5:$S$154,11),Lotes!$S$5:$S$154,0)),""),"") | F31: =IFERROR(IF(LARGE(Lotes!$S$5:$S$154,11)>0,INDEX(Lotes!$E$5:$E$154,MATCH(LARGE(Lotes!$S$5:$S$154,11),Lotes!$S$5:$S$154,0)),""),"") | G31: =IFERROR(IF(LARGE(Lotes!$S$5:$S$154,11)>0,INDEX(Lotes!$L$5:$L$154,MATCH(LARGE(Lotes!$S$5:$S$154,11),Lotes!$S$5:$S$154,0)),""),"") | H31: =IFERROR(IF(LARGE(Lotes!$S$5:$S$154,11)>0,INDEX(Lotes!$N$5:$N$154,MATCH(LARGE(Lotes!$S$5:$S$154,11),Lotes!$S$5:$S$154,0)),""),"") | I31: =IFERROR(IF(LARGE(Lotes!$S$5:$S$154,11)>0,INDEX(Lotes!$O$5:$O$154,MATCH(LARGE(Lotes!$S$5:$S$154,11),Lotes!$S$5:$S$154,0)),""),"")
A32: 12 | B32: =IFERROR(IF(LARGE(Lotes!$S$5:$S$154,12)>0,INDEX(Lotes!$A$5:$A$154,MATCH(LARGE(Lotes!$S$5:$S$154,12),Lotes!$S$5:$S$154,0)),""),"") | C32: =IFERROR(IF(LARGE(Lotes!$S$5:$S$154,12)>0,INDEX(Lotes!$B$5:$B$154,MATCH(LARGE(Lotes!$S$5:$S$154,12),Lotes!$S$5:$S$154,0)),""),"") | D32: =IFERROR(IF(LARGE(Lotes!$S$5:$S$154,12)>0,INDEX(Lotes!$C$5:$C$154,MATCH(LARGE(Lotes!$S$5:$S$154,12),Lotes!$S$5:$S$154,0)),""),"") | E32: =IFERROR(IF(LARGE(Lotes!$S$5:$S$154,12)>0,INDEX(Lotes!$D$5:$D$154,MATCH(LARGE(Lotes!$S$5:$S$154,12),Lotes!$S$5:$S$154,0)),""),"") | F32: =IFERROR(IF(LARGE(Lotes!$S$5:$S$154,12)>0,INDEX(Lotes!$E$5:$E$154,MATCH(LARGE(Lotes!$S$5:$S$154,12),Lotes!$S$5:$S$154,0)),""),"") | G32: =IFERROR(IF(LARGE(Lotes!$S$5:$S$154,12)>0,INDEX(Lotes!$L$5:$L$154,MATCH(LARGE(Lotes!$S$5:$S$154,12),Lotes!$S$5:$S$154,0)),""),"") | H32: =IFERROR(IF(LARGE(Lotes!$S$5:$S$154,12)>0,INDEX(Lotes!$N$5:$N$154,MATCH(LARGE(Lotes!$S$5:$S$154,12),Lotes!$S$5:$S$154,0)),""),"") | I32: =IFERROR(IF(LARGE(Lotes!$S$5:$S$154,12)>0,INDEX(Lotes!$O$5:$O$154,MATCH(LARGE(Lotes!$S$5:$S$154,12),Lotes!$S$5:$S$154,0)),""),"")
A35: Por mês de competência (ano do painel)
A36: Mês | B36: Lotes | C36: Guias | D36: Enviado (R$) | E36: Pago (R$) | F36: Glosa (R$) | G36: Glosa (%) | H36: A receber (R$) | I36: Situação
A37: Janeiro | B37: =COUNTIFS(Lotes!$B$5:$B$154,DATE(Config!$B$6,1,1),Lotes!$A$5:$A$154,"<>") -> 3 | C37: =SUMIFS(Lotes!$C$5:$C$154,Lotes!$B$5:$B$154,DATE(Config!$B$6,1,1)) -> 69 | D37: =SUMIFS(Lotes!$D$5:$D$154,Lotes!$B$5:$B$154,DATE(Config!$B$6,1,1)) -> 7000 | E37: =SUMIFS(Lotes!$G$5:$G$154,Lotes!$B$5:$B$154,DATE(Config!$B$6,1,1)) -> 6595 | F37: =SUMIFS(Lotes!$M$5:$M$154,Lotes!$B$5:$B$154,DATE(Config!$B$6,1,1)) -> 405 | G37: =IF(E37+F37=0,"",F37/(E37+F37)) -> 0.057857143 | H37: =SUMIFS(Lotes!$D$5:$D$154,Lotes!$B$5:$B$154,DATE(Config!$B$6,1,1),Lotes!$N$5:$N$154,"Aguardando")+SUMIFS(Lotes!$D$5:$D$154,Lotes!$B$5:$B$154,DATE(Config!$B$6,1,1),Lotes!$N$5:$N$154,"Atrasada") -> 0 | I37: =IF(B37=0,"",IF(COUNTIFS(Lotes!$B$5:$B$154,DATE(Config!$B$6,1,1),Lotes!$N$5:$N$154,"Atrasada")>0,"Com atraso",IF(COUNTIFS(Lotes!$B$5:$B$154,DATE(Config!$B$6,1,1),Lotes!$N$5:$N$154,"Em separação")>0,"Em separação",IF(H37>0,"Aguardando","Fechado")))) -> Fechado
A38: Fevereiro | B38: =COUNTIFS(Lotes!$B$5:$B$154,DATE(Config!$B$6,2,1),Lotes!$A$5:$A$154,"<>") -> 3 | C38: =SUMIFS(Lotes!$C$5:$C$154,Lotes!$B$5:$B$154,DATE(Config!$B$6,2,1)) -> 62 | D38: =SUMIFS(Lotes!$D$5:$D$154,Lotes!$B$5:$B$154,DATE(Config!$B$6,2,1)) -> 6266 | E38: =SUMIFS(Lotes!$G$5:$G$154,Lotes!$B$5:$B$154,DATE(Config!$B$6,2,1)) -> 5910 | F38: =SUMIFS(Lotes!$M$5:$M$154,Lotes!$B$5:$B$154,DATE(Config!$B$6,2,1)) -> 356 | G38: =IF(E38+F38=0,"",F38/(E38+F38)) -> 0.056814555 | H38: =SUMIFS(Lotes!$D$5:$D$154,Lotes!$B$5:$B$154,DATE(Config!$B$6,2,1),Lotes!$N$5:$N$154,"Aguardando")+SUMIFS(Lotes!$D$5:$D$154,Lotes!$B$5:$B$154,DATE(Config!$B$6,2,1),Lotes!$N$5:$N$154,"Atrasada") -> 0 | I38: =IF(B38=0,"",IF(COUNTIFS(Lotes!$B$5:$B$154,DATE(Config!$B$6,2,1),Lotes!$N$5:$N$154,"Atrasada")>0,"Com atraso",IF(COUNTIFS(Lotes!$B$5:$B$154,DATE(Config!$B$6,2,1),Lotes!$N$5:$N$154,"Em separação")>0,"Em separação",IF(H38>0,"Aguardando","Fechado")))) -> Fechado
A39: Março | B39: =COUNTIFS(Lotes!$B$5:$B$154,DATE(Config!$B$6,3,1),Lotes!$A$5:$A$154,"<>") -> 3 | C39: =SUMIFS(Lotes!$C$5:$C$154,Lotes!$B$5:$B$154,DATE(Config!$B$6,3,1)) -> 113 | D39: =SUMIFS(Lotes!$D$5:$D$154,Lotes!$B$5:$B$154,DATE(Config!$B$6,3,1)) -> 11855 | E39: =SUMIFS(Lotes!$G$5:$G$154,Lotes!$B$5:$B$154,DATE(Config!$B$6,3,1)) -> 11115 | F39: =SUMIFS(Lotes!$M$5:$M$154,Lotes!$B$5:$B$154,DATE(Config!$B$6,3,1)) -> 740 | G39: =IF(E39+F39=0,"",F39/(E39+F39)) -> 0.062420919 | H39: =SUMIFS(Lotes!$D$5:$D$154,Lotes!$B$5:$B$154,DATE(Config!$B$6,3,1),Lotes!$N$5:$N$154,"Aguardando")+SUMIFS(Lotes!$D$5:$D$154,Lotes!$B$5:$B$154,DATE(Config!$B$6,3,1),Lotes!$N$5:$N$154,"Atrasada") -> 0 | I39: =IF(B39=0,"",IF(COUNTIFS(Lotes!$B$5:$B$154,DATE(Config!$B$6,3,1),Lotes!$N$5:$N$154,"Atrasada")>0,"Com atraso",IF(COUNTIFS(Lotes!$B$5:$B$154,DATE(Config!$B$6,3,1),Lotes!$N$5:$N$154,"Em separação")>0,"Em separação",IF(H39>0,"Aguardando","Fechado")))) -> Fechado
A40: Abril | B40: =COUNTIFS(Lotes!$B$5:$B$154,DATE(Config!$B$6,4,1),Lotes!$A$5:$A$154,"<>") -> 3 | C40: =SUMIFS(Lotes!$C$5:$C$154,Lotes!$B$5:$B$154,DATE(Config!$B$6,4,1)) -> 86 | D40: =SUMIFS(Lotes!$D$5:$D$154,Lotes!$B$5:$B$154,DATE(Config!$B$6,4,1)) -> 8418 | E40: =SUMIFS(Lotes!$G$5:$G$154,Lotes!$B$5:$B$154,DATE(Config!$B$6,4,1)) -> 7796 | F40: =SUMIFS(Lotes!$M$5:$M$154,Lotes!$B$5:$B$154,DATE(Config!$B$6,4,1)) -> 622 | G40: =IF(E40+F40=0,"",F40/(E40+F40)) -> 0.073889285 | H40: =SUMIFS(Lotes!$D$5:$D$154,Lotes!$B$5:$B$154,DATE(Config!$B$6,4,1),Lotes!$N$5:$N$154,"Aguardando")+SUMIFS(Lotes!$D$5:$D$154,Lotes!$B$5:$B$154,DATE(Config!$B$6,4,1),Lotes!$N$5:$N$154,"Atrasada") -> 0 | I40: =IF(B40=0,"",IF(COUNTIFS(Lotes!$B$5:$B$154,DATE(Config!$B$6,4,1),Lotes!$N$5:$N$154,"Atrasada")>0,"Com atraso",IF(COUNTIFS(Lotes!$B$5:$B$154,DATE(Config!$B$6,4,1),Lotes!$N$5:$N$154,"Em separação")>0,"Em separação",IF(H40>0,"Aguardando","Fechado")))) -> Fechado
A41: Maio | B41: =COUNTIFS(Lotes!$B$5:$B$154,DATE(Config!$B$6,5,1),Lotes!$A$5:$A$154,"<>") -> 3 | C41: =SUMIFS(Lotes!$C$5:$C$154,Lotes!$B$5:$B$154,DATE(Config!$B$6,5,1)) -> 100 | D41: =SUMIFS(Lotes!$D$5:$D$154,Lotes!$B$5:$B$154,DATE(Config!$B$6,5,1)) -> 10541 | E41: =SUMIFS(Lotes!$G$5:$G$154,Lotes!$B$5:$B$154,DATE(Config!$B$6,5,1)) -> 9936 | F41: =SUMIFS(Lotes!$M$5:$M$154,Lotes!$B$5:$B$154,DATE(Config!$B$6,5,1)) -> 605 | G41: =IF(E41+F41=0,"",F41/(E41+F41)) -> 0.057394934 | H41: =SUMIFS(Lotes!$D$5:$D$154,Lotes!$B$5:$B$154,DATE(Config!$B$6,5,1),Lotes!$N$5:$N$154,"Aguardando")+SUMIFS(Lotes!$D$5:$D$154,Lotes!$B$5:$B$154,DATE(Config!$B$6,5,1),Lotes!$N$5:$N$154,"Atrasada") -> 0 | I41: =IF(B41=0,"",IF(COUNTIFS(Lotes!$B$5:$B$154,DATE(Config!$B$6,5,1),Lotes!$N$5:$N$154,"Atrasada")>0,"Com atraso",IF(COUNTIFS(Lotes!$B$5:$B$154,DATE(Config!$B$6,5,1),Lotes!$N$5:$N$154,"Em separação")>0,"Em separação",IF(H41>0,"Aguardando","Fechado")))) -> Fechado
A42: Junho | B42: =COUNTIFS(Lotes!$B$5:$B$154,DATE(Config!$B$6,6,1),Lotes!$A$5:$A$154,"<>") -> 3 | C42: =SUMIFS(Lotes!$C$5:$C$154,Lotes!$B$5:$B$154,DATE(Config!$B$6,6,1)) -> 114 | D42: =SUMIFS(Lotes!$D$5:$D$154,Lotes!$B$5:$B$154,DATE(Config!$B$6,6,1)) -> 11552 | E42: =SUMIFS(Lotes!$G$5:$G$154,Lotes!$B$5:$B$154,DATE(Config!$B$6,6,1)) -> 9450 | F42: =SUMIFS(Lotes!$M$5:$M$154,Lotes!$B$5:$B$154,DATE(Config!$B$6,6,1)) -> 375 | G42: =IF(E42+F42=0,"",F42/(E42+F42)) -> 0.038167939 | H42: =SUMIFS(Lotes!$D$5:$D$154,Lotes!$B$5:$B$154,DATE(Config!$B$6,6,1),Lotes!$N$5:$N$154,"Aguardando")+SUMIFS(Lotes!$D$5:$D$154,Lotes!$B$5:$B$154,DATE(Config!$B$6,6,1),Lotes!$N$5:$N$154,"Atrasada") -> 1727 | I42: =IF(B42=0,"",IF(COUNTIFS(Lotes!$B$5:$B$154,DATE(Config!$B$6,6,1),Lotes!$N$5:$N$154,"Atrasada")>0,"Com atraso",IF(COUNTIFS(Lotes!$B$5:$B$154,DATE(Config!$B$6,6,1),Lotes!$N$5:$N$154,"Em separação")>0,"Em separação",IF(H42>0,"Aguardando","Fechado")))) -> Com atraso
A43: Julho | B43: =COUNTIFS(Lotes!$B$5:$B$154,DATE(Config!$B$6,7,1),Lotes!$A$5:$A$154,"<>") -> 3 | C43: =SUMIFS(Lotes!$C$5:$C$154,Lotes!$B$5:$B$154,DATE(Config!$B$6,7,1)) -> 100 | D43: =SUMIFS(Lotes!$D$5:$D$154,Lotes!$B$5:$B$154,DATE(Config!$B$6,7,1)) -> 10350 | E43: =SUMIFS(Lotes!$G$5:$G$154,Lotes!$B$5:$B$154,DATE(Config!$B$6,7,1)) -> 5780 | F43: =SUMIFS(Lotes!$M$5:$M$154,Lotes!$B$5:$B$154,DATE(Config!$B$6,7,1)) -> 170 | G43: =IF(E43+F43=0,"",F43/(E43+F43)) -> 0.028571429 | H43: =SUMIFS(Lotes!$D$5:$D$154,Lotes!$B$5:$B$154,DATE(Config!$B$6,7,1),Lotes!$N$5:$N$154,"Aguardando")+SUMIFS(Lotes!$D$5:$D$154,Lotes!$B$5:$B$154,DATE(Config!$B$6,7,1),Lotes!$N$5:$N$154,"Atrasada") -> 4400 | I43: =IF(B43=0,"",IF(COUNTIFS(Lotes!$B$5:$B$154,DATE(Config!$B$6,7,1),Lotes!$N$5:$N$154,"Atrasada")>0,"Com atraso",IF(COUNTIFS(Lotes!$B$5:$B$154,DATE(Config!$B$6,7,1),Lotes!$N$5:$N$154,"Em separação")>0,"Em separação",IF(H43>0,"Aguardando","Fechado")))) -> Aguardando
A44: Agosto | B44: =COUNTIFS(Lotes!$B$5:$B$154,DATE(Config!$B$6,8,1),Lotes!$A$5:$A$154,"<>") -> 3 | C44: =SUMIFS(Lotes!$C$5:$C$154,Lotes!$B$5:$B$154,DATE(Config!$B$6,8,1)) -> 97 | D44: =SUMIFS(Lotes!$D$5:$D$154,Lotes!$B$5:$B$154,DATE(Config!$B$6,8,1)) -> 9631 | E44: =SUMIFS(Lotes!$G$5:$G$154,Lotes!$B$5:$B$154,DATE(Config!$B$6,8,1)) -> 0 | F44: =SUMIFS(Lotes!$M$5:$M$154,Lotes!$B$5:$B$154,DATE(Config!$B$6,8,1)) -> 0 | G44: =IF(E44+F44=0,"",F44/(E44+F44)) | H44: =SUMIFS(Lotes!$D$5:$D$154,Lotes!$B$5:$B$154,DATE(Config!$B$6,8,1),Lotes!$N$5:$N$154,"Aguardando")+SUMIFS(Lotes!$D$5:$D$154,Lotes!$B$5:$B$154,DATE(Config!$B$6,8,1),Lotes!$N$5:$N$154,"Atrasada") -> 9631 | I44: =IF(B44=0,"",IF(COUNTIFS(Lotes!$B$5:$B$154,DATE(Config!$B$6,8,1),Lotes!$N$5:$N$154,"Atrasada")>0,"Com atraso",IF(COUNTIFS(Lotes!$B$5:$B$154,DATE(Config!$B$6,8,1),Lotes!$N$5:$N$154,"Em separação")>0,"Em separação",IF(H44>0,"Aguardando","Fechado")))) -> Aguardando
A45: Setembro | B45: =COUNTIFS(Lotes!$B$5:$B$154,DATE(Config!$B$6,9,1),Lotes!$A$5:$A$154,"<>") -> 3 | C45: =SUMIFS(Lotes!$C$5:$C$154,Lotes!$B$5:$B$154,DATE(Config!$B$6,9,1)) -> 42 | D45: =SUMIFS(Lotes!$D$5:$D$154,Lotes!$B$5:$B$154,DATE(Config!$B$6,9,1)) -> 4425 | E45: =SUMIFS(Lotes!$G$5:$G$154,Lotes!$B$5:$B$154,DATE(Config!$B$6,9,1)) -> 0 | F45: =SUMIFS(Lotes!$M$5:$M$154,Lotes!$B$5:$B$154,DATE(Config!$B$6,9,1)) -> 0 | G45: =IF(E45+F45=0,"",F45/(E45+F45)) | H45: =SUMIFS(Lotes!$D$5:$D$154,Lotes!$B$5:$B$154,DATE(Config!$B$6,9,1),Lotes!$N$5:$N$154,"Aguardando")+SUMIFS(Lotes!$D$5:$D$154,Lotes!$B$5:$B$154,DATE(Config!$B$6,9,1),Lotes!$N$5:$N$154,"Atrasada") -> 0 | I45: =IF(B45=0,"",IF(COUNTIFS(Lotes!$B$5:$B$154,DATE(Config!$B$6,9,1),Lotes!$N$5:$N$154,"Atrasada")>0,"Com atraso",IF(COUNTIFS(Lotes!$B$5:$B$154,DATE(Config!$B$6,9,1),Lotes!$N$5:$N$154,"Em separação")>0,"Em separação",IF(H45>0,"Aguardando","Fechado")))) -> Em separação
A46: Outubro | B46: =COUNTIFS(Lotes!$B$5:$B$154,DATE(Config!$B$6,10,1),Lotes!$A$5:$A$154,"<>") -> 0 | C46: =SUMIFS(Lotes!$C$5:$C$154,Lotes!$B$5:$B$154,DATE(Config!$B$6,10,1)) -> 0 | D46: =SUMIFS(Lotes!$D$5:$D$154,Lotes!$B$5:$B$154,DATE(Config!$B$6,10,1)) -> 0 | E46: =SUMIFS(Lotes!$G$5:$G$154,Lotes!$B$5:$B$154,DATE(Config!$B$6,10,1)) -> 0 | F46: =SUMIFS(Lotes!$M$5:$M$154,Lotes!$B$5:$B$154,DATE(Config!$B$6,10,1)) -> 0 | G46: =IF(E46+F46=0,"",F46/(E46+F46)) | H46: =SUMIFS(Lotes!$D$5:$D$154,Lotes!$B$5:$B$154,DATE(Config!$B$6,10,1),Lotes!$N$5:$N$154,"Aguardando")+SUMIFS(Lotes!$D$5:$D$154,Lotes!$B$5:$B$154,DATE(Config!$B$6,10,1),Lotes!$N$5:$N$154,"Atrasada") -> 0 | I46: =IF(B46=0,"",IF(COUNTIFS(Lotes!$B$5:$B$154,DATE(Config!$B$6,10,1),Lotes!$N$5:$N$154,"Atrasada")>0,"Com atraso",IF(COUNTIFS(Lotes!$B$5:$B$154,DATE(Config!$B$6,10,1),Lotes!$N$5:$N$154,"Em separação")>0,"Em separação",IF(H46>0,"Aguardando","Fechado"))))
...

Sheet Config
A1: Configurações
A2: Células amarelas: você preenche. Cada convênio com o prazo contratual de pagamento (dias após o envio do lote) e o dia de envio.
A4: Clínica | B4: Clínica Vida Plena (exemplo fictício)
A5: Data de referência (hoje) | B5: 46279
A6: Ano do painel | B6: 2026
A7: Tolerância de atraso antes de avisar (dias) | B7: 0
A9: Convênio | B9: Prazo de pagamento (dias) | C9: Dia de envio do lote | D9: Glosa histórica (informativa) | E9: Observação
A10: Saúde Total | B10: 30 | C10: 5 | D10: 0.03 | E10: Prazo contado do envio do lote (contrato)
A11: MediPlan | B11: 45 | C11: 5 | D11: 0.06 | E11: Prazo contado do envio do lote (contrato)
A12: Vida Care | B12: 60 | C12: 5 | D12: 0.1 | E12: Prazo contado do envio do lote (contrato)
A17: Preencha de cima para baixo, sem pular linha. Prazo: o que está no contrato (30, 45 ou 60 dias após o envio). A glosa histórica é só uma referência para o simulador (07); o Painel calcula a glosa real dos lotes pagos.
A18: Recurso de glosa: administrativo (guia sem autorização, código errado, prazo). O texto do recurso é seu; o prompt "Recebíveis 03 · Recurso de glosa em linguagem administrativa" da biblioteca ajuda a redigir, sem conteúdo clínico.

Sheet Guias
A1: Guias
A2: Uma linha por atendimento de convênio realizado (copie da Agenda da planilha 01: data, paciente, pagador, procedimento, profissional, valor). Quando o convênio pagar o lote, marque as guias glosadas e o recurso.
A4: Guia (nº) | B4: Data do atendimento | C4: Paciente | D4: Convênio | E4: Procedimento | F4: Profissional | G4: Valor (R$) | H4: Glosada? | I4: Recurso | J4: Competência | K4: Lote (chave) | L4: Situação do lote | M4: Valor glosado (R$)
A5: G2026-0431 | B5: 46174 | C5: Isabela Pinto | D5: Saúde Total | E5: Consulta | F5: Dra. Carolina Mendes | G5: 120 | J5: =IF(B5="","",DATE(YEAR(B5),MONTH(B5),1)) -> 46174 | K5: =IF(OR(B5="",D5=""),"",D5&"|"&TEXT(J5,"yyyy-mm")) -> Saúde Total|2026-06 | L5: =IF(K5="","",IFERROR(INDEX(Lotes!$N$5:$N$154,MATCH(K5,Lotes!$P$5:$P$154,0)),"Sem lote cadastrado")) -> Em recurso | M5: =IF(H5="Sim",G5,0) -> 0 | N5: =IF(AND(H5="Sim",I5<>"Aceito"),G5+ROW()/100000,0) -> 0
A6: G2026-0432 | B6: 46174 | C6: Tatiana Cunha | D6: Saúde Total | E6: Consulta | F6: Dra. Carolina Mendes | G6: 120 | J6: =IF(B6="","",DATE(YEAR(B6),MONTH(B6),1)) -> 46174 | K6: =IF(OR(B6="",D6=""),"",D6&"|"&TEXT(J6,"yyyy-mm")) -> Saúde Total|2026-06 | L6: =IF(K6="","",IFERROR(INDEX(Lotes!$N$5:$N$154,MATCH(K6,Lotes!$P$5:$P$154,0)),"Sem lote cadastrado")) -> Em recurso | M6: =IF(H6="Sim",G6,0) -> 0 | N6: =IF(AND(H6="Sim",I6<>"Aceito"),G6+ROW()/100000,0) -> 0
A7: G2026-0433 | B7: 46174 | C7: Débora Machado | D7: Saúde Total | E7: Consulta | F7: Dra. Carolina Mendes | G7: 120 | J7: =IF(B7="","",DATE(YEAR(B7),MONTH(B7),1)) -> 46174 | K7: =IF(OR(B7="",D7=""),"",D7&"|"&TEXT(J7,"yyyy-mm")) -> Saúde Total|2026-06 | L7: =IF(K7="","",IFERROR(INDEX(Lotes!$N$5:$N$154,MATCH(K7,Lotes!$P$5:$P$154,0)),"Sem lote cadastrado")) -> Em recurso | M7: =IF(H7="Sim",G7,0) -> 0 | N7: =IF(AND(H7="Sim",I7<>"Aceito"),G7+ROW()/100000,0) -> 0
A8: G2026-0434 | B8: 46174 | C8: Otávio Martins | D8: MediPlan | E8: Consulta | F8: Dr. Paulo Andrade | G8: 100 | J8: =IF(B8="","",DATE(YEAR(B8),MONTH(B8),1)) -> 46174 | K8: =IF(OR(B8="",D8=""),"",D8&"|"&TEXT(J8,"yyyy-mm")) -> MediPlan|2026-06 | L8: =IF(K8="","",IFERROR(INDEX(Lotes!$N$5:$N$154,MATCH(K8,Lotes!$P$5:$P$154,0)),"Sem lote cadastrado")) -> Paga com glosa | M8: =IF(H8="Sim",G8,0) -> 0 | N8: =IF(AND(H8="Sim",I8<>"Aceito"),G8+ROW()/100000,0) -> 0
A9: G2026-0435 | B9: 46174 | C9: Mateus Martins | D9: Vida Care | E9: Consulta | F9: Dr. Paulo Andrade | G9: 90 | J9: =IF(B9="","",DATE(YEAR(B9),MONTH(B9),1)) -> 46174 | K9: =IF(OR(B9="",D9=""),"",D9&"|"&TEXT(J9,"yyyy-mm")) -> Vida Care|2026-06 | L9: =IF(K9="","",IFERROR(INDEX(Lotes!$N$5:$N$154,MATCH(K9,Lotes!$P$5:$P$154,0)),"Sem lote cadastrado")) -> Atrasada | M9: =IF(H9="Sim",G9,0) -> 0 | N9: =IF(AND(H9="Sim",I9<>"Aceito"),G9+ROW()/100000,0) -> 0
A10: G2026-0436 | B10: 46174 | C10: Leandro Ferreira | D10: Saúde Total | E10: Holter | F10: Dr. Paulo Andrade | G10: 105 | J10: =IF(B10="","",DATE(YEAR(B10),MONTH(B10),1)) -> 46174 | K10: =IF(OR(B10="",D10=""),"",D10&"|"&TEXT(J10,"yyyy-mm")) -> Saúde Total|2026-06 | L10: =IF(K10="","",IFERROR(INDEX(Lotes!$N$5:$N$154,MATCH(K10,Lotes!$P$5:$P$154,0)),"Sem lote cadastrado")) -> Em recurso | M10: =IF(H10="Sim",G10,0) -> 0 | N10: =IF(AND(H10="Sim",I10<>"Aceito"),G10+ROW()/100000,0) -> 0
A11: G2026-0437 | B11: 46175 | C11: Sérgio Batista | D11: MediPlan | E11: Consulta | F11: Dra. Carolina Mendes | G11: 100 | J11: =IF(B11="","",DATE(YEAR(B11),MONTH(B11),1)) -> 46174 | K11: =IF(OR(B11="",D11=""),"",D11&"|"&TEXT(J11,"yyyy-mm")) -> MediPlan|2026-06 | L11: =IF(K11="","",IFERROR(INDEX(Lotes!$N$5:$N$154,MATCH(K11,Lotes!$P$5:$P$154,0)),"Sem lote cadastrado")) -> Paga com glosa | M11: =IF(H11="Sim",G11,0) -> 0 | N11: =IF(AND(H11="Sim",I11<>"Aceito"),G11+ROW()/100000,0) -> 0
A12: G2026-0438 | B12: 46175 | C12: Carlos Castro | D12: Saúde Total | E12: Consulta | F12: Dra. Carolina Mendes | G12: 120 | J12: =IF(B12="","",DATE(YEAR(B12),MONTH(B12),1)) -> 46174 | K12: =IF(OR(B12="",D12=""),"",D12&"|"&TEXT(J12,"yyyy-mm")) -> Saúde Total|2026-06 | L12: =IF(K12="","",IFERROR(INDEX(Lotes!$N$5:$N$154,MATCH(K12,Lotes!$P$5:$P$154,0)),"Sem lote cadastrado")) -> Em recurso | M12: =IF(H12="Sim",G12,0) -> 0 | N12: =IF(AND(H12="Sim",I12<>"Aceito"),G12+ROW()/100000,0) -> 0
A13: G2026-0439 | B13: 46175 | C13: Lucas Xavier | D13: Saúde Total | E13: Consulta | F13: Dra. Carolina Mendes | G13: 120 | J13: =IF(B13="","",DATE(YEAR(B13),MONTH(B13),1)) -> 46174 | K13: =IF(OR(B13="",D13=""),"",D13&"|"&TEXT(J13,"yyyy-mm")) -> Saúde Total|2026-06 | L13: =IF(K13="","",IFERROR(INDEX(Lotes!$N$5:$N$154,MATCH(K13,Lotes!$P$5:$P$154,0)),"Sem lote cadastrado")) -> Em recurso | M13: =IF(H13="Sim",G13,0) -> 0 | N13: =IF(AND(H13="Sim",I13<>"Aceito"),G13+ROW()/100000,0) -> 0
A14: G2026-0440 | B14: 46175 | C14: Rafael Nascimento | D14: Saúde Total | E14: Avaliação endócrina | F14: Dra. Renata Sousa | G14: 130 | J14: =IF(B14="","",DATE(YEAR(B14),MONTH(B14),1)) -> 46174 | K14: =IF(OR(B14="",D14=""),"",D14&"|"&TEXT(J14,"yyyy-mm")) -> Saúde Total|2026-06 | L14: =IF(K14="","",IFERROR(INDEX(Lotes!$N$5:$N$154,MATCH(K14,Lotes!$P$5:$P$154,0)),"Sem lote cadastrado")) -> Em recurso | M14: =IF(H14="Sim",G14,0) -> 0 | N14: =IF(AND(H14="Sim",I14<>"Aceito"),G14+ROW()/100000,0) -> 0
A15: G2026-0441 | B15: 46175 | C15: Leandro Cardoso | D15: MediPlan | E15: Consulta | F15: Dr. Paulo Andrade | G15: 100 | J15: =IF(B15="","",DATE(YEAR(B15),MONTH(B15),1)) -> 46174 | K15: =IF(OR(B15="",D15=""),"",D15&"|"&TEXT(J15,"yyyy-mm")) -> MediPlan|2026-06 | L15: =IF(K15="","",IFERROR(INDEX(Lotes!$N$5:$N$154,MATCH(K15,Lotes!$P$5:$P$154,0)),"Sem lote cadastrado")) -> Paga com glosa | M15: =IF(H15="Sim",G15,0) -> 0 | N15: =IF(AND(H15="Sim",I15<>"Aceito"),G15+ROW()/100000,0) -> 0
A16: G2026-0442 | B16: 46175 | C16: Gisele Lopes | D16: Saúde Total | E16: Avaliação endócrina | F16: Dra. Renata Sousa | G16: 130 | J16: =IF(B16="","",DATE(YEAR(B16),MONTH(B16),1)) -> 46174 | K16: =IF(OR(B16="",D16=""),"",D16&"|"&TEXT(J16,"yyyy-mm")) -> Saúde Total|2026-06 | L16: =IF(K16="","",IFERROR(INDEX(Lotes!$N$5:$N$154,MATCH(K16,Lotes!$P$5:$P$154,0)),"Sem lote cadastrado")) -> Em recurso | M16: =IF(H16="Sim",G16,0) -> 0 | N16: =IF(AND(H16="Sim",I16<>"Aceito"),G16+ROW()/100000,0) -> 0
... A54: G2026-0480 | B54: 46189 | C54: Juliana Silva | D54: Vida Care | E54: Consulta | F54: Dra. Carolina Mendes | G54: 90 | J54: =IF(B54="","",DATE(YEAR(B54),MONTH(B54),1)) -> 46174 | K54: =IF(OR(B54="",D54=""),"",D54&"|"&TEXT(J54,"yyyy-mm")) -> Vida Care|2026-06 | L54: =IF(K54="","",IFERROR(INDEX(Lotes!$N$5:$N$154,MATCH(K54,Lotes!$P$5:$P$154,0)),"Sem lote cadastrado")) -> Atrasada | M54: =IF(H54="Sim",G54,0) -> 0 | N54: =IF(AND(H54="Sim",I54<>"Aceito"),G54+ROW()/100000,0) -> 0
A55: G2026-0481 | B55: 46189 | C55: Carlos Castro | D55: Saúde Total | E55: Consulta | F55: Dra. Carolina Mendes | G55: 120 | H55: Sim | I55: Em recurso | J55: =IF(B55="","",DATE(YEAR(B55),MONTH(B55),1)) -> 46174 | K55: =IF(OR(B55="",D55=""),"",D55&"|"&TEXT(J55,"yyyy-mm")) -> Saúde Total|2026-06 | L55: =IF(K55="","",IFERROR(INDEX(Lotes!$N$5:$N$154,MATCH(K55,Lotes!$P$5:$P$154,0)),"Sem lote cadastrado")) -> Em recurso | M55: =IF(H55="Sim",G55,0) -> 120 | N55: =IF(AND(H55="Sim",I55<>"Aceito"),G55+ROW()/100000,0) -> 120.00055
A56: G2026-0482 | B56: 46189 | C56: Paulo Freitas | D56: Saúde Total | E56: Avaliação endócrina | F56: Dra. Renata Sousa | G56: 130 | J56: =IF(B56="","",DATE(YEAR(B56),MONTH(B56),1)) -> 46174 | K56: =IF(OR(B56="",D56=""),"",D56&"|"&TEXT(J56,"yyyy-mm")) -> Saúde Total|2026-06 | L56: =IF(K56="","",IFERROR(INDEX(Lotes!$N$5:$N$154,MATCH(K56,Lotes!$P$5:$P$154,0)),"Sem lote cadastrado")) -> Em recurso | M56: =IF(H56="Sim",G56,0) -> 0 | N56: =IF(AND(H56="Sim",I56<>"Aceito"),G56+ROW()/100000,0) -> 0
A57: G2026-0483 | B57: 46189 | C57: Sérgio Teixeira | D57: MediPlan | E57: Consulta | F57: Dr. Paulo Andrade | G57: 100 | H57: Sim | J57: =IF(B57="","",DATE(YEAR(B57),MONTH(B57),1)) -> 46174 | K57: =IF(OR(B57="",D57=""),"",D57&"|"&TEXT(J57,"yyyy-mm")) -> MediPlan|2026-06 | L57: =IF(K57="","",IFERROR(INDEX(Lotes!$N$5:$N$154,MATCH(K57,Lotes!$P$5:$P$154,0)),"Sem lote cadastrado")) -> Paga com glosa | M57: =IF(H57="Sim",G57,0) -> 100 | N57: =IF(AND(H57="Sim",I57<>"Aceito"),G57+ROW()/100000,0) -> 100.00057
A58: G2026-0484 | B58: 46189 | C58: Beatriz Gonçalves | D58: Saúde Total | E58: Consulta | F58: Dr. Paulo Andrade | G58: 120 | J58: =IF(B58="","",DATE(YEAR(B58),MONTH(B58),1)) -> 46174 | K58: =IF(OR(B58="",D58=""),"",D58&"|"&TEXT(J58,"yyyy-mm")) -> Saúde Total|2026-06 | L58: =IF(K58="","",IFERROR(INDEX(Lotes!$N$5:$N$154,MATCH(K58,Lotes!$P$5:$P$154,0)),"Sem lote cadastrado")) -> Em recurso | M58: =IF(H58="Sim",G58,0) -> 0 | N58: =IF(AND(H58="Sim",I58<>"Aceito"),G58+ROW()/100000,0) -> 0
A59: G2026-0485 | B59: 46189 | C59: Gisele Lima | D59: Saúde Total | E59: ECG | F59: Dr. Paulo Andrade | G59: 40 | J59: =IF(B59="","",DATE(YEAR(B59),MONTH(B59),1)) -> 46174 | K59: =IF(OR(B59="",D59=""),"",D59&"|"&TEXT(J59,"yyyy-mm")) -> Saúde Total|2026-06 | L59: =IF(K59="","",IFERROR(INDEX(Lotes!$N$5:$N$154,MATCH(K59,Lotes!$P$5:$P$154,0)),"Sem lote cadastrado")) -> Em recurso | M59: =IF(H59="Sim",G59,0) -> 0 | N59: =IF(AND(H59="Sim",I59<>"Aceito"),G59+ROW()/100000,0) -> 0
A60: G2026-0486 | B60: 46189 | C60: Roberta Fernandes | D60: Saúde Total | E60: ECG | F60: Dr. Paulo Andrade | G60: 40 | J60: =IF(B60="","",DATE(YEAR(B60),MONTH(B60),1)) -> 46174 | K60: =IF(OR(B60="",D60=""),"",D60&"|"&TEXT(J60,"yyyy-mm")) -> Saúde Total|2026-06 | L60: =IF(K60="","",IFERROR(INDEX(Lotes!$N$5:$N$154,MATCH(K60,Lotes!$P$5:$P$154,0)),"Sem lote cadastrado")) -> Em recurso | M60: =IF(H60="Sim",G60,0) -> 0 | N60: =IF(AND(H60="Sim",I60<>"Aceito"),G60+ROW()/100000,0) -> 0
A61: G2026-0487 | B61: 46189 | C61: Tatiana Gonçalves | D61: Saúde Total | E61: Consulta | F61: Dr. Paulo Andrade | G61: 120 | J61: =IF(B61="","",DATE(YEAR(B61),MONTH(B61),1)) -> 46174 | K61: =IF(OR(B61="",D61=""),"",D61&"|"&TEXT(J61,"yyyy-mm")) -> Saúde Total|2026-06 | L61: =IF(K61="","",IFERROR(INDEX(Lotes!$N$5:$N$154,MATCH(K61,Lotes!$P$5:$P$154,0)),"Sem lote cadastrado")) -> Em recurso | M61: =IF(H61="Sim",G61,0) -> 0 | N61: =IF(AND(H61="Sim",I61<>"Aceito"),G61+ROW()/100000,0) -> 0
A62: G2026-0488 | B62: 46190 | C62: Mônica Batista | D62: MediPlan | E62: Consulta | F62: Dra. Carolina Mendes | G62: 100 | J62: =IF(B62="","",DATE(YEAR(B62),MONTH(B62),1)) -> 46174 | K62: =IF(OR(B62="",D62=""),"",D62&"|"&TEXT(J62,"yyyy-mm")) -> MediPlan|2026-06 | L62: =IF(K62="","",IFERROR(INDEX(Lotes!$N$5:$N$154,MATCH(K62,Lotes!$P$5:$P$154,0)),"Sem lote cadastrado")) -> Paga com glosa | M62: =IF(H62="Sim",G62,0) -> 0 | N62: =IF(AND(H62="Sim",I62<>"Aceito"),G62+ROW()/100000,0) -> 0
A63: G2026-0489 | B63: 46190 | C63: Tatiana Cunha | D63: Saúde Total | E63: Consulta | F63: Dra. Carolina Mendes | G63: 120 | J63: =IF(B63="","",DATE(YEAR(B63),MONTH(B63),1)) -> 46174 | K63: =IF(OR(B63="",D63=""),"",D63&"|"&TEXT(J63,"yyyy-mm")) -> Saúde Total|2026-06 | L63: =IF(K63="","",IFERROR(INDEX(Lotes!$N$5:$N$154,MATCH(K63,Lotes!$P$5:$P$154,0)),"Sem lote cadastrado")) -> Em recurso | M63: =IF(H63="Sim",G63,0) -> 0 | N63: =IF(AND(H63="Sim",I63<>"Aceito"),G63+ROW()/100000,0) -> 0
A64: G2026-0490 | B64: 46190 | C64: Priscila Castro | D64: Saúde Total | E64: Consulta | F64: Dra. Carolina Mendes | G64: 120 | J64: =IF(B64="","",DATE(YEAR(B64),MONTH(B64),1)) -> 46174 | K64: =IF(OR(B64="",D64=""),"",D64&"|"&TEXT(J64,"yyyy-mm")) -> Saúde Total|2026-06 | L64: =IF(K64="","",IFERROR(INDEX(Lotes!$N$5:$N$154,MATCH(K64,Lotes!$P$5:$P$154,0)),"Sem lote cadastrado")) -> Em recurso | M64: =IF(H64="Sim",G64,0) -> 0 | N64: =IF(AND(H64="Sim",I64<>"Aceito"),G64+ROW()/100000,0) -> 0
A65: G2026-0491 | B65: 46190 | C65: Débora Machado | D65: Saúde Total | E65: Consulta | F65: Dra. Carolina Mendes | G65: 120 | J65: =IF(B65="","",DATE(YEAR(B65),MONTH(B65),1)) -> 46174 | K65: =IF(OR(B65="",D65=""),"",D65&"|"&TEXT(J65,"yyyy-mm")) -> Saúde Total|2026-06 | L65: =IF(K65="","",IFERROR(INDEX(Lotes!$N$5:$N$154,MATCH(K65,Lotes!$P$5:$P$154,0)),"Sem lote cadastrado")) -> Em recurso | M65: =IF(H65="Sim",G65,0) -> 0 | N65: =IF(AND(H65="Sim",I65<>"Aceito"),G65+ROW()/100000,0) -> 0
A66: G2026-0492 | B66: 46191 | C66: Letícia Vieira | D66: Saúde Total | E66: Consulta | F66: Dra. Carolina Mendes | G66: 120 | J66: =IF(B66="","",DATE(YEAR(B66),MONTH(B66),1)) -> 46174 | K66: =IF(OR(B66="",D66=""),"",D66&"|"&TEXT(J66,"yyyy-mm")) -> Saúde Total|2026-06 | L66: =IF(K66="","",IFERROR(INDEX(Lotes!$N$5:$N$154,MATCH(K66,Lotes!$P$5:$P$154,0)),"Sem lote cadastrado")) -> Em recurso | M66: =IF(H66="Sim",G66,0) -> 0 | N66: =IF(AND(H66="Sim",I66<>"Aceito"),G66+ROW()/100000,0) -> 0
A67: G2026-0493 | B67: 46191 | C67: Eduardo Nunes | D67: MediPlan | E67: Consulta | F67: Dra. Carolina Mendes | G67: 100 | J67: =IF(B67="","",DATE(YEAR(B67),MONTH(B67),1)) -> 46174 | K67: =IF(OR(B67="",D67=""),"",D67&"|"&TEXT(J67,"yyyy-mm")) -> MediPlan|2026-06 | L67: =IF(K67="","",IFERROR(INDEX(Lotes!$N$5:$N$154,MATCH(K67,Lotes!$P$5:$P$154,0)),"Sem lote cadastrado")) -> Paga com glosa | M67: =IF(H67="Sim",G67,0) -> 0 | N67: =IF(AND(H67="Sim",I67<>"Aceito"),G67+ROW()/100000,0) -> 0
A68: G2026-0494 | B68: 46191 | C68: Simone Monteiro | D68: Vida Care | E68: Consulta | F68: Dra. Carolina Mendes | G68: 90 | J68: =IF(B68="","",DATE(YEAR(B68),MONTH(B68),1)) -> 46174 | K68: =IF(OR(B68="",D68=""),"",D68&"|"&TEXT(J68,"yyyy-mm")) -> Vida Care|2026-06 | L68: =IF(K68="","",IFERROR(INDEX(Lotes!$N$5:$N$154,MATCH(K68,Lotes!$P$5:$P$154,0)),"Sem lote cadastrado")) -> Atrasada | M68: =IF(H68="Sim",G68,0) -> 0 | N68: =IF(AND(H68="Sim",I68<>"Aceito"),G68+ROW()/100000,0) -> 0
A69: G2026-0495 | B69: 46191 | C69: Daniel Melo | D69: Saúde Total | E69: Consulta | F69: Dra. Carolina Mendes | G69: 120 | H69: Sim | I69: Em recurso | J69: =IF(B69="","",DATE(YEAR(B69),MONTH(B69),1)) -> 46174 | K69: =IF(OR(B69="",D69=""),"",D69&"|"&TEXT(J69,"yyyy-mm")) -> Saúde Total|2026-06 | L69: =IF(K69="","",IFERROR(INDEX(Lotes!$N$5:$N$154,MATCH(K69,Lotes!$P$5:$P$154,0)),"Sem lote cadastrado")) -> Em recurso | M69: =IF(H69="Sim",G69,0) -> 120 | N69: =IF(AND(H69="Sim",I69<>"Aceito"),G69+ROW()/100000,0) -> 120.00069
A70: G2026-0496 | B70: 46191 | C70: Juliana Ribeiro | D70: Saúde Total | E70: Consulta | F70: Dra. Carolina Mendes | G70: 120 | J70: =IF(B70="","",DATE(YEAR(B70),MONTH(B70),1)) -> 46174 | K70: =IF(OR(B70="",D70=""),"",D70&"|"&TEXT(J70,"yyyy-mm")) -> Saúde Total|2026-06 | L70: =IF(K70="","",IFERROR(INDEX(Lotes!$N$5:$N$154,MATCH(K70,Lotes!$P$5:$P$154,0)),"Sem lote cadastrado")) -> Em recurso | M70: =IF(H70="Sim",G70,0) -> 0 | N70: =IF(AND(H70="Sim",I70<>"Aceito"),G70+ROW()/100000,0) -> 0
A71: G2026-0497 | B71: 46191 | C71: Priscila Pinto | D71: Saúde Total | E71: Consulta | F71: Dr. Paulo Andrade | G71: 120 | J71: =IF(B71="","",DATE(YEAR(B71),MONTH(B71),1)) -> 46174 | K71: =IF(OR(B71="",D71=""),"",D71&"|"&TEXT(J71,"yyyy-mm")) -> Saúde Total|2026-06 | L71: =IF(K71="","",IFERROR(INDEX(Lotes!$N$5:$N$154,MATCH(K71,Lotes!$P$5:$P$154,0)),"Sem lote cadastrado")) -> Em recurso | M71: =IF(H71="Sim",G71,0) -> 0 | N71: =IF(AND(H71="Sim",I71<>"Aceito"),G71+ROW()/100000,0) -> 0
A72: G2026-0498 | B72: 46191 | C72: Fernanda Gonçalves | D72: Saúde Total | E72: Avaliação endócrina | F72: Dra. Renata Sousa | G72: 130 | J72: =IF(B72="","",DATE(YEAR(B72),MONTH(B72),1)) -> 46174 | K72: =IF(OR(B72="",D72=""),"",D72&"|"&TEXT(J72,"yyyy-mm")) -> Saúde Total|2026-06 | L72: =IF(K72="","",IFERROR(INDEX(Lotes!$N$5:$N$154,MATCH(K72,Lotes!$P$5:$P$154,0)),"Sem lote cadastrado")) -> Em recurso | M72: =IF(H72="Sim",G72,0) -> 0 | N72: =IF(AND(H72="Sim",I72<>"Aceito"),G72+ROW()/100000,0) -> 0
A73: G2026-0499 | B73: 46191 | C73: Priscila Rocha | D73: MediPlan | E73: Consulta | F73: Dr. Paulo Andrade | G73: 100 | J73: =IF(B73="","",DATE(YEAR(B73),MONTH(B73),1)) -> 46174 | K73: =IF(OR(B73="",D73=""),"",D73&"|"&TEXT(J73,"yyyy-mm")) -> MediPlan|2026-06 | L73: =IF(K73="","",IFERROR(INDEX(Lotes!$N$5:$N$154,MATCH(K73,Lotes!$P$5:$P$154,0)),"Sem lote cadastrado")) -> Paga com glosa | M73: =IF(H73="Sim",G73,0) -> 0 | N73: =IF(AND(H73="Sim",I73<>"Aceito"),G73+ROW()/100000,0) -> 0
A74: G2026-0500 | B74: 46191 | C74: Helena Ribeiro | D74: MediPlan | E74: Consulta | F74: Dr. Paulo Andrade | G74: 100 | J74: =IF(B74="","",DATE(YEAR(B74),MONTH(B74),1)) -> 46174 | K74: =IF(OR(B74="",D74=""),"",D74&"|"&TEXT(J74,"yyyy-mm")) -> MediPlan|2026-06 | L74: =IF(K74="","",IFERROR(INDEX(Lotes!$N$5:$N$154,MATCH(K74,Lotes!$P$5:$P$154,0)),"Sem lote cadastrado")) -> Paga com glosa | M74: =IF(H74="Sim",G74,0) -> 0 | N74: =IF(AND(H74="Sim",I74<>"Aceito"),G74+ROW()/100000,0) -> 0
A75: G2026-0501 | B75: 46191 | C75: Camila Martins | D75: Vida Care | E75: Teste ergométrico | F75: Dr. Paulo Andrade | G75: 110 | J75: =IF(B75="","",DATE(YEAR(B75),MONTH(B75),1)) -> 46174 | K75: =IF(OR(B75="",D75=""),"",D75&"|"&TEXT(J75,"yyyy-mm")) -> Vida Care|2026-06 | L75: =IF(K75="","",IFERROR(INDEX(Lotes!$N$5:$N$154,MATCH(K75,Lotes!$P$5:$P$154,0)),"Sem lote cadastrado")) -> Atrasada | M75: =IF(H75="Sim",G75,0) -> 0 | N75: =IF(AND(H75="Sim",I75<>"Aceito"),G75+ROW()/100000,0) -> 0
A76: G2026-0502 | B76: 46191 | C76: Rafael Araújo | D76: MediPlan | E76: Consulta | F76: Dr. Paulo Andrade | G76: 100 | J76: =IF(B76="","",DATE(YEAR(B76),MONTH(B76),1)) -> 46174 | K76: =IF(OR(B76="",D76=""),"",D76&"|"&TEXT(J76,"yyyy-mm")) -> MediPlan|2026-06 | L76: =IF(K76="","",IFERROR(INDEX(Lotes!$N$5:$N$154,MATCH(K76,Lotes!$P$5:$P$154,0)),"Sem lote cadastrado")) -> Paga com glosa | M76: =IF(H76="Sim",G76,0) -> 0 | N76: =IF(AND(H76="Sim",I76<>"Aceito"),G76+ROW()/100000,0) -> 0
A77: G2026-0503 | B77: 46191 | C77: Ricardo Melo | D77: Saúde Total | E77: MAPA | F77: Dr. Paulo Andrade | G77: 95 | J77: =IF(B77="","",DATE(YEAR(B77),MONTH(B77),1)) -> 46174 | K77: =IF(OR(B77="",D77=""),"",D77&"|"&TEXT(J77,"yyyy-mm")) -> Saúde Total|2026-06 | L77: =IF(K77="","",IFERROR(INDEX(Lotes!$N$5:$N$154,MATCH(K77,Lotes!$P$5:$P$154,0)),"Sem lote cadastrado")) -> Em recurso | M77: =IF(H77="Sim",G77,0) -> 0 | N77: =IF(AND(H77="Sim",I77<>"Aceito"),G77+ROW()/100000,0) -> 0
A78: G2026-0504 | B78: 46192 | C78: Gabriel Vieira | D78: Vida Care | E78: Consulta | F78: Dr. Paulo Andrade | G78: 90 | J78: =IF(B78="","",DATE(YEAR(B78),MONTH(B78),1)) -> 46174 | K78: =IF(OR(B78="",D78=""),"",D78&"|"&TEXT(J78,"yyyy-mm")) -> Vida Care|2026-06 | L78: =IF(K78="","",IFERROR(INDEX(Lotes!$N$5:$N$154,MATCH(K78,Lotes!$P$5:$P$154,0)),"Sem lote cadastrado")) -> Atrasada | M78: =IF(H78="Sim",G78,0) -> 0 | N78: =IF(AND(H78="Sim",I78<>"Aceito"),G78+ROW()/100000,0) -> 0
...

Sheet Lotes
A1: Lotes de convênio
A2: Uma linha por convênio e mês de competência. Amarelo: guias e valor enviados, data de envio, pagamento recebido, recurso de glosa e valor recuperado. Branco: previsão, glosa, situação e atraso.
A4: Convênio | B4: Competência (mês) | C4: Nº de guias | D4: Valor enviado (R$) | E4: Data de envio | F4: Data do pagamento | G4: Valor pago (R$) | H4: Recurso de glosa | I4: Valor recuperado (R$) | J4: Data da recuperação | K4: Prazo (dias) | L4: Previsão de pagamento | M4: Glosa (R$) | N4: Situação | O4: Dias de atraso | P4: Chave | Q4: Guias na aba Guias (R$) | R4: Diferença (R$)
A5: Saúde Total | B5: 45931 | C5: 46 | D5: 4290 | E5: 45966 | F5: 45999 | G5: 4180 | K5: =IF(A5="","",IFERROR(INDEX(Config!$B$10:$B$15,MATCH(A5,Config!$A$10:$A$15,0)),"")) -> 30 | L5: =IF(OR(A5="",E5="",K5=""),"",E5+K5) -> 45996 | M5: =IF(OR(A5="",F5=""),0,MAX(0,D5-G5)) -> 110 | N5: =IF(A5="","",IF(E5="","Em separação",IF(F5<>"",IF(H5="Em recurso","Em recurso",IF(M5>0,"Paga com glosa","Paga")),IF(L5+Config!$B$7<Config!$B$5,"Atrasada","Aguardando")))) -> Paga com glosa | O5: =IF(N5="Atrasada",Config!$B$5-L5,"") | P5: =IF(OR(A5="",B5=""),"",A5&"|"&TEXT(B5,"yyyy-mm")) -> Saúde Total|2025-10 | Q5: =IF(P5="","",IF(COUNTIF(Guias!$K$5:$K$1504,P5)=0,"",SUMIFS(Guias!$G$5:$G$1504,Guias!$K$5:$K$1504,P5))) | R5: =IF(Q5="","",D5-Q5) | S5: =IF(OR(N5="Atrasada",N5="Aguardando"),IF(N5="Atrasada",100000+O5,0)+D5/1000000+ROW()/100000000,0) -> 0 | T5: =IF(AND(F5<>"",E5<>""),F5-E5,"") -> 33
