Workbook

Sheet Como usar
A1: Parcelas particulares e inadimplência
A2: Kit de Gestão para Médicos · Seu Sócio Gestor · versão 1.0 (setembro de 2026)
A4: O que esta planilha faz | B4: Você lança as parcelas combinadas a prazo com cada paciente e marca as pagas; ela mostra o que vence nos próximos dias, o que já venceu por faixa de atraso, a inadimplência e a lista de quem cobrar primeiro, com a ação sugerida da régua de cobrança.
A5: Passo 1 | B5: Em Config, ajuste as janelas (7 e 30 dias) e a régua: a partir de quantos dias de atraso fazer o quê. Escreva as ações do seu jeito, educadas e diretas.
A6: Passo 2 | B6: Em Pacientes, cole os nomes e contatos da planilha 01 (aba Pacientes; a 01 é a fonte) de quem paga a prazo. É a lista que alimenta a escolha do paciente em Parcelas.
A7: Passo 3 | B7: Em Parcelas, uma linha por parcela: paciente, procedimento, data do atendimento, número da parcela, vencimento e valor. Quando receber, marque Pago? = Sim e a data, e lance a mesma entrada no caixa (planilha 09, categoria "Particular a prazo"). O à vista não entra aqui.
A8: Passo 4 | B8: Em Painel, veja o que vence em 7 e 30 dias, o vencido por faixa, a inadimplência (vencido ÷ (pago + vencido), a mesma conta das planilhas 17, 19 e 20) e a lista "Cobrar primeiro" com o texto da régua para cada parcela.
A9: Rotina | B9: Sexta-feira, 4 minutos (rotina da semana, planilha 03): conferir o extrato, marcar as parcelas pagas, mandar as mensagens da lista "Cobrar primeiro" e lembrar quem vence na semana seguinte. Tudo numa passada só, na sexta.
A10: Com a IA | B10: Copie uma linha de "Cobrar primeiro" (sem o nome: procedimento, valor, dias, ação) e use o prompt "Recebíveis 04 · Cobrança educada em três versões" da biblioteca do kit, ou os 15 modelos de mensagem do bônus. Nunca cole dados do paciente que ele não autorizou.
A11: Legenda | B11: Células amarelas: você preenche. Brancas: calculadas. Não é preciso mexer em nada fora do amarelo.
A12: Proteção | B12: Fórmulas protegidas sem senha. Para editar: Revisar > Desproteger planilha (Excel) ou Dados > Proteger intervalos (Google Sheets).
A13: Requisitos | B13: Excel 2016 ou mais novo, Microsoft 365 ou Google Sheets (só funções do Excel 2007+; nada de MÍNIMOSES, MÁXIMOSES ou UNIRTEXTO). No celular abre nos aplicativos; para preencher, use o computador.
A14: Dados de pacientes | B14: Guarde só o que a gestão precisa (nome, contato, valor, data). Nada de diagnóstico, prontuário ou exame nestas planilhas: o kit é gestão, não é prontuário. Veja o guia LGPD do kit antes de colar qualquer tabela em uma IA.
A15: Google Sheets | B15: Faça upload no Google Drive e abra com o Google Sheets. Fórmulas, listas, cores, semáforos e gráficos funcionam: as regras de cor que dependem do mês escolhido em Config usam INDIRECT, que é a forma que o Sheets aceita para regra condicional apontar para outra aba.
... A18: Suporte | B18: suporte@seusociogestor.com.br · resposta em até 5 dias úteis · reembolso em até 7 dias pelo mesmo canal.

Sheet Painel
A1: =Config!$B$4&" · Parcelas e inadimplência · "&TEXT(DAY(Config!$B$5),"00")&"/"&TEXT(MONTH(Config!$B$5),"00")&"/"&YEAR(Config!$B$5) -> Clínica Vida Plena (exemplo fictício) · Parcelas e inadimplência · 14/09/2026
A2: Nada para digitar aqui: tudo vem de Parcelas e da régua em Config. Só o que foi combinado a prazo entra aqui.
A4: ="Vence em até "&Config!$B$6&" dias" -> Vence em até 7 dias | C4: ="Vence em até "&Config!$B$7&" dias" -> Vence em até 30 dias | E4: Em aberto (total) | G4: Vencido (R$) | I4: Parcelas vencidas | K4: Inadimplência (vencido ÷ (pago + vencido))
A5: =SUMIFS(Parcelas!$F$5:$F$404,Parcelas!$I$5:$I$404,"A vencer",Parcelas!$K$5:$K$404,"<="&Config!$B$6) -> 970 | C5: =SUMIFS(Parcelas!$F$5:$F$404,Parcelas!$I$5:$I$404,"A vencer",Parcelas!$K$5:$K$404,"<="&Config!$B$7) -> 4705 | E5: =SUMIFS(Parcelas!$F$5:$F$404,Parcelas!$I$5:$I$404,"A vencer")+SUMIFS(Parcelas!$F$5:$F$404,Parcelas!$I$5:$I$404,"Vencida") -> 9855 | G5: =SUMIFS(Parcelas!$F$5:$F$404,Parcelas!$I$5:$I$404,"Vencida") -> 3775 | I5: =COUNTIFS(Parcelas!$I$5:$I$404,"Vencida") -> 14 | K5: =IFERROR(G5/(G5+SUMIFS(Parcelas!$F$5:$F$404,Parcelas!$I$5:$I$404,"Paga")),0) -> 0.093579574
A7: Inadimplência = vencido ÷ (pago + vencido): de tudo o que já venceu, quanto ainda não entrou. É a definição usada em todo o kit (17, 19, 20) e vale só para o que foi combinado a prazo (o à vista entra direto no caixa). Outra conta possível, vencido ÷ em aberto, mede a carteira futura e dá um número maior; não a use para comparar com estas planilhas.
A9: Vencidas por faixa de atraso
A10: Faixa | B10: Parcelas | C10: Valor (R$) | D10: % do vencido | E10: Ação da régua
A11: =IF(Config!$C$10="","",Config!$C$10) -> 1 a 6 dias | B11: =IF(Config!$C$10="","",COUNTIFS(Parcelas!$L$5:$L$404,Config!$C$10)) -> 2 | C11: =IF(Config!$C$10="","",SUMIFS(Parcelas!$F$5:$F$404,Parcelas!$L$5:$L$404,Config!$C$10)) -> 320 | D11: =IF(Config!$C$10="","",IFERROR(C11/$G$5,0)) -> 0.084768212 | E11: =IF(Config!$C$10="","",Config!$B$10) -> Lembrete gentil por WhatsApp: confirmar se o Pix chegou e reenviar o link de pagamento, se preciso.
A12: =IF(Config!$C$11="","",Config!$C$11) -> 7 a 14 dias | B12: =IF(Config!$C$11="","",COUNTIFS(Parcelas!$L$5:$L$404,Config!$C$11)) -> 0 | C12: =IF(Config!$C$11="","",SUMIFS(Parcelas!$F$5:$F$404,Parcelas!$L$5:$L$404,Config!$C$11)) -> 0 | D12: =IF(Config!$C$11="","",IFERROR(C12/$G$5,0)) -> 0 | E12: =IF(Config!$C$11="","",Config!$B$11) -> Mensagem da recepção perguntando se houve algum imprevisto e oferecendo uma nova data para o pagamento.
A13: =IF(Config!$C$12="","",Config!$C$12) -> 15 a 29 dias | B13: =IF(Config!$C$12="","",COUNTIFS(Parcelas!$L$5:$L$404,Config!$C$12)) -> 0 | C13: =IF(Config!$C$12="","",SUMIFS(Parcelas!$F$5:$F$404,Parcelas!$L$5:$L$404,Config!$C$12)) -> 0 | D13: =IF(Config!$C$12="","",IFERROR(C13/$G$5,0)) -> 0 | E13: =IF(Config!$C$12="","",Config!$B$12) -> Ligação da recepção com o demonstrativo das parcelas em aberto e proposta de nova data ou divisão do valor.
A14: =IF(Config!$C$13="","",Config!$C$13) -> 30 dias ou mais | B14: =IF(Config!$C$13="","",COUNTIFS(Parcelas!$L$5:$L$404,Config!$C$13)) -> 12 | C14: =IF(Config!$C$13="","",SUMIFS(Parcelas!$F$5:$F$404,Parcelas!$L$5:$L$404,Config!$C$13)) -> 3455 | D14: =IF(Config!$C$13="","",IFERROR(C14/$G$5,0)) -> 0.91523179 | E14: =IF(Config!$C$13="","",Config!$B$13) -> Conversa do médico ou da administração para combinar um plano de pagamento; registrar por escrito o que foi combinado.
A15: Antes da régua | B15: =COUNTIFS(Parcelas!$L$5:$L$404,"Antes da régua") -> 0 | C15: =SUMIFS(Parcelas!$F$5:$F$404,Parcelas!$L$5:$L$404,"Antes da régua") -> 0 | D15: =IFERROR(C15/$G$5,0) -> 0 | E15: Vencidas há menos dias que o primeiro passo da régua.
A17: Cobrar primeiro
A18: Parcelas vencidas em ordem de valor × dias de atraso: as que mais pesam no caixa vêm no topo. O texto da última coluna é a ação da régua para a faixa de cada uma.
A19: # | B19: Paciente | C19: Procedimento | D19: Parcela | E19: Vencimento | F19: Valor (R$) | G19: Dias de atraso | H19: Faixa | I19: Ação sugerida
A20: 1 | B20: =IFERROR(IF(LARGE(Parcelas!$N$5:$N$404,1)>0,INDEX(Parcelas!$A$5:$A$404,MATCH(LARGE(Parcelas!$N$5:$N$404,1),Parcelas!$N$5:$N$404,0)),""),"") -> Gabriel Reis | C20: =IFERROR(IF(LARGE(Parcelas!$N$5:$N$404,1)>0,INDEX(Parcelas!$B$5:$B$404,MATCH(LARGE(Parcelas!$N$5:$N$404,1),Parcelas!$N$5:$N$404,0)),""),"") -> Avaliação endócrina | D20: =IFERROR(IF(LARGE(Parcelas!$N$5:$N$404,1)>0,INDEX(Parcelas!$D$5:$D$404,MATCH(LARGE(Parcelas!$N$5:$N$404,1),Parcelas!$N$5:$N$404,0)),""),"") -> 1 | E20: =IFERROR(IF(LARGE(Parcelas!$N$5:$N$404,1)>0,INDEX(Parcelas!$E$5:$E$404,MATCH(LARGE(Parcelas!$N$5:$N$404,1),Parcelas!$N$5:$N$404,0)),""),"") -> 46121 | F20: =IFERROR(IF(LARGE(Parcelas!$N$5:$N$404,1)>0,INDEX(Parcelas!$F$5:$F$404,MATCH(LARGE(Parcelas!$N$5:$N$404,1),Parcelas!$N$5:$N$404,0)),""),"") -> 400 | G20: =IFERROR(IF(LARGE(Parcelas!$N$5:$N$404,1)>0,INDEX(Parcelas!$J$5:$J$404,MATCH(LARGE(Parcelas!$N$5:$N$404,1),Parcelas!$N$5:$N$404,0)),""),"") -> 158 | H20: =IFERROR(IF(LARGE(Parcelas!$N$5:$N$404,1)>0,INDEX(Parcelas!$L$5:$L$404,MATCH(LARGE(Parcelas!$N$5:$N$404,1),Parcelas!$N$5:$N$404,0)),""),"") -> 30 dias ou mais | I20: =IFERROR(IF(LARGE(Parcelas!$N$5:$N$404,1)>0,INDEX(Parcelas!$M$5:$M$404,MATCH(LARGE(Parcelas!$N$5:$N$404,1),Parcelas!$N$5:$N$404,0)),""),"") -> Conversa do médico ou da administração para combinar um plano de pagamento; registrar por escrito o que foi combinado.
A21: 2 | B21: =IFERROR(IF(LARGE(Parcelas!$N$5:$N$404,2)>0,INDEX(Parcelas!$A$5:$A$404,MATCH(LARGE(Parcelas!$N$5:$N$404,2),Parcelas!$N$5:$N$404,0)),""),"") -> Priscila Reis | C21: =IFERROR(IF(LARGE(Parcelas!$N$5:$N$404,2)>0,INDEX(Parcelas!$B$5:$B$404,MATCH(LARGE(Parcelas!$N$5:$N$404,2),Parcelas!$N$5:$N$404,0)),""),"") -> Avaliação endócrina | D21: =IFERROR(IF(LARGE(Parcelas!$N$5:$N$404,2)>0,INDEX(Parcelas!$D$5:$D$404,MATCH(LARGE(Parcelas!$N$5:$N$404,2),Parcelas!$N$5:$N$404,0)),""),"") -> 1 | E21: =IFERROR(IF(LARGE(Parcelas!$N$5:$N$404,2)>0,INDEX(Parcelas!$E$5:$E$404,MATCH(LARGE(Parcelas!$N$5:$N$404,2),Parcelas!$N$5:$N$404,0)),""),"") -> 46149 | F21: =IFERROR(IF(LARGE(Parcelas!$N$5:$N$404,2)>0,INDEX(Parcelas!$F$5:$F$404,MATCH(LARGE(Parcelas!$N$5:$N$404,2),Parcelas!$N$5:$N$404,0)),""),"") -> 400 | G21: =IFERROR(IF(LARGE(Parcelas!$N$5:$N$404,2)>0,INDEX(Parcelas!$J$5:$J$404,MATCH(LARGE(Parcelas!$N$5:$N$404,2),Parcelas!$N$5:$N$404,0)),""),"") -> 130 | H21: =IFERROR(IF(LARGE(Parcelas!$N$5:$N$404,2)>0,INDEX(Parcelas!$L$5:$L$404,MATCH(LARGE(Parcelas!$N$5:$N$404,2),Parcelas!$N$5:$N$404,0)),""),"") -> 30 dias ou mais | I21: =IFERROR(IF(LARGE(Parcelas!$N$5:$N$404,2)>0,INDEX(Parcelas!$M$5:$M$404,MATCH(LARGE(Parcelas!$N$5:$N$404,2),Parcelas!$N$5:$N$404,0)),""),"") -> Conversa do médico ou da administração para combinar um plano de pagamento; registrar por escrito o que foi combinado.
A22: 3 | B22: =IFERROR(IF(LARGE(Parcelas!$N$5:$N$404,3)>0,INDEX(Parcelas!$A$5:$A$404,MATCH(LARGE(Parcelas!$N$5:$N$404,3),Parcelas!$N$5:$N$404,0)),""),"") -> Márcia Duarte | C22: =IFERROR(IF(LARGE(Parcelas!$N$5:$N$404,3)>0,INDEX(Parcelas!$B$5:$B$404,MATCH(LARGE(Parcelas!$N$5:$N$404,3),Parcelas!$N$5:$N$404,0)),""),"") -> Avaliação endócrina | D22: =IFERROR(IF(LARGE(Parcelas!$N$5:$N$404,3)>0,INDEX(Parcelas!$D$5:$D$404,MATCH(LARGE(Parcelas!$N$5:$N$404,3),Parcelas!$N$5:$N$404,0)),""),"") -> 1 | E22: =IFERROR(IF(LARGE(Parcelas!$N$5:$N$404,3)>0,INDEX(Parcelas!$E$5:$E$404,MATCH(LARGE(Parcelas!$N$5:$N$404,3),Parcelas!$N$5:$N$404,0)),""),"") -> 46065 | F22: =IFERROR(IF(LARGE(Parcelas!$N$5:$N$404,3)>0,INDEX(Parcelas!$F$5:$F$404,MATCH(LARGE(Parcelas!$N$5:$N$404,3),Parcelas!$N$5:$N$404,0)),""),"") -> 200 | G22: =IFERROR(IF(LARGE(Parcelas!$N$5:$N$404,3)>0,INDEX(Parcelas!$J$5:$J$404,MATCH(LARGE(Parcelas!$N$5:$N$404,3),Parcelas!$N$5:$N$404,0)),""),"") -> 214 | H22: =IFERROR(IF(LARGE(Parcelas!$N$5:$N$404,3)>0,INDEX(Parcelas!$L$5:$L$404,MATCH(LARGE(Parcelas!$N$5:$N$404,3),Parcelas!$N$5:$N$404,0)),""),"") -> 30 dias ou mais | I22: =IFERROR(IF(LARGE(Parcelas!$N$5:$N$404,3)>0,INDEX(Parcelas!$M$5:$M$404,MATCH(LARGE(Parcelas!$N$5:$N$404,3),Parcelas!$N$5:$N$404,0)),""),"") -> Conversa do médico ou da administração para combinar um plano de pagamento; registrar por escrito o que foi combinado.
A23: 4 | B23: =IFERROR(IF(LARGE(Parcelas!$N$5:$N$404,4)>0,INDEX(Parcelas!$A$5:$A$404,MATCH(LARGE(Parcelas!$N$5:$N$404,4),Parcelas!$N$5:$N$404,0)),""),"") -> Helena Moreira | C23: =IFERROR(IF(LARGE(Parcelas!$N$5:$N$404,4)>0,INDEX(Parcelas!$B$5:$B$404,MATCH(LARGE(Parcelas!$N$5:$N$404,4),Parcelas!$N$5:$N$404,0)),""),"") -> Consulta | D23: =IFERROR(IF(LARGE(Parcelas!$N$5:$N$404,4)>0,INDEX(Parcelas!$D$5:$D$404,MATCH(LARGE(Parcelas!$N$5:$N$404,4),Parcelas!$N$5:$N$404,0)),""),"") -> 1 | E23: =IFERROR(IF(LARGE(Parcelas!$N$5:$N$404,4)>0,INDEX(Parcelas!$E$5:$E$404,MATCH(LARGE(Parcelas!$N$5:$N$404,4),Parcelas!$N$5:$N$404,0)),""),"") -> 46186 | F23: =IFERROR(IF(LARGE(Parcelas!$N$5:$N$404,4)>0,INDEX(Parcelas!$F$5:$F$404,MATCH(LARGE(Parcelas!$N$5:$N$404,4),Parcelas!$N$5:$N$404,0)),""),"") -> 380 | G23: =IFERROR(IF(LARGE(Parcelas!$N$5:$N$404,4)>0,INDEX(Parcelas!$J$5:$J$404,MATCH(LARGE(Parcelas!$N$5:$N$404,4),Parcelas!$N$5:$N$404,0)),""),"") -> 93 | H23: =IFERROR(IF(LARGE(Parcelas!$N$5:$N$404,4)>0,INDEX(Parcelas!$L$5:$L$404,MATCH(LARGE(Parcelas!$N$5:$N$404,4),Parcelas!$N$5:$N$404,0)),""),"") -> 30 dias ou mais | I23: =IFERROR(IF(LARGE(Parcelas!$N$5:$N$404,4)>0,INDEX(Parcelas!$M$5:$M$404,MATCH(LARGE(Parcelas!$N$5:$N$404,4),Parcelas!$N$5:$N$404,0)),""),"") -> Conversa do médico ou da administração para combinar um plano de pagamento; registrar por escrito o que foi combinado.
A24: 5 | B24: =IFERROR(IF(LARGE(Parcelas!$N$5:$N$404,5)>0,INDEX(Parcelas!$A$5:$A$404,MATCH(LARGE(Parcelas!$N$5:$N$404,5),Parcelas!$N$5:$N$404,0)),""),"") -> Mônica Martins | C24: =IFERROR(IF(LARGE(Parcelas!$N$5:$N$404,5)>0,INDEX(Parcelas!$B$5:$B$404,MATCH(LARGE(Parcelas!$N$5:$N$404,5),Parcelas!$N$5:$N$404,0)),""),"") -> Consulta | D24: =IFERROR(IF(LARGE(Parcelas!$N$5:$N$404,5)>0,INDEX(Parcelas!$D$5:$D$404,MATCH(LARGE(Parcelas!$N$5:$N$404,5),Parcelas!$N$5:$N$404,0)),""),"") -> 1 | E24: =IFERROR(IF(LARGE(Parcelas!$N$5:$N$404,5)>0,INDEX(Parcelas!$E$5:$E$404,MATCH(LARGE(Parcelas!$N$5:$N$404,5),Parcelas!$N$5:$N$404,0)),""),"") -> 46094 | F24: =IFERROR(IF(LARGE(Parcelas!$N$5:$N$404,5)>0,INDEX(Parcelas!$F$5:$F$404,MATCH(LARGE(Parcelas!$N$5:$N$404,5),Parcelas!$N$5:$N$404,0)),""),"") -> 190 | G24: =IFERROR(IF(LARGE(Parcelas!$N$5:$N$404,5)>0,INDEX(Parcelas!$J$5:$J$404,MATCH(LARGE(Parcelas!$N$5:$N$404,5),Parcelas!$N$5:$N$404,0)),""),"") -> 185 | H24: =IFERROR(IF(LARGE(Parcelas!$N$5:$N$404,5)>0,INDEX(Parcelas!$L$5:$L$404,MATCH(LARGE(Parcelas!$N$5:$N$404,5),Parcelas!$N$5:$N$404,0)),""),"") -> 30 dias ou mais | I24: =IFERROR(IF(LARGE(Parcelas!$N$5:$N$404,5)>0,INDEX(Parcelas!$M$5:$M$404,MATCH(LARGE(Parcelas!$N$5:$N$404,5),Parcelas!$N$5:$N$404,0)),""),"") -> Conversa do médico ou da administração para combinar um plano de pagamento; registrar por escrito o que foi combinado.
A25: 6 | B25: =IFERROR(IF(LARGE(Parcelas!$N$5:$N$404,6)>0,INDEX(Parcelas!$A$5:$A$404,MATCH(LARGE(Parcelas!$N$5:$N$404,6),Parcelas!$N$5:$N$404,0)),""),"") -> Mariana Nascimento | C25: =IFERROR(IF(LARGE(Parcelas!$N$5:$N$404,6)>0,INDEX(Parcelas!$B$5:$B$404,MATCH(LARGE(Parcelas!$N$5:$N$404,6),Parcelas!$N$5:$N$404,0)),""),"") -> Consulta | D25: =IFERROR(IF(LARGE(Parcelas!$N$5:$N$404,6)>0,INDEX(Parcelas!$D$5:$D$404,MATCH(LARGE(Parcelas!$N$5:$N$404,6),Parcelas!$N$5:$N$404,0)),""),"") -> 1 | E25: =IFERROR(IF(LARGE(Parcelas!$N$5:$N$404,6)>0,INDEX(Parcelas!$E$5:$E$404,MATCH(LARGE(Parcelas!$N$5:$N$404,6),Parcelas!$N$5:$N$404,0)),""),"") -> 46192 | F25: =IFERROR(IF(LARGE(Parcelas!$N$5:$N$404,6)>0,INDEX(Parcelas!$F$5:$F$404,MATCH(LARGE(Parcelas!$N$5:$N$404,6),Parcelas!$N$5:$N$404,0)),""),"") -> 380 | G25: =IFERROR(IF(LARGE(Parcelas!$N$5:$N$404,6)>0,INDEX(Parcelas!$J$5:$J$404,MATCH(LARGE(Parcelas!$N$5:$N$404,6),Parcelas!$N$5:$N$404,0)),""),"") -> 87 | H25: =IFERROR(IF(LARGE(Parcelas!$N$5:$N$404,6)>0,INDEX(Parcelas!$L$5:$L$404,MATCH(LARGE(Parcelas!$N$5:$N$404,6),Parcelas!$N$5:$N$404,0)),""),"") -> 30 dias ou mais | I25: =IFERROR(IF(LARGE(Parcelas!$N$5:$N$404,6)>0,INDEX(Parcelas!$M$5:$M$404,MATCH(LARGE(Parcelas!$N$5:$N$404,6),Parcelas!$N$5:$N$404,0)),""),"") -> Conversa do médico ou da administração para combinar um plano de pagamento; registrar por escrito o que foi combinado.
A26: 7 | B26: =IFERROR(IF(LARGE(Parcelas!$N$5:$N$404,7)>0,INDEX(Parcelas!$A$5:$A$404,MATCH(LARGE(Parcelas!$N$5:$N$404,7),Parcelas!$N$5:$N$404,0)),""),"") -> Mariana Nascimento | C26: =IFERROR(IF(LARGE(Parcelas!$N$5:$N$404,7)>0,INDEX(Parcelas!$B$5:$B$404,MATCH(LARGE(Parcelas!$N$5:$N$404,7),Parcelas!$N$5:$N$404,0)),""),"") -> Consulta | D26: =IFERROR(IF(LARGE(Parcelas!$N$5:$N$404,7)>0,INDEX(Parcelas!$D$5:$D$404,MATCH(LARGE(Parcelas!$N$5:$N$404,7),Parcelas!$N$5:$N$404,0)),""),"") -> 1 | E26: =IFERROR(IF(LARGE(Parcelas!$N$5:$N$404,7)>0,INDEX(Parcelas!$E$5:$E$404,MATCH(LARGE(Parcelas!$N$5:$N$404,7),Parcelas!$N$5:$N$404,0)),""),"") -> 46200 | F26: =IFERROR(IF(LARGE(Parcelas!$N$5:$N$404,7)>0,INDEX(Parcelas!$F$5:$F$404,MATCH(LARGE(Parcelas!$N$5:$N$404,7),Parcelas!$N$5:$N$404,0)),""),"") -> 380 | G26: =IFERROR(IF(LARGE(Parcelas!$N$5:$N$404,7)>0,INDEX(Parcelas!$J$5:$J$404,MATCH(LARGE(Parcelas!$N$5:$N$404,7),Parcelas!$N$5:$N$404,0)),""),"") -> 79 | H26: =IFERROR(IF(LARGE(Parcelas!$N$5:$N$404,7)>0,INDEX(Parcelas!$L$5:$L$404,MATCH(LARGE(Parcelas!$N$5:$N$404,7),Parcelas!$N$5:$N$404,0)),""),"") -> 30 dias ou mais | I26: =IFERROR(IF(LARGE(Parcelas!$N$5:$N$404,7)>0,INDEX(Parcelas!$M$5:$M$404,MATCH(LARGE(Parcelas!$N$5:$N$404,7),Parcelas!$N$5:$N$404,0)),""),"") -> Conversa do médico ou da administração para combinar um plano de pagamento; registrar por escrito o que foi combinado.
A27: 8 | B27: =IFERROR(IF(LARGE(Parcelas!$N$5:$N$404,8)>0,INDEX(Parcelas!$A$5:$A$404,MATCH(LARGE(Parcelas!$N$5:$N$404,8),Parcelas!$N$5:$N$404,0)),""),"") -> Patrícia Fernandes | C27: =IFERROR(IF(LARGE(Parcelas!$N$5:$N$404,8)>0,INDEX(Parcelas!$B$5:$B$404,MATCH(LARGE(Parcelas!$N$5:$N$404,8),Parcelas!$N$5:$N$404,0)),""),"") -> Consulta | D27: =IFERROR(IF(LARGE(Parcelas!$N$5:$N$404,8)>0,INDEX(Parcelas!$D$5:$D$404,MATCH(LARGE(Parcelas!$N$5:$N$404,8),Parcelas!$N$5:$N$404,0)),""),"") -> 2 | E27: =IFERROR(IF(LARGE(Parcelas!$N$5:$N$404,8)>0,INDEX(Parcelas!$E$5:$E$404,MATCH(LARGE(Parcelas!$N$5:$N$404,8),Parcelas!$N$5:$N$404,0)),""),"") -> 46160 | F27: =IFERROR(IF(LARGE(Parcelas!$N$5:$N$404,8)>0,INDEX(Parcelas!$F$5:$F$404,MATCH(LARGE(Parcelas!$N$5:$N$404,8),Parcelas!$N$5:$N$404,0)),""),"") -> 190 | G27: =IFERROR(IF(LARGE(Parcelas!$N$5:$N$404,8)>0,INDEX(Parcelas!$J$5:$J$404,MATCH(LARGE(Parcelas!$N$5:$N$404,8),Parcelas!$N$5:$N$404,0)),""),"") -> 119 | H27: =IFERROR(IF(LARGE(Parcelas!$N$5:$N$404,8)>0,INDEX(Parcelas!$L$5:$L$404,MATCH(LARGE(Parcelas!$N$5:$N$404,8),Parcelas!$N$5:$N$404,0)),""),"") -> 30 dias ou mais | I27: =IFERROR(IF(LARGE(Parcelas!$N$5:$N$404,8)>0,INDEX(Parcelas!$M$5:$M$404,MATCH(LARGE(Parcelas!$N$5:$N$404,8),Parcelas!$N$5:$N$404,0)),""),"") -> Conversa do médico ou da administração para combinar um plano de pagamento; registrar por escrito o que foi combinado.
A28: 9 | B28: =IFERROR(IF(LARGE(Parcelas!$N$5:$N$404,9)>0,INDEX(Parcelas!$A$5:$A$404,MATCH(LARGE(Parcelas!$N$5:$N$404,9),Parcelas!$N$5:$N$404,0)),""),"") -> Rafael Dias | C28: =IFERROR(IF(LARGE(Parcelas!$N$5:$N$404,9)>0,INDEX(Parcelas!$B$5:$B$404,MATCH(LARGE(Parcelas!$N$5:$N$404,9),Parcelas!$N$5:$N$404,0)),""),"") -> Consulta | D28: =IFERROR(IF(LARGE(Parcelas!$N$5:$N$404,9)>0,INDEX(Parcelas!$D$5:$D$404,MATCH(LARGE(Parcelas!$N$5:$N$404,9),Parcelas!$N$5:$N$404,0)),""),"") -> 2 | E28: =IFERROR(IF(LARGE(Parcelas!$N$5:$N$404,9)>0,INDEX(Parcelas!$E$5:$E$404,MATCH(LARGE(Parcelas!$N$5:$N$404,9),Parcelas!$N$5:$N$404,0)),""),"") -> 46165 | F28: =IFERROR(IF(LARGE(Parcelas!$N$5:$N$404,9)>0,INDEX(Parcelas!$F$5:$F$404,MATCH(LARGE(Parcelas!$N$5:$N$404,9),Parcelas!$N$5:$N$404,0)),""),"") -> 190 | G28: =IFERROR(IF(LARGE(Parcelas!$N$5:$N$404,9)>0,INDEX(Parcelas!$J$5:$J$404,MATCH(LARGE(Parcelas!$N$5:$N$404,9),Parcelas!$N$5:$N$404,0)),""),"") -> 114 | H28: =IFERROR(IF(LARGE(Parcelas!$N$5:$N$404,9)>0,INDEX(Parcelas!$L$5:$L$404,MATCH(LARGE(Parcelas!$N$5:$N$404,9),Parcelas!$N$5:$N$404,0)),""),"") -> 30 dias ou mais | I28: =IFERROR(IF(LARGE(Parcelas!$N$5:$N$404,9)>0,INDEX(Parcelas!$M$5:$M$404,MATCH(LARGE(Parcelas!$N$5:$N$404,9),Parcelas!$N$5:$N$404,0)),""),"") -> Conversa do médico ou da administração para combinar um plano de pagamento; registrar por escrito o que foi combinado.
A29: 10 | B29: =IFERROR(IF(LARGE(Parcelas!$N$5:$N$404,10)>0,INDEX(Parcelas!$A$5:$A$404,MATCH(LARGE(Parcelas!$N$5:$N$404,10),Parcelas!$N$5:$N$404,0)),""),"") -> Cláudia Costa | C29: =IFERROR(IF(LARGE(Parcelas!$N$5:$N$404,10)>0,INDEX(Parcelas!$B$5:$B$404,MATCH(LARGE(Parcelas!$N$5:$N$404,10),Parcelas!$N$5:$N$404,0)),""),"") -> Consulta | D29: =IFERROR(IF(LARGE(Parcelas!$N$5:$N$404,10)>0,INDEX(Parcelas!$D$5:$D$404,MATCH(LARGE(Parcelas!$N$5:$N$404,10),Parcelas!$N$5:$N$404,0)),""),"") -> 1 | E29: =IFERROR(IF(LARGE(Parcelas!$N$5:$N$404,10)>0,INDEX(Parcelas!$E$5:$E$404,MATCH(LARGE(Parcelas!$N$5:$N$404,10),Parcelas!$N$5:$N$404,0)),""),"") -> 46225 | F29: =IFERROR(IF(LARGE(Parcelas!$N$5:$N$404,10)>0,INDEX(Parcelas!$F$5:$F$404,MATCH(LARGE(Parcelas!$N$5:$N$404,10),Parcelas!$N$5:$N$404,0)),""),"") -> 380 | G29: =IFERROR(IF(LARGE(Parcelas!$N$5:$N$404,10)>0,INDEX(Parcelas!$J$5:$J$404,MATCH(LARGE(Parcelas!$N$5:$N$404,10),Parcelas!$N$5:$N$404,0)),""),"") -> 54 | H29: =IFERROR(IF(LARGE(Parcelas!$N$5:$N$404,10)>0,INDEX(Parcelas!$L$5:$L$404,MATCH(LARGE(Parcelas!$N$5:$N$404,10),Parcelas!$N$5:$N$404,0)),""),"") -> 30 dias ou mais | I29: =IFERROR(IF(LARGE(Parcelas!$N$5:$N$404,10)>0,INDEX(Parcelas!$M$5:$M$404,MATCH(LARGE(Parcelas!$N$5:$N$404,10),Parcelas!$N$5:$N$404,0)),""),"") -> Conversa do médico ou da administração para combinar um plano de pagamento; registrar por escrito o que foi combinado.
A31: Vencem nos próximos dias
A32: ="Parcelas a vencer em até "&Config!$B$7&" dias, a mais próxima primeiro. Bom momento para lembrar o paciente antes do vencimento." -> Parcelas a vencer em até 30 dias, a mais próxima primeiro. Bom momento para lembrar o paciente antes do vencimento.
A33: # | B33: Paciente | C33: Procedimento | D33: Parcela | E33: Vencimento | F33: Valor (R$) | G33: Dias para vencer
A34: 1 | B34: =IFERROR(IF(LARGE(Parcelas!$O$5:$O$404,1)>0,INDEX(Parcelas!$A$5:$A$404,MATCH(LARGE(Parcelas!$O$5:$O$404,1),Parcelas!$O$5:$O$404,0)),""),"") -> Elaine Cardoso | C34: =IFERROR(IF(LARGE(Parcelas!$O$5:$O$404,1)>0,INDEX(Parcelas!$B$5:$B$404,MATCH(LARGE(Parcelas!$O$5:$O$404,1),Parcelas!$O$5:$O$404,0)),""),"") -> Consulta | D34: =IFERROR(IF(LARGE(Parcelas!$O$5:$O$404,1)>0,INDEX(Parcelas!$D$5:$D$404,MATCH(LARGE(Parcelas!$O$5:$O$404,1),Parcelas!$O$5:$O$404,0)),""),"") -> 1 | E34: =IFERROR(IF(LARGE(Parcelas!$O$5:$O$404,1)>0,INDEX(Parcelas!$E$5:$E$404,MATCH(LARGE(Parcelas!$O$5:$O$404,1),Parcelas!$O$5:$O$404,0)),""),"") -> 46281 | F34: =IFERROR(IF(LARGE(Parcelas!$O$5:$O$404,1)>0,INDEX(Parcelas!$F$5:$F$404,MATCH(LARGE(Parcelas!$O$5:$O$404,1),Parcelas!$O$5:$O$404,0)),""),"") -> 190 | G34: =IFERROR(IF(LARGE(Parcelas!$O$5:$O$404,1)>0,INDEX(Parcelas!$K$5:$K$404,MATCH(LARGE(Parcelas!$O$5:$O$404,1),Parcelas!$O$5:$O$404,0)),""),"") -> 2
A35: 2 | B35: =IFERROR(IF(LARGE(Parcelas!$O$5:$O$404,2)>0,INDEX(Parcelas!$A$5:$A$404,MATCH(LARGE(Parcelas!$O$5:$O$404,2),Parcelas!$O$5:$O$404,0)),""),"") -> Fábio Gomes | C35: =IFERROR(IF(LARGE(Parcelas!$O$5:$O$404,2)>0,INDEX(Parcelas!$B$5:$B$404,MATCH(LARGE(Parcelas!$O$5:$O$404,2),Parcelas!$O$5:$O$404,0)),""),"") -> Avaliação endócrina | D35: =IFERROR(IF(LARGE(Parcelas!$O$5:$O$404,2)>0,INDEX(Parcelas!$D$5:$D$404,MATCH(LARGE(Parcelas!$O$5:$O$404,2),Parcelas!$O$5:$O$404,0)),""),"") -> 1 | E35: =IFERROR(IF(LARGE(Parcelas!$O$5:$O$404,2)>0,INDEX(Parcelas!$E$5:$E$404,MATCH(LARGE(Parcelas!$O$5:$O$404,2),Parcelas!$O$5:$O$404,0)),""),"") -> 46282 | F35: =IFERROR(IF(LARGE(Parcelas!$O$5:$O$404,2)>0,INDEX(Parcelas!$F$5:$F$404,MATCH(LARGE(Parcelas!$O$5:$O$404,2),Parcelas!$O$5:$O$404,0)),""),"") -> 400 | G35: =IFERROR(IF(LARGE(Parcelas!$O$5:$O$404,2)>0,INDEX(Parcelas!$K$5:$K$404,MATCH(LARGE(Parcelas!$O$5:$O$404,2),Parcelas!$O$5:$O$404,0)),""),"") -> 3
A36: 3 | B36: =IFERROR(IF(LARGE(Parcelas!$O$5:$O$404,3)>0,INDEX(Parcelas!$A$5:$A$404,MATCH(LARGE(Parcelas!$O$5:$O$404,3),Parcelas!$O$5:$O$404,0)),""),"") -> Eduardo Lima | C36: =IFERROR(IF(LARGE(Parcelas!$O$5:$O$404,3)>0,INDEX(Parcelas!$B$5:$B$404,MATCH(LARGE(Parcelas!$O$5:$O$404,3),Parcelas!$O$5:$O$404,0)),""),"") -> Consulta | D36: =IFERROR(IF(LARGE(Parcelas!$O$5:$O$404,3)>0,INDEX(Parcelas!$D$5:$D$404,MATCH(LARGE(Parcelas!$O$5:$O$404,3),Parcelas!$O$5:$O$404,0)),""),"") -> 1 | E36: =IFERROR(IF(LARGE(Parcelas!$O$5:$O$404,3)>0,INDEX(Parcelas!$E$5:$E$404,MATCH(LARGE(Parcelas!$O$5:$O$404,3),Parcelas!$O$5:$O$404,0)),""),"") -> 46284 | F36: =IFERROR(IF(LARGE(Parcelas!$O$5:$O$404,3)>0,INDEX(Parcelas!$F$5:$F$404,MATCH(LARGE(Parcelas!$O$5:$O$404,3),Parcelas!$O$5:$O$404,0)),""),"") -> 380 | G36: =IFERROR(IF(LARGE(Parcelas!$O$5:$O$404,3)>0,INDEX(Parcelas!$K$5:$K$404,MATCH(LARGE(Parcelas!$O$5:$O$404,3),Parcelas!$O$5:$O$404,0)),""),"") -> 5
A37: 4 | B37: =IFERROR(IF(LARGE(Parcelas!$O$5:$O$404,4)>0,INDEX(Parcelas!$A$5:$A$404,MATCH(LARGE(Parcelas!$O$5:$O$404,4),Parcelas!$O$5:$O$404,0)),""),"") -> Eduardo Lima | C37: =IFERROR(IF(LARGE(Parcelas!$O$5:$O$404,4)>0,INDEX(Parcelas!$B$5:$B$404,MATCH(LARGE(Parcelas!$O$5:$O$404,4),Parcelas!$O$5:$O$404,0)),""),"") -> Teste ergométrico | D37: =IFERROR(IF(LARGE(Parcelas!$O$5:$O$404,4)>0,INDEX(Parcelas!$D$5:$D$404,MATCH(LARGE(Parcelas!$O$5:$O$404,4),Parcelas!$O$5:$O$404,0)),""),"") -> 2 | E37: =IFERROR(IF(LARGE(Parcelas!$O$5:$O$404,4)>0,INDEX(Parcelas!$E$5:$E$404,MATCH(LARGE(Parcelas!$O$5:$O$404,4),Parcelas!$O$5:$O$404,0)),""),"") -> 46287 | F37: =IFERROR(IF(LARGE(Parcelas!$O$5:$O$404,4)>0,INDEX(Parcelas!$F$5:$F$404,MATCH(LARGE(Parcelas!$O$5:$O$404,4),Parcelas!$O$5:$O$404,0)),""),"") -> 225 | G37: =IFERROR(IF(LARGE(Parcelas!$O$5:$O$404,4)>0,INDEX(Parcelas!$K$5:$K$404,MATCH(LARGE(Parcelas!$O$5:$O$404,4),Parcelas!$O$5:$O$404,0)),""),"") -> 8
A38: 5 | B38: =IFERROR(IF(LARGE(Parcelas!$O$5:$O$404,5)>0,INDEX(Parcelas!$A$5:$A$404,MATCH(LARGE(Parcelas!$O$5:$O$404,5),Parcelas!$O$5:$O$404,0)),""),"") -> Cláudia Santos | C38: =IFERROR(IF(LARGE(Parcelas!$O$5:$O$404,5)>0,INDEX(Parcelas!$B$5:$B$404,MATCH(LARGE(Parcelas!$O$5:$O$404,5),Parcelas!$O$5:$O$404,0)),""),"") -> Consulta | D38: =IFERROR(IF(LARGE(Parcelas!$O$5:$O$404,5)>0,INDEX(Parcelas!$D$5:$D$404,MATCH(LARGE(Parcelas!$O$5:$O$404,5),Parcelas!$O$5:$O$404,0)),""),"") -> 1 | E38: =IFERROR(IF(LARGE(Parcelas!$O$5:$O$404,5)>0,INDEX(Parcelas!$E$5:$E$404,MATCH(LARGE(Parcelas!$O$5:$O$404,5),Parcelas!$O$5:$O$404,0)),""),"") -> 46288 | F38: =IFERROR(IF(LARGE(Parcelas!$O$5:$O$404,5)>0,INDEX(Parcelas!$F$5:$F$404,MATCH(LARGE(Parcelas!$O$5:$O$404,5),Parcelas!$O$5:$O$404,0)),""),"") -> 380 | G38: =IFERROR(IF(LARGE(Parcelas!$O$5:$O$404,5)>0,INDEX(Parcelas!$K$5:$K$404,MATCH(LARGE(Parcelas!$O$5:$O$404,5),Parcelas!$O$5:$O$404,0)),""),"") -> 9
A39: 6 | B39: =IFERROR(IF(LARGE(Parcelas!$O$5:$O$404,6)>0,INDEX(Parcelas!$A$5:$A$404,MATCH(LARGE(Parcelas!$O$5:$O$404,6),Parcelas!$O$5:$O$404,0)),""),"") -> Rodrigo Moreira | C39: =IFERROR(IF(LARGE(Parcelas!$O$5:$O$404,6)>0,INDEX(Parcelas!$B$5:$B$404,MATCH(LARGE(Parcelas!$O$5:$O$404,6),Parcelas!$O$5:$O$404,0)),""),"") -> Teste ergométrico | D39: =IFERROR(IF(LARGE(Parcelas!$O$5:$O$404,6)>0,INDEX(Parcelas!$D$5:$D$404,MATCH(LARGE(Parcelas!$O$5:$O$404,6),Parcelas!$O$5:$O$404,0)),""),"") -> 2 | E39: =IFERROR(IF(LARGE(Parcelas!$O$5:$O$404,6)>0,INDEX(Parcelas!$E$5:$E$404,MATCH(LARGE(Parcelas!$O$5:$O$404,6),Parcelas!$O$5:$O$404,0)),""),"") -> 46290 | F39: =IFERROR(IF(LARGE(Parcelas!$O$5:$O$404,6)>0,INDEX(Parcelas!$F$5:$F$404,MATCH(LARGE(Parcelas!$O$5:$O$404,6),Parcelas!$O$5:$O$404,0)),""),"") -> 225 | G39: =IFERROR(IF(LARGE(Parcelas!$O$5:$O$404,6)>0,INDEX(Parcelas!$K$5:$K$404,MATCH(LARGE(Parcelas!$O$5:$O$404,6),Parcelas!$O$5:$O$404,0)),""),"") -> 11
A40: 7 | B40: =IFERROR(IF(LARGE(Parcelas!$O$5:$O$404,7)>0,INDEX(Parcelas!$A$5:$A$404,MATCH(LARGE(Parcelas!$O$5:$O$404,7),Parcelas!$O$5:$O$404,0)),""),"") -> Sérgio Martins | C40: =IFERROR(IF(LARGE(Parcelas!$O$5:$O$404,7)>0,INDEX(Parcelas!$B$5:$B$404,MATCH(LARGE(Parcelas!$O$5:$O$404,7),Parcelas!$O$5:$O$404,0)),""),"") -> Consulta | D40: =IFERROR(IF(LARGE(Parcelas!$O$5:$O$404,7)>0,INDEX(Parcelas!$D$5:$D$404,MATCH(LARGE(Parcelas!$O$5:$O$404,7),Parcelas!$O$5:$O$404,0)),""),"") -> 1 | E40: =IFERROR(IF(LARGE(Parcelas!$O$5:$O$404,7)>0,INDEX(Parcelas!$E$5:$E$404,MATCH(LARGE(Parcelas!$O$5:$O$404,7),Parcelas!$O$5:$O$404,0)),""),"") -> 46290 | F40: =IFERROR(IF(LARGE(Parcelas!$O$5:$O$404,7)>0,INDEX(Parcelas!$F$5:$F$404,MATCH(LARGE(Parcelas!$O$5:$O$404,7),Parcelas!$O$5:$O$404,0)),""),"") -> 380 | G40: =IFERROR(IF(LARGE(Parcelas!$O$5:$O$404,7)>0,INDEX(Parcelas!$K$5:$K$404,MATCH(LARGE(Parcelas!$O$5:$O$404,7),Parcelas!$O$5:$O$404,0)),""),"") -> 11
A41: 8 | B41: =IFERROR(IF(LARGE(Parcelas!$O$5:$O$404,8)>0,INDEX(Parcelas!$A$5:$A$404,MATCH(LARGE(Parcelas!$O$5:$O$404,8),Parcelas!$O$5:$O$404,0)),""),"") -> Rafael Pereira | C41: =IFERROR(IF(LARGE(Parcelas!$O$5:$O$404,8)>0,INDEX(Parcelas!$B$5:$B$404,MATCH(LARGE(Parcelas!$O$5:$O$404,8),Parcelas!$O$5:$O$404,0)),""),"") -> Avaliação endócrina | D41: =IFERROR(IF(LARGE(Parcelas!$O$5:$O$404,8)>0,INDEX(Parcelas!$D$5:$D$404,MATCH(LARGE(Parcelas!$O$5:$O$404,8),Parcelas!$O$5:$O$404,0)),""),"") -> 2 | E41: =IFERROR(IF(LARGE(Parcelas!$O$5:$O$404,8)>0,INDEX(Parcelas!$E$5:$E$404,MATCH(LARGE(Parcelas!$O$5:$O$404,8),Parcelas!$O$5:$O$404,0)),""),"") -> 46291 | F41: =IFERROR(IF(LARGE(Parcelas!$O$5:$O$404,8)>0,INDEX(Parcelas!$F$5:$F$404,MATCH(LARGE(Parcelas!$O$5:$O$404,8),Parcelas!$O$5:$O$404,0)),""),"") -> 200 | G41: =IFERROR(IF(LARGE(Parcelas!$O$5:$O$404,8)>0,INDEX(Parcelas!$K$5:$K$404,MATCH(LARGE(Parcelas!$O$5:$O$404,8),Parcelas!$O$5:$O$404,0)),""),"") -> 12
A43: Fonte: aba Parcelas. A planilha avisa e sugere; a conversa com o paciente é sua, sempre em particular e sem constrangimento.

Sheet Config
A1: Configurações e régua de cobrança
A2: Células amarelas: você preenche. A régua diz o que fazer em cada faixa de atraso; o texto aparece no Painel, parcela por parcela.
A4: Clínica | B4: Clínica Vida Plena (exemplo fictício)
A5: Data de referência (hoje) | B5: 46279
A6: Janela curta: vence em até (dias) | B6: 7
A7: Janela longa: vence em até (dias) | B7: 30
A9: A partir de (dias de atraso) | B9: Ação sugerida | C9: Faixa (calculada)
A10: 1 | B10: Lembrete gentil por WhatsApp: confirmar se o Pix chegou e reenviar o link de pagamento, se preciso. | C10: =IF(A10="","",IF(A11-1=A10,A10&" dia"&IF(A10>1,"s",""),A10&" a "&(A11-1)&" dias")) -> 1 a 6 dias
A11: 7 | B11: Mensagem da recepção perguntando se houve algum imprevisto e oferecendo uma nova data para o pagamento. | C11: =IF(A11="","",IF(A12-1=A11,A11&" dia"&IF(A11>1,"s",""),A11&" a "&(A12-1)&" dias")) -> 7 a 14 dias
A12: 15 | B12: Ligação da recepção com o demonstrativo das parcelas em aberto e proposta de nova data ou divisão do valor. | C12: =IF(A12="","",IF(A13-1=A12,A12&" dia"&IF(A12>1,"s",""),A12&" a "&(A13-1)&" dias")) -> 15 a 29 dias
A13: 30 | B13: Conversa do médico ou da administração para combinar um plano de pagamento; registrar por escrito o que foi combinado. | C13: =IF(A13="","",A13&" dias ou mais") -> 30 dias ou mais
A15: Os dias precisam estar em ordem crescente (ex.: 1, 7, 15, 30). Cada parcela vencida recebe a ação da maior faixa que ela já alcançou. Escreva as ações como você fala com o paciente: educado, direto e sem ameaça. Cobrança de paciente tem regras próprias (CDC e ética médica): nada de exposição ou constrangimento.
A16: Os modelos de mensagem do bônus "15 modelos de mensagem" seguem esta mesma régua.
A17: Regra que vale mais que a régua: quem tem parcela vencida em aberto não combina novo parcelamento. O atendimento acontece normalmente; o que muda é a forma de pagamento, que passa a ser à vista (Pix, dinheiro ou cartão), combinada em particular e sem constrangimento. Atendimento nunca é condicionado a pagamento. No exemplo do kit, nenhum paciente com parcela vencida recebeu crédito novo, e o mesmo vale para orçamento aprovado a prazo (planilha 15).

Sheet Pacientes
A1: Pacientes (entrada)
A2: Copie da planilha 01 (aba Pacientes; a 01 é a fonte): nome e contato. As colunas brancas somam as parcelas de cada paciente.
A4: Paciente | B4: Contato | C4: Parcelas | D4: Valor em parcelas (R$) | E4: Pago (R$) | F4: Em aberto (R$) | G4: Vencido (R$) | H4: Situação
A5: Ana Costa | B5: (11) 90000-0147 | C5: =IF(A5="","",COUNTIFS(Parcelas!$A$5:$A$404,A5)) -> 3 | D5: =IF(A5="","",SUMIFS(Parcelas!$F$5:$F$404,Parcelas!$A$5:$A$404,A5)) -> 760 | E5: =IF(A5="","",SUMIFS(Parcelas!$F$5:$F$404,Parcelas!$A$5:$A$404,A5,Parcelas!$I$5:$I$404,"Paga")) -> 380 | F5: =IF(A5="","",D5-E5) -> 380 | G5: =IF(A5="","",SUMIFS(Parcelas!$F$5:$F$404,Parcelas!$A$5:$A$404,A5,Parcelas!$I$5:$I$404,"Vencida")) -> 0 | H5: =IF(A5="","",IF(G5>0,"Em atraso",IF(F5>0,"Em dia","Sem parcela em aberto"))) -> Em dia
A6: Beatriz Gomes | B6: (11) 90000-0254 | C6: =IF(A6="","",COUNTIFS(Parcelas!$A$5:$A$404,A6)) -> 2 | D6: =IF(A6="","",SUMIFS(Parcelas!$F$5:$F$404,Parcelas!$A$5:$A$404,A6)) -> 400 | E6: =IF(A6="","",SUMIFS(Parcelas!$F$5:$F$404,Parcelas!$A$5:$A$404,A6,Parcelas!$I$5:$I$404,"Paga")) -> 400 | F6: =IF(A6="","",D6-E6) -> 0 | G6: =IF(A6="","",SUMIFS(Parcelas!$F$5:$F$404,Parcelas!$A$5:$A$404,A6,Parcelas!$I$5:$I$404,"Vencida")) -> 0 | H6: =IF(A6="","",IF(G6>0,"Em atraso",IF(F6>0,"Em dia","Sem parcela em aberto"))) -> Sem parcela em aberto
A7: Camila Dias | B7: (11) 90000-0241 | C7: =IF(A7="","",COUNTIFS(Parcelas!$A$5:$A$404,A7)) -> 3 | D7: =IF(A7="","",SUMIFS(Parcelas!$F$5:$F$404,Parcelas!$A$5:$A$404,A7)) -> 800 | E7: =IF(A7="","",SUMIFS(Parcelas!$F$5:$F$404,Parcelas!$A$5:$A$404,A7,Parcelas!$I$5:$I$404,"Paga")) -> 800 | F7: =IF(A7="","",D7-E7) -> 0 | G7: =IF(A7="","",SUMIFS(Parcelas!$F$5:$F$404,Parcelas!$A$5:$A$404,A7,Parcelas!$I$5:$I$404,"Vencida")) -> 0 | H7: =IF(A7="","",IF(G7>0,"Em atraso",IF(F7>0,"Em dia","Sem parcela em aberto"))) -> Sem parcela em aberto
A8: Camila Freitas | B8: (11) 90000-0212 | C8: =IF(A8="","",COUNTIFS(Parcelas!$A$5:$A$404,A8)) -> 3 | D8: =IF(A8="","",SUMIFS(Parcelas!$F$5:$F$404,Parcelas!$A$5:$A$404,A8)) -> 760 | E8: =IF(A8="","",SUMIFS(Parcelas!$F$5:$F$404,Parcelas!$A$5:$A$404,A8,Parcelas!$I$5:$I$404,"Paga")) -> 760 | F8: =IF(A8="","",D8-E8) -> 0 | G8: =IF(A8="","",SUMIFS(Parcelas!$F$5:$F$404,Parcelas!$A$5:$A$404,A8,Parcelas!$I$5:$I$404,"Vencida")) -> 0 | H8: =IF(A8="","",IF(G8>0,"Em atraso",IF(F8>0,"Em dia","Sem parcela em aberto"))) -> Sem parcela em aberto
A9: Carlos Fernandes | B9: (11) 90000-0154 | C9: =IF(A9="","",COUNTIFS(Parcelas!$A$5:$A$404,A9)) -> 2 | D9: =IF(A9="","",SUMIFS(Parcelas!$F$5:$F$404,Parcelas!$A$5:$A$404,A9)) -> 380 | E9: =IF(A9="","",SUMIFS(Parcelas!$F$5:$F$404,Parcelas!$A$5:$A$404,A9,Parcelas!$I$5:$I$404,"Paga")) -> 190 | F9: =IF(A9="","",D9-E9) -> 190 | G9: =IF(A9="","",SUMIFS(Parcelas!$F$5:$F$404,Parcelas!$A$5:$A$404,A9,Parcelas!$I$5:$I$404,"Vencida")) -> 190 | H9: =IF(A9="","",IF(G9>0,"Em atraso",IF(F9>0,"Em dia","Sem parcela em aberto"))) -> Em atraso
A10: Carlos Freitas | B10: (11) 90000-0223 | C10: =IF(A10="","",COUNTIFS(Parcelas!$A$5:$A$404,A10)) -> 4 | D10: =IF(A10="","",SUMIFS(Parcelas!$F$5:$F$404,Parcelas!$A$5:$A$404,A10)) -> 800 | E10: =IF(A10="","",SUMIFS(Parcelas!$F$5:$F$404,Parcelas!$A$5:$A$404,A10,Parcelas!$I$5:$I$404,"Paga")) -> 800 | F10: =IF(A10="","",D10-E10) -> 0 | G10: =IF(A10="","",SUMIFS(Parcelas!$F$5:$F$404,Parcelas!$A$5:$A$404,A10,Parcelas!$I$5:$I$404,"Vencida")) -> 0 | H10: =IF(A10="","",IF(G10>0,"Em atraso",IF(F10>0,"Em dia","Sem parcela em aberto"))) -> Sem parcela em aberto
A11: Carlos Oliveira | B11: (11) 90000-0215 | C11: =IF(A11="","",COUNTIFS(Parcelas!$A$5:$A$404,A11)) -> 4 | D11: =IF(A11="","",SUMIFS(Parcelas!$F$5:$F$404,Parcelas!$A$5:$A$404,A11)) -> 760 | E11: =IF(A11="","",SUMIFS(Parcelas!$F$5:$F$404,Parcelas!$A$5:$A$404,A11,Parcelas!$I$5:$I$404,"Paga")) -> 760 | F11: =IF(A11="","",D11-E11) -> 0 | G11: =IF(A11="","",SUMIFS(Parcelas!$F$5:$F$404,Parcelas!$A$5:$A$404,A11,Parcelas!$I$5:$I$404,"Vencida")) -> 0 | H11: =IF(A11="","",IF(G11>0,"Em atraso",IF(F11>0,"Em dia","Sem parcela em aberto"))) -> Sem parcela em aberto
A12: Cláudia Costa | B12: (11) 90000-0163 | C12: =IF(A12="","",COUNTIFS(Parcelas!$A$5:$A$404,A12)) -> 3 | D12: =IF(A12="","",SUMIFS(Parcelas!$F$5:$F$404,Parcelas!$A$5:$A$404,A12)) -> 760 | E12: =IF(A12="","",SUMIFS(Parcelas!$F$5:$F$404,Parcelas!$A$5:$A$404,A12,Parcelas!$I$5:$I$404,"Paga")) -> 380 | F12: =IF(A12="","",D12-E12) -> 380 | G12: =IF(A12="","",SUMIFS(Parcelas!$F$5:$F$404,Parcelas!$A$5:$A$404,A12,Parcelas!$I$5:$I$404,"Vencida")) -> 380 | H12: =IF(A12="","",IF(G12>0,"Em atraso",IF(F12>0,"Em dia","Sem parcela em aberto"))) -> Em atraso
A13: Cláudia Santos | B13: (11) 90000-0106 | C13: =IF(A13="","",COUNTIFS(Parcelas!$A$5:$A$404,A13)) -> 2 | D13: =IF(A13="","",SUMIFS(Parcelas!$F$5:$F$404,Parcelas!$A$5:$A$404,A13)) -> 760 | E13: =IF(A13="","",SUMIFS(Parcelas!$F$5:$F$404,Parcelas!$A$5:$A$404,A13,Parcelas!$I$5:$I$404,"Paga")) -> 380 | F13: =IF(A13="","",D13-E13) -> 380 | G13: =IF(A13="","",SUMIFS(Parcelas!$F$5:$F$404,Parcelas!$A$5:$A$404,A13,Parcelas!$I$5:$I$404,"Vencida")) -> 0 | H13: =IF(A13="","",IF(G13>0,"Em atraso",IF(F13>0,"Em dia","Sem parcela em aberto"))) -> Em dia
A14: Eduardo Lima | B14: (11) 90000-0111 | C14: =IF(A14="","",COUNTIFS(Parcelas!$A$5:$A$404,A14)) -> 4 | D14: =IF(A14="","",SUMIFS(Parcelas!$F$5:$F$404,Parcelas!$A$5:$A$404,A14)) -> 1210 | E14: =IF(A14="","",SUMIFS(Parcelas!$F$5:$F$404,Parcelas!$A$5:$A$404,A14,Parcelas!$I$5:$I$404,"Paga")) -> 605 | F14: =IF(A14="","",D14-E14) -> 605 | G14: =IF(A14="","",SUMIFS(Parcelas!$F$5:$F$404,Parcelas!$A$5:$A$404,A14,Parcelas!$I$5:$I$404,"Vencida")) -> 0 | H14: =IF(A14="","",IF(G14>0,"Em atraso",IF(F14>0,"Em dia","Sem parcela em aberto"))) -> Em dia
A15: Elaine Cardoso | B15: (11) 90000-0144 | C15: =IF(A15="","",COUNTIFS(Parcelas!$A$5:$A$404,A15)) -> 7 | D15: =IF(A15="","",SUMIFS(Parcelas!$F$5:$F$404,Parcelas!$A$5:$A$404,A15)) -> 1650 | E15: =IF(A15="","",SUMIFS(Parcelas!$F$5:$F$404,Parcelas!$A$5:$A$404,A15,Parcelas!$I$5:$I$404,"Paga")) -> 1140 | F15: =IF(A15="","",D15-E15) -> 510 | G15: =IF(A15="","",SUMIFS(Parcelas!$F$5:$F$404,Parcelas!$A$5:$A$404,A15,Parcelas!$I$5:$I$404,"Vencida")) -> 130 | H15: =IF(A15="","",IF(G15>0,"Em atraso",IF(F15>0,"Em dia","Sem parcela em aberto"))) -> Em atraso
A16: Fernanda Freitas | B16: (11) 90000-0120 | C16: =IF(A16="","",COUNTIFS(Parcelas!$A$5:$A$404,A16)) -> 4 | D16: =IF(A16="","",SUMIFS(Parcelas!$F$5:$F$404,Parcelas!$A$5:$A$404,A16)) -> 1130 | E16: =IF(A16="","",SUMIFS(Parcelas!$F$5:$F$404,Parcelas!$A$5:$A$404,A16,Parcelas!$I$5:$I$404,"Paga")) -> 680 | F16: =IF(A16="","",D16-E16) -> 450 | G16: =IF(A16="","",SUMIFS(Parcelas!$F$5:$F$404,Parcelas!$A$5:$A$404,A16,Parcelas!$I$5:$I$404,"Vencida")) -> 0 | H16: =IF(A16="","",IF(G16>0,"Em atraso",IF(F16>0,"Em dia","Sem parcela em aberto"))) -> Em dia
... A64: Wagner Lima | B64: (11) 90000-0137 | C64: =IF(A64="","",COUNTIFS(Parcelas!$A$5:$A$404,A64)) -> 4 | D64: =IF(A64="","",SUMIFS(Parcelas!$F$5:$F$404,Parcelas!$A$5:$A$404,A64)) -> 1310 | E64: =IF(A64="","",SUMIFS(Parcelas!$F$5:$F$404,Parcelas!$A$5:$A$404,A64,Parcelas!$I$5:$I$404,"Paga")) -> 1310 | F64: =IF(A64="","",D64-E64) -> 0 | G64: =IF(A64="","",SUMIFS(Parcelas!$F$5:$F$404,Parcelas!$A$5:$A$404,A64,Parcelas!$I$5:$I$404,"Vencida")) -> 0 | H64: =IF(A64="","",IF(G64>0,"Em atraso",IF(F64>0,"Em dia","Sem parcela em aberto"))) -> Sem parcela em aberto
C65: =IF(A65="","",COUNTIFS(Parcelas!$A$5:$A$404,A65)) | D65: =IF(A65="","",SUMIFS(Parcelas!$F$5:$F$404,Parcelas!$A$5:$A$404,A65)) | E65: =IF(A65="","",SUMIFS(Parcelas!$F$5:$F$404,Parcelas!$A$5:$A$404,A65,Parcelas!$I$5:$I$404,"Paga")) | F65: =IF(A65="","",D65-E65) | G65: =IF(A65="","",SUMIFS(Parcelas!$F$5:$F$404,Parcelas!$A$5:$A$404,A65,Parcelas!$I$5:$I$404,"Vencida")) | H65: =IF(A65="","",IF(G65>0,"Em atraso",IF(F65>0,"Em dia","Sem parcela em aberto")))
C66: =IF(A66="","",COUNTIFS(Parcelas!$A$5:$A$404,A66)) | D66: =IF(A66="","",SUMIFS(Parcelas!$F$5:$F$404,Parcelas!$A$5:$A$404,A66)) | E66: =IF(A66="","",SUMIFS(Parcelas!$F$5:$F$404,Parcelas!$A$5:$A$404,A66,Parcelas!$I$5:$I$404,"Paga")) | F66: =IF(A66="","",D66-E66) | G66: =IF(A66="","",SUMIFS(Parcelas!$F$5:$F$404,Parcelas!$A$5:$A$404,A66,Parcelas!$I$5:$I$404,"Vencida")) | H66: =IF(A66="","",IF(G66>0,"Em atraso",IF(F66>0,"Em dia","Sem parcela em aberto")))
C67: =IF(A67="","",COUNTIFS(Parcelas!$A$5:$A$404,A67)) | D67: =IF(A67="","",SUMIFS(Parcelas!$F$5:$F$404,Parcelas!$A$5:$A$404,A67)) | E67: =IF(A67="","",SUMIFS(Parcelas!$F$5:$F$404,Parcelas!$A$5:$A$404,A67,Parcelas!$I$5:$I$404,"Paga")) | F67: =IF(A67="","",D67-E67) | G67: =IF(A67="","",SUMIFS(Parcelas!$F$5:$F$404,Parcelas!$A$5:$A$404,A67,Parcelas!$I$5:$I$404,"Vencida")) | H67: =IF(A67="","",IF(G67>0,"Em atraso",IF(F67>0,"Em dia","Sem parcela em aberto")))
C68: =IF(A68="","",COUNTIFS(Parcelas!$A$5:$A$404,A68)) | D68: =IF(A68="","",SUMIFS(Parcelas!$F$5:$F$404,Parcelas!$A$5:$A$404,A68)) | E68: =IF(A68="","",SUMIFS(Parcelas!$F$5:$F$404,Parcelas!$A$5:$A$404,A68,Parcelas!$I$5:$I$404,"Paga")) | F68: =IF(A68="","",D68-E68) | G68: =IF(A68="","",SUMIFS(Parcelas!$F$5:$F$404,Parcelas!$A$5:$A$404,A68,Parcelas!$I$5:$I$404,"Vencida")) | H68: =IF(A68="","",IF(G68>0,"Em atraso",IF(F68>0,"Em dia","Sem parcela em aberto")))
C69: =IF(A69="","",COUNTIFS(Parcelas!$A$5:$A$404,A69)) | D69: =IF(A69="","",SUMIFS(Parcelas!$F$5:$F$404,Parcelas!$A$5:$A$404,A69)) | E69: =IF(A69="","",SUMIFS(Parcelas!$F$5:$F$404,Parcelas!$A$5:$A$404,A69,Parcelas!$I$5:$I$404,"Paga")) | F69: =IF(A69="","",D69-E69) | G69: =IF(A69="","",SUMIFS(Parcelas!$F$5:$F$404,Parcelas!$A$5:$A$404,A69,Parcelas!$I$5:$I$404,"Vencida")) | H69: =IF(A69="","",IF(G69>0,"Em atraso",IF(F69>0,"Em dia","Sem parcela em aberto")))
C70: =IF(A70="","",COUNTIFS(Parcelas!$A$5:$A$404,A70)) | D70: =IF(A70="","",SUMIFS(Parcelas!$F$5:$F$404,Parcelas!$A$5:$A$404,A70)) | E70: =IF(A70="","",SUMIFS(Parcelas!$F$5:$F$404,Parcelas!$A$5:$A$404,A70,Parcelas!$I$5:$I$404,"Paga")) | F70: =IF(A70="","",D70-E70) | G70: =IF(A70="","",SUMIFS(Parcelas!$F$5:$F$404,Parcelas!$A$5:$A$404,A70,Parcelas!$I$5:$I$404,"Vencida")) | H70: =IF(A70="","",IF(G70>0,"Em atraso",IF(F70>0,"Em dia","Sem parcela em aberto")))
C71: =IF(A71="","",COUNTIFS(Parcelas!$A$5:$A$404,A71)) | D71: =IF(A71="","",SUMIFS(Parcelas!$F$5:$F$404,Parcelas!$A$5:$A$404,A71)) | E71: =IF(A71="","",SUMIFS(Parcelas!$F$5:$F$404,Parcelas!$A$5:$A$404,A71,Parcelas!$I$5:$I$404,"Paga")) | F71: =IF(A71="","",D71-E71) | G71: =IF(A71="","",SUMIFS(Parcelas!$F$5:$F$404,Parcelas!$A$5:$A$404,A71,Parcelas!$I$5:$I$404,"Vencida")) | H71: =IF(A71="","",IF(G71>0,"Em atraso",IF(F71>0,"Em dia","Sem parcela em aberto")))
C72: =IF(A72="","",COUNTIFS(Parcelas!$A$5:$A$404,A72)) | D72: =IF(A72="","",SUMIFS(Parcelas!$F$5:$F$404,Parcelas!$A$5:$A$404,A72)) | E72: =IF(A72="","",SUMIFS(Parcelas!$F$5:$F$404,Parcelas!$A$5:$A$404,A72,Parcelas!$I$5:$I$404,"Paga")) | F72: =IF(A72="","",D72-E72) | G72: =IF(A72="","",SUMIFS(Parcelas!$F$5:$F$404,Parcelas!$A$5:$A$404,A72,Parcelas!$I$5:$I$404,"Vencida")) | H72: =IF(A72="","",IF(G72>0,"Em atraso",IF(F72>0,"Em dia","Sem parcela em aberto")))
C73: =IF(A73="","",COUNTIFS(Parcelas!$A$5:$A$404,A73)) | D73: =IF(A73="","",SUMIFS(Parcelas!$F$5:$F$404,Parcelas!$A$5:$A$404,A73)) | E73: =IF(A73="","",SUMIFS(Parcelas!$F$5:$F$404,Parcelas!$A$5:$A$404,A73,Parcelas!$I$5:$I$404,"Paga")) | F73: =IF(A73="","",D73-E73) | G73: =IF(A73="","",SUMIFS(Parcelas!$F$5:$F$404,Parcelas!$A$5:$A$404,A73,Parcelas!$I$5:$I$404,"Vencida")) | H73: =IF(A73="","",IF(G73>0,"Em atraso",IF(F73>0,"Em dia","Sem parcela em aberto")))
C74: =IF(A74="","",COUNTIFS(Parcelas!$A$5:$A$404,A74)) | D74: =IF(A74="","",SUMIFS(Parcelas!$F$5:$F$404,Parcelas!$A$5:$A$404,A74)) | E74: =IF(A74="","",SUMIFS(Parcelas!$F$5:$F$404,Parcelas!$A$5:$A$404,A74,Parcelas!$I$5:$I$404,"Paga")) | F74: =IF(A74="","",D74-E74) | G74: =IF(A74="","",SUMIFS(Parcelas!$F$5:$F$404,Parcelas!$A$5:$A$404,A74,Parcelas!$I$5:$I$404,"Vencida")) | H74: =IF(A74="","",IF(G74>0,"Em atraso",IF(F74>0,"Em dia","Sem parcela em aberto")))
C75: =IF(A75="","",COUNTIFS(Parcelas!$A$5:$A$404,A75)) | D75: =IF(A75="","",SUMIFS(Parcelas!$F$5:$F$404,Parcelas!$A$5:$A$404,A75)) | E75: =IF(A75="","",SUMIFS(Parcelas!$F$5:$F$404,Parcelas!$A$5:$A$404,A75,Parcelas!$I$5:$I$404,"Paga")) | F75: =IF(A75="","",D75-E75) | G75: =IF(A75="","",SUMIFS(Parcelas!$F$5:$F$404,Parcelas!$A$5:$A$404,A75,Parcelas!$I$5:$I$404,"Vencida")) | H75: =IF(A75="","",IF(G75>0,"Em atraso",IF(F75>0,"Em dia","Sem parcela em aberto")))
C76: =IF(A76="","",COUNTIFS(Parcelas!$A$5:$A$404,A76)) | D76: =IF(A76="","",SUMIFS(Parcelas!$F$5:$F$404,Parcelas!$A$5:$A$404,A76)) | E76: =IF(A76="","",SUMIFS(Parcelas!$F$5:$F$404,Parcelas!$A$5:$A$404,A76,Parcelas!$I$5:$I$404,"Paga")) | F76: =IF(A76="","",D76-E76) | G76: =IF(A76="","",SUMIFS(Parcelas!$F$5:$F$404,Parcelas!$A$5:$A$404,A76,Parcelas!$I$5:$I$404,"Vencida")) | H76: =IF(A76="","",IF(G76>0,"Em atraso",IF(F76>0,"Em dia","Sem parcela em aberto")))
... C404: =IF(A404="","",COUNTIFS(Parcelas!$A$5:$A$404,A404)) | D404: =IF(A404="","",SUMIFS(Parcelas!$F$5:$F$404,Parcelas!$A$5:$A$404,A404)) | E404: =IF(A404="","",SUMIFS(Parcelas!$F$5:$F$404,Parcelas!$A$5:$A$404,A404,Parcelas!$I$5:$I$404,"Paga")) | F404: =IF(A404="","",D404-E404) | G404: =IF(A404="","",SUMIFS(Parcelas!$F$5:$F$404,Parcelas!$A$5:$A$404,A404,Parcelas!$I$5:$I$404,"Vencida")) | H404: =IF(A404="","",IF(G404>0,"Em atraso",IF(F404>0,"Em dia","Sem parcela em aberto")))
A406: Cadastre aqui todos os pacientes que já pagaram a prazo alguma vez (a lista alimenta a escolha do paciente em Parcelas). Só nome e contato: nada clínico.

Sheet Parcelas
A1: Parcelas
A2: Uma linha por parcela combinada a prazo. Escolha o paciente na lista; situação, dias e ação da régua são calculados.
A4: Paciente | B4: Procedimento | C4: Data do atendimento | D4: Nº da parcela | E4: Vencimento | F4: Valor (R$) | G4: Pago? | H4: Data do pagamento | I4: Situação | J4: Dias de atraso | K4: Dias para vencer | L4: Faixa de atraso | M4: Ação sugerida (régua)
A5: Fábio Gomes | B5: Avaliação endócrina | C5: 46028 | D5: 1 | E5: 46058 | F5: 200 | G5: Sim | H5: 46061 | I5: =IF(A5="","",IF(G5="Sim","Paga",IF(E5="","Sem vencimento",IF(E5<Config!$B$5,"Vencida","A vencer")))) -> Paga | J5: =IF(I5="Vencida",Config!$B$5-E5,"") | K5: =IF(I5="A vencer",E5-Config!$B$5,"") | L5: =IF(I5<>"Vencida","",IF(COUNTIF(Config!$A$10:$A$13,"<="&J5)=0,"Antes da régua",INDEX(Config!$C$10:$C$13,COUNTIF(Config!$A$10:$A$13,"<="&J5)))) | M5: =IF(I5<>"Vencida","",IF(COUNTIF(Config!$A$10:$A$13,"<="&J5)=0,"Aguardar: ainda não chegou ao primeiro passo da régua.",INDEX(Config!$B$10:$B$13,COUNTIF(Config!$A$10:$A$13,"<="&J5)))) | N5: =IF(I5="Vencida",F5*J5+ROW()/100000,0) -> 0 | O5: =IF(AND(I5="A vencer",K5<=Config!$B$7),100000-K5-ROW()/100000,0) -> 0
A6: Fábio Gomes | B6: Avaliação endócrina | C6: 46028 | D6: 2 | E6: 46088 | F6: 200 | G6: Sim | H6: 46088 | I6: =IF(A6="","",IF(G6="Sim","Paga",IF(E6="","Sem vencimento",IF(E6<Config!$B$5,"Vencida","A vencer")))) -> Paga | J6: =IF(I6="Vencida",Config!$B$5-E6,"") | K6: =IF(I6="A vencer",E6-Config!$B$5,"") | L6: =IF(I6<>"Vencida","",IF(COUNTIF(Config!$A$10:$A$13,"<="&J6)=0,"Antes da régua",INDEX(Config!$C$10:$C$13,COUNTIF(Config!$A$10:$A$13,"<="&J6)))) | M6: =IF(I6<>"Vencida","",IF(COUNTIF(Config!$A$10:$A$13,"<="&J6)=0,"Aguardar: ainda não chegou ao primeiro passo da régua.",INDEX(Config!$B$10:$B$13,COUNTIF(Config!$A$10:$A$13,"<="&J6)))) | N6: =IF(I6="Vencida",F6*J6+ROW()/100000,0) -> 0 | O6: =IF(AND(I6="A vencer",K6<=Config!$B$7),100000-K6-ROW()/100000,0) -> 0
A7: Larissa Costa | B7: Consulta | C7: 46030 | D7: 1 | E7: 46060 | F7: 190 | G7: Sim | H7: 46063 | I7: =IF(A7="","",IF(G7="Sim","Paga",IF(E7="","Sem vencimento",IF(E7<Config!$B$5,"Vencida","A vencer")))) -> Paga | J7: =IF(I7="Vencida",Config!$B$5-E7,"") | K7: =IF(I7="A vencer",E7-Config!$B$5,"") | L7: =IF(I7<>"Vencida","",IF(COUNTIF(Config!$A$10:$A$13,"<="&J7)=0,"Antes da régua",INDEX(Config!$C$10:$C$13,COUNTIF(Config!$A$10:$A$13,"<="&J7)))) | M7: =IF(I7<>"Vencida","",IF(COUNTIF(Config!$A$10:$A$13,"<="&J7)=0,"Aguardar: ainda não chegou ao primeiro passo da régua.",INDEX(Config!$B$10:$B$13,COUNTIF(Config!$A$10:$A$13,"<="&J7)))) | N7: =IF(I7="Vencida",F7*J7+ROW()/100000,0) -> 0 | O7: =IF(AND(I7="A vencer",K7<=Config!$B$7),100000-K7-ROW()/100000,0) -> 0
A8: Larissa Costa | B8: Consulta | C8: 46030 | D8: 2 | E8: 46090 | F8: 190 | G8: Sim | H8: 46091 | I8: =IF(A8="","",IF(G8="Sim","Paga",IF(E8="","Sem vencimento",IF(E8<Config!$B$5,"Vencida","A vencer")))) -> Paga | J8: =IF(I8="Vencida",Config!$B$5-E8,"") | K8: =IF(I8="A vencer",E8-Config!$B$5,"") | L8: =IF(I8<>"Vencida","",IF(COUNTIF(Config!$A$10:$A$13,"<="&J8)=0,"Antes da régua",INDEX(Config!$C$10:$C$13,COUNTIF(Config!$A$10:$A$13,"<="&J8)))) | M8: =IF(I8<>"Vencida","",IF(COUNTIF(Config!$A$10:$A$13,"<="&J8)=0,"Aguardar: ainda não chegou ao primeiro passo da régua.",INDEX(Config!$B$10:$B$13,COUNTIF(Config!$A$10:$A$13,"<="&J8)))) | N8: =IF(I8="Vencida",F8*J8+ROW()/100000,0) -> 0 | O8: =IF(AND(I8="A vencer",K8<=Config!$B$7),100000-K8-ROW()/100000,0) -> 0
A9: Gisele Ribeiro | B9: Check-up cardiológico (consulta + ECG + teste ergométrico) | C9: 46034 | D9: 1 | E9: 46064 | F9: 480 | G9: Sim | H9: 46065 | I9: =IF(A9="","",IF(G9="Sim","Paga",IF(E9="","Sem vencimento",IF(E9<Config!$B$5,"Vencida","A vencer")))) -> Paga | J9: =IF(I9="Vencida",Config!$B$5-E9,"") | K9: =IF(I9="A vencer",E9-Config!$B$5,"") | L9: =IF(I9<>"Vencida","",IF(COUNTIF(Config!$A$10:$A$13,"<="&J9)=0,"Antes da régua",INDEX(Config!$C$10:$C$13,COUNTIF(Config!$A$10:$A$13,"<="&J9)))) | M9: =IF(I9<>"Vencida","",IF(COUNTIF(Config!$A$10:$A$13,"<="&J9)=0,"Aguardar: ainda não chegou ao primeiro passo da régua.",INDEX(Config!$B$10:$B$13,COUNTIF(Config!$A$10:$A$13,"<="&J9)))) | N9: =IF(I9="Vencida",F9*J9+ROW()/100000,0) -> 0 | O9: =IF(AND(I9="A vencer",K9<=Config!$B$7),100000-K9-ROW()/100000,0) -> 0
A10: Gisele Ribeiro | B10: Check-up cardiológico (consulta + ECG + teste ergométrico) | C10: 46034 | D10: 2 | E10: 46094 | F10: 480 | G10: Sim | H10: 46094 | I10: =IF(A10="","",IF(G10="Sim","Paga",IF(E10="","Sem vencimento",IF(E10<Config!$B$5,"Vencida","A vencer")))) -> Paga | J10: =IF(I10="Vencida",Config!$B$5-E10,"") | K10: =IF(I10="A vencer",E10-Config!$B$5,"") | L10: =IF(I10<>"Vencida","",IF(COUNTIF(Config!$A$10:$A$13,"<="&J10)=0,"Antes da régua",INDEX(Config!$C$10:$C$13,COUNTIF(Config!$A$10:$A$13,"<="&J10)))) | M10: =IF(I10<>"Vencida","",IF(COUNTIF(Config!$A$10:$A$13,"<="&J10)=0,"Aguardar: ainda não chegou ao primeiro passo da régua.",INDEX(Config!$B$10:$B$13,COUNTIF(Config!$A$10:$A$13,"<="&J10)))) | N10: =IF(I10="Vencida",F10*J10+ROW()/100000,0) -> 0 | O10: =IF(AND(I10="A vencer",K10<=Config!$B$7),100000-K10-ROW()/100000,0) -> 0
A11: Márcia Duarte | B11: Avaliação endócrina | C11: 46035 | D11: 1 | E11: 46065 | F11: 200 | G11: Não | I11: =IF(A11="","",IF(G11="Sim","Paga",IF(E11="","Sem vencimento",IF(E11<Config!$B$5,"Vencida","A vencer")))) -> Vencida | J11: =IF(I11="Vencida",Config!$B$5-E11,"") -> 214 | K11: =IF(I11="A vencer",E11-Config!$B$5,"") | L11: =IF(I11<>"Vencida","",IF(COUNTIF(Config!$A$10:$A$13,"<="&J11)=0,"Antes da régua",INDEX(Config!$C$10:$C$13,COUNTIF(Config!$A$10:$A$13,"<="&J11)))) -> 30 dias ou mais | M11: =IF(I11<>"Vencida","",IF(COUNTIF(Config!$A$10:$A$13,"<="&J11)=0,"Aguardar: ainda não chegou ao primeiro passo da régua.",INDEX(Config!$B$10:$B$13,COUNTIF(Config!$A$10:$A$13,"<="&J11)))) -> Conversa do médico ou da administração para combinar um plano de pagamento; registrar por escrito o que foi combinado. | N11: =IF(I11="Vencida",F11*J11+ROW()/100000,0) -> 42800 | O11: =IF(AND(I11="A vencer",K11<=Config!$B$7),100000-K11-ROW()/100000,0) -> 0
A12: Márcia Duarte | B12: Avaliação endócrina | C12: 46035 | D12: 2 | E12: 46095 | F12: 200 | G12: Sim | H12: 46100 | I12: =IF(A12="","",IF(G12="Sim","Paga",IF(E12="","Sem vencimento",IF(E12<Config!$B$5,"Vencida","A vencer")))) -> Paga | J12: =IF(I12="Vencida",Config!$B$5-E12,"") | K12: =IF(I12="A vencer",E12-Config!$B$5,"") | L12: =IF(I12<>"Vencida","",IF(COUNTIF(Config!$A$10:$A$13,"<="&J12)=0,"Antes da régua",INDEX(Config!$C$10:$C$13,COUNTIF(Config!$A$10:$A$13,"<="&J12)))) | M12: =IF(I12<>"Vencida","",IF(COUNTIF(Config!$A$10:$A$13,"<="&J12)=0,"Aguardar: ainda não chegou ao primeiro passo da régua.",INDEX(Config!$B$10:$B$13,COUNTIF(Config!$A$10:$A$13,"<="&J12)))) | N12: =IF(I12="Vencida",F12*J12+ROW()/100000,0) -> 0 | O12: =IF(AND(I12="A vencer",K12<=Config!$B$7),100000-K12-ROW()/100000,0) -> 0
A13: Wagner Lima | B13: Holter | C13: 46038 | D13: 1 | E13: 46068 | F13: 175 | G13: Sim | H13: 46071 | I13: =IF(A13="","",IF(G13="Sim","Paga",IF(E13="","Sem vencimento",IF(E13<Config!$B$5,"Vencida","A vencer")))) -> Paga | J13: =IF(I13="Vencida",Config!$B$5-E13,"") | K13: =IF(I13="A vencer",E13-Config!$B$5,"") | L13: =IF(I13<>"Vencida","",IF(COUNTIF(Config!$A$10:$A$13,"<="&J13)=0,"Antes da régua",INDEX(Config!$C$10:$C$13,COUNTIF(Config!$A$10:$A$13,"<="&J13)))) | M13: =IF(I13<>"Vencida","",IF(COUNTIF(Config!$A$10:$A$13,"<="&J13)=0,"Aguardar: ainda não chegou ao primeiro passo da régua.",INDEX(Config!$B$10:$B$13,COUNTIF(Config!$A$10:$A$13,"<="&J13)))) | N13: =IF(I13="Vencida",F13*J13+ROW()/100000,0) -> 0 | O13: =IF(AND(I13="A vencer",K13<=Config!$B$7),100000-K13-ROW()/100000,0) -> 0
A14: Wagner Lima | B14: Holter | C14: 46038 | D14: 2 | E14: 46098 | F14: 175 | G14: Sim | H14: 46098 | I14: =IF(A14="","",IF(G14="Sim","Paga",IF(E14="","Sem vencimento",IF(E14<Config!$B$5,"Vencida","A vencer")))) -> Paga | J14: =IF(I14="Vencida",Config!$B$5-E14,"") | K14: =IF(I14="A vencer",E14-Config!$B$5,"") | L14: =IF(I14<>"Vencida","",IF(COUNTIF(Config!$A$10:$A$13,"<="&J14)=0,"Antes da régua",INDEX(Config!$C$10:$C$13,COUNTIF(Config!$A$10:$A$13,"<="&J14)))) | M14: =IF(I14<>"Vencida","",IF(COUNTIF(Config!$A$10:$A$13,"<="&J14)=0,"Aguardar: ainda não chegou ao primeiro passo da régua.",INDEX(Config!$B$10:$B$13,COUNTIF(Config!$A$10:$A$13,"<="&J14)))) | N14: =IF(I14="Vencida",F14*J14+ROW()/100000,0) -> 0 | O14: =IF(AND(I14="A vencer",K14<=Config!$B$7),100000-K14-ROW()/100000,0) -> 0
A15: Carlos Oliveira | B15: Consulta | C15: 46044 | D15: 1 | E15: 46074 | F15: 190 | G15: Sim | H15: 46076 | I15: =IF(A15="","",IF(G15="Sim","Paga",IF(E15="","Sem vencimento",IF(E15<Config!$B$5,"Vencida","A vencer")))) -> Paga | J15: =IF(I15="Vencida",Config!$B$5-E15,"") | K15: =IF(I15="A vencer",E15-Config!$B$5,"") | L15: =IF(I15<>"Vencida","",IF(COUNTIF(Config!$A$10:$A$13,"<="&J15)=0,"Antes da régua",INDEX(Config!$C$10:$C$13,COUNTIF(Config!$A$10:$A$13,"<="&J15)))) | M15: =IF(I15<>"Vencida","",IF(COUNTIF(Config!$A$10:$A$13,"<="&J15)=0,"Aguardar: ainda não chegou ao primeiro passo da régua.",INDEX(Config!$B$10:$B$13,COUNTIF(Config!$A$10:$A$13,"<="&J15)))) | N15: =IF(I15="Vencida",F15*J15+ROW()/100000,0) -> 0 | O15: =IF(AND(I15="A vencer",K15<=Config!$B$7),100000-K15-ROW()/100000,0) -> 0
A16: Carlos Oliveira | B16: Consulta | C16: 46044 | D16: 2 | E16: 46104 | F16: 190 | G16: Sim | H16: 46104 | I16: =IF(A16="","",IF(G16="Sim","Paga",IF(E16="","Sem vencimento",IF(E16<Config!$B$5,"Vencida","A vencer")))) -> Paga | J16: =IF(I16="Vencida",Config!$B$5-E16,"") | K16: =IF(I16="A vencer",E16-Config!$B$5,"") | L16: =IF(I16<>"Vencida","",IF(COUNTIF(Config!$A$10:$A$13,"<="&J16)=0,"Antes da régua",INDEX(Config!$C$10:$C$13,COUNTIF(Config!$A$10:$A$13,"<="&J16)))) | M16: =IF(I16<>"Vencida","",IF(COUNTIF(Config!$A$10:$A$13,"<="&J16)=0,"Aguardar: ainda não chegou ao primeiro passo da régua.",INDEX(Config!$B$10:$B$13,COUNTIF(Config!$A$10:$A$13,"<="&J16)))) | N16: =IF(I16="Vencida",F16*J16+ROW()/100000,0) -> 0 | O16: =IF(AND(I16="A vencer",K16<=Config!$B$7),100000-K16-ROW()/100000,0) -> 0
A17: Gabriel Reis | B17: Avaliação endócrina | C17: 46044 | D17: 1 | E17: 46074 | F17: 400 | G17: Sim | H17: 46074 | I17: =IF(A17="","",IF(G17="Sim","Paga",IF(E17="","Sem vencimento",IF(E17<Config!$B$5,"Vencida","A vencer")))) -> Paga | J17: =IF(I17="Vencida",Config!$B$5-E17,"") | K17: =IF(I17="A vencer",E17-Config!$B$5,"") | L17: =IF(I17<>"Vencida","",IF(COUNTIF(Config!$A$10:$A$13,"<="&J17)=0,"Antes da régua",INDEX(Config!$C$10:$C$13,COUNTIF(Config!$A$10:$A$13,"<="&J17)))) | M17: =IF(I17<>"Vencida","",IF(COUNTIF(Config!$A$10:$A$13,"<="&J17)=0,"Aguardar: ainda não chegou ao primeiro passo da régua.",INDEX(Config!$B$10:$B$13,COUNTIF(Config!$A$10:$A$13,"<="&J17)))) | N17: =IF(I17="Vencida",F17*J17+ROW()/100000,0) -> 0 | O17: =IF(AND(I17="A vencer",K17<=Config!$B$7),100000-K17-ROW()/100000,0) -> 0
A18: Helena Moreira | B18: Consulta | C18: 46049 | D18: 1 | E18: 46079 | F18: 190 | G18: Sim | H18: 46080 | I18: =IF(A18="","",IF(G18="Sim","Paga",IF(E18="","Sem vencimento",IF(E18<Config!$B$5,"Vencida","A vencer")))) -> Paga | J18: =IF(I18="Vencida",Config!$B$5-E18,"") | K18: =IF(I18="A vencer",E18-Config!$B$5,"") | L18: =IF(I18<>"Vencida","",IF(COUNTIF(Config!$A$10:$A$13,"<="&J18)=0,"Antes da régua",INDEX(Config!$C$10:$C$13,COUNTIF(Config!$A$10:$A$13,"<="&J18)))) | M18: =IF(I18<>"Vencida","",IF(COUNTIF(Config!$A$10:$A$13,"<="&J18)=0,"Aguardar: ainda não chegou ao primeiro passo da régua.",INDEX(Config!$B$10:$B$13,COUNTIF(Config!$A$10:$A$13,"<="&J18)))) | N18: =IF(I18="Vencida",F18*J18+ROW()/100000,0) -> 0 | O18: =IF(AND(I18="A vencer",K18<=Config!$B$7),100000-K18-ROW()/100000,0) -> 0
A19: Helena Moreira | B19: Consulta | C19: 46049 | D19: 2 | E19: 46109 | F19: 190 | G19: Sim | H19: 46110 | I19: =IF(A19="","",IF(G19="Sim","Paga",IF(E19="","Sem vencimento",IF(E19<Config!$B$5,"Vencida","A vencer")))) -> Paga | J19: =IF(I19="Vencida",Config!$B$5-E19,"") | K19: =IF(I19="A vencer",E19-Config!$B$5,"") | L19: =IF(I19<>"Vencida","",IF(COUNTIF(Config!$A$10:$A$13,"<="&J19)=0,"Antes da régua",INDEX(Config!$C$10:$C$13,COUNTIF(Config!$A$10:$A$13,"<="&J19)))) | M19: =IF(I19<>"Vencida","",IF(COUNTIF(Config!$A$10:$A$13,"<="&J19)=0,"Aguardar: ainda não chegou ao primeiro passo da régua.",INDEX(Config!$B$10:$B$13,COUNTIF(Config!$A$10:$A$13,"<="&J19)))) | N19: =IF(I19="Vencida",F19*J19+ROW()/100000,0) -> 0 | O19: =IF(AND(I19="A vencer",K19<=Config!$B$7),100000-K19-ROW()/100000,0) -> 0
A20: Otávio Nascimento | B20: Teste ergométrico | C20: 46051 | D20: 1 | E20: 46081 | F20: 450 | G20: Sim | H20: 46084 | I20: =IF(A20="","",IF(G20="Sim","Paga",IF(E20="","Sem vencimento",IF(E20<Config!$B$5,"Vencida","A vencer")))) -> Paga | J20: =IF(I20="Vencida",Config!$B$5-E20,"") | K20: =IF(I20="A vencer",E20-Config!$B$5,"") | L20: =IF(I20<>"Vencida","",IF(COUNTIF(Config!$A$10:$A$13,"<="&J20)=0,"Antes da régua",INDEX(Config!$C$10:$C$13,COUNTIF(Config!$A$10:$A$13,"<="&J20)))) | M20: =IF(I20<>"Vencida","",IF(COUNTIF(Config!$A$10:$A$13,"<="&J20)=0,"Aguardar: ainda não chegou ao primeiro passo da régua.",INDEX(Config!$B$10:$B$13,COUNTIF(Config!$A$10:$A$13,"<="&J20)))) | N20: =IF(I20="Vencida",F20*J20+ROW()/100000,0) -> 0 | O20: =IF(AND(I20="A vencer",K20<=Config!$B$7),100000-K20-ROW()/100000,0) -> 0
A21: Rafael Pereira | B21: Avaliação endócrina | C21: 46056 | D21: 1 | E21: 46086 | F21: 400 | G21: Sim | H21: 46088 | I21: =IF(A21="","",IF(G21="Sim","Paga",IF(E21="","Sem vencimento",IF(E21<Config!$B$5,"Vencida","A vencer")))) -> Paga | J21: =IF(I21="Vencida",Config!$B$5-E21,"") | K21: =IF(I21="A vencer",E21-Config!$B$5,"") | L21: =IF(I21<>"Vencida","",IF(COUNTIF(Config!$A$10:$A$13,"<="&J21)=0,"Antes da régua",INDEX(Config!$C$10:$C$13,COUNTIF(Config!$A$10:$A$13,"<="&J21)))) | M21: =IF(I21<>"Vencida","",IF(COUNTIF(Config!$A$10:$A$13,"<="&J21)=0,"Aguardar: ainda não chegou ao primeiro passo da régua.",INDEX(Config!$B$10:$B$13,COUNTIF(Config!$A$10:$A$13,"<="&J21)))) | N21: =IF(I21="Vencida",F21*J21+ROW()/100000,0) -> 0 | O21: =IF(AND(I21="A vencer",K21<=Config!$B$7),100000-K21-ROW()/100000,0) -> 0
A22: Fernanda Freitas | B22: Consulta | C22: 46063 | D22: 1 | E22: 46093 | F22: 380 | G22: Sim | H22: 46098 | I22: =IF(A22="","",IF(G22="Sim","Paga",IF(E22="","Sem vencimento",IF(E22<Config!$B$5,"Vencida","A vencer")))) -> Paga | J22: =IF(I22="Vencida",Config!$B$5-E22,"") | K22: =IF(I22="A vencer",E22-Config!$B$5,"") | L22: =IF(I22<>"Vencida","",IF(COUNTIF(Config!$A$10:$A$13,"<="&J22)=0,"Antes da régua",INDEX(Config!$C$10:$C$13,COUNTIF(Config!$A$10:$A$13,"<="&J22)))) | M22: =IF(I22<>"Vencida","",IF(COUNTIF(Config!$A$10:$A$13,"<="&J22)=0,"Aguardar: ainda não chegou ao primeiro passo da régua.",INDEX(Config!$B$10:$B$13,COUNTIF(Config!$A$10:$A$13,"<="&J22)))) | N22: =IF(I22="Vencida",F22*J22+ROW()/100000,0) -> 0 | O22: =IF(AND(I22="A vencer",K22<=Config!$B$7),100000-K22-ROW()/100000,0) -> 0
