Workbook

Sheet Como usar
A1: Conciliação de cartão e taxas
A2: Kit de Gestão para Médicos · Seu Sócio Gestor · versão 1.0 (setembro de 2026)
A4: O que esta planilha faz | B4: Cada pagamento no cartão ou no Pix com a taxa da operadora, o valor líquido e o dia em que cai na conta. Mostra quanto as taxas comem no mês (e a quantas consultas equivalem), o que ainda vai cair, o que já deveria ter caído e não foi conferido, e o dia a dia para bater com o extrato.
A5: Passo 1 | B5: Em Config, digite as taxas e os prazos da sua operadora (contrato da maquininha ou extrato), se antecipa o crédito e o preço da consulta particular (só para a comparação).
A6: Passo 2 | B6: Em Vendas, uma linha por pagamento: data, paciente, procedimento, tipo, parcelas e valor bruto (copie da Agenda da 01, filtrando os particulares pagos com Pix ou cartão). A cada quinzena, escreva em "Parcelas já conferidas" quantas parcelas daquela venda você já achou no extrato: 1 para Pix, débito e crédito à vista; no parcelado vá somando conforme cada parcela cai. Assim a venda volta para "A conferir" quando a parcela seguinte vencer, em vez de ficar conferida para sempre depois da primeira.
A7: Passo 3 | B7: Em Painel, escolha o mês em Config: vendas, taxas, líquido, por tipo, dia a dia e a lista "Falta conferir". No fechamento do mês, lance o total de taxas como saída "Taxas de cartão" no caixa (09).
A8: Rotina | B8: É uma planilha QUINZENAL, fora dos 30 minutos semanais da planilha 03: a cada 15 dias, 10 minutos para conferir o extrato da operadora contra "Cai na conta neste dia" e marcar as conferidas. No fechamento do mês, lance o total de taxas no caixa (09). Uma vez por semestre: comparar a taxa média com outra operadora.
A9: Limite e como estender | B9: A aba Vendas tem 2.000 linhas (5 a 2004): mais de um ano com cerca de 100 pagamentos por mês. Perto do fim, desproteja a aba, copie a última linha para baixo e ajuste o número final nas fórmulas do Painel, ou comece um arquivo por ano.
A10: Ligação com as outras planilhas | B10: O caixa (09) registra o bruto na data em que cai na conta, usando as datas desta planilha; a taxa do mês é a saída do fim do mês em que o dinheiro caiu. Por isso a taxa desta tela (vendas de agosto) e a do caixa (recebimentos de agosto) são números diferentes de propósito. O resultado mensal (18) mostra as taxas como despesa variável. No exemplo o Painel está em agosto (mês fechado); setembro está em andamento.
A11: Com a IA | B11: Copie "Por tipo de pagamento" e use o prompt "Caixa 09 · A taxa da maquininha está comendo a margem?" da biblioteca do kit para decidir entre absorver a taxa, oferecer desconto no Pix ou trocar de operadora.
A12: Legenda | B12: Células amarelas: você preenche. Brancas: calculadas. Não é preciso mexer em nada fora do amarelo.
A13: Proteção | B13: Fórmulas protegidas sem senha. Para editar: Revisar > Desproteger planilha (Excel) ou Dados > Proteger intervalos (Google Sheets).
A14: Requisitos | B14: Excel 2016 ou mais novo, Microsoft 365 ou Google Sheets (só funções do Excel 2007+; nada de MÍNIMOSES, MÁXIMOSES ou UNIRTEXTO). No celular abre nos aplicativos; para preencher, use o computador.
A15: Dados de pacientes | B15: Guarde só o que a gestão precisa (nome, contato, valor, data). Nada de diagnóstico, prontuário ou exame nestas planilhas: o kit é gestão, não é prontuário. Veja o guia LGPD do kit antes de colar qualquer tabela em uma IA.
... A19: Suporte | B19: suporte@seusociogestor.com.br · resposta em até 5 dias úteis · reembolso em até 7 dias pelo mesmo canal.

Sheet Painel
A1: =Config!$B$4&" · Conciliação de cartão e taxas · "&Config!$B$6&" de "&Config!$B$5 -> Clínica Vida Plena (exemplo fictício) · Conciliação de cartão e taxas · Agosto de 2026
A2: Nada para digitar aqui. Escolha o mês em Config; tudo vem de Vendas. Taxas por mês da venda; a receber por previsão na conta.
A4: Vendas no mês (bruto) | C4: Taxas no mês | E4: Taxa média | G4: Líquido no mês | I4: Ainda vai cair (todas as vendas) | K4: A conferir
A5: =SUMIFS(Vendas!$F$5:$F$2004,Vendas!$P$5:$P$2004,Config!$B$7,Vendas!$Q$5:$Q$2004,Config!$B$5) -> 31820 | C5: =SUMIFS(Vendas!$I$5:$I$2004,Vendas!$P$5:$P$2004,Config!$B$7,Vendas!$Q$5:$Q$2004,Config!$B$5) -> 484.12 | E5: =IF(A5=0,"",C5/A5) -> 0.015214331 | G5: =A5-C5 -> 31335.88 | I5: =SUM(Vendas!$O$5:$O$2004) -> 12388.26 | K5: =SUM(Vendas!$T$5:$T$2004) -> 5652.71
A7: ="As taxas do mês equivalem a "&FIXED(IF(Config!$B$9=0,0,C5/Config!$B$9),1)&" consultas particulares. Lance este total no caixa (09) como saída 'Taxas de cartão' no fim do mês." -> As taxas do mês equivalem a 1,3 consultas particulares. Lance este total no caixa (09) como saída 'Taxas de cartão' no fim do mês.
A9: Por tipo de pagamento no mês
A10: Tipo | B10: Vendas | C10: Bruto (R$) | D10: Taxas (R$) | E10: Taxa média | F10: Líquido (R$) | G10: % do bruto | H10: Barra
A11: Pix | B11: =COUNTIFS(Vendas!$D$5:$D$2004,"Pix",Vendas!$P$5:$P$2004,Config!$B$7,Vendas!$Q$5:$Q$2004,Config!$B$5) -> 37 | C11: =SUMIFS(Vendas!$F$5:$F$2004,Vendas!$D$5:$D$2004,"Pix",Vendas!$P$5:$P$2004,Config!$B$7,Vendas!$Q$5:$Q$2004,Config!$B$5) -> 13380 | D11: =SUMIFS(Vendas!$I$5:$I$2004,Vendas!$D$5:$D$2004,"Pix",Vendas!$P$5:$P$2004,Config!$B$7,Vendas!$Q$5:$Q$2004,Config!$B$5) -> 0 | E11: =IF(C11=0,"",D11/C11) -> 0 | F11: =C11-D11 -> 13380 | G11: =IF($A$5=0,"",C11/$A$5) -> 0.42049026 | H11: =IF(G11="","",REPT("█",ROUND(G11*30,0))) -> █████████████
A12: Cartão de débito | B12: =COUNTIFS(Vendas!$D$5:$D$2004,"Cartão de débito",Vendas!$P$5:$P$2004,Config!$B$7,Vendas!$Q$5:$Q$2004,Config!$B$5) -> 22 | C12: =SUMIFS(Vendas!$F$5:$F$2004,Vendas!$D$5:$D$2004,"Cartão de débito",Vendas!$P$5:$P$2004,Config!$B$7,Vendas!$Q$5:$Q$2004,Config!$B$5) -> 8090 | D12: =SUMIFS(Vendas!$I$5:$I$2004,Vendas!$D$5:$D$2004,"Cartão de débito",Vendas!$P$5:$P$2004,Config!$B$7,Vendas!$Q$5:$Q$2004,Config!$B$5) -> 121.35 | E12: =IF(C12=0,"",D12/C12) -> 0.015 | F12: =C12-D12 -> 7968.65 | G12: =IF($A$5=0,"",C12/$A$5) -> 0.25424261 | H12: =IF(G12="","",REPT("█",ROUND(G12*30,0))) -> ████████
A13: Cartão de crédito à vista | B13: =COUNTIFS(Vendas!$D$5:$D$2004,"Cartão de crédito",Vendas!$P$5:$P$2004,Config!$B$7,Vendas!$Q$5:$Q$2004,Config!$B$5)-COUNTIFS(Vendas!$D$5:$D$2004,"Cartão de crédito",Vendas!$E$5:$E$2004,">1",Vendas!$P$5:$P$2004,Config!$B$7,Vendas!$Q$5:$Q$2004,Config!$B$5) -> 16 | C13: =SUMIFS(Vendas!$F$5:$F$2004,Vendas!$D$5:$D$2004,"Cartão de crédito",Vendas!$P$5:$P$2004,Config!$B$7,Vendas!$Q$5:$Q$2004,Config!$B$5)-SUMIFS(Vendas!$F$5:$F$2004,Vendas!$D$5:$D$2004,"Cartão de crédito",Vendas!$E$5:$E$2004,">1",Vendas!$P$5:$P$2004,Config!$B$7,Vendas!$Q$5:$Q$2004,Config!$B$5) -> 5840 | D13: =SUMIFS(Vendas!$I$5:$I$2004,Vendas!$D$5:$D$2004,"Cartão de crédito",Vendas!$P$5:$P$2004,Config!$B$7,Vendas!$Q$5:$Q$2004,Config!$B$5)-SUMIFS(Vendas!$I$5:$I$2004,Vendas!$D$5:$D$2004,"Cartão de crédito",Vendas!$E$5:$E$2004,">1",Vendas!$P$5:$P$2004,Config!$B$7,Vendas!$Q$5:$Q$2004,Config!$B$5) -> 186.88 | E13: =IF(C13=0,"",D13/C13) -> 0.032 | F13: =C13-D13 -> 5653.12 | G13: =IF($A$5=0,"",C13/$A$5) -> 0.18353237 | H13: =IF(G13="","",REPT("█",ROUND(G13*30,0))) -> ██████
A14: Cartão de crédito parcelado | B14: =COUNTIFS(Vendas!$D$5:$D$2004,"Cartão de crédito",Vendas!$E$5:$E$2004,">1",Vendas!$P$5:$P$2004,Config!$B$7,Vendas!$Q$5:$Q$2004,Config!$B$5) -> 12 | C14: =SUMIFS(Vendas!$F$5:$F$2004,Vendas!$D$5:$D$2004,"Cartão de crédito",Vendas!$E$5:$E$2004,">1",Vendas!$P$5:$P$2004,Config!$B$7,Vendas!$Q$5:$Q$2004,Config!$B$5) -> 4510 | D14: =SUMIFS(Vendas!$I$5:$I$2004,Vendas!$D$5:$D$2004,"Cartão de crédito",Vendas!$E$5:$E$2004,">1",Vendas!$P$5:$P$2004,Config!$B$7,Vendas!$Q$5:$Q$2004,Config!$B$5) -> 175.89 | E14: =IF(C14=0,"",D14/C14) -> 0.039 | F14: =C14-D14 -> 4334.11 | G14: =IF($A$5=0,"",C14/$A$5) -> 0.14173476 | H14: =IF(G14="","",REPT("█",ROUND(G14*30,0))) -> ████
A15: Total | B15: =SUM(B11:B14) -> 87 | C15: =SUM(C11:C14) -> 31820 | D15: =SUM(D11:D14) -> 484.12 | F15: =SUM(F11:F14) -> 31335.88
A16: Parcelado custa mais e demora mais. Se o parcelado pesa, vale oferecer desconto no Pix em vez de absorver a taxa; a decisão é da clínica.
A18: Dia a dia do mês: vendas, taxas e previsão de crédito
A19: Dia | B19: Data | C19: Vendas | D19: Bruto (R$) | E19: Taxas (R$) | F19: Líquido (R$) | G19: Cai na conta neste dia (R$) | H19: Conferido?
A20: 1 | B20: =IF(1>DAY(DATE(Config!$B$5,Config!$B$7+1,0)),"",DATE(Config!$B$5,Config!$B$7,1)) -> 46235 | C20: =IF(B20="","",COUNTIFS(Vendas!$A$5:$A$2004,B20)) -> 0 | D20: =IF(B20="","",SUMIFS(Vendas!$F$5:$F$2004,Vendas!$A$5:$A$2004,B20)) -> 0 | E20: =IF(B20="","",SUMIFS(Vendas!$I$5:$I$2004,Vendas!$A$5:$A$2004,B20)) -> 0 | F20: =IF(B20="","",D20-E20) -> 0 | G20: =IF(B20="","",SUMPRODUCT((Vendas!$U$5:$U$2004>0)*(Vendas!$U$5:$U$2004<=B20)*(MOD(B20-Vendas!$U$5:$U$2004,30)=0)*((B20-Vendas!$U$5:$U$2004)/30<Vendas!$V$5:$V$2004)*Vendas!$W$5:$W$2004)) -> 1886.245 | H20: =IF(OR(B20="",G20=0),"",IF(COUNTIFS(Vendas!$L$5:$L$2004,B20,Vendas!$R$5:$R$2004,"A conferir")>0,"Falta conferir",IF(B20>Config!$B$8,"A cair","Conferido"))) -> Conferido
A21: 2 | B21: =IF(2>DAY(DATE(Config!$B$5,Config!$B$7+1,0)),"",DATE(Config!$B$5,Config!$B$7,2)) -> 46236 | C21: =IF(B21="","",COUNTIFS(Vendas!$A$5:$A$2004,B21)) -> 0 | D21: =IF(B21="","",SUMIFS(Vendas!$F$5:$F$2004,Vendas!$A$5:$A$2004,B21)) -> 0 | E21: =IF(B21="","",SUMIFS(Vendas!$I$5:$I$2004,Vendas!$A$5:$A$2004,B21)) -> 0 | F21: =IF(B21="","",D21-E21) -> 0 | G21: =IF(B21="","",SUMPRODUCT((Vendas!$U$5:$U$2004>0)*(Vendas!$U$5:$U$2004<=B21)*(MOD(B21-Vendas!$U$5:$U$2004,30)=0)*((B21-Vendas!$U$5:$U$2004)/30<Vendas!$V$5:$V$2004)*Vendas!$W$5:$W$2004)) -> 0 | H21: =IF(OR(B21="",G21=0),"",IF(COUNTIFS(Vendas!$L$5:$L$2004,B21,Vendas!$R$5:$R$2004,"A conferir")>0,"Falta conferir",IF(B21>Config!$B$8,"A cair","Conferido")))
A22: 3 | B22: =IF(3>DAY(DATE(Config!$B$5,Config!$B$7+1,0)),"",DATE(Config!$B$5,Config!$B$7,3)) -> 46237 | C22: =IF(B22="","",COUNTIFS(Vendas!$A$5:$A$2004,B22)) -> 2 | D22: =IF(B22="","",SUMIFS(Vendas!$F$5:$F$2004,Vendas!$A$5:$A$2004,B22)) -> 680 | E22: =IF(B22="","",SUMIFS(Vendas!$I$5:$I$2004,Vendas!$A$5:$A$2004,B22)) -> 16.66 | F22: =IF(B22="","",D22-E22) -> 663.34 | G22: =IF(B22="","",SUMPRODUCT((Vendas!$U$5:$U$2004>0)*(Vendas!$U$5:$U$2004<=B22)*(MOD(B22-Vendas!$U$5:$U$2004,30)=0)*((B22-Vendas!$U$5:$U$2004)/30<Vendas!$V$5:$V$2004)*Vendas!$W$5:$W$2004)) -> 0 | H22: =IF(OR(B22="",G22=0),"",IF(COUNTIFS(Vendas!$L$5:$L$2004,B22,Vendas!$R$5:$R$2004,"A conferir")>0,"Falta conferir",IF(B22>Config!$B$8,"A cair","Conferido")))
A23: 4 | B23: =IF(4>DAY(DATE(Config!$B$5,Config!$B$7+1,0)),"",DATE(Config!$B$5,Config!$B$7,4)) -> 46238 | C23: =IF(B23="","",COUNTIFS(Vendas!$A$5:$A$2004,B23)) -> 8 | D23: =IF(B23="","",SUMIFS(Vendas!$F$5:$F$2004,Vendas!$A$5:$A$2004,B23)) -> 3060 | E23: =IF(B23="","",SUMIFS(Vendas!$I$5:$I$2004,Vendas!$A$5:$A$2004,B23)) -> 47.42 | F23: =IF(B23="","",D23-E23) -> 3012.58 | G23: =IF(B23="","",SUMPRODUCT((Vendas!$U$5:$U$2004>0)*(Vendas!$U$5:$U$2004<=B23)*(MOD(B23-Vendas!$U$5:$U$2004,30)=0)*((B23-Vendas!$U$5:$U$2004)/30<Vendas!$V$5:$V$2004)*Vendas!$W$5:$W$2004)) -> 1055.5 | H23: =IF(OR(B23="",G23=0),"",IF(COUNTIFS(Vendas!$L$5:$L$2004,B23,Vendas!$R$5:$R$2004,"A conferir")>0,"Falta conferir",IF(B23>Config!$B$8,"A cair","Conferido"))) -> Conferido
A24: 5 | B24: =IF(5>DAY(DATE(Config!$B$5,Config!$B$7+1,0)),"",DATE(Config!$B$5,Config!$B$7,5)) -> 46239 | C24: =IF(B24="","",COUNTIFS(Vendas!$A$5:$A$2004,B24)) -> 3 | D24: =IF(B24="","",SUMIFS(Vendas!$F$5:$F$2004,Vendas!$A$5:$A$2004,B24)) -> 1140 | E24: =IF(B24="","",SUMIFS(Vendas!$I$5:$I$2004,Vendas!$A$5:$A$2004,B24)) -> 20.52 | F24: =IF(B24="","",D24-E24) -> 1119.48 | G24: =IF(B24="","",SUMPRODUCT((Vendas!$U$5:$U$2004>0)*(Vendas!$U$5:$U$2004<=B24)*(MOD(B24-Vendas!$U$5:$U$2004,30)=0)*((B24-Vendas!$U$5:$U$2004)/30<Vendas!$V$5:$V$2004)*Vendas!$W$5:$W$2004)) -> 2447.33 | H24: =IF(OR(B24="",G24=0),"",IF(COUNTIFS(Vendas!$L$5:$L$2004,B24,Vendas!$R$5:$R$2004,"A conferir")>0,"Falta conferir",IF(B24>Config!$B$8,"A cair","Conferido"))) -> Conferido
A25: 6 | B25: =IF(6>DAY(DATE(Config!$B$5,Config!$B$7+1,0)),"",DATE(Config!$B$5,Config!$B$7,6)) -> 46240 | C25: =IF(B25="","",COUNTIFS(Vendas!$A$5:$A$2004,B25)) -> 5 | D25: =IF(B25="","",SUMIFS(Vendas!$F$5:$F$2004,Vendas!$A$5:$A$2004,B25)) -> 2010 | E25: =IF(B25="","",SUMIFS(Vendas!$I$5:$I$2004,Vendas!$A$5:$A$2004,B25)) -> 36.12 | F25: =IF(B25="","",D25-E25) -> 1973.88 | G25: =IF(B25="","",SUMPRODUCT((Vendas!$U$5:$U$2004>0)*(Vendas!$U$5:$U$2004<=B25)*(MOD(B25-Vendas!$U$5:$U$2004,30)=0)*((B25-Vendas!$U$5:$U$2004)/30<Vendas!$V$5:$V$2004)*Vendas!$W$5:$W$2004)) -> 1959.98 | H25: =IF(OR(B25="",G25=0),"",IF(COUNTIFS(Vendas!$L$5:$L$2004,B25,Vendas!$R$5:$R$2004,"A conferir")>0,"Falta conferir",IF(B25>Config!$B$8,"A cair","Conferido"))) -> Conferido
A26: 7 | B26: =IF(7>DAY(DATE(Config!$B$5,Config!$B$7+1,0)),"",DATE(Config!$B$5,Config!$B$7,7)) -> 46241 | C26: =IF(B26="","",COUNTIFS(Vendas!$A$5:$A$2004,B26)) -> 2 | D26: =IF(B26="","",SUMIFS(Vendas!$F$5:$F$2004,Vendas!$A$5:$A$2004,B26)) -> 510 | E26: =IF(B26="","",SUMIFS(Vendas!$I$5:$I$2004,Vendas!$A$5:$A$2004,B26)) -> 12.16 | F26: =IF(B26="","",D26-E26) -> 497.84 | G26: =IF(B26="","",SUMPRODUCT((Vendas!$U$5:$U$2004>0)*(Vendas!$U$5:$U$2004<=B26)*(MOD(B26-Vendas!$U$5:$U$2004,30)=0)*((B26-Vendas!$U$5:$U$2004)/30<Vendas!$V$5:$V$2004)*Vendas!$W$5:$W$2004)) -> 872.14 | H26: =IF(OR(B26="",G26=0),"",IF(COUNTIFS(Vendas!$L$5:$L$2004,B26,Vendas!$R$5:$R$2004,"A conferir")>0,"Falta conferir",IF(B26>Config!$B$8,"A cair","Conferido"))) -> Conferido
A27: 8 | B27: =IF(8>DAY(DATE(Config!$B$5,Config!$B$7+1,0)),"",DATE(Config!$B$5,Config!$B$7,8)) -> 46242 | C27: =IF(B27="","",COUNTIFS(Vendas!$A$5:$A$2004,B27)) -> 0 | D27: =IF(B27="","",SUMIFS(Vendas!$F$5:$F$2004,Vendas!$A$5:$A$2004,B27)) -> 0 | E27: =IF(B27="","",SUMIFS(Vendas!$I$5:$I$2004,Vendas!$A$5:$A$2004,B27)) -> 0 | F27: =IF(B27="","",D27-E27) -> 0 | G27: =IF(B27="","",SUMPRODUCT((Vendas!$U$5:$U$2004>0)*(Vendas!$U$5:$U$2004<=B27)*(MOD(B27-Vendas!$U$5:$U$2004,30)=0)*((B27-Vendas!$U$5:$U$2004)/30<Vendas!$V$5:$V$2004)*Vendas!$W$5:$W$2004)) -> 1623.51 | H27: =IF(OR(B27="",G27=0),"",IF(COUNTIFS(Vendas!$L$5:$L$2004,B27,Vendas!$R$5:$R$2004,"A conferir")>0,"Falta conferir",IF(B27>Config!$B$8,"A cair","Conferido"))) -> Conferido
A28: 9 | B28: =IF(9>DAY(DATE(Config!$B$5,Config!$B$7+1,0)),"",DATE(Config!$B$5,Config!$B$7,9)) -> 46243 | C28: =IF(B28="","",COUNTIFS(Vendas!$A$5:$A$2004,B28)) -> 0 | D28: =IF(B28="","",SUMIFS(Vendas!$F$5:$F$2004,Vendas!$A$5:$A$2004,B28)) -> 0 | E28: =IF(B28="","",SUMIFS(Vendas!$I$5:$I$2004,Vendas!$A$5:$A$2004,B28)) -> 0 | F28: =IF(B28="","",D28-E28) -> 0 | G28: =IF(B28="","",SUMPRODUCT((Vendas!$U$5:$U$2004>0)*(Vendas!$U$5:$U$2004<=B28)*(MOD(B28-Vendas!$U$5:$U$2004,30)=0)*((B28-Vendas!$U$5:$U$2004)/30<Vendas!$V$5:$V$2004)*Vendas!$W$5:$W$2004)) -> 0 | H28: =IF(OR(B28="",G28=0),"",IF(COUNTIFS(Vendas!$L$5:$L$2004,B28,Vendas!$R$5:$R$2004,"A conferir")>0,"Falta conferir",IF(B28>Config!$B$8,"A cair","Conferido")))
A29: 10 | B29: =IF(10>DAY(DATE(Config!$B$5,Config!$B$7+1,0)),"",DATE(Config!$B$5,Config!$B$7,10)) -> 46244 | C29: =IF(B29="","",COUNTIFS(Vendas!$A$5:$A$2004,B29)) -> 3 | D29: =IF(B29="","",SUMIFS(Vendas!$F$5:$F$2004,Vendas!$A$5:$A$2004,B29)) -> 860 | E29: =IF(B29="","",SUMIFS(Vendas!$I$5:$I$2004,Vendas!$A$5:$A$2004,B29)) -> 17.41 | F29: =IF(B29="","",D29-E29) -> 842.59 | G29: =IF(B29="","",SUMPRODUCT((Vendas!$U$5:$U$2004>0)*(Vendas!$U$5:$U$2004<=B29)*(MOD(B29-Vendas!$U$5:$U$2004,30)=0)*((B29-Vendas!$U$5:$U$2004)/30<Vendas!$V$5:$V$2004)*Vendas!$W$5:$W$2004)) -> 130 | H29: =IF(OR(B29="",G29=0),"",IF(COUNTIFS(Vendas!$L$5:$L$2004,B29,Vendas!$R$5:$R$2004,"A conferir")>0,"Falta conferir",IF(B29>Config!$B$8,"A cair","Conferido"))) -> Conferido
A30: 11 | B30: =IF(11>DAY(DATE(Config!$B$5,Config!$B$7+1,0)),"",DATE(Config!$B$5,Config!$B$7,11)) -> 46245 | C30: =IF(B30="","",COUNTIFS(Vendas!$A$5:$A$2004,B30)) -> 7 | D30: =IF(B30="","",SUMIFS(Vendas!$F$5:$F$2004,Vendas!$A$5:$A$2004,B30)) -> 2490 | E30: =IF(B30="","",SUMIFS(Vendas!$I$5:$I$2004,Vendas!$A$5:$A$2004,B30)) -> 45.03 | F30: =IF(B30="","",D30-E30) -> 2444.97 | G30: =IF(B30="","",SUMPRODUCT((Vendas!$U$5:$U$2004>0)*(Vendas!$U$5:$U$2004<=B30)*(MOD(B30-Vendas!$U$5:$U$2004,30)=0)*((B30-Vendas!$U$5:$U$2004)/30<Vendas!$V$5:$V$2004)*Vendas!$W$5:$W$2004)) -> 1540.975 | H30: =IF(OR(B30="",G30=0),"",IF(COUNTIFS(Vendas!$L$5:$L$2004,B30,Vendas!$R$5:$R$2004,"A conferir")>0,"Falta conferir",IF(B30>Config!$B$8,"A cair","Conferido"))) -> Conferido
A31: 12 | B31: =IF(12>DAY(DATE(Config!$B$5,Config!$B$7+1,0)),"",DATE(Config!$B$5,Config!$B$7,12)) -> 46246 | C31: =IF(B31="","",COUNTIFS(Vendas!$A$5:$A$2004,B31)) -> 4 | D31: =IF(B31="","",SUMIFS(Vendas!$F$5:$F$2004,Vendas!$A$5:$A$2004,B31)) -> 1520 | E31: =IF(B31="","",SUMIFS(Vendas!$I$5:$I$2004,Vendas!$A$5:$A$2004,B31)) -> 24.32 | F31: =IF(B31="","",D31-E31) -> 1495.68 | G31: =IF(B31="","",SUMPRODUCT((Vendas!$U$5:$U$2004>0)*(Vendas!$U$5:$U$2004<=B31)*(MOD(B31-Vendas!$U$5:$U$2004,30)=0)*((B31-Vendas!$U$5:$U$2004)/30<Vendas!$V$5:$V$2004)*Vendas!$W$5:$W$2004)) -> 1413.18 | H31: =IF(OR(B31="",G31=0),"",IF(COUNTIFS(Vendas!$L$5:$L$2004,B31,Vendas!$R$5:$R$2004,"A conferir")>0,"Falta conferir",IF(B31>Config!$B$8,"A cair","Conferido"))) -> Falta conferir
A32: 13 | B32: =IF(13>DAY(DATE(Config!$B$5,Config!$B$7+1,0)),"",DATE(Config!$B$5,Config!$B$7,13)) -> 46247 | C32: =IF(B32="","",COUNTIFS(Vendas!$A$5:$A$2004,B32)) -> 8 | D32: =IF(B32="","",SUMIFS(Vendas!$F$5:$F$2004,Vendas!$A$5:$A$2004,B32)) -> 3120 | E32: =IF(B32="","",SUMIFS(Vendas!$I$5:$I$2004,Vendas!$A$5:$A$2004,B32)) -> 24.16 | F32: =IF(B32="","",D32-E32) -> 3095.84 | G32: =IF(B32="","",SUMPRODUCT((Vendas!$U$5:$U$2004>0)*(Vendas!$U$5:$U$2004<=B32)*(MOD(B32-Vendas!$U$5:$U$2004,30)=0)*((B32-Vendas!$U$5:$U$2004)/30<Vendas!$V$5:$V$2004)*Vendas!$W$5:$W$2004)) -> 3551.38 | H32: =IF(OR(B32="",G32=0),"",IF(COUNTIFS(Vendas!$L$5:$L$2004,B32,Vendas!$R$5:$R$2004,"A conferir")>0,"Falta conferir",IF(B32>Config!$B$8,"A cair","Conferido"))) -> Falta conferir
A33: 14 | B33: =IF(14>DAY(DATE(Config!$B$5,Config!$B$7+1,0)),"",DATE(Config!$B$5,Config!$B$7,14)) -> 46248 | C33: =IF(B33="","",COUNTIFS(Vendas!$A$5:$A$2004,B33)) -> 0 | D33: =IF(B33="","",SUMIFS(Vendas!$F$5:$F$2004,Vendas!$A$5:$A$2004,B33)) -> 0 | E33: =IF(B33="","",SUMIFS(Vendas!$I$5:$I$2004,Vendas!$A$5:$A$2004,B33)) -> 0 | F33: =IF(B33="","",D33-E33) -> 0 | G33: =IF(B33="","",SUMPRODUCT((Vendas!$U$5:$U$2004>0)*(Vendas!$U$5:$U$2004<=B33)*(MOD(B33-Vendas!$U$5:$U$2004,30)=0)*((B33-Vendas!$U$5:$U$2004)/30<Vendas!$V$5:$V$2004)*Vendas!$W$5:$W$2004)) -> 1155.84 | H33: =IF(OR(B33="",G33=0),"",IF(COUNTIFS(Vendas!$L$5:$L$2004,B33,Vendas!$R$5:$R$2004,"A conferir")>0,"Falta conferir",IF(B33>Config!$B$8,"A cair","Conferido"))) -> Conferido
A34: 15 | B34: =IF(15>DAY(DATE(Config!$B$5,Config!$B$7+1,0)),"",DATE(Config!$B$5,Config!$B$7,15)) -> 46249 | C34: =IF(B34="","",COUNTIFS(Vendas!$A$5:$A$2004,B34)) -> 0 | D34: =IF(B34="","",SUMIFS(Vendas!$F$5:$F$2004,Vendas!$A$5:$A$2004,B34)) -> 0 | E34: =IF(B34="","",SUMIFS(Vendas!$I$5:$I$2004,Vendas!$A$5:$A$2004,B34)) -> 0 | F34: =IF(B34="","",D34-E34) -> 0 | G34: =IF(B34="","",SUMPRODUCT((Vendas!$U$5:$U$2004>0)*(Vendas!$U$5:$U$2004<=B34)*(MOD(B34-Vendas!$U$5:$U$2004,30)=0)*((B34-Vendas!$U$5:$U$2004)/30<Vendas!$V$5:$V$2004)*Vendas!$W$5:$W$2004)) -> 1122.88 | H34: =IF(OR(B34="",G34=0),"",IF(COUNTIFS(Vendas!$L$5:$L$2004,B34,Vendas!$R$5:$R$2004,"A conferir")>0,"Falta conferir",IF(B34>Config!$B$8,"A cair","Conferido"))) -> Conferido
A35: 16 | B35: =IF(16>DAY(DATE(Config!$B$5,Config!$B$7+1,0)),"",DATE(Config!$B$5,Config!$B$7,16)) -> 46250 | C35: =IF(B35="","",COUNTIFS(Vendas!$A$5:$A$2004,B35)) -> 0 | D35: =IF(B35="","",SUMIFS(Vendas!$F$5:$F$2004,Vendas!$A$5:$A$2004,B35)) -> 0 | E35: =IF(B35="","",SUMIFS(Vendas!$I$5:$I$2004,Vendas!$A$5:$A$2004,B35)) -> 0 | F35: =IF(B35="","",D35-E35) -> 0 | G35: =IF(B35="","",SUMPRODUCT((Vendas!$U$5:$U$2004>0)*(Vendas!$U$5:$U$2004<=B35)*(MOD(B35-Vendas!$U$5:$U$2004,30)=0)*((B35-Vendas!$U$5:$U$2004)/30<Vendas!$V$5:$V$2004)*Vendas!$W$5:$W$2004)) -> 367.84 | H35: =IF(OR(B35="",G35=0),"",IF(COUNTIFS(Vendas!$L$5:$L$2004,B35,Vendas!$R$5:$R$2004,"A conferir")>0,"Falta conferir",IF(B35>Config!$B$8,"A cair","Conferido"))) -> Conferido
A36: 17 | B36: =IF(17>DAY(DATE(Config!$B$5,Config!$B$7+1,0)),"",DATE(Config!$B$5,Config!$B$7,17)) -> 46251 | C36: =IF(B36="","",COUNTIFS(Vendas!$A$5:$A$2004,B36)) -> 3 | D36: =IF(B36="","",SUMIFS(Vendas!$F$5:$F$2004,Vendas!$A$5:$A$2004,B36)) -> 1060 | E36: =IF(B36="","",SUMIFS(Vendas!$I$5:$I$2004,Vendas!$A$5:$A$2004,B36)) -> 17.4 | F36: =IF(B36="","",D36-E36) -> 1042.6 | G36: =IF(B36="","",SUMPRODUCT((Vendas!$U$5:$U$2004>0)*(Vendas!$U$5:$U$2004<=B36)*(MOD(B36-Vendas!$U$5:$U$2004,30)=0)*((B36-Vendas!$U$5:$U$2004)/30<Vendas!$V$5:$V$2004)*Vendas!$W$5:$W$2004)) -> 380 | H36: =IF(OR(B36="",G36=0),"",IF(COUNTIFS(Vendas!$L$5:$L$2004,B36,Vendas!$R$5:$R$2004,"A conferir")>0,"Falta conferir",IF(B36>Config!$B$8,"A cair","Conferido"))) -> Conferido
A37: 18 | B37: =IF(18>DAY(DATE(Config!$B$5,Config!$B$7+1,0)),"",DATE(Config!$B$5,Config!$B$7,18)) -> 46252 | C37: =IF(B37="","",COUNTIFS(Vendas!$A$5:$A$2004,B37)) -> 4 | D37: =IF(B37="","",SUMIFS(Vendas!$F$5:$F$2004,Vendas!$A$5:$A$2004,B37)) -> 1540 | E37: =IF(B37="","",SUMIFS(Vendas!$I$5:$I$2004,Vendas!$A$5:$A$2004,B37)) -> 20.52 | F37: =IF(B37="","",D37-E37) -> 1519.48 | G37: =IF(B37="","",SUMPRODUCT((Vendas!$U$5:$U$2004>0)*(Vendas!$U$5:$U$2004<=B37)*(MOD(B37-Vendas!$U$5:$U$2004,30)=0)*((B37-Vendas!$U$5:$U$2004)/30<Vendas!$V$5:$V$2004)*Vendas!$W$5:$W$2004)) -> 1154.3 | H37: =IF(OR(B37="",G37=0),"",IF(COUNTIFS(Vendas!$L$5:$L$2004,B37,Vendas!$R$5:$R$2004,"A conferir")>0,"Falta conferir",IF(B37>Config!$B$8,"A cair","Conferido"))) -> Conferido
A38: 19 | B38: =IF(19>DAY(DATE(Config!$B$5,Config!$B$7+1,0)),"",DATE(Config!$B$5,Config!$B$7,19)) -> 46253 | C38: =IF(B38="","",COUNTIFS(Vendas!$A$5:$A$2004,B38)) -> 2 | D38: =IF(B38="","",SUMIFS(Vendas!$F$5:$F$2004,Vendas!$A$5:$A$2004,B38)) -> 760 | E38: =IF(B38="","",SUMIFS(Vendas!$I$5:$I$2004,Vendas!$A$5:$A$2004,B38)) -> 5.7 | F38: =IF(B38="","",D38-E38) -> 754.3 | G38: =IF(B38="","",SUMPRODUCT((Vendas!$U$5:$U$2004>0)*(Vendas!$U$5:$U$2004<=B38)*(MOD(B38-Vendas!$U$5:$U$2004,30)=0)*((B38-Vendas!$U$5:$U$2004)/30<Vendas!$V$5:$V$2004)*Vendas!$W$5:$W$2004)) -> 1489.98 | H38: =IF(OR(B38="",G38=0),"",IF(COUNTIFS(Vendas!$L$5:$L$2004,B38,Vendas!$R$5:$R$2004,"A conferir")>0,"Falta conferir",IF(B38>Config!$B$8,"A cair","Conferido"))) -> Conferido
A39: 20 | B39: =IF(20>DAY(DATE(Config!$B$5,Config!$B$7+1,0)),"",DATE(Config!$B$5,Config!$B$7,20)) -> 46254 | C39: =IF(B39="","",COUNTIFS(Vendas!$A$5:$A$2004,B39)) -> 9 | D39: =IF(B39="","",SUMIFS(Vendas!$F$5:$F$2004,Vendas!$A$5:$A$2004,B39)) -> 3370 | E39: =IF(B39="","",SUMIFS(Vendas!$I$5:$I$2004,Vendas!$A$5:$A$2004,B39)) -> 34.4 | F39: =IF(B39="","",D39-E39) -> 3335.6 | G39: =IF(B39="","",SUMPRODUCT((Vendas!$U$5:$U$2004>0)*(Vendas!$U$5:$U$2004<=B39)*(MOD(B39-Vendas!$U$5:$U$2004,30)=0)*((B39-Vendas!$U$5:$U$2004)/30<Vendas!$V$5:$V$2004)*Vendas!$W$5:$W$2004)) -> 3481.93 | H39: =IF(OR(B39="",G39=0),"",IF(COUNTIFS(Vendas!$L$5:$L$2004,B39,Vendas!$R$5:$R$2004,"A conferir")>0,"Falta conferir",IF(B39>Config!$B$8,"A cair","Conferido"))) -> Conferido
A40: 21 | B40: =IF(21>DAY(DATE(Config!$B$5,Config!$B$7+1,0)),"",DATE(Config!$B$5,Config!$B$7,21)) -> 46255 | C40: =IF(B40="","",COUNTIFS(Vendas!$A$5:$A$2004,B40)) -> 0 | D40: =IF(B40="","",SUMIFS(Vendas!$F$5:$F$2004,Vendas!$A$5:$A$2004,B40)) -> 0 | E40: =IF(B40="","",SUMIFS(Vendas!$I$5:$I$2004,Vendas!$A$5:$A$2004,B40)) -> 0 | F40: =IF(B40="","",D40-E40) -> 0 | G40: =IF(B40="","",SUMPRODUCT((Vendas!$U$5:$U$2004>0)*(Vendas!$U$5:$U$2004<=B40)*(MOD(B40-Vendas!$U$5:$U$2004,30)=0)*((B40-Vendas!$U$5:$U$2004)/30<Vendas!$V$5:$V$2004)*Vendas!$W$5:$W$2004)) -> 1129.68 | H40: =IF(OR(B40="",G40=0),"",IF(COUNTIFS(Vendas!$L$5:$L$2004,B40,Vendas!$R$5:$R$2004,"A conferir")>0,"Falta conferir",IF(B40>Config!$B$8,"A cair","Conferido"))) -> Conferido
A41: 22 | B41: =IF(22>DAY(DATE(Config!$B$5,Config!$B$7+1,0)),"",DATE(Config!$B$5,Config!$B$7,22)) -> 46256 | C41: =IF(B41="","",COUNTIFS(Vendas!$A$5:$A$2004,B41)) -> 0 | D41: =IF(B41="","",SUMIFS(Vendas!$F$5:$F$2004,Vendas!$A$5:$A$2004,B41)) -> 0 | E41: =IF(B41="","",SUMIFS(Vendas!$I$5:$I$2004,Vendas!$A$5:$A$2004,B41)) -> 0 | F41: =IF(B41="","",D41-E41) -> 0 | G41: =IF(B41="","",SUMPRODUCT((Vendas!$U$5:$U$2004>0)*(Vendas!$U$5:$U$2004<=B41)*(MOD(B41-Vendas!$U$5:$U$2004,30)=0)*((B41-Vendas!$U$5:$U$2004)/30<Vendas!$V$5:$V$2004)*Vendas!$W$5:$W$2004)) -> 1485.26 | H41: =IF(OR(B41="",G41=0),"",IF(COUNTIFS(Vendas!$L$5:$L$2004,B41,Vendas!$R$5:$R$2004,"A conferir")>0,"Falta conferir",IF(B41>Config!$B$8,"A cair","Conferido"))) -> Conferido
A42: 23 | B42: =IF(23>DAY(DATE(Config!$B$5,Config!$B$7+1,0)),"",DATE(Config!$B$5,Config!$B$7,23)) -> 46257 | C42: =IF(B42="","",COUNTIFS(Vendas!$A$5:$A$2004,B42)) -> 0 | D42: =IF(B42="","",SUMIFS(Vendas!$F$5:$F$2004,Vendas!$A$5:$A$2004,B42)) -> 0 | E42: =IF(B42="","",SUMIFS(Vendas!$I$5:$I$2004,Vendas!$A$5:$A$2004,B42)) -> 0 | F42: =IF(B42="","",D42-E42) -> 0 | G42: =IF(B42="","",SUMPRODUCT((Vendas!$U$5:$U$2004>0)*(Vendas!$U$5:$U$2004<=B42)*(MOD(B42-Vendas!$U$5:$U$2004,30)=0)*((B42-Vendas!$U$5:$U$2004)/30<Vendas!$V$5:$V$2004)*Vendas!$W$5:$W$2004)) -> 0 | H42: =IF(OR(B42="",G42=0),"",IF(COUNTIFS(Vendas!$L$5:$L$2004,B42,Vendas!$R$5:$R$2004,"A conferir")>0,"Falta conferir",IF(B42>Config!$B$8,"A cair","Conferido")))
A43: 24 | B43: =IF(24>DAY(DATE(Config!$B$5,Config!$B$7+1,0)),"",DATE(Config!$B$5,Config!$B$7,24)) -> 46258 | C43: =IF(B43="","",COUNTIFS(Vendas!$A$5:$A$2004,B43)) -> 7 | D43: =IF(B43="","",SUMIFS(Vendas!$F$5:$F$2004,Vendas!$A$5:$A$2004,B43)) -> 2410 | E43: =IF(B43="","",SUMIFS(Vendas!$I$5:$I$2004,Vendas!$A$5:$A$2004,B43)) -> 36.84 | F43: =IF(B43="","",D43-E43) -> 2373.16 | G43: =IF(B43="","",SUMPRODUCT((Vendas!$U$5:$U$2004>0)*(Vendas!$U$5:$U$2004<=B43)*(MOD(B43-Vendas!$U$5:$U$2004,30)=0)*((B43-Vendas!$U$5:$U$2004)/30<Vendas!$V$5:$V$2004)*Vendas!$W$5:$W$2004)) -> 1140 | H43: =IF(OR(B43="",G43=0),"",IF(COUNTIFS(Vendas!$L$5:$L$2004,B43,Vendas!$R$5:$R$2004,"A conferir")>0,"Falta conferir",IF(B43>Config!$B$8,"A cair","Conferido"))) -> Conferido
A44: 25 | B44: =IF(25>DAY(DATE(Config!$B$5,Config!$B$7+1,0)),"",DATE(Config!$B$5,Config!$B$7,25)) -> 46259 | C44: =IF(B44="","",COUNTIFS(Vendas!$A$5:$A$2004,B44)) -> 8 | D44: =IF(B44="","",SUMIFS(Vendas!$F$5:$F$2004,Vendas!$A$5:$A$2004,B44)) -> 3020 | E44: =IF(B44="","",SUMIFS(Vendas!$I$5:$I$2004,Vendas!$A$5:$A$2004,B44)) -> 76.09 | F44: =IF(B44="","",D44-E44) -> 2943.91 | G44: =IF(B44="","",SUMPRODUCT((Vendas!$U$5:$U$2004>0)*(Vendas!$U$5:$U$2004<=B44)*(MOD(B44-Vendas!$U$5:$U$2004,30)=0)*((B44-Vendas!$U$5:$U$2004)/30<Vendas!$V$5:$V$2004)*Vendas!$W$5:$W$2004)) -> 1134.3 | H44: =IF(OR(B44="",G44=0),"",IF(COUNTIFS(Vendas!$L$5:$L$2004,B44,Vendas!$R$5:$R$2004,"A conferir")>0,"Falta conferir",IF(B44>Config!$B$8,"A cair","Conferido"))) -> Conferido
...

Sheet Config
A1: Configurações
A2: Células amarelas: você preenche. Taxas e prazos da sua operadora (o contrato da maquininha diz; confira no extrato).
A4: Clínica | B4: Clínica Vida Plena (exemplo fictício) | H4: Meses
A5: Ano do painel | B5: 2026 | H5: Janeiro
A6: Mês do painel | B6: Agosto | H6: Fevereiro
A7: Número do mês | B7: =MATCH(B6,$H$5:$H$16,0) -> 8 | H7: Março
A8: Data de referência (hoje) | B8: 46279 | H8: Abril
A9: Preço da consulta particular (para a comparação) | B9: 380 | H9: Maio
H10: Junho
A11: Tipo | B11: Taxa (%) | C11: Cai na conta em (dias) | D11: Observação | H11: Julho
A12: Pix | B12: 0 | C12: 0 | D12: Pix na conta PJ: no exemplo, sem taxa (alguns bancos cobram por recebimento). | H12: Agosto
A13: Cartão de débito | B13: 0.015 | C13: 1 | D13: Débito costuma cair no dia útil seguinte. | H13: Setembro
A14: Cartão de crédito | B14: 0.032 | C14: 30 | D14: Crédito à vista cai em 30 dias. | H14: Outubro
A15: Cartão de crédito parcelado | B15: 0.039 | C15: 30 | D15: Parcelado: cada parcela cai 30 dias depois da anterior; a taxa é maior. | H15: Novembro
H16: Dezembro
A17: Antecipar o crédito? (Sim/Não) | B17: Não | D17: Com antecipação, o crédito cai em 1 dia e a operadora cobra a taxa de antecipação sobre o valor pelo prazo antecipado. No exemplo, a clínica não antecipa.
A18: Taxa de antecipação (% ao mês) | B18: 0.018
A20: As taxas do exemplo são ilustrativas. Pegue as suas no contrato da maquininha ou no extrato da operadora; elas mudam por bandeira e por volume.

Sheet Vendas
A1: Vendas no cartão e no Pix
A2: Uma linha por pagamento (copie da Agenda da planilha 01: atendimentos particulares realizados com Pix ou cartão). Amarelo: data, paciente, procedimento, tipo, parcelas, valor bruto e a conferência no extrato.
A4: Data da venda | B4: Paciente | C4: Procedimento | D4: Tipo | E4: Parcelas | F4: Valor bruto (R$) | G4: Parcelas já conferidas | H4: Taxa (%) | I4: Taxa (R$) | J4: Valor líquido (R$) | K4: Líquido por parcela (R$) | L4: 1ª parcela cai em | M4: Última parcela cai em | N4: Já previsto até hoje (R$) | O4: Ainda vai cair (R$) | P4: Mês | Q4: Ano | R4: Situação
A5: 46174 | B5: Cláudia Santos | C5: MAPA | D5: Pix | F5: 300 | G5: 1 | H5: =IF(D5="","",IFERROR(INDEX(Config!$B$12:$B$15,MATCH(IF(AND(D5="Cartão de crédito",N(E5)>1),"Cartão de crédito parcelado",D5),Config!$A$12:$A$15,0)),0)+IF(AND(Config!$B$17="Sim",LEFT(D5,17)="Cartão de crédito"),Config!$B$18*IFERROR(INDEX(Config!$C$12:$C$15,MATCH(IF(AND(D5="Cartão de crédito",N(E5)>1),"Cartão de crédito parcelado",D5),Config!$A$12:$A$15,0)),0)/30*MAX(1,N(E5)),0)) -> 0 | I5: =IF(OR(D5="",F5=""),"",ROUND(F5*H5,2)) -> 0 | J5: =IF(I5="","",F5-I5) -> 300 | K5: =IF(J5="","",J5/MAX(1,N(E5))) -> 300 | L5: =IF(OR(D5="",A5=""),"",A5+IF(AND(Config!$B$17="Sim",LEFT(D5,17)="Cartão de crédito"),1,IFERROR(INDEX(Config!$C$12:$C$15,MATCH(IF(AND(D5="Cartão de crédito",N(E5)>1),"Cartão de crédito parcelado",D5),Config!$A$12:$A$15,0)),0))) -> 46174 | M5: =IF(L5="","",IF(AND(Config!$B$17="Sim",LEFT(D5,17)="Cartão de crédito"),L5,L5+30*(MAX(1,N(E5))-1))) -> 46174 | N5: =IF(OR(L5="",K5=""),"",K5*MIN(MAX(1,N(E5)),MAX(0,INT((Config!$B$8-L5)/30)+1))) -> 300 | O5: =IF(J5="","",J5-N(N5)) -> 0 | P5: =IF(A5="","",MONTH(A5)) -> 6 | Q5: =IF(A5="","",YEAR(A5)) -> 2026 | R5: =IF(L5="","",IF(L5>Config!$B$8,"A cair",IF(N(G5)>=MIN(MAX(1,N(E5)),MAX(0,INT((Config!$B$8-L5)/30)+1)),IF(N(G5)>=MAX(1,N(E5)),"Conferido","Conferido até aqui"),"A conferir"))) -> Conferido | S5: =IF(R5="A conferir",(Config!$B$8-L5)*1000+N(F5)/1000+ROW()/100000,0) -> 0 | T5: =IF(R5="A conferir",N(N5),0) -> 0 | U5: =IF(L5="",0,L5) -> 46174 | V5: =IF(L5="",0,MAX(1,N(E5))) -> 1 | W5: =IF(K5="",0,K5) -> 300
A6: 46175 | B6: Otávio Nascimento | C6: Consulta | D6: Cartão de crédito | F6: 380 | G6: 1 | H6: =IF(D6="","",IFERROR(INDEX(Config!$B$12:$B$15,MATCH(IF(AND(D6="Cartão de crédito",N(E6)>1),"Cartão de crédito parcelado",D6),Config!$A$12:$A$15,0)),0)+IF(AND(Config!$B$17="Sim",LEFT(D6,17)="Cartão de crédito"),Config!$B$18*IFERROR(INDEX(Config!$C$12:$C$15,MATCH(IF(AND(D6="Cartão de crédito",N(E6)>1),"Cartão de crédito parcelado",D6),Config!$A$12:$A$15,0)),0)/30*MAX(1,N(E6)),0)) -> 0.032 | I6: =IF(OR(D6="",F6=""),"",ROUND(F6*H6,2)) -> 12.16 | J6: =IF(I6="","",F6-I6) -> 367.84 | K6: =IF(J6="","",J6/MAX(1,N(E6))) -> 367.84 | L6: =IF(OR(D6="",A6=""),"",A6+IF(AND(Config!$B$17="Sim",LEFT(D6,17)="Cartão de crédito"),1,IFERROR(INDEX(Config!$C$12:$C$15,MATCH(IF(AND(D6="Cartão de crédito",N(E6)>1),"Cartão de crédito parcelado",D6),Config!$A$12:$A$15,0)),0))) -> 46205 | M6: =IF(L6="","",IF(AND(Config!$B$17="Sim",LEFT(D6,17)="Cartão de crédito"),L6,L6+30*(MAX(1,N(E6))-1))) -> 46205 | N6: =IF(OR(L6="",K6=""),"",K6*MIN(MAX(1,N(E6)),MAX(0,INT((Config!$B$8-L6)/30)+1))) -> 367.84 | O6: =IF(J6="","",J6-N(N6)) -> 0 | P6: =IF(A6="","",MONTH(A6)) -> 6 | Q6: =IF(A6="","",YEAR(A6)) -> 2026 | R6: =IF(L6="","",IF(L6>Config!$B$8,"A cair",IF(N(G6)>=MIN(MAX(1,N(E6)),MAX(0,INT((Config!$B$8-L6)/30)+1)),IF(N(G6)>=MAX(1,N(E6)),"Conferido","Conferido até aqui"),"A conferir"))) -> Conferido | S6: =IF(R6="A conferir",(Config!$B$8-L6)*1000+N(F6)/1000+ROW()/100000,0) -> 0 | T6: =IF(R6="A conferir",N(N6),0) -> 0 | U6: =IF(L6="",0,L6) -> 46205 | V6: =IF(L6="",0,MAX(1,N(E6))) -> 1 | W6: =IF(K6="",0,K6) -> 367.84
A7: 46175 | B7: Leandro Oliveira | C7: Consulta | D7: Pix | F7: 380 | G7: 1 | H7: =IF(D7="","",IFERROR(INDEX(Config!$B$12:$B$15,MATCH(IF(AND(D7="Cartão de crédito",N(E7)>1),"Cartão de crédito parcelado",D7),Config!$A$12:$A$15,0)),0)+IF(AND(Config!$B$17="Sim",LEFT(D7,17)="Cartão de crédito"),Config!$B$18*IFERROR(INDEX(Config!$C$12:$C$15,MATCH(IF(AND(D7="Cartão de crédito",N(E7)>1),"Cartão de crédito parcelado",D7),Config!$A$12:$A$15,0)),0)/30*MAX(1,N(E7)),0)) -> 0 | I7: =IF(OR(D7="",F7=""),"",ROUND(F7*H7,2)) -> 0 | J7: =IF(I7="","",F7-I7) -> 380 | K7: =IF(J7="","",J7/MAX(1,N(E7))) -> 380 | L7: =IF(OR(D7="",A7=""),"",A7+IF(AND(Config!$B$17="Sim",LEFT(D7,17)="Cartão de crédito"),1,IFERROR(INDEX(Config!$C$12:$C$15,MATCH(IF(AND(D7="Cartão de crédito",N(E7)>1),"Cartão de crédito parcelado",D7),Config!$A$12:$A$15,0)),0))) -> 46175 | M7: =IF(L7="","",IF(AND(Config!$B$17="Sim",LEFT(D7,17)="Cartão de crédito"),L7,L7+30*(MAX(1,N(E7))-1))) -> 46175 | N7: =IF(OR(L7="",K7=""),"",K7*MIN(MAX(1,N(E7)),MAX(0,INT((Config!$B$8-L7)/30)+1))) -> 380 | O7: =IF(J7="","",J7-N(N7)) -> 0 | P7: =IF(A7="","",MONTH(A7)) -> 6 | Q7: =IF(A7="","",YEAR(A7)) -> 2026 | R7: =IF(L7="","",IF(L7>Config!$B$8,"A cair",IF(N(G7)>=MIN(MAX(1,N(E7)),MAX(0,INT((Config!$B$8-L7)/30)+1)),IF(N(G7)>=MAX(1,N(E7)),"Conferido","Conferido até aqui"),"A conferir"))) -> Conferido | S7: =IF(R7="A conferir",(Config!$B$8-L7)*1000+N(F7)/1000+ROW()/100000,0) -> 0 | T7: =IF(R7="A conferir",N(N7),0) -> 0 | U7: =IF(L7="",0,L7) -> 46175 | V7: =IF(L7="",0,MAX(1,N(E7))) -> 1 | W7: =IF(K7="",0,K7) -> 380
A8: 46175 | B8: Cláudia Costa | C8: Consulta | D8: Pix | F8: 380 | G8: 1 | H8: =IF(D8="","",IFERROR(INDEX(Config!$B$12:$B$15,MATCH(IF(AND(D8="Cartão de crédito",N(E8)>1),"Cartão de crédito parcelado",D8),Config!$A$12:$A$15,0)),0)+IF(AND(Config!$B$17="Sim",LEFT(D8,17)="Cartão de crédito"),Config!$B$18*IFERROR(INDEX(Config!$C$12:$C$15,MATCH(IF(AND(D8="Cartão de crédito",N(E8)>1),"Cartão de crédito parcelado",D8),Config!$A$12:$A$15,0)),0)/30*MAX(1,N(E8)),0)) -> 0 | I8: =IF(OR(D8="",F8=""),"",ROUND(F8*H8,2)) -> 0 | J8: =IF(I8="","",F8-I8) -> 380 | K8: =IF(J8="","",J8/MAX(1,N(E8))) -> 380 | L8: =IF(OR(D8="",A8=""),"",A8+IF(AND(Config!$B$17="Sim",LEFT(D8,17)="Cartão de crédito"),1,IFERROR(INDEX(Config!$C$12:$C$15,MATCH(IF(AND(D8="Cartão de crédito",N(E8)>1),"Cartão de crédito parcelado",D8),Config!$A$12:$A$15,0)),0))) -> 46175 | M8: =IF(L8="","",IF(AND(Config!$B$17="Sim",LEFT(D8,17)="Cartão de crédito"),L8,L8+30*(MAX(1,N(E8))-1))) -> 46175 | N8: =IF(OR(L8="",K8=""),"",K8*MIN(MAX(1,N(E8)),MAX(0,INT((Config!$B$8-L8)/30)+1))) -> 380 | O8: =IF(J8="","",J8-N(N8)) -> 0 | P8: =IF(A8="","",MONTH(A8)) -> 6 | Q8: =IF(A8="","",YEAR(A8)) -> 2026 | R8: =IF(L8="","",IF(L8>Config!$B$8,"A cair",IF(N(G8)>=MIN(MAX(1,N(E8)),MAX(0,INT((Config!$B$8-L8)/30)+1)),IF(N(G8)>=MAX(1,N(E8)),"Conferido","Conferido até aqui"),"A conferir"))) -> Conferido | S8: =IF(R8="A conferir",(Config!$B$8-L8)*1000+N(F8)/1000+ROW()/100000,0) -> 0 | T8: =IF(R8="A conferir",N(N8),0) -> 0 | U8: =IF(L8="",0,L8) -> 46175 | V8: =IF(L8="",0,MAX(1,N(E8))) -> 1 | W8: =IF(K8="",0,K8) -> 380
A9: 46175 | B9: Eduardo Pereira | C9: Avaliação endócrina | D9: Pix | F9: 400 | G9: 1 | H9: =IF(D9="","",IFERROR(INDEX(Config!$B$12:$B$15,MATCH(IF(AND(D9="Cartão de crédito",N(E9)>1),"Cartão de crédito parcelado",D9),Config!$A$12:$A$15,0)),0)+IF(AND(Config!$B$17="Sim",LEFT(D9,17)="Cartão de crédito"),Config!$B$18*IFERROR(INDEX(Config!$C$12:$C$15,MATCH(IF(AND(D9="Cartão de crédito",N(E9)>1),"Cartão de crédito parcelado",D9),Config!$A$12:$A$15,0)),0)/30*MAX(1,N(E9)),0)) -> 0 | I9: =IF(OR(D9="",F9=""),"",ROUND(F9*H9,2)) -> 0 | J9: =IF(I9="","",F9-I9) -> 400 | K9: =IF(J9="","",J9/MAX(1,N(E9))) -> 400 | L9: =IF(OR(D9="",A9=""),"",A9+IF(AND(Config!$B$17="Sim",LEFT(D9,17)="Cartão de crédito"),1,IFERROR(INDEX(Config!$C$12:$C$15,MATCH(IF(AND(D9="Cartão de crédito",N(E9)>1),"Cartão de crédito parcelado",D9),Config!$A$12:$A$15,0)),0))) -> 46175 | M9: =IF(L9="","",IF(AND(Config!$B$17="Sim",LEFT(D9,17)="Cartão de crédito"),L9,L9+30*(MAX(1,N(E9))-1))) -> 46175 | N9: =IF(OR(L9="",K9=""),"",K9*MIN(MAX(1,N(E9)),MAX(0,INT((Config!$B$8-L9)/30)+1))) -> 400 | O9: =IF(J9="","",J9-N(N9)) -> 0 | P9: =IF(A9="","",MONTH(A9)) -> 6 | Q9: =IF(A9="","",YEAR(A9)) -> 2026 | R9: =IF(L9="","",IF(L9>Config!$B$8,"A cair",IF(N(G9)>=MIN(MAX(1,N(E9)),MAX(0,INT((Config!$B$8-L9)/30)+1)),IF(N(G9)>=MAX(1,N(E9)),"Conferido","Conferido até aqui"),"A conferir"))) -> Conferido | S9: =IF(R9="A conferir",(Config!$B$8-L9)*1000+N(F9)/1000+ROW()/100000,0) -> 0 | T9: =IF(R9="A conferir",N(N9),0) -> 0 | U9: =IF(L9="",0,L9) -> 46175 | V9: =IF(L9="",0,MAX(1,N(E9))) -> 1 | W9: =IF(K9="",0,K9) -> 400
A10: 46175 | B10: Rafael Pereira | C10: Avaliação endócrina | D10: Pix | F10: 400 | G10: 1 | H10: =IF(D10="","",IFERROR(INDEX(Config!$B$12:$B$15,MATCH(IF(AND(D10="Cartão de crédito",N(E10)>1),"Cartão de crédito parcelado",D10),Config!$A$12:$A$15,0)),0)+IF(AND(Config!$B$17="Sim",LEFT(D10,17)="Cartão de crédito"),Config!$B$18*IFERROR(INDEX(Config!$C$12:$C$15,MATCH(IF(AND(D10="Cartão de crédito",N(E10)>1),"Cartão de crédito parcelado",D10),Config!$A$12:$A$15,0)),0)/30*MAX(1,N(E10)),0)) -> 0 | I10: =IF(OR(D10="",F10=""),"",ROUND(F10*H10,2)) -> 0 | J10: =IF(I10="","",F10-I10) -> 400 | K10: =IF(J10="","",J10/MAX(1,N(E10))) -> 400 | L10: =IF(OR(D10="",A10=""),"",A10+IF(AND(Config!$B$17="Sim",LEFT(D10,17)="Cartão de crédito"),1,IFERROR(INDEX(Config!$C$12:$C$15,MATCH(IF(AND(D10="Cartão de crédito",N(E10)>1),"Cartão de crédito parcelado",D10),Config!$A$12:$A$15,0)),0))) -> 46175 | M10: =IF(L10="","",IF(AND(Config!$B$17="Sim",LEFT(D10,17)="Cartão de crédito"),L10,L10+30*(MAX(1,N(E10))-1))) -> 46175 | N10: =IF(OR(L10="",K10=""),"",K10*MIN(MAX(1,N(E10)),MAX(0,INT((Config!$B$8-L10)/30)+1))) -> 400 | O10: =IF(J10="","",J10-N(N10)) -> 0 | P10: =IF(A10="","",MONTH(A10)) -> 6 | Q10: =IF(A10="","",YEAR(A10)) -> 2026 | R10: =IF(L10="","",IF(L10>Config!$B$8,"A cair",IF(N(G10)>=MIN(MAX(1,N(E10)),MAX(0,INT((Config!$B$8-L10)/30)+1)),IF(N(G10)>=MAX(1,N(E10)),"Conferido","Conferido até aqui"),"A conferir"))) -> Conferido | S10: =IF(R10="A conferir",(Config!$B$8-L10)*1000+N(F10)/1000+ROW()/100000,0) -> 0 | T10: =IF(R10="A conferir",N(N10),0) -> 0 | U10: =IF(L10="",0,L10) -> 46175 | V10: =IF(L10="",0,MAX(1,N(E10))) -> 1 | W10: =IF(K10="",0,K10) -> 400
A11: 46175 | B11: Elaine Cardoso | C11: Teste ergométrico | D11: Cartão de crédito | E11: 2 | F11: 450 | G11: 2 | H11: =IF(D11="","",IFERROR(INDEX(Config!$B$12:$B$15,MATCH(IF(AND(D11="Cartão de crédito",N(E11)>1),"Cartão de crédito parcelado",D11),Config!$A$12:$A$15,0)),0)+IF(AND(Config!$B$17="Sim",LEFT(D11,17)="Cartão de crédito"),Config!$B$18*IFERROR(INDEX(Config!$C$12:$C$15,MATCH(IF(AND(D11="Cartão de crédito",N(E11)>1),"Cartão de crédito parcelado",D11),Config!$A$12:$A$15,0)),0)/30*MAX(1,N(E11)),0)) -> 0.039 | I11: =IF(OR(D11="",F11=""),"",ROUND(F11*H11,2)) -> 17.55 | J11: =IF(I11="","",F11-I11) -> 432.45 | K11: =IF(J11="","",J11/MAX(1,N(E11))) -> 216.225 | L11: =IF(OR(D11="",A11=""),"",A11+IF(AND(Config!$B$17="Sim",LEFT(D11,17)="Cartão de crédito"),1,IFERROR(INDEX(Config!$C$12:$C$15,MATCH(IF(AND(D11="Cartão de crédito",N(E11)>1),"Cartão de crédito parcelado",D11),Config!$A$12:$A$15,0)),0))) -> 46205 | M11: =IF(L11="","",IF(AND(Config!$B$17="Sim",LEFT(D11,17)="Cartão de crédito"),L11,L11+30*(MAX(1,N(E11))-1))) -> 46235 | N11: =IF(OR(L11="",K11=""),"",K11*MIN(MAX(1,N(E11)),MAX(0,INT((Config!$B$8-L11)/30)+1))) -> 432.45 | O11: =IF(J11="","",J11-N(N11)) -> 0 | P11: =IF(A11="","",MONTH(A11)) -> 6 | Q11: =IF(A11="","",YEAR(A11)) -> 2026 | R11: =IF(L11="","",IF(L11>Config!$B$8,"A cair",IF(N(G11)>=MIN(MAX(1,N(E11)),MAX(0,INT((Config!$B$8-L11)/30)+1)),IF(N(G11)>=MAX(1,N(E11)),"Conferido","Conferido até aqui"),"A conferir"))) -> Conferido | S11: =IF(R11="A conferir",(Config!$B$8-L11)*1000+N(F11)/1000+ROW()/100000,0) -> 0 | T11: =IF(R11="A conferir",N(N11),0) -> 0 | U11: =IF(L11="",0,L11) -> 46205 | V11: =IF(L11="",0,MAX(1,N(E11))) -> 2 | W11: =IF(K11="",0,K11) -> 216.225
A12: 46176 | B12: Lucas Lopes | C12: Consulta | D12: Cartão de crédito | F12: 380 | G12: 1 | H12: =IF(D12="","",IFERROR(INDEX(Config!$B$12:$B$15,MATCH(IF(AND(D12="Cartão de crédito",N(E12)>1),"Cartão de crédito parcelado",D12),Config!$A$12:$A$15,0)),0)+IF(AND(Config!$B$17="Sim",LEFT(D12,17)="Cartão de crédito"),Config!$B$18*IFERROR(INDEX(Config!$C$12:$C$15,MATCH(IF(AND(D12="Cartão de crédito",N(E12)>1),"Cartão de crédito parcelado",D12),Config!$A$12:$A$15,0)),0)/30*MAX(1,N(E12)),0)) -> 0.032 | I12: =IF(OR(D12="",F12=""),"",ROUND(F12*H12,2)) -> 12.16 | J12: =IF(I12="","",F12-I12) -> 367.84 | K12: =IF(J12="","",J12/MAX(1,N(E12))) -> 367.84 | L12: =IF(OR(D12="",A12=""),"",A12+IF(AND(Config!$B$17="Sim",LEFT(D12,17)="Cartão de crédito"),1,IFERROR(INDEX(Config!$C$12:$C$15,MATCH(IF(AND(D12="Cartão de crédito",N(E12)>1),"Cartão de crédito parcelado",D12),Config!$A$12:$A$15,0)),0))) -> 46206 | M12: =IF(L12="","",IF(AND(Config!$B$17="Sim",LEFT(D12,17)="Cartão de crédito"),L12,L12+30*(MAX(1,N(E12))-1))) -> 46206 | N12: =IF(OR(L12="",K12=""),"",K12*MIN(MAX(1,N(E12)),MAX(0,INT((Config!$B$8-L12)/30)+1))) -> 367.84 | O12: =IF(J12="","",J12-N(N12)) -> 0 | P12: =IF(A12="","",MONTH(A12)) -> 6 | Q12: =IF(A12="","",YEAR(A12)) -> 2026 | R12: =IF(L12="","",IF(L12>Config!$B$8,"A cair",IF(N(G12)>=MIN(MAX(1,N(E12)),MAX(0,INT((Config!$B$8-L12)/30)+1)),IF(N(G12)>=MAX(1,N(E12)),"Conferido","Conferido até aqui"),"A conferir"))) -> Conferido | S12: =IF(R12="A conferir",(Config!$B$8-L12)*1000+N(F12)/1000+ROW()/100000,0) -> 0 | T12: =IF(R12="A conferir",N(N12),0) -> 0 | U12: =IF(L12="",0,L12) -> 46206 | V12: =IF(L12="",0,MAX(1,N(E12))) -> 1 | W12: =IF(K12="",0,K12) -> 367.84
A13: 46176 | B13: Helena Moreira | C13: Consulta | D13: Pix | F13: 380 | G13: 1 | H13: =IF(D13="","",IFERROR(INDEX(Config!$B$12:$B$15,MATCH(IF(AND(D13="Cartão de crédito",N(E13)>1),"Cartão de crédito parcelado",D13),Config!$A$12:$A$15,0)),0)+IF(AND(Config!$B$17="Sim",LEFT(D13,17)="Cartão de crédito"),Config!$B$18*IFERROR(INDEX(Config!$C$12:$C$15,MATCH(IF(AND(D13="Cartão de crédito",N(E13)>1),"Cartão de crédito parcelado",D13),Config!$A$12:$A$15,0)),0)/30*MAX(1,N(E13)),0)) -> 0 | I13: =IF(OR(D13="",F13=""),"",ROUND(F13*H13,2)) -> 0 | J13: =IF(I13="","",F13-I13) -> 380 | K13: =IF(J13="","",J13/MAX(1,N(E13))) -> 380 | L13: =IF(OR(D13="",A13=""),"",A13+IF(AND(Config!$B$17="Sim",LEFT(D13,17)="Cartão de crédito"),1,IFERROR(INDEX(Config!$C$12:$C$15,MATCH(IF(AND(D13="Cartão de crédito",N(E13)>1),"Cartão de crédito parcelado",D13),Config!$A$12:$A$15,0)),0))) -> 46176 | M13: =IF(L13="","",IF(AND(Config!$B$17="Sim",LEFT(D13,17)="Cartão de crédito"),L13,L13+30*(MAX(1,N(E13))-1))) -> 46176 | N13: =IF(OR(L13="",K13=""),"",K13*MIN(MAX(1,N(E13)),MAX(0,INT((Config!$B$8-L13)/30)+1))) -> 380 | O13: =IF(J13="","",J13-N(N13)) -> 0 | P13: =IF(A13="","",MONTH(A13)) -> 6 | Q13: =IF(A13="","",YEAR(A13)) -> 2026 | R13: =IF(L13="","",IF(L13>Config!$B$8,"A cair",IF(N(G13)>=MIN(MAX(1,N(E13)),MAX(0,INT((Config!$B$8-L13)/30)+1)),IF(N(G13)>=MAX(1,N(E13)),"Conferido","Conferido até aqui"),"A conferir"))) -> Conferido | S13: =IF(R13="A conferir",(Config!$B$8-L13)*1000+N(F13)/1000+ROW()/100000,0) -> 0 | T13: =IF(R13="A conferir",N(N13),0) -> 0 | U13: =IF(L13="",0,L13) -> 46176 | V13: =IF(L13="",0,MAX(1,N(E13))) -> 1 | W13: =IF(K13="",0,K13) -> 380
A14: 46181 | B14: Mônica Martins | C14: Consulta | D14: Cartão de débito | F14: 380 | G14: 1 | H14: =IF(D14="","",IFERROR(INDEX(Config!$B$12:$B$15,MATCH(IF(AND(D14="Cartão de crédito",N(E14)>1),"Cartão de crédito parcelado",D14),Config!$A$12:$A$15,0)),0)+IF(AND(Config!$B$17="Sim",LEFT(D14,17)="Cartão de crédito"),Config!$B$18*IFERROR(INDEX(Config!$C$12:$C$15,MATCH(IF(AND(D14="Cartão de crédito",N(E14)>1),"Cartão de crédito parcelado",D14),Config!$A$12:$A$15,0)),0)/30*MAX(1,N(E14)),0)) -> 0.015 | I14: =IF(OR(D14="",F14=""),"",ROUND(F14*H14,2)) -> 5.7 | J14: =IF(I14="","",F14-I14) -> 374.3 | K14: =IF(J14="","",J14/MAX(1,N(E14))) -> 374.3 | L14: =IF(OR(D14="",A14=""),"",A14+IF(AND(Config!$B$17="Sim",LEFT(D14,17)="Cartão de crédito"),1,IFERROR(INDEX(Config!$C$12:$C$15,MATCH(IF(AND(D14="Cartão de crédito",N(E14)>1),"Cartão de crédito parcelado",D14),Config!$A$12:$A$15,0)),0))) -> 46182 | M14: =IF(L14="","",IF(AND(Config!$B$17="Sim",LEFT(D14,17)="Cartão de crédito"),L14,L14+30*(MAX(1,N(E14))-1))) -> 46182 | N14: =IF(OR(L14="",K14=""),"",K14*MIN(MAX(1,N(E14)),MAX(0,INT((Config!$B$8-L14)/30)+1))) -> 374.3 | O14: =IF(J14="","",J14-N(N14)) -> 0 | P14: =IF(A14="","",MONTH(A14)) -> 6 | Q14: =IF(A14="","",YEAR(A14)) -> 2026 | R14: =IF(L14="","",IF(L14>Config!$B$8,"A cair",IF(N(G14)>=MIN(MAX(1,N(E14)),MAX(0,INT((Config!$B$8-L14)/30)+1)),IF(N(G14)>=MAX(1,N(E14)),"Conferido","Conferido até aqui"),"A conferir"))) -> Conferido | S14: =IF(R14="A conferir",(Config!$B$8-L14)*1000+N(F14)/1000+ROW()/100000,0) -> 0 | T14: =IF(R14="A conferir",N(N14),0) -> 0 | U14: =IF(L14="",0,L14) -> 46182 | V14: =IF(L14="",0,MAX(1,N(E14))) -> 1 | W14: =IF(K14="",0,K14) -> 374.3
A15: 46181 | B15: Mariana Nascimento | C15: Consulta | D15: Pix | F15: 380 | G15: 1 | H15: =IF(D15="","",IFERROR(INDEX(Config!$B$12:$B$15,MATCH(IF(AND(D15="Cartão de crédito",N(E15)>1),"Cartão de crédito parcelado",D15),Config!$A$12:$A$15,0)),0)+IF(AND(Config!$B$17="Sim",LEFT(D15,17)="Cartão de crédito"),Config!$B$18*IFERROR(INDEX(Config!$C$12:$C$15,MATCH(IF(AND(D15="Cartão de crédito",N(E15)>1),"Cartão de crédito parcelado",D15),Config!$A$12:$A$15,0)),0)/30*MAX(1,N(E15)),0)) -> 0 | I15: =IF(OR(D15="",F15=""),"",ROUND(F15*H15,2)) -> 0 | J15: =IF(I15="","",F15-I15) -> 380 | K15: =IF(J15="","",J15/MAX(1,N(E15))) -> 380 | L15: =IF(OR(D15="",A15=""),"",A15+IF(AND(Config!$B$17="Sim",LEFT(D15,17)="Cartão de crédito"),1,IFERROR(INDEX(Config!$C$12:$C$15,MATCH(IF(AND(D15="Cartão de crédito",N(E15)>1),"Cartão de crédito parcelado",D15),Config!$A$12:$A$15,0)),0))) -> 46181 | M15: =IF(L15="","",IF(AND(Config!$B$17="Sim",LEFT(D15,17)="Cartão de crédito"),L15,L15+30*(MAX(1,N(E15))-1))) -> 46181 | N15: =IF(OR(L15="",K15=""),"",K15*MIN(MAX(1,N(E15)),MAX(0,INT((Config!$B$8-L15)/30)+1))) -> 380 | O15: =IF(J15="","",J15-N(N15)) -> 0 | P15: =IF(A15="","",MONTH(A15)) -> 6 | Q15: =IF(A15="","",YEAR(A15)) -> 2026 | R15: =IF(L15="","",IF(L15>Config!$B$8,"A cair",IF(N(G15)>=MIN(MAX(1,N(E15)),MAX(0,INT((Config!$B$8-L15)/30)+1)),IF(N(G15)>=MAX(1,N(E15)),"Conferido","Conferido até aqui"),"A conferir"))) -> Conferido | S15: =IF(R15="A conferir",(Config!$B$8-L15)*1000+N(F15)/1000+ROW()/100000,0) -> 0 | T15: =IF(R15="A conferir",N(N15),0) -> 0 | U15: =IF(L15="",0,L15) -> 46181 | V15: =IF(L15="",0,MAX(1,N(E15))) -> 1 | W15: =IF(K15="",0,K15) -> 380
A16: 46181 | B16: Rodrigo Moreira | C16: ECG | D16: Cartão de crédito | F16: 130 | G16: 1 | H16: =IF(D16="","",IFERROR(INDEX(Config!$B$12:$B$15,MATCH(IF(AND(D16="Cartão de crédito",N(E16)>1),"Cartão de crédito parcelado",D16),Config!$A$12:$A$15,0)),0)+IF(AND(Config!$B$17="Sim",LEFT(D16,17)="Cartão de crédito"),Config!$B$18*IFERROR(INDEX(Config!$C$12:$C$15,MATCH(IF(AND(D16="Cartão de crédito",N(E16)>1),"Cartão de crédito parcelado",D16),Config!$A$12:$A$15,0)),0)/30*MAX(1,N(E16)),0)) -> 0.032 | I16: =IF(OR(D16="",F16=""),"",ROUND(F16*H16,2)) -> 4.16 | J16: =IF(I16="","",F16-I16) -> 125.84 | K16: =IF(J16="","",J16/MAX(1,N(E16))) -> 125.84 | L16: =IF(OR(D16="",A16=""),"",A16+IF(AND(Config!$B$17="Sim",LEFT(D16,17)="Cartão de crédito"),1,IFERROR(INDEX(Config!$C$12:$C$15,MATCH(IF(AND(D16="Cartão de crédito",N(E16)>1),"Cartão de crédito parcelado",D16),Config!$A$12:$A$15,0)),0))) -> 46211 | M16: =IF(L16="","",IF(AND(Config!$B$17="Sim",LEFT(D16,17)="Cartão de crédito"),L16,L16+30*(MAX(1,N(E16))-1))) -> 46211 | N16: =IF(OR(L16="",K16=""),"",K16*MIN(MAX(1,N(E16)),MAX(0,INT((Config!$B$8-L16)/30)+1))) -> 125.84 | O16: =IF(J16="","",J16-N(N16)) -> 0 | P16: =IF(A16="","",MONTH(A16)) -> 6 | Q16: =IF(A16="","",YEAR(A16)) -> 2026 | R16: =IF(L16="","",IF(L16>Config!$B$8,"A cair",IF(N(G16)>=MIN(MAX(1,N(E16)),MAX(0,INT((Config!$B$8-L16)/30)+1)),IF(N(G16)>=MAX(1,N(E16)),"Conferido","Conferido até aqui"),"A conferir"))) -> Conferido | S16: =IF(R16="A conferir",(Config!$B$8-L16)*1000+N(F16)/1000+ROW()/100000,0) -> 0 | T16: =IF(R16="A conferir",N(N16),0) -> 0 | U16: =IF(L16="",0,L16) -> 46211 | V16: =IF(L16="",0,MAX(1,N(E16))) -> 1 | W16: =IF(K16="",0,K16) -> 125.84
A17: 46181 | B17: Wagner Santos | C17: ECG | D17: Cartão de crédito | F17: 130 | G17: 1 | H17: =IF(D17="","",IFERROR(INDEX(Config!$B$12:$B$15,MATCH(IF(AND(D17="Cartão de crédito",N(E17)>1),"Cartão de crédito parcelado",D17),Config!$A$12:$A$15,0)),0)+IF(AND(Config!$B$17="Sim",LEFT(D17,17)="Cartão de crédito"),Config!$B$18*IFERROR(INDEX(Config!$C$12:$C$15,MATCH(IF(AND(D17="Cartão de crédito",N(E17)>1),"Cartão de crédito parcelado",D17),Config!$A$12:$A$15,0)),0)/30*MAX(1,N(E17)),0)) -> 0.032 | I17: =IF(OR(D17="",F17=""),"",ROUND(F17*H17,2)) -> 4.16 | J17: =IF(I17="","",F17-I17) -> 125.84 | K17: =IF(J17="","",J17/MAX(1,N(E17))) -> 125.84 | L17: =IF(OR(D17="",A17=""),"",A17+IF(AND(Config!$B$17="Sim",LEFT(D17,17)="Cartão de crédito"),1,IFERROR(INDEX(Config!$C$12:$C$15,MATCH(IF(AND(D17="Cartão de crédito",N(E17)>1),"Cartão de crédito parcelado",D17),Config!$A$12:$A$15,0)),0))) -> 46211 | M17: =IF(L17="","",IF(AND(Config!$B$17="Sim",LEFT(D17,17)="Cartão de crédito"),L17,L17+30*(MAX(1,N(E17))-1))) -> 46211 | N17: =IF(OR(L17="",K17=""),"",K17*MIN(MAX(1,N(E17)),MAX(0,INT((Config!$B$8-L17)/30)+1))) -> 125.84 | O17: =IF(J17="","",J17-N(N17)) -> 0 | P17: =IF(A17="","",MONTH(A17)) -> 6 | Q17: =IF(A17="","",YEAR(A17)) -> 2026 | R17: =IF(L17="","",IF(L17>Config!$B$8,"A cair",IF(N(G17)>=MIN(MAX(1,N(E17)),MAX(0,INT((Config!$B$8-L17)/30)+1)),IF(N(G17)>=MAX(1,N(E17)),"Conferido","Conferido até aqui"),"A conferir"))) -> Conferido | S17: =IF(R17="A conferir",(Config!$B$8-L17)*1000+N(F17)/1000+ROW()/100000,0) -> 0 | T17: =IF(R17="A conferir",N(N17),0) -> 0 | U17: =IF(L17="",0,L17) -> 46211 | V17: =IF(L17="",0,MAX(1,N(E17))) -> 1 | W17: =IF(K17="",0,K17) -> 125.84
A18: 46182 | B18: Regina Macedo | C18: Consulta | D18: Cartão de crédito | F18: 380 | G18: 1 | H18: =IF(D18="","",IFERROR(INDEX(Config!$B$12:$B$15,MATCH(IF(AND(D18="Cartão de crédito",N(E18)>1),"Cartão de crédito parcelado",D18),Config!$A$12:$A$15,0)),0)+IF(AND(Config!$B$17="Sim",LEFT(D18,17)="Cartão de crédito"),Config!$B$18*IFERROR(INDEX(Config!$C$12:$C$15,MATCH(IF(AND(D18="Cartão de crédito",N(E18)>1),"Cartão de crédito parcelado",D18),Config!$A$12:$A$15,0)),0)/30*MAX(1,N(E18)),0)) -> 0.032 | I18: =IF(OR(D18="",F18=""),"",ROUND(F18*H18,2)) -> 12.16 | J18: =IF(I18="","",F18-I18) -> 367.84 | K18: =IF(J18="","",J18/MAX(1,N(E18))) -> 367.84 | L18: =IF(OR(D18="",A18=""),"",A18+IF(AND(Config!$B$17="Sim",LEFT(D18,17)="Cartão de crédito"),1,IFERROR(INDEX(Config!$C$12:$C$15,MATCH(IF(AND(D18="Cartão de crédito",N(E18)>1),"Cartão de crédito parcelado",D18),Config!$A$12:$A$15,0)),0))) -> 46212 | M18: =IF(L18="","",IF(AND(Config!$B$17="Sim",LEFT(D18,17)="Cartão de crédito"),L18,L18+30*(MAX(1,N(E18))-1))) -> 46212 | N18: =IF(OR(L18="",K18=""),"",K18*MIN(MAX(1,N(E18)),MAX(0,INT((Config!$B$8-L18)/30)+1))) -> 367.84 | O18: =IF(J18="","",J18-N(N18)) -> 0 | P18: =IF(A18="","",MONTH(A18)) -> 6 | Q18: =IF(A18="","",YEAR(A18)) -> 2026 | R18: =IF(L18="","",IF(L18>Config!$B$8,"A cair",IF(N(G18)>=MIN(MAX(1,N(E18)),MAX(0,INT((Config!$B$8-L18)/30)+1)),IF(N(G18)>=MAX(1,N(E18)),"Conferido","Conferido até aqui"),"A conferir"))) -> Conferido | S18: =IF(R18="A conferir",(Config!$B$8-L18)*1000+N(F18)/1000+ROW()/100000,0) -> 0 | T18: =IF(R18="A conferir",N(N18),0) -> 0 | U18: =IF(L18="",0,L18) -> 46212 | V18: =IF(L18="",0,MAX(1,N(E18))) -> 1 | W18: =IF(K18="",0,K18) -> 367.84
A19: 46182 | B19: Cláudia Santos | C19: Consulta | D19: Cartão de crédito | E19: 2 | F19: 380 | G19: 2 | H19: =IF(D19="","",IFERROR(INDEX(Config!$B$12:$B$15,MATCH(IF(AND(D19="Cartão de crédito",N(E19)>1),"Cartão de crédito parcelado",D19),Config!$A$12:$A$15,0)),0)+IF(AND(Config!$B$17="Sim",LEFT(D19,17)="Cartão de crédito"),Config!$B$18*IFERROR(INDEX(Config!$C$12:$C$15,MATCH(IF(AND(D19="Cartão de crédito",N(E19)>1),"Cartão de crédito parcelado",D19),Config!$A$12:$A$15,0)),0)/30*MAX(1,N(E19)),0)) -> 0.039 | I19: =IF(OR(D19="",F19=""),"",ROUND(F19*H19,2)) -> 14.82 | J19: =IF(I19="","",F19-I19) -> 365.18 | K19: =IF(J19="","",J19/MAX(1,N(E19))) -> 182.59 | L19: =IF(OR(D19="",A19=""),"",A19+IF(AND(Config!$B$17="Sim",LEFT(D19,17)="Cartão de crédito"),1,IFERROR(INDEX(Config!$C$12:$C$15,MATCH(IF(AND(D19="Cartão de crédito",N(E19)>1),"Cartão de crédito parcelado",D19),Config!$A$12:$A$15,0)),0))) -> 46212 | M19: =IF(L19="","",IF(AND(Config!$B$17="Sim",LEFT(D19,17)="Cartão de crédito"),L19,L19+30*(MAX(1,N(E19))-1))) -> 46242 | N19: =IF(OR(L19="",K19=""),"",K19*MIN(MAX(1,N(E19)),MAX(0,INT((Config!$B$8-L19)/30)+1))) -> 365.18 | O19: =IF(J19="","",J19-N(N19)) -> 0 | P19: =IF(A19="","",MONTH(A19)) -> 6 | Q19: =IF(A19="","",YEAR(A19)) -> 2026 | R19: =IF(L19="","",IF(L19>Config!$B$8,"A cair",IF(N(G19)>=MIN(MAX(1,N(E19)),MAX(0,INT((Config!$B$8-L19)/30)+1)),IF(N(G19)>=MAX(1,N(E19)),"Conferido","Conferido até aqui"),"A conferir"))) -> Conferido | S19: =IF(R19="A conferir",(Config!$B$8-L19)*1000+N(F19)/1000+ROW()/100000,0) -> 0 | T19: =IF(R19="A conferir",N(N19),0) -> 0 | U19: =IF(L19="",0,L19) -> 46212 | V19: =IF(L19="",0,MAX(1,N(E19))) -> 2 | W19: =IF(K19="",0,K19) -> 182.59
A20: 46182 | B20: Camila Dias | C20: Avaliação endócrina | D20: Pix | F20: 400 | G20: 1 | H20: =IF(D20="","",IFERROR(INDEX(Config!$B$12:$B$15,MATCH(IF(AND(D20="Cartão de crédito",N(E20)>1),"Cartão de crédito parcelado",D20),Config!$A$12:$A$15,0)),0)+IF(AND(Config!$B$17="Sim",LEFT(D20,17)="Cartão de crédito"),Config!$B$18*IFERROR(INDEX(Config!$C$12:$C$15,MATCH(IF(AND(D20="Cartão de crédito",N(E20)>1),"Cartão de crédito parcelado",D20),Config!$A$12:$A$15,0)),0)/30*MAX(1,N(E20)),0)) -> 0 | I20: =IF(OR(D20="",F20=""),"",ROUND(F20*H20,2)) -> 0 | J20: =IF(I20="","",F20-I20) -> 400 | K20: =IF(J20="","",J20/MAX(1,N(E20))) -> 400 | L20: =IF(OR(D20="",A20=""),"",A20+IF(AND(Config!$B$17="Sim",LEFT(D20,17)="Cartão de crédito"),1,IFERROR(INDEX(Config!$C$12:$C$15,MATCH(IF(AND(D20="Cartão de crédito",N(E20)>1),"Cartão de crédito parcelado",D20),Config!$A$12:$A$15,0)),0))) -> 46182 | M20: =IF(L20="","",IF(AND(Config!$B$17="Sim",LEFT(D20,17)="Cartão de crédito"),L20,L20+30*(MAX(1,N(E20))-1))) -> 46182 | N20: =IF(OR(L20="",K20=""),"",K20*MIN(MAX(1,N(E20)),MAX(0,INT((Config!$B$8-L20)/30)+1))) -> 400 | O20: =IF(J20="","",J20-N(N20)) -> 0 | P20: =IF(A20="","",MONTH(A20)) -> 6 | Q20: =IF(A20="","",YEAR(A20)) -> 2026 | R20: =IF(L20="","",IF(L20>Config!$B$8,"A cair",IF(N(G20)>=MIN(MAX(1,N(E20)),MAX(0,INT((Config!$B$8-L20)/30)+1)),IF(N(G20)>=MAX(1,N(E20)),"Conferido","Conferido até aqui"),"A conferir"))) -> Conferido | S20: =IF(R20="A conferir",(Config!$B$8-L20)*1000+N(F20)/1000+ROW()/100000,0) -> 0 | T20: =IF(R20="A conferir",N(N20),0) -> 0 | U20: =IF(L20="",0,L20) -> 46182 | V20: =IF(L20="",0,MAX(1,N(E20))) -> 1 | W20: =IF(K20="",0,K20) -> 400
A21: 46182 | B21: Mariana Gomes | C21: Avaliação endócrina | D21: Cartão de crédito | E21: 2 | F21: 400 | G21: 2 | H21: =IF(D21="","",IFERROR(INDEX(Config!$B$12:$B$15,MATCH(IF(AND(D21="Cartão de crédito",N(E21)>1),"Cartão de crédito parcelado",D21),Config!$A$12:$A$15,0)),0)+IF(AND(Config!$B$17="Sim",LEFT(D21,17)="Cartão de crédito"),Config!$B$18*IFERROR(INDEX(Config!$C$12:$C$15,MATCH(IF(AND(D21="Cartão de crédito",N(E21)>1),"Cartão de crédito parcelado",D21),Config!$A$12:$A$15,0)),0)/30*MAX(1,N(E21)),0)) -> 0.039 | I21: =IF(OR(D21="",F21=""),"",ROUND(F21*H21,2)) -> 15.6 | J21: =IF(I21="","",F21-I21) -> 384.4 | K21: =IF(J21="","",J21/MAX(1,N(E21))) -> 192.2 | L21: =IF(OR(D21="",A21=""),"",A21+IF(AND(Config!$B$17="Sim",LEFT(D21,17)="Cartão de crédito"),1,IFERROR(INDEX(Config!$C$12:$C$15,MATCH(IF(AND(D21="Cartão de crédito",N(E21)>1),"Cartão de crédito parcelado",D21),Config!$A$12:$A$15,0)),0))) -> 46212 | M21: =IF(L21="","",IF(AND(Config!$B$17="Sim",LEFT(D21,17)="Cartão de crédito"),L21,L21+30*(MAX(1,N(E21))-1))) -> 46242 | N21: =IF(OR(L21="",K21=""),"",K21*MIN(MAX(1,N(E21)),MAX(0,INT((Config!$B$8-L21)/30)+1))) -> 384.4 | O21: =IF(J21="","",J21-N(N21)) -> 0 | P21: =IF(A21="","",MONTH(A21)) -> 6 | Q21: =IF(A21="","",YEAR(A21)) -> 2026 | R21: =IF(L21="","",IF(L21>Config!$B$8,"A cair",IF(N(G21)>=MIN(MAX(1,N(E21)),MAX(0,INT((Config!$B$8-L21)/30)+1)),IF(N(G21)>=MAX(1,N(E21)),"Conferido","Conferido até aqui"),"A conferir"))) -> Conferido | S21: =IF(R21="A conferir",(Config!$B$8-L21)*1000+N(F21)/1000+ROW()/100000,0) -> 0 | T21: =IF(R21="A conferir",N(N21),0) -> 0 | U21: =IF(L21="",0,L21) -> 46212 | V21: =IF(L21="",0,MAX(1,N(E21))) -> 2 | W21: =IF(K21="",0,K21) -> 192.2
A22: 46182 | B22: Cláudia Melo | C22: Avaliação endócrina | D22: Cartão de crédito | F22: 400 | G22: 1 | H22: =IF(D22="","",IFERROR(INDEX(Config!$B$12:$B$15,MATCH(IF(AND(D22="Cartão de crédito",N(E22)>1),"Cartão de crédito parcelado",D22),Config!$A$12:$A$15,0)),0)+IF(AND(Config!$B$17="Sim",LEFT(D22,17)="Cartão de crédito"),Config!$B$18*IFERROR(INDEX(Config!$C$12:$C$15,MATCH(IF(AND(D22="Cartão de crédito",N(E22)>1),"Cartão de crédito parcelado",D22),Config!$A$12:$A$15,0)),0)/30*MAX(1,N(E22)),0)) -> 0.032 | I22: =IF(OR(D22="",F22=""),"",ROUND(F22*H22,2)) -> 12.8 | J22: =IF(I22="","",F22-I22) -> 387.2 | K22: =IF(J22="","",J22/MAX(1,N(E22))) -> 387.2 | L22: =IF(OR(D22="",A22=""),"",A22+IF(AND(Config!$B$17="Sim",LEFT(D22,17)="Cartão de crédito"),1,IFERROR(INDEX(Config!$C$12:$C$15,MATCH(IF(AND(D22="Cartão de crédito",N(E22)>1),"Cartão de crédito parcelado",D22),Config!$A$12:$A$15,0)),0))) -> 46212 | M22: =IF(L22="","",IF(AND(Config!$B$17="Sim",LEFT(D22,17)="Cartão de crédito"),L22,L22+30*(MAX(1,N(E22))-1))) -> 46212 | N22: =IF(OR(L22="",K22=""),"",K22*MIN(MAX(1,N(E22)),MAX(0,INT((Config!$B$8-L22)/30)+1))) -> 387.2 | O22: =IF(J22="","",J22-N(N22)) -> 0 | P22: =IF(A22="","",MONTH(A22)) -> 6 | Q22: =IF(A22="","",YEAR(A22)) -> 2026 | R22: =IF(L22="","",IF(L22>Config!$B$8,"A cair",IF(N(G22)>=MIN(MAX(1,N(E22)),MAX(0,INT((Config!$B$8-L22)/30)+1)),IF(N(G22)>=MAX(1,N(E22)),"Conferido","Conferido até aqui"),"A conferir"))) -> Conferido | S22: =IF(R22="A conferir",(Config!$B$8-L22)*1000+N(F22)/1000+ROW()/100000,0) -> 0 | T22: =IF(R22="A conferir",N(N22),0) -> 0 | U22: =IF(L22="",0,L22) -> 46212 | V22: =IF(L22="",0,MAX(1,N(E22))) -> 1 | W22: =IF(K22="",0,K22) -> 387.2
