Workbook

Sheet Como usar
A1: Base Limpa
A2: Kit IA no Trabalho · Completo · Seu Sócio Gestor · versão 1.0 (setembro de 2026)
A4: O que esta planilha faz | B4: É o modelo de uma base de dados "certa": uma linha por registro, uma coluna por informação, sem células mescladas, sem totais no meio, com listas e validações. É a planilha que ensina a fazer todas as outras, e a que a tabela dinâmica e a IA leem sem erro.
A5: As 7 regras | B5: 1. Cabeçalho na linha 1, uma coluna por informação. 2. Uma linha por registro; nada de linhas em branco ou subtotais no meio. 3. Datas como data, números como número, texto como texto. 4. Categorias vêm de lista, não digitadas à mão. 5. Nada mesclado. 6. O que é calculado fica em coluna própria, com fórmula igual do topo ao fim. 7. Os totais e as análises ficam em outra aba.
A6: Passo 1 | B6: Na aba Base, apague os exemplos e cole os seus dados respeitando o cabeçalho. Troque os nomes das colunas para o seu caso; mantenha uma informação por coluna.
A7: Passo 2 | B7: Use a aba Listas para as categorias. Cada coluna de categoria da Base aponta para uma lista; assim ninguém escreve "marketing", "Marketing" e "MKT" como três coisas diferentes.
A8: Passo 3 | B8: Rode o Checklist de limpeza. Ele mostra quantas linhas estão preenchidas e conta: linhas com data mas sem valor; linhas com valor mas sem data; datas fora do intervalo (antes de 2020 ou no futuro); categorias fora da lista; clientes fora da lista; status em branco; quantidade zero ou em branco; e possíveis lançamentos em dobro (mesmo dia, cliente, descrição e valor). O último item, células mescladas, você confere à mão. Tudo OK, a base está pronta.
A9: Passo 4 | B9: Na aba Resumo, o exemplo de análise por categoria e mês feito só com SOMASES e CONT.SES. A aula 2 mostra como montar a tabela dinâmica a partir desta Base.
A10: Com a IA | B10: Copie 20 a 30 linhas da Base (sem dados pessoais) e use "Estruturar 03: desenhar as colunas" para adaptar ao seu caso, ou "Analisar 08: resumo executivo de uma tabela grande".
A11: Legenda | B11: Células amarelas: você preenche. Brancas: calculadas.
A12: Proteção | B12: Todas as abas são protegidas sem senha. Na Base e nas Listas as células amarelas seguem livres para digitar e colar; o que está bloqueado são as 4.000 fórmulas das colunas calculadas, para uma colagem não apagá-las sem você perceber. Para editar o resto: Revisar > Desproteger planilha (Excel) ou Dados > Proteger intervalos (Google Sheets).
A13: Google Sheets | B13: Faça upload no Google Drive e abra com o Google Sheets. Para a tabela dinâmica: Inserir > Tabela dinâmica, selecionando a aba Base inteira.
A14: Exemplos | B14: Prisma Comunicação é uma empresa fictícia. Os dados são inventados.
A15: Suporte | B15: suporte@seusociogestor.com.br · resposta em até 5 dias úteis · reembolso em até 7 dias pelo mesmo canal.

Sheet Listas
A1: Listas
A2: Cada coluna é uma lista usada pela Base. Mude à vontade; adicione linhas abaixo.
A4: Categoria | B4: Canal | C4: Responsável | D4: Status | E4: Cliente
A5: Serviço | B5: Indicação | C5: Ana | D5: Pago | E5: Loja Verde
A6: Produto | B6: Instagram | C6: Bruno | D6: Em aberto | E6: Bistrô 42
A7: Reembolso | B7: Site | C7: Carla | D7: Cancelado | E7: Horizonte
A8: Ajuste | B8: Evento | C8: Diego | E8: Padaria do Sol
B9: Cliente antigo | E9: Clínica Bem-Estar
E10: Aurora Móveis
E11: Café Central
E12: Escola Nova Era

Sheet Base
A1: ID | B1: Data | C1: Cliente | D1: Categoria | E1: Canal | F1: Responsável | G1: Descrição | H1: Quantidade | I1: Valor unitário | J1: Valor total | K1: Status | L1: Mês | M1: Ano
A2: =IF(B2="","",ROW()-1) -> 1 | B2: 46023 | C2: Loja Verde | D2: Serviço | E2: Evento | F2: Ana | G2: Layout de página | H2: 2 | I2: 2400 | J2: =IF(OR(H2="",I2=""),"",H2*I2) -> 4800 | K2: Pago | L2: =IF(B2="","",MONTH(B2)) -> 1 | M2: =IF(B2="","",YEAR(B2)) -> 2026
A3: =IF(B3="","",ROW()-1) -> 2 | B3: 46024 | C3: Café Central | D3: Serviço | E3: Indicação | F3: Diego | G3: Layout de página | H3: 1 | I3: 1200 | J3: =IF(OR(H3="",I3=""),"",H3*I3) -> 1200 | K3: Pago | L3: =IF(B3="","",MONTH(B3)) -> 1 | M3: =IF(B3="","",YEAR(B3)) -> 2026
A4: =IF(B4="","",ROW()-1) -> 3 | B4: 46024 | C4: Bistrô 42 | D4: Serviço | E4: Instagram | F4: Diego | G4: Diagramação | H4: 1 | I4: 2400 | J4: =IF(OR(H4="",I4=""),"",H4*I4) -> 2400 | K4: Em aberto | L4: =IF(B4="","",MONTH(B4)) -> 1 | M4: =IF(B4="","",YEAR(B4)) -> 2026
A5: =IF(B5="","",ROW()-1) -> 4 | B5: 46027 | C5: Café Central | D5: Serviço | E5: Indicação | F5: Diego | G5: Vídeo curto | H5: 3 | I5: 2400 | J5: =IF(OR(H5="",I5=""),"",H5*I5) -> 7200 | K5: Pago | L5: =IF(B5="","",MONTH(B5)) -> 1 | M5: =IF(B5="","",YEAR(B5)) -> 2026
A6: =IF(B6="","",ROW()-1) -> 5 | B6: 46029 | C6: Clínica Bem-Estar | D6: Reembolso | E6: Evento | F6: Ana | G6: Estorno parcial | H6: 1 | I6: -200 | J6: =IF(OR(H6="",I6=""),"",H6*I6) -> -200 | K6: Em aberto | L6: =IF(B6="","",MONTH(B6)) -> 1 | M6: =IF(B6="","",YEAR(B6)) -> 2026
A7: =IF(B7="","",ROW()-1) -> 6 | B7: 46032 | C7: Escola Nova Era | D7: Produto | E7: Instagram | F7: Ana | G7: Pacote de ícones | H7: 2 | I7: 149 | J7: =IF(OR(H7="",I7=""),"",H7*I7) -> 298 | K7: Em aberto | L7: =IF(B7="","",MONTH(B7)) -> 1 | M7: =IF(B7="","",YEAR(B7)) -> 2026
A8: =IF(B8="","",ROW()-1) -> 7 | B8: 46035 | C8: Horizonte | D8: Serviço | E8: Evento | F8: Carla | G8: Consultoria de marca | H8: 1 | I8: 3200 | J8: =IF(OR(H8="",I8=""),"",H8*I8) -> 3200 | K8: Pago | L8: =IF(B8="","",MONTH(B8)) -> 1 | M8: =IF(B8="","",YEAR(B8)) -> 2026
A9: =IF(B9="","",ROW()-1) -> 8 | B9: 46036 | C9: Bistrô 42 | D9: Serviço | E9: Indicação | F9: Bruno | G9: Vídeo curto | H9: 2 | I9: 800 | J9: =IF(OR(H9="",I9=""),"",H9*I9) -> 1600 | K9: Pago | L9: =IF(B9="","",MONTH(B9)) -> 1 | M9: =IF(B9="","",YEAR(B9)) -> 2026
A10: =IF(B10="","",ROW()-1) -> 9 | B10: 46036 | C10: Padaria do Sol | D10: Serviço | E10: Evento | F10: Diego | G10: Vídeo curto | H10: 3 | I10: 1200 | J10: =IF(OR(H10="",I10=""),"",H10*I10) -> 3600 | K10: Em aberto | L10: =IF(B10="","",MONTH(B10)) -> 1 | M10: =IF(B10="","",YEAR(B10)) -> 2026
A11: =IF(B11="","",ROW()-1) -> 10 | B11: 46037 | C11: Loja Verde | D11: Serviço | E11: Instagram | F11: Diego | G11: Layout de página | H11: 1 | I11: 1200 | J11: =IF(OR(H11="",I11=""),"",H11*I11) -> 1200 | K11: Pago | L11: =IF(B11="","",MONTH(B11)) -> 1 | M11: =IF(B11="","",YEAR(B11)) -> 2026
A12: =IF(B12="","",ROW()-1) -> 11 | B12: 46038 | C12: Bistrô 42 | D12: Serviço | E12: Indicação | F12: Diego | G12: Layout de página | H12: 2 | I12: 800 | J12: =IF(OR(H12="",I12=""),"",H12*I12) -> 1600 | K12: Pago | L12: =IF(B12="","",MONTH(B12)) -> 1 | M12: =IF(B12="","",YEAR(B12)) -> 2026
A13: =IF(B13="","",ROW()-1) -> 12 | B13: 46038 | C13: Aurora Móveis | D13: Serviço | E13: Instagram | F13: Bruno | G13: Consultoria de marca | H13: 2 | I13: 800 | J13: =IF(OR(H13="",I13=""),"",H13*I13) -> 1600 | K13: Pago | L13: =IF(B13="","",MONTH(B13)) -> 1 | M13: =IF(B13="","",YEAR(B13)) -> 2026
... A181: =IF(B181="","",ROW()-1) -> 180 | B181: 46277 | C181: Padaria do Sol | D181: Ajuste | E181: Site | F181: Ana | G181: Ajuste de fatura | H181: 3 | I181: -150 | J181: =IF(OR(H181="",I181=""),"",H181*I181) -> -450 | K181: Pago | L181: =IF(B181="","",MONTH(B181)) -> 9 | M181: =IF(B181="","",YEAR(B181)) -> 2026
A182: =IF(B182="","",ROW()-1) | J182: =IF(OR(H182="",I182=""),"",H182*I182) | L182: =IF(B182="","",MONTH(B182)) | M182: =IF(B182="","",YEAR(B182))
A183: =IF(B183="","",ROW()-1) | J183: =IF(OR(H183="",I183=""),"",H183*I183) | L183: =IF(B183="","",MONTH(B183)) | M183: =IF(B183="","",YEAR(B183))
A184: =IF(B184="","",ROW()-1) | J184: =IF(OR(H184="",I184=""),"",H184*I184) | L184: =IF(B184="","",MONTH(B184)) | M184: =IF(B184="","",YEAR(B184))
A185: =IF(B185="","",ROW()-1) | J185: =IF(OR(H185="",I185=""),"",H185*I185) | L185: =IF(B185="","",MONTH(B185)) | M185: =IF(B185="","",YEAR(B185))
A186: =IF(B186="","",ROW()-1) | J186: =IF(OR(H186="",I186=""),"",H186*I186) | L186: =IF(B186="","",MONTH(B186)) | M186: =IF(B186="","",YEAR(B186))
A187: =IF(B187="","",ROW()-1) | J187: =IF(OR(H187="",I187=""),"",H187*I187) | L187: =IF(B187="","",MONTH(B187)) | M187: =IF(B187="","",YEAR(B187))
A188: =IF(B188="","",ROW()-1) | J188: =IF(OR(H188="",I188=""),"",H188*I188) | L188: =IF(B188="","",MONTH(B188)) | M188: =IF(B188="","",YEAR(B188))
A189: =IF(B189="","",ROW()-1) | J189: =IF(OR(H189="",I189=""),"",H189*I189) | L189: =IF(B189="","",MONTH(B189)) | M189: =IF(B189="","",YEAR(B189))
A190: =IF(B190="","",ROW()-1) | J190: =IF(OR(H190="",I190=""),"",H190*I190) | L190: =IF(B190="","",MONTH(B190)) | M190: =IF(B190="","",YEAR(B190))
A191: =IF(B191="","",ROW()-1) | J191: =IF(OR(H191="",I191=""),"",H191*I191) | L191: =IF(B191="","",MONTH(B191)) | M191: =IF(B191="","",YEAR(B191))
A192: =IF(B192="","",ROW()-1) | J192: =IF(OR(H192="",I192=""),"",H192*I192) | L192: =IF(B192="","",MONTH(B192)) | M192: =IF(B192="","",YEAR(B192))
A193: =IF(B193="","",ROW()-1) | J193: =IF(OR(H193="",I193=""),"",H193*I193) | L193: =IF(B193="","",MONTH(B193)) | M193: =IF(B193="","",YEAR(B193))
... A1001: =IF(B1001="","",ROW()-1) | J1001: =IF(OR(H1001="",I1001=""),"",H1001*I1001) | L1001: =IF(B1001="","",MONTH(B1001)) | M1001: =IF(B1001="","",YEAR(B1001))

Sheet Checklist
A1: Checklist de limpeza
A2: Rode antes de analisar. Tudo zerado = base pronta para tabela dinâmica e para a IA.
A4: Verificação | B4: Resultado | C4: Situação | D4: Como corrigir
A5: Linhas preenchidas | B5: =COUNTA(Base!$B$2:$B$1001) -> 180 | C5: — | D5: Só informação.
A6: Linhas com data mas sem valor | B6: =COUNTIFS(Base!$B$2:$B$1001,"<>",Base!$I$2:$I$1001,"") -> 0 | C6: =IF(B6=0,"OK","Corrigir") -> OK | D6: Preencha o valor unitário ou apague a linha.
A7: Linhas com valor mas sem data | B7: =COUNTIFS(Base!$B$2:$B$1001,"",Base!$I$2:$I$1001,"<>") -> 0 | C7: =IF(B7=0,"OK","Corrigir") -> OK | D7: Toda linha precisa de data.
A8: Datas fora do intervalo (antes de 2020 ou no futuro) | B8: =COUNTIFS(Base!$B$2:$B$1001,"<"&DATE(2020,1,1))+COUNTIFS(Base!$B$2:$B$1001,">"&TODAY()) -> 0 | C8: =IF(B8=0,"OK","Corrigir") -> OK | D8: Confira digitação: 2062 em vez de 2026, por exemplo.
A9: Categorias fora da lista | B9: =COUNTIFS(Base!$B$2:$B$1001,"<>")-SUMPRODUCT(COUNTIFS(Base!$D$2:$D$1001,Listas!$A$5:$A$34,Base!$B$2:$B$1001,"<>")) -> 0 | C9: =IF(B9=0,"OK","Corrigir") -> OK | D9: Use a lista da coluna Categoria; padronize maiúsculas e abreviações.
A10: Clientes fora da lista | B10: =COUNTIFS(Base!$B$2:$B$1001,"<>")-SUMPRODUCT(COUNTIFS(Base!$C$2:$C$1001,Listas!$E$5:$E$34,Base!$B$2:$B$1001,"<>")) -> 0 | C10: =IF(B10=0,"OK","Corrigir") -> OK | D10: Cadastre o cliente em Listas ou corrija o nome.
A11: Status em branco | B11: =COUNTIFS(Base!$B$2:$B$1001,"<>",Base!$K$2:$K$1001,"") -> 0 | C11: =IF(B11=0,"OK","Corrigir") -> OK | D11: Escolha Pago, Em aberto ou Cancelado.
A12: Quantidade zero ou em branco | B12: =COUNTIFS(Base!$B$2:$B$1001,"<>",Base!$H$2:$H$1001,"")+COUNTIFS(Base!$B$2:$B$1001,"<>",Base!$H$2:$H$1001,0) -> 0 | C12: =IF(B12=0,"OK","Corrigir") -> OK | D12: Quantidade mínima é 1.
A13: Descrições duplicadas no mesmo dia e cliente (possível lançamento em dobro) | B13: =SUMPRODUCT(--(COUNTIFS(Base!$B$2:$B$1001,Base!$B$2:$B$1001,Base!$C$2:$C$1001,Base!$C$2:$C$1001,Base!$G$2:$G$1001,Base!$G$2:$G$1001,Base!$I$2:$I$1001,Base!$I$2:$I$1001)>1),--(Base!$B$2:$B$1001<>"")) -> 0 | C13: =IF(B13=0,"OK","Corrigir") -> OK | D13: Abra o filtro por cliente e data e confira se é repetição.
A14: Células mescladas na Base (confira: Página Inicial > Mesclar deve estar desligado) | B14: 0 | C14: =IF(B14=0,"OK","Corrigir") -> OK | D14: Nunca mescle células em uma base. Se mesclar, a tabela dinâmica quebra.
A16: Base pronta? | B16: =IF(COUNTIF(C6:C14,"Corrigir")=0,"Sim: pode analisar","Ainda não: "&COUNTIF(C6:C14,"Corrigir")&" item(ns) para corrigir") -> Sim: pode analisar

Sheet Resumo
A1: Resumo por categoria e mês
A2: Exemplo de análise feita só com SOMASES e CONT.SES em cima da Base. A tabela dinâmica faz o mesmo em 3 cliques (aula 2).
A4: Ano | B4: 2026
A5: Só status | B5: Pago
A7: Categoria | B7: Jan | C7: Fev | D7: Mar | E7: Abr | F7: Mai | G7: Jun | H7: Jul | I7: Ago | J7: Set | K7: Out | L7: Nov | M7: Dez | N7: Total
A8: =IF(Listas!$A$5="","",Listas!$A$5) -> Serviço | B8: =IF(Listas!$A$5="","",SUMIFS(Base!$J$2:$J$1001,Base!$D$2:$D$1001,Listas!$A$5,Base!$L$2:$L$1001,1,Base!$M$2:$M$1001,$B$4,Base!$K$2:$K$1001,$B$5)) -> 40000 | C8: =IF(Listas!$A$5="","",SUMIFS(Base!$J$2:$J$1001,Base!$D$2:$D$1001,Listas!$A$5,Base!$L$2:$L$1001,2,Base!$M$2:$M$1001,$B$4,Base!$K$2:$K$1001,$B$5)) -> 15300 | D8: =IF(Listas!$A$5="","",SUMIFS(Base!$J$2:$J$1001,Base!$D$2:$D$1001,Listas!$A$5,Base!$L$2:$L$1001,3,Base!$M$2:$M$1001,$B$4,Base!$K$2:$K$1001,$B$5)) -> 44400 | E8: =IF(Listas!$A$5="","",SUMIFS(Base!$J$2:$J$1001,Base!$D$2:$D$1001,Listas!$A$5,Base!$L$2:$L$1001,4,Base!$M$2:$M$1001,$B$4,Base!$K$2:$K$1001,$B$5)) -> 29800 | F8: =IF(Listas!$A$5="","",SUMIFS(Base!$J$2:$J$1001,Base!$D$2:$D$1001,Listas!$A$5,Base!$L$2:$L$1001,5,Base!$M$2:$M$1001,$B$4,Base!$K$2:$K$1001,$B$5)) -> 24600 | G8: =IF(Listas!$A$5="","",SUMIFS(Base!$J$2:$J$1001,Base!$D$2:$D$1001,Listas!$A$5,Base!$L$2:$L$1001,6,Base!$M$2:$M$1001,$B$4,Base!$K$2:$K$1001,$B$5)) -> 30300 | H8: =IF(Listas!$A$5="","",SUMIFS(Base!$J$2:$J$1001,Base!$D$2:$D$1001,Listas!$A$5,Base!$L$2:$L$1001,7,Base!$M$2:$M$1001,$B$4,Base!$K$2:$K$1001,$B$5)) -> 40000 | I8: =IF(Listas!$A$5="","",SUMIFS(Base!$J$2:$J$1001,Base!$D$2:$D$1001,Listas!$A$5,Base!$L$2:$L$1001,8,Base!$M$2:$M$1001,$B$4,Base!$K$2:$K$1001,$B$5)) -> 30900 | J8: =IF(Listas!$A$5="","",SUMIFS(Base!$J$2:$J$1001,Base!$D$2:$D$1001,Listas!$A$5,Base!$L$2:$L$1001,9,Base!$M$2:$M$1001,$B$4,Base!$K$2:$K$1001,$B$5)) -> 6400 | K8: =IF(Listas!$A$5="","",SUMIFS(Base!$J$2:$J$1001,Base!$D$2:$D$1001,Listas!$A$5,Base!$L$2:$L$1001,10,Base!$M$2:$M$1001,$B$4,Base!$K$2:$K$1001,$B$5)) -> 0 | L8: =IF(Listas!$A$5="","",SUMIFS(Base!$J$2:$J$1001,Base!$D$2:$D$1001,Listas!$A$5,Base!$L$2:$L$1001,11,Base!$M$2:$M$1001,$B$4,Base!$K$2:$K$1001,$B$5)) -> 0 | M8: =IF(Listas!$A$5="","",SUMIFS(Base!$J$2:$J$1001,Base!$D$2:$D$1001,Listas!$A$5,Base!$L$2:$L$1001,12,Base!$M$2:$M$1001,$B$4,Base!$K$2:$K$1001,$B$5)) -> 0 | N8: =IF(A8="","",SUM(B8:M8)) -> 261700
A9: =IF(Listas!$A$6="","",Listas!$A$6) -> Produto | B9: =IF(Listas!$A$6="","",SUMIFS(Base!$J$2:$J$1001,Base!$D$2:$D$1001,Listas!$A$6,Base!$L$2:$L$1001,1,Base!$M$2:$M$1001,$B$4,Base!$K$2:$K$1001,$B$5)) -> 194 | C9: =IF(Listas!$A$6="","",SUMIFS(Base!$J$2:$J$1001,Base!$D$2:$D$1001,Listas!$A$6,Base!$L$2:$L$1001,2,Base!$M$2:$M$1001,$B$4,Base!$K$2:$K$1001,$B$5)) -> 394 | D9: =IF(Listas!$A$6="","",SUMIFS(Base!$J$2:$J$1001,Base!$D$2:$D$1001,Listas!$A$6,Base!$L$2:$L$1001,3,Base!$M$2:$M$1001,$B$4,Base!$K$2:$K$1001,$B$5)) -> 593 | E9: =IF(Listas!$A$6="","",SUMIFS(Base!$J$2:$J$1001,Base!$D$2:$D$1001,Listas!$A$6,Base!$L$2:$L$1001,4,Base!$M$2:$M$1001,$B$4,Base!$K$2:$K$1001,$B$5)) -> 977 | F9: =IF(Listas!$A$6="","",SUMIFS(Base!$J$2:$J$1001,Base!$D$2:$D$1001,Listas!$A$6,Base!$L$2:$L$1001,5,Base!$M$2:$M$1001,$B$4,Base!$K$2:$K$1001,$B$5)) -> 291 | G9: =IF(Listas!$A$6="","",SUMIFS(Base!$J$2:$J$1001,Base!$D$2:$D$1001,Listas!$A$6,Base!$L$2:$L$1001,6,Base!$M$2:$M$1001,$B$4,Base!$K$2:$K$1001,$B$5)) -> 638 | H9: =IF(Listas!$A$6="","",SUMIFS(Base!$J$2:$J$1001,Base!$D$2:$D$1001,Listas!$A$6,Base!$L$2:$L$1001,7,Base!$M$2:$M$1001,$B$4,Base!$K$2:$K$1001,$B$5)) -> 347 | I9: =IF(Listas!$A$6="","",SUMIFS(Base!$J$2:$J$1001,Base!$D$2:$D$1001,Listas!$A$6,Base!$L$2:$L$1001,8,Base!$M$2:$M$1001,$B$4,Base!$K$2:$K$1001,$B$5)) -> 891 | J9: =IF(Listas!$A$6="","",SUMIFS(Base!$J$2:$J$1001,Base!$D$2:$D$1001,Listas!$A$6,Base!$L$2:$L$1001,9,Base!$M$2:$M$1001,$B$4,Base!$K$2:$K$1001,$B$5)) -> 0 | K9: =IF(Listas!$A$6="","",SUMIFS(Base!$J$2:$J$1001,Base!$D$2:$D$1001,Listas!$A$6,Base!$L$2:$L$1001,10,Base!$M$2:$M$1001,$B$4,Base!$K$2:$K$1001,$B$5)) -> 0 | L9: =IF(Listas!$A$6="","",SUMIFS(Base!$J$2:$J$1001,Base!$D$2:$D$1001,Listas!$A$6,Base!$L$2:$L$1001,11,Base!$M$2:$M$1001,$B$4,Base!$K$2:$K$1001,$B$5)) -> 0 | M9: =IF(Listas!$A$6="","",SUMIFS(Base!$J$2:$J$1001,Base!$D$2:$D$1001,Listas!$A$6,Base!$L$2:$L$1001,12,Base!$M$2:$M$1001,$B$4,Base!$K$2:$K$1001,$B$5)) -> 0 | N9: =IF(A9="","",SUM(B9:M9)) -> 4325
A10: =IF(Listas!$A$7="","",Listas!$A$7) -> Reembolso | B10: =IF(Listas!$A$7="","",SUMIFS(Base!$J$2:$J$1001,Base!$D$2:$D$1001,Listas!$A$7,Base!$L$2:$L$1001,1,Base!$M$2:$M$1001,$B$4,Base!$K$2:$K$1001,$B$5)) -> 0 | C10: =IF(Listas!$A$7="","",SUMIFS(Base!$J$2:$J$1001,Base!$D$2:$D$1001,Listas!$A$7,Base!$L$2:$L$1001,2,Base!$M$2:$M$1001,$B$4,Base!$K$2:$K$1001,$B$5)) -> 0 | D10: =IF(Listas!$A$7="","",SUMIFS(Base!$J$2:$J$1001,Base!$D$2:$D$1001,Listas!$A$7,Base!$L$2:$L$1001,3,Base!$M$2:$M$1001,$B$4,Base!$K$2:$K$1001,$B$5)) -> -600 | E10: =IF(Listas!$A$7="","",SUMIFS(Base!$J$2:$J$1001,Base!$D$2:$D$1001,Listas!$A$7,Base!$L$2:$L$1001,4,Base!$M$2:$M$1001,$B$4,Base!$K$2:$K$1001,$B$5)) -> 0 | F10: =IF(Listas!$A$7="","",SUMIFS(Base!$J$2:$J$1001,Base!$D$2:$D$1001,Listas!$A$7,Base!$L$2:$L$1001,5,Base!$M$2:$M$1001,$B$4,Base!$K$2:$K$1001,$B$5)) -> 0 | G10: =IF(Listas!$A$7="","",SUMIFS(Base!$J$2:$J$1001,Base!$D$2:$D$1001,Listas!$A$7,Base!$L$2:$L$1001,6,Base!$M$2:$M$1001,$B$4,Base!$K$2:$K$1001,$B$5)) -> 0 | H10: =IF(Listas!$A$7="","",SUMIFS(Base!$J$2:$J$1001,Base!$D$2:$D$1001,Listas!$A$7,Base!$L$2:$L$1001,7,Base!$M$2:$M$1001,$B$4,Base!$K$2:$K$1001,$B$5)) -> -200 | I10: =IF(Listas!$A$7="","",SUMIFS(Base!$J$2:$J$1001,Base!$D$2:$D$1001,Listas!$A$7,Base!$L$2:$L$1001,8,Base!$M$2:$M$1001,$B$4,Base!$K$2:$K$1001,$B$5)) -> -400 | J10: =IF(Listas!$A$7="","",SUMIFS(Base!$J$2:$J$1001,Base!$D$2:$D$1001,Listas!$A$7,Base!$L$2:$L$1001,9,Base!$M$2:$M$1001,$B$4,Base!$K$2:$K$1001,$B$5)) -> -200 | K10: =IF(Listas!$A$7="","",SUMIFS(Base!$J$2:$J$1001,Base!$D$2:$D$1001,Listas!$A$7,Base!$L$2:$L$1001,10,Base!$M$2:$M$1001,$B$4,Base!$K$2:$K$1001,$B$5)) -> 0 | L10: =IF(Listas!$A$7="","",SUMIFS(Base!$J$2:$J$1001,Base!$D$2:$D$1001,Listas!$A$7,Base!$L$2:$L$1001,11,Base!$M$2:$M$1001,$B$4,Base!$K$2:$K$1001,$B$5)) -> 0 | M10: =IF(Listas!$A$7="","",SUMIFS(Base!$J$2:$J$1001,Base!$D$2:$D$1001,Listas!$A$7,Base!$L$2:$L$1001,12,Base!$M$2:$M$1001,$B$4,Base!$K$2:$K$1001,$B$5)) -> 0 | N10: =IF(A10="","",SUM(B10:M10)) -> -1400
A11: =IF(Listas!$A$8="","",Listas!$A$8) -> Ajuste | B11: =IF(Listas!$A$8="","",SUMIFS(Base!$J$2:$J$1001,Base!$D$2:$D$1001,Listas!$A$8,Base!$L$2:$L$1001,1,Base!$M$2:$M$1001,$B$4,Base!$K$2:$K$1001,$B$5)) -> -150 | C11: =IF(Listas!$A$8="","",SUMIFS(Base!$J$2:$J$1001,Base!$D$2:$D$1001,Listas!$A$8,Base!$L$2:$L$1001,2,Base!$M$2:$M$1001,$B$4,Base!$K$2:$K$1001,$B$5)) -> -150 | D11: =IF(Listas!$A$8="","",SUMIFS(Base!$J$2:$J$1001,Base!$D$2:$D$1001,Listas!$A$8,Base!$L$2:$L$1001,3,Base!$M$2:$M$1001,$B$4,Base!$K$2:$K$1001,$B$5)) -> 0 | E11: =IF(Listas!$A$8="","",SUMIFS(Base!$J$2:$J$1001,Base!$D$2:$D$1001,Listas!$A$8,Base!$L$2:$L$1001,4,Base!$M$2:$M$1001,$B$4,Base!$K$2:$K$1001,$B$5)) -> 450 | F11: =IF(Listas!$A$8="","",SUMIFS(Base!$J$2:$J$1001,Base!$D$2:$D$1001,Listas!$A$8,Base!$L$2:$L$1001,5,Base!$M$2:$M$1001,$B$4,Base!$K$2:$K$1001,$B$5)) -> 150 | G11: =IF(Listas!$A$8="","",SUMIFS(Base!$J$2:$J$1001,Base!$D$2:$D$1001,Listas!$A$8,Base!$L$2:$L$1001,6,Base!$M$2:$M$1001,$B$4,Base!$K$2:$K$1001,$B$5)) -> -150 | H11: =IF(Listas!$A$8="","",SUMIFS(Base!$J$2:$J$1001,Base!$D$2:$D$1001,Listas!$A$8,Base!$L$2:$L$1001,7,Base!$M$2:$M$1001,$B$4,Base!$K$2:$K$1001,$B$5)) -> -300 | I11: =IF(Listas!$A$8="","",SUMIFS(Base!$J$2:$J$1001,Base!$D$2:$D$1001,Listas!$A$8,Base!$L$2:$L$1001,8,Base!$M$2:$M$1001,$B$4,Base!$K$2:$K$1001,$B$5)) -> 750 | J11: =IF(Listas!$A$8="","",SUMIFS(Base!$J$2:$J$1001,Base!$D$2:$D$1001,Listas!$A$8,Base!$L$2:$L$1001,9,Base!$M$2:$M$1001,$B$4,Base!$K$2:$K$1001,$B$5)) -> -450 | K11: =IF(Listas!$A$8="","",SUMIFS(Base!$J$2:$J$1001,Base!$D$2:$D$1001,Listas!$A$8,Base!$L$2:$L$1001,10,Base!$M$2:$M$1001,$B$4,Base!$K$2:$K$1001,$B$5)) -> 0 | L11: =IF(Listas!$A$8="","",SUMIFS(Base!$J$2:$J$1001,Base!$D$2:$D$1001,Listas!$A$8,Base!$L$2:$L$1001,11,Base!$M$2:$M$1001,$B$4,Base!$K$2:$K$1001,$B$5)) -> 0 | M11: =IF(Listas!$A$8="","",SUMIFS(Base!$J$2:$J$1001,Base!$D$2:$D$1001,Listas!$A$8,Base!$L$2:$L$1001,12,Base!$M$2:$M$1001,$B$4,Base!$K$2:$K$1001,$B$5)) -> 0 | N11: =IF(A11="","",SUM(B11:M11)) -> 150
A12: =IF(Listas!$A$9="","",Listas!$A$9) | B12: =IF(Listas!$A$9="","",SUMIFS(Base!$J$2:$J$1001,Base!$D$2:$D$1001,Listas!$A$9,Base!$L$2:$L$1001,1,Base!$M$2:$M$1001,$B$4,Base!$K$2:$K$1001,$B$5)) | C12: =IF(Listas!$A$9="","",SUMIFS(Base!$J$2:$J$1001,Base!$D$2:$D$1001,Listas!$A$9,Base!$L$2:$L$1001,2,Base!$M$2:$M$1001,$B$4,Base!$K$2:$K$1001,$B$5)) | D12: =IF(Listas!$A$9="","",SUMIFS(Base!$J$2:$J$1001,Base!$D$2:$D$1001,Listas!$A$9,Base!$L$2:$L$1001,3,Base!$M$2:$M$1001,$B$4,Base!$K$2:$K$1001,$B$5)) | E12: =IF(Listas!$A$9="","",SUMIFS(Base!$J$2:$J$1001,Base!$D$2:$D$1001,Listas!$A$9,Base!$L$2:$L$1001,4,Base!$M$2:$M$1001,$B$4,Base!$K$2:$K$1001,$B$5)) | F12: =IF(Listas!$A$9="","",SUMIFS(Base!$J$2:$J$1001,Base!$D$2:$D$1001,Listas!$A$9,Base!$L$2:$L$1001,5,Base!$M$2:$M$1001,$B$4,Base!$K$2:$K$1001,$B$5)) | G12: =IF(Listas!$A$9="","",SUMIFS(Base!$J$2:$J$1001,Base!$D$2:$D$1001,Listas!$A$9,Base!$L$2:$L$1001,6,Base!$M$2:$M$1001,$B$4,Base!$K$2:$K$1001,$B$5)) | H12: =IF(Listas!$A$9="","",SUMIFS(Base!$J$2:$J$1001,Base!$D$2:$D$1001,Listas!$A$9,Base!$L$2:$L$1001,7,Base!$M$2:$M$1001,$B$4,Base!$K$2:$K$1001,$B$5)) | I12: =IF(Listas!$A$9="","",SUMIFS(Base!$J$2:$J$1001,Base!$D$2:$D$1001,Listas!$A$9,Base!$L$2:$L$1001,8,Base!$M$2:$M$1001,$B$4,Base!$K$2:$K$1001,$B$5)) | J12: =IF(Listas!$A$9="","",SUMIFS(Base!$J$2:$J$1001,Base!$D$2:$D$1001,Listas!$A$9,Base!$L$2:$L$1001,9,Base!$M$2:$M$1001,$B$4,Base!$K$2:$K$1001,$B$5)) | K12: =IF(Listas!$A$9="","",SUMIFS(Base!$J$2:$J$1001,Base!$D$2:$D$1001,Listas!$A$9,Base!$L$2:$L$1001,10,Base!$M$2:$M$1001,$B$4,Base!$K$2:$K$1001,$B$5)) | L12: =IF(Listas!$A$9="","",SUMIFS(Base!$J$2:$J$1001,Base!$D$2:$D$1001,Listas!$A$9,Base!$L$2:$L$1001,11,Base!$M$2:$M$1001,$B$4,Base!$K$2:$K$1001,$B$5)) | M12: =IF(Listas!$A$9="","",SUMIFS(Base!$J$2:$J$1001,Base!$D$2:$D$1001,Listas!$A$9,Base!$L$2:$L$1001,12,Base!$M$2:$M$1001,$B$4,Base!$K$2:$K$1001,$B$5)) | N12: =IF(A12="","",SUM(B12:M12))
A13: =IF(Listas!$A$10="","",Listas!$A$10) | B13: =IF(Listas!$A$10="","",SUMIFS(Base!$J$2:$J$1001,Base!$D$2:$D$1001,Listas!$A$10,Base!$L$2:$L$1001,1,Base!$M$2:$M$1001,$B$4,Base!$K$2:$K$1001,$B$5)) | C13: =IF(Listas!$A$10="","",SUMIFS(Base!$J$2:$J$1001,Base!$D$2:$D$1001,Listas!$A$10,Base!$L$2:$L$1001,2,Base!$M$2:$M$1001,$B$4,Base!$K$2:$K$1001,$B$5)) | D13: =IF(Listas!$A$10="","",SUMIFS(Base!$J$2:$J$1001,Base!$D$2:$D$1001,Listas!$A$10,Base!$L$2:$L$1001,3,Base!$M$2:$M$1001,$B$4,Base!$K$2:$K$1001,$B$5)) | E13: =IF(Listas!$A$10="","",SUMIFS(Base!$J$2:$J$1001,Base!$D$2:$D$1001,Listas!$A$10,Base!$L$2:$L$1001,4,Base!$M$2:$M$1001,$B$4,Base!$K$2:$K$1001,$B$5)) | F13: =IF(Listas!$A$10="","",SUMIFS(Base!$J$2:$J$1001,Base!$D$2:$D$1001,Listas!$A$10,Base!$L$2:$L$1001,5,Base!$M$2:$M$1001,$B$4,Base!$K$2:$K$1001,$B$5)) | G13: =IF(Listas!$A$10="","",SUMIFS(Base!$J$2:$J$1001,Base!$D$2:$D$1001,Listas!$A$10,Base!$L$2:$L$1001,6,Base!$M$2:$M$1001,$B$4,Base!$K$2:$K$1001,$B$5)) | H13: =IF(Listas!$A$10="","",SUMIFS(Base!$J$2:$J$1001,Base!$D$2:$D$1001,Listas!$A$10,Base!$L$2:$L$1001,7,Base!$M$2:$M$1001,$B$4,Base!$K$2:$K$1001,$B$5)) | I13: =IF(Listas!$A$10="","",SUMIFS(Base!$J$2:$J$1001,Base!$D$2:$D$1001,Listas!$A$10,Base!$L$2:$L$1001,8,Base!$M$2:$M$1001,$B$4,Base!$K$2:$K$1001,$B$5)) | J13: =IF(Listas!$A$10="","",SUMIFS(Base!$J$2:$J$1001,Base!$D$2:$D$1001,Listas!$A$10,Base!$L$2:$L$1001,9,Base!$M$2:$M$1001,$B$4,Base!$K$2:$K$1001,$B$5)) | K13: =IF(Listas!$A$10="","",SUMIFS(Base!$J$2:$J$1001,Base!$D$2:$D$1001,Listas!$A$10,Base!$L$2:$L$1001,10,Base!$M$2:$M$1001,$B$4,Base!$K$2:$K$1001,$B$5)) | L13: =IF(Listas!$A$10="","",SUMIFS(Base!$J$2:$J$1001,Base!$D$2:$D$1001,Listas!$A$10,Base!$L$2:$L$1001,11,Base!$M$2:$M$1001,$B$4,Base!$K$2:$K$1001,$B$5)) | M13: =IF(Listas!$A$10="","",SUMIFS(Base!$J$2:$J$1001,Base!$D$2:$D$1001,Listas!$A$10,Base!$L$2:$L$1001,12,Base!$M$2:$M$1001,$B$4,Base!$K$2:$K$1001,$B$5)) | N13: =IF(A13="","",SUM(B13:M13))
A14: =IF(Listas!$A$11="","",Listas!$A$11) | B14: =IF(Listas!$A$11="","",SUMIFS(Base!$J$2:$J$1001,Base!$D$2:$D$1001,Listas!$A$11,Base!$L$2:$L$1001,1,Base!$M$2:$M$1001,$B$4,Base!$K$2:$K$1001,$B$5)) | C14: =IF(Listas!$A$11="","",SUMIFS(Base!$J$2:$J$1001,Base!$D$2:$D$1001,Listas!$A$11,Base!$L$2:$L$1001,2,Base!$M$2:$M$1001,$B$4,Base!$K$2:$K$1001,$B$5)) | D14: =IF(Listas!$A$11="","",SUMIFS(Base!$J$2:$J$1001,Base!$D$2:$D$1001,Listas!$A$11,Base!$L$2:$L$1001,3,Base!$M$2:$M$1001,$B$4,Base!$K$2:$K$1001,$B$5)) | E14: =IF(Listas!$A$11="","",SUMIFS(Base!$J$2:$J$1001,Base!$D$2:$D$1001,Listas!$A$11,Base!$L$2:$L$1001,4,Base!$M$2:$M$1001,$B$4,Base!$K$2:$K$1001,$B$5)) | F14: =IF(Listas!$A$11="","",SUMIFS(Base!$J$2:$J$1001,Base!$D$2:$D$1001,Listas!$A$11,Base!$L$2:$L$1001,5,Base!$M$2:$M$1001,$B$4,Base!$K$2:$K$1001,$B$5)) | G14: =IF(Listas!$A$11="","",SUMIFS(Base!$J$2:$J$1001,Base!$D$2:$D$1001,Listas!$A$11,Base!$L$2:$L$1001,6,Base!$M$2:$M$1001,$B$4,Base!$K$2:$K$1001,$B$5)) | H14: =IF(Listas!$A$11="","",SUMIFS(Base!$J$2:$J$1001,Base!$D$2:$D$1001,Listas!$A$11,Base!$L$2:$L$1001,7,Base!$M$2:$M$1001,$B$4,Base!$K$2:$K$1001,$B$5)) | I14: =IF(Listas!$A$11="","",SUMIFS(Base!$J$2:$J$1001,Base!$D$2:$D$1001,Listas!$A$11,Base!$L$2:$L$1001,8,Base!$M$2:$M$1001,$B$4,Base!$K$2:$K$1001,$B$5)) | J14: =IF(Listas!$A$11="","",SUMIFS(Base!$J$2:$J$1001,Base!$D$2:$D$1001,Listas!$A$11,Base!$L$2:$L$1001,9,Base!$M$2:$M$1001,$B$4,Base!$K$2:$K$1001,$B$5)) | K14: =IF(Listas!$A$11="","",SUMIFS(Base!$J$2:$J$1001,Base!$D$2:$D$1001,Listas!$A$11,Base!$L$2:$L$1001,10,Base!$M$2:$M$1001,$B$4,Base!$K$2:$K$1001,$B$5)) | L14: =IF(Listas!$A$11="","",SUMIFS(Base!$J$2:$J$1001,Base!$D$2:$D$1001,Listas!$A$11,Base!$L$2:$L$1001,11,Base!$M$2:$M$1001,$B$4,Base!$K$2:$K$1001,$B$5)) | M14: =IF(Listas!$A$11="","",SUMIFS(Base!$J$2:$J$1001,Base!$D$2:$D$1001,Listas!$A$11,Base!$L$2:$L$1001,12,Base!$M$2:$M$1001,$B$4,Base!$K$2:$K$1001,$B$5)) | N14: =IF(A14="","",SUM(B14:M14))
A15: =IF(Listas!$A$12="","",Listas!$A$12) | B15: =IF(Listas!$A$12="","",SUMIFS(Base!$J$2:$J$1001,Base!$D$2:$D$1001,Listas!$A$12,Base!$L$2:$L$1001,1,Base!$M$2:$M$1001,$B$4,Base!$K$2:$K$1001,$B$5)) | C15: =IF(Listas!$A$12="","",SUMIFS(Base!$J$2:$J$1001,Base!$D$2:$D$1001,Listas!$A$12,Base!$L$2:$L$1001,2,Base!$M$2:$M$1001,$B$4,Base!$K$2:$K$1001,$B$5)) | D15: =IF(Listas!$A$12="","",SUMIFS(Base!$J$2:$J$1001,Base!$D$2:$D$1001,Listas!$A$12,Base!$L$2:$L$1001,3,Base!$M$2:$M$1001,$B$4,Base!$K$2:$K$1001,$B$5)) | E15: =IF(Listas!$A$12="","",SUMIFS(Base!$J$2:$J$1001,Base!$D$2:$D$1001,Listas!$A$12,Base!$L$2:$L$1001,4,Base!$M$2:$M$1001,$B$4,Base!$K$2:$K$1001,$B$5)) | F15: =IF(Listas!$A$12="","",SUMIFS(Base!$J$2:$J$1001,Base!$D$2:$D$1001,Listas!$A$12,Base!$L$2:$L$1001,5,Base!$M$2:$M$1001,$B$4,Base!$K$2:$K$1001,$B$5)) | G15: =IF(Listas!$A$12="","",SUMIFS(Base!$J$2:$J$1001,Base!$D$2:$D$1001,Listas!$A$12,Base!$L$2:$L$1001,6,Base!$M$2:$M$1001,$B$4,Base!$K$2:$K$1001,$B$5)) | H15: =IF(Listas!$A$12="","",SUMIFS(Base!$J$2:$J$1001,Base!$D$2:$D$1001,Listas!$A$12,Base!$L$2:$L$1001,7,Base!$M$2:$M$1001,$B$4,Base!$K$2:$K$1001,$B$5)) | I15: =IF(Listas!$A$12="","",SUMIFS(Base!$J$2:$J$1001,Base!$D$2:$D$1001,Listas!$A$12,Base!$L$2:$L$1001,8,Base!$M$2:$M$1001,$B$4,Base!$K$2:$K$1001,$B$5)) | J15: =IF(Listas!$A$12="","",SUMIFS(Base!$J$2:$J$1001,Base!$D$2:$D$1001,Listas!$A$12,Base!$L$2:$L$1001,9,Base!$M$2:$M$1001,$B$4,Base!$K$2:$K$1001,$B$5)) | K15: =IF(Listas!$A$12="","",SUMIFS(Base!$J$2:$J$1001,Base!$D$2:$D$1001,Listas!$A$12,Base!$L$2:$L$1001,10,Base!$M$2:$M$1001,$B$4,Base!$K$2:$K$1001,$B$5)) | L15: =IF(Listas!$A$12="","",SUMIFS(Base!$J$2:$J$1001,Base!$D$2:$D$1001,Listas!$A$12,Base!$L$2:$L$1001,11,Base!$M$2:$M$1001,$B$4,Base!$K$2:$K$1001,$B$5)) | M15: =IF(Listas!$A$12="","",SUMIFS(Base!$J$2:$J$1001,Base!$D$2:$D$1001,Listas!$A$12,Base!$L$2:$L$1001,12,Base!$M$2:$M$1001,$B$4,Base!$K$2:$K$1001,$B$5)) | N15: =IF(A15="","",SUM(B15:M15))
A16: =IF(Listas!$A$13="","",Listas!$A$13) | B16: =IF(Listas!$A$13="","",SUMIFS(Base!$J$2:$J$1001,Base!$D$2:$D$1001,Listas!$A$13,Base!$L$2:$L$1001,1,Base!$M$2:$M$1001,$B$4,Base!$K$2:$K$1001,$B$5)) | C16: =IF(Listas!$A$13="","",SUMIFS(Base!$J$2:$J$1001,Base!$D$2:$D$1001,Listas!$A$13,Base!$L$2:$L$1001,2,Base!$M$2:$M$1001,$B$4,Base!$K$2:$K$1001,$B$5)) | D16: =IF(Listas!$A$13="","",SUMIFS(Base!$J$2:$J$1001,Base!$D$2:$D$1001,Listas!$A$13,Base!$L$2:$L$1001,3,Base!$M$2:$M$1001,$B$4,Base!$K$2:$K$1001,$B$5)) | E16: =IF(Listas!$A$13="","",SUMIFS(Base!$J$2:$J$1001,Base!$D$2:$D$1001,Listas!$A$13,Base!$L$2:$L$1001,4,Base!$M$2:$M$1001,$B$4,Base!$K$2:$K$1001,$B$5)) | F16: =IF(Listas!$A$13="","",SUMIFS(Base!$J$2:$J$1001,Base!$D$2:$D$1001,Listas!$A$13,Base!$L$2:$L$1001,5,Base!$M$2:$M$1001,$B$4,Base!$K$2:$K$1001,$B$5)) | G16: =IF(Listas!$A$13="","",SUMIFS(Base!$J$2:$J$1001,Base!$D$2:$D$1001,Listas!$A$13,Base!$L$2:$L$1001,6,Base!$M$2:$M$1001,$B$4,Base!$K$2:$K$1001,$B$5)) | H16: =IF(Listas!$A$13="","",SUMIFS(Base!$J$2:$J$1001,Base!$D$2:$D$1001,Listas!$A$13,Base!$L$2:$L$1001,7,Base!$M$2:$M$1001,$B$4,Base!$K$2:$K$1001,$B$5)) | I16: =IF(Listas!$A$13="","",SUMIFS(Base!$J$2:$J$1001,Base!$D$2:$D$1001,Listas!$A$13,Base!$L$2:$L$1001,8,Base!$M$2:$M$1001,$B$4,Base!$K$2:$K$1001,$B$5)) | J16: =IF(Listas!$A$13="","",SUMIFS(Base!$J$2:$J$1001,Base!$D$2:$D$1001,Listas!$A$13,Base!$L$2:$L$1001,9,Base!$M$2:$M$1001,$B$4,Base!$K$2:$K$1001,$B$5)) | K16: =IF(Listas!$A$13="","",SUMIFS(Base!$J$2:$J$1001,Base!$D$2:$D$1001,Listas!$A$13,Base!$L$2:$L$1001,10,Base!$M$2:$M$1001,$B$4,Base!$K$2:$K$1001,$B$5)) | L16: =IF(Listas!$A$13="","",SUMIFS(Base!$J$2:$J$1001,Base!$D$2:$D$1001,Listas!$A$13,Base!$L$2:$L$1001,11,Base!$M$2:$M$1001,$B$4,Base!$K$2:$K$1001,$B$5)) | M16: =IF(Listas!$A$13="","",SUMIFS(Base!$J$2:$J$1001,Base!$D$2:$D$1001,Listas!$A$13,Base!$L$2:$L$1001,12,Base!$M$2:$M$1001,$B$4,Base!$K$2:$K$1001,$B$5)) | N16: =IF(A16="","",SUM(B16:M16))
A17: =IF(Listas!$A$14="","",Listas!$A$14) | B17: =IF(Listas!$A$14="","",SUMIFS(Base!$J$2:$J$1001,Base!$D$2:$D$1001,Listas!$A$14,Base!$L$2:$L$1001,1,Base!$M$2:$M$1001,$B$4,Base!$K$2:$K$1001,$B$5)) | C17: =IF(Listas!$A$14="","",SUMIFS(Base!$J$2:$J$1001,Base!$D$2:$D$1001,Listas!$A$14,Base!$L$2:$L$1001,2,Base!$M$2:$M$1001,$B$4,Base!$K$2:$K$1001,$B$5)) | D17: =IF(Listas!$A$14="","",SUMIFS(Base!$J$2:$J$1001,Base!$D$2:$D$1001,Listas!$A$14,Base!$L$2:$L$1001,3,Base!$M$2:$M$1001,$B$4,Base!$K$2:$K$1001,$B$5)) | E17: =IF(Listas!$A$14="","",SUMIFS(Base!$J$2:$J$1001,Base!$D$2:$D$1001,Listas!$A$14,Base!$L$2:$L$1001,4,Base!$M$2:$M$1001,$B$4,Base!$K$2:$K$1001,$B$5)) | F17: =IF(Listas!$A$14="","",SUMIFS(Base!$J$2:$J$1001,Base!$D$2:$D$1001,Listas!$A$14,Base!$L$2:$L$1001,5,Base!$M$2:$M$1001,$B$4,Base!$K$2:$K$1001,$B$5)) | G17: =IF(Listas!$A$14="","",SUMIFS(Base!$J$2:$J$1001,Base!$D$2:$D$1001,Listas!$A$14,Base!$L$2:$L$1001,6,Base!$M$2:$M$1001,$B$4,Base!$K$2:$K$1001,$B$5)) | H17: =IF(Listas!$A$14="","",SUMIFS(Base!$J$2:$J$1001,Base!$D$2:$D$1001,Listas!$A$14,Base!$L$2:$L$1001,7,Base!$M$2:$M$1001,$B$4,Base!$K$2:$K$1001,$B$5)) | I17: =IF(Listas!$A$14="","",SUMIFS(Base!$J$2:$J$1001,Base!$D$2:$D$1001,Listas!$A$14,Base!$L$2:$L$1001,8,Base!$M$2:$M$1001,$B$4,Base!$K$2:$K$1001,$B$5)) | J17: =IF(Listas!$A$14="","",SUMIFS(Base!$J$2:$J$1001,Base!$D$2:$D$1001,Listas!$A$14,Base!$L$2:$L$1001,9,Base!$M$2:$M$1001,$B$4,Base!$K$2:$K$1001,$B$5)) | K17: =IF(Listas!$A$14="","",SUMIFS(Base!$J$2:$J$1001,Base!$D$2:$D$1001,Listas!$A$14,Base!$L$2:$L$1001,10,Base!$M$2:$M$1001,$B$4,Base!$K$2:$K$1001,$B$5)) | L17: =IF(Listas!$A$14="","",SUMIFS(Base!$J$2:$J$1001,Base!$D$2:$D$1001,Listas!$A$14,Base!$L$2:$L$1001,11,Base!$M$2:$M$1001,$B$4,Base!$K$2:$K$1001,$B$5)) | M17: =IF(Listas!$A$14="","",SUMIFS(Base!$J$2:$J$1001,Base!$D$2:$D$1001,Listas!$A$14,Base!$L$2:$L$1001,12,Base!$M$2:$M$1001,$B$4,Base!$K$2:$K$1001,$B$5)) | N17: =IF(A17="","",SUM(B17:M17))
A18: =IF(Listas!$A$15="","",Listas!$A$15) | B18: =IF(Listas!$A$15="","",SUMIFS(Base!$J$2:$J$1001,Base!$D$2:$D$1001,Listas!$A$15,Base!$L$2:$L$1001,1,Base!$M$2:$M$1001,$B$4,Base!$K$2:$K$1001,$B$5)) | C18: =IF(Listas!$A$15="","",SUMIFS(Base!$J$2:$J$1001,Base!$D$2:$D$1001,Listas!$A$15,Base!$L$2:$L$1001,2,Base!$M$2:$M$1001,$B$4,Base!$K$2:$K$1001,$B$5)) | D18: =IF(Listas!$A$15="","",SUMIFS(Base!$J$2:$J$1001,Base!$D$2:$D$1001,Listas!$A$15,Base!$L$2:$L$1001,3,Base!$M$2:$M$1001,$B$4,Base!$K$2:$K$1001,$B$5)) | E18: =IF(Listas!$A$15="","",SUMIFS(Base!$J$2:$J$1001,Base!$D$2:$D$1001,Listas!$A$15,Base!$L$2:$L$1001,4,Base!$M$2:$M$1001,$B$4,Base!$K$2:$K$1001,$B$5)) | F18: =IF(Listas!$A$15="","",SUMIFS(Base!$J$2:$J$1001,Base!$D$2:$D$1001,Listas!$A$15,Base!$L$2:$L$1001,5,Base!$M$2:$M$1001,$B$4,Base!$K$2:$K$1001,$B$5)) | G18: =IF(Listas!$A$15="","",SUMIFS(Base!$J$2:$J$1001,Base!$D$2:$D$1001,Listas!$A$15,Base!$L$2:$L$1001,6,Base!$M$2:$M$1001,$B$4,Base!$K$2:$K$1001,$B$5)) | H18: =IF(Listas!$A$15="","",SUMIFS(Base!$J$2:$J$1001,Base!$D$2:$D$1001,Listas!$A$15,Base!$L$2:$L$1001,7,Base!$M$2:$M$1001,$B$4,Base!$K$2:$K$1001,$B$5)) | I18: =IF(Listas!$A$15="","",SUMIFS(Base!$J$2:$J$1001,Base!$D$2:$D$1001,Listas!$A$15,Base!$L$2:$L$1001,8,Base!$M$2:$M$1001,$B$4,Base!$K$2:$K$1001,$B$5)) | J18: =IF(Listas!$A$15="","",SUMIFS(Base!$J$2:$J$1001,Base!$D$2:$D$1001,Listas!$A$15,Base!$L$2:$L$1001,9,Base!$M$2:$M$1001,$B$4,Base!$K$2:$K$1001,$B$5)) | K18: =IF(Listas!$A$15="","",SUMIFS(Base!$J$2:$J$1001,Base!$D$2:$D$1001,Listas!$A$15,Base!$L$2:$L$1001,10,Base!$M$2:$M$1001,$B$4,Base!$K$2:$K$1001,$B$5)) | L18: =IF(Listas!$A$15="","",SUMIFS(Base!$J$2:$J$1001,Base!$D$2:$D$1001,Listas!$A$15,Base!$L$2:$L$1001,11,Base!$M$2:$M$1001,$B$4,Base!$K$2:$K$1001,$B$5)) | M18: =IF(Listas!$A$15="","",SUMIFS(Base!$J$2:$J$1001,Base!$D$2:$D$1001,Listas!$A$15,Base!$L$2:$L$1001,12,Base!$M$2:$M$1001,$B$4,Base!$K$2:$K$1001,$B$5)) | N18: =IF(A18="","",SUM(B18:M18))
A19: =IF(Listas!$A$16="","",Listas!$A$16) | B19: =IF(Listas!$A$16="","",SUMIFS(Base!$J$2:$J$1001,Base!$D$2:$D$1001,Listas!$A$16,Base!$L$2:$L$1001,1,Base!$M$2:$M$1001,$B$4,Base!$K$2:$K$1001,$B$5)) | C19: =IF(Listas!$A$16="","",SUMIFS(Base!$J$2:$J$1001,Base!$D$2:$D$1001,Listas!$A$16,Base!$L$2:$L$1001,2,Base!$M$2:$M$1001,$B$4,Base!$K$2:$K$1001,$B$5)) | D19: =IF(Listas!$A$16="","",SUMIFS(Base!$J$2:$J$1001,Base!$D$2:$D$1001,Listas!$A$16,Base!$L$2:$L$1001,3,Base!$M$2:$M$1001,$B$4,Base!$K$2:$K$1001,$B$5)) | E19: =IF(Listas!$A$16="","",SUMIFS(Base!$J$2:$J$1001,Base!$D$2:$D$1001,Listas!$A$16,Base!$L$2:$L$1001,4,Base!$M$2:$M$1001,$B$4,Base!$K$2:$K$1001,$B$5)) | F19: =IF(Listas!$A$16="","",SUMIFS(Base!$J$2:$J$1001,Base!$D$2:$D$1001,Listas!$A$16,Base!$L$2:$L$1001,5,Base!$M$2:$M$1001,$B$4,Base!$K$2:$K$1001,$B$5)) | G19: =IF(Listas!$A$16="","",SUMIFS(Base!$J$2:$J$1001,Base!$D$2:$D$1001,Listas!$A$16,Base!$L$2:$L$1001,6,Base!$M$2:$M$1001,$B$4,Base!$K$2:$K$1001,$B$5)) | H19: =IF(Listas!$A$16="","",SUMIFS(Base!$J$2:$J$1001,Base!$D$2:$D$1001,Listas!$A$16,Base!$L$2:$L$1001,7,Base!$M$2:$M$1001,$B$4,Base!$K$2:$K$1001,$B$5)) | I19: =IF(Listas!$A$16="","",SUMIFS(Base!$J$2:$J$1001,Base!$D$2:$D$1001,Listas!$A$16,Base!$L$2:$L$1001,8,Base!$M$2:$M$1001,$B$4,Base!$K$2:$K$1001,$B$5)) | J19: =IF(Listas!$A$16="","",SUMIFS(Base!$J$2:$J$1001,Base!$D$2:$D$1001,Listas!$A$16,Base!$L$2:$L$1001,9,Base!$M$2:$M$1001,$B$4,Base!$K$2:$K$1001,$B$5)) | K19: =IF(Listas!$A$16="","",SUMIFS(Base!$J$2:$J$1001,Base!$D$2:$D$1001,Listas!$A$16,Base!$L$2:$L$1001,10,Base!$M$2:$M$1001,$B$4,Base!$K$2:$K$1001,$B$5)) | L19: =IF(Listas!$A$16="","",SUMIFS(Base!$J$2:$J$1001,Base!$D$2:$D$1001,Listas!$A$16,Base!$L$2:$L$1001,11,Base!$M$2:$M$1001,$B$4,Base!$K$2:$K$1001,$B$5)) | M19: =IF(Listas!$A$16="","",SUMIFS(Base!$J$2:$J$1001,Base!$D$2:$D$1001,Listas!$A$16,Base!$L$2:$L$1001,12,Base!$M$2:$M$1001,$B$4,Base!$K$2:$K$1001,$B$5)) | N19: =IF(A19="","",SUM(B19:M19))
A20: =IF(Listas!$A$17="","",Listas!$A$17) | B20: =IF(Listas!$A$17="","",SUMIFS(Base!$J$2:$J$1001,Base!$D$2:$D$1001,Listas!$A$17,Base!$L$2:$L$1001,1,Base!$M$2:$M$1001,$B$4,Base!$K$2:$K$1001,$B$5)) | C20: =IF(Listas!$A$17="","",SUMIFS(Base!$J$2:$J$1001,Base!$D$2:$D$1001,Listas!$A$17,Base!$L$2:$L$1001,2,Base!$M$2:$M$1001,$B$4,Base!$K$2:$K$1001,$B$5)) | D20: =IF(Listas!$A$17="","",SUMIFS(Base!$J$2:$J$1001,Base!$D$2:$D$1001,Listas!$A$17,Base!$L$2:$L$1001,3,Base!$M$2:$M$1001,$B$4,Base!$K$2:$K$1001,$B$5)) | E20: =IF(Listas!$A$17="","",SUMIFS(Base!$J$2:$J$1001,Base!$D$2:$D$1001,Listas!$A$17,Base!$L$2:$L$1001,4,Base!$M$2:$M$1001,$B$4,Base!$K$2:$K$1001,$B$5)) | F20: =IF(Listas!$A$17="","",SUMIFS(Base!$J$2:$J$1001,Base!$D$2:$D$1001,Listas!$A$17,Base!$L$2:$L$1001,5,Base!$M$2:$M$1001,$B$4,Base!$K$2:$K$1001,$B$5)) | G20: =IF(Listas!$A$17="","",SUMIFS(Base!$J$2:$J$1001,Base!$D$2:$D$1001,Listas!$A$17,Base!$L$2:$L$1001,6,Base!$M$2:$M$1001,$B$4,Base!$K$2:$K$1001,$B$5)) | H20: =IF(Listas!$A$17="","",SUMIFS(Base!$J$2:$J$1001,Base!$D$2:$D$1001,Listas!$A$17,Base!$L$2:$L$1001,7,Base!$M$2:$M$1001,$B$4,Base!$K$2:$K$1001,$B$5)) | I20: =IF(Listas!$A$17="","",SUMIFS(Base!$J$2:$J$1001,Base!$D$2:$D$1001,Listas!$A$17,Base!$L$2:$L$1001,8,Base!$M$2:$M$1001,$B$4,Base!$K$2:$K$1001,$B$5)) | J20: =IF(Listas!$A$17="","",SUMIFS(Base!$J$2:$J$1001,Base!$D$2:$D$1001,Listas!$A$17,Base!$L$2:$L$1001,9,Base!$M$2:$M$1001,$B$4,Base!$K$2:$K$1001,$B$5)) | K20: =IF(Listas!$A$17="","",SUMIFS(Base!$J$2:$J$1001,Base!$D$2:$D$1001,Listas!$A$17,Base!$L$2:$L$1001,10,Base!$M$2:$M$1001,$B$4,Base!$K$2:$K$1001,$B$5)) | L20: =IF(Listas!$A$17="","",SUMIFS(Base!$J$2:$J$1001,Base!$D$2:$D$1001,Listas!$A$17,Base!$L$2:$L$1001,11,Base!$M$2:$M$1001,$B$4,Base!$K$2:$K$1001,$B$5)) | M20: =IF(Listas!$A$17="","",SUMIFS(Base!$J$2:$J$1001,Base!$D$2:$D$1001,Listas!$A$17,Base!$L$2:$L$1001,12,Base!$M$2:$M$1001,$B$4,Base!$K$2:$K$1001,$B$5)) | N20: =IF(A20="","",SUM(B20:M20))
A21: =IF(Listas!$A$18="","",Listas!$A$18) | B21: =IF(Listas!$A$18="","",SUMIFS(Base!$J$2:$J$1001,Base!$D$2:$D$1001,Listas!$A$18,Base!$L$2:$L$1001,1,Base!$M$2:$M$1001,$B$4,Base!$K$2:$K$1001,$B$5)) | C21: =IF(Listas!$A$18="","",SUMIFS(Base!$J$2:$J$1001,Base!$D$2:$D$1001,Listas!$A$18,Base!$L$2:$L$1001,2,Base!$M$2:$M$1001,$B$4,Base!$K$2:$K$1001,$B$5)) | D21: =IF(Listas!$A$18="","",SUMIFS(Base!$J$2:$J$1001,Base!$D$2:$D$1001,Listas!$A$18,Base!$L$2:$L$1001,3,Base!$M$2:$M$1001,$B$4,Base!$K$2:$K$1001,$B$5)) | E21: =IF(Listas!$A$18="","",SUMIFS(Base!$J$2:$J$1001,Base!$D$2:$D$1001,Listas!$A$18,Base!$L$2:$L$1001,4,Base!$M$2:$M$1001,$B$4,Base!$K$2:$K$1001,$B$5)) | F21: =IF(Listas!$A$18="","",SUMIFS(Base!$J$2:$J$1001,Base!$D$2:$D$1001,Listas!$A$18,Base!$L$2:$L$1001,5,Base!$M$2:$M$1001,$B$4,Base!$K$2:$K$1001,$B$5)) | G21: =IF(Listas!$A$18="","",SUMIFS(Base!$J$2:$J$1001,Base!$D$2:$D$1001,Listas!$A$18,Base!$L$2:$L$1001,6,Base!$M$2:$M$1001,$B$4,Base!$K$2:$K$1001,$B$5)) | H21: =IF(Listas!$A$18="","",SUMIFS(Base!$J$2:$J$1001,Base!$D$2:$D$1001,Listas!$A$18,Base!$L$2:$L$1001,7,Base!$M$2:$M$1001,$B$4,Base!$K$2:$K$1001,$B$5)) | I21: =IF(Listas!$A$18="","",SUMIFS(Base!$J$2:$J$1001,Base!$D$2:$D$1001,Listas!$A$18,Base!$L$2:$L$1001,8,Base!$M$2:$M$1001,$B$4,Base!$K$2:$K$1001,$B$5)) | J21: =IF(Listas!$A$18="","",SUMIFS(Base!$J$2:$J$1001,Base!$D$2:$D$1001,Listas!$A$18,Base!$L$2:$L$1001,9,Base!$M$2:$M$1001,$B$4,Base!$K$2:$K$1001,$B$5)) | K21: =IF(Listas!$A$18="","",SUMIFS(Base!$J$2:$J$1001,Base!$D$2:$D$1001,Listas!$A$18,Base!$L$2:$L$1001,10,Base!$M$2:$M$1001,$B$4,Base!$K$2:$K$1001,$B$5)) | L21: =IF(Listas!$A$18="","",SUMIFS(Base!$J$2:$J$1001,Base!$D$2:$D$1001,Listas!$A$18,Base!$L$2:$L$1001,11,Base!$M$2:$M$1001,$B$4,Base!$K$2:$K$1001,$B$5)) | M21: =IF(Listas!$A$18="","",SUMIFS(Base!$J$2:$J$1001,Base!$D$2:$D$1001,Listas!$A$18,Base!$L$2:$L$1001,12,Base!$M$2:$M$1001,$B$4,Base!$K$2:$K$1001,$B$5)) | N21: =IF(A21="","",SUM(B21:M21))
A22: =IF(Listas!$A$19="","",Listas!$A$19) | B22: =IF(Listas!$A$19="","",SUMIFS(Base!$J$2:$J$1001,Base!$D$2:$D$1001,Listas!$A$19,Base!$L$2:$L$1001,1,Base!$M$2:$M$1001,$B$4,Base!$K$2:$K$1001,$B$5)) | C22: =IF(Listas!$A$19="","",SUMIFS(Base!$J$2:$J$1001,Base!$D$2:$D$1001,Listas!$A$19,Base!$L$2:$L$1001,2,Base!$M$2:$M$1001,$B$4,Base!$K$2:$K$1001,$B$5)) | D22: =IF(Listas!$A$19="","",SUMIFS(Base!$J$2:$J$1001,Base!$D$2:$D$1001,Listas!$A$19,Base!$L$2:$L$1001,3,Base!$M$2:$M$1001,$B$4,Base!$K$2:$K$1001,$B$5)) | E22: =IF(Listas!$A$19="","",SUMIFS(Base!$J$2:$J$1001,Base!$D$2:$D$1001,Listas!$A$19,Base!$L$2:$L$1001,4,Base!$M$2:$M$1001,$B$4,Base!$K$2:$K$1001,$B$5)) | F22: =IF(Listas!$A$19="","",SUMIFS(Base!$J$2:$J$1001,Base!$D$2:$D$1001,Listas!$A$19,Base!$L$2:$L$1001,5,Base!$M$2:$M$1001,$B$4,Base!$K$2:$K$1001,$B$5)) | G22: =IF(Listas!$A$19="","",SUMIFS(Base!$J$2:$J$1001,Base!$D$2:$D$1001,Listas!$A$19,Base!$L$2:$L$1001,6,Base!$M$2:$M$1001,$B$4,Base!$K$2:$K$1001,$B$5)) | H22: =IF(Listas!$A$19="","",SUMIFS(Base!$J$2:$J$1001,Base!$D$2:$D$1001,Listas!$A$19,Base!$L$2:$L$1001,7,Base!$M$2:$M$1001,$B$4,Base!$K$2:$K$1001,$B$5)) | I22: =IF(Listas!$A$19="","",SUMIFS(Base!$J$2:$J$1001,Base!$D$2:$D$1001,Listas!$A$19,Base!$L$2:$L$1001,8,Base!$M$2:$M$1001,$B$4,Base!$K$2:$K$1001,$B$5)) | J22: =IF(Listas!$A$19="","",SUMIFS(Base!$J$2:$J$1001,Base!$D$2:$D$1001,Listas!$A$19,Base!$L$2:$L$1001,9,Base!$M$2:$M$1001,$B$4,Base!$K$2:$K$1001,$B$5)) | K22: =IF(Listas!$A$19="","",SUMIFS(Base!$J$2:$J$1001,Base!$D$2:$D$1001,Listas!$A$19,Base!$L$2:$L$1001,10,Base!$M$2:$M$1001,$B$4,Base!$K$2:$K$1001,$B$5)) | L22: =IF(Listas!$A$19="","",SUMIFS(Base!$J$2:$J$1001,Base!$D$2:$D$1001,Listas!$A$19,Base!$L$2:$L$1001,11,Base!$M$2:$M$1001,$B$4,Base!$K$2:$K$1001,$B$5)) | M22: =IF(Listas!$A$19="","",SUMIFS(Base!$J$2:$J$1001,Base!$D$2:$D$1001,Listas!$A$19,Base!$L$2:$L$1001,12,Base!$M$2:$M$1001,$B$4,Base!$K$2:$K$1001,$B$5)) | N22: =IF(A22="","",SUM(B22:M22))
A23: =IF(Listas!$A$20="","",Listas!$A$20) | B23: =IF(Listas!$A$20="","",SUMIFS(Base!$J$2:$J$1001,Base!$D$2:$D$1001,Listas!$A$20,Base!$L$2:$L$1001,1,Base!$M$2:$M$1001,$B$4,Base!$K$2:$K$1001,$B$5)) | C23: =IF(Listas!$A$20="","",SUMIFS(Base!$J$2:$J$1001,Base!$D$2:$D$1001,Listas!$A$20,Base!$L$2:$L$1001,2,Base!$M$2:$M$1001,$B$4,Base!$K$2:$K$1001,$B$5)) | D23: =IF(Listas!$A$20="","",SUMIFS(Base!$J$2:$J$1001,Base!$D$2:$D$1001,Listas!$A$20,Base!$L$2:$L$1001,3,Base!$M$2:$M$1001,$B$4,Base!$K$2:$K$1001,$B$5)) | E23: =IF(Listas!$A$20="","",SUMIFS(Base!$J$2:$J$1001,Base!$D$2:$D$1001,Listas!$A$20,Base!$L$2:$L$1001,4,Base!$M$2:$M$1001,$B$4,Base!$K$2:$K$1001,$B$5)) | F23: =IF(Listas!$A$20="","",SUMIFS(Base!$J$2:$J$1001,Base!$D$2:$D$1001,Listas!$A$20,Base!$L$2:$L$1001,5,Base!$M$2:$M$1001,$B$4,Base!$K$2:$K$1001,$B$5)) | G23: =IF(Listas!$A$20="","",SUMIFS(Base!$J$2:$J$1001,Base!$D$2:$D$1001,Listas!$A$20,Base!$L$2:$L$1001,6,Base!$M$2:$M$1001,$B$4,Base!$K$2:$K$1001,$B$5)) | H23: =IF(Listas!$A$20="","",SUMIFS(Base!$J$2:$J$1001,Base!$D$2:$D$1001,Listas!$A$20,Base!$L$2:$L$1001,7,Base!$M$2:$M$1001,$B$4,Base!$K$2:$K$1001,$B$5)) | I23: =IF(Listas!$A$20="","",SUMIFS(Base!$J$2:$J$1001,Base!$D$2:$D$1001,Listas!$A$20,Base!$L$2:$L$1001,8,Base!$M$2:$M$1001,$B$4,Base!$K$2:$K$1001,$B$5)) | J23: =IF(Listas!$A$20="","",SUMIFS(Base!$J$2:$J$1001,Base!$D$2:$D$1001,Listas!$A$20,Base!$L$2:$L$1001,9,Base!$M$2:$M$1001,$B$4,Base!$K$2:$K$1001,$B$5)) | K23: =IF(Listas!$A$20="","",SUMIFS(Base!$J$2:$J$1001,Base!$D$2:$D$1001,Listas!$A$20,Base!$L$2:$L$1001,10,Base!$M$2:$M$1001,$B$4,Base!$K$2:$K$1001,$B$5)) | L23: =IF(Listas!$A$20="","",SUMIFS(Base!$J$2:$J$1001,Base!$D$2:$D$1001,Listas!$A$20,Base!$L$2:$L$1001,11,Base!$M$2:$M$1001,$B$4,Base!$K$2:$K$1001,$B$5)) | M23: =IF(Listas!$A$20="","",SUMIFS(Base!$J$2:$J$1001,Base!$D$2:$D$1001,Listas!$A$20,Base!$L$2:$L$1001,12,Base!$M$2:$M$1001,$B$4,Base!$K$2:$K$1001,$B$5)) | N23: =IF(A23="","",SUM(B23:M23))
A24: =IF(Listas!$A$21="","",Listas!$A$21) | B24: =IF(Listas!$A$21="","",SUMIFS(Base!$J$2:$J$1001,Base!$D$2:$D$1001,Listas!$A$21,Base!$L$2:$L$1001,1,Base!$M$2:$M$1001,$B$4,Base!$K$2:$K$1001,$B$5)) | C24: =IF(Listas!$A$21="","",SUMIFS(Base!$J$2:$J$1001,Base!$D$2:$D$1001,Listas!$A$21,Base!$L$2:$L$1001,2,Base!$M$2:$M$1001,$B$4,Base!$K$2:$K$1001,$B$5)) | D24: =IF(Listas!$A$21="","",SUMIFS(Base!$J$2:$J$1001,Base!$D$2:$D$1001,Listas!$A$21,Base!$L$2:$L$1001,3,Base!$M$2:$M$1001,$B$4,Base!$K$2:$K$1001,$B$5)) | E24: =IF(Listas!$A$21="","",SUMIFS(Base!$J$2:$J$1001,Base!$D$2:$D$1001,Listas!$A$21,Base!$L$2:$L$1001,4,Base!$M$2:$M$1001,$B$4,Base!$K$2:$K$1001,$B$5)) | F24: =IF(Listas!$A$21="","",SUMIFS(Base!$J$2:$J$1001,Base!$D$2:$D$1001,Listas!$A$21,Base!$L$2:$L$1001,5,Base!$M$2:$M$1001,$B$4,Base!$K$2:$K$1001,$B$5)) | G24: =IF(Listas!$A$21="","",SUMIFS(Base!$J$2:$J$1001,Base!$D$2:$D$1001,Listas!$A$21,Base!$L$2:$L$1001,6,Base!$M$2:$M$1001,$B$4,Base!$K$2:$K$1001,$B$5)) | H24: =IF(Listas!$A$21="","",SUMIFS(Base!$J$2:$J$1001,Base!$D$2:$D$1001,Listas!$A$21,Base!$L$2:$L$1001,7,Base!$M$2:$M$1001,$B$4,Base!$K$2:$K$1001,$B$5)) | I24: =IF(Listas!$A$21="","",SUMIFS(Base!$J$2:$J$1001,Base!$D$2:$D$1001,Listas!$A$21,Base!$L$2:$L$1001,8,Base!$M$2:$M$1001,$B$4,Base!$K$2:$K$1001,$B$5)) | J24: =IF(Listas!$A$21="","",SUMIFS(Base!$J$2:$J$1001,Base!$D$2:$D$1001,Listas!$A$21,Base!$L$2:$L$1001,9,Base!$M$2:$M$1001,$B$4,Base!$K$2:$K$1001,$B$5)) | K24: =IF(Listas!$A$21="","",SUMIFS(Base!$J$2:$J$1001,Base!$D$2:$D$1001,Listas!$A$21,Base!$L$2:$L$1001,10,Base!$M$2:$M$1001,$B$4,Base!$K$2:$K$1001,$B$5)) | L24: =IF(Listas!$A$21="","",SUMIFS(Base!$J$2:$J$1001,Base!$D$2:$D$1001,Listas!$A$21,Base!$L$2:$L$1001,11,Base!$M$2:$M$1001,$B$4,Base!$K$2:$K$1001,$B$5)) | M24: =IF(Listas!$A$21="","",SUMIFS(Base!$J$2:$J$1001,Base!$D$2:$D$1001,Listas!$A$21,Base!$L$2:$L$1001,12,Base!$M$2:$M$1001,$B$4,Base!$K$2:$K$1001,$B$5)) | N24: =IF(A24="","",SUM(B24:M24))
A25: =IF(Listas!$A$22="","",Listas!$A$22) | B25: =IF(Listas!$A$22="","",SUMIFS(Base!$J$2:$J$1001,Base!$D$2:$D$1001,Listas!$A$22,Base!$L$2:$L$1001,1,Base!$M$2:$M$1001,$B$4,Base!$K$2:$K$1001,$B$5)) | C25: =IF(Listas!$A$22="","",SUMIFS(Base!$J$2:$J$1001,Base!$D$2:$D$1001,Listas!$A$22,Base!$L$2:$L$1001,2,Base!$M$2:$M$1001,$B$4,Base!$K$2:$K$1001,$B$5)) | D25: =IF(Listas!$A$22="","",SUMIFS(Base!$J$2:$J$1001,Base!$D$2:$D$1001,Listas!$A$22,Base!$L$2:$L$1001,3,Base!$M$2:$M$1001,$B$4,Base!$K$2:$K$1001,$B$5)) | E25: =IF(Listas!$A$22="","",SUMIFS(Base!$J$2:$J$1001,Base!$D$2:$D$1001,Listas!$A$22,Base!$L$2:$L$1001,4,Base!$M$2:$M$1001,$B$4,Base!$K$2:$K$1001,$B$5)) | F25: =IF(Listas!$A$22="","",SUMIFS(Base!$J$2:$J$1001,Base!$D$2:$D$1001,Listas!$A$22,Base!$L$2:$L$1001,5,Base!$M$2:$M$1001,$B$4,Base!$K$2:$K$1001,$B$5)) | G25: =IF(Listas!$A$22="","",SUMIFS(Base!$J$2:$J$1001,Base!$D$2:$D$1001,Listas!$A$22,Base!$L$2:$L$1001,6,Base!$M$2:$M$1001,$B$4,Base!$K$2:$K$1001,$B$5)) | H25: =IF(Listas!$A$22="","",SUMIFS(Base!$J$2:$J$1001,Base!$D$2:$D$1001,Listas!$A$22,Base!$L$2:$L$1001,7,Base!$M$2:$M$1001,$B$4,Base!$K$2:$K$1001,$B$5)) | I25: =IF(Listas!$A$22="","",SUMIFS(Base!$J$2:$J$1001,Base!$D$2:$D$1001,Listas!$A$22,Base!$L$2:$L$1001,8,Base!$M$2:$M$1001,$B$4,Base!$K$2:$K$1001,$B$5)) | J25: =IF(Listas!$A$22="","",SUMIFS(Base!$J$2:$J$1001,Base!$D$2:$D$1001,Listas!$A$22,Base!$L$2:$L$1001,9,Base!$M$2:$M$1001,$B$4,Base!$K$2:$K$1001,$B$5)) | K25: =IF(Listas!$A$22="","",SUMIFS(Base!$J$2:$J$1001,Base!$D$2:$D$1001,Listas!$A$22,Base!$L$2:$L$1001,10,Base!$M$2:$M$1001,$B$4,Base!$K$2:$K$1001,$B$5)) | L25: =IF(Listas!$A$22="","",SUMIFS(Base!$J$2:$J$1001,Base!$D$2:$D$1001,Listas!$A$22,Base!$L$2:$L$1001,11,Base!$M$2:$M$1001,$B$4,Base!$K$2:$K$1001,$B$5)) | M25: =IF(Listas!$A$22="","",SUMIFS(Base!$J$2:$J$1001,Base!$D$2:$D$1001,Listas!$A$22,Base!$L$2:$L$1001,12,Base!$M$2:$M$1001,$B$4,Base!$K$2:$K$1001,$B$5)) | N25: =IF(A25="","",SUM(B25:M25))
A26: =IF(Listas!$A$23="","",Listas!$A$23) | B26: =IF(Listas!$A$23="","",SUMIFS(Base!$J$2:$J$1001,Base!$D$2:$D$1001,Listas!$A$23,Base!$L$2:$L$1001,1,Base!$M$2:$M$1001,$B$4,Base!$K$2:$K$1001,$B$5)) | C26: =IF(Listas!$A$23="","",SUMIFS(Base!$J$2:$J$1001,Base!$D$2:$D$1001,Listas!$A$23,Base!$L$2:$L$1001,2,Base!$M$2:$M$1001,$B$4,Base!$K$2:$K$1001,$B$5)) | D26: =IF(Listas!$A$23="","",SUMIFS(Base!$J$2:$J$1001,Base!$D$2:$D$1001,Listas!$A$23,Base!$L$2:$L$1001,3,Base!$M$2:$M$1001,$B$4,Base!$K$2:$K$1001,$B$5)) | E26: =IF(Listas!$A$23="","",SUMIFS(Base!$J$2:$J$1001,Base!$D$2:$D$1001,Listas!$A$23,Base!$L$2:$L$1001,4,Base!$M$2:$M$1001,$B$4,Base!$K$2:$K$1001,$B$5)) | F26: =IF(Listas!$A$23="","",SUMIFS(Base!$J$2:$J$1001,Base!$D$2:$D$1001,Listas!$A$23,Base!$L$2:$L$1001,5,Base!$M$2:$M$1001,$B$4,Base!$K$2:$K$1001,$B$5)) | G26: =IF(Listas!$A$23="","",SUMIFS(Base!$J$2:$J$1001,Base!$D$2:$D$1001,Listas!$A$23,Base!$L$2:$L$1001,6,Base!$M$2:$M$1001,$B$4,Base!$K$2:$K$1001,$B$5)) | H26: =IF(Listas!$A$23="","",SUMIFS(Base!$J$2:$J$1001,Base!$D$2:$D$1001,Listas!$A$23,Base!$L$2:$L$1001,7,Base!$M$2:$M$1001,$B$4,Base!$K$2:$K$1001,$B$5)) | I26: =IF(Listas!$A$23="","",SUMIFS(Base!$J$2:$J$1001,Base!$D$2:$D$1001,Listas!$A$23,Base!$L$2:$L$1001,8,Base!$M$2:$M$1001,$B$4,Base!$K$2:$K$1001,$B$5)) | J26: =IF(Listas!$A$23="","",SUMIFS(Base!$J$2:$J$1001,Base!$D$2:$D$1001,Listas!$A$23,Base!$L$2:$L$1001,9,Base!$M$2:$M$1001,$B$4,Base!$K$2:$K$1001,$B$5)) | K26: =IF(Listas!$A$23="","",SUMIFS(Base!$J$2:$J$1001,Base!$D$2:$D$1001,Listas!$A$23,Base!$L$2:$L$1001,10,Base!$M$2:$M$1001,$B$4,Base!$K$2:$K$1001,$B$5)) | L26: =IF(Listas!$A$23="","",SUMIFS(Base!$J$2:$J$1001,Base!$D$2:$D$1001,Listas!$A$23,Base!$L$2:$L$1001,11,Base!$M$2:$M$1001,$B$4,Base!$K$2:$K$1001,$B$5)) | M26: =IF(Listas!$A$23="","",SUMIFS(Base!$J$2:$J$1001,Base!$D$2:$D$1001,Listas!$A$23,Base!$L$2:$L$1001,12,Base!$M$2:$M$1001,$B$4,Base!$K$2:$K$1001,$B$5)) | N26: =IF(A26="","",SUM(B26:M26))
A27: =IF(Listas!$A$24="","",Listas!$A$24) | B27: =IF(Listas!$A$24="","",SUMIFS(Base!$J$2:$J$1001,Base!$D$2:$D$1001,Listas!$A$24,Base!$L$2:$L$1001,1,Base!$M$2:$M$1001,$B$4,Base!$K$2:$K$1001,$B$5)) | C27: =IF(Listas!$A$24="","",SUMIFS(Base!$J$2:$J$1001,Base!$D$2:$D$1001,Listas!$A$24,Base!$L$2:$L$1001,2,Base!$M$2:$M$1001,$B$4,Base!$K$2:$K$1001,$B$5)) | D27: =IF(Listas!$A$24="","",SUMIFS(Base!$J$2:$J$1001,Base!$D$2:$D$1001,Listas!$A$24,Base!$L$2:$L$1001,3,Base!$M$2:$M$1001,$B$4,Base!$K$2:$K$1001,$B$5)) | E27: =IF(Listas!$A$24="","",SUMIFS(Base!$J$2:$J$1001,Base!$D$2:$D$1001,Listas!$A$24,Base!$L$2:$L$1001,4,Base!$M$2:$M$1001,$B$4,Base!$K$2:$K$1001,$B$5)) | F27: =IF(Listas!$A$24="","",SUMIFS(Base!$J$2:$J$1001,Base!$D$2:$D$1001,Listas!$A$24,Base!$L$2:$L$1001,5,Base!$M$2:$M$1001,$B$4,Base!$K$2:$K$1001,$B$5)) | G27: =IF(Listas!$A$24="","",SUMIFS(Base!$J$2:$J$1001,Base!$D$2:$D$1001,Listas!$A$24,Base!$L$2:$L$1001,6,Base!$M$2:$M$1001,$B$4,Base!$K$2:$K$1001,$B$5)) | H27: =IF(Listas!$A$24="","",SUMIFS(Base!$J$2:$J$1001,Base!$D$2:$D$1001,Listas!$A$24,Base!$L$2:$L$1001,7,Base!$M$2:$M$1001,$B$4,Base!$K$2:$K$1001,$B$5)) | I27: =IF(Listas!$A$24="","",SUMIFS(Base!$J$2:$J$1001,Base!$D$2:$D$1001,Listas!$A$24,Base!$L$2:$L$1001,8,Base!$M$2:$M$1001,$B$4,Base!$K$2:$K$1001,$B$5)) | J27: =IF(Listas!$A$24="","",SUMIFS(Base!$J$2:$J$1001,Base!$D$2:$D$1001,Listas!$A$24,Base!$L$2:$L$1001,9,Base!$M$2:$M$1001,$B$4,Base!$K$2:$K$1001,$B$5)) | K27: =IF(Listas!$A$24="","",SUMIFS(Base!$J$2:$J$1001,Base!$D$2:$D$1001,Listas!$A$24,Base!$L$2:$L$1001,10,Base!$M$2:$M$1001,$B$4,Base!$K$2:$K$1001,$B$5)) | L27: =IF(Listas!$A$24="","",SUMIFS(Base!$J$2:$J$1001,Base!$D$2:$D$1001,Listas!$A$24,Base!$L$2:$L$1001,11,Base!$M$2:$M$1001,$B$4,Base!$K$2:$K$1001,$B$5)) | M27: =IF(Listas!$A$24="","",SUMIFS(Base!$J$2:$J$1001,Base!$D$2:$D$1001,Listas!$A$24,Base!$L$2:$L$1001,12,Base!$M$2:$M$1001,$B$4,Base!$K$2:$K$1001,$B$5)) | N27: =IF(A27="","",SUM(B27:M27))
A28: =IF(Listas!$A$25="","",Listas!$A$25) | B28: =IF(Listas!$A$25="","",SUMIFS(Base!$J$2:$J$1001,Base!$D$2:$D$1001,Listas!$A$25,Base!$L$2:$L$1001,1,Base!$M$2:$M$1001,$B$4,Base!$K$2:$K$1001,$B$5)) | C28: =IF(Listas!$A$25="","",SUMIFS(Base!$J$2:$J$1001,Base!$D$2:$D$1001,Listas!$A$25,Base!$L$2:$L$1001,2,Base!$M$2:$M$1001,$B$4,Base!$K$2:$K$1001,$B$5)) | D28: =IF(Listas!$A$25="","",SUMIFS(Base!$J$2:$J$1001,Base!$D$2:$D$1001,Listas!$A$25,Base!$L$2:$L$1001,3,Base!$M$2:$M$1001,$B$4,Base!$K$2:$K$1001,$B$5)) | E28: =IF(Listas!$A$25="","",SUMIFS(Base!$J$2:$J$1001,Base!$D$2:$D$1001,Listas!$A$25,Base!$L$2:$L$1001,4,Base!$M$2:$M$1001,$B$4,Base!$K$2:$K$1001,$B$5)) | F28: =IF(Listas!$A$25="","",SUMIFS(Base!$J$2:$J$1001,Base!$D$2:$D$1001,Listas!$A$25,Base!$L$2:$L$1001,5,Base!$M$2:$M$1001,$B$4,Base!$K$2:$K$1001,$B$5)) | G28: =IF(Listas!$A$25="","",SUMIFS(Base!$J$2:$J$1001,Base!$D$2:$D$1001,Listas!$A$25,Base!$L$2:$L$1001,6,Base!$M$2:$M$1001,$B$4,Base!$K$2:$K$1001,$B$5)) | H28: =IF(Listas!$A$25="","",SUMIFS(Base!$J$2:$J$1001,Base!$D$2:$D$1001,Listas!$A$25,Base!$L$2:$L$1001,7,Base!$M$2:$M$1001,$B$4,Base!$K$2:$K$1001,$B$5)) | I28: =IF(Listas!$A$25="","",SUMIFS(Base!$J$2:$J$1001,Base!$D$2:$D$1001,Listas!$A$25,Base!$L$2:$L$1001,8,Base!$M$2:$M$1001,$B$4,Base!$K$2:$K$1001,$B$5)) | J28: =IF(Listas!$A$25="","",SUMIFS(Base!$J$2:$J$1001,Base!$D$2:$D$1001,Listas!$A$25,Base!$L$2:$L$1001,9,Base!$M$2:$M$1001,$B$4,Base!$K$2:$K$1001,$B$5)) | K28: =IF(Listas!$A$25="","",SUMIFS(Base!$J$2:$J$1001,Base!$D$2:$D$1001,Listas!$A$25,Base!$L$2:$L$1001,10,Base!$M$2:$M$1001,$B$4,Base!$K$2:$K$1001,$B$5)) | L28: =IF(Listas!$A$25="","",SUMIFS(Base!$J$2:$J$1001,Base!$D$2:$D$1001,Listas!$A$25,Base!$L$2:$L$1001,11,Base!$M$2:$M$1001,$B$4,Base!$K$2:$K$1001,$B$5)) | M28: =IF(Listas!$A$25="","",SUMIFS(Base!$J$2:$J$1001,Base!$D$2:$D$1001,Listas!$A$25,Base!$L$2:$L$1001,12,Base!$M$2:$M$1001,$B$4,Base!$K$2:$K$1001,$B$5)) | N28: =IF(A28="","",SUM(B28:M28))
A29: =IF(Listas!$A$26="","",Listas!$A$26) | B29: =IF(Listas!$A$26="","",SUMIFS(Base!$J$2:$J$1001,Base!$D$2:$D$1001,Listas!$A$26,Base!$L$2:$L$1001,1,Base!$M$2:$M$1001,$B$4,Base!$K$2:$K$1001,$B$5)) | C29: =IF(Listas!$A$26="","",SUMIFS(Base!$J$2:$J$1001,Base!$D$2:$D$1001,Listas!$A$26,Base!$L$2:$L$1001,2,Base!$M$2:$M$1001,$B$4,Base!$K$2:$K$1001,$B$5)) | D29: =IF(Listas!$A$26="","",SUMIFS(Base!$J$2:$J$1001,Base!$D$2:$D$1001,Listas!$A$26,Base!$L$2:$L$1001,3,Base!$M$2:$M$1001,$B$4,Base!$K$2:$K$1001,$B$5)) | E29: =IF(Listas!$A$26="","",SUMIFS(Base!$J$2:$J$1001,Base!$D$2:$D$1001,Listas!$A$26,Base!$L$2:$L$1001,4,Base!$M$2:$M$1001,$B$4,Base!$K$2:$K$1001,$B$5)) | F29: =IF(Listas!$A$26="","",SUMIFS(Base!$J$2:$J$1001,Base!$D$2:$D$1001,Listas!$A$26,Base!$L$2:$L$1001,5,Base!$M$2:$M$1001,$B$4,Base!$K$2:$K$1001,$B$5)) | G29: =IF(Listas!$A$26="","",SUMIFS(Base!$J$2:$J$1001,Base!$D$2:$D$1001,Listas!$A$26,Base!$L$2:$L$1001,6,Base!$M$2:$M$1001,$B$4,Base!$K$2:$K$1001,$B$5)) | H29: =IF(Listas!$A$26="","",SUMIFS(Base!$J$2:$J$1001,Base!$D$2:$D$1001,Listas!$A$26,Base!$L$2:$L$1001,7,Base!$M$2:$M$1001,$B$4,Base!$K$2:$K$1001,$B$5)) | I29: =IF(Listas!$A$26="","",SUMIFS(Base!$J$2:$J$1001,Base!$D$2:$D$1001,Listas!$A$26,Base!$L$2:$L$1001,8,Base!$M$2:$M$1001,$B$4,Base!$K$2:$K$1001,$B$5)) | J29: =IF(Listas!$A$26="","",SUMIFS(Base!$J$2:$J$1001,Base!$D$2:$D$1001,Listas!$A$26,Base!$L$2:$L$1001,9,Base!$M$2:$M$1001,$B$4,Base!$K$2:$K$1001,$B$5)) | K29: =IF(Listas!$A$26="","",SUMIFS(Base!$J$2:$J$1001,Base!$D$2:$D$1001,Listas!$A$26,Base!$L$2:$L$1001,10,Base!$M$2:$M$1001,$B$4,Base!$K$2:$K$1001,$B$5)) | L29: =IF(Listas!$A$26="","",SUMIFS(Base!$J$2:$J$1001,Base!$D$2:$D$1001,Listas!$A$26,Base!$L$2:$L$1001,11,Base!$M$2:$M$1001,$B$4,Base!$K$2:$K$1001,$B$5)) | M29: =IF(Listas!$A$26="","",SUMIFS(Base!$J$2:$J$1001,Base!$D$2:$D$1001,Listas!$A$26,Base!$L$2:$L$1001,12,Base!$M$2:$M$1001,$B$4,Base!$K$2:$K$1001,$B$5)) | N29: =IF(A29="","",SUM(B29:M29))
A30: =IF(Listas!$A$27="","",Listas!$A$27) | B30: =IF(Listas!$A$27="","",SUMIFS(Base!$J$2:$J$1001,Base!$D$2:$D$1001,Listas!$A$27,Base!$L$2:$L$1001,1,Base!$M$2:$M$1001,$B$4,Base!$K$2:$K$1001,$B$5)) | C30: =IF(Listas!$A$27="","",SUMIFS(Base!$J$2:$J$1001,Base!$D$2:$D$1001,Listas!$A$27,Base!$L$2:$L$1001,2,Base!$M$2:$M$1001,$B$4,Base!$K$2:$K$1001,$B$5)) | D30: =IF(Listas!$A$27="","",SUMIFS(Base!$J$2:$J$1001,Base!$D$2:$D$1001,Listas!$A$27,Base!$L$2:$L$1001,3,Base!$M$2:$M$1001,$B$4,Base!$K$2:$K$1001,$B$5)) | E30: =IF(Listas!$A$27="","",SUMIFS(Base!$J$2:$J$1001,Base!$D$2:$D$1001,Listas!$A$27,Base!$L$2:$L$1001,4,Base!$M$2:$M$1001,$B$4,Base!$K$2:$K$1001,$B$5)) | F30: =IF(Listas!$A$27="","",SUMIFS(Base!$J$2:$J$1001,Base!$D$2:$D$1001,Listas!$A$27,Base!$L$2:$L$1001,5,Base!$M$2:$M$1001,$B$4,Base!$K$2:$K$1001,$B$5)) | G30: =IF(Listas!$A$27="","",SUMIFS(Base!$J$2:$J$1001,Base!$D$2:$D$1001,Listas!$A$27,Base!$L$2:$L$1001,6,Base!$M$2:$M$1001,$B$4,Base!$K$2:$K$1001,$B$5)) | H30: =IF(Listas!$A$27="","",SUMIFS(Base!$J$2:$J$1001,Base!$D$2:$D$1001,Listas!$A$27,Base!$L$2:$L$1001,7,Base!$M$2:$M$1001,$B$4,Base!$K$2:$K$1001,$B$5)) | I30: =IF(Listas!$A$27="","",SUMIFS(Base!$J$2:$J$1001,Base!$D$2:$D$1001,Listas!$A$27,Base!$L$2:$L$1001,8,Base!$M$2:$M$1001,$B$4,Base!$K$2:$K$1001,$B$5)) | J30: =IF(Listas!$A$27="","",SUMIFS(Base!$J$2:$J$1001,Base!$D$2:$D$1001,Listas!$A$27,Base!$L$2:$L$1001,9,Base!$M$2:$M$1001,$B$4,Base!$K$2:$K$1001,$B$5)) | K30: =IF(Listas!$A$27="","",SUMIFS(Base!$J$2:$J$1001,Base!$D$2:$D$1001,Listas!$A$27,Base!$L$2:$L$1001,10,Base!$M$2:$M$1001,$B$4,Base!$K$2:$K$1001,$B$5)) | L30: =IF(Listas!$A$27="","",SUMIFS(Base!$J$2:$J$1001,Base!$D$2:$D$1001,Listas!$A$27,Base!$L$2:$L$1001,11,Base!$M$2:$M$1001,$B$4,Base!$K$2:$K$1001,$B$5)) | M30: =IF(Listas!$A$27="","",SUMIFS(Base!$J$2:$J$1001,Base!$D$2:$D$1001,Listas!$A$27,Base!$L$2:$L$1001,12,Base!$M$2:$M$1001,$B$4,Base!$K$2:$K$1001,$B$5)) | N30: =IF(A30="","",SUM(B30:M30))
A31: =IF(Listas!$A$28="","",Listas!$A$28) | B31: =IF(Listas!$A$28="","",SUMIFS(Base!$J$2:$J$1001,Base!$D$2:$D$1001,Listas!$A$28,Base!$L$2:$L$1001,1,Base!$M$2:$M$1001,$B$4,Base!$K$2:$K$1001,$B$5)) | C31: =IF(Listas!$A$28="","",SUMIFS(Base!$J$2:$J$1001,Base!$D$2:$D$1001,Listas!$A$28,Base!$L$2:$L$1001,2,Base!$M$2:$M$1001,$B$4,Base!$K$2:$K$1001,$B$5)) | D31: =IF(Listas!$A$28="","",SUMIFS(Base!$J$2:$J$1001,Base!$D$2:$D$1001,Listas!$A$28,Base!$L$2:$L$1001,3,Base!$M$2:$M$1001,$B$4,Base!$K$2:$K$1001,$B$5)) | E31: =IF(Listas!$A$28="","",SUMIFS(Base!$J$2:$J$1001,Base!$D$2:$D$1001,Listas!$A$28,Base!$L$2:$L$1001,4,Base!$M$2:$M$1001,$B$4,Base!$K$2:$K$1001,$B$5)) | F31: =IF(Listas!$A$28="","",SUMIFS(Base!$J$2:$J$1001,Base!$D$2:$D$1001,Listas!$A$28,Base!$L$2:$L$1001,5,Base!$M$2:$M$1001,$B$4,Base!$K$2:$K$1001,$B$5)) | G31: =IF(Listas!$A$28="","",SUMIFS(Base!$J$2:$J$1001,Base!$D$2:$D$1001,Listas!$A$28,Base!$L$2:$L$1001,6,Base!$M$2:$M$1001,$B$4,Base!$K$2:$K$1001,$B$5)) | H31: =IF(Listas!$A$28="","",SUMIFS(Base!$J$2:$J$1001,Base!$D$2:$D$1001,Listas!$A$28,Base!$L$2:$L$1001,7,Base!$M$2:$M$1001,$B$4,Base!$K$2:$K$1001,$B$5)) | I31: =IF(Listas!$A$28="","",SUMIFS(Base!$J$2:$J$1001,Base!$D$2:$D$1001,Listas!$A$28,Base!$L$2:$L$1001,8,Base!$M$2:$M$1001,$B$4,Base!$K$2:$K$1001,$B$5)) | J31: =IF(Listas!$A$28="","",SUMIFS(Base!$J$2:$J$1001,Base!$D$2:$D$1001,Listas!$A$28,Base!$L$2:$L$1001,9,Base!$M$2:$M$1001,$B$4,Base!$K$2:$K$1001,$B$5)) | K31: =IF(Listas!$A$28="","",SUMIFS(Base!$J$2:$J$1001,Base!$D$2:$D$1001,Listas!$A$28,Base!$L$2:$L$1001,10,Base!$M$2:$M$1001,$B$4,Base!$K$2:$K$1001,$B$5)) | L31: =IF(Listas!$A$28="","",SUMIFS(Base!$J$2:$J$1001,Base!$D$2:$D$1001,Listas!$A$28,Base!$L$2:$L$1001,11,Base!$M$2:$M$1001,$B$4,Base!$K$2:$K$1001,$B$5)) | M31: =IF(Listas!$A$28="","",SUMIFS(Base!$J$2:$J$1001,Base!$D$2:$D$1001,Listas!$A$28,Base!$L$2:$L$1001,12,Base!$M$2:$M$1001,$B$4,Base!$K$2:$K$1001,$B$5)) | N31: =IF(A31="","",SUM(B31:M31))
